Workbook

Sheet 打字練習表
B2: 漢字 | C2: 羅馬字母拼音 | D2: 字母 | E2: 鍵盤按鍵
E3: 1 | F3: 2 | G3: 3 | H3: 4 | I3: 5 | J3: 6 | K3: 7 | L3: 8 | M3: 9
B4: 涼 | C4: liang5 | D4: =IF( LEN(C4)>0, LEN(C4), "") -> 6 | E4: {=IF(E$3<>$D4, MID($C4,E$3,1), INDEX(音調表!$D$3:$D$12, MATCH(TRUE, EXACT(MID($C4,E$3,1), 音調表!$B$3:$B$12),0)))} -> l | F4: {=IF(F$3<>$D4, MID($C4,F$3,1), INDEX(音調表!$D$3:$D$12, MATCH(TRUE, EXACT(MID($C4,F$3,1), 音調表!$B$3:$B$12),0)))} -> i | G4: {=IF(G$3<>$D4, MID($C4,G$3,1), INDEX(音調表!$D$3:$D$12, MATCH(TRUE, EXACT(MID($C4,G$3,1), 音調表!$B$3:$B$12),0)))} -> a | H4: {=IF(H$3<>$D4, MID($C4,H$3,1), INDEX(音調表!$D$3:$D$12, MATCH(TRUE, EXACT(MID($C4,H$3,1), 音調表!$B$3:$B$12),0)))} -> n | I4: {=IF(I$3<>$D4, MID($C4,I$3,1), INDEX(音調表!$D$3:$D$12, MATCH(TRUE, EXACT(MID($C4,I$3,1), 音調表!$B$3:$B$12),0)))} -> g | J4: {=IF(J$3<>$D4, MID($C4,J$3,1), INDEX(音調表!$D$3:$D$12, MATCH(TRUE, EXACT(MID($C4,J$3,1), 音調表!$B$3:$B$12),0)))} -> / | K4: {=IF(K$3<>$D4, MID($C4,K$3,1), INDEX(音調表!$D$3:$D$12, MATCH(TRUE, EXACT(MID($C4,K$3,1), 音調表!$B$3:$B$12),0)))} | L4: {=IF(L$3<>$D4, MID($C4,L$3,1), INDEX(音調表!$D$3:$D$12, MATCH(TRUE, EXACT(MID($C4,L$3,1), 音調表!$B$3:$B$12),0)))} | M4: {=IF(M$3<>$D4, MID($C4,M$3,1), INDEX(音調表!$D$3:$D$12, MATCH(TRUE, EXACT(MID($C4,M$3,1), 音調表!$B$3:$B$12),0)))} | Q4: {=IF( ISNUMBER(VALUE(J4)), INDEX(音調表!$D$3:$D$12, MATCH(TRUE, EXACT(J4, 音調表!$B$3:$B$12),0)), "")}
B5: 州 | C5: ziu1 | D5: =IF( LEN(C5)>0, LEN(C5), "") -> 4 | E5: {=IF(E$3<>$D5, MID($C5,E$3,1), INDEX(音調表!$D$3:$D$12, MATCH(TRUE, EXACT(MID($C5,E$3,1), 音調表!$B$3:$B$12),0)))} -> z | F5: {=IF(F$3<>$D5, MID($C5,F$3,1), INDEX(音調表!$D$3:$D$12, MATCH(TRUE, EXACT(MID($C5,F$3,1), 音調表!$B$3:$B$12),0)))} -> i | G5: {=IF(G$3<>$D5, MID($C5,G$3,1), INDEX(音調表!$D$3:$D$12, MATCH(TRUE, EXACT(MID($C5,G$3,1), 音調表!$B$3:$B$12),0)))} -> u | H5: {=IF(H$3<>$D5, MID($C5,H$3,1), INDEX(音調表!$D$3:$D$12, MATCH(TRUE, EXACT(MID($C5,H$3,1), 音調表!$B$3:$B$12),0)))} -> ; | I5: {=IF(I$3<>$D5, MID($C5,I$3,1), INDEX(音調表!$D$3:$D$12, MATCH(TRUE, EXACT(MID($C5,I$3,1), 音調表!$B$3:$B$12),0)))} | J5: {=IF(J$3<>$D5, MID($C5,J$3,1), INDEX(音調表!$D$3:$D$12, MATCH(TRUE, EXACT(MID($C5,J$3,1), 音調表!$B$3:$B$12),0)))} | K5: {=IF(K$3<>$D5, MID($C5,K$3,1), INDEX(音調表!$D$3:$D$12, MATCH(TRUE, EXACT(MID($C5,K$3,1), 音調表!$B$3:$B$12),0)))} | L5: {=IF(L$3<>$D5, MID($C5,L$3,1), INDEX(音調表!$D$3:$D$12, MATCH(TRUE, EXACT(MID($C5,L$3,1), 音調表!$B$3:$B$12),0)))} | M5: {=IF(M$3<>$D5, MID($C5,M$3,1), INDEX(音調表!$D$3:$D$12, MATCH(TRUE, EXACT(MID($C5,M$3,1), 音調表!$B$3:$B$12),0)))}
B6: 詞 | C6: su5 | D6: =IF( LEN(C6)>0, LEN(C6), "") -> 3 | E6: {=IF(E$3<>$D6, MID($C6,E$3,1), INDEX(音調表!$D$3:$D$12, MATCH(TRUE, EXACT(MID($C6,E$3,1), 音調表!$B$3:$B$12),0)))} -> s | F6: {=IF(F$3<>$D6, MID($C6,F$3,1), INDEX(音調表!$D$3:$D$12, MATCH(TRUE, EXACT(MID($C6,F$3,1), 音調表!$B$3:$B$12),0)))} -> u | G6: {=IF(G$3<>$D6, MID($C6,G$3,1), INDEX(音調表!$D$3:$D$12, MATCH(TRUE, EXACT(MID($C6,G$3,1), 音調表!$B$3:$B$12),0)))} -> / | H6: {=IF(H$3<>$D6, MID($C6,H$3,1), INDEX(音調表!$D$3:$D$12, MATCH(TRUE, EXACT(MID($C6,H$3,1), 音調表!$B$3:$B$12),0)))} | I6: {=IF(I$3<>$D6, MID($C6,I$3,1), INDEX(音調表!$D$3:$D$12, MATCH(TRUE, EXACT(MID($C6,I$3,1), 音調表!$B$3:$B$12),0)))} | J6: {=IF(J$3<>$D6, MID($C6,J$3,1), INDEX(音調表!$D$3:$D$12, MATCH(TRUE, EXACT(MID($C6,J$3,1), 音調表!$B$3:$B$12),0)))} | K6: {=IF(K$3<>$D6, MID($C6,K$3,1), INDEX(音調表!$D$3:$D$12, MATCH(TRUE, EXACT(MID($C6,K$3,1), 音調表!$B$3:$B$12),0)))} | L6: {=IF(L$3<>$D6, MID($C6,L$3,1), INDEX(音調表!$D$3:$D$12, MATCH(TRUE, EXACT(MID($C6,L$3,1), 音調表!$B$3:$B$12),0)))} | M6: {=IF(M$3<>$D6, MID($C6,M$3,1), INDEX(音調表!$D$3:$D$12, MATCH(TRUE, EXACT(MID($C6,M$3,1), 音調表!$B$3:$B$12),0)))}
D7: =IF( LEN(C7)>0, LEN(C7), "") | E7: {=IF(E$3<>$D7, MID($C7,E$3,1), INDEX(音調表!$D$3:$D$12, MATCH(TRUE, EXACT(MID($C7,E$3,1), 音調表!$B$3:$B$12),0)))} | F7: {=IF(F$3<>$D7, MID($C7,F$3,1), INDEX(音調表!$D$3:$D$12, MATCH(TRUE, EXACT(MID($C7,F$3,1), 音調表!$B$3:$B$12),0)))} | G7: {=IF(G$3<>$D7, MID($C7,G$3,1), INDEX(音調表!$D$3:$D$12, MATCH(TRUE, EXACT(MID($C7,G$3,1), 音調表!$B$3:$B$12),0)))} | H7: {=IF(H$3<>$D7, MID($C7,H$3,1), INDEX(音調表!$D$3:$D$12, MATCH(TRUE, EXACT(MID($C7,H$3,1), 音調表!$B$3:$B$12),0)))} | I7: {=IF(I$3<>$D7, MID($C7,I$3,1), INDEX(音調表!$D$3:$D$12, MATCH(TRUE, EXACT(MID($C7,I$3,1), 音調表!$B$3:$B$12),0)))} | J7: {=IF(J$3<>$D7, MID($C7,J$3,1), INDEX(音調表!$D$3:$D$12, MATCH(TRUE, EXACT(MID($C7,J$3,1), 音調表!$B$3:$B$12),0)))} | K7: {=IF(K$3<>$D7, MID($C7,K$3,1), INDEX(音調表!$D$3:$D$12, MATCH(TRUE, EXACT(MID($C7,K$3,1), 音調表!$B$3:$B$12),0)))} | L7: {=IF(L$3<>$D7, MID($C7,L$3,1), INDEX(音調表!$D$3:$D$12, MATCH(TRUE, EXACT(MID($C7,L$3,1), 音調表!$B$3:$B$12),0)))} | M7: {=IF(M$3<>$D7, MID($C7,M$3,1), INDEX(音調表!$D$3:$D$12, MATCH(TRUE, EXACT(MID($C7,M$3,1), 音調表!$B$3:$B$12),0)))}
B8: 王 | C8: ong5 | D8: =IF( LEN(C8)>0, LEN(C8), "") -> 4 | E8: {=IF(E$3<>$D8, MID($C8,E$3,1), INDEX(音調表!$D$3:$D$12, MATCH(TRUE, EXACT(MID($C8,E$3,1), 音調表!$B$3:$B$12),0)))} -> o | F8: {=IF(F$3<>$D8, MID($C8,F$3,1), INDEX(音調表!$D$3:$D$12, MATCH(TRUE, EXACT(MID($C8,F$3,1), 音調表!$B$3:$B$12),0)))} -> n | G8: {=IF(G$3<>$D8, MID($C8,G$3,1), INDEX(音調表!$D$3:$D$12, MATCH(TRUE, EXACT(MID($C8,G$3,1), 音調表!$B$3:$B$12),0)))} -> g | H8: {=IF(H$3<>$D8, MID($C8,H$3,1), INDEX(音調表!$D$3:$D$12, MATCH(TRUE, EXACT(MID($C8,H$3,1), 音調表!$B$3:$B$12),0)))} -> / | I8: {=IF(I$3<>$D8, MID($C8,I$3,1), INDEX(音調表!$D$3:$D$12, MATCH(TRUE, EXACT(MID($C8,I$3,1), 音調表!$B$3:$B$12),0)))} | J8: {=IF(J$3<>$D8, MID($C8,J$3,1), INDEX(音調表!$D$3:$D$12, MATCH(TRUE, EXACT(MID($C8,J$3,1), 音調表!$B$3:$B$12),0)))} | K8: {=IF(K$3<>$D8, MID($C8,K$3,1), INDEX(音調表!$D$3:$D$12, MATCH(TRUE, EXACT(MID($C8,K$3,1), 音調表!$B$3:$B$12),0)))} | L8: {=IF(L$3<>$D8, MID($C8,L$3,1), INDEX(音調表!$D$3:$D$12, MATCH(TRUE, EXACT(MID($C8,L$3,1), 音調表!$B$3:$B$12),0)))} | M8: {=IF(M$3<>$D8, MID($C8,M$3,1), INDEX(音調表!$D$3:$D$12, MATCH(TRUE, EXACT(MID($C8,M$3,1), 音調表!$B$3:$B$12),0)))}
B9: 之 | C9: zi1 | D9: =IF( LEN(C9)>0, LEN(C9), "") -> 3 | E9: {=IF(E$3<>$D9, MID($C9,E$3,1), INDEX(音調表!$D$3:$D$12, MATCH(TRUE, EXACT(MID($C9,E$3,1), 音調表!$B$3:$B$12),0)))} -> z | F9: {=IF(F$3<>$D9, MID($C9,F$3,1), INDEX(音調表!$D$3:$D$12, MATCH(TRUE, EXACT(MID($C9,F$3,1), 音調表!$B$3:$B$12),0)))} -> i | G9: {=IF(G$3<>$D9, MID($C9,G$3,1), INDEX(音調表!$D$3:$D$12, MATCH(TRUE, EXACT(MID($C9,G$3,1), 音調表!$B$3:$B$12),0)))} -> ; | H9: {=IF(H$3<>$D9, MID($C9,H$3,1), INDEX(音調表!$D$3:$D$12, MATCH(TRUE, EXACT(MID($C9,H$3,1), 音調表!$B$3:$B$12),0)))} | I9: {=IF(I$3<>$D9, MID($C9,I$3,1), INDEX(音調表!$D$3:$D$12, MATCH(TRUE, EXACT(MID($C9,I$3,1), 音調表!$B$3:$B$12),0)))} | J9: {=IF(J$3<>$D9, MID($C9,J$3,1), INDEX(音調表!$D$3:$D$12, MATCH(TRUE, EXACT(MID($C9,J$3,1), 音調表!$B$3:$B$12),0)))} | K9: {=IF(K$3<>$D9, MID($C9,K$3,1), INDEX(音調表!$D$3:$D$12, MATCH(TRUE, EXACT(MID($C9,K$3,1), 音調表!$B$3:$B$12),0)))} | L9: {=IF(L$3<>$D9, MID($C9,L$3,1), INDEX(音調表!$D$3:$D$12, MATCH(TRUE, EXACT(MID($C9,L$3,1), 音調表!$B$3:$B$12),0)))} | M9: {=IF(M$3<>$D9, MID($C9,M$3,1), INDEX(音調表!$D$3:$D$12, MATCH(TRUE, EXACT(MID($C9,M$3,1), 音調表!$B$3:$B$12),0)))}
B10: 渙 | C10: huan3 | D10: =IF( LEN(C10)>0, LEN(C10), "") -> 5 | E10: {=IF(E$3<>$D10, MID($C10,E$3,1), INDEX(音調表!$D$3:$D$12, MATCH(TRUE, EXACT(MID($C10,E$3,1), 音調表!$B$3:$B$12),0)))} -> h | F10: {=IF(F$3<>$D10, MID($C10,F$3,1), INDEX(音調表!$D$3:$D$12, MATCH(TRUE, EXACT(MID($C10,F$3,1), 音調表!$B$3:$B$12),0)))} -> u | G10: {=IF(G$3<>$D10, MID($C10,G$3,1), INDEX(音調表!$D$3:$D$12, MATCH(TRUE, EXACT(MID($C10,G$3,1), 音調表!$B$3:$B$12),0)))} -> a | H10: {=IF(H$3<>$D10, MID($C10,H$3,1), INDEX(音調表!$D$3:$D$12, MATCH(TRUE, EXACT(MID($C10,H$3,1), 音調表!$B$3:$B$12),0)))} -> n | I10: {=IF(I$3<>$D10, MID($C10,I$3,1), INDEX(音調表!$D$3:$D$12, MATCH(TRUE, EXACT(MID($C10,I$3,1), 音調表!$B$3:$B$12),0)))} -> _ | J10: {=IF(J$3<>$D10, MID($C10,J$3,1), INDEX(音調表!$D$3:$D$12, MATCH(TRUE, EXACT(MID($C10,J$3,1), 音調表!$B$3:$B$12),0)))} | K10: {=IF(K$3<>$D10, MID($C10,K$3,1), INDEX(音調表!$D$3:$D$12, MATCH(TRUE, EXACT(MID($C10,K$3,1), 音調表!$B$3:$B$12),0)))} | L10: {=IF(L$3<>$D10, MID($C10,L$3,1), INDEX(音調表!$D$3:$D$12, MATCH(TRUE, EXACT(MID($C10,L$3,1), 音調表!$B$3:$B$12),0)))} | M10: {=IF(M$3<>$D10, MID($C10,M$3,1), INDEX(音調表!$D$3:$D$12, MATCH(TRUE, EXACT(MID($C10,M$3,1), 音調表!$B$3:$B$12),0)))}
D11: =IF( LEN(C11)>0, LEN(C11), "") | E11: {=IF(E$3<>$D11, MID($C11,E$3,1), INDEX(音調表!$D$3:$D$12, MATCH(TRUE, EXACT(MID($C11,E$3,1), 音調表!$B$3:$B$12),0)))} | F11: {=IF(F$3<>$D11, MID($C11,F$3,1), INDEX(音調表!$D$3:$D$12, MATCH(TRUE, EXACT(MID($C11,F$3,1), 音調表!$B$3:$B$12),0)))} | G11: {=IF(G$3<>$D11, MID($C11,G$3,1), INDEX(音調表!$D$3:$D$12, MATCH(TRUE, EXACT(MID($C11,G$3,1), 音調表!$B$3:$B$12),0)))} | H11: {=IF(H$3<>$D11, MID($C11,H$3,1), INDEX(音調表!$D$3:$D$12, MATCH(TRUE, EXACT(MID($C11,H$3,1), 音調表!$B$3:$B$12),0)))} | I11: {=IF(I$3<>$D11, MID($C11,I$3,1), INDEX(音調表!$D$3:$D$12, MATCH(TRUE, EXACT(MID($C11,I$3,1), 音調表!$B$3:$B$12),0)))} | J11: {=IF(J$3<>$D11, MID($C11,J$3,1), INDEX(音調表!$D$3:$D$12, MATCH(TRUE, EXACT(MID($C11,J$3,1), 音調表!$B$3:$B$12),0)))} | K11: {=IF(K$3<>$D11, MID($C11,K$3,1), INDEX(音調表!$D$3:$D$12, MATCH(TRUE, EXACT(MID($C11,K$3,1), 音調表!$B$3:$B$12),0)))} | L11: {=IF(L$3<>$D11, MID($C11,L$3,1), INDEX(音調表!$D$3:$D$12, MATCH(TRUE, EXACT(MID($C11,L$3,1), 音調表!$B$3:$B$12),0)))} | M11: {=IF(M$3<>$D11, MID($C11,M$3,1), INDEX(音調表!$D$3:$D$12, MATCH(TRUE, EXACT(MID($C11,M$3,1), 音調表!$B$3:$B$12),0)))}
B12: 黄 | C12: hong5 | D12: =IF( LEN(C12)>0, LEN(C12), "") -> 5 | E12: {=IF(E$3<>$D12, MID($C12,E$3,1), INDEX(音調表!$D$3:$D$12, MATCH(TRUE, EXACT(MID($C12,E$3,1), 音調表!$B$3:$B$12),0)))} -> h | F12: {=IF(F$3<>$D12, MID($C12,F$3,1), INDEX(音調表!$D$3:$D$12, MATCH(TRUE, EXACT(MID($C12,F$3,1), 音調表!$B$3:$B$12),0)))} -> o | G12: {=IF(G$3<>$D12, MID($C12,G$3,1), INDEX(音調表!$D$3:$D$12, MATCH(TRUE, EXACT(MID($C12,G$3,1), 音調表!$B$3:$B$12),0)))} -> n | H12: {=IF(H$3<>$D12, MID($C12,H$3,1), INDEX(音調表!$D$3:$D$12, MATCH(TRUE, EXACT(MID($C12,H$3,1), 音調表!$B$3:$B$12),0)))} -> g | I12: {=IF(I$3<>$D12, MID($C12,I$3,1), INDEX(音調表!$D$3:$D$12, MATCH(TRUE, EXACT(MID($C12,I$3,1), 音調表!$B$3:$B$12),0)))} -> / | J12: {=IF(J$3<>$D12, MID($C12,J$3,1), INDEX(音調表!$D$3:$D$12, MATCH(TRUE, EXACT(MID($C12,J$3,1), 音調表!$B$3:$B$12),0)))} | K12: {=IF(K$3<>$D12, MID($C12,K$3,1), INDEX(音調表!$D$3:$D$12, MATCH(TRUE, EXACT(MID($C12,K$3,1), 音調表!$B$3:$B$12),0)))} | L12: {=IF(L$3<>$D12, MID($C12,L$3,1), INDEX(音調表!$D$3:$D$12, MATCH(TRUE, EXACT(MID($C12,L$3,1), 音調表!$B$3:$B$12),0)))} | M12: {=IF(M$3<>$D12, MID($C12,M$3,1), INDEX(音調表!$D$3:$D$12, MATCH(TRUE, EXACT(MID($C12,M$3,1), 音調表!$B$3:$B$12),0)))}
B13: 河 | C13: ho5 | D13: =IF( LEN(C13)>0, LEN(C13), "") -> 3 | E13: {=IF(E$3<>$D13, MID($C13,E$3,1), INDEX(音調表!$D$3:$D$12, MATCH(TRUE, EXACT(MID($C13,E$3,1), 音調表!$B$3:$B$12),0)))} -> h | F13: {=IF(F$3<>$D13, MID($C13,F$3,1), INDEX(音調表!$D$3:$D$12, MATCH(TRUE, EXACT(MID($C13,F$3,1), 音調表!$B$3:$B$12),0)))} -> o | G13: {=IF(G$3<>$D13, MID($C13,G$3,1), INDEX(音調表!$D$3:$D$12, MATCH(TRUE, EXACT(MID($C13,G$3,1), 音調表!$B$3:$B$12),0)))} -> / | H13: {=IF(H$3<>$D13, MID($C13,H$3,1), INDEX(音調表!$D$3:$D$12, MATCH(TRUE, EXACT(MID($C13,H$3,1), 音調表!$B$3:$B$12),0)))} | I13: {=IF(I$3<>$D13, MID($C13,I$3,1), INDEX(音調表!$D$3:$D$12, MATCH(TRUE, EXACT(MID($C13,I$3,1), 音調表!$B$3:$B$12),0)))} | J13: {=IF(J$3<>$D13, MID($C13,J$3,1), INDEX(音調表!$D$3:$D$12, MATCH(TRUE, EXACT(MID($C13,J$3,1), 音調表!$B$3:$B$12),0)))} | K13: {=IF(K$3<>$D13, MID($C13,K$3,1), INDEX(音調表!$D$3:$D$12, MATCH(TRUE, EXACT(MID($C13,K$3,1), 音調表!$B$3:$B$12),0)))} | L13: {=IF(L$3<>$D13, MID($C13,L$3,1), INDEX(音調表!$D$3:$D$12, MATCH(TRUE, EXACT(MID($C13,L$3,1), 音調表!$B$3:$B$12),0)))} | M13: {=IF(M$3<>$D13, MID($C13,M$3,1), INDEX(音調表!$D$3:$D$12, MATCH(TRUE, EXACT(MID($C13,M$3,1), 音調表!$B$3:$B$12),0)))}
B14: 遠 | C14: uan2 | D14: =IF( LEN(C14)>0, LEN(C14), "") -> 4 | E14: {=IF(E$3<>$D14, MID($C14,E$3,1), INDEX(音調表!$D$3:$D$12, MATCH(TRUE, EXACT(MID($C14,E$3,1), 音調表!$B$3:$B$12),0)))} -> u | F14: {=IF(F$3<>$D14, MID($C14,F$3,1), INDEX(音調表!$D$3:$D$12, MATCH(TRUE, EXACT(MID($C14,F$3,1), 音調表!$B$3:$B$12),0)))} -> a | G14: {=IF(G$3<>$D14, MID($C14,G$3,1), INDEX(音調表!$D$3:$D$12, MATCH(TRUE, EXACT(MID($C14,G$3,1), 音調表!$B$3:$B$12),0)))} -> n | H14: {=IF(H$3<>$D14, MID($C14,H$3,1), INDEX(音調表!$D$3:$D$12, MATCH(TRUE, EXACT(MID($C14,H$3,1), 音調表!$B$3:$B$12),0)))} -> \ | I14: {=IF(I$3<>$D14, MID($C14,I$3,1), INDEX(音調表!$D$3:$D$12, MATCH(TRUE, EXACT(MID($C14,I$3,1), 音調表!$B$3:$B$12),0)))} | J14: {=IF(J$3<>$D14, MID($C14,J$3,1), INDEX(音調表!$D$3:$D$12, MATCH(TRUE, EXACT(MID($C14,J$3,1), 音調表!$B$3:$B$12),0)))} | K14: {=IF(K$3<>$D14, MID($C14,K$3,1), INDEX(音調表!$D$3:$D$12, MATCH(TRUE, EXACT(MID($C14,K$3,1), 音調表!$B$3:$B$12),0)))} | L14: {=IF(L$3<>$D14, MID($C14,L$3,1), INDEX(音調表!$D$3:$D$12, MATCH(TRUE, EXACT(MID($C14,L$3,1), 音調表!$B$3:$B$12),0)))} | M14: {=IF(M$3<>$D14, MID($C14,M$3,1), INDEX(音調表!$D$3:$D$12, MATCH(TRUE, EXACT(MID($C14,M$3,1), 音調表!$B$3:$B$12),0)))}
B15: 上 | C15: siong2 | D15: =IF( LEN(C15)>0, LEN(C15), "") -> 6 | E15: {=IF(E$3<>$D15, MID($C15,E$3,1), INDEX(音調表!$D$3:$D$12, MATCH(TRUE, EXACT(MID($C15,E$3,1), 音調表!$B$3:$B$12),0)))} -> s | F15: {=IF(F$3<>$D15, MID($C15,F$3,1), INDEX(音調表!$D$3:$D$12, MATCH(TRUE, EXACT(MID($C15,F$3,1), 音調表!$B$3:$B$12),0)))} -> i | G15: {=IF(G$3<>$D15, MID($C15,G$3,1), INDEX(音調表!$D$3:$D$12, MATCH(TRUE, EXACT(MID($C15,G$3,1), 音調表!$B$3:$B$12),0)))} -> o | H15: {=IF(H$3<>$D15, MID($C15,H$3,1), INDEX(音調表!$D$3:$D$12, MATCH(TRUE, EXACT(MID($C15,H$3,1), 音調表!$B$3:$B$12),0)))} -> n | I15: {=IF(I$3<>$D15, MID($C15,I$3,1), INDEX(音調表!$D$3:$D$12, MATCH(TRUE, EXACT(MID($C15,I$3,1), 音調表!$B$3:$B$12),0)))} -> g | J15: {=IF(J$3<>$D15, MID($C15,J$3,1), INDEX(音調表!$D$3:$D$12, MATCH(TRUE, EXACT(MID($C15,J$3,1), 音調表!$B$3:$B$12),0)))} -> \ | K15: {=IF(K$3<>$D15, MID($C15,K$3,1), INDEX(音調表!$D$3:$D$12, MATCH(TRUE, EXACT(MID($C15,K$3,1), 音調表!$B$3:$B$12),0)))} | L15: {=IF(L$3<>$D15, MID($C15,L$3,1), INDEX(音調表!$D$3:$D$12, MATCH(TRUE, EXACT(MID($C15,L$3,1), 音調表!$B$3:$B$12),0)))} | M15: {=IF(M$3<>$D15, MID($C15,M$3,1), INDEX(音調表!$D$3:$D$12, MATCH(TRUE, EXACT(MID($C15,M$3,1), 音調表!$B$3:$B$12),0)))}
B16: 白 | C16: pik8 | D16: =IF( LEN(C16)>0, LEN(C16), "") -> 4 | E16: {=IF(E$3<>$D16, MID($C16,E$3,1), INDEX(音調表!$D$3:$D$12, MATCH(TRUE, EXACT(MID($C16,E$3,1), 音調表!$B$3:$B$12),0)))} -> p | F16: {=IF(F$3<>$D16, MID($C16,F$3,1), INDEX(音調表!$D$3:$D$12, MATCH(TRUE, EXACT(MID($C16,F$3,1), 音調表!$B$3:$B$12),0)))} -> i | G16: {=IF(G$3<>$D16, MID($C16,G$3,1), INDEX(音調表!$D$3:$D$12, MATCH(TRUE, EXACT(MID($C16,G$3,1), 音調表!$B$3:$B$12),0)))} -> k | H16: {=IF(H$3<>$D16, MID($C16,H$3,1), INDEX(音調表!$D$3:$D$12, MATCH(TRUE, EXACT(MID($C16,H$3,1), 音調表!$B$3:$B$12),0)))} -> ] | I16: {=IF(I$3<>$D16, MID($C16,I$3,1), INDEX(音調表!$D$3:$D$12, MATCH(TRUE, EXACT(MID($C16,I$3,1), 音調表!$B$3:$B$12),0)))} | J16: {=IF(J$3<>$D16, MID($C16,J$3,1), INDEX(音調表!$D$3:$D$12, MATCH(TRUE, EXACT(MID($C16,J$3,1), 音調表!$B$3:$B$12),0)))} | K16: {=IF(K$3<>$D16, MID($C16,K$3,1), INDEX(音調表!$D$3:$D$12, MATCH(TRUE, EXACT(MID($C16,K$3,1), 音調表!$B$3:$B$12),0)))} | L16: {=IF(L$3<>$D16, MID($C16,L$3,1), INDEX(音調表!$D$3:$D$12, MATCH(TRUE, EXACT(MID($C16,L$3,1), 音調表!$B$3:$B$12),0)))} | M16: {=IF(M$3<>$D16, MID($C16,M$3,1), INDEX(音調表!$D$3:$D$12, MATCH(TRUE, EXACT(MID($C16,M$3,1), 音調表!$B$3:$B$12),0)))}
B17: 雲 | C17: hun5 | D17: =IF( LEN(C17)>0, LEN(C17), "") -> 4 | E17: {=IF(E$3<>$D17, MID($C17,E$3,1), INDEX(音調表!$D$3:$D$12, MATCH(TRUE, EXACT(MID($C17,E$3,1), 音調表!$B$3:$B$12),0)))} -> h | F17: {=IF(F$3<>$D17, MID($C17,F$3,1), INDEX(音調表!$D$3:$D$12, MATCH(TRUE, EXACT(MID($C17,F$3,1), 音調表!$B$3:$B$12),0)))} -> u | G17: {=IF(G$3<>$D17, MID($C17,G$3,1), INDEX(音調表!$D$3:$D$12, MATCH(TRUE, EXACT(MID($C17,G$3,1), 音調表!$B$3:$B$12),0)))} -> n | H17: {=IF(H$3<>$D17, MID($C17,H$3,1), INDEX(音調表!$D$3:$D$12, MATCH(TRUE, EXACT(MID($C17,H$3,1), 音調表!$B$3:$B$12),0)))} -> / | I17: {=IF(I$3<>$D17, MID($C17,I$3,1), INDEX(音調表!$D$3:$D$12, MATCH(TRUE, EXACT(MID($C17,I$3,1), 音調表!$B$3:$B$12),0)))} | J17: {=IF(J$3<>$D17, MID($C17,J$3,1), INDEX(音調表!$D$3:$D$12, MATCH(TRUE, EXACT(MID($C17,J$3,1), 音調表!$B$3:$B$12),0)))} | K17: {=IF(K$3<>$D17, MID($C17,K$3,1), INDEX(音調表!$D$3:$D$12, MATCH(TRUE, EXACT(MID($C17,K$3,1), 音調表!$B$3:$B$12),0)))} | L17: {=IF(L$3<>$D17, MID($C17,L$3,1), INDEX(音調表!$D$3:$D$12, MATCH(TRUE, EXACT(MID($C17,L$3,1), 音調表!$B$3:$B$12),0)))} | M17: {=IF(M$3<>$D17, MID($C17,M$3,1), INDEX(音調表!$D$3:$D$12, MATCH(TRUE, EXACT(MID($C17,M$3,1), 音調表!$B$3:$B$12),0)))}
B18: 間 | C18: kan1 | D18: =IF( LEN(C18)>0, LEN(C18), "") -> 4 | E18: {=IF(E$3<>$D18, MID($C18,E$3,1), INDEX(音調表!$D$3:$D$12, MATCH(TRUE, EXACT(MID($C18,E$3,1), 音調表!$B$3:$B$12),0)))} -> k | F18: {=IF(F$3<>$D18, MID($C18,F$3,1), INDEX(音調表!$D$3:$D$12, MATCH(TRUE, EXACT(MID($C18,F$3,1), 音調表!$B$3:$B$12),0)))} -> a | G18: {=IF(G$3<>$D18, MID($C18,G$3,1), INDEX(音調表!$D$3:$D$12, MATCH(TRUE, EXACT(MID($C18,G$3,1), 音調表!$B$3:$B$12),0)))} -> n | H18: {=IF(H$3<>$D18, MID($C18,H$3,1), INDEX(音調表!$D$3:$D$12, MATCH(TRUE, EXACT(MID($C18,H$3,1), 音調表!$B$3:$B$12),0)))} -> ; | I18: {=IF(I$3<>$D18, MID($C18,I$3,1), INDEX(音調表!$D$3:$D$12, MATCH(TRUE, EXACT(MID($C18,I$3,1), 音調表!$B$3:$B$12),0)))} | J18: {=IF(J$3<>$D18, MID($C18,J$3,1), INDEX(音調表!$D$3:$D$12, MATCH(TRUE, EXACT(MID($C18,J$3,1), 音調表!$B$3:$B$12),0)))} | K18: {=IF(K$3<>$D18, MID($C18,K$3,1), INDEX(音調表!$D$3:$D$12, MATCH(TRUE, EXACT(MID($C18,K$3,1), 音調表!$B$3:$B$12),0)))} | L18: {=IF(L$3<>$D18, MID($C18,L$3,1), INDEX(音調表!$D$3:$D$12, MATCH(TRUE, EXACT(MID($C18,L$3,1), 音調表!$B$3:$B$12),0)))} | M18: {=IF(M$3<>$D18, MID($C18,M$3,1), INDEX(音調表!$D$3:$D$12, MATCH(TRUE, EXACT(MID($C18,M$3,1), 音調表!$B$3:$B$12),0)))}
B19: ， | D19: =IF( LEN(C19)>0, LEN(C19), "") | E19: ` | F19: , | G19: {=IF(G$3<>$D19, MID($C19,G$3,1), INDEX(音調表!$D$3:$D$12, MATCH(TRUE, EXACT(MID($C19,G$3,1), 音調表!$B$3:$B$12),0)))} | H19: {=IF(H$3<>$D19, MID($C19,H$3,1), INDEX(音調表!$D$3:$D$12, MATCH(TRUE, EXACT(MID($C19,H$3,1), 音調表!$B$3:$B$12),0)))} | I19: {=IF(I$3<>$D19, MID($C19,I$3,1), INDEX(音調表!$D$3:$D$12, MATCH(TRUE, EXACT(MID($C19,I$3,1), 音調表!$B$3:$B$12),0)))} | J19: {=IF(J$3<>$D19, MID($C19,J$3,1), INDEX(音調表!$D$3:$D$12, MATCH(TRUE, EXACT(MID($C19,J$3,1), 音調表!$B$3:$B$12),0)))} | K19: {=IF(K$3<>$D19, MID($C19,K$3,1), INDEX(音調表!$D$3:$D$12, MATCH(TRUE, EXACT(MID($C19,K$3,1), 音調表!$B$3:$B$12),0)))} | L19: {=IF(L$3<>$D19, MID($C19,L$3,1), INDEX(音調表!$D$3:$D$12, MATCH(TRUE, EXACT(MID($C19,L$3,1), 音調表!$B$3:$B$12),0)))} | M19: {=IF(M$3<>$D19, MID($C19,M$3,1), INDEX(音調表!$D$3:$D$12, MATCH(TRUE, EXACT(MID($C19,M$3,1), 音調表!$B$3:$B$12),0)))}
B20: 一 | C20: it4 | D20: =IF( LEN(C20)>0, LEN(C20), "") -> 3 | E20: {=IF(E$3<>$D20, MID($C20,E$3,1), INDEX(音調表!$D$3:$D$12, MATCH(TRUE, EXACT(MID($C20,E$3,1), 音調表!$B$3:$B$12),0)))} -> i | F20: {=IF(F$3<>$D20, MID($C20,F$3,1), INDEX(音調表!$D$3:$D$12, MATCH(TRUE, EXACT(MID($C20,F$3,1), 音調表!$B$3:$B$12),0)))} -> t | G20: {=IF(G$3<>$D20, MID($C20,G$3,1), INDEX(音調表!$D$3:$D$12, MATCH(TRUE, EXACT(MID($C20,G$3,1), 音調表!$B$3:$B$12),0)))} -> [ | H20: {=IF(H$3<>$D20, MID($C20,H$3,1), INDEX(音調表!$D$3:$D$12, MATCH(TRUE, EXACT(MID($C20,H$3,1), 音調表!$B$3:$B$12),0)))} | I20: {=IF(I$3<>$D20, MID($C20,I$3,1), INDEX(音調表!$D$3:$D$12, MATCH(TRUE, EXACT(MID($C20,I$3,1), 音調表!$B$3:$B$12),0)))} | J20: {=IF(J$3<>$D20, MID($C20,J$3,1), INDEX(音調表!$D$3:$D$12, MATCH(TRUE, EXACT(MID($C20,J$3,1), 音調表!$B$3:$B$12),0)))} | K20: {=IF(K$3<>$D20, MID($C20,K$3,1), INDEX(音調表!$D$3:$D$12, MATCH(TRUE, EXACT(MID($C20,K$3,1), 音調表!$B$3:$B$12),0)))} | L20: {=IF(L$3<>$D20, MID($C20,L$3,1), INDEX(音調表!$D$3:$D$12, MATCH(TRUE, EXACT(MID($C20,L$3,1), 音調表!$B$3:$B$12),0)))} | M20: {=IF(M$3<>$D20, MID($C20,M$3,1), INDEX(音調表!$D$3:$D$12, MATCH(TRUE, EXACT(MID($C20,M$3,1), 音調表!$B$3:$B$12),0)))}
B21: 片 | C21: phian3 | D21: =IF( LEN(C21)>0, LEN(C21), "") -> 6 | E21: {=IF(E$3<>$D21, MID($C21,E$3,1), INDEX(音調表!$D$3:$D$12, MATCH(TRUE, EXACT(MID($C21,E$3,1), 音調表!$B$3:$B$12),0)))} -> p | F21: {=IF(F$3<>$D21, MID($C21,F$3,1), INDEX(音調表!$D$3:$D$12, MATCH(TRUE, EXACT(MID($C21,F$3,1), 音調表!$B$3:$B$12),0)))} -> h | G21: {=IF(G$3<>$D21, MID($C21,G$3,1), INDEX(音調表!$D$3:$D$12, MATCH(TRUE, EXACT(MID($C21,G$3,1), 音調表!$B$3:$B$12),0)))} -> i | H21: {=IF(H$3<>$D21, MID($C21,H$3,1), INDEX(音調表!$D$3:$D$12, MATCH(TRUE, EXACT(MID($C21,H$3,1), 音調表!$B$3:$B$12),0)))} -> a | I21: {=IF(I$3<>$D21, MID($C21,I$3,1), INDEX(音調表!$D$3:$D$12, MATCH(TRUE, EXACT(MID($C21,I$3,1), 音調表!$B$3:$B$12),0)))} -> n | J21: {=IF(J$3<>$D21, MID($C21,J$3,1), INDEX(音調表!$D$3:$D$12, MATCH(TRUE, EXACT(MID($C21,J$3,1), 音調表!$B$3:$B$12),0)))} -> _ | K21: {=IF(K$3<>$D21, MID($C21,K$3,1), INDEX(音調表!$D$3:$D$12, MATCH(TRUE, EXACT(MID($C21,K$3,1), 音調表!$B$3:$B$12),0)))} | L21: {=IF(L$3<>$D21, MID($C21,L$3,1), INDEX(音調表!$D$3:$D$12, MATCH(TRUE, EXACT(MID($C21,L$3,1), 音調表!$B$3:$B$12),0)))} | M21: {=IF(M$3<>$D21, MID($C21,M$3,1), INDEX(音調表!$D$3:$D$12, MATCH(TRUE, EXACT(MID($C21,M$3,1), 音調表!$B$3:$B$12),0)))}
B22: 孤 | C22: koo1 | D22: =IF( LEN(C22)>0, LEN(C22), "") -> 4 | E22: {=IF(E$3<>$D22, MID($C22,E$3,1), INDEX(音調表!$D$3:$D$12, MATCH(TRUE, EXACT(MID($C22,E$3,1), 音調表!$B$3:$B$12),0)))} -> k | F22: {=IF(F$3<>$D22, MID($C22,F$3,1), INDEX(音調表!$D$3:$D$12, MATCH(TRUE, EXACT(MID($C22,F$3,1), 音調表!$B$3:$B$12),0)))} -> o | G22: {=IF(G$3<>$D22, MID($C22,G$3,1), INDEX(音調表!$D$3:$D$12, MATCH(TRUE, EXACT(MID($C22,G$3,1), 音調表!$B$3:$B$12),0)))} -> o | H22: {=IF(H$3<>$D22, MID($C22,H$3,1), INDEX(音調表!$D$3:$D$12, MATCH(TRUE, EXACT(MID($C22,H$3,1), 音調表!$B$3:$B$12),0)))} -> ; | I22: {=IF(I$3<>$D22, MID($C22,I$3,1), INDEX(音調表!$D$3:$D$12, MATCH(TRUE, EXACT(MID($C22,I$3,1), 音調表!$B$3:$B$12),0)))} | J22: {=IF(J$3<>$D22, MID($C22,J$3,1), INDEX(音調表!$D$3:$D$12, MATCH(TRUE, EXACT(MID($C22,J$3,1), 音調表!$B$3:$B$12),0)))} | K22: {=IF(K$3<>$D22, MID($C22,K$3,1), INDEX(音調表!$D$3:$D$12, MATCH(TRUE, EXACT(MID($C22,K$3,1), 音調表!$B$3:$B$12),0)))} | L22: {=IF(L$3<>$D22, MID($C22,L$3,1), INDEX(音調表!$D$3:$D$12, MATCH(TRUE, EXACT(MID($C22,L$3,1), 音調表!$B$3:$B$12),0)))} | M22: {=IF(M$3<>$D22, MID($C22,M$3,1), INDEX(音調表!$D$3:$D$12, MATCH(TRUE, EXACT(MID($C22,M$3,1), 音調表!$B$3:$B$12),0)))}
B23: 城 | C23: sing5 | D23: =IF( LEN(C23)>0, LEN(C23), "") -> 5 | E23: {=IF(E$3<>$D23, MID($C23,E$3,1), INDEX(音調表!$D$3:$D$12, MATCH(TRUE, EXACT(MID($C23,E$3,1), 音調表!$B$3:$B$12),0)))} -> s | F23: {=IF(F$3<>$D23, MID($C23,F$3,1), INDEX(音調表!$D$3:$D$12, MATCH(TRUE, EXACT(MID($C23,F$3,1), 音調表!$B$3:$B$12),0)))} -> i | G23: {=IF(G$3<>$D23, MID($C23,G$3,1), INDEX(音調表!$D$3:$D$12, MATCH(TRUE, EXACT(MID($C23,G$3,1), 音調表!$B$3:$B$12),0)))} -> n | H23: {=IF(H$3<>$D23, MID($C23,H$3,1), INDEX(音調表!$D$3:$D$12, MATCH(TRUE, EXACT(MID($C23,H$3,1), 音調表!$B$3:$B$12),0)))} -> g | I23: {=IF(I$3<>$D23, MID($C23,I$3,1), INDEX(音調表!$D$3:$D$12, MATCH(TRUE, EXACT(MID($C23,I$3,1), 音調表!$B$3:$B$12),0)))} -> / | J23: {=IF(J$3<>$D23, MID($C23,J$3,1), INDEX(音調表!$D$3:$D$12, MATCH(TRUE, EXACT(MID($C23,J$3,1), 音調表!$B$3:$B$12),0)))} | K23: {=IF(K$3<>$D23, MID($C23,K$3,1), INDEX(音調表!$D$3:$D$12, MATCH(TRUE, EXACT(MID($C23,K$3,1), 音調表!$B$3:$B$12),0)))} | L23: {=IF(L$3<>$D23, MID($C23,L$3,1), INDEX(音調表!$D$3:$D$12, MATCH(TRUE, EXACT(MID($C23,L$3,1), 音調表!$B$3:$B$12),0)))} | M23: {=IF(M$3<>$D23, MID($C23,M$3,1), INDEX(音調表!$D$3:$D$12, MATCH(TRUE, EXACT(MID($C23,M$3,1), 音調表!$B$3:$B$12),0)))}
B24: 萬 | C24: ban7 | D24: =IF( LEN(C24)>0, LEN(C24), "") -> 4 | E24: {=IF(E$3<>$D24, MID($C24,E$3,1), INDEX(音調表!$D$3:$D$12, MATCH(TRUE, EXACT(MID($C24,E$3,1), 音調表!$B$3:$B$12),0)))} -> b | F24: {=IF(F$3<>$D24, MID($C24,F$3,1), INDEX(音調表!$D$3:$D$12, MATCH(TRUE, EXACT(MID($C24,F$3,1), 音調表!$B$3:$B$12),0)))} -> a | G24: {=IF(G$3<>$D24, MID($C24,G$3,1), INDEX(音調表!$D$3:$D$12, MATCH(TRUE, EXACT(MID($C24,G$3,1), 音調表!$B$3:$B$12),0)))} -> n | H24: {=IF(H$3<>$D24, MID($C24,H$3,1), INDEX(音調表!$D$3:$D$12, MATCH(TRUE, EXACT(MID($C24,H$3,1), 音調表!$B$3:$B$12),0)))} -> - | I24: {=IF(I$3<>$D24, MID($C24,I$3,1), INDEX(音調表!$D$3:$D$12, MATCH(TRUE, EXACT(MID($C24,I$3,1), 音調表!$B$3:$B$12),0)))} | J24: {=IF(J$3<>$D24, MID($C24,J$3,1), INDEX(音調表!$D$3:$D$12, MATCH(TRUE, EXACT(MID($C24,J$3,1), 音調表!$B$3:$B$12),0)))} | K24: {=IF(K$3<>$D24, MID($C24,K$3,1), INDEX(音調表!$D$3:$D$12, MATCH(TRUE, EXACT(MID($C24,K$3,1), 音調表!$B$3:$B$12),0)))} | L24: {=IF(L$3<>$D24, MID($C24,L$3,1), INDEX(音調表!$D$3:$D$12, MATCH(TRUE, EXACT(MID($C24,L$3,1), 音調表!$B$3:$B$12),0)))} | M24: {=IF(M$3<>$D24, MID($C24,M$3,1), INDEX(音調表!$D$3:$D$12, MATCH(TRUE, EXACT(MID($C24,M$3,1), 音調表!$B$3:$B$12),0)))}
B25: 仞 | C25: jin7 | D25: =IF( LEN(C25)>0, LEN(C25), "") -> 4 | E25: {=IF(E$3<>$D25, MID($C25,E$3,1), INDEX(音調表!$D$3:$D$12, MATCH(TRUE, EXACT(MID($C25,E$3,1), 音調表!$B$3:$B$12),0)))} -> j | F25: {=IF(F$3<>$D25, MID($C25,F$3,1), INDEX(音調表!$D$3:$D$12, MATCH(TRUE, EXACT(MID($C25,F$3,1), 音調表!$B$3:$B$12),0)))} -> i | G25: {=IF(G$3<>$D25, MID($C25,G$3,1), INDEX(音調表!$D$3:$D$12, MATCH(TRUE, EXACT(MID($C25,G$3,1), 音調表!$B$3:$B$12),0)))} -> n | H25: {=IF(H$3<>$D25, MID($C25,H$3,1), INDEX(音調表!$D$3:$D$12, MATCH(TRUE, EXACT(MID($C25,H$3,1), 音調表!$B$3:$B$12),0)))} -> - | I25: {=IF(I$3<>$D25, MID($C25,I$3,1), INDEX(音調表!$D$3:$D$12, MATCH(TRUE, EXACT(MID($C25,I$3,1), 音調表!$B$3:$B$12),0)))} | J25: {=IF(J$3<>$D25, MID($C25,J$3,1), INDEX(音調表!$D$3:$D$12, MATCH(TRUE, EXACT(MID($C25,J$3,1), 音調表!$B$3:$B$12),0)))} | K25: {=IF(K$3<>$D25, MID($C25,K$3,1), INDEX(音調表!$D$3:$D$12, MATCH(TRUE, EXACT(MID($C25,K$3,1), 音調表!$B$3:$B$12),0)))} | L25: {=IF(L$3<>$D25, MID($C25,L$3,1), INDEX(音調表!$D$3:$D$12, MATCH(TRUE, EXACT(MID($C25,L$3,1), 音調表!$B$3:$B$12),0)))} | M25: {=IF(M$3<>$D25, MID($C25,M$3,1), INDEX(音調表!$D$3:$D$12, MATCH(TRUE, EXACT(MID($C25,M$3,1), 音調表!$B$3:$B$12),0)))}
B26: 山 | C26: san1 | D26: =IF( LEN(C26)>0, LEN(C26), "") -> 4 | E26: {=IF(E$3<>$D26, MID($C26,E$3,1), INDEX(音調表!$D$3:$D$12, MATCH(TRUE, EXACT(MID($C26,E$3,1), 音調表!$B$3:$B$12),0)))} -> s | F26: {=IF(F$3<>$D26, MID($C26,F$3,1), INDEX(音調表!$D$3:$D$12, MATCH(TRUE, EXACT(MID($C26,F$3,1), 音調表!$B$3:$B$12),0)))} -> a | G26: {=IF(G$3<>$D26, MID($C26,G$3,1), INDEX(音調表!$D$3:$D$12, MATCH(TRUE, EXACT(MID($C26,G$3,1), 音調表!$B$3:$B$12),0)))} -> n | H26: {=IF(H$3<>$D26, MID($C26,H$3,1), INDEX(音調表!$D$3:$D$12, MATCH(TRUE, EXACT(MID($C26,H$3,1), 音調表!$B$3:$B$12),0)))} -> ; | I26: {=IF(I$3<>$D26, MID($C26,I$3,1), INDEX(音調表!$D$3:$D$12, MATCH(TRUE, EXACT(MID($C26,I$3,1), 音調表!$B$3:$B$12),0)))} | J26: {=IF(J$3<>$D26, MID($C26,J$3,1), INDEX(音調表!$D$3:$D$12, MATCH(TRUE, EXACT(MID($C26,J$3,1), 音調表!$B$3:$B$12),0)))} | K26: {=IF(K$3<>$D26, MID($C26,K$3,1), INDEX(音調表!$D$3:$D$12, MATCH(TRUE, EXACT(MID($C26,K$3,1), 音調表!$B$3:$B$12),0)))} | L26: {=IF(L$3<>$D26, MID($C26,L$3,1), INDEX(音調表!$D$3:$D$12, MATCH(TRUE, EXACT(MID($C26,L$3,1), 音調表!$B$3:$B$12),0)))} | M26: {=IF(M$3<>$D26, MID($C26,M$3,1), INDEX(音調表!$D$3:$D$12, MATCH(TRUE, EXACT(MID($C26,M$3,1), 音調表!$B$3:$B$12),0)))}
B27: 。 | D27: =IF( LEN(C27)>0, LEN(C27), "") | E27: ` | F27: . | G27: {=IF(G$3<>$D27, MID($C27,G$3,1), INDEX(音調表!$D$3:$D$12, MATCH(TRUE, EXACT(MID($C27,G$3,1), 音調表!$B$3:$B$12),0)))} | H27: {=IF(H$3<>$D27, MID($C27,H$3,1), INDEX(音調表!$D$3:$D$12, MATCH(TRUE, EXACT(MID($C27,H$3,1), 音調表!$B$3:$B$12),0)))} | I27: {=IF(I$3<>$D27, MID($C27,I$3,1), INDEX(音調表!$D$3:$D$12, MATCH(TRUE, EXACT(MID($C27,I$3,1), 音調表!$B$3:$B$12),0)))} | J27: {=IF(J$3<>$D27, MID($C27,J$3,1), INDEX(音調表!$D$3:$D$12, MATCH(TRUE, EXACT(MID($C27,J$3,1), 音調表!$B$3:$B$12),0)))} | K27: {=IF(K$3<>$D27, MID($C27,K$3,1), INDEX(音調表!$D$3:$D$12, MATCH(TRUE, EXACT(MID($C27,K$3,1), 音調表!$B$3:$B$12),0)))} | L27: {=IF(L$3<>$D27, MID($C27,L$3,1), INDEX(音調表!$D$3:$D$12, MATCH(TRUE, EXACT(MID($C27,L$3,1), 音調表!$B$3:$B$12),0)))} | M27: {=IF(M$3<>$D27, MID($C27,M$3,1), INDEX(音調表!$D$3:$D$12, MATCH(TRUE, EXACT(MID($C27,M$3,1), 音調表!$B$3:$B$12),0)))}
D28: =IF( LEN(C28)>0, LEN(C28), "") | E28: {=IF(E$3<>$D28, MID($C28,E$3,1), INDEX(音調表!$D$3:$D$12, MATCH(TRUE, EXACT(MID($C28,E$3,1), 音調表!$B$3:$B$12),0)))} | F28: {=IF(F$3<>$D28, MID($C28,F$3,1), INDEX(音調表!$D$3:$D$12, MATCH(TRUE, EXACT(MID($C28,F$3,1), 音調表!$B$3:$B$12),0)))} | G28: {=IF(G$3<>$D28, MID($C28,G$3,1), INDEX(音調表!$D$3:$D$12, MATCH(TRUE, EXACT(MID($C28,G$3,1), 音調表!$B$3:$B$12),0)))} | H28: {=IF(H$3<>$D28, MID($C28,H$3,1), INDEX(音調表!$D$3:$D$12, MATCH(TRUE, EXACT(MID($C28,H$3,1), 音調表!$B$3:$B$12),0)))} | I28: {=IF(I$3<>$D28, MID($C28,I$3,1), INDEX(音調表!$D$3:$D$12, MATCH(TRUE, EXACT(MID($C28,I$3,1), 音調表!$B$3:$B$12),0)))} | J28: {=IF(J$3<>$D28, MID($C28,J$3,1), INDEX(音調表!$D$3:$D$12, MATCH(TRUE, EXACT(MID($C28,J$3,1), 音調表!$B$3:$B$12),0)))} | K28: {=IF(K$3<>$D28, MID($C28,K$3,1), INDEX(音調表!$D$3:$D$12, MATCH(TRUE, EXACT(MID($C28,K$3,1), 音調表!$B$3:$B$12),0)))} | L28: {=IF(L$3<>$D28, MID($C28,L$3,1), INDEX(音調表!$D$3:$D$12, MATCH(TRUE, EXACT(MID($C28,L$3,1), 音調表!$B$3:$B$12),0)))} | M28: {=IF(M$3<>$D28, MID($C28,M$3,1), INDEX(音調表!$D$3:$D$12, MATCH(TRUE, EXACT(MID($C28,M$3,1), 音調表!$B$3:$B$12),0)))}
B29: 羌 | C29: khiang1 | D29: =IF( LEN(C29)>0, LEN(C29), "") -> 7 | E29: {=IF(E$3<>$D29, MID($C29,E$3,1), INDEX(音調表!$D$3:$D$12, MATCH(TRUE, EXACT(MID($C29,E$3,1), 音調表!$B$3:$B$12),0)))} -> k | F29: {=IF(F$3<>$D29, MID($C29,F$3,1), INDEX(音調表!$D$3:$D$12, MATCH(TRUE, EXACT(MID($C29,F$3,1), 音調表!$B$3:$B$12),0)))} -> h | G29: {=IF(G$3<>$D29, MID($C29,G$3,1), INDEX(音調表!$D$3:$D$12, MATCH(TRUE, EXACT(MID($C29,G$3,1), 音調表!$B$3:$B$12),0)))} -> i | H29: {=IF(H$3<>$D29, MID($C29,H$3,1), INDEX(音調表!$D$3:$D$12, MATCH(TRUE, EXACT(MID($C29,H$3,1), 音調表!$B$3:$B$12),0)))} -> a | I29: {=IF(I$3<>$D29, MID($C29,I$3,1), INDEX(音調表!$D$3:$D$12, MATCH(TRUE, EXACT(MID($C29,I$3,1), 音調表!$B$3:$B$12),0)))} -> n | J29: {=IF(J$3<>$D29, MID($C29,J$3,1), INDEX(音調表!$D$3:$D$12, MATCH(TRUE, EXACT(MID($C29,J$3,1), 音調表!$B$3:$B$12),0)))} -> g | K29: {=IF(K$3<>$D29, MID($C29,K$3,1), INDEX(音調表!$D$3:$D$12, MATCH(TRUE, EXACT(MID($C29,K$3,1), 音調表!$B$3:$B$12),0)))} -> ; | L29: {=IF(L$3<>$D29, MID($C29,L$3,1), INDEX(音調表!$D$3:$D$12, MATCH(TRUE, EXACT(MID($C29,L$3,1), 音調表!$B$3:$B$12),0)))} | M29: {=IF(M$3<>$D29, MID($C29,M$3,1), INDEX(音調表!$D$3:$D$12, MATCH(TRUE, EXACT(MID($C29,M$3,1), 音調表!$B$3:$B$12),0)))}
B30: 笛 | C30: tik8 | D30: =IF( LEN(C30)>0, LEN(C30), "") -> 4 | E30: {=IF(E$3<>$D30, MID($C30,E$3,1), INDEX(音調表!$D$3:$D$12, MATCH(TRUE, EXACT(MID($C30,E$3,1), 音調表!$B$3:$B$12),0)))} -> t | F30: {=IF(F$3<>$D30, MID($C30,F$3,1), INDEX(音調表!$D$3:$D$12, MATCH(TRUE, EXACT(MID($C30,F$3,1), 音調表!$B$3:$B$12),0)))} -> i | G30: {=IF(G$3<>$D30, MID($C30,G$3,1), INDEX(音調表!$D$3:$D$12, MATCH(TRUE, EXACT(MID($C30,G$3,1), 音調表!$B$3:$B$12),0)))} -> k | H30: {=IF(H$3<>$D30, MID($C30,H$3,1), INDEX(音調表!$D$3:$D$12, MATCH(TRUE, EXACT(MID($C30,H$3,1), 音調表!$B$3:$B$12),0)))} -> ] | I30: {=IF(I$3<>$D30, MID($C30,I$3,1), INDEX(音調表!$D$3:$D$12, MATCH(TRUE, EXACT(MID($C30,I$3,1), 音調表!$B$3:$B$12),0)))} | J30: {=IF(J$3<>$D30, MID($C30,J$3,1), INDEX(音調表!$D$3:$D$12, MATCH(TRUE, EXACT(MID($C30,J$3,1), 音調表!$B$3:$B$12),0)))} | K30: {=IF(K$3<>$D30, MID($C30,K$3,1), INDEX(音調表!$D$3:$D$12, MATCH(TRUE, EXACT(MID($C30,K$3,1), 音調表!$B$3:$B$12),0)))} | L30: {=IF(L$3<>$D30, MID($C30,L$3,1), INDEX(音調表!$D$3:$D$12, MATCH(TRUE, EXACT(MID($C30,L$3,1), 音調表!$B$3:$B$12),0)))} | M30: {=IF(M$3<>$D30, MID($C30,M$3,1), INDEX(音調表!$D$3:$D$12, MATCH(TRUE, EXACT(MID($C30,M$3,1), 音調表!$B$3:$B$12),0)))}
B31: 何 | C31: ho5 | D31: =IF( LEN(C31)>0, LEN(C31), "") -> 3 | E31: {=IF(E$3<>$D31, MID($C31,E$3,1), INDEX(音調表!$D$3:$D$12, MATCH(TRUE, EXACT(MID($C31,E$3,1), 音調表!$B$3:$B$12),0)))} -> h | F31: {=IF(F$3<>$D31, MID($C31,F$3,1), INDEX(音調表!$D$3:$D$12, MATCH(TRUE, EXACT(MID($C31,F$3,1), 音調表!$B$3:$B$12),0)))} -> o | G31: {=IF(G$3<>$D31, MID($C31,G$3,1), INDEX(音調表!$D$3:$D$12, MATCH(TRUE, EXACT(MID($C31,G$3,1), 音調表!$B$3:$B$12),0)))} -> / | H31: {=IF(H$3<>$D31, MID($C31,H$3,1), INDEX(音調表!$D$3:$D$12, MATCH(TRUE, EXACT(MID($C31,H$3,1), 音調表!$B$3:$B$12),0)))} | I31: {=IF(I$3<>$D31, MID($C31,I$3,1), INDEX(音調表!$D$3:$D$12, MATCH(TRUE, EXACT(MID($C31,I$3,1), 音調表!$B$3:$B$12),0)))} | J31: {=IF(J$3<>$D31, MID($C31,J$3,1), INDEX(音調表!$D$3:$D$12, MATCH(TRUE, EXACT(MID($C31,J$3,1), 音調表!$B$3:$B$12),0)))} | K31: {=IF(K$3<>$D31, MID($C31,K$3,1), INDEX(音調表!$D$3:$D$12, MATCH(TRUE, EXACT(MID($C31,K$3,1), 音調表!$B$3:$B$12),0)))} | L31: {=IF(L$3<>$D31, MID($C31,L$3,1), INDEX(音調表!$D$3:$D$12, MATCH(TRUE, EXACT(MID($C31,L$3,1), 音調表!$B$3:$B$12),0)))} | M31: {=IF(M$3<>$D31, MID($C31,M$3,1), INDEX(音調表!$D$3:$D$12, MATCH(TRUE, EXACT(MID($C31,M$3,1), 音調表!$B$3:$B$12),0)))}
B32: 須 | C32: su1 | D32: =IF( LEN(C32)>0, LEN(C32), "") -> 3 | E32: {=IF(E$3<>$D32, MID($C32,E$3,1), INDEX(音調表!$D$3:$D$12, MATCH(TRUE, EXACT(MID($C32,E$3,1), 音調表!$B$3:$B$12),0)))} -> s | F32: {=IF(F$3<>$D32, MID($C32,F$3,1), INDEX(音調表!$D$3:$D$12, MATCH(TRUE, EXACT(MID($C32,F$3,1), 音調表!$B$3:$B$12),0)))} -> u | G32: {=IF(G$3<>$D32, MID($C32,G$3,1), INDEX(音調表!$D$3:$D$12, MATCH(TRUE, EXACT(MID($C32,G$3,1), 音調表!$B$3:$B$12),0)))} -> ; | H32: {=IF(H$3<>$D32, MID($C32,H$3,1), INDEX(音調表!$D$3:$D$12, MATCH(TRUE, EXACT(MID($C32,H$3,1), 音調表!$B$3:$B$12),0)))} | I32: {=IF(I$3<>$D32, MID($C32,I$3,1), INDEX(音調表!$D$3:$D$12, MATCH(TRUE, EXACT(MID($C32,I$3,1), 音調表!$B$3:$B$12),0)))} | J32: {=IF(J$3<>$D32, MID($C32,J$3,1), INDEX(音調表!$D$3:$D$12, MATCH(TRUE, EXACT(MID($C32,J$3,1), 音調表!$B$3:$B$12),0)))} | K32: {=IF(K$3<>$D32, MID($C32,K$3,1), INDEX(音調表!$D$3:$D$12, MATCH(TRUE, EXACT(MID($C32,K$3,1), 音調表!$B$3:$B$12),0)))} | L32: {=IF(L$3<>$D32, MID($C32,L$3,1), INDEX(音調表!$D$3:$D$12, MATCH(TRUE, EXACT(MID($C32,L$3,1), 音調表!$B$3:$B$12),0)))} | M32: {=IF(M$3<>$D32, MID($C32,M$3,1), INDEX(音調表!$D$3:$D$12, MATCH(TRUE, EXACT(MID($C32,M$3,1), 音調表!$B$3:$B$12),0)))}
B33: 怨 | C33: uan3 | D33: =IF( LEN(C33)>0, LEN(C33), "") -> 4 | E33: {=IF(E$3<>$D33, MID($C33,E$3,1), INDEX(音調表!$D$3:$D$12, MATCH(TRUE, EXACT(MID($C33,E$3,1), 音調表!$B$3:$B$12),0)))} -> u | F33: {=IF(F$3<>$D33, MID($C33,F$3,1), INDEX(音調表!$D$3:$D$12, MATCH(TRUE, EXACT(MID($C33,F$3,1), 音調表!$B$3:$B$12),0)))} -> a | G33: {=IF(G$3<>$D33, MID($C33,G$3,1), INDEX(音調表!$D$3:$D$12, MATCH(TRUE, EXACT(MID($C33,G$3,1), 音調表!$B$3:$B$12),0)))} -> n | H33: {=IF(H$3<>$D33, MID($C33,H$3,1), INDEX(音調表!$D$3:$D$12, MATCH(TRUE, EXACT(MID($C33,H$3,1), 音調表!$B$3:$B$12),0)))} -> _ | I33: {=IF(I$3<>$D33, MID($C33,I$3,1), INDEX(音調表!$D$3:$D$12, MATCH(TRUE, EXACT(MID($C33,I$3,1), 音調表!$B$3:$B$12),0)))} | J33: {=IF(J$3<>$D33, MID($C33,J$3,1), INDEX(音調表!$D$3:$D$12, MATCH(TRUE, EXACT(MID($C33,J$3,1), 音調表!$B$3:$B$12),0)))} | K33: {=IF(K$3<>$D33, MID($C33,K$3,1), INDEX(音調表!$D$3:$D$12, MATCH(TRUE, EXACT(MID($C33,K$3,1), 音調表!$B$3:$B$12),0)))} | L33: {=IF(L$3<>$D33, MID($C33,L$3,1), INDEX(音調表!$D$3:$D$12, MATCH(TRUE, EXACT(MID($C33,L$3,1), 音調表!$B$3:$B$12),0)))} | M33: {=IF(M$3<>$D33, MID($C33,M$3,1), INDEX(音調表!$D$3:$D$12, MATCH(TRUE, EXACT(MID($C33,M$3,1), 音調表!$B$3:$B$12),0)))}
B34: 楊 | C34: iong5 | D34: =IF( LEN(C34)>0, LEN(C34), "") -> 5 | E34: {=IF(E$3<>$D34, MID($C34,E$3,1), INDEX(音調表!$D$3:$D$12, MATCH(TRUE, EXACT(MID($C34,E$3,1), 音調表!$B$3:$B$12),0)))} -> i | F34: {=IF(F$3<>$D34, MID($C34,F$3,1), INDEX(音調表!$D$3:$D$12, MATCH(TRUE, EXACT(MID($C34,F$3,1), 音調表!$B$3:$B$12),0)))} -> o | G34: {=IF(G$3<>$D34, MID($C34,G$3,1), INDEX(音調表!$D$3:$D$12, MATCH(TRUE, EXACT(MID($C34,G$3,1), 音調表!$B$3:$B$12),0)))} -> n | H34: {=IF(H$3<>$D34, MID($C34,H$3,1), INDEX(音調表!$D$3:$D$12, MATCH(TRUE, EXACT(MID($C34,H$3,1), 音調表!$B$3:$B$12),0)))} -> g | I34: {=IF(I$3<>$D34, MID($C34,I$3,1), INDEX(音調表!$D$3:$D$12, MATCH(TRUE, EXACT(MID($C34,I$3,1), 音調表!$B$3:$B$12),0)))} -> / | J34: {=IF(J$3<>$D34, MID($C34,J$3,1), INDEX(音調表!$D$3:$D$12, MATCH(TRUE, EXACT(MID($C34,J$3,1), 音調表!$B$3:$B$12),0)))} | K34: {=IF(K$3<>$D34, MID($C34,K$3,1), INDEX(音調表!$D$3:$D$12, MATCH(TRUE, EXACT(MID($C34,K$3,1), 音調表!$B$3:$B$12),0)))} | L34: {=IF(L$3<>$D34, MID($C34,L$3,1), INDEX(音調表!$D$3:$D$12, MATCH(TRUE, EXACT(MID($C34,L$3,1), 音調表!$B$3:$B$12),0)))} | M34: {=IF(M$3<>$D34, MID($C34,M$3,1), INDEX(音調表!$D$3:$D$12, MATCH(TRUE, EXACT(MID($C34,M$3,1), 音調表!$B$3:$B$12),0)))}
B35: 柳 | C35: liu2 | D35: =IF( LEN(C35)>0, LEN(C35), "") -> 4 | E35: {=IF(E$3<>$D35, MID($C35,E$3,1), INDEX(音調表!$D$3:$D$12, MATCH(TRUE, EXACT(MID($C35,E$3,1), 音調表!$B$3:$B$12),0)))} -> l | F35: {=IF(F$3<>$D35, MID($C35,F$3,1), INDEX(音調表!$D$3:$D$12, MATCH(TRUE, EXACT(MID($C35,F$3,1), 音調表!$B$3:$B$12),0)))} -> i | G35: {=IF(G$3<>$D35, MID($C35,G$3,1), INDEX(音調表!$D$3:$D$12, MATCH(TRUE, EXACT(MID($C35,G$3,1), 音調表!$B$3:$B$12),0)))} -> u | H35: {=IF(H$3<>$D35, MID($C35,H$3,1), INDEX(音調表!$D$3:$D$12, MATCH(TRUE, EXACT(MID($C35,H$3,1), 音調表!$B$3:$B$12),0)))} -> \ | I35: {=IF(I$3<>$D35, MID($C35,I$3,1), INDEX(音調表!$D$3:$D$12, MATCH(TRUE, EXACT(MID($C35,I$3,1), 音調表!$B$3:$B$12),0)))} | J35: {=IF(J$3<>$D35, MID($C35,J$3,1), INDEX(音調表!$D$3:$D$12, MATCH(TRUE, EXACT(MID($C35,J$3,1), 音調表!$B$3:$B$12),0)))} | K35: {=IF(K$3<>$D35, MID($C35,K$3,1), INDEX(音調表!$D$3:$D$12, MATCH(TRUE, EXACT(MID($C35,K$3,1), 音調表!$B$3:$B$12),0)))} | L35: {=IF(L$3<>$D35, MID($C35,L$3,1), INDEX(音調表!$D$3:$D$12, MATCH(TRUE, EXACT(MID($C35,L$3,1), 音調表!$B$3:$B$12),0)))} | M35: {=IF(M$3<>$D35, MID($C35,M$3,1), INDEX(音調表!$D$3:$D$12, MATCH(TRUE, EXACT(MID($C35,M$3,1), 音調表!$B$3:$B$12),0)))}
B36: ， | D36: =IF( LEN(C36)>0, LEN(C36), "") | E36: ` | F36: , | G36: {=IF(G$3<>$D36, MID($C36,G$3,1), INDEX(音調表!$D$3:$D$12, MATCH(TRUE, EXACT(MID($C36,G$3,1), 音調表!$B$3:$B$12),0)))} | H36: {=IF(H$3<>$D36, MID($C36,H$3,1), INDEX(音調表!$D$3:$D$12, MATCH(TRUE, EXACT(MID($C36,H$3,1), 音調表!$B$3:$B$12),0)))} | I36: {=IF(I$3<>$D36, MID($C36,I$3,1), INDEX(音調表!$D$3:$D$12, MATCH(TRUE, EXACT(MID($C36,I$3,1), 音調表!$B$3:$B$12),0)))} | J36: {=IF(J$3<>$D36, MID($C36,J$3,1), INDEX(音調表!$D$3:$D$12, MATCH(TRUE, EXACT(MID($C36,J$3,1), 音調表!$B$3:$B$12),0)))} | K36: {=IF(K$3<>$D36, MID($C36,K$3,1), INDEX(音調表!$D$3:$D$12, MATCH(TRUE, EXACT(MID($C36,K$3,1), 音調表!$B$3:$B$12),0)))} | L36: {=IF(L$3<>$D36, MID($C36,L$3,1), INDEX(音調表!$D$3:$D$12, MATCH(TRUE, EXACT(MID($C36,L$3,1), 音調表!$B$3:$B$12),0)))} | M36: {=IF(M$3<>$D36, MID($C36,M$3,1), INDEX(音調表!$D$3:$D$12, MATCH(TRUE, EXACT(MID($C36,M$3,1), 音調表!$B$3:$B$12),0)))}
B37: 春 | C37: cun1 | D37: =IF( LEN(C37)>0, LEN(C37), "") -> 4 | E37: {=IF(E$3<>$D37, MID($C37,E$3,1), INDEX(音調表!$D$3:$D$12, MATCH(TRUE, EXACT(MID($C37,E$3,1), 音調表!$B$3:$B$12),0)))} -> c | F37: {=IF(F$3<>$D37, MID($C37,F$3,1), INDEX(音調表!$D$3:$D$12, MATCH(TRUE, EXACT(MID($C37,F$3,1), 音調表!$B$3:$B$12),0)))} -> u | G37: {=IF(G$3<>$D37, MID($C37,G$3,1), INDEX(音調表!$D$3:$D$12, MATCH(TRUE, EXACT(MID($C37,G$3,1), 音調表!$B$3:$B$12),0)))} -> n | H37: {=IF(H$3<>$D37, MID($C37,H$3,1), INDEX(音調表!$D$3:$D$12, MATCH(TRUE, EXACT(MID($C37,H$3,1), 音調表!$B$3:$B$12),0)))} -> ; | I37: {=IF(I$3<>$D37, MID($C37,I$3,1), INDEX(音調表!$D$3:$D$12, MATCH(TRUE, EXACT(MID($C37,I$3,1), 音調表!$B$3:$B$12),0)))} | J37: {=IF(J$3<>$D37, MID($C37,J$3,1), INDEX(音調表!$D$3:$D$12, MATCH(TRUE, EXACT(MID($C37,J$3,1), 音調表!$B$3:$B$12),0)))} | K37: {=IF(K$3<>$D37, MID($C37,K$3,1), INDEX(音調表!$D$3:$D$12, MATCH(TRUE, EXACT(MID($C37,K$3,1), 音調表!$B$3:$B$12),0)))} | L37: {=IF(L$3<>$D37, MID($C37,L$3,1), INDEX(音調表!$D$3:$D$12, MATCH(TRUE, EXACT(MID($C37,L$3,1), 音調表!$B$3:$B$12),0)))} | M37: {=IF(M$3<>$D37, MID($C37,M$3,1), INDEX(音調表!$D$3:$D$12, MATCH(TRUE, EXACT(MID($C37,M$3,1), 音調表!$B$3:$B$12),0)))}
B38: 風 | C38: hong1 | D38: =IF( LEN(C38)>0, LEN(C38), "") -> 5 | E38: {=IF(E$3<>$D38, MID($C38,E$3,1), INDEX(音調表!$D$3:$D$12, MATCH(TRUE, EXACT(MID($C38,E$3,1), 音調表!$B$3:$B$12),0)))} -> h | F38: {=IF(F$3<>$D38, MID($C38,F$3,1), INDEX(音調表!$D$3:$D$12, MATCH(TRUE, EXACT(MID($C38,F$3,1), 音調表!$B$3:$B$12),0)))} -> o | G38: {=IF(G$3<>$D38, MID($C38,G$3,1), INDEX(音調表!$D$3:$D$12, MATCH(TRUE, EXACT(MID($C38,G$3,1), 音調表!$B$3:$B$12),0)))} -> n | H38: {=IF(H$3<>$D38, MID($C38,H$3,1), INDEX(音調表!$D$3:$D$12, MATCH(TRUE, EXACT(MID($C38,H$3,1), 音調表!$B$3:$B$12),0)))} -> g | I38: {=IF(I$3<>$D38, MID($C38,I$3,1), INDEX(音調表!$D$3:$D$12, MATCH(TRUE, EXACT(MID($C38,I$3,1), 音調表!$B$3:$B$12),0)))} -> ; | J38: {=IF(J$3<>$D38, MID($C38,J$3,1), INDEX(音調表!$D$3:$D$12, MATCH(TRUE, EXACT(MID($C38,J$3,1), 音調表!$B$3:$B$12),0)))} | K38: {=IF(K$3<>$D38, MID($C38,K$3,1), INDEX(音調表!$D$3:$D$12, MATCH(TRUE, EXACT(MID($C38,K$3,1), 音調表!$B$3:$B$12),0)))} | L38: {=IF(L$3<>$D38, MID($C38,L$3,1), INDEX(音調表!$D$3:$D$12, MATCH(TRUE, EXACT(MID($C38,L$3,1), 音調表!$B$3:$B$12),0)))} | M38: {=IF(M$3<>$D38, MID($C38,M$3,1), INDEX(音調表!$D$3:$D$12, MATCH(TRUE, EXACT(MID($C38,M$3,1), 音調表!$B$3:$B$12),0)))}
B39: 不 | C39: put4 | D39: =IF( LEN(C39)>0, LEN(C39), "") -> 4 | E39: {=IF(E$3<>$D39, MID($C39,E$3,1), INDEX(音調表!$D$3:$D$12, MATCH(TRUE, EXACT(MID($C39,E$3,1), 音調表!$B$3:$B$12),0)))} -> p | F39: {=IF(F$3<>$D39, MID($C39,F$3,1), INDEX(音調表!$D$3:$D$12, MATCH(TRUE, EXACT(MID($C39,F$3,1), 音調表!$B$3:$B$12),0)))} -> u | G39: {=IF(G$3<>$D39, MID($C39,G$3,1), INDEX(音調表!$D$3:$D$12, MATCH(TRUE, EXACT(MID($C39,G$3,1), 音調表!$B$3:$B$12),0)))} -> t | H39: {=IF(H$3<>$D39, MID($C39,H$3,1), INDEX(音調表!$D$3:$D$12, MATCH(TRUE, EXACT(MID($C39,H$3,1), 音調表!$B$3:$B$12),0)))} -> [ | I39: {=IF(I$3<>$D39, MID($C39,I$3,1), INDEX(音調表!$D$3:$D$12, MATCH(TRUE, EXACT(MID($C39,I$3,1), 音調表!$B$3:$B$12),0)))} | J39: {=IF(J$3<>$D39, MID($C39,J$3,1), INDEX(音調表!$D$3:$D$12, MATCH(TRUE, EXACT(MID($C39,J$3,1), 音調表!$B$3:$B$12),0)))} | K39: {=IF(K$3<>$D39, MID($C39,K$3,1), INDEX(音調表!$D$3:$D$12, MATCH(TRUE, EXACT(MID($C39,K$3,1), 音調表!$B$3:$B$12),0)))} | L39: {=IF(L$3<>$D39, MID($C39,L$3,1), INDEX(音調表!$D$3:$D$12, MATCH(TRUE, EXACT(MID($C39,L$3,1), 音調表!$B$3:$B$12),0)))} | M39: {=IF(M$3<>$D39, MID($C39,M$3,1), INDEX(音調表!$D$3:$D$12, MATCH(TRUE, EXACT(MID($C39,M$3,1), 音調表!$B$3:$B$12),0)))}
B40: 度 | C40: too7 | D40: =IF( LEN(C40)>0, LEN(C40), "") -> 4 | E40: {=IF(E$3<>$D40, MID($C40,E$3,1), INDEX(音調表!$D$3:$D$12, MATCH(TRUE, EXACT(MID($C40,E$3,1), 音調表!$B$3:$B$12),0)))} -> t | F40: {=IF(F$3<>$D40, MID($C40,F$3,1), INDEX(音調表!$D$3:$D$12, MATCH(TRUE, EXACT(MID($C40,F$3,1), 音調表!$B$3:$B$12),0)))} -> o | G40: {=IF(G$3<>$D40, MID($C40,G$3,1), INDEX(音調表!$D$3:$D$12, MATCH(TRUE, EXACT(MID($C40,G$3,1), 音調表!$B$3:$B$12),0)))} -> o | H40: {=IF(H$3<>$D40, MID($C40,H$3,1), INDEX(音調表!$D$3:$D$12, MATCH(TRUE, EXACT(MID($C40,H$3,1), 音調表!$B$3:$B$12),0)))} -> - | I40: {=IF(I$3<>$D40, MID($C40,I$3,1), INDEX(音調表!$D$3:$D$12, MATCH(TRUE, EXACT(MID($C40,I$3,1), 音調表!$B$3:$B$12),0)))} | J40: {=IF(J$3<>$D40, MID($C40,J$3,1), INDEX(音調表!$D$3:$D$12, MATCH(TRUE, EXACT(MID($C40,J$3,1), 音調表!$B$3:$B$12),0)))} | K40: {=IF(K$3<>$D40, MID($C40,K$3,1), INDEX(音調表!$D$3:$D$12, MATCH(TRUE, EXACT(MID($C40,K$3,1), 音調表!$B$3:$B$12),0)))} | L40: {=IF(L$3<>$D40, MID($C40,L$3,1), INDEX(音調表!$D$3:$D$12, MATCH(TRUE, EXACT(MID($C40,L$3,1), 音調表!$B$3:$B$12),0)))} | M40: {=IF(M$3<>$D40, MID($C40,M$3,1), INDEX(音調表!$D$3:$D$12, MATCH(TRUE, EXACT(MID($C40,M$3,1), 音調表!$B$3:$B$12),0)))}
B41: 玉 | C41: giok8 | D41: =IF( LEN(C41)>0, LEN(C41), "") -> 5 | E41: {=IF(E$3<>$D41, MID($C41,E$3,1), INDEX(音調表!$D$3:$D$12, MATCH(TRUE, EXACT(MID($C41,E$3,1), 音調表!$B$3:$B$12),0)))} -> g | F41: {=IF(F$3<>$D41, MID($C41,F$3,1), INDEX(音調表!$D$3:$D$12, MATCH(TRUE, EXACT(MID($C41,F$3,1), 音調表!$B$3:$B$12),0)))} -> i | G41: {=IF(G$3<>$D41, MID($C41,G$3,1), INDEX(音調表!$D$3:$D$12, MATCH(TRUE, EXACT(MID($C41,G$3,1), 音調表!$B$3:$B$12),0)))} -> o | H41: {=IF(H$3<>$D41, MID($C41,H$3,1), INDEX(音調表!$D$3:$D$12, MATCH(TRUE, EXACT(MID($C41,H$3,1), 音調表!$B$3:$B$12),0)))} -> k | I41: {=IF(I$3<>$D41, MID($C41,I$3,1), INDEX(音調表!$D$3:$D$12, MATCH(TRUE, EXACT(MID($C41,I$3,1), 音調表!$B$3:$B$12),0)))} -> ] | J41: {=IF(J$3<>$D41, MID($C41,J$3,1), INDEX(音調表!$D$3:$D$12, MATCH(TRUE, EXACT(MID($C41,J$3,1), 音調表!$B$3:$B$12),0)))} | K41: {=IF(K$3<>$D41, MID($C41,K$3,1), INDEX(音調表!$D$3:$D$12, MATCH(TRUE, EXACT(MID($C41,K$3,1), 音調表!$B$3:$B$12),0)))} | L41: {=IF(L$3<>$D41, MID($C41,L$3,1), INDEX(音調表!$D$3:$D$12, MATCH(TRUE, EXACT(MID($C41,L$3,1), 音調表!$B$3:$B$12),0)))} | M41: {=IF(M$3<>$D41, MID($C41,M$3,1), INDEX(音調表!$D$3:$D$12, MATCH(TRUE, EXACT(MID($C41,M$3,1), 音調表!$B$3:$B$12),0)))}
...

Sheet 音調表
B2: 調號 | C2: 四聲八調 | D2: 聲調按鍵 | E2: 漢字 | F2: 台語音標 | G2: 按鍵輸入
B3: 1 | C3: 陰平(a) | D3: ; | E3: 東 | F3: tong1 | G3: tong;
B4: 2 | C4: 陰上(á) | D4: \ | E4: 黨 | F4: tong2 | G4: tong\
B5: 3 | C5: 陰去(à) | D5: _ | E5: 棟 | F5: tong3 | G5: tong_
B6: 4 | C6: 陰入(ah) | D6: [ | E6: 督 | F6: tok4 | G6: tok[
B7: 5 | C7: 陽平(â) | D7: / | E7: 同 | F7: tong5 | G7: tong/
B8: 6 | C8: 陽上(ǎ) | D8: \ | E8: 動 | F8: tong6 | G8: tong\
B9: 7 | C9: 陽去(ā) 陽去(ā) | D9: - | E9: 洞 | F9: tong7 | G9: tong-
B10: 8 | C10: 陽入(a̍h) | D10: ] | E10: 毒 | F10: tok8 | G10: tok]
B11: 0 | C11: 陰入 | D11: . | E11: 督 | F11: tok0 | G11: tok.
B12: 0 | C12: 陽入 | D12: . | E12: 毒 | F12: tok0 | G12: tok.
