Workbook
Name URL: '打字練習表 (按鍵)'!$S$46
Name URL: 按鍵位置表!$C$1
Name ver: 按鍵位置表!$J$1
Name 零聲母: Bug産生器!$L$1
Name 零聲母: 'Bug産生器 (2)'!$L$1
Name 零聲母: '打字練習表【方音符號】 (2)'!$I$1
Name 零聲母: 打字練習表【台語注音二式】!$I$1
Name 零聲母: 打字練習表【台羅拼音】!$I$1
Name 零聲母: 教材製作【方音符號】!$P$1
Name 零聲母: 打字練習表【方音符號】!$P$1

Sheet Bug産生器
B1: 聲母 | C1: 零ㄅㄆㄇㆠㄉㄊㄋㄌㄍㄎㆣㄏㄗㄘㆡㄙㄐㄑㆢㄒ | K1: 零聲母 | L1: Ø | Z1: q | AC1: Ø | AE1: 零聲母
F2: 方音符號 | Z2: 台羅拼音
B4: 漢字 | C4: 十五音 | D4: 方音符號 | E4: 台羅拼音字母 | F4: 字母 | G4: 韻母 | H4: 音調 | I4: 方音調符 | J4: 方音音調按鍵 | K4: 聲母 | L4: 含零聲母 | M4: 輸入按鍵 | N4: 鍵盤字串 | O4: 字長 | P4: 調號位置 | Q4: 鍵盤按鍵 | Z4: 字母 | AA4: 韻母 | AB4: 含零聲母 | AC4: 音調 | AD4: 聲母 | AE4: 音調按鍵 | AF4: 輸入按鍵 | AG4: 字長 | AH4: 調號位置 | AI4: 鍵盤按鍵
Q5: 1 | R5: 2 | S5: 3 | T5: 4 | U5: 5 | V5: 6 | W5: 7 | X5: 8 | AI5: 1 | AJ5: 2 | AK5: 3 | AL5: 4 | AM5: 5 | AN5: 6 | AO5: 7 | AP5: 8
B6: 做 | C6: 高五曾 | D6: =IF(LEFT($L6)="Ø",SUBSTITUTE($L6, "Ø", ""), $L6) -> ㄗㄜˊ | E6: =_xlfn.CONCAT(AD6,AA6,AC6) -> tso5 | F6: =IF($C6="", "", IF(OR($H6=4,$H6=8), _xlfn.CONCAT(LEFT($C6),"（促）"), _xlfn.CONCAT(LEFT($C6),"（舒）"))) -> 高（舒） | G6: =IF($C6="", "", _xlfn.XLOOKUP(F6, 十五音韻母表[十五音],十五音韻母表[方音符號]) ) -> ㄜ | H6: =IF($C6="", "", _xlfn.XLOOKUP(MID(C6,2,1), 音調表[八音調號], 音調表[台羅調號]) ) -> 5 | I6: =IF($C6="", "", _xlfn.XLOOKUP($H6, 音調表[台羅調號], 音調表[方音符號聲調符號]) ) -> ˊ | J6: =IF($C6="", "", _xlfn.XLOOKUP(MID($C6,2,1), 音調表[八音調號], 音調表[方音符號聲調按鍵]) ) -> 6 | K6: =IFERROR( _xlfn.XLOOKUP(RIGHT($C6), 十五音聲母表[十八音],十五音聲母表[方音符號]), "" ) -> ㄗ | L6: =IF($C6="","", _xlfn.CONCAT($K6, $G6, IF(OR($I6="一", $I6="四"), "", $I6))) -> ㄗㄜˊ | M6: =IF($C6="","",IF($K6=零聲母,_xlfn.CONCAT(G6,J6,"="),_xlfn.CONCAT(G6,J6,K6))) -> ㄜ6ㄗ | N6: =_xlfn.CONCAT(Q6:X6) -> k6y | O6: =IF($C6="", "", LEN($L6)) -> 3 | P6: =IF($C6="", "", LEN($G6)+1) -> 2 | Q6: {=IFERROR( INDEX(按鍵位置表[鍵盤按鍵], MATCH(TRUE, EXACT(MID($M6,Q$5,1), 按鍵位置表[方音按鍵]), 0)), "" )} -> k | R6: {=IFERROR( INDEX(按鍵位置表[鍵盤按鍵], MATCH(TRUE, EXACT(MID($M6,R$5,1), 按鍵位置表[方音按鍵]), 0)), "" )} -> 6 | S6: {=IFERROR( INDEX(按鍵位置表[鍵盤按鍵], MATCH(TRUE, EXACT(MID($M6,S$5,1), 按鍵位置表[方音按鍵]), 0)), "" )} -> y | T6: {=IFERROR( INDEX(按鍵位置表[鍵盤按鍵], MATCH(TRUE, EXACT(MID($M6,T$5,1), 按鍵位置表[方音按鍵]), 0)), "" )} | U6: {=IFERROR( INDEX(按鍵位置表[鍵盤按鍵], MATCH(TRUE, EXACT(MID($M6,U$5,1), 按鍵位置表[方音按鍵]), 0)), "" )} | V6: {=IFERROR( INDEX(按鍵位置表[鍵盤按鍵], MATCH(TRUE, EXACT(MID($M6,V$5,1), 按鍵位置表[方音按鍵]), 0)), "" )} | W6: {=IFERROR( INDEX(按鍵位置表[鍵盤按鍵], MATCH(TRUE, EXACT(MID($M6,W$5,1), 按鍵位置表[方音按鍵]), 0)), "" )} | X6: {=IFERROR( INDEX(按鍵位置表[鍵盤按鍵], MATCH(TRUE, EXACT(MID($M6,X$5,1), 按鍵位置表[方音按鍵]), 0)), "" )} | Z6: =IF($C6="", "", IF(OR($G6=4,$G6=8), _xlfn.CONCAT(LEFT($C6),"（促）"), _xlfn.CONCAT(LEFT($C6),"（舒）"))) -> 高（舒） | AA6: =IF($C6="", "", _xlfn.XLOOKUP(Z6, 十五音韻母表[十五音],十五音韻母表[台羅拼音]) ) -> o | AB6: =IF($C6="","", _xlfn.CONCAT($F6, $J6, $G6)) -> 高（舒）6ㄜ | AC6: =IF($C6="", "", _xlfn.XLOOKUP(MID($C6,2,1), 音調表[八音調號], 音調表[台羅調號]) ) -> 5 | AD6: =IFERROR( _xlfn.XLOOKUP(RIGHT($C6), 十五音聲母表[十八音],十五音聲母表[台羅拼音]), "" ) -> ts | AE6: =IF($C6="", "", _xlfn.XLOOKUP(MID($C6,2,1), 音調表[八音調號], 音調表[羅馬拼音聲調按鍵]) ) -> / | AF6: =IF($C6="","",_xlfn.CONCAT(AA6,AE6,AD6)) -> o/ts | AG6: =IF($C6="", "", LEN($D6)) -> 3 | AH6: =IF($C6="", "", LEN($J6)+1) -> 2 | AI6: =MID($AF6, VALUE(AI$5),1) -> o | AJ6: =MID($AF6, VALUE(AJ$5),1) -> / | AK6: =MID($AF6, VALUE(AK$5),1) -> t | AL6: =MID($AF6, VALUE(AL$5),1) -> s | AM6: =MID($AF6, VALUE(AM$5),1) | AN6: =MID($AF6, VALUE(AN$5),1) | AO6: =MID($AF6, VALUE(AO$5),1) | AP6: =MID($AF6, VALUE(AP$5),1)
B7: 床 | C7: 公五出 | D7: =IF(LEFT($L7)="Ø",SUBSTITUTE($L7, "Ø", ""), $L7) -> ㄘㆲˊ | E7: =_xlfn.CONCAT(AD7,AA7,AC7) -> tshong5 | F7: =IF($C7="", "", IF(OR($H7=4,$H7=8), _xlfn.CONCAT(LEFT($C7),"（促）"), _xlfn.CONCAT(LEFT($C7),"（舒）"))) -> 公（舒） | G7: =IF($C7="", "", _xlfn.XLOOKUP(F7, 十五音韻母表[十五音],十五音韻母表[方音符號]) ) -> ㆲ | H7: =IF($C7="", "", _xlfn.XLOOKUP(MID(C7,2,1), 音調表[八音調號], 音調表[台羅調號]) ) -> 5 | I7: =IF($C7="", "", _xlfn.XLOOKUP($H7, 音調表[台羅調號], 音調表[方音符號聲調符號]) ) -> ˊ | J7: =IF($C7="", "", _xlfn.XLOOKUP(MID($C7,2,1), 音調表[八音調號], 音調表[方音符號聲調按鍵]) ) -> 6 | K7: =IFERROR( _xlfn.XLOOKUP(RIGHT($C7), 十五音聲母表[十八音],十五音聲母表[方音符號]), "" ) -> ㄘ | L7: =IF($C7="","", _xlfn.CONCAT($K7, $G7, IF(OR($I7="一", $I7="四"), "", $I7))) -> ㄘㆲˊ | M7: =IF($C7="","",IF($K7=零聲母,_xlfn.CONCAT(G7,J7,"="),_xlfn.CONCAT(G7,J7,K7))) -> ㆲ6ㄘ | N7: =_xlfn.CONCAT(Q7:X7) -> o6h | O7: =IF($C7="", "", LEN($L7)) -> 3 | P7: =IF($C7="", "", LEN($G7)+1) -> 2 | Q7: {=IFERROR( INDEX(按鍵位置表[鍵盤按鍵], MATCH(TRUE, EXACT(MID($M7,Q$5,1), 按鍵位置表[方音按鍵]), 0)), "" )} -> o | R7: {=IFERROR( INDEX(按鍵位置表[鍵盤按鍵], MATCH(TRUE, EXACT(MID($M7,R$5,1), 按鍵位置表[方音按鍵]), 0)), "" )} -> 6 | S7: {=IFERROR( INDEX(按鍵位置表[鍵盤按鍵], MATCH(TRUE, EXACT(MID($M7,S$5,1), 按鍵位置表[方音按鍵]), 0)), "" )} -> h | T7: {=IFERROR( INDEX(按鍵位置表[鍵盤按鍵], MATCH(TRUE, EXACT(MID($M7,T$5,1), 按鍵位置表[方音按鍵]), 0)), "" )} | U7: {=IFERROR( INDEX(按鍵位置表[鍵盤按鍵], MATCH(TRUE, EXACT(MID($M7,U$5,1), 按鍵位置表[方音按鍵]), 0)), "" )} | V7: {=IFERROR( INDEX(按鍵位置表[鍵盤按鍵], MATCH(TRUE, EXACT(MID($M7,V$5,1), 按鍵位置表[方音按鍵]), 0)), "" )} | W7: {=IFERROR( INDEX(按鍵位置表[鍵盤按鍵], MATCH(TRUE, EXACT(MID($M7,W$5,1), 按鍵位置表[方音按鍵]), 0)), "" )} | X7: {=IFERROR( INDEX(按鍵位置表[鍵盤按鍵], MATCH(TRUE, EXACT(MID($M7,X$5,1), 按鍵位置表[方音按鍵]), 0)), "" )} | Z7: =IF($C7="", "", IF(OR($G7=4,$G7=8), _xlfn.CONCAT(LEFT($C7),"（促）"), _xlfn.CONCAT(LEFT($C7),"（舒）"))) -> 公（舒） | AA7: =IF($C7="", "", _xlfn.XLOOKUP(Z7, 十五音韻母表[十五音],十五音韻母表[台羅拼音]) ) -> ong | AB7: =IF($C7="","", _xlfn.CONCAT($F7, $J7, $G7)) -> 公（舒）6ㆲ | AC7: =IF($C7="", "", _xlfn.XLOOKUP(MID($C7,2,1), 音調表[八音調號], 音調表[台羅調號]) ) -> 5 | AD7: =IFERROR( _xlfn.XLOOKUP(RIGHT($C7), 十五音聲母表[十八音],十五音聲母表[台羅拼音]), "" ) -> tsh | AE7: =IF($C7="", "", _xlfn.XLOOKUP(MID($C7,2,1), 音調表[八音調號], 音調表[羅馬拼音聲調按鍵]) ) -> / | AF7: =IF($C7="","",_xlfn.CONCAT(AA7,AE7,AD7)) -> ong/tsh | AG7: =IF($C7="", "", LEN($D7)) -> 3 | AH7: =IF($C7="", "", LEN($J7)+1) -> 2 | AI7: =MID($AF7, VALUE(AI$5),1) -> o | AJ7: =MID($AF7, VALUE(AJ$5),1) -> n | AK7: =MID($AF7, VALUE(AK$5),1) -> g | AL7: =MID($AF7, VALUE(AL$5),1) -> / | AM7: =MID($AF7, VALUE(AM$5),1) -> t | AN7: =MID($AF7, VALUE(AN$5),1) -> s | AO7: =MID($AF7, VALUE(AO$5),1) -> h | AP7: =MID($AF7, VALUE(AP$5),1)
B9: =_xlfn.CONCAT("1. 漢字：【", B6,"】，十五音標音：【",C6,"】，方音符號：【",D6,"】，台羅拼音：【",E6,"】。") -> 1. 漢字：【做】，十五音標音：【高五曾】，方音符號：【ㄗㄜˊ】，台羅拼音：【tso5】。
B10: =_xlfn.CONCAT(" - 字母（韻母）：字母【",F6,"】，以方音符號【",G6,"】代，用按鍵：【", LEFT(N6,P6-1),"】輸入； ") -> - 字母（韻母）：字母【高（舒）】，以方音符號【ㄜ】代，用按鍵：【k】輸入；
B11: =_xlfn.CONCAT(" - 八音（音調）：八音【",MID($C$6,2,1),"】，以方音符號【",I6,"】代，用按鍵：【",J6,"】輸入；") -> - 八音（音調）：八音【五】，以方音符號【ˊ】代，用按鍵：【6】輸入；
B12: =_xlfn.CONCAT(" - 切音（聲母）：切音【",RIGHT($C$6,1),"】，以方音符號【",K6,"】代，用按鍵：【",RIGHT(N6,O6-P6),"】輸入。") -> - 切音（聲母）：切音【曾】，以方音符號【ㄗ】代，用按鍵：【y】輸入。

Sheet Bug産生器 (2)
B1: 聲母 | C1: 零ㄅㄆㄇㆠㄉㄊㄋㄌㄍㄎㆣㄏㄗㄘㆡㄙㄐㄑㆢㄒ | K1: 零聲母 | L1: Ø | Z1: q | AC1: Ø | AE1: 零聲母
F2: 方音符號 | Z2: 台羅拼音
B4: 漢字 | C4: 十五音 | D4: 方音符號 | E4: 台羅拼音字母 | F4: 字母 | G4: 韻母 | H4: 音調 | I4: 方音調符 | J4: 方音音調按鍵 | K4: 聲母 | L4: 含零聲母 | M4: 輸入按鍵 | N4: 鍵盤字串 | O4: 字長 | P4: 調號位置 | Q4: 鍵盤按鍵 | Z4: 字母 | AA4: 韻母 | AB4: 含零聲母 | AC4: 音調 | AD4: 聲母 | AE4: 音調按鍵 | AF4: 輸入按鍵 | AG4: 字長 | AH4: 調號位置 | AI4: 鍵盤按鍵
Q5: 1 | R5: 2 | S5: 3 | T5: 4 | U5: 5 | V5: 6 | W5: 7 | X5: 8 | AI5: 1 | AJ5: 2 | AK5: 3 | AL5: 4 | AM5: 5 | AN5: 6 | AO5: 7 | AP5: 8
B6: 床 | C6: 公五出 | D6: =IF(LEFT($L6)="Ø",SUBSTITUTE($L6, "Ø", ""), $L6) -> ㄘㆲˊ | E6: =_xlfn.CONCAT(AD6,AA6,AC6) -> tshong5 | F6: =IF($C6="", "", IF(OR($H6=4,$H6=8), _xlfn.CONCAT(LEFT($C6),"（促）"), _xlfn.CONCAT(LEFT($C6),"（舒）"))) -> 公（舒） | G6: =IF($C6="", "", _xlfn.XLOOKUP(F6, 十五音韻母表[十五音],十五音韻母表[方音符號]) ) -> ㆲ | H6: =IF($C6="", "", _xlfn.XLOOKUP(MID(C6,2,1), 音調表[八音調號], 音調表[台羅調號]) ) -> 5 | I6: =IF($C6="", "", _xlfn.XLOOKUP($H6, 音調表[台羅調號], 音調表[方音符號聲調符號]) ) -> ˊ | J6: =IF($C6="", "", _xlfn.XLOOKUP(MID($C6,2,1), 音調表[八音調號], 音調表[方音符號聲調按鍵]) ) -> 6 | K6: =IFERROR( _xlfn.XLOOKUP(RIGHT($C6), 十五音聲母表[十八音],十五音聲母表[方音符號]), "" ) -> ㄘ | L6: =IF($C6="","", _xlfn.CONCAT($K6, $G6, IF(OR($I6="一", $I6="四"), "", $I6))) -> ㄘㆲˊ | M6: =IF($C6="","",IF($K6=零聲母,_xlfn.CONCAT(G6,J6,"="),_xlfn.CONCAT(G6,J6,K6))) -> ㆲ6ㄘ | N6: =_xlfn.CONCAT(Q6:X6) -> o6h | O6: =IF($C6="", "", LEN($L6)) -> 3 | P6: =IF($C6="", "", LEN($G6)+1) -> 2 | Q6: {=IFERROR( INDEX(按鍵位置表[鍵盤按鍵], MATCH(TRUE, EXACT(MID($M6,Q$5,1), 按鍵位置表[方音按鍵]), 0)), "" )} -> o | R6: {=IFERROR( INDEX(按鍵位置表[鍵盤按鍵], MATCH(TRUE, EXACT(MID($M6,R$5,1), 按鍵位置表[方音按鍵]), 0)), "" )} -> 6 | S6: {=IFERROR( INDEX(按鍵位置表[鍵盤按鍵], MATCH(TRUE, EXACT(MID($M6,S$5,1), 按鍵位置表[方音按鍵]), 0)), "" )} -> h | T6: {=IFERROR( INDEX(按鍵位置表[鍵盤按鍵], MATCH(TRUE, EXACT(MID($M6,T$5,1), 按鍵位置表[方音按鍵]), 0)), "" )} | U6: {=IFERROR( INDEX(按鍵位置表[鍵盤按鍵], MATCH(TRUE, EXACT(MID($M6,U$5,1), 按鍵位置表[方音按鍵]), 0)), "" )} | V6: {=IFERROR( INDEX(按鍵位置表[鍵盤按鍵], MATCH(TRUE, EXACT(MID($M6,V$5,1), 按鍵位置表[方音按鍵]), 0)), "" )} | W6: {=IFERROR( INDEX(按鍵位置表[鍵盤按鍵], MATCH(TRUE, EXACT(MID($M6,W$5,1), 按鍵位置表[方音按鍵]), 0)), "" )} | X6: {=IFERROR( INDEX(按鍵位置表[鍵盤按鍵], MATCH(TRUE, EXACT(MID($M6,X$5,1), 按鍵位置表[方音按鍵]), 0)), "" )} | Z6: =IF($C6="", "", IF(OR($G6=4,$G6=8), _xlfn.CONCAT(LEFT($C6),"（促）"), _xlfn.CONCAT(LEFT($C6),"（舒）"))) -> 公（舒） | AA6: =IF($C6="", "", _xlfn.XLOOKUP(Z6, 十五音韻母表[十五音],十五音韻母表[台羅拼音]) ) -> ong | AB6: =IF($C6="","", _xlfn.CONCAT($F6, $J6, $G6)) -> 公（舒）6ㆲ | AC6: =IF($C6="", "", _xlfn.XLOOKUP(MID($C6,2,1), 音調表[八音調號], 音調表[台羅調號]) ) -> 5 | AD6: =IFERROR( _xlfn.XLOOKUP(RIGHT($C6), 十五音聲母表[十八音],十五音聲母表[台羅拼音]), "" ) -> tsh | AE6: =IF($C6="", "", _xlfn.XLOOKUP(MID($C6,2,1), 音調表[八音調號], 音調表[羅馬拼音聲調按鍵]) ) -> / | AF6: =IF($C6="","",_xlfn.CONCAT(AA6,AE6,AD6)) -> ong/tsh | AG6: =IF($C6="", "", LEN($D6)) -> 3 | AH6: =IF($C6="", "", LEN($J6)+1) -> 2 | AI6: =MID($AF6, VALUE(AI$5),1) -> o | AJ6: =MID($AF6, VALUE(AJ$5),1) -> n | AK6: =MID($AF6, VALUE(AK$5),1) -> g | AL6: =MID($AF6, VALUE(AL$5),1) -> / | AM6: =MID($AF6, VALUE(AM$5),1) -> t | AN6: =MID($AF6, VALUE(AN$5),1) -> s | AO6: =MID($AF6, VALUE(AO$5),1) -> h | AP6: =MID($AF6, VALUE(AP$5),1)
D7: =IF(LEFT($L7)="Ø",SUBSTITUTE($L7, "Ø", ""), $L7) | E7: =_xlfn.CONCAT(AD7,AA7,AC7) | F7: =IF($C7="", "", IF(OR($H7=4,$H7=8), _xlfn.CONCAT(LEFT($C7),"（促）"), _xlfn.CONCAT(LEFT($C7),"（舒）"))) | G7: =IF($C7="", "", _xlfn.XLOOKUP(F7, 十五音韻母表[十五音],十五音韻母表[方音符號]) ) | H7: =IF($C7="", "", _xlfn.XLOOKUP(MID(C7,2,1), 音調表[八音調號], 音調表[台羅調號]) ) | I7: =IF($C7="", "", _xlfn.XLOOKUP($H7, 音調表[台羅調號], 音調表[方音符號聲調符號]) ) | J7: =IF($C7="", "", _xlfn.XLOOKUP(MID($C7,2,1), 音調表[八音調號], 音調表[方音符號聲調按鍵]) ) | K7: =IFERROR( _xlfn.XLOOKUP(RIGHT($C7), 十五音聲母表[十八音],十五音聲母表[方音符號]), "" ) | L7: =IF($C7="","", _xlfn.CONCAT($K7, $G7, IF(OR($I7="一", $I7="四"), "", $I7))) | M7: =IF($C7="","",IF($K7=零聲母,_xlfn.CONCAT(G7,J7,"="),_xlfn.CONCAT(G7,J7,K7))) | N7: =_xlfn.CONCAT(Q7:X7) | O7: =IF($C7="", "", LEN($L7)) | P7: =IF($C7="", "", LEN($G7)+1) | Q7: {=IFERROR( INDEX(按鍵位置表[鍵盤按鍵], MATCH(TRUE, EXACT(MID($M7,Q$5,1), 按鍵位置表[方音按鍵]), 0)), "" )} | R7: {=IFERROR( INDEX(按鍵位置表[鍵盤按鍵], MATCH(TRUE, EXACT(MID($M7,R$5,1), 按鍵位置表[方音按鍵]), 0)), "" )} | S7: {=IFERROR( INDEX(按鍵位置表[鍵盤按鍵], MATCH(TRUE, EXACT(MID($M7,S$5,1), 按鍵位置表[方音按鍵]), 0)), "" )} | T7: {=IFERROR( INDEX(按鍵位置表[鍵盤按鍵], MATCH(TRUE, EXACT(MID($M7,T$5,1), 按鍵位置表[方音按鍵]), 0)), "" )} | U7: {=IFERROR( INDEX(按鍵位置表[鍵盤按鍵], MATCH(TRUE, EXACT(MID($M7,U$5,1), 按鍵位置表[方音按鍵]), 0)), "" )} | V7: {=IFERROR( INDEX(按鍵位置表[鍵盤按鍵], MATCH(TRUE, EXACT(MID($M7,V$5,1), 按鍵位置表[方音按鍵]), 0)), "" )} | W7: {=IFERROR( INDEX(按鍵位置表[鍵盤按鍵], MATCH(TRUE, EXACT(MID($M7,W$5,1), 按鍵位置表[方音按鍵]), 0)), "" )} | X7: {=IFERROR( INDEX(按鍵位置表[鍵盤按鍵], MATCH(TRUE, EXACT(MID($M7,X$5,1), 按鍵位置表[方音按鍵]), 0)), "" )} | Z7: =IF($C7="", "", IF(OR($G7=4,$G7=8), _xlfn.CONCAT(LEFT($C7),"（促）"), _xlfn.CONCAT(LEFT($C7),"（舒）"))) | AA7: =IF($C7="", "", _xlfn.XLOOKUP(Z7, 十五音韻母表[十五音],十五音韻母表[台羅拼音]) ) | AB7: =IF($C7="","", _xlfn.CONCAT($F7, $J7, $G7)) | AC7: =IF($C7="", "", _xlfn.XLOOKUP(MID($C7,2,1), 音調表[八音調號], 音調表[台羅調號]) ) | AD7: =IFERROR( _xlfn.XLOOKUP(RIGHT($C7), 十五音聲母表[十八音],十五音聲母表[台羅拼音]), "" ) | AE7: =IF($C7="", "", _xlfn.XLOOKUP(MID($C7,2,1), 音調表[八音調號], 音調表[羅馬拼音聲調按鍵]) ) | AF7: =IF($C7="","",_xlfn.CONCAT(AA7,AE7,AD7)) | AG7: =IF($C7="", "", LEN($D7)) | AH7: =IF($C7="", "", LEN($J7)+1) | AI7: =MID($AF7, VALUE(AI$5),1) | AJ7: =MID($AF7, VALUE(AJ$5),1) | AK7: =MID($AF7, VALUE(AK$5),1) | AL7: =MID($AF7, VALUE(AL$5),1) | AM7: =MID($AF7, VALUE(AM$5),1) | AN7: =MID($AF7, VALUE(AN$5),1) | AO7: =MID($AF7, VALUE(AO$5),1) | AP7: =MID($AF7, VALUE(AP$5),1)
B9: =_xlfn.CONCAT("1. 漢字：【", B6,"】，十五音標音：【",C6,"】，方音符號：【",D6,"】，台羅拼音：【",E6,"】。") -> 1. 漢字：【床】，十五音標音：【公五出】，方音符號：【ㄘㆲˊ】，台羅拼音：【tshong5】。
B10: =_xlfn.CONCAT(" - 字母（韻母）：字母【",F6,"】，以方音符號【",G6,"】代，用按鍵：【", LEFT(N6,P6-1),"】輸入； ") -> - 字母（韻母）：字母【公（舒）】，以方音符號【ㆲ】代，用按鍵：【o】輸入；
B11: =_xlfn.CONCAT(" - 八音（音調）：八音【",MID($C$6,2,1),"】，以方音符號【",I6,"】代，用按鍵：【",J6,"】輸入；") -> - 八音（音調）：八音【五】，以方音符號【ˊ】代，用按鍵：【6】輸入；
B12: =_xlfn.CONCAT(" - 切音（聲母）：切音【",RIGHT($C$6,1),"】，以方音符號【",K6,"】代，用按鍵：【",RIGHT(N6,O6-P6),"】輸入。") -> - 切音（聲母）：切音【出】，以方音符號【ㄘ】代，用按鍵：【h】輸入。

Sheet 漢字注音
A1: =COLUMN() -> 1 | B1: =COLUMN() -> 2 | C1: =COLUMN() -> 3
V2: =LEN(V3) -> 45
V3: 《涼州詞》王之渙 黃河遠上白雲間， 一片孤城萬仞山。 羌笛何須怨楊柳， 春風不度玉門關。
E4: liang5 | F4: ziu1 | G4: su5 | I4: ong5 | J4: zi1 | K4: huan3
B5: 1 | D5: 《 | E5: 涼 | F5: 州 | G5: 詞 | H5: 》 | I5: 王 | J5: 之 | K5: 渙 | L5: =CHAR(10)
E6: ㄌㄧㄤˊ | F6: ㄐㄧㄨ | G6: ㄙㄨˊ | I6: ㆲˊ | J6: ㄐㄧ | K6: ㄏㄨㄢ˪
D8: hong5 | E8: ho5 | F8: uan2 | G8: siong2 | H8: pik8 | I8: hun5 | J8: kan1
B9: =B5+1 -> 2 | D9: 黃 | E9: 河 | F9: 遠 | G9: 上 | H9: 白 | I9: 雲 | J9: 間 | K9: ， | L9: =CHAR(10)
D10: ㄏㆲˊ | E10: ㄏㄜˊ | F10: ㄨㄢˋ | G10: ㄒㄧㆲˋ | H10: ㄅㄧㆻ˙ | I10: ㄏㄨㄣˊ | J10: ㄍㄢ
D12: it4 | E12: phian3 | F12: koo1 | G12: sing5 | H12: ban7 | I12: jin7 | J12: san1
B13: =B9+1 -> 3 | D13: 一 | E13: 片 | F13: 孤 | G13: 城 | H13: 萬 | I13: 仞 | J13: 山 | K13: 。 | L13: =CHAR(10)
D14: ㄧㆵ | E14: ㄆㄧㄢ˪ | F14: ㄍㆦ | G14: ㄒㄧㄥˊ | H14: ㆠㄢ˫ | I14: ㆢㄧㄣ˫ | J14: ㄙㄢ
E15: tik8
D16: khiang1 | E16: tik8 | F16: ho5 | G16: su1 | H16: uan3 | I16: iong5 | J16: liu2
B17: =B13+1 -> 4 | D17: 羌 | E17: 笛 | F17: 何 | G17: 須 | H17: 怨 | I17: 楊 | J17: 柳 | K17: ， | L17: =CHAR(10)
D18: ㄎㄧㄤ | E18: ㄉㄧㆻ˙ | F18: ㄏㄜˊ | G18: ㄙㄨ | H18: ㄨㄢ˪ | I18: ㄧㆲˊ | J18: ㄌㄧㄨˋ
D20: cun1 | E20: hong1 | F20: put4 | G20: too7 | H20: giok8 | I20: bun5 | J20: kuan1
B21: =B17+1 -> 5 | D21: 春 | E21: 風 | F21: 不 | G21: 度 | H21: 玉 | I21: 門 | J21: 關 | K21: 。 | L21: =CHAR(10)
D22: ㄘㄨㄣ | E22: ㄏㆲ | F22: ㄅㄨㆵ | G22: ㄉㆦ˫ | H22: ㆣㄧㆦㆻ˙ | I22: ㆠㄨㄣˊ | J22: ㄍㄨㄢ
B25: =B21+1 -> 6 | D25: φ
B29: =B25+1 -> 7
B33: =B29+1 -> 8
B37: =B33+1 -> 9
B41: =B37+1 -> 10
B45: =B41+1 -> 11
B49: =B45+1 -> 12
B53: =B49+1 -> 13
B57: =B53+1 -> 14
B61: =B57+1 -> 15
B65: =B61+1 -> 16
B69: =B65+1 -> 17
B73: =B69+1 -> 18
... B2001: =B1997+1 -> 500

Sheet 十五音聲母
A1: 序號 | B1: 音序 | C1: 漢字例 | D1: 十五音 | E1: 十八音 | F1: 國際音標 | G1: 台羅拼音 | H1: 台語音標 | I1: 白話字 | J1: 閩拼方案 | K1: 注音二式 | L1: 注音二式代 | M1: 方音符號 | N1: 台語注音
A2: 1 | B2: 11 | C2: 恩 | D2: 英 | E2: 英 | G2: Ø | J2: Ø | K2: Ø | L2: Ø | M2: Ø | N2: Ø
A3: 2 | B3: 2 | C3: 比 | D3: 邊 | E3: 邊 | F3: p | G3: p | H3: p | I3: p | J3: b | K3: b | L3: b | M3: ㄅ | N3: ㄅ
A4: 3 | B4: 6 | C4: 鼻 | D4: 頗 | E4: 頗 | F4: pʰ | G4: ph | H4: ph | I4: ph | J4: p | K4: p | L4: p | M4: ㄆ | N4: ㄆ
A5: 4 | B5: 12 | C5: 文 | D5: 門 | E5: 門 | F5: b | G5: b | H5: b | I5: b | J5: bb | K5: bb | L5: bb | M5: ㆠ | N5: ㄪ
A6: 5 | B6: 12 | C6: 毛 | D6: 門 | E6: 毛 | F6: m | G6: m | H6: m | I6: m | J6: bbn | K6: m | L6: bbn | M6: ㄇ | N6: ㄇ
A7: 6 | B7: 5 | C7: 底 | D7: 地 | E7: 地 | F7: t | G7: t | H7: t | I7: t | J7: d | K7: d | L7: d | M7: ㄉ | N7: ㄉ
A8: 7 | B8: 7 | C8: 替 | D8: 他 | E8: 他 | F8: tʰ | G8: th | H8: th | I8: th | J8: t | K8: t | L8: t | M8: ㄊ | N8: ㄊ
A9: 8 | B9: 1 | C9: 理 | D9: 柳 | E9: 柳 | F9: l | G9: l | H9: l | I9: l | J9: l | K9: l | L9: l | M9: ㄌ | N9: ㄌ
A10: 9 | B10: 1 | C10: 耐 | D10: 柳 | E10: 耐 | F10: n | G10: n | H10: n | I10: n | J10: ln | K10: n | L10: ln | M10: ㄋ | N10: ㄋ
A11: 10 | B11: 3 | C11: 己 | D11: 求 | E11: 求 | F11: k | G11: k | H11: k | I11: k | J11: g | K11: g | L11: g | M11: ㄍ | N11: ㄍ
A12: 11 | B12: 4 | C12: 起 | D12: 去 | E12: 去 | F12: kʰ | G12: kh | H12: kh | I12: kh | J12: k | K12: k | L12: k | M12: ㄎ | N12: ㄎ
A13: 12 | B13: 13 | C13: 禦 | D13: 語 | E13: 語 | F13: ɡ | G13: g | H13: g | I13: g | J13: gg | K13: gg | L13: gg | M13: ㆣ | N13: ㄫ
A14: 13 | B14: 13 | C14: 雅 | D14: 語 | E14: 雅 | F14: ŋ | G14: ng | H14: ng | I14: ng | J14: ggn | K14: ng | L14: ggn | M14: ㄫ | N14: ⁰ㄫ
... A23: 22 | B23: 10 | C23: 施 | D23: 時 | E23: 時 | F23: ɕ | G23: si | H23: si | I23: si | J23: si | K23: shi | L23: si | M23: ㄒ | N23: ㄒ

Sheet 十五音韻母
A1: 序號 | B1: 韻序 | C1: 漢字例 | D1: 十五音 | E1: 國際音標 | F1: 國際音標2 | G1: 台羅拼音 | H1: 台語音標 | I1: 白話字 | J1: 閩拼方案 | K1: 注音二式 | L1: 方音符號 | M1: 台語注音 | O1: =_xlfn.CONCAT("ɛ", _xlfn.UNICHAR(HEX2DEC(RIGHT("U+0303",4)))) -> ɛ̃ | P1: =_xlfn.CONCAT("ɛ", _xlfn.UNICHAR(HEX2DEC(RIGHT("U+0294",4)))) -> ɛʔ | Q1: ɔ
A2: 1 | B2: =IF(MOD(十五音韻母表[[#This Row],[序號]],2)=0, 十五音韻母表[[#This Row],[序號]]/2, ROUNDUP(十五音韻母表[[#This Row],[序號]]/2,0)) -> 1 | C2: 分 | D2: 君（舒） | E2: un | G2: un | H2: un | I2: un | J2: un | K2: un | L2: ㄨㄣ | M2: ㄨㄣ
A3: 2 | B3: =IF(MOD(十五音韻母表[[#This Row],[序號]],2)=0, 十五音韻母表[[#This Row],[序號]]/2, ROUNDUP(十五音韻母表[[#This Row],[序號]]/2,0)) -> 1 | C3: 佛 | D3: 君（促） | E3: ut̚ | G3: ut | H3: ut | I3: ut | J3: ut | K3: ut | L3: ㄨㆵ | M3: ㄨㄉ
A4: 3 | B4: =IF(MOD(十五音韻母表[[#This Row],[序號]],2)=0, 十五音韻母表[[#This Row],[序號]]/2, ROUNDUP(十五音韻母表[[#This Row],[序號]]/2,0)) -> 2 | C4: 掀 | D4: 堅（舒） | E4: ɪan | G4: ian | H4: ian | I4: ian | J4: ian | K4: ian | L4: ㄧㄢ | M4: ㄧㄢ
A5: 4 | B5: =IF(MOD(十五音韻母表[[#This Row],[序號]],2)=0, 十五音韻母表[[#This Row],[序號]]/2, ROUNDUP(十五音韻母表[[#This Row],[序號]]/2,0)) -> 2 | C5: 結 | D5: 堅（促） | E5: ɪat̚ | G5: iat | H5: iat | I5: iat | J5: iat | K5: iat | L5: ㄧㄚㆵ | M5: ㄧㄚㄉ
A6: 5 | B6: =IF(MOD(十五音韻母表[[#This Row],[序號]],2)=0, 十五音韻母表[[#This Row],[序號]]/2, ROUNDUP(十五音韻母表[[#This Row],[序號]]/2,0)) -> 3 | C6: 深 | D6: 金（舒） | E6: im | G6: im | H6: im | I6: im | J6: im | K6: im | L6: ㄧㆬ | M6: ㄧㄇ
A7: 6 | B7: =IF(MOD(十五音韻母表[[#This Row],[序號]],2)=0, 十五音韻母表[[#This Row],[序號]]/2, ROUNDUP(十五音韻母表[[#This Row],[序號]]/2,0)) -> 3 | C7: 急 | D7: 金（促） | E7: ip̚ | G7: ip | H7: ip | I7: ip | J7: ip | K7: ip | L7: 一ㆴ | M7: ㄧㄅ
A8: 7 | B8: =IF(MOD(十五音韻母表[[#This Row],[序號]],2)=0, 十五音韻母表[[#This Row],[序號]]/2, ROUNDUP(十五音韻母表[[#This Row],[序號]]/2,0)) -> 4 | C8: 歸 | D8: 規（舒） | E8: ui | G8: ui | H8: ui | I8: ui | J8: ui | K8: ui | L8: ㄨㄧ | M8: ㄨㄧ
A9: 8 | B9: =IF(MOD(十五音韻母表[[#This Row],[序號]],2)=0, 十五音韻母表[[#This Row],[序號]]/2, ROUNDUP(十五音韻母表[[#This Row],[序號]]/2,0)) -> 4 | D9: 規（促） | G9: ui | H9: ui | I9: ui | J9: ui | K9: ui | L9: ㄨㄧㆷ
A10: 9 | B10: =IF(MOD(十五音韻母表[[#This Row],[序號]],2)=0, 十五音韻母表[[#This Row],[序號]]/2, ROUNDUP(十五音韻母表[[#This Row],[序號]]/2,0)) -> 5 | C10: 加 | D10: 嘉（舒） | E10: e | F10: ɛ | G10: ee | H10: ee | L10: ㄝ | M10: ㄝ
A11: 10 | B11: =IF(MOD(十五音韻母表[[#This Row],[序號]],2)=0, 十五音韻母表[[#This Row],[序號]]/2, ROUNDUP(十五音韻母表[[#This Row],[序號]]/2,0)) -> 5 | C11: 格 | D11: 嘉（促） | E11: eʔ | F11: ɛʔ | G11: =IF(G10="", "", _xlfn.CONCAT(G10, "h")) -> eeh | H11: =IF(H10="", "", _xlfn.CONCAT(H10, "h")) -> eeh | I11: =IF(I10="", "", _xlfn.CONCAT(I10, "h")) | J11: =IF(J10="", "", _xlfn.CONCAT(J10, "h")) | K11: =IF(K10="", "", _xlfn.CONCAT(K10, "h")) | L11: =IF(L10="", "", _xlfn.CONCAT(L10, "ㆷ")) -> ㄝㆷ | M11: =IF(M10="", "", _xlfn.CONCAT(M10, "ㄏ")) -> ㄝㄏ
A12: 11 | B12: =IF(MOD(十五音韻母表[[#This Row],[序號]],2)=0, 十五音韻母表[[#This Row],[序號]]/2, ROUNDUP(十五音韻母表[[#This Row],[序號]]/2,0)) -> 6 | C12: 蘭 | D12: 干（舒） | E12: an | G12: an | H12: an | I12: an | J12: an | K12: an | L12: ㄢ | M12: ㄢ
A13: 12 | B13: =IF(MOD(十五音韻母表[[#This Row],[序號]],2)=0, 十五音韻母表[[#This Row],[序號]]/2, ROUNDUP(十五音韻母表[[#This Row],[序號]]/2,0)) -> 6 | C13: 擦 | D13: 干（促） | E13: at̚ | G13: at | H13: at | I13: at | J13: at | K13: at | L13: ㄚㆵ | M13: ㄚㄉ
A14: 13 | B14: =IF(MOD(十五音韻母表[[#This Row],[序號]],2)=0, 十五音韻母表[[#This Row],[序號]]/2, ROUNDUP(十五音韻母表[[#This Row],[序號]]/2,0)) -> 7 | C14: 風 | D14: 公（舒） | E14: ɔŋ | G14: ong | H14: ong | I14: ong | J14: ong | K14: ong | L14: ㆲ | M14: ㄛㄥ
A15: 14 | B15: =IF(MOD(十五音韻母表[[#This Row],[序號]],2)=0, 十五音韻母表[[#This Row],[序號]]/2, ROUNDUP(十五音韻母表[[#This Row],[序號]]/2,0)) -> 7 | C15: 服 | D15: 公（促） | E15: ɔk̚ | G15: ok | H15: ok | I15: ok | J15: ok | K15: ok | L15: ㆦㆻ | M15: ㄛㄍ
A16: 15 | B16: =IF(MOD(十五音韻母表[[#This Row],[序號]],2)=0, 十五音韻母表[[#This Row],[序號]]/2, ROUNDUP(十五音韻母表[[#This Row],[序號]]/2,0)) -> 8 | C16: 怪 | D16: 乖（舒） | E16: uai | G16: uai | H16: uai | I16: oai | J16: uai | K16: uai | L16: ㄨㄞ | M16: ㄨㄞ
A17: 16 | B17: =IF(MOD(十五音韻母表[[#This Row],[序號]],2)=0, 十五音韻母表[[#This Row],[序號]]/2, ROUNDUP(十五音韻母表[[#This Row],[序號]]/2,0)) -> 8 | C17: 孬 | D17: 乖（促） | E17: uaiʔ | G17: =IF(G16="", "", _xlfn.CONCAT(G16, "h")) -> uaih | H17: =IF(H16="", "", _xlfn.CONCAT(H16, "h")) -> uaih | I17: =IF(I16="", "", _xlfn.CONCAT(I16, "h")) -> oaih | J17: =IF(J16="", "", _xlfn.CONCAT(J16, "h")) -> uaih | K17: =IF(K16="", "", _xlfn.CONCAT(K16, "h")) -> uaih | L17: =IF(L16="", "", _xlfn.CONCAT(L16, "ㆷ")) -> ㄨㄞㆷ | M17: =IF(M16="", "", _xlfn.CONCAT(M16, "ㄏ")) -> ㄨㄞㄏ
A18: 17 | B18: =IF(MOD(十五音韻母表[[#This Row],[序號]],2)=0, 十五音韻母表[[#This Row],[序號]]/2, ROUNDUP(十五音韻母表[[#This Row],[序號]]/2,0)) -> 9 | C18: 情 | D18: 經（舒） | E18: ɪŋ | F18: ɛŋ | G18: ing | H18: ing | I18: eng | J18: ing | K18: ing | L18: ㄧㄥ | M18: ㄧㄥ
A19: 18 | B19: =IF(MOD(十五音韻母表[[#This Row],[序號]],2)=0, 十五音韻母表[[#This Row],[序號]]/2, ROUNDUP(十五音韻母表[[#This Row],[序號]]/2,0)) -> 9 | C19: 測 | D19: 經（促） | E19: ɪk | F19: ɛk | G19: ik | H19: ik | I19: ek | J19: ik | K19: ik | L19: ㄧㆻ | M19: ㄧㄍ
A20: 19 | B20: =IF(MOD(十五音韻母表[[#This Row],[序號]],2)=0, 十五音韻母表[[#This Row],[序號]]/2, ROUNDUP(十五音韻母表[[#This Row],[序號]]/2,0)) -> 10 | C20: 團 | D20: 觀（舒） | E20: uan | G20: uan | H20: uan | I20: oan | J20: uan | K20: uan | L20: ㄨㄢ | M20: ㄨㄢ
A21: 20 | B21: =IF(MOD(十五音韻母表[[#This Row],[序號]],2)=0, 十五音韻母表[[#This Row],[序號]]/2, ROUNDUP(十五音韻母表[[#This Row],[序號]]/2,0)) -> 10 | C21: 決 | D21: 觀（促） | E21: uat̚ | G21: uat | H21: uat | I21: oat | J21: uat | K21: uat | L21: ㄨㄚㆵ | M21: ㄨㄚㄉ
A22: 21 | B22: =IF(MOD(十五音韻母表[[#This Row],[序號]],2)=0, 十五音韻母表[[#This Row],[序號]]/2, ROUNDUP(十五音韻母表[[#This Row],[序號]]/2,0)) -> 11 | C22: 姑 | D22: 沽（舒） | E22: ɔ | F22: ou | G22: oo | H22: oo | I22: o͘ | J22: oo | K22: oo | L22: ㆦ | M22: ㄛ
A23: 22 | B23: =IF(MOD(十五音韻母表[[#This Row],[序號]],2)=0, 十五音韻母表[[#This Row],[序號]]/2, ROUNDUP(十五音韻母表[[#This Row],[序號]]/2,0)) -> 11 | D23: 沽（促） | E23: =_xlfn.CONCAT(E22, "h") -> ɔh | G23: =IF(G22="", "", _xlfn.CONCAT(G22, "h")) -> ooh | H23: =IF(H22="", "", _xlfn.CONCAT(H22, "h")) -> ooh | I23: =IF(I22="", "", _xlfn.CONCAT(I22, "h")) -> o͘h | J23: =IF(J22="", "", _xlfn.CONCAT(J22, "h")) -> ooh | K23: =IF(K22="", "", _xlfn.CONCAT(K22, "h")) -> ooh | L23: =IF(L22="", "", _xlfn.CONCAT(L22, "ㆷ")) -> ㆦㆷ | M23: =IF(M22="", "", _xlfn.CONCAT(M22, "ㄏ")) -> ㄛㄏ
A24: 23 | B24: =IF(MOD(十五音韻母表[[#This Row],[序號]],2)=0, 十五音韻母表[[#This Row],[序號]]/2, ROUNDUP(十五音韻母表[[#This Row],[序號]]/2,0)) -> 12 | C24: 鵰 | D24: 嬌（舒） | E24: ɪaʊ | G24: iau | H24: iau | I24: iau | J24: iao | K24: iau | L24: ㄧㄠ | M24: ㄧㄠ
A25: 24 | B25: =IF(MOD(十五音韻母表[[#This Row],[序號]],2)=0, 十五音韻母表[[#This Row],[序號]]/2, ROUNDUP(十五音韻母表[[#This Row],[序號]]/2,0)) -> 12 | C25: 愀 | D25: 嬌（促） | E25: ɪaʊʔ | G25: iauh | H25: iauh | I25: iauh | J25: iaoh | K25: iauh | L25: ㄧㄠㆷ | M25: ㄧㄠㄏ
A26: 25 | B26: =IF(MOD(十五音韻母表[[#This Row],[序號]],2)=0, 十五音韻母表[[#This Row],[序號]]/2, ROUNDUP(十五音韻母表[[#This Row],[序號]]/2,0)) -> 13 | C26: 街 | D26: 稽（舒） | E26: e | F26: ei | G26: e | H26: ei | I26: e | J26: e | K26: e | L26: ㆤ | M26: ㄝ
A27: 26 | B27: =IF(MOD(十五音韻母表[[#This Row],[序號]],2)=0, 十五音韻母表[[#This Row],[序號]]/2, ROUNDUP(十五音韻母表[[#This Row],[序號]]/2,0)) -> 13 | G27: =IF(G26="", "", _xlfn.CONCAT(G26, "h")) -> eh | H27: =IF(H26="", "", _xlfn.CONCAT(H26, "h")) -> eih | I27: =IF(I26="", "", _xlfn.CONCAT(I26, "h")) -> eh | J27: =IF(J26="", "", _xlfn.CONCAT(J26, "h")) -> eh | K27: =IF(K26="", "", _xlfn.CONCAT(K26, "h")) -> eh | L27: =IF(L26="", "", _xlfn.CONCAT(L26, "ㆷ")) -> ㆤㆷ | M27: =IF(M26="", "", _xlfn.CONCAT(M26, "ㄏ")) -> ㄝㄏ
A28: 27 | B28: =IF(MOD(十五音韻母表[[#This Row],[序號]],2)=0, 十五音韻母表[[#This Row],[序號]]/2, ROUNDUP(十五音韻母表[[#This Row],[序號]]/2,0)) -> 14 | C28: 中 | D28: 恭（舒） | E28: ɪɔŋ | G28: iong | H28: iong | I28: iong | J28: iong | K28: iong | L28: ㄧㆲ | M28: ㄧㄛㄥ
A29: 28 | B29: =IF(MOD(十五音韻母表[[#This Row],[序號]],2)=0, 十五音韻母表[[#This Row],[序號]]/2, ROUNDUP(十五音韻母表[[#This Row],[序號]]/2,0)) -> 14 | C29: 菊 | D29: 恭（促） | E29: ɪɔk̚ | G29: iok | H29: iok | I29: iok | J29: iok | K29: iook | L29: ㄧㆦㆻ | M29: ㄧㄛㄍ
A30: 29 | B30: =IF(MOD(十五音韻母表[[#This Row],[序號]],2)=0, 十五音韻母表[[#This Row],[序號]]/2, ROUNDUP(十五音韻母表[[#This Row],[序號]]/2,0)) -> 15 | C30: 刀 | D30: 高（舒） | E30: ə | G30: o | H30: o | I30: o | J30: o | K30: or | L30: ㄜ | M30: ㄜ
A31: 30 | B31: =IF(MOD(十五音韻母表[[#This Row],[序號]],2)=0, 十五音韻母表[[#This Row],[序號]]/2, ROUNDUP(十五音韻母表[[#This Row],[序號]]/2,0)) -> 15 | C31: 卓 | D31: 高（促） | E31: əʔ | G31: =IF(G30="", "", _xlfn.CONCAT(G30, "h")) -> oh | H31: =IF(H30="", "", _xlfn.CONCAT(H30, "h")) -> oh | I31: =IF(I30="", "", _xlfn.CONCAT(I30, "h")) -> oh | J31: =IF(J30="", "", _xlfn.CONCAT(J30, "h")) -> oh | K31: =IF(K30="", "", _xlfn.CONCAT(K30, "h")) -> orh | L31: =IF(L30="", "", _xlfn.CONCAT(L30, "ㆷ")) -> ㄜㆷ | M31: =IF(M30="", "", _xlfn.CONCAT(M30, "ㄏ")) -> ㄜㄏ
A32: 31 | B32: =IF(MOD(十五音韻母表[[#This Row],[序號]],2)=0, 十五音韻母表[[#This Row],[序號]]/2, ROUNDUP(十五音韻母表[[#This Row],[序號]]/2,0)) -> 16 | C32: 皆 | D32: 皆（舒） | E32: aɪ | G32: ai | H32: ai | I32: ai | J32: ai | K32: ai | L32: ㄞ | M32: ㄞ
A33: 32 | B33: =IF(MOD(十五音韻母表[[#This Row],[序號]],2)=0, 十五音韻母表[[#This Row],[序號]]/2, ROUNDUP(十五音韻母表[[#This Row],[序號]]/2,0)) -> 16 | G33: =IF(G32="", "", _xlfn.CONCAT(G32, "h")) -> aih | H33: =IF(H32="", "", _xlfn.CONCAT(H32, "h")) -> aih | I33: =IF(I32="", "", _xlfn.CONCAT(I32, "h")) -> aih | J33: =IF(J32="", "", _xlfn.CONCAT(J32, "h")) -> aih | K33: =IF(K32="", "", _xlfn.CONCAT(K32, "h")) -> aih | L33: =IF(L32="", "", _xlfn.CONCAT(L32, "ㆷ")) -> ㄞㆷ | M33: =IF(M32="", "", _xlfn.CONCAT(M32, "ㄏ")) -> ㄞㄏ
A34: 33 | B34: =IF(MOD(十五音韻母表[[#This Row],[序號]],2)=0, 十五音韻母表[[#This Row],[序號]]/2, ROUNDUP(十五音韻母表[[#This Row],[序號]]/2,0)) -> 17 | C34: 今 | D34: 巾（舒） | E34: in | G34: in | H34: in | I34: in | J34: in | K34: in | L34: ㄧㄣ | M34: ㄧㄣ
A35: 34 | B35: =IF(MOD(十五音韻母表[[#This Row],[序號]],2)=0, 十五音韻母表[[#This Row],[序號]]/2, ROUNDUP(十五音韻母表[[#This Row],[序號]]/2,0)) -> 17 | C35: 乞 | D35: 巾（促） | E35: it̚ | G35: it | H35: it | I35: it | J35: it | K35: it | L35: ㄧㆵ | M35: ㄧㄉ
A36: 35 | B36: =IF(MOD(十五音韻母表[[#This Row],[序號]],2)=0, 十五音韻母表[[#This Row],[序號]]/2, ROUNDUP(十五音韻母表[[#This Row],[序號]]/2,0)) -> 18 | C36: 漳 | D36: 姜（舒） | E36: ɪaŋ | G36: iang | H36: iang | I36: iang | J36: iang | K36: iang | L36: ㄧㄤ | M36: ㄧㄤ
A37: 36 | B37: =IF(MOD(十五音韻母表[[#This Row],[序號]],2)=0, 十五音韻母表[[#This Row],[序號]]/2, ROUNDUP(十五音韻母表[[#This Row],[序號]]/2,0)) -> 18 | C37: 鑠 | D37: 姜（促） | E37: ɪak̚ | G37: iak | H37: iak | I37: iak | J37: iak | K37: iak | L37: ㄧㄚㆻ | M37: ㄧㄚㄍ
A38: 37 | B38: =IF(MOD(十五音韻母表[[#This Row],[序號]],2)=0, 十五音韻母表[[#This Row],[序號]]/2, ROUNDUP(十五音韻母表[[#This Row],[序號]]/2,0)) -> 19 | C38: 堪 | D38: 甘（舒） | E38: am | G38: am | H38: am | I38: am | J38: am | K38: am | L38: ㆰ | M38: ㄚㄇ
A39: 38 | B39: =IF(MOD(十五音韻母表[[#This Row],[序號]],2)=0, 十五音韻母表[[#This Row],[序號]]/2, ROUNDUP(十五音韻母表[[#This Row],[序號]]/2,0)) -> 19 | C39: 合 | D39: 甘（促） | E39: ap̚ | G39: ap | H39: ap | I39: ap | J39: ap | K39: ap | L39: ㄚㆴ | M39: ㄚㄅ
A40: 39 | B40: =IF(MOD(十五音韻母表[[#This Row],[序號]],2)=0, 十五音韻母表[[#This Row],[序號]]/2, ROUNDUP(十五音韻母表[[#This Row],[序號]]/2,0)) -> 20 | C40: 呱 | D40: 瓜（舒） | E40: ua | G40: ua | H40: ua | I40: oa | J40: ua | K40: ua | L40: ㄨㄚ | M40: ㄨㄚ
...

Sheet 音調表
B2: 序號 | C2: W聲調名 | D2: 四聲八調 | E2: 八音調號 | F2: 台羅調號 | G2: 閩拼調號 | H2: 羅馬拼音聲調符號 | I2: 羅馬拼音聲調按鍵 | J2: 方音符號聲調符號 | K2: 方音符號聲調按鍵 | L2: 漢字 | M2: 台語音標 | N2: 按鍵輸入 | O2: 方音符號 | P2: 按鍵輸入2
B3: 1 | C3: 高音調 | D3: 陰平(a) | E3: 一 | F3: 1 | G3: 1 | H3: 1 | I3: ; | J3: 一 | K3: " | L3: 東 | M3: tong1 | N3: tong; | O3: ㄉㆲ | P3: ㄉㆲ【空白】
B4: 2 | C4: 中音調 | D4: 陽去(ā) | E4: 七 | F4: 7 | G4: 6 | H4: ˉ | I4: - | J4: ˫ | K4: 5 | L4: 洞 | M4: tong7 | N4: tong- | O4: ㄉㆲ˙ | P4: ㄉㆲ【3】
B5: 3 | C5: 低音調 | D5: 陰去(à) | E5: 三 | F5: 3 | G5: 5 | H5: ˋ | I5: _ | J5: ˪ | K5: 3 | L5: 棟 | M5: tong3 | N5: tong_ | O5: ㄉㆲ˪ | P5: ㄉㆲ【3】
B6: 4 | C6: 高降調 | D6: 陰上(á) | E6: 二 | F6: 2 | G6: 3 | H6: ˊ | I6: \ | J6: ˋ | K6: 4 | L6: 黨 | M6: tong2 | N6: tong\ | O6: ㄉㆲˋ | P6: ㄉㆲ【4】
B7: 6 | C7: 低升調 | D7: 陽平(â) | E7: 五 | F7: 5 | G7: 2 | H7: ˆ | I7: / | J7: ˊ | K7: 6 | L7: 同 | M7: tong5 | N7: tong/ | O7: ㄉㆲˊ | P7: ㄉㆲ【6】
B8: 7 | C8: 低促調 | D8: 陰入(ah) | E8: 四 | F8: 4 | G8: 7 | H8: 4 | I8: [ | J8: 四 | K8: [ | L8: 督 | M8: tok4 | N8: tok[ | O8: ㄉㆦㆻ | P8: ㄉㆦㆻ【空白】
B9: 8 | C9: 高促調 | D9: 陽入(a̍h) | E9: 八 | F9: 8 | G9: 8 | H9: ˈ | I9: ] | J9: ˙ | K9: ] | L9: 毒 | M9: tok8 | N9: tok] | O9: ㄉㆦㆻ˙ | P9: ㄉㆦㆻ【7】

Sheet 按鍵位置表
B1: URL | C1: https://alanjui.github.io/Blogger/assets/images/keys/key_ | I1: ver | J1: 2026-08-22_11:25
B2: 序號 | C2: 方音符號 | D2: 方音按鍵 | E2: 方音符號標籤 | F2: 台羅拼音 | G2: 鍵盤按鍵 | H2: 按鍵位置 | I2: Note | J2: Pict URL | K2: Pict
B3: 1 | C3: ㄅ | D3: ㄅ | E3: =_xlfn.CONCAT(按鍵位置表[[#This Row],[鍵盤按鍵]], " [",按鍵位置表[[#This Row],[方音符號]], "]") -> 1 [ㄅ] | F3: p | G3: 1 | H3: 1 | J3: =_xlfn.CONCAT(URL, H3, ".png", "?ver=$H$1") -> https://alanjui.github.io/Blogger/assets/images/keys/key_1.png?ver=$H$1 | K3: =IFERROR( _xlfn.IMAGE(按鍵位置表[[#This Row],[Pict URL]]), "") -> #VALUE!
B4: 2 | C4: ㆠ | D4: ㆠ | E4: =_xlfn.CONCAT(按鍵位置表[[#This Row],[鍵盤按鍵]], " [",按鍵位置表[[#This Row],[方音符號]], "]") -> ! [ㆠ] | F4: b | G4: ! | H4: 1 | J4: =_xlfn.CONCAT(URL, H4, ".png", "?ver=$H$1") -> https://alanjui.github.io/Blogger/assets/images/keys/key_1.png?ver=$H$1 | K4: =IFERROR( _xlfn.IMAGE(按鍵位置表[[#This Row],[Pict URL]]), "") -> #VALUE!
B5: 3 | C5: ㄆ | D5: ㄆ | E5: =_xlfn.CONCAT(按鍵位置表[[#This Row],[鍵盤按鍵]], " [",按鍵位置表[[#This Row],[方音符號]], "]") -> q [ㄆ] | F5: ph | G5: q | H5: q | J5: =_xlfn.CONCAT(URL, H5, ".png", "?ver=$H$1") -> https://alanjui.github.io/Blogger/assets/images/keys/key_q.png?ver=$H$1 | K5: =IFERROR( _xlfn.IMAGE(按鍵位置表[[#This Row],[Pict URL]]), "") -> #VALUE!
B6: 4 | C6: ㄇ | D6: ㄇ | E6: =_xlfn.CONCAT(按鍵位置表[[#This Row],[鍵盤按鍵]], " [",按鍵位置表[[#This Row],[方音符號]], "]") -> a [ㄇ] | F6: m | G6: a | H6: a | J6: =_xlfn.CONCAT(URL, H6, ".png", "?ver=$H$1") -> https://alanjui.github.io/Blogger/assets/images/keys/key_a.png?ver=$H$1 | K6: =IFERROR( _xlfn.IMAGE(按鍵位置表[[#This Row],[Pict URL]]), "") -> #VALUE!
B7: 5 | C7: ㄉ | D7: ㄉ | E7: =_xlfn.CONCAT(按鍵位置表[[#This Row],[鍵盤按鍵]], " [",按鍵位置表[[#This Row],[方音符號]], "]") -> 2 [ㄉ] | F7: t | G7: 2 | H7: 2 | J7: =_xlfn.CONCAT(URL, H7, ".png", "?ver=$H$1") -> https://alanjui.github.io/Blogger/assets/images/keys/key_2.png?ver=$H$1 | K7: =IFERROR( _xlfn.IMAGE(按鍵位置表[[#This Row],[Pict URL]]), "") -> #VALUE!
B8: 6 | C8: ㄊ | D8: ㄊ | E8: =_xlfn.CONCAT(按鍵位置表[[#This Row],[鍵盤按鍵]], " [",按鍵位置表[[#This Row],[方音符號]], "]") -> w [ㄊ] | F8: th | G8: w | H8: w | J8: =_xlfn.CONCAT(URL, H8, ".png", "?ver=$H$1") -> https://alanjui.github.io/Blogger/assets/images/keys/key_w.png?ver=$H$1 | K8: =IFERROR( _xlfn.IMAGE(按鍵位置表[[#This Row],[Pict URL]]), "") -> #VALUE!
B9: 7 | C9: ㄋ | D9: ㄋ | E9: =_xlfn.CONCAT(按鍵位置表[[#This Row],[鍵盤按鍵]], " [",按鍵位置表[[#This Row],[方音符號]], "]") -> s [ㄋ] | F9: n | G9: s | H9: s | J9: =_xlfn.CONCAT(URL, H9, ".png", "?ver=$H$1") -> https://alanjui.github.io/Blogger/assets/images/keys/key_s.png?ver=$H$1 | K9: =IFERROR( _xlfn.IMAGE(按鍵位置表[[#This Row],[Pict URL]]), "") -> #VALUE!
B10: 8 | C10: ㄌ | D10: ㄌ | E10: =_xlfn.CONCAT(按鍵位置表[[#This Row],[鍵盤按鍵]], " [",按鍵位置表[[#This Row],[方音符號]], "]") -> x [ㄌ] | F10: l | G10: x | H10: x | J10: =_xlfn.CONCAT(URL, H10, ".png", "?ver=$H$1") -> https://alanjui.github.io/Blogger/assets/images/keys/key_x.png?ver=$H$1 | K10: =IFERROR( _xlfn.IMAGE(按鍵位置表[[#This Row],[Pict URL]]), "") -> #VALUE!
B11: 9 | C11: ㄍ | D11: ㄍ | E11: =_xlfn.CONCAT(按鍵位置表[[#This Row],[鍵盤按鍵]], " [",按鍵位置表[[#This Row],[方音符號]], "]") -> e [ㄍ] | F11: k | G11: e | H11: e | J11: =_xlfn.CONCAT(URL, H11, ".png", "?ver=$H$1") -> https://alanjui.github.io/Blogger/assets/images/keys/key_e.png?ver=$H$1 | K11: =IFERROR( _xlfn.IMAGE(按鍵位置表[[#This Row],[Pict URL]]), "") -> #VALUE!
B12: 10 | C12: ㆣ | D12: ㆣ | E12: =_xlfn.CONCAT(按鍵位置表[[#This Row],[鍵盤按鍵]], " [",按鍵位置表[[#This Row],[方音符號]], "]") -> E [ㆣ] | F12: g | G12: E | H12: e | J12: =_xlfn.CONCAT(URL, H12, ".png", "?ver=$H$1") -> https://alanjui.github.io/Blogger/assets/images/keys/key_e.png?ver=$H$1 | K12: =IFERROR( _xlfn.IMAGE(按鍵位置表[[#This Row],[Pict URL]]), "") -> #VALUE!
B13: 11 | C13: ㄎ | D13: ㄎ | E13: =_xlfn.CONCAT(按鍵位置表[[#This Row],[鍵盤按鍵]], " [",按鍵位置表[[#This Row],[方音符號]], "]") -> d [ㄎ] | F13: kh | G13: d | H13: d | J13: =_xlfn.CONCAT(URL, H13, ".png", "?ver=$H$1") -> https://alanjui.github.io/Blogger/assets/images/keys/key_d.png?ver=$H$1 | K13: =IFERROR( _xlfn.IMAGE(按鍵位置表[[#This Row],[Pict URL]]), "") -> #VALUE!
B14: 12 | C14: ㄏ | D14: ㄏ | E14: =_xlfn.CONCAT(按鍵位置表[[#This Row],[鍵盤按鍵]], " [",按鍵位置表[[#This Row],[方音符號]], "]") -> c [ㄏ] | F14: h | G14: c | H14: c | J14: =_xlfn.CONCAT(URL, H14, ".png", "?ver=$H$1") -> https://alanjui.github.io/Blogger/assets/images/keys/key_c.png?ver=$H$1 | K14: =IFERROR( _xlfn.IMAGE(按鍵位置表[[#This Row],[Pict URL]]), "") -> #VALUE!
B15: 13 | C15: ㄐ | D15: ㄐ | E15: =_xlfn.CONCAT(按鍵位置表[[#This Row],[鍵盤按鍵]], " [",按鍵位置表[[#This Row],[方音符號]], "]") -> r [ㄐ] | F15: z(i) | G15: r | H15: r | J15: =_xlfn.CONCAT(URL, H15, ".png", "?ver=$H$1") -> https://alanjui.github.io/Blogger/assets/images/keys/key_r.png?ver=$H$1 | K15: =IFERROR( _xlfn.IMAGE(按鍵位置表[[#This Row],[Pict URL]]), "") -> #VALUE!
B16: 14 | C16: ㆢ | D16: ㆢ | E16: =_xlfn.CONCAT(按鍵位置表[[#This Row],[鍵盤按鍵]], " [",按鍵位置表[[#This Row],[方音符號]], "]") -> R [ㆢ] | F16: j(i) | G16: R | H16: r | J16: =_xlfn.CONCAT(URL, H16, ".png", "?ver=$H$1") -> https://alanjui.github.io/Blogger/assets/images/keys/key_r.png?ver=$H$1 | K16: =IFERROR( _xlfn.IMAGE(按鍵位置表[[#This Row],[Pict URL]]), "") -> #VALUE!
... B24: 22 | C24: ㄚ | D24: ㄚ | E24: =_xlfn.CONCAT(按鍵位置表[[#This Row],[鍵盤按鍵]], " [",按鍵位置表[[#This Row],[方音符號]], "]") -> 8 [ㄚ] | F24: a | G24: 8 | H24: 8 | J24: =_xlfn.CONCAT(URL, H24, ".png", "?ver=$H$1") -> https://alanjui.github.io/Blogger/assets/images/keys/key_8.png?ver=$H$1 | K24: =IFERROR( _xlfn.IMAGE(按鍵位置表[[#This Row],[Pict URL]]), "") -> #VALUE!
B25: 23 | C25: ㆩ | D25: ㆩ | E25: =_xlfn.CONCAT(按鍵位置表[[#This Row],[鍵盤按鍵]], " [",按鍵位置表[[#This Row],[方音符號]], "]") -> * [ㆩ] | F25: aⁿ | G25: * | H25: 8 | J25: =_xlfn.CONCAT(URL, H25, ".png", "?ver=$H$1") -> https://alanjui.github.io/Blogger/assets/images/keys/key_8.png?ver=$H$1 | K25: =IFERROR( _xlfn.IMAGE(按鍵位置表[[#This Row],[Pict URL]]), "") -> #VALUE!
B26: 24 | C26: ㄧ | D26: ㄧ | E26: =_xlfn.CONCAT(按鍵位置表[[#This Row],[鍵盤按鍵]], " [",按鍵位置表[[#This Row],[方音符號]], "]") -> u [ㄧ] | F26: i | G26: u | H26: u | J26: =_xlfn.CONCAT(URL, H26, ".png", "?ver=$H$1") -> https://alanjui.github.io/Blogger/assets/images/keys/key_u.png?ver=$H$1 | K26: =IFERROR( _xlfn.IMAGE(按鍵位置表[[#This Row],[Pict URL]]), "") -> #VALUE!
B27: 25 | C27: ㆪ | D27: ㆪ | E27: =_xlfn.CONCAT(按鍵位置表[[#This Row],[鍵盤按鍵]], " [",按鍵位置表[[#This Row],[方音符號]], "]") -> U [ㆪ] | F27: iⁿ | G27: U | H27: u | J27: =_xlfn.CONCAT(URL, H27, ".png", "?ver=$H$1") -> https://alanjui.github.io/Blogger/assets/images/keys/key_u.png?ver=$H$1 | K27: =IFERROR( _xlfn.IMAGE(按鍵位置表[[#This Row],[Pict URL]]), "") -> #VALUE!
B28: 26 | C28: ㄨ | D28: ㄨ | E28: =_xlfn.CONCAT(按鍵位置表[[#This Row],[鍵盤按鍵]], " [",按鍵位置表[[#This Row],[方音符號]], "]") -> j [ㄨ] | F28: u | G28: j | H28: j | J28: =_xlfn.CONCAT(URL, H28, ".png", "?ver=$H$1") -> https://alanjui.github.io/Blogger/assets/images/keys/key_j.png?ver=$H$1 | K28: =IFERROR( _xlfn.IMAGE(按鍵位置表[[#This Row],[Pict URL]]), "") -> #VALUE!
B29: 27 | C29: ㆫ | D29: ㆫ | E29: =_xlfn.CONCAT(按鍵位置表[[#This Row],[鍵盤按鍵]], " [",按鍵位置表[[#This Row],[方音符號]], "]") -> J [ㆫ] | F29: uⁿ | G29: J | H29: j | J29: =_xlfn.CONCAT(URL, H29, ".png", "?ver=$H$1") -> https://alanjui.github.io/Blogger/assets/images/keys/key_j.png?ver=$H$1 | K29: =IFERROR( _xlfn.IMAGE(按鍵位置表[[#This Row],[Pict URL]]), "") -> #VALUE!
B30: 28 | C30: ㆤ | D30: ㆤ | E30: =_xlfn.CONCAT(按鍵位置表[[#This Row],[鍵盤按鍵]], " [",按鍵位置表[[#This Row],[方音符號]], "]") -> , [ㆤ] | F30: e | G30: , | H30: comma | J30: =_xlfn.CONCAT(URL, H30, ".png", "?ver=$H$1") -> https://alanjui.github.io/Blogger/assets/images/keys/key_comma.png?ver=$H$1 | K30: =IFERROR( _xlfn.IMAGE(按鍵位置表[[#This Row],[Pict URL]]), "") -> #VALUE!
B31: 29 | C31: ㆥ | D31: ㆥ | E31: =_xlfn.CONCAT(按鍵位置表[[#This Row],[鍵盤按鍵]], " [",按鍵位置表[[#This Row],[方音符號]], "]") -> < [ㆥ] | F31: eⁿ | G31: < | H31: comma | J31: =_xlfn.CONCAT(URL, H31, ".png", "?ver=$H$1") -> https://alanjui.github.io/Blogger/assets/images/keys/key_comma.png?ver=$H$1 | K31: =IFERROR( _xlfn.IMAGE(按鍵位置表[[#This Row],[Pict URL]]), "") -> #VALUE!
B32: 30 | C32: ㆦ | D32: ㆦ | E32: =_xlfn.CONCAT(按鍵位置表[[#This Row],[鍵盤按鍵]], " [",按鍵位置表[[#This Row],[方音符號]], "]") -> i [ㆦ] | F32: oo | G32: i | H32: i | J32: =_xlfn.CONCAT(URL, H32, ".png", "?ver=$H$1") -> https://alanjui.github.io/Blogger/assets/images/keys/key_i.png?ver=$H$1 | K32: =IFERROR( _xlfn.IMAGE(按鍵位置表[[#This Row],[Pict URL]]), "") -> #VALUE!
B33: 31 | C33: ㆧ | D33: ㆧ | E33: =_xlfn.CONCAT(按鍵位置表[[#This Row],[鍵盤按鍵]], " [",按鍵位置表[[#This Row],[方音符號]], "]") -> I [ㆧ] | F33: oⁿ | G33: I | H33: i | J33: =_xlfn.CONCAT(URL, H33, ".png", "?ver=$H$1") -> https://alanjui.github.io/Blogger/assets/images/keys/key_i.png?ver=$H$1 | K33: =IFERROR( _xlfn.IMAGE(按鍵位置表[[#This Row],[Pict URL]]), "") -> #VALUE!
B34: 32 | C34: ㄜ | D34: ㄜ | E34: =_xlfn.CONCAT(按鍵位置表[[#This Row],[鍵盤按鍵]], " [",按鍵位置表[[#This Row],[方音符號]], "]") -> k [ㄜ] | F34: o | G34: k | H34: k | J34: =_xlfn.CONCAT(URL, H34, ".png", "?ver=$H$1") -> https://alanjui.github.io/Blogger/assets/images/keys/key_k.png?ver=$H$1 | K34: =IFERROR( _xlfn.IMAGE(按鍵位置表[[#This Row],[Pict URL]]), "") -> #VALUE!
B35: 33 | C35: ㆨ | D35: ㆨ | E35: =_xlfn.CONCAT(按鍵位置表[[#This Row],[鍵盤按鍵]], " [",按鍵位置表[[#This Row],[方音符號]], "]") -> K [ㆨ] | F35: ir | G35: K | H35: k | J35: =_xlfn.CONCAT(URL, H35, ".png", "?ver=$H$1") -> https://alanjui.github.io/Blogger/assets/images/keys/key_k.png?ver=$H$1 | K35: =IFERROR( _xlfn.IMAGE(按鍵位置表[[#This Row],[Pict URL]]), "") -> #VALUE!
B36: 34 | C36: ㄞ | D36: ㄞ | E36: =_xlfn.CONCAT(按鍵位置表[[#This Row],[鍵盤按鍵]], " [",按鍵位置表[[#This Row],[方音符號]], "]") -> 9 [ㄞ] | F36: ai | G36: 9 | H36: 9 | J36: =_xlfn.CONCAT(URL, H36, ".png", "?ver=$H$1") -> https://alanjui.github.io/Blogger/assets/images/keys/key_9.png?ver=$H$1 | K36: =IFERROR( _xlfn.IMAGE(按鍵位置表[[#This Row],[Pict URL]]), "") -> #VALUE!
B37: 35 | C37: ㆮ | D37: ㆮ | E37: =_xlfn.CONCAT(按鍵位置表[[#This Row],[鍵盤按鍵]], " [",按鍵位置表[[#This Row],[方音符號]], "]") -> ( [ㆮ] | F37: aiⁿ | G37: ( | H37: 9 | J37: =_xlfn.CONCAT(URL, H37, ".png", "?ver=$H$1") -> https://alanjui.github.io/Blogger/assets/images/keys/key_9.png?ver=$H$1 | K37: =IFERROR( _xlfn.IMAGE(按鍵位置表[[#This Row],[Pict URL]]), "") -> #VALUE!
B38: 36 | C38: ㄠ | D38: ㄠ | E38: =_xlfn.CONCAT(按鍵位置表[[#This Row],[鍵盤按鍵]], " [",按鍵位置表[[#This Row],[方音符號]], "]") -> l [ㄠ] | F38: au | G38: l | H38: l | J38: =_xlfn.CONCAT(URL, H38, ".png", "?ver=$H$1") -> https://alanjui.github.io/Blogger/assets/images/keys/key_l.png?ver=$H$1 | K38: =IFERROR( _xlfn.IMAGE(按鍵位置表[[#This Row],[Pict URL]]), "") -> #VALUE! | M38: ㄙㄧㄥˊ
B39: 37 | C39: ㆯ | D39: ㆯ | E39: =_xlfn.CONCAT(按鍵位置表[[#This Row],[鍵盤按鍵]], " [",按鍵位置表[[#This Row],[方音符號]], "]") -> L [ㆯ] | F39: auⁿ | G39: L | H39: l | J39: =_xlfn.CONCAT(URL, H39, ".png", "?ver=$H$1") -> https://alanjui.github.io/Blogger/assets/images/keys/key_l.png?ver=$H$1 | K39: =IFERROR( _xlfn.IMAGE(按鍵位置表[[#This Row],[Pict URL]]), "") -> #VALUE!
B40: 38 | C40: ㄢ | D40: ㄢ | E40: =_xlfn.CONCAT(按鍵位置表[[#This Row],[鍵盤按鍵]], " [",按鍵位置表[[#This Row],[方音符號]], "]") -> 0 [ㄢ] | F40: an | G40: 0 | H40: 0 | J40: =_xlfn.CONCAT(URL, H40, ".png", "?ver=$H$1") -> https://alanjui.github.io/Blogger/assets/images/keys/key_0.png?ver=$H$1 | K40: =IFERROR( _xlfn.IMAGE(按鍵位置表[[#This Row],[Pict URL]]), "") -> #VALUE!
B41: 39 | C41: ㄣ | D41: ㄣ | E41: =_xlfn.CONCAT(按鍵位置表[[#This Row],[鍵盤按鍵]], " [",按鍵位置表[[#This Row],[方音符號]], "]") -> p [ㄣ] | F41: -n | G41: p | H41: p | J41: =_xlfn.CONCAT(URL, H41, ".png", "?ver=$H$1") -> https://alanjui.github.io/Blogger/assets/images/keys/key_p.png?ver=$H$1 | K41: =IFERROR( _xlfn.IMAGE(按鍵位置表[[#This Row],[Pict URL]]), "") -> #VALUE!
B42: 40 | C42: ㄤ | D42: ㄤ | E42: =_xlfn.CONCAT(按鍵位置表[[#This Row],[鍵盤按鍵]], " [",按鍵位置表[[#This Row],[方音符號]], "]") -> ; [ㄤ] | F42: ang | G42: ; | H42: semicolon | J42: =_xlfn.CONCAT(URL, H42, ".png", "?ver=$H$1") -> https://alanjui.github.io/Blogger/assets/images/keys/key_semicolon.png?ver=$H$1 | K42: =IFERROR( _xlfn.IMAGE(按鍵位置表[[#This Row],[Pict URL]]), "") -> #VALUE!
B43: 41 | C43: ㆭ | D43: ㆭ | E43: =_xlfn.CONCAT(按鍵位置表[[#This Row],[鍵盤按鍵]], " [",按鍵位置表[[#This Row],[方音符號]], "]") -> / [ㆭ] | F43: -ng | G43: / | H43: slash | J43: =_xlfn.CONCAT(URL, H43, ".png", "?ver=$H$1") -> https://alanjui.github.io/Blogger/assets/images/keys/key_slash.png?ver=$H$1 | K43: =IFERROR( _xlfn.IMAGE(按鍵位置表[[#This Row],[Pict URL]]), "") -> #VALUE!
B44: 41 | C44: ㄥ | D44: ㄥ | E44: =E43 -> / [ㆭ] | F44: -ng | G44: / | H44: slash | J44: =_xlfn.CONCAT(URL, H44, ".png", "?ver=$H$1") -> https://alanjui.github.io/Blogger/assets/images/keys/key_slash.png?ver=$H$1 | K44: =IFERROR( _xlfn.IMAGE(按鍵位置表[[#This Row],[Pict URL]]), "") -> #VALUE!
B45: 42 | C45: ㆬ | D45: ㆬ | E45: =_xlfn.CONCAT(按鍵位置表[[#This Row],[鍵盤按鍵]], " [",按鍵位置表[[#This Row],[方音符號]], "]") -> m [ㆬ] | F45: -m | G45: m | H45: m | J45: =_xlfn.CONCAT(URL, H45, ".png", "?ver=$H$1") -> https://alanjui.github.io/Blogger/assets/images/keys/key_m.png?ver=$H$1 | K45: =IFERROR( _xlfn.IMAGE(按鍵位置表[[#This Row],[Pict URL]]), "") -> #VALUE!
B46: 43 | C46: ㆰ | D46: ㆰ | E46: =_xlfn.CONCAT(按鍵位置表[[#This Row],[鍵盤按鍵]], " [",按鍵位置表[[#This Row],[方音符號]], "]") -> M [ㆰ] | F46: am | G46: M | H46: m | J46: =_xlfn.CONCAT(URL, H46, ".png", "?ver=$H$1") -> https://alanjui.github.io/Blogger/assets/images/keys/key_m.png?ver=$H$1 | K46: =IFERROR( _xlfn.IMAGE(按鍵位置表[[#This Row],[Pict URL]]), "") -> #VALUE!
B47: 44 | C47: ㆲ | D47: ㆲ | E47: =_xlfn.CONCAT(按鍵位置表[[#This Row],[鍵盤按鍵]], " [",按鍵位置表[[#This Row],[方音符號]], "]") -> o [ㆲ] | F47: ong | G47: o | H47: o | J47: =_xlfn.CONCAT(URL, H47, ".png", "?ver=$H$1") -> https://alanjui.github.io/Blogger/assets/images/keys/key_o.png?ver=$H$1 | K47: =IFERROR( _xlfn.IMAGE(按鍵位置表[[#This Row],[Pict URL]]), "") -> #VALUE!
...

Sheet 打字練習表【台羅拼音】
B1: 聲母 | C1: 零ㄅㄆㄇㆠㄉㄊㄋㄌㄍㄎㆣㄏㄗㄘㆡㄙㄐㄑㆢㄒ | G1: Ø | H1: 零聲母 | I1: q
B3: 漢字 | C3: 十五音 | D3: 注音符號/ 拼音字母 | E3: 含零聲母 | F3: 聲母 | G3: 音調 | H3: 音調按鍵 | I3: 字母 | J3: 韻母 | K3: 輸入順序 | L3: 字長 | M3: 調號位置 | N3: 鍵盤按鍵
N4: 1 | O4: 2 | P4: 3 | Q4: 4 | R4: 5 | S4: 6 | T4: 7 | U4: 8
B5: 《 | D5: =IF(LEFT($E5)="Ø",SUBSTITUTE($E5, "Ø", ""), $E5) | E5: =IF($C5="","", _xlfn.CONCAT($F5, $J5, $G5)) | F5: =IFERROR( _xlfn.XLOOKUP(RIGHT($C5), 十五音聲母表[十八音],十五音聲母表[台羅拼音]), "" ) | G5: =IF($C5="", "", _xlfn.XLOOKUP(MID(C5,2,1), 音調表[八音調號], 音調表[台羅調號]) ) | H5: =IF($C5="", "", _xlfn.XLOOKUP(MID($C5,2,1), 音調表[八音調號], 音調表[羅馬拼音聲調按鍵]) ) | I5: =IF($C5="", "", IF(OR($G5=4,$G5=8), _xlfn.CONCAT(LEFT($C5),"（促）"), _xlfn.CONCAT(LEFT($C5),"（舒）"))) | J5: =IF($C5="", "", _xlfn.XLOOKUP($I5, 十五音韻母表[十五音],十五音韻母表[台羅拼音]) ) | K5: =IF($C5="","",_xlfn.CONCAT(J5,H5,F5)) | L5: =IF($C5="", "", LEN($D5)) | M5: =IF($C5="", "", LEN($J5)+1) | N5: =IF($M5="","", IF(MID($K5,N$4,1)="Ø", 零聲母, MID($K5,N$4,1))) | O5: =IF($M5="","", IF(MID($K5,O$4,1)="Ø", 零聲母, MID($K5,O$4,1))) | P5: =IF($M5="","", IF(MID($K5,P$4,1)="Ø", 零聲母, MID($K5,P$4,1))) | Q5: =IF($M5="","", IF(MID($K5,Q$4,1)="Ø", 零聲母, MID($K5,Q$4,1))) | R5: =IF($M5="","", IF(MID($K5,R$4,1)="Ø", 零聲母, MID($K5,R$4,1))) | S5: =IF($M5="","", IF(MID($K5,S$4,1)="Ø", 零聲母, MID($K5,S$4,1))) | T5: =IF($M5="","", IF(MID($K5,T$4,1)="Ø", 零聲母, MID($K5,T$4,1))) | U5: =IF($M5="","", IF(MID($K5,U$4,1)="Ø", 零聲母, MID($K5,U$4,1)))
B6: 涼 | C6: 姜五柳 | D6: =IF(LEFT($E6)="Ø",SUBSTITUTE($E6, "Ø", ""), $E6) -> liang5 | E6: =IF($C6="","", _xlfn.CONCAT($F6, $J6, $G6)) -> liang5 | F6: =IFERROR( _xlfn.XLOOKUP(RIGHT($C6), 十五音聲母表[十八音],十五音聲母表[台羅拼音]), "" ) -> l | G6: =IF($C6="", "", _xlfn.XLOOKUP(MID(C6,2,1), 音調表[八音調號], 音調表[台羅調號]) ) -> 5 | H6: =IF($C6="", "", _xlfn.XLOOKUP(MID($C6,2,1), 音調表[八音調號], 音調表[羅馬拼音聲調按鍵]) ) -> / | I6: =IF($C6="", "", IF(OR($G6=4,$G6=8), _xlfn.CONCAT(LEFT($C6),"（促）"), _xlfn.CONCAT(LEFT($C6),"（舒）"))) -> 姜（舒） | J6: =IF($C6="", "", _xlfn.XLOOKUP($I6, 十五音韻母表[十五音],十五音韻母表[台羅拼音]) ) -> iang | K6: =IF($C6="","",_xlfn.CONCAT(J6,H6,F6)) -> iang/l | L6: =IF($C6="", "", LEN($D6)) -> 6 | M6: =IF($C6="", "", LEN($J6)+1) -> 5 | N6: =IF($M6="","", IF(MID($K6,N$4,1)="Ø", 零聲母, MID($K6,N$4,1))) -> i | O6: =IF($M6="","", IF(MID($K6,O$4,1)="Ø", 零聲母, MID($K6,O$4,1))) -> a | P6: =IF($M6="","", IF(MID($K6,P$4,1)="Ø", 零聲母, MID($K6,P$4,1))) -> n | Q6: =IF($M6="","", IF(MID($K6,Q$4,1)="Ø", 零聲母, MID($K6,Q$4,1))) -> g | R6: =IF($M6="","", IF(MID($K6,R$4,1)="Ø", 零聲母, MID($K6,R$4,1))) -> / | S6: =IF($M6="","", IF(MID($K6,S$4,1)="Ø", 零聲母, MID($K6,S$4,1))) -> l | T6: =IF($M6="","", IF(MID($K6,T$4,1)="Ø", 零聲母, MID($K6,T$4,1))) | U6: =IF($M6="","", IF(MID($K6,U$4,1)="Ø", 零聲母, MID($K6,U$4,1)))
B7: 州 | C7: 丩一曾 | D7: =IF(LEFT($E7)="Ø",SUBSTITUTE($E7, "Ø", ""), $E7) -> tsiu1 | E7: =IF($C7="","", _xlfn.CONCAT($F7, $J7, $G7)) -> tsiu1 | F7: =IFERROR( _xlfn.XLOOKUP(RIGHT($C7), 十五音聲母表[十八音],十五音聲母表[台羅拼音]), "" ) -> ts | G7: =IF($C7="", "", _xlfn.XLOOKUP(MID(C7,2,1), 音調表[八音調號], 音調表[台羅調號]) ) -> 1 | H7: =IF($C7="", "", _xlfn.XLOOKUP(MID($C7,2,1), 音調表[八音調號], 音調表[羅馬拼音聲調按鍵]) ) -> ; | I7: =IF($C7="", "", IF(OR($G7=4,$G7=8), _xlfn.CONCAT(LEFT($C7),"（促）"), _xlfn.CONCAT(LEFT($C7),"（舒）"))) -> 丩（舒） | J7: =IF($C7="", "", _xlfn.XLOOKUP($I7, 十五音韻母表[十五音],十五音韻母表[台羅拼音]) ) -> iu | K7: =IF($C7="","",_xlfn.CONCAT(J7,H7,F7)) -> iu;ts | L7: =IF($C7="", "", LEN($D7)) -> 5 | M7: =IF($C7="", "", LEN($J7)+1) -> 3 | N7: =IF($M7="","", IF(MID($K7,N$4,1)="Ø", 零聲母, MID($K7,N$4,1))) -> i | O7: =IF($M7="","", IF(MID($K7,O$4,1)="Ø", 零聲母, MID($K7,O$4,1))) -> u | P7: =IF($M7="","", IF(MID($K7,P$4,1)="Ø", 零聲母, MID($K7,P$4,1))) -> ; | Q7: =IF($M7="","", IF(MID($K7,Q$4,1)="Ø", 零聲母, MID($K7,Q$4,1))) -> t | R7: =IF($M7="","", IF(MID($K7,R$4,1)="Ø", 零聲母, MID($K7,R$4,1))) -> s | S7: =IF($M7="","", IF(MID($K7,S$4,1)="Ø", 零聲母, MID($K7,S$4,1))) | T7: =IF($M7="","", IF(MID($K7,T$4,1)="Ø", 零聲母, MID($K7,T$4,1))) | U7: =IF($M7="","", IF(MID($K7,U$4,1)="Ø", 零聲母, MID($K7,U$4,1)))
B8: 詞 | C8: 艍五時 | D8: =IF(LEFT($E8)="Ø",SUBSTITUTE($E8, "Ø", ""), $E8) -> su5 | E8: =IF($C8="","", _xlfn.CONCAT($F8, $J8, $G8)) -> su5 | F8: =IFERROR( _xlfn.XLOOKUP(RIGHT($C8), 十五音聲母表[十八音],十五音聲母表[台羅拼音]), "" ) -> s | G8: =IF($C8="", "", _xlfn.XLOOKUP(MID(C8,2,1), 音調表[八音調號], 音調表[台羅調號]) ) -> 5 | H8: =IF($C8="", "", _xlfn.XLOOKUP(MID($C8,2,1), 音調表[八音調號], 音調表[羅馬拼音聲調按鍵]) ) -> / | I8: =IF($C8="", "", IF(OR($G8=4,$G8=8), _xlfn.CONCAT(LEFT($C8),"（促）"), _xlfn.CONCAT(LEFT($C8),"（舒）"))) -> 艍（舒） | J8: =IF($C8="", "", _xlfn.XLOOKUP($I8, 十五音韻母表[十五音],十五音韻母表[台羅拼音]) ) -> u | K8: =IF($C8="","",_xlfn.CONCAT(J8,H8,F8)) -> u/s | L8: =IF($C8="", "", LEN($D8)) -> 3 | M8: =IF($C8="", "", LEN($J8)+1) -> 2 | N8: =IF($M8="","", IF(MID($K8,N$4,1)="Ø", 零聲母, MID($K8,N$4,1))) -> u | O8: =IF($M8="","", IF(MID($K8,O$4,1)="Ø", 零聲母, MID($K8,O$4,1))) -> / | P8: =IF($M8="","", IF(MID($K8,P$4,1)="Ø", 零聲母, MID($K8,P$4,1))) -> s | Q8: =IF($M8="","", IF(MID($K8,Q$4,1)="Ø", 零聲母, MID($K8,Q$4,1))) | R8: =IF($M8="","", IF(MID($K8,R$4,1)="Ø", 零聲母, MID($K8,R$4,1))) | S8: =IF($M8="","", IF(MID($K8,S$4,1)="Ø", 零聲母, MID($K8,S$4,1))) | T8: =IF($M8="","", IF(MID($K8,T$4,1)="Ø", 零聲母, MID($K8,T$4,1))) | U8: =IF($M8="","", IF(MID($K8,U$4,1)="Ø", 零聲母, MID($K8,U$4,1)))
B9: 》 | D9: =IF(LEFT($E9)="Ø",SUBSTITUTE($E9, "Ø", ""), $E9) | E9: =IF($C9="","", _xlfn.CONCAT($F9, $J9, $G9)) | F9: =IFERROR( _xlfn.XLOOKUP(RIGHT($C9), 十五音聲母表[十八音],十五音聲母表[台羅拼音]), "" ) | G9: =IF($C9="", "", _xlfn.XLOOKUP(MID(C9,2,1), 音調表[八音調號], 音調表[台羅調號]) ) | H9: =IF($C9="", "", _xlfn.XLOOKUP(MID($C9,2,1), 音調表[八音調號], 音調表[羅馬拼音聲調按鍵]) ) | I9: =IF($C9="", "", IF(OR($G9=4,$G9=8), _xlfn.CONCAT(LEFT($C9),"（促）"), _xlfn.CONCAT(LEFT($C9),"（舒）"))) | J9: =IF($C9="", "", _xlfn.XLOOKUP($I9, 十五音韻母表[十五音],十五音韻母表[台羅拼音]) ) | K9: =IF($C9="","",_xlfn.CONCAT(J9,H9,F9)) | L9: =IF($C9="", "", LEN($D9)) | M9: =IF($C9="", "", LEN($J9)+1) | N9: =IF($M9="","", IF(MID($K9,N$4,1)="Ø", 零聲母, MID($K9,N$4,1))) | O9: =IF($M9="","", IF(MID($K9,O$4,1)="Ø", 零聲母, MID($K9,O$4,1))) | P9: =IF($M9="","", IF(MID($K9,P$4,1)="Ø", 零聲母, MID($K9,P$4,1))) | Q9: =IF($M9="","", IF(MID($K9,Q$4,1)="Ø", 零聲母, MID($K9,Q$4,1))) | R9: =IF($M9="","", IF(MID($K9,R$4,1)="Ø", 零聲母, MID($K9,R$4,1))) | S9: =IF($M9="","", IF(MID($K9,S$4,1)="Ø", 零聲母, MID($K9,S$4,1))) | T9: =IF($M9="","", IF(MID($K9,T$4,1)="Ø", 零聲母, MID($K9,T$4,1))) | U9: =IF($M9="","", IF(MID($K9,U$4,1)="Ø", 零聲母, MID($K9,U$4,1)))
B10: 王 | C10: 公五英 | D10: =IF(LEFT($E10)="Ø",SUBSTITUTE($E10, "Ø", ""), $E10) -> ong5 | E10: =IF($C10="","", _xlfn.CONCAT($F10, $J10, $G10)) -> Øong5 | F10: =IFERROR( _xlfn.XLOOKUP(RIGHT($C10), 十五音聲母表[十八音],十五音聲母表[台羅拼音]), "" ) -> Ø | G10: =IF($C10="", "", _xlfn.XLOOKUP(MID(C10,2,1), 音調表[八音調號], 音調表[台羅調號]) ) -> 5 | H10: =IF($C10="", "", _xlfn.XLOOKUP(MID($C10,2,1), 音調表[八音調號], 音調表[羅馬拼音聲調按鍵]) ) -> / | I10: =IF($C10="", "", IF(OR($G10=4,$G10=8), _xlfn.CONCAT(LEFT($C10),"（促）"), _xlfn.CONCAT(LEFT($C10),"（舒）"))) -> 公（舒） | J10: =IF($C10="", "", _xlfn.XLOOKUP($I10, 十五音韻母表[十五音],十五音韻母表[台羅拼音]) ) -> ong | K10: =IF($C10="","",_xlfn.CONCAT(J10,H10,F10)) -> ong/Ø | L10: =IF($C10="", "", LEN($D10)) -> 4 | M10: =IF($C10="", "", LEN($J10)+1) -> 4 | N10: =IF($M10="","", IF(MID($K10,N$4,1)="Ø", 零聲母, MID($K10,N$4,1))) -> o | O10: =IF($M10="","", IF(MID($K10,O$4,1)="Ø", 零聲母, MID($K10,O$4,1))) -> n | P10: =IF($M10="","", IF(MID($K10,P$4,1)="Ø", 零聲母, MID($K10,P$4,1))) -> g | Q10: =IF($M10="","", IF(MID($K10,Q$4,1)="Ø", 零聲母, MID($K10,Q$4,1))) -> / | R10: =IF($M10="","", IF(MID($K10,R$4,1)="Ø", 零聲母, MID($K10,R$4,1))) -> q | S10: =IF($M10="","", IF(MID($K10,S$4,1)="Ø", 零聲母, MID($K10,S$4,1))) | T10: =IF($M10="","", IF(MID($K10,T$4,1)="Ø", 零聲母, MID($K10,T$4,1))) | U10: =IF($M10="","", IF(MID($K10,U$4,1)="Ø", 零聲母, MID($K10,U$4,1)))
B11: 之 | C11: 居一曾 | D11: =IF(LEFT($E11)="Ø",SUBSTITUTE($E11, "Ø", ""), $E11) -> tsi1 | E11: =IF($C11="","", _xlfn.CONCAT($F11, $J11, $G11)) -> tsi1 | F11: =IFERROR( _xlfn.XLOOKUP(RIGHT($C11), 十五音聲母表[十八音],十五音聲母表[台羅拼音]), "" ) -> ts | G11: =IF($C11="", "", _xlfn.XLOOKUP(MID(C11,2,1), 音調表[八音調號], 音調表[台羅調號]) ) -> 1 | H11: =IF($C11="", "", _xlfn.XLOOKUP(MID($C11,2,1), 音調表[八音調號], 音調表[羅馬拼音聲調按鍵]) ) -> ; | I11: =IF($C11="", "", IF(OR($G11=4,$G11=8), _xlfn.CONCAT(LEFT($C11),"（促）"), _xlfn.CONCAT(LEFT($C11),"（舒）"))) -> 居（舒） | J11: =IF($C11="", "", _xlfn.XLOOKUP($I11, 十五音韻母表[十五音],十五音韻母表[台羅拼音]) ) -> i | K11: =IF($C11="","",_xlfn.CONCAT(J11,H11,F11)) -> i;ts | L11: =IF($C11="", "", LEN($D11)) -> 4 | M11: =IF($C11="", "", LEN($J11)+1) -> 2 | N11: =IF($M11="","", IF(MID($K11,N$4,1)="Ø", 零聲母, MID($K11,N$4,1))) -> i | O11: =IF($M11="","", IF(MID($K11,O$4,1)="Ø", 零聲母, MID($K11,O$4,1))) -> ; | P11: =IF($M11="","", IF(MID($K11,P$4,1)="Ø", 零聲母, MID($K11,P$4,1))) -> t | Q11: =IF($M11="","", IF(MID($K11,Q$4,1)="Ø", 零聲母, MID($K11,Q$4,1))) -> s | R11: =IF($M11="","", IF(MID($K11,R$4,1)="Ø", 零聲母, MID($K11,R$4,1))) | S11: =IF($M11="","", IF(MID($K11,S$4,1)="Ø", 零聲母, MID($K11,S$4,1))) | T11: =IF($M11="","", IF(MID($K11,T$4,1)="Ø", 零聲母, MID($K11,T$4,1))) | U11: =IF($M11="","", IF(MID($K11,U$4,1)="Ø", 零聲母, MID($K11,U$4,1)))
B12: 渙 | C12: 觀三喜 | D12: =IF(LEFT($E12)="Ø",SUBSTITUTE($E12, "Ø", ""), $E12) -> huan3 | E12: =IF($C12="","", _xlfn.CONCAT($F12, $J12, $G12)) -> huan3 | F12: =IFERROR( _xlfn.XLOOKUP(RIGHT($C12), 十五音聲母表[十八音],十五音聲母表[台羅拼音]), "" ) -> h | G12: =IF($C12="", "", _xlfn.XLOOKUP(MID(C12,2,1), 音調表[八音調號], 音調表[台羅調號]) ) -> 3 | H12: =IF($C12="", "", _xlfn.XLOOKUP(MID($C12,2,1), 音調表[八音調號], 音調表[羅馬拼音聲調按鍵]) ) -> _ | I12: =IF($C12="", "", IF(OR($G12=4,$G12=8), _xlfn.CONCAT(LEFT($C12),"（促）"), _xlfn.CONCAT(LEFT($C12),"（舒）"))) -> 觀（舒） | J12: =IF($C12="", "", _xlfn.XLOOKUP($I12, 十五音韻母表[十五音],十五音韻母表[台羅拼音]) ) -> uan | K12: =IF($C12="","",_xlfn.CONCAT(J12,H12,F12)) -> uan_h | L12: =IF($C12="", "", LEN($D12)) -> 5 | M12: =IF($C12="", "", LEN($J12)+1) -> 4 | N12: =IF($M12="","", IF(MID($K12,N$4,1)="Ø", 零聲母, MID($K12,N$4,1))) -> u | O12: =IF($M12="","", IF(MID($K12,O$4,1)="Ø", 零聲母, MID($K12,O$4,1))) -> a | P12: =IF($M12="","", IF(MID($K12,P$4,1)="Ø", 零聲母, MID($K12,P$4,1))) -> n | Q12: =IF($M12="","", IF(MID($K12,Q$4,1)="Ø", 零聲母, MID($K12,Q$4,1))) -> _ | R12: =IF($M12="","", IF(MID($K12,R$4,1)="Ø", 零聲母, MID($K12,R$4,1))) -> h | S12: =IF($M12="","", IF(MID($K12,S$4,1)="Ø", 零聲母, MID($K12,S$4,1))) | T12: =IF($M12="","", IF(MID($K12,T$4,1)="Ø", 零聲母, MID($K12,T$4,1))) | U12: =IF($M12="","", IF(MID($K12,U$4,1)="Ø", 零聲母, MID($K12,U$4,1)))
D13: =IF(LEFT($E13)="Ø",SUBSTITUTE($E13, "Ø", ""), $E13) | E13: =IF($C13="","", _xlfn.CONCAT($F13, $J13, $G13)) | F13: =IFERROR( _xlfn.XLOOKUP(RIGHT($C13), 十五音聲母表[十八音],十五音聲母表[台羅拼音]), "" ) | G13: =IF($C13="", "", _xlfn.XLOOKUP(MID(C13,2,1), 音調表[八音調號], 音調表[台羅調號]) ) | H13: =IF($C13="", "", _xlfn.XLOOKUP(MID($C13,2,1), 音調表[八音調號], 音調表[羅馬拼音聲調按鍵]) ) | I13: =IF($C13="", "", IF(OR($G13=4,$G13=8), _xlfn.CONCAT(LEFT($C13),"（促）"), _xlfn.CONCAT(LEFT($C13),"（舒）"))) | J13: =IF($C13="", "", _xlfn.XLOOKUP($I13, 十五音韻母表[十五音],十五音韻母表[台羅拼音]) ) | K13: =IF($C13="","",_xlfn.CONCAT(J13,H13,F13)) | L13: =IF($C13="", "", LEN($D13)) | M13: =IF($C13="", "", LEN($J13)+1) | N13: =IF($M13="","", IF(MID($K13,N$4,1)="Ø", 零聲母, MID($K13,N$4,1))) | O13: =IF($M13="","", IF(MID($K13,O$4,1)="Ø", 零聲母, MID($K13,O$4,1))) | P13: =IF($M13="","", IF(MID($K13,P$4,1)="Ø", 零聲母, MID($K13,P$4,1))) | Q13: =IF($M13="","", IF(MID($K13,Q$4,1)="Ø", 零聲母, MID($K13,Q$4,1))) | R13: =IF($M13="","", IF(MID($K13,R$4,1)="Ø", 零聲母, MID($K13,R$4,1))) | S13: =IF($M13="","", IF(MID($K13,S$4,1)="Ø", 零聲母, MID($K13,S$4,1))) | T13: =IF($M13="","", IF(MID($K13,T$4,1)="Ø", 零聲母, MID($K13,T$4,1))) | U13: =IF($M13="","", IF(MID($K13,U$4,1)="Ø", 零聲母, MID($K13,U$4,1)))
B14: 黃 | C14: 公五喜 | D14: =IF(LEFT($E14)="Ø",SUBSTITUTE($E14, "Ø", ""), $E14) -> hong5 | E14: =IF($C14="","", _xlfn.CONCAT($F14, $J14, $G14)) -> hong5 | F14: =IFERROR( _xlfn.XLOOKUP(RIGHT($C14), 十五音聲母表[十八音],十五音聲母表[台羅拼音]), "" ) -> h | G14: =IF($C14="", "", _xlfn.XLOOKUP(MID(C14,2,1), 音調表[八音調號], 音調表[台羅調號]) ) -> 5 | H14: =IF($C14="", "", _xlfn.XLOOKUP(MID($C14,2,1), 音調表[八音調號], 音調表[羅馬拼音聲調按鍵]) ) -> / | I14: =IF($C14="", "", IF(OR($G14=4,$G14=8), _xlfn.CONCAT(LEFT($C14),"（促）"), _xlfn.CONCAT(LEFT($C14),"（舒）"))) -> 公（舒） | J14: =IF($C14="", "", _xlfn.XLOOKUP($I14, 十五音韻母表[十五音],十五音韻母表[台羅拼音]) ) -> ong | K14: =IF($C14="","",_xlfn.CONCAT(J14,H14,F14)) -> ong/h | L14: =IF($C14="", "", LEN($D14)) -> 5 | M14: =IF($C14="", "", LEN($J14)+1) -> 4 | N14: =IF($M14="","", IF(MID($K14,N$4,1)="Ø", 零聲母, MID($K14,N$4,1))) -> o | O14: =IF($M14="","", IF(MID($K14,O$4,1)="Ø", 零聲母, MID($K14,O$4,1))) -> n | P14: =IF($M14="","", IF(MID($K14,P$4,1)="Ø", 零聲母, MID($K14,P$4,1))) -> g | Q14: =IF($M14="","", IF(MID($K14,Q$4,1)="Ø", 零聲母, MID($K14,Q$4,1))) -> / | R14: =IF($M14="","", IF(MID($K14,R$4,1)="Ø", 零聲母, MID($K14,R$4,1))) -> h | S14: =IF($M14="","", IF(MID($K14,S$4,1)="Ø", 零聲母, MID($K14,S$4,1))) | T14: =IF($M14="","", IF(MID($K14,T$4,1)="Ø", 零聲母, MID($K14,T$4,1))) | U14: =IF($M14="","", IF(MID($K14,U$4,1)="Ø", 零聲母, MID($K14,U$4,1)))
B15: 河 | C15: 高五喜 | D15: =IF(LEFT($E15)="Ø",SUBSTITUTE($E15, "Ø", ""), $E15) -> ho5 | E15: =IF($C15="","", _xlfn.CONCAT($F15, $J15, $G15)) -> ho5 | F15: =IFERROR( _xlfn.XLOOKUP(RIGHT($C15), 十五音聲母表[十八音],十五音聲母表[台羅拼音]), "" ) -> h | G15: =IF($C15="", "", _xlfn.XLOOKUP(MID(C15,2,1), 音調表[八音調號], 音調表[台羅調號]) ) -> 5 | H15: =IF($C15="", "", _xlfn.XLOOKUP(MID($C15,2,1), 音調表[八音調號], 音調表[羅馬拼音聲調按鍵]) ) -> / | I15: =IF($C15="", "", IF(OR($G15=4,$G15=8), _xlfn.CONCAT(LEFT($C15),"（促）"), _xlfn.CONCAT(LEFT($C15),"（舒）"))) -> 高（舒） | J15: =IF($C15="", "", _xlfn.XLOOKUP($I15, 十五音韻母表[十五音],十五音韻母表[台羅拼音]) ) -> o | K15: =IF($C15="","",_xlfn.CONCAT(J15,H15,F15)) -> o/h | L15: =IF($C15="", "", LEN($D15)) -> 3 | M15: =IF($C15="", "", LEN($J15)+1) -> 2 | N15: =IF($M15="","", IF(MID($K15,N$4,1)="Ø", 零聲母, MID($K15,N$4,1))) -> o | O15: =IF($M15="","", IF(MID($K15,O$4,1)="Ø", 零聲母, MID($K15,O$4,1))) -> / | P15: =IF($M15="","", IF(MID($K15,P$4,1)="Ø", 零聲母, MID($K15,P$4,1))) -> h | Q15: =IF($M15="","", IF(MID($K15,Q$4,1)="Ø", 零聲母, MID($K15,Q$4,1))) | R15: =IF($M15="","", IF(MID($K15,R$4,1)="Ø", 零聲母, MID($K15,R$4,1))) | S15: =IF($M15="","", IF(MID($K15,S$4,1)="Ø", 零聲母, MID($K15,S$4,1))) | T15: =IF($M15="","", IF(MID($K15,T$4,1)="Ø", 零聲母, MID($K15,T$4,1))) | U15: =IF($M15="","", IF(MID($K15,U$4,1)="Ø", 零聲母, MID($K15,U$4,1)))
B16: 遠 | C16: 觀二英 | D16: =IF(LEFT($E16)="Ø",SUBSTITUTE($E16, "Ø", ""), $E16) -> uan2 | E16: =IF($C16="","", _xlfn.CONCAT($F16, $J16, $G16)) -> Øuan2 | F16: =IFERROR( _xlfn.XLOOKUP(RIGHT($C16), 十五音聲母表[十八音],十五音聲母表[台羅拼音]), "" ) -> Ø | G16: =IF($C16="", "", _xlfn.XLOOKUP(MID(C16,2,1), 音調表[八音調號], 音調表[台羅調號]) ) -> 2 | H16: =IF($C16="", "", _xlfn.XLOOKUP(MID($C16,2,1), 音調表[八音調號], 音調表[羅馬拼音聲調按鍵]) ) -> \ | I16: =IF($C16="", "", IF(OR($G16=4,$G16=8), _xlfn.CONCAT(LEFT($C16),"（促）"), _xlfn.CONCAT(LEFT($C16),"（舒）"))) -> 觀（舒） | J16: =IF($C16="", "", _xlfn.XLOOKUP($I16, 十五音韻母表[十五音],十五音韻母表[台羅拼音]) ) -> uan | K16: =IF($C16="","",_xlfn.CONCAT(J16,H16,F16)) -> uan\Ø | L16: =IF($C16="", "", LEN($D16)) -> 4 | M16: =IF($C16="", "", LEN($J16)+1) -> 4 | N16: =IF($M16="","", IF(MID($K16,N$4,1)="Ø", 零聲母, MID($K16,N$4,1))) -> u | O16: =IF($M16="","", IF(MID($K16,O$4,1)="Ø", 零聲母, MID($K16,O$4,1))) -> a | P16: =IF($M16="","", IF(MID($K16,P$4,1)="Ø", 零聲母, MID($K16,P$4,1))) -> n | Q16: =IF($M16="","", IF(MID($K16,Q$4,1)="Ø", 零聲母, MID($K16,Q$4,1))) -> \ | R16: =IF($M16="","", IF(MID($K16,R$4,1)="Ø", 零聲母, MID($K16,R$4,1))) -> q | S16: =IF($M16="","", IF(MID($K16,S$4,1)="Ø", 零聲母, MID($K16,S$4,1))) | T16: =IF($M16="","", IF(MID($K16,T$4,1)="Ø", 零聲母, MID($K16,T$4,1))) | U16: =IF($M16="","", IF(MID($K16,U$4,1)="Ø", 零聲母, MID($K16,U$4,1)))
B17: 上 | C17: 恭二時 | D17: =IF(LEFT($E17)="Ø",SUBSTITUTE($E17, "Ø", ""), $E17) -> siong2 | E17: =IF($C17="","", _xlfn.CONCAT($F17, $J17, $G17)) -> siong2 | F17: =IFERROR( _xlfn.XLOOKUP(RIGHT($C17), 十五音聲母表[十八音],十五音聲母表[台羅拼音]), "" ) -> s | G17: =IF($C17="", "", _xlfn.XLOOKUP(MID(C17,2,1), 音調表[八音調號], 音調表[台羅調號]) ) -> 2 | H17: =IF($C17="", "", _xlfn.XLOOKUP(MID($C17,2,1), 音調表[八音調號], 音調表[羅馬拼音聲調按鍵]) ) -> \ | I17: =IF($C17="", "", IF(OR($G17=4,$G17=8), _xlfn.CONCAT(LEFT($C17),"（促）"), _xlfn.CONCAT(LEFT($C17),"（舒）"))) -> 恭（舒） | J17: =IF($C17="", "", _xlfn.XLOOKUP($I17, 十五音韻母表[十五音],十五音韻母表[台羅拼音]) ) -> iong | K17: =IF($C17="","",_xlfn.CONCAT(J17,H17,F17)) -> iong\s | L17: =IF($C17="", "", LEN($D17)) -> 6 | M17: =IF($C17="", "", LEN($J17)+1) -> 5 | N17: =IF($M17="","", IF(MID($K17,N$4,1)="Ø", 零聲母, MID($K17,N$4,1))) -> i | O17: =IF($M17="","", IF(MID($K17,O$4,1)="Ø", 零聲母, MID($K17,O$4,1))) -> o | P17: =IF($M17="","", IF(MID($K17,P$4,1)="Ø", 零聲母, MID($K17,P$4,1))) -> n | Q17: =IF($M17="","", IF(MID($K17,Q$4,1)="Ø", 零聲母, MID($K17,Q$4,1))) -> g | R17: =IF($M17="","", IF(MID($K17,R$4,1)="Ø", 零聲母, MID($K17,R$4,1))) -> \ | S17: =IF($M17="","", IF(MID($K17,S$4,1)="Ø", 零聲母, MID($K17,S$4,1))) -> s | T17: =IF($M17="","", IF(MID($K17,T$4,1)="Ø", 零聲母, MID($K17,T$4,1))) | U17: =IF($M17="","", IF(MID($K17,U$4,1)="Ø", 零聲母, MID($K17,U$4,1)))
B18: 白 | C18: 經八邊 | D18: =IF(LEFT($E18)="Ø",SUBSTITUTE($E18, "Ø", ""), $E18) -> pik8 | E18: =IF($C18="","", _xlfn.CONCAT($F18, $J18, $G18)) -> pik8 | F18: =IFERROR( _xlfn.XLOOKUP(RIGHT($C18), 十五音聲母表[十八音],十五音聲母表[台羅拼音]), "" ) -> p | G18: =IF($C18="", "", _xlfn.XLOOKUP(MID(C18,2,1), 音調表[八音調號], 音調表[台羅調號]) ) -> 8 | H18: =IF($C18="", "", _xlfn.XLOOKUP(MID($C18,2,1), 音調表[八音調號], 音調表[羅馬拼音聲調按鍵]) ) -> ] | I18: =IF($C18="", "", IF(OR($G18=4,$G18=8), _xlfn.CONCAT(LEFT($C18),"（促）"), _xlfn.CONCAT(LEFT($C18),"（舒）"))) -> 經（促） | J18: =IF($C18="", "", _xlfn.XLOOKUP($I18, 十五音韻母表[十五音],十五音韻母表[台羅拼音]) ) -> ik | K18: =IF($C18="","",_xlfn.CONCAT(J18,H18,F18)) -> ik]p | L18: =IF($C18="", "", LEN($D18)) -> 4 | M18: =IF($C18="", "", LEN($J18)+1) -> 3 | N18: =IF($M18="","", IF(MID($K18,N$4,1)="Ø", 零聲母, MID($K18,N$4,1))) -> i | O18: =IF($M18="","", IF(MID($K18,O$4,1)="Ø", 零聲母, MID($K18,O$4,1))) -> k | P18: =IF($M18="","", IF(MID($K18,P$4,1)="Ø", 零聲母, MID($K18,P$4,1))) -> ] | Q18: =IF($M18="","", IF(MID($K18,Q$4,1)="Ø", 零聲母, MID($K18,Q$4,1))) -> p | R18: =IF($M18="","", IF(MID($K18,R$4,1)="Ø", 零聲母, MID($K18,R$4,1))) | S18: =IF($M18="","", IF(MID($K18,S$4,1)="Ø", 零聲母, MID($K18,S$4,1))) | T18: =IF($M18="","", IF(MID($K18,T$4,1)="Ø", 零聲母, MID($K18,T$4,1))) | U18: =IF($M18="","", IF(MID($K18,U$4,1)="Ø", 零聲母, MID($K18,U$4,1)))
