Workbook
Name URL: 打字練習表!$S$1
Name 覩9: 漢字注音!$A$5

Sheet 漢字注音
A1: =COLUMN() -> 1 | B1: =COLUMN() -> 2 | C1: =COLUMN() -> 3
V2: =LEN(V3) -> 45
V3: 《涼州詞》王之渙 黃河遠上白雲間， 一片孤城萬仞山。 羌笛何須怨楊柳， 春風不度玉門關。
E4: liang5 | F4: ziu1 | G4: su5 | I4: ong5 | J4: zi1 | K4: huan3
B5: 1 | D5: 《 | E5: 涼 | F5: 州 | G5: 詞 | H5: 》 | I5: 王 | J5: 之 | K5: 渙 | L5: =CHAR(10)
E6: ㄌㄧㄤˊ | F6: ㄐㄧㄨ | G6: ㄙㄨˊ | I6: ㆲˊ | J6: ㄐㄧ | K6: ㄏㄨㄢ˪
D8: hong5 | E8: ho5 | F8: uan2 | G8: siong2 | H8: pik8 | I8: hun5 | J8: kan1
B9: =B5+1 -> 2 | D9: 黃 | E9: 河 | F9: 遠 | G9: 上 | H9: 白 | I9: 雲 | J9: 間 | K9: ， | L9: =CHAR(10)
D10: ㄏㆲˊ | E10: ㄏㄜˊ | F10: ㄨㄢˋ | G10: ㄒㄧㆲˋ | H10: ㄅㄧㆻ˙ | I10: ㄏㄨㄣˊ | J10: ㄍㄢ
D12: it4 | E12: phian3 | F12: koo1 | G12: sing5 | H12: ban7 | I12: jin7 | J12: san1
B13: =B9+1 -> 3 | D13: 一 | E13: 片 | F13: 孤 | G13: 城 | H13: 萬 | I13: 仞 | J13: 山 | K13: 。 | L13: =CHAR(10)
D14: ㄧㆵ | E14: ㄆㄧㄢ˪ | F14: ㄍㆦ | G14: ㄒㄧㄥˊ | H14: ㆠㄢ˫ | I14: ㆢㄧㄣ˫ | J14: ㄙㄢ
E15: tik8
D16: khiang1 | E16: tik8 | F16: ho5 | G16: su1 | H16: uan3 | I16: iong5 | J16: liu2
B17: =B13+1 -> 4 | D17: 羌 | E17: 笛 | F17: 何 | G17: 須 | H17: 怨 | I17: 楊 | J17: 柳 | K17: ， | L17: =CHAR(10)
D18: ㄎㄧㄤ | E18: ㄉㄧㆻ˙ | F18: ㄏㄜˊ | G18: ㄙㄨ | H18: ㄨㄢ˪ | I18: ㄧㆲˊ | J18: ㄌㄧㄨˋ
D20: cun1 | E20: hong1 | F20: put4 | G20: too7 | H20: giok8 | I20: bun5 | J20: kuan1
B21: =B17+1 -> 5 | D21: 春 | E21: 風 | F21: 不 | G21: 度 | H21: 玉 | I21: 門 | J21: 關 | K21: 。 | L21: =CHAR(10)
D22: ㄘㄨㄣ | E22: ㄏㆲ | F22: ㄅㄨㆵ | G22: ㄉㆦ˫ | H22: ㆣㄧㆦㆻ˙ | I22: ㆠㄨㄣˊ | J22: ㄍㄨㄢ
B25: =B21+1 -> 6 | D25: φ
B29: =B25+1 -> 7
B33: =B29+1 -> 8
B37: =B33+1 -> 9
B41: =B37+1 -> 10
B45: =B41+1 -> 11
B49: =B45+1 -> 12
B53: =B49+1 -> 13
B57: =B53+1 -> 14
B61: =B57+1 -> 15
B65: =B61+1 -> 16
B69: =B65+1 -> 17
B73: =B69+1 -> 18
... B2001: =B1997+1 -> 500

Sheet 按鍵位置表
B2: 序號 | C2: 方音符號 | D2: 台羅拼音 | E2: 鍵盤按鍵 | F2: 按鍵位置 | G2: Note | H2: Pict URL | I2: Pict
B3: 1 | C3: ㄅ | D3: p | E3: 1 | F3: 1 | H3: =_xlfn.CONCAT(URL, F3, ".png") -> https://alanjui.github.io/Blogger/assets/images/keys/key_1.png | I3: =IFERROR( _xlfn.IMAGE(按鍵位置表[[#This Row],[Pict URL]]), "") -> #VALUE!
B4: 2 | C4: ㆠ | D4: b | E4: ! | F4: 1 | H4: =_xlfn.CONCAT(URL, F4, ".png") -> https://alanjui.github.io/Blogger/assets/images/keys/key_1.png | I4: =IFERROR( _xlfn.IMAGE(按鍵位置表[[#This Row],[Pict URL]]), "") -> #VALUE!
B5: 3 | C5: ㄆ | D5: ph | E5: q | F5: q | H5: =_xlfn.CONCAT(URL, F5, ".png") -> https://alanjui.github.io/Blogger/assets/images/keys/key_q.png | I5: =IFERROR( _xlfn.IMAGE(按鍵位置表[[#This Row],[Pict URL]]), "") -> #VALUE!
B6: 4 | C6: ㄇ | D6: m | E6: a | F6: a | H6: =_xlfn.CONCAT(URL, F6, ".png") -> https://alanjui.github.io/Blogger/assets/images/keys/key_a.png | I6: =IFERROR( _xlfn.IMAGE(按鍵位置表[[#This Row],[Pict URL]]), "") -> #VALUE!
B7: 5 | C7: ㄉ | D7: t | E7: 2 | F7: 2 | H7: =_xlfn.CONCAT(URL, F7, ".png") -> https://alanjui.github.io/Blogger/assets/images/keys/key_2.png | I7: =IFERROR( _xlfn.IMAGE(按鍵位置表[[#This Row],[Pict URL]]), "") -> #VALUE!
B8: 6 | C8: ㄊ | D8: th | E8: w | F8: w | H8: =_xlfn.CONCAT(URL, F8, ".png") -> https://alanjui.github.io/Blogger/assets/images/keys/key_w.png | I8: =IFERROR( _xlfn.IMAGE(按鍵位置表[[#This Row],[Pict URL]]), "") -> #VALUE!
B9: 7 | C9: ㄋ | D9: n | E9: s | F9: s | H9: =_xlfn.CONCAT(URL, F9, ".png") -> https://alanjui.github.io/Blogger/assets/images/keys/key_s.png | I9: =IFERROR( _xlfn.IMAGE(按鍵位置表[[#This Row],[Pict URL]]), "") -> #VALUE!
B10: 8 | C10: ㄌ | D10: l | E10: x | F10: x | H10: =_xlfn.CONCAT(URL, F10, ".png") -> https://alanjui.github.io/Blogger/assets/images/keys/key_x.png | I10: =IFERROR( _xlfn.IMAGE(按鍵位置表[[#This Row],[Pict URL]]), "") -> #VALUE!
B11: 9 | C11: ㄍ | D11: k | E11: e | F11: e | H11: =_xlfn.CONCAT(URL, F11, ".png") -> https://alanjui.github.io/Blogger/assets/images/keys/key_e.png | I11: =IFERROR( _xlfn.IMAGE(按鍵位置表[[#This Row],[Pict URL]]), "") -> #VALUE!
B12: 10 | C12: ㆣ | D12: g | E12: E | F12: e | H12: =_xlfn.CONCAT(URL, F12, ".png") -> https://alanjui.github.io/Blogger/assets/images/keys/key_e.png | I12: =IFERROR( _xlfn.IMAGE(按鍵位置表[[#This Row],[Pict URL]]), "") -> #VALUE!
B13: 11 | C13: ㄎ | D13: kh | E13: d | F13: d | H13: =_xlfn.CONCAT(URL, F13, ".png") -> https://alanjui.github.io/Blogger/assets/images/keys/key_d.png | I13: =IFERROR( _xlfn.IMAGE(按鍵位置表[[#This Row],[Pict URL]]), "") -> #VALUE!
B14: 12 | C14: ㄏ | D14: h | E14: c | F14: c | H14: =_xlfn.CONCAT(URL, F14, ".png") -> https://alanjui.github.io/Blogger/assets/images/keys/key_c.png | I14: =IFERROR( _xlfn.IMAGE(按鍵位置表[[#This Row],[Pict URL]]), "") -> #VALUE!
B15: 13 | C15: ㄐ | D15: z(i) | E15: r | F15: r | H15: =_xlfn.CONCAT(URL, F15, ".png") -> https://alanjui.github.io/Blogger/assets/images/keys/key_r.png | I15: =IFERROR( _xlfn.IMAGE(按鍵位置表[[#This Row],[Pict URL]]), "") -> #VALUE!
B16: 14 | C16: ㆢ | D16: j(i) | E16: R | F16: r | H16: =_xlfn.CONCAT(URL, F16, ".png") -> https://alanjui.github.io/Blogger/assets/images/keys/key_r.png | I16: =IFERROR( _xlfn.IMAGE(按鍵位置表[[#This Row],[Pict URL]]), "") -> #VALUE!
... B24: 22 | C24: ㄚ | D24: a | E24: 8 | F24: 8 | H24: =_xlfn.CONCAT(URL, F24, ".png") -> https://alanjui.github.io/Blogger/assets/images/keys/key_8.png | I24: =IFERROR( _xlfn.IMAGE(按鍵位置表[[#This Row],[Pict URL]]), "") -> #VALUE!
B25: 23 | C25: ㆩ | D25: aⁿ | E25: * | F25: 8 | H25: =_xlfn.CONCAT(URL, F25, ".png") -> https://alanjui.github.io/Blogger/assets/images/keys/key_8.png | I25: =IFERROR( _xlfn.IMAGE(按鍵位置表[[#This Row],[Pict URL]]), "") -> #VALUE!
B26: 24 | C26: ㄧ | D26: i | E26: u | F26: u | H26: =_xlfn.CONCAT(URL, F26, ".png") -> https://alanjui.github.io/Blogger/assets/images/keys/key_u.png | I26: =IFERROR( _xlfn.IMAGE(按鍵位置表[[#This Row],[Pict URL]]), "") -> #VALUE!
B27: 25 | C27: ㆪ | D27: iⁿ | E27: U | F27: u | H27: =_xlfn.CONCAT(URL, F27, ".png") -> https://alanjui.github.io/Blogger/assets/images/keys/key_u.png | I27: =IFERROR( _xlfn.IMAGE(按鍵位置表[[#This Row],[Pict URL]]), "") -> #VALUE!
B28: 26 | C28: ㄨ | D28: u | E28: j | F28: j | H28: =_xlfn.CONCAT(URL, F28, ".png") -> https://alanjui.github.io/Blogger/assets/images/keys/key_j.png | I28: =IFERROR( _xlfn.IMAGE(按鍵位置表[[#This Row],[Pict URL]]), "") -> #VALUE!
B29: 27 | C29: ㆫ | D29: uⁿ | E29: J | F29: j | H29: =_xlfn.CONCAT(URL, F29, ".png") -> https://alanjui.github.io/Blogger/assets/images/keys/key_j.png | I29: =IFERROR( _xlfn.IMAGE(按鍵位置表[[#This Row],[Pict URL]]), "") -> #VALUE!
B30: 28 | C30: ㆤ | D30: e | E30: , | F30: comma | H30: =_xlfn.CONCAT(URL, F30, ".png") -> https://alanjui.github.io/Blogger/assets/images/keys/key_comma.png | I30: =IFERROR( _xlfn.IMAGE(按鍵位置表[[#This Row],[Pict URL]]), "") -> #VALUE!
B31: 29 | C31: ㆥ | D31: eⁿ | E31: < | F31: comma | H31: =_xlfn.CONCAT(URL, F31, ".png") -> https://alanjui.github.io/Blogger/assets/images/keys/key_comma.png | I31: =IFERROR( _xlfn.IMAGE(按鍵位置表[[#This Row],[Pict URL]]), "") -> #VALUE!
B32: 30 | C32: ㆦ | D32: oo | E32: i | F32: i | H32: =_xlfn.CONCAT(URL, F32, ".png") -> https://alanjui.github.io/Blogger/assets/images/keys/key_i.png | I32: =IFERROR( _xlfn.IMAGE(按鍵位置表[[#This Row],[Pict URL]]), "") -> #VALUE!
B33: 31 | C33: ㆧ | D33: oⁿ | E33: I | F33: i | H33: =_xlfn.CONCAT(URL, F33, ".png") -> https://alanjui.github.io/Blogger/assets/images/keys/key_i.png | I33: =IFERROR( _xlfn.IMAGE(按鍵位置表[[#This Row],[Pict URL]]), "") -> #VALUE!
B34: 32 | C34: ㄜ | D34: o | E34: k | F34: k | H34: =_xlfn.CONCAT(URL, F34, ".png") -> https://alanjui.github.io/Blogger/assets/images/keys/key_k.png | I34: =IFERROR( _xlfn.IMAGE(按鍵位置表[[#This Row],[Pict URL]]), "") -> #VALUE!
B35: 33 | C35: ㆨ | D35: ir | E35: K | F35: k | H35: =_xlfn.CONCAT(URL, F35, ".png") -> https://alanjui.github.io/Blogger/assets/images/keys/key_k.png | I35: =IFERROR( _xlfn.IMAGE(按鍵位置表[[#This Row],[Pict URL]]), "") -> #VALUE!
B36: 34 | C36: ㄞ | D36: ai | E36: 9 | F36: 9 | H36: =_xlfn.CONCAT(URL, F36, ".png") -> https://alanjui.github.io/Blogger/assets/images/keys/key_9.png | I36: =IFERROR( _xlfn.IMAGE(按鍵位置表[[#This Row],[Pict URL]]), "") -> #VALUE!
B37: 35 | C37: ㆮ | D37: aiⁿ | E37: ( | F37: 9 | H37: =_xlfn.CONCAT(URL, F37, ".png") -> https://alanjui.github.io/Blogger/assets/images/keys/key_9.png | I37: =IFERROR( _xlfn.IMAGE(按鍵位置表[[#This Row],[Pict URL]]), "") -> #VALUE!
B38: 36 | C38: ㄠ | D38: au | E38: l | F38: l | H38: =_xlfn.CONCAT(URL, F38, ".png") -> https://alanjui.github.io/Blogger/assets/images/keys/key_l.png | I38: =IFERROR( _xlfn.IMAGE(按鍵位置表[[#This Row],[Pict URL]]), "") -> #VALUE!
B39: 37 | C39: ㆯ | D39: auⁿ | E39: L | F39: l | H39: =_xlfn.CONCAT(URL, F39, ".png") -> https://alanjui.github.io/Blogger/assets/images/keys/key_l.png | I39: =IFERROR( _xlfn.IMAGE(按鍵位置表[[#This Row],[Pict URL]]), "") -> #VALUE!
B40: 38 | C40: ㄢ | D40: an | E40: 0 | F40: 0 | H40: =_xlfn.CONCAT(URL, F40, ".png") -> https://alanjui.github.io/Blogger/assets/images/keys/key_0.png | I40: =IFERROR( _xlfn.IMAGE(按鍵位置表[[#This Row],[Pict URL]]), "") -> #VALUE!
B41: 39 | C41: ㄣ | D41: -n | E41: p | F41: p | H41: =_xlfn.CONCAT(URL, F41, ".png") -> https://alanjui.github.io/Blogger/assets/images/keys/key_p.png | I41: =IFERROR( _xlfn.IMAGE(按鍵位置表[[#This Row],[Pict URL]]), "") -> #VALUE!
B42: 40 | C42: ㄤ | D42: ang | E42: ; | F42: semicolon | H42: =_xlfn.CONCAT(URL, F42, ".png") -> https://alanjui.github.io/Blogger/assets/images/keys/key_semicolon.png | I42: =IFERROR( _xlfn.IMAGE(按鍵位置表[[#This Row],[Pict URL]]), "") -> #VALUE!
B43: 41 | C43: ㆭ | D43: -ng | E43: / | F43: slash | H43: =_xlfn.CONCAT(URL, F43, ".png") -> https://alanjui.github.io/Blogger/assets/images/keys/key_slash.png | I43: =IFERROR( _xlfn.IMAGE(按鍵位置表[[#This Row],[Pict URL]]), "") -> #VALUE!
B44: 42 | C44: ㆬ | D44: -m | E44: m | F44: m | H44: =_xlfn.CONCAT(URL, F44, ".png") -> https://alanjui.github.io/Blogger/assets/images/keys/key_m.png | I44: =IFERROR( _xlfn.IMAGE(按鍵位置表[[#This Row],[Pict URL]]), "") -> #VALUE!
B45: 43 | C45: ㆰ | D45: am | E45: M | F45: m | H45: =_xlfn.CONCAT(URL, F45, ".png") -> https://alanjui.github.io/Blogger/assets/images/keys/key_m.png | I45: =IFERROR( _xlfn.IMAGE(按鍵位置表[[#This Row],[Pict URL]]), "") -> #VALUE!
B46: 44 | C46: ㆲ | D46: ong | E46: o | F46: o | H46: =_xlfn.CONCAT(URL, F46, ".png") -> https://alanjui.github.io/Blogger/assets/images/keys/key_o.png | I46: =IFERROR( _xlfn.IMAGE(按鍵位置表[[#This Row],[Pict URL]]), "") -> #VALUE!
B47: 45 | C47: ㆱ | D47: om | E47: O | F47: o | H47: =_xlfn.CONCAT(URL, F47, ".png") -> https://alanjui.github.io/Blogger/assets/images/keys/key_o.png | I47: =IFERROR( _xlfn.IMAGE(按鍵位置表[[#This Row],[Pict URL]]), "") -> #VALUE!
B48: 46 | C48: ㆵ | D48: -t | E48: t | F48: t | H48: =_xlfn.CONCAT(URL, F48, ".png") -> https://alanjui.github.io/Blogger/assets/images/keys/key_t.png | I48: =IFERROR( _xlfn.IMAGE(按鍵位置表[[#This Row],[Pict URL]]), "") -> #VALUE!
...

Sheet 打字練習表
B1: 聲母 | C1: 零ㄅㄆㄇㆠㄉㄊㄋㄌㄍㄎㆣㄏㄗㄘㆡㄙㄐㄑㆢㄒ | R1: URL | S1: https://alanjui.github.io/Blogger/assets/images/keys/key_ | Y1: https://alanjui.github.io/Blogger/assets/images/keys/key_
B3: 漢字 | C3: 十五音 | D3: 注音符號/ 拼音字母 | E3: 補零聲母 | F3: 補省略調號 | G3: 字母 | H3: 聲母序 | I3: 鍵盤按鍵 | R3: 鍵盤按鍵
I4: 1 | J4: 2 | K4: 3 | L4: 4 | M4: 5 | N4: 6 | O4: 7 | P4: 8 | R4: 1 | S4: 2 | T4: 3 | U4: 4 | V4: 5 | W4: 6 | X4: 7 | Y4: 8
B5: 《 | E5: =IF($D5="", "", IF(RIGHT($C5,1)="英",_xlfn.CONCAT("零", $D5),$D5)) | F5: =IF(MID($C5,2,1)="一",_xlfn.CONCAT($D5,"1"),IF(MID($C5,2,1)="四",_xlfn.CONCAT($D5,"4"), IF($D5="","",$E5))) | G5: =IF(LEN($F5)=0, "", LEN($F5)) | H5: =IF($D5="", "", SEARCH(LEFT($F5), $C$1)) | I5: =IF(AND($H5>0, I$4<$G5), IF(MID($F5,I$4+1,1)="1", """", IF(MID($F5,I$4+1,1)="4", "[", MID($F5,I$4+1,1))), IF(I$4<=$G5, IF(LEFT($F5,1)="零", "Ø", LEFT($F5,1)), "")) | J5: =IF(AND($H5>0, J$4<$G5), IF(MID($F5,J$4+1,1)="1", """", IF(MID($F5,J$4+1,1)="4", "[", MID($F5,J$4+1,1))), IF(J$4<=$G5, IF(LEFT($F5,1)="零", "Ø", LEFT($F5,1)), "")) | K5: =IF(AND($H5>0, K$4<$G5), IF(MID($F5,K$4+1,1)="1", """", IF(MID($F5,K$4+1,1)="4", "[", MID($F5,K$4+1,1))), IF(K$4<=$G5, IF(LEFT($F5,1)="零", "Ø", LEFT($F5,1)), "")) | L5: =IF(AND($H5>0, L$4<$G5), IF(MID($F5,L$4+1,1)="1", """", IF(MID($F5,L$4+1,1)="4", "[", MID($F5,L$4+1,1))), IF(L$4<=$G5, IF(LEFT($F5,1)="零", "Ø", LEFT($F5,1)), "")) | M5: =IF(AND($H5>0, M$4<$G5), IF(MID($F5,M$4+1,1)="1", """", IF(MID($F5,M$4+1,1)="4", "[", MID($F5,M$4+1,1))), IF(M$4<=$G5, IF(LEFT($F5,1)="零", "Ø", LEFT($F5,1)), "")) | N5: =IF(AND($H5>0, N$4<$G5), IF(MID($F5,N$4+1,1)="1", """", IF(MID($F5,N$4+1,1)="4", "[", MID($F5,N$4+1,1))), IF(N$4<=$G5, IF(LEFT($F5,1)="零", "Ø", LEFT($F5,1)), "")) | O5: =IF(AND($H5>0, O$4<$G5), IF(MID($F5,O$4+1,1)="1", """", IF(MID($F5,O$4+1,1)="4", "[", MID($F5,O$4+1,1))), IF(O$4<=$G5, IF(LEFT($F5,1)="零", "Ø", LEFT($F5,1)), "")) | P5: =IF(AND($H5>0, P$4<$G5), IF(MID($F5,P$4+1,1)="1", """", IF(MID($F5,P$4+1,1)="4", "[", MID($F5,P$4+1,1))), IF(P$4<=$G5, IF(LEFT($F5,1)="零", "Ø", LEFT($F5,1)), "")) | R5: =IFERROR( _xlfn.IMAGE(_xlfn.XLOOKUP(I5,按鍵位置表[方音符號], 按鍵位置表[Pict URL])), "") | S5: =IFERROR( _xlfn.IMAGE(_xlfn.XLOOKUP(J5,按鍵位置表[方音符號], 按鍵位置表[Pict URL])), "") | T5: =IFERROR( _xlfn.IMAGE(_xlfn.XLOOKUP(K5,按鍵位置表[方音符號], 按鍵位置表[Pict URL])), "") | U5: =IFERROR( _xlfn.IMAGE(_xlfn.XLOOKUP(L5,按鍵位置表[方音符號], 按鍵位置表[Pict URL])), "") | V5: =IFERROR( _xlfn.IMAGE(_xlfn.XLOOKUP(M5,按鍵位置表[方音符號], 按鍵位置表[Pict URL])), "") | W5: =IFERROR( _xlfn.IMAGE(_xlfn.XLOOKUP(N5,按鍵位置表[方音符號], 按鍵位置表[Pict URL])), "") | X5: =IFERROR( _xlfn.IMAGE(_xlfn.XLOOKUP(O5,按鍵位置表[方音符號], 按鍵位置表[Pict URL])), "") | Y5: =IFERROR( _xlfn.IMAGE(_xlfn.XLOOKUP(P5,按鍵位置表[方音符號], 按鍵位置表[Pict URL])), "")
B6: 涼 | C6: 姜五柳 | D6: ㄌㄧㄤˊ | E6: =IF($D6="", "", IF(RIGHT($C6,1)="英",_xlfn.CONCAT("零", $D6),$D6)) -> ㄌㄧㄤˊ | F6: =IF(MID($C6,2,1)="一",_xlfn.CONCAT($D6,"1"),IF(MID($C6,2,1)="四",_xlfn.CONCAT($D6,"4"), IF($D6="","",$E6))) -> ㄌㄧㄤˊ | G6: =IF(LEN($F6)=0, "", LEN($F6)) -> 4 | H6: =IF($D6="", "", SEARCH(LEFT($F6), $C$1)) -> 9 | I6: =IF(AND($H6>0, I$4<$G6), IF(MID($F6,I$4+1,1)="1", """", IF(MID($F6,I$4+1,1)="4", "[", MID($F6,I$4+1,1))), IF(I$4<=$G6, IF(LEFT($F6,1)="零", "=", LEFT($F6,1)), "")) -> ㄧ | J6: =IF(AND($H6>0, J$4<$G6), IF(MID($F6,J$4+1,1)="1", """", IF(MID($F6,J$4+1,1)="4", "[", MID($F6,J$4+1,1))), IF(J$4<=$G6, IF(LEFT($F6,1)="零", "=", LEFT($F6,1)), "")) -> ㄤ | K6: =IF(AND($H6>0, K$4<$G6), IF(MID($F6,K$4+1,1)="1", """", IF(MID($F6,K$4+1,1)="4", "[", MID($F6,K$4+1,1))), IF(K$4<=$G6, IF(LEFT($F6,1)="零", "=", LEFT($F6,1)), "")) -> ˊ | L6: =IF(AND($H6>0, L$4<$G6), IF(MID($F6,L$4+1,1)="1", """", IF(MID($F6,L$4+1,1)="4", "[", MID($F6,L$4+1,1))), IF(L$4<=$G6, IF(LEFT($F6,1)="零", "=", LEFT($F6,1)), "")) -> ㄌ | M6: =IF(AND($H6>0, M$4<$G6), IF(MID($F6,M$4+1,1)="1", """", IF(MID($F6,M$4+1,1)="4", "[", MID($F6,M$4+1,1))), IF(M$4<=$G6, IF(LEFT($F6,1)="零", "=", LEFT($F6,1)), "")) | N6: =IF(AND($H6>0, N$4<$G6), IF(MID($F6,N$4+1,1)="1", """", IF(MID($F6,N$4+1,1)="4", "[", MID($F6,N$4+1,1))), IF(N$4<=$G6, IF(LEFT($F6,1)="零", "=", LEFT($F6,1)), "")) | O6: =IF(AND($H6>0, O$4<$G6), IF(MID($F6,O$4+1,1)="1", """", IF(MID($F6,O$4+1,1)="4", "[", MID($F6,O$4+1,1))), IF(O$4<=$G6, IF(LEFT($F6,1)="零", "=", LEFT($F6,1)), "")) | P6: =IF(AND($H6>0, P$4<$G6), IF(MID($F6,P$4+1,1)="1", """", IF(MID($F6,P$4+1,1)="4", "[", MID($F6,P$4+1,1))), IF(P$4<=$G6, IF(LEFT($F6,1)="零", "=", LEFT($F6,1)), "")) | R6: =IFERROR( _xlfn.IMAGE(_xlfn.XLOOKUP(I6,按鍵位置表[方音符號], 按鍵位置表[Pict URL])), "") -> #VALUE! | S6: =IFERROR( _xlfn.IMAGE(_xlfn.XLOOKUP(J6,按鍵位置表[方音符號], 按鍵位置表[Pict URL])), "") -> #VALUE! | T6: =IFERROR( _xlfn.IMAGE(_xlfn.XLOOKUP(K6,按鍵位置表[方音符號], 按鍵位置表[Pict URL])), "") -> #VALUE! | U6: =IFERROR( _xlfn.IMAGE(_xlfn.XLOOKUP(L6,按鍵位置表[方音符號], 按鍵位置表[Pict URL])), "") -> #VALUE! | V6: =IFERROR( _xlfn.IMAGE(_xlfn.XLOOKUP(M6,按鍵位置表[方音符號], 按鍵位置表[Pict URL])), "") | W6: =IFERROR( _xlfn.IMAGE(_xlfn.XLOOKUP(N6,按鍵位置表[方音符號], 按鍵位置表[Pict URL])), "") | X6: =IFERROR( _xlfn.IMAGE(_xlfn.XLOOKUP(O6,按鍵位置表[方音符號], 按鍵位置表[Pict URL])), "") | Y6: =IFERROR( _xlfn.IMAGE(_xlfn.XLOOKUP(P6,按鍵位置表[方音符號], 按鍵位置表[Pict URL])), "")
B7: 州 | C7: 丩一曾 | D7: ㄐㄧㄨ | E7: =IF($D7="", "", IF(RIGHT($C7,1)="英",_xlfn.CONCAT("零", $D7),$D7)) -> ㄐㄧㄨ | F7: =IF(MID($C7,2,1)="一",_xlfn.CONCAT($D7,"1"),IF(MID($C7,2,1)="四",_xlfn.CONCAT($D7,"4"), IF($D7="","",$E7))) -> ㄐㄧㄨ1 | G7: =IF(LEN($F7)=0, "", LEN($F7)) -> 4 | H7: =IF($D7="", "", SEARCH(LEFT($F7), $C$1)) -> 18 | I7: =IF(AND($H7>0, I$4<$G7), IF(MID($F7,I$4+1,1)="1", """", IF(MID($F7,I$4+1,1)="4", "[", MID($F7,I$4+1,1))), IF(I$4<=$G7, IF(LEFT($F7,1)="零", "=", LEFT($F7,1)), "")) -> ㄧ | J7: =IF(AND($H7>0, J$4<$G7), IF(MID($F7,J$4+1,1)="1", """", IF(MID($F7,J$4+1,1)="4", "[", MID($F7,J$4+1,1))), IF(J$4<=$G7, IF(LEFT($F7,1)="零", "=", LEFT($F7,1)), "")) -> ㄨ | K7: =IF(AND($H7>0, K$4<$G7), IF(MID($F7,K$4+1,1)="1", """", IF(MID($F7,K$4+1,1)="4", "[", MID($F7,K$4+1,1))), IF(K$4<=$G7, IF(LEFT($F7,1)="零", "=", LEFT($F7,1)), "")) -> " | L7: =IF(AND($H7>0, L$4<$G7), IF(MID($F7,L$4+1,1)="1", """", IF(MID($F7,L$4+1,1)="4", "[", MID($F7,L$4+1,1))), IF(L$4<=$G7, IF(LEFT($F7,1)="零", "=", LEFT($F7,1)), "")) -> ㄐ | M7: =IF(AND($H7>0, M$4<$G7), IF(MID($F7,M$4+1,1)="1", """", IF(MID($F7,M$4+1,1)="4", "[", MID($F7,M$4+1,1))), IF(M$4<=$G7, IF(LEFT($F7,1)="零", "=", LEFT($F7,1)), "")) | N7: =IF(AND($H7>0, N$4<$G7), IF(MID($F7,N$4+1,1)="1", """", IF(MID($F7,N$4+1,1)="4", "[", MID($F7,N$4+1,1))), IF(N$4<=$G7, IF(LEFT($F7,1)="零", "=", LEFT($F7,1)), "")) | O7: =IF(AND($H7>0, O$4<$G7), IF(MID($F7,O$4+1,1)="1", """", IF(MID($F7,O$4+1,1)="4", "[", MID($F7,O$4+1,1))), IF(O$4<=$G7, IF(LEFT($F7,1)="零", "=", LEFT($F7,1)), "")) | P7: =IF(AND($H7>0, P$4<$G7), IF(MID($F7,P$4+1,1)="1", """", IF(MID($F7,P$4+1,1)="4", "[", MID($F7,P$4+1,1))), IF(P$4<=$G7, IF(LEFT($F7,1)="零", "=", LEFT($F7,1)), "")) | R7: =IFERROR( _xlfn.IMAGE(_xlfn.XLOOKUP(I7,按鍵位置表[方音符號], 按鍵位置表[Pict URL])), "") -> #VALUE! | S7: =IFERROR( _xlfn.IMAGE(_xlfn.XLOOKUP(J7,按鍵位置表[方音符號], 按鍵位置表[Pict URL])), "") -> #VALUE! | T7: =IFERROR( _xlfn.IMAGE(_xlfn.XLOOKUP(K7,按鍵位置表[方音符號], 按鍵位置表[Pict URL])), "") -> #VALUE! | U7: =IFERROR( _xlfn.IMAGE(_xlfn.XLOOKUP(L7,按鍵位置表[方音符號], 按鍵位置表[Pict URL])), "") -> #VALUE! | V7: =IFERROR( _xlfn.IMAGE(_xlfn.XLOOKUP(M7,按鍵位置表[方音符號], 按鍵位置表[Pict URL])), "") | W7: =IFERROR( _xlfn.IMAGE(_xlfn.XLOOKUP(N7,按鍵位置表[方音符號], 按鍵位置表[Pict URL])), "") | X7: =IFERROR( _xlfn.IMAGE(_xlfn.XLOOKUP(O7,按鍵位置表[方音符號], 按鍵位置表[Pict URL])), "") | Y7: =IFERROR( _xlfn.IMAGE(_xlfn.XLOOKUP(P7,按鍵位置表[方音符號], 按鍵位置表[Pict URL])), "")
B8: 詞 | C8: 艍五時 | D8: ㄙㄨˊ | E8: =IF($D8="", "", IF(RIGHT($C8,1)="英",_xlfn.CONCAT("零", $D8),$D8)) -> ㄙㄨˊ | F8: =IF(MID($C8,2,1)="一",_xlfn.CONCAT($D8,"1"),IF(MID($C8,2,1)="四",_xlfn.CONCAT($D8,"4"), IF($D8="","",$E8))) -> ㄙㄨˊ | G8: =IF(LEN($F8)=0, "", LEN($F8)) -> 3 | H8: =IF($D8="", "", SEARCH(LEFT($F8), $C$1)) -> 17 | I8: =IF(AND($H8>0, I$4<$G8), IF(MID($F8,I$4+1,1)="1", """", IF(MID($F8,I$4+1,1)="4", "[", MID($F8,I$4+1,1))), IF(I$4<=$G8, IF(LEFT($F8,1)="零", "=", LEFT($F8,1)), "")) -> ㄨ | J8: =IF(AND($H8>0, J$4<$G8), IF(MID($F8,J$4+1,1)="1", """", IF(MID($F8,J$4+1,1)="4", "[", MID($F8,J$4+1,1))), IF(J$4<=$G8, IF(LEFT($F8,1)="零", "=", LEFT($F8,1)), "")) -> ˊ | K8: =IF(AND($H8>0, K$4<$G8), IF(MID($F8,K$4+1,1)="1", """", IF(MID($F8,K$4+1,1)="4", "[", MID($F8,K$4+1,1))), IF(K$4<=$G8, IF(LEFT($F8,1)="零", "=", LEFT($F8,1)), "")) -> ㄙ | L8: =IF(AND($H8>0, L$4<$G8), IF(MID($F8,L$4+1,1)="1", """", IF(MID($F8,L$4+1,1)="4", "[", MID($F8,L$4+1,1))), IF(L$4<=$G8, IF(LEFT($F8,1)="零", "=", LEFT($F8,1)), "")) | M8: =IF(AND($H8>0, M$4<$G8), IF(MID($F8,M$4+1,1)="1", """", IF(MID($F8,M$4+1,1)="4", "[", MID($F8,M$4+1,1))), IF(M$4<=$G8, IF(LEFT($F8,1)="零", "=", LEFT($F8,1)), "")) | N8: =IF(AND($H8>0, N$4<$G8), IF(MID($F8,N$4+1,1)="1", """", IF(MID($F8,N$4+1,1)="4", "[", MID($F8,N$4+1,1))), IF(N$4<=$G8, IF(LEFT($F8,1)="零", "=", LEFT($F8,1)), "")) | O8: =IF(AND($H8>0, O$4<$G8), IF(MID($F8,O$4+1,1)="1", """", IF(MID($F8,O$4+1,1)="4", "[", MID($F8,O$4+1,1))), IF(O$4<=$G8, IF(LEFT($F8,1)="零", "=", LEFT($F8,1)), "")) | P8: =IF(AND($H8>0, P$4<$G8), IF(MID($F8,P$4+1,1)="1", """", IF(MID($F8,P$4+1,1)="4", "[", MID($F8,P$4+1,1))), IF(P$4<=$G8, IF(LEFT($F8,1)="零", "=", LEFT($F8,1)), "")) | R8: =IFERROR( _xlfn.IMAGE(_xlfn.XLOOKUP(I8,按鍵位置表[方音符號], 按鍵位置表[Pict URL])), "") -> #VALUE! | S8: =IFERROR( _xlfn.IMAGE(_xlfn.XLOOKUP(J8,按鍵位置表[方音符號], 按鍵位置表[Pict URL])), "") -> #VALUE! | T8: =IFERROR( _xlfn.IMAGE(_xlfn.XLOOKUP(K8,按鍵位置表[方音符號], 按鍵位置表[Pict URL])), "") -> #VALUE! | U8: =IFERROR( _xlfn.IMAGE(_xlfn.XLOOKUP(L8,按鍵位置表[方音符號], 按鍵位置表[Pict URL])), "") | V8: =IFERROR( _xlfn.IMAGE(_xlfn.XLOOKUP(M8,按鍵位置表[方音符號], 按鍵位置表[Pict URL])), "") | W8: =IFERROR( _xlfn.IMAGE(_xlfn.XLOOKUP(N8,按鍵位置表[方音符號], 按鍵位置表[Pict URL])), "") | X8: =IFERROR( _xlfn.IMAGE(_xlfn.XLOOKUP(O8,按鍵位置表[方音符號], 按鍵位置表[Pict URL])), "") | Y8: =IFERROR( _xlfn.IMAGE(_xlfn.XLOOKUP(P8,按鍵位置表[方音符號], 按鍵位置表[Pict URL])), "")
B9: 》 | E9: =IF($D9="", "", IF(RIGHT($C9,1)="英",_xlfn.CONCAT("零", $D9),$D9)) | F9: =IF(MID($C9,2,1)="一",_xlfn.CONCAT($D9,"1"),IF(MID($C9,2,1)="四",_xlfn.CONCAT($D9,"4"), IF($D9="","",$E9))) | G9: =IF(LEN($F9)=0, "", LEN($F9)) | H9: =IF($D9="", "", SEARCH(LEFT($F9), $C$1)) | I9: =IF(AND($H9>0, I$4<$G9), IF(MID($F9,I$4+1,1)="1", """", IF(MID($F9,I$4+1,1)="4", "[", MID($F9,I$4+1,1))), IF(I$4<=$G9, IF(LEFT($F9,1)="零", "=", LEFT($F9,1)), "")) | J9: =IF(AND($H9>0, J$4<$G9), IF(MID($F9,J$4+1,1)="1", """", IF(MID($F9,J$4+1,1)="4", "[", MID($F9,J$4+1,1))), IF(J$4<=$G9, IF(LEFT($F9,1)="零", "=", LEFT($F9,1)), "")) | K9: =IF(AND($H9>0, K$4<$G9), IF(MID($F9,K$4+1,1)="1", """", IF(MID($F9,K$4+1,1)="4", "[", MID($F9,K$4+1,1))), IF(K$4<=$G9, IF(LEFT($F9,1)="零", "=", LEFT($F9,1)), "")) | L9: =IF(AND($H9>0, L$4<$G9), IF(MID($F9,L$4+1,1)="1", """", IF(MID($F9,L$4+1,1)="4", "[", MID($F9,L$4+1,1))), IF(L$4<=$G9, IF(LEFT($F9,1)="零", "=", LEFT($F9,1)), "")) | M9: =IF(AND($H9>0, M$4<$G9), IF(MID($F9,M$4+1,1)="1", """", IF(MID($F9,M$4+1,1)="4", "[", MID($F9,M$4+1,1))), IF(M$4<=$G9, IF(LEFT($F9,1)="零", "=", LEFT($F9,1)), "")) | N9: =IF(AND($H9>0, N$4<$G9), IF(MID($F9,N$4+1,1)="1", """", IF(MID($F9,N$4+1,1)="4", "[", MID($F9,N$4+1,1))), IF(N$4<=$G9, IF(LEFT($F9,1)="零", "=", LEFT($F9,1)), "")) | O9: =IF(AND($H9>0, O$4<$G9), IF(MID($F9,O$4+1,1)="1", """", IF(MID($F9,O$4+1,1)="4", "[", MID($F9,O$4+1,1))), IF(O$4<=$G9, IF(LEFT($F9,1)="零", "=", LEFT($F9,1)), "")) | P9: =IF(AND($H9>0, P$4<$G9), IF(MID($F9,P$4+1,1)="1", """", IF(MID($F9,P$4+1,1)="4", "[", MID($F9,P$4+1,1))), IF(P$4<=$G9, IF(LEFT($F9,1)="零", "=", LEFT($F9,1)), "")) | R9: =IFERROR( _xlfn.IMAGE(_xlfn.XLOOKUP(I9,按鍵位置表[方音符號], 按鍵位置表[Pict URL])), "") | S9: =IFERROR( _xlfn.IMAGE(_xlfn.XLOOKUP(J9,按鍵位置表[方音符號], 按鍵位置表[Pict URL])), "") | T9: =IFERROR( _xlfn.IMAGE(_xlfn.XLOOKUP(K9,按鍵位置表[方音符號], 按鍵位置表[Pict URL])), "") | U9: =IFERROR( _xlfn.IMAGE(_xlfn.XLOOKUP(L9,按鍵位置表[方音符號], 按鍵位置表[Pict URL])), "") | V9: =IFERROR( _xlfn.IMAGE(_xlfn.XLOOKUP(M9,按鍵位置表[方音符號], 按鍵位置表[Pict URL])), "") | W9: =IFERROR( _xlfn.IMAGE(_xlfn.XLOOKUP(N9,按鍵位置表[方音符號], 按鍵位置表[Pict URL])), "") | X9: =IFERROR( _xlfn.IMAGE(_xlfn.XLOOKUP(O9,按鍵位置表[方音符號], 按鍵位置表[Pict URL])), "") | Y9: =IFERROR( _xlfn.IMAGE(_xlfn.XLOOKUP(P9,按鍵位置表[方音符號], 按鍵位置表[Pict URL])), "")
B10: 王 | C10: 公五英 | D10: ㆲˊ | E10: =IF($D10="", "", IF(RIGHT($C10,1)="英",_xlfn.CONCAT("零", $D10),$D10)) -> 零ㆲˊ | F10: =IF(MID($C10,2,1)="一",_xlfn.CONCAT($D10,"1"),IF(MID($C10,2,1)="四",_xlfn.CONCAT($D10,"4"), IF($D10="","",$E10))) -> 零ㆲˊ | G10: =IF(LEN($F10)=0, "", LEN($F10)) -> 3 | H10: =IF($D10="", "", SEARCH(LEFT($F10), $C$1)) -> 1 | I10: =IF(AND($H10>0, I$4<$G10), IF(MID($F10,I$4+1,1)="1", """", IF(MID($F10,I$4+1,1)="4", "[", MID($F10,I$4+1,1))), IF(I$4<=$G10, IF(LEFT($F10,1)="零", "=", LEFT($F10,1)), "")) -> ㆲ | J10: =IF(AND($H10>0, J$4<$G10), IF(MID($F10,J$4+1,1)="1", """", IF(MID($F10,J$4+1,1)="4", "[", MID($F10,J$4+1,1))), IF(J$4<=$G10, IF(LEFT($F10,1)="零", "=", LEFT($F10,1)), "")) -> ˊ | K10: =IF(AND($H10>0, K$4<$G10), IF(MID($F10,K$4+1,1)="1", """", IF(MID($F10,K$4+1,1)="4", "[", MID($F10,K$4+1,1))), IF(K$4<=$G10, IF(LEFT($F10,1)="零", "=", LEFT($F10,1)), "")) -> = | L10: =IF(AND($H10>0, L$4<$G10), IF(MID($F10,L$4+1,1)="1", """", IF(MID($F10,L$4+1,1)="4", "[", MID($F10,L$4+1,1))), IF(L$4<=$G10, IF(LEFT($F10,1)="零", "=", LEFT($F10,1)), "")) | M10: =IF(AND($H10>0, M$4<$G10), IF(MID($F10,M$4+1,1)="1", """", IF(MID($F10,M$4+1,1)="4", "[", MID($F10,M$4+1,1))), IF(M$4<=$G10, IF(LEFT($F10,1)="零", "=", LEFT($F10,1)), "")) | N10: =IF(AND($H10>0, N$4<$G10), IF(MID($F10,N$4+1,1)="1", """", IF(MID($F10,N$4+1,1)="4", "[", MID($F10,N$4+1,1))), IF(N$4<=$G10, IF(LEFT($F10,1)="零", "=", LEFT($F10,1)), "")) | O10: =IF(AND($H10>0, O$4<$G10), IF(MID($F10,O$4+1,1)="1", """", IF(MID($F10,O$4+1,1)="4", "[", MID($F10,O$4+1,1))), IF(O$4<=$G10, IF(LEFT($F10,1)="零", "=", LEFT($F10,1)), "")) | P10: =IF(AND($H10>0, P$4<$G10), IF(MID($F10,P$4+1,1)="1", """", IF(MID($F10,P$4+1,1)="4", "[", MID($F10,P$4+1,1))), IF(P$4<=$G10, IF(LEFT($F10,1)="零", "=", LEFT($F10,1)), "")) | R10: =IFERROR( _xlfn.IMAGE(_xlfn.XLOOKUP(I10,按鍵位置表[方音符號], 按鍵位置表[Pict URL])), "") -> #VALUE! | S10: =IFERROR( _xlfn.IMAGE(_xlfn.XLOOKUP(J10,按鍵位置表[方音符號], 按鍵位置表[Pict URL])), "") -> #VALUE! | T10: =IFERROR( _xlfn.IMAGE(_xlfn.XLOOKUP(K10,按鍵位置表[方音符號], 按鍵位置表[Pict URL])), "") -> #VALUE! | U10: =IFERROR( _xlfn.IMAGE(_xlfn.XLOOKUP(L10,按鍵位置表[方音符號], 按鍵位置表[Pict URL])), "") | V10: =IFERROR( _xlfn.IMAGE(_xlfn.XLOOKUP(M10,按鍵位置表[方音符號], 按鍵位置表[Pict URL])), "") | W10: =IFERROR( _xlfn.IMAGE(_xlfn.XLOOKUP(N10,按鍵位置表[方音符號], 按鍵位置表[Pict URL])), "") | X10: =IFERROR( _xlfn.IMAGE(_xlfn.XLOOKUP(O10,按鍵位置表[方音符號], 按鍵位置表[Pict URL])), "") | Y10: =IFERROR( _xlfn.IMAGE(_xlfn.XLOOKUP(P10,按鍵位置表[方音符號], 按鍵位置表[Pict URL])), "")
B11: 之 | C11: 居一曾 | D11: ㄐㄧ | E11: =IF($D11="", "", IF(RIGHT($C11,1)="英",_xlfn.CONCAT("零", $D11),$D11)) -> ㄐㄧ | F11: =IF(MID($C11,2,1)="一",_xlfn.CONCAT($D11,"1"),IF(MID($C11,2,1)="四",_xlfn.CONCAT($D11,"4"), IF($D11="","",$E11))) -> ㄐㄧ1 | G11: =IF(LEN($F11)=0, "", LEN($F11)) -> 3 | H11: =IF($D11="", "", SEARCH(LEFT($F11), $C$1)) -> 18 | I11: =IF(AND($H11>0, I$4<$G11), IF(MID($F11,I$4+1,1)="1", """", IF(MID($F11,I$4+1,1)="4", "[", MID($F11,I$4+1,1))), IF(I$4<=$G11, IF(LEFT($F11,1)="零", "=", LEFT($F11,1)), "")) -> ㄧ | J11: =IF(AND($H11>0, J$4<$G11), IF(MID($F11,J$4+1,1)="1", """", IF(MID($F11,J$4+1,1)="4", "[", MID($F11,J$4+1,1))), IF(J$4<=$G11, IF(LEFT($F11,1)="零", "=", LEFT($F11,1)), "")) -> " | K11: =IF(AND($H11>0, K$4<$G11), IF(MID($F11,K$4+1,1)="1", """", IF(MID($F11,K$4+1,1)="4", "[", MID($F11,K$4+1,1))), IF(K$4<=$G11, IF(LEFT($F11,1)="零", "=", LEFT($F11,1)), "")) -> ㄐ | L11: =IF(AND($H11>0, L$4<$G11), IF(MID($F11,L$4+1,1)="1", """", IF(MID($F11,L$4+1,1)="4", "[", MID($F11,L$4+1,1))), IF(L$4<=$G11, IF(LEFT($F11,1)="零", "=", LEFT($F11,1)), "")) | M11: =IF(AND($H11>0, M$4<$G11), IF(MID($F11,M$4+1,1)="1", """", IF(MID($F11,M$4+1,1)="4", "[", MID($F11,M$4+1,1))), IF(M$4<=$G11, IF(LEFT($F11,1)="零", "=", LEFT($F11,1)), "")) | N11: =IF(AND($H11>0, N$4<$G11), IF(MID($F11,N$4+1,1)="1", """", IF(MID($F11,N$4+1,1)="4", "[", MID($F11,N$4+1,1))), IF(N$4<=$G11, IF(LEFT($F11,1)="零", "=", LEFT($F11,1)), "")) | O11: =IF(AND($H11>0, O$4<$G11), IF(MID($F11,O$4+1,1)="1", """", IF(MID($F11,O$4+1,1)="4", "[", MID($F11,O$4+1,1))), IF(O$4<=$G11, IF(LEFT($F11,1)="零", "=", LEFT($F11,1)), "")) | P11: =IF(AND($H11>0, P$4<$G11), IF(MID($F11,P$4+1,1)="1", """", IF(MID($F11,P$4+1,1)="4", "[", MID($F11,P$4+1,1))), IF(P$4<=$G11, IF(LEFT($F11,1)="零", "=", LEFT($F11,1)), "")) | R11: =IFERROR( _xlfn.IMAGE(_xlfn.XLOOKUP(I11,按鍵位置表[方音符號], 按鍵位置表[Pict URL])), "") -> #VALUE! | S11: =IFERROR( _xlfn.IMAGE(_xlfn.XLOOKUP(J11,按鍵位置表[方音符號], 按鍵位置表[Pict URL])), "") -> #VALUE! | T11: =IFERROR( _xlfn.IMAGE(_xlfn.XLOOKUP(K11,按鍵位置表[方音符號], 按鍵位置表[Pict URL])), "") -> #VALUE! | U11: =IFERROR( _xlfn.IMAGE(_xlfn.XLOOKUP(L11,按鍵位置表[方音符號], 按鍵位置表[Pict URL])), "") | V11: =IFERROR( _xlfn.IMAGE(_xlfn.XLOOKUP(M11,按鍵位置表[方音符號], 按鍵位置表[Pict URL])), "") | W11: =IFERROR( _xlfn.IMAGE(_xlfn.XLOOKUP(N11,按鍵位置表[方音符號], 按鍵位置表[Pict URL])), "") | X11: =IFERROR( _xlfn.IMAGE(_xlfn.XLOOKUP(O11,按鍵位置表[方音符號], 按鍵位置表[Pict URL])), "") | Y11: =IFERROR( _xlfn.IMAGE(_xlfn.XLOOKUP(P11,按鍵位置表[方音符號], 按鍵位置表[Pict URL])), "")
B12: 渙 | C12: 觀三喜 | D12: ㄏㄨㄢ˪ | E12: =IF($D12="", "", IF(RIGHT($C12,1)="英",_xlfn.CONCAT("零", $D12),$D12)) -> ㄏㄨㄢ˪ | F12: =IF(MID($C12,2,1)="一",_xlfn.CONCAT($D12,"1"),IF(MID($C12,2,1)="四",_xlfn.CONCAT($D12,"4"), IF($D12="","",$E12))) -> ㄏㄨㄢ˪ | G12: =IF(LEN($F12)=0, "", LEN($F12)) -> 4 | H12: =IF($D12="", "", SEARCH(LEFT($F12), $C$1)) -> 13 | I12: =IF(AND($H12>0, I$4<$G12), IF(MID($F12,I$4+1,1)="1", """", IF(MID($F12,I$4+1,1)="4", "[", MID($F12,I$4+1,1))), IF(I$4<=$G12, IF(LEFT($F12,1)="零", "=", LEFT($F12,1)), "")) -> ㄨ | J12: =IF(AND($H12>0, J$4<$G12), IF(MID($F12,J$4+1,1)="1", """", IF(MID($F12,J$4+1,1)="4", "[", MID($F12,J$4+1,1))), IF(J$4<=$G12, IF(LEFT($F12,1)="零", "=", LEFT($F12,1)), "")) -> ㄢ | K12: =IF(AND($H12>0, K$4<$G12), IF(MID($F12,K$4+1,1)="1", """", IF(MID($F12,K$4+1,1)="4", "[", MID($F12,K$4+1,1))), IF(K$4<=$G12, IF(LEFT($F12,1)="零", "=", LEFT($F12,1)), "")) -> ˪ | L12: =IF(AND($H12>0, L$4<$G12), IF(MID($F12,L$4+1,1)="1", """", IF(MID($F12,L$4+1,1)="4", "[", MID($F12,L$4+1,1))), IF(L$4<=$G12, IF(LEFT($F12,1)="零", "=", LEFT($F12,1)), "")) -> ㄏ | M12: =IF(AND($H12>0, M$4<$G12), IF(MID($F12,M$4+1,1)="1", """", IF(MID($F12,M$4+1,1)="4", "[", MID($F12,M$4+1,1))), IF(M$4<=$G12, IF(LEFT($F12,1)="零", "=", LEFT($F12,1)), "")) | N12: =IF(AND($H12>0, N$4<$G12), IF(MID($F12,N$4+1,1)="1", """", IF(MID($F12,N$4+1,1)="4", "[", MID($F12,N$4+1,1))), IF(N$4<=$G12, IF(LEFT($F12,1)="零", "=", LEFT($F12,1)), "")) | O12: =IF(AND($H12>0, O$4<$G12), IF(MID($F12,O$4+1,1)="1", """", IF(MID($F12,O$4+1,1)="4", "[", MID($F12,O$4+1,1))), IF(O$4<=$G12, IF(LEFT($F12,1)="零", "=", LEFT($F12,1)), "")) | P12: =IF(AND($H12>0, P$4<$G12), IF(MID($F12,P$4+1,1)="1", """", IF(MID($F12,P$4+1,1)="4", "[", MID($F12,P$4+1,1))), IF(P$4<=$G12, IF(LEFT($F12,1)="零", "=", LEFT($F12,1)), "")) | R12: =IFERROR( _xlfn.IMAGE(_xlfn.XLOOKUP(I12,按鍵位置表[方音符號], 按鍵位置表[Pict URL])), "") -> #VALUE! | S12: =IFERROR( _xlfn.IMAGE(_xlfn.XLOOKUP(J12,按鍵位置表[方音符號], 按鍵位置表[Pict URL])), "") -> #VALUE! | T12: =IFERROR( _xlfn.IMAGE(_xlfn.XLOOKUP(K12,按鍵位置表[方音符號], 按鍵位置表[Pict URL])), "") -> #VALUE! | U12: =IFERROR( _xlfn.IMAGE(_xlfn.XLOOKUP(L12,按鍵位置表[方音符號], 按鍵位置表[Pict URL])), "") -> #VALUE! | V12: =IFERROR( _xlfn.IMAGE(_xlfn.XLOOKUP(M12,按鍵位置表[方音符號], 按鍵位置表[Pict URL])), "") | W12: =IFERROR( _xlfn.IMAGE(_xlfn.XLOOKUP(N12,按鍵位置表[方音符號], 按鍵位置表[Pict URL])), "") | X12: =IFERROR( _xlfn.IMAGE(_xlfn.XLOOKUP(O12,按鍵位置表[方音符號], 按鍵位置表[Pict URL])), "") | Y12: =IFERROR( _xlfn.IMAGE(_xlfn.XLOOKUP(P12,按鍵位置表[方音符號], 按鍵位置表[Pict URL])), "")
E13: =IF($D13="", "", IF(RIGHT($C13,1)="英",_xlfn.CONCAT("零", $D13),$D13)) | F13: =IF(MID($C13,2,1)="一",_xlfn.CONCAT($D13,"1"),IF(MID($C13,2,1)="四",_xlfn.CONCAT($D13,"4"), IF($D13="","",$E13))) | G13: =IF(LEN($F13)=0, "", LEN($F13)) | H13: =IF($D13="", "", SEARCH(LEFT($F13), $C$1)) | I13: =IF(AND($H13>0, I$4<$G13), IF(MID($F13,I$4+1,1)="1", """", IF(MID($F13,I$4+1,1)="4", "[", MID($F13,I$4+1,1))), IF(I$4<=$G13, IF(LEFT($F13,1)="零", "=", LEFT($F13,1)), "")) | J13: =IF(AND($H13>0, J$4<$G13), IF(MID($F13,J$4+1,1)="1", """", IF(MID($F13,J$4+1,1)="4", "[", MID($F13,J$4+1,1))), IF(J$4<=$G13, IF(LEFT($F13,1)="零", "=", LEFT($F13,1)), "")) | K13: =IF(AND($H13>0, K$4<$G13), IF(MID($F13,K$4+1,1)="1", """", IF(MID($F13,K$4+1,1)="4", "[", MID($F13,K$4+1,1))), IF(K$4<=$G13, IF(LEFT($F13,1)="零", "=", LEFT($F13,1)), "")) | L13: =IF(AND($H13>0, L$4<$G13), IF(MID($F13,L$4+1,1)="1", """", IF(MID($F13,L$4+1,1)="4", "[", MID($F13,L$4+1,1))), IF(L$4<=$G13, IF(LEFT($F13,1)="零", "=", LEFT($F13,1)), "")) | M13: =IF(AND($H13>0, M$4<$G13), IF(MID($F13,M$4+1,1)="1", """", IF(MID($F13,M$4+1,1)="4", "[", MID($F13,M$4+1,1))), IF(M$4<=$G13, IF(LEFT($F13,1)="零", "=", LEFT($F13,1)), "")) | N13: =IF(AND($H13>0, N$4<$G13), IF(MID($F13,N$4+1,1)="1", """", IF(MID($F13,N$4+1,1)="4", "[", MID($F13,N$4+1,1))), IF(N$4<=$G13, IF(LEFT($F13,1)="零", "=", LEFT($F13,1)), "")) | O13: =IF(AND($H13>0, O$4<$G13), IF(MID($F13,O$4+1,1)="1", """", IF(MID($F13,O$4+1,1)="4", "[", MID($F13,O$4+1,1))), IF(O$4<=$G13, IF(LEFT($F13,1)="零", "=", LEFT($F13,1)), "")) | P13: =IF(AND($H13>0, P$4<$G13), IF(MID($F13,P$4+1,1)="1", """", IF(MID($F13,P$4+1,1)="4", "[", MID($F13,P$4+1,1))), IF(P$4<=$G13, IF(LEFT($F13,1)="零", "=", LEFT($F13,1)), "")) | R13: =IFERROR( _xlfn.IMAGE(_xlfn.XLOOKUP(I13,按鍵位置表[方音符號], 按鍵位置表[Pict URL])), "") | S13: =IFERROR( _xlfn.IMAGE(_xlfn.XLOOKUP(J13,按鍵位置表[方音符號], 按鍵位置表[Pict URL])), "") | T13: =IFERROR( _xlfn.IMAGE(_xlfn.XLOOKUP(K13,按鍵位置表[方音符號], 按鍵位置表[Pict URL])), "") | U13: =IFERROR( _xlfn.IMAGE(_xlfn.XLOOKUP(L13,按鍵位置表[方音符號], 按鍵位置表[Pict URL])), "") | V13: =IFERROR( _xlfn.IMAGE(_xlfn.XLOOKUP(M13,按鍵位置表[方音符號], 按鍵位置表[Pict URL])), "") | W13: =IFERROR( _xlfn.IMAGE(_xlfn.XLOOKUP(N13,按鍵位置表[方音符號], 按鍵位置表[Pict URL])), "") | X13: =IFERROR( _xlfn.IMAGE(_xlfn.XLOOKUP(O13,按鍵位置表[方音符號], 按鍵位置表[Pict URL])), "") | Y13: =IFERROR( _xlfn.IMAGE(_xlfn.XLOOKUP(P13,按鍵位置表[方音符號], 按鍵位置表[Pict URL])), "")
B14: 黃 | C14: 公五喜 | D14: ㄏㆲˊ | E14: =IF($D14="", "", IF(RIGHT($C14,1)="英",_xlfn.CONCAT("零", $D14),$D14)) -> ㄏㆲˊ | F14: =IF(MID($C14,2,1)="一",_xlfn.CONCAT($D14,"1"),IF(MID($C14,2,1)="四",_xlfn.CONCAT($D14,"4"), IF($D14="","",$E14))) -> ㄏㆲˊ | G14: =IF(LEN($F14)=0, "", LEN($F14)) -> 3 | H14: =IF($D14="", "", SEARCH(LEFT($F14), $C$1)) -> 13 | I14: =IF(AND($H14>0, I$4<$G14), IF(MID($F14,I$4+1,1)="1", """", IF(MID($F14,I$4+1,1)="4", "[", MID($F14,I$4+1,1))), IF(I$4<=$G14, IF(LEFT($F14,1)="零", "=", LEFT($F14,1)), "")) -> ㆲ | J14: =IF(AND($H14>0, J$4<$G14), IF(MID($F14,J$4+1,1)="1", """", IF(MID($F14,J$4+1,1)="4", "[", MID($F14,J$4+1,1))), IF(J$4<=$G14, IF(LEFT($F14,1)="零", "=", LEFT($F14,1)), "")) -> ˊ | K14: =IF(AND($H14>0, K$4<$G14), IF(MID($F14,K$4+1,1)="1", """", IF(MID($F14,K$4+1,1)="4", "[", MID($F14,K$4+1,1))), IF(K$4<=$G14, IF(LEFT($F14,1)="零", "=", LEFT($F14,1)), "")) -> ㄏ | L14: =IF(AND($H14>0, L$4<$G14), IF(MID($F14,L$4+1,1)="1", """", IF(MID($F14,L$4+1,1)="4", "[", MID($F14,L$4+1,1))), IF(L$4<=$G14, IF(LEFT($F14,1)="零", "=", LEFT($F14,1)), "")) | M14: =IF(AND($H14>0, M$4<$G14), IF(MID($F14,M$4+1,1)="1", """", IF(MID($F14,M$4+1,1)="4", "[", MID($F14,M$4+1,1))), IF(M$4<=$G14, IF(LEFT($F14,1)="零", "=", LEFT($F14,1)), "")) | N14: =IF(AND($H14>0, N$4<$G14), IF(MID($F14,N$4+1,1)="1", """", IF(MID($F14,N$4+1,1)="4", "[", MID($F14,N$4+1,1))), IF(N$4<=$G14, IF(LEFT($F14,1)="零", "=", LEFT($F14,1)), "")) | O14: =IF(AND($H14>0, O$4<$G14), IF(MID($F14,O$4+1,1)="1", """", IF(MID($F14,O$4+1,1)="4", "[", MID($F14,O$4+1,1))), IF(O$4<=$G14, IF(LEFT($F14,1)="零", "=", LEFT($F14,1)), "")) | P14: =IF(AND($H14>0, P$4<$G14), IF(MID($F14,P$4+1,1)="1", """", IF(MID($F14,P$4+1,1)="4", "[", MID($F14,P$4+1,1))), IF(P$4<=$G14, IF(LEFT($F14,1)="零", "=", LEFT($F14,1)), "")) | R14: =IFERROR( _xlfn.IMAGE(_xlfn.XLOOKUP(I14,按鍵位置表[方音符號], 按鍵位置表[Pict URL])), "") -> #VALUE! | S14: =IFERROR( _xlfn.IMAGE(_xlfn.XLOOKUP(J14,按鍵位置表[方音符號], 按鍵位置表[Pict URL])), "") -> #VALUE! | T14: =IFERROR( _xlfn.IMAGE(_xlfn.XLOOKUP(K14,按鍵位置表[方音符號], 按鍵位置表[Pict URL])), "") -> #VALUE! | U14: =IFERROR( _xlfn.IMAGE(_xlfn.XLOOKUP(L14,按鍵位置表[方音符號], 按鍵位置表[Pict URL])), "") | V14: =IFERROR( _xlfn.IMAGE(_xlfn.XLOOKUP(M14,按鍵位置表[方音符號], 按鍵位置表[Pict URL])), "") | W14: =IFERROR( _xlfn.IMAGE(_xlfn.XLOOKUP(N14,按鍵位置表[方音符號], 按鍵位置表[Pict URL])), "") | X14: =IFERROR( _xlfn.IMAGE(_xlfn.XLOOKUP(O14,按鍵位置表[方音符號], 按鍵位置表[Pict URL])), "") | Y14: =IFERROR( _xlfn.IMAGE(_xlfn.XLOOKUP(P14,按鍵位置表[方音符號], 按鍵位置表[Pict URL])), "")
B15: 河 | C15: 高五喜 | D15: ㄏㄜˊ | E15: =IF($D15="", "", IF(RIGHT($C15,1)="英",_xlfn.CONCAT("零", $D15),$D15)) -> ㄏㄜˊ | F15: =IF(MID($C15,2,1)="一",_xlfn.CONCAT($D15,"1"),IF(MID($C15,2,1)="四",_xlfn.CONCAT($D15,"4"), IF($D15="","",$E15))) -> ㄏㄜˊ | G15: =IF(LEN($F15)=0, "", LEN($F15)) -> 3 | H15: =IF($D15="", "", SEARCH(LEFT($F15), $C$1)) -> 13 | I15: =IF(AND($H15>0, I$4<$G15), IF(MID($F15,I$4+1,1)="1", """", IF(MID($F15,I$4+1,1)="4", "[", MID($F15,I$4+1,1))), IF(I$4<=$G15, IF(LEFT($F15,1)="零", "=", LEFT($F15,1)), "")) -> ㄜ | J15: =IF(AND($H15>0, J$4<$G15), IF(MID($F15,J$4+1,1)="1", """", IF(MID($F15,J$4+1,1)="4", "[", MID($F15,J$4+1,1))), IF(J$4<=$G15, IF(LEFT($F15,1)="零", "=", LEFT($F15,1)), "")) -> ˊ | K15: =IF(AND($H15>0, K$4<$G15), IF(MID($F15,K$4+1,1)="1", """", IF(MID($F15,K$4+1,1)="4", "[", MID($F15,K$4+1,1))), IF(K$4<=$G15, IF(LEFT($F15,1)="零", "=", LEFT($F15,1)), "")) -> ㄏ | L15: =IF(AND($H15>0, L$4<$G15), IF(MID($F15,L$4+1,1)="1", """", IF(MID($F15,L$4+1,1)="4", "[", MID($F15,L$4+1,1))), IF(L$4<=$G15, IF(LEFT($F15,1)="零", "=", LEFT($F15,1)), "")) | M15: =IF(AND($H15>0, M$4<$G15), IF(MID($F15,M$4+1,1)="1", """", IF(MID($F15,M$4+1,1)="4", "[", MID($F15,M$4+1,1))), IF(M$4<=$G15, IF(LEFT($F15,1)="零", "=", LEFT($F15,1)), "")) | N15: =IF(AND($H15>0, N$4<$G15), IF(MID($F15,N$4+1,1)="1", """", IF(MID($F15,N$4+1,1)="4", "[", MID($F15,N$4+1,1))), IF(N$4<=$G15, IF(LEFT($F15,1)="零", "=", LEFT($F15,1)), "")) | O15: =IF(AND($H15>0, O$4<$G15), IF(MID($F15,O$4+1,1)="1", """", IF(MID($F15,O$4+1,1)="4", "[", MID($F15,O$4+1,1))), IF(O$4<=$G15, IF(LEFT($F15,1)="零", "=", LEFT($F15,1)), "")) | P15: =IF(AND($H15>0, P$4<$G15), IF(MID($F15,P$4+1,1)="1", """", IF(MID($F15,P$4+1,1)="4", "[", MID($F15,P$4+1,1))), IF(P$4<=$G15, IF(LEFT($F15,1)="零", "=", LEFT($F15,1)), "")) | R15: =IFERROR( _xlfn.IMAGE(_xlfn.XLOOKUP(I15,按鍵位置表[方音符號], 按鍵位置表[Pict URL])), "") -> #VALUE! | S15: =IFERROR( _xlfn.IMAGE(_xlfn.XLOOKUP(J15,按鍵位置表[方音符號], 按鍵位置表[Pict URL])), "") -> #VALUE! | T15: =IFERROR( _xlfn.IMAGE(_xlfn.XLOOKUP(K15,按鍵位置表[方音符號], 按鍵位置表[Pict URL])), "") -> #VALUE! | U15: =IFERROR( _xlfn.IMAGE(_xlfn.XLOOKUP(L15,按鍵位置表[方音符號], 按鍵位置表[Pict URL])), "") | V15: =IFERROR( _xlfn.IMAGE(_xlfn.XLOOKUP(M15,按鍵位置表[方音符號], 按鍵位置表[Pict URL])), "") | W15: =IFERROR( _xlfn.IMAGE(_xlfn.XLOOKUP(N15,按鍵位置表[方音符號], 按鍵位置表[Pict URL])), "") | X15: =IFERROR( _xlfn.IMAGE(_xlfn.XLOOKUP(O15,按鍵位置表[方音符號], 按鍵位置表[Pict URL])), "") | Y15: =IFERROR( _xlfn.IMAGE(_xlfn.XLOOKUP(P15,按鍵位置表[方音符號], 按鍵位置表[Pict URL])), "")
B16: 遠 | C16: 觀二英 | D16: ㄨㄢˋ | E16: =IF($D16="", "", IF(RIGHT($C16,1)="英",_xlfn.CONCAT("零", $D16),$D16)) -> 零ㄨㄢˋ | F16: =IF(MID($C16,2,1)="一",_xlfn.CONCAT($D16,"1"),IF(MID($C16,2,1)="四",_xlfn.CONCAT($D16,"4"), IF($D16="","",$E16))) -> 零ㄨㄢˋ | G16: =IF(LEN($F16)=0, "", LEN($F16)) -> 4 | H16: =IF($D16="", "", SEARCH(LEFT($F16), $C$1)) -> 1 | I16: =IF(AND($H16>0, I$4<$G16), IF(MID($F16,I$4+1,1)="1", """", IF(MID($F16,I$4+1,1)="4", "[", MID($F16,I$4+1,1))), IF(I$4<=$G16, IF(LEFT($F16,1)="零", "=", LEFT($F16,1)), "")) -> ㄨ | J16: =IF(AND($H16>0, J$4<$G16), IF(MID($F16,J$4+1,1)="1", """", IF(MID($F16,J$4+1,1)="4", "[", MID($F16,J$4+1,1))), IF(J$4<=$G16, IF(LEFT($F16,1)="零", "=", LEFT($F16,1)), "")) -> ㄢ | K16: =IF(AND($H16>0, K$4<$G16), IF(MID($F16,K$4+1,1)="1", """", IF(MID($F16,K$4+1,1)="4", "[", MID($F16,K$4+1,1))), IF(K$4<=$G16, IF(LEFT($F16,1)="零", "=", LEFT($F16,1)), "")) -> ˋ | L16: =IF(AND($H16>0, L$4<$G16), IF(MID($F16,L$4+1,1)="1", """", IF(MID($F16,L$4+1,1)="4", "[", MID($F16,L$4+1,1))), IF(L$4<=$G16, IF(LEFT($F16,1)="零", "=", LEFT($F16,1)), "")) -> = | M16: =IF(AND($H16>0, M$4<$G16), IF(MID($F16,M$4+1,1)="1", """", IF(MID($F16,M$4+1,1)="4", "[", MID($F16,M$4+1,1))), IF(M$4<=$G16, IF(LEFT($F16,1)="零", "=", LEFT($F16,1)), "")) | N16: =IF(AND($H16>0, N$4<$G16), IF(MID($F16,N$4+1,1)="1", """", IF(MID($F16,N$4+1,1)="4", "[", MID($F16,N$4+1,1))), IF(N$4<=$G16, IF(LEFT($F16,1)="零", "=", LEFT($F16,1)), "")) | O16: =IF(AND($H16>0, O$4<$G16), IF(MID($F16,O$4+1,1)="1", """", IF(MID($F16,O$4+1,1)="4", "[", MID($F16,O$4+1,1))), IF(O$4<=$G16, IF(LEFT($F16,1)="零", "=", LEFT($F16,1)), "")) | P16: =IF(AND($H16>0, P$4<$G16), IF(MID($F16,P$4+1,1)="1", """", IF(MID($F16,P$4+1,1)="4", "[", MID($F16,P$4+1,1))), IF(P$4<=$G16, IF(LEFT($F16,1)="零", "=", LEFT($F16,1)), "")) | R16: =IFERROR( _xlfn.IMAGE(_xlfn.XLOOKUP(I16,按鍵位置表[方音符號], 按鍵位置表[Pict URL])), "") -> #VALUE! | S16: =IFERROR( _xlfn.IMAGE(_xlfn.XLOOKUP(J16,按鍵位置表[方音符號], 按鍵位置表[Pict URL])), "") -> #VALUE! | T16: =IFERROR( _xlfn.IMAGE(_xlfn.XLOOKUP(K16,按鍵位置表[方音符號], 按鍵位置表[Pict URL])), "") -> #VALUE! | U16: =IFERROR( _xlfn.IMAGE(_xlfn.XLOOKUP(L16,按鍵位置表[方音符號], 按鍵位置表[Pict URL])), "") -> #VALUE! | V16: =IFERROR( _xlfn.IMAGE(_xlfn.XLOOKUP(M16,按鍵位置表[方音符號], 按鍵位置表[Pict URL])), "") | W16: =IFERROR( _xlfn.IMAGE(_xlfn.XLOOKUP(N16,按鍵位置表[方音符號], 按鍵位置表[Pict URL])), "") | X16: =IFERROR( _xlfn.IMAGE(_xlfn.XLOOKUP(O16,按鍵位置表[方音符號], 按鍵位置表[Pict URL])), "") | Y16: =IFERROR( _xlfn.IMAGE(_xlfn.XLOOKUP(P16,按鍵位置表[方音符號], 按鍵位置表[Pict URL])), "")
B17: 上 | C17: 恭二時 | D17: ㄒㄧㆲˋ | E17: =IF($D17="", "", IF(RIGHT($C17,1)="英",_xlfn.CONCAT("零", $D17),$D17)) -> ㄒㄧㆲˋ | F17: =IF(MID($C17,2,1)="一",_xlfn.CONCAT($D17,"1"),IF(MID($C17,2,1)="四",_xlfn.CONCAT($D17,"4"), IF($D17="","",$E17))) -> ㄒㄧㆲˋ | G17: =IF(LEN($F17)=0, "", LEN($F17)) -> 4 | H17: =IF($D17="", "", SEARCH(LEFT($F17), $C$1)) -> 21 | I17: =IF(AND($H17>0, I$4<$G17), IF(MID($F17,I$4+1,1)="1", """", IF(MID($F17,I$4+1,1)="4", "[", MID($F17,I$4+1,1))), IF(I$4<=$G17, IF(LEFT($F17,1)="零", "=", LEFT($F17,1)), "")) -> ㄧ | J17: =IF(AND($H17>0, J$4<$G17), IF(MID($F17,J$4+1,1)="1", """", IF(MID($F17,J$4+1,1)="4", "[", MID($F17,J$4+1,1))), IF(J$4<=$G17, IF(LEFT($F17,1)="零", "=", LEFT($F17,1)), "")) -> ㆲ | K17: =IF(AND($H17>0, K$4<$G17), IF(MID($F17,K$4+1,1)="1", """", IF(MID($F17,K$4+1,1)="4", "[", MID($F17,K$4+1,1))), IF(K$4<=$G17, IF(LEFT($F17,1)="零", "=", LEFT($F17,1)), "")) -> ˋ | L17: =IF(AND($H17>0, L$4<$G17), IF(MID($F17,L$4+1,1)="1", """", IF(MID($F17,L$4+1,1)="4", "[", MID($F17,L$4+1,1))), IF(L$4<=$G17, IF(LEFT($F17,1)="零", "=", LEFT($F17,1)), "")) -> ㄒ | M17: =IF(AND($H17>0, M$4<$G17), IF(MID($F17,M$4+1,1)="1", """", IF(MID($F17,M$4+1,1)="4", "[", MID($F17,M$4+1,1))), IF(M$4<=$G17, IF(LEFT($F17,1)="零", "=", LEFT($F17,1)), "")) | N17: =IF(AND($H17>0, N$4<$G17), IF(MID($F17,N$4+1,1)="1", """", IF(MID($F17,N$4+1,1)="4", "[", MID($F17,N$4+1,1))), IF(N$4<=$G17, IF(LEFT($F17,1)="零", "=", LEFT($F17,1)), "")) | O17: =IF(AND($H17>0, O$4<$G17), IF(MID($F17,O$4+1,1)="1", """", IF(MID($F17,O$4+1,1)="4", "[", MID($F17,O$4+1,1))), IF(O$4<=$G17, IF(LEFT($F17,1)="零", "=", LEFT($F17,1)), "")) | P17: =IF(AND($H17>0, P$4<$G17), IF(MID($F17,P$4+1,1)="1", """", IF(MID($F17,P$4+1,1)="4", "[", MID($F17,P$4+1,1))), IF(P$4<=$G17, IF(LEFT($F17,1)="零", "=", LEFT($F17,1)), "")) | R17: =IFERROR( _xlfn.IMAGE(_xlfn.XLOOKUP(I17,按鍵位置表[方音符號], 按鍵位置表[Pict URL])), "") -> #VALUE! | S17: =IFERROR( _xlfn.IMAGE(_xlfn.XLOOKUP(J17,按鍵位置表[方音符號], 按鍵位置表[Pict URL])), "") -> #VALUE! | T17: =IFERROR( _xlfn.IMAGE(_xlfn.XLOOKUP(K17,按鍵位置表[方音符號], 按鍵位置表[Pict URL])), "") -> #VALUE! | U17: =IFERROR( _xlfn.IMAGE(_xlfn.XLOOKUP(L17,按鍵位置表[方音符號], 按鍵位置表[Pict URL])), "") -> #VALUE! | V17: =IFERROR( _xlfn.IMAGE(_xlfn.XLOOKUP(M17,按鍵位置表[方音符號], 按鍵位置表[Pict URL])), "") | W17: =IFERROR( _xlfn.IMAGE(_xlfn.XLOOKUP(N17,按鍵位置表[方音符號], 按鍵位置表[Pict URL])), "") | X17: =IFERROR( _xlfn.IMAGE(_xlfn.XLOOKUP(O17,按鍵位置表[方音符號], 按鍵位置表[Pict URL])), "") | Y17: =IFERROR( _xlfn.IMAGE(_xlfn.XLOOKUP(P17,按鍵位置表[方音符號], 按鍵位置表[Pict URL])), "")
B18: 白 | C18: 經八邊 | D18: ㄅㄧㆻ˙ | E18: =IF($D18="", "", IF(RIGHT($C18,1)="英",_xlfn.CONCAT("零", $D18),$D18)) -> ㄅㄧㆻ˙ | F18: =IF(MID($C18,2,1)="一",_xlfn.CONCAT($D18,"1"),IF(MID($C18,2,1)="四",_xlfn.CONCAT($D18,"4"), IF($D18="","",$E18))) -> ㄅㄧㆻ˙ | G18: =IF(LEN($F18)=0, "", LEN($F18)) -> 4 | H18: =IF($D18="", "", SEARCH(LEFT($F18), $C$1)) -> 2 | I18: =IF(AND($H18>0, I$4<$G18), IF(MID($F18,I$4+1,1)="1", """", IF(MID($F18,I$4+1,1)="4", "[", MID($F18,I$4+1,1))), IF(I$4<=$G18, IF(LEFT($F18,1)="零", "=", LEFT($F18,1)), "")) -> ㄧ | J18: =IF(AND($H18>0, J$4<$G18), IF(MID($F18,J$4+1,1)="1", """", IF(MID($F18,J$4+1,1)="4", "[", MID($F18,J$4+1,1))), IF(J$4<=$G18, IF(LEFT($F18,1)="零", "=", LEFT($F18,1)), "")) -> ㆻ | K18: =IF(AND($H18>0, K$4<$G18), IF(MID($F18,K$4+1,1)="1", """", IF(MID($F18,K$4+1,1)="4", "[", MID($F18,K$4+1,1))), IF(K$4<=$G18, IF(LEFT($F18,1)="零", "=", LEFT($F18,1)), "")) -> ˙ | L18: =IF(AND($H18>0, L$4<$G18), IF(MID($F18,L$4+1,1)="1", """", IF(MID($F18,L$4+1,1)="4", "[", MID($F18,L$4+1,1))), IF(L$4<=$G18, IF(LEFT($F18,1)="零", "=", LEFT($F18,1)), "")) -> ㄅ | M18: =IF(AND($H18>0, M$4<$G18), IF(MID($F18,M$4+1,1)="1", """", IF(MID($F18,M$4+1,1)="4", "[", MID($F18,M$4+1,1))), IF(M$4<=$G18, IF(LEFT($F18,1)="零", "=", LEFT($F18,1)), "")) | N18: =IF(AND($H18>0, N$4<$G18), IF(MID($F18,N$4+1,1)="1", """", IF(MID($F18,N$4+1,1)="4", "[", MID($F18,N$4+1,1))), IF(N$4<=$G18, IF(LEFT($F18,1)="零", "=", LEFT($F18,1)), "")) | O18: =IF(AND($H18>0, O$4<$G18), IF(MID($F18,O$4+1,1)="1", """", IF(MID($F18,O$4+1,1)="4", "[", MID($F18,O$4+1,1))), IF(O$4<=$G18, IF(LEFT($F18,1)="零", "=", LEFT($F18,1)), "")) | P18: =IF(AND($H18>0, P$4<$G18), IF(MID($F18,P$4+1,1)="1", """", IF(MID($F18,P$4+1,1)="4", "[", MID($F18,P$4+1,1))), IF(P$4<=$G18, IF(LEFT($F18,1)="零", "=", LEFT($F18,1)), "")) | R18: =IFERROR( _xlfn.IMAGE(_xlfn.XLOOKUP(I18,按鍵位置表[方音符號], 按鍵位置表[Pict URL])), "") -> #VALUE! | S18: =IFERROR( _xlfn.IMAGE(_xlfn.XLOOKUP(J18,按鍵位置表[方音符號], 按鍵位置表[Pict URL])), "") -> #VALUE! | T18: =IFERROR( _xlfn.IMAGE(_xlfn.XLOOKUP(K18,按鍵位置表[方音符號], 按鍵位置表[Pict URL])), "") -> #VALUE! | U18: =IFERROR( _xlfn.IMAGE(_xlfn.XLOOKUP(L18,按鍵位置表[方音符號], 按鍵位置表[Pict URL])), "") -> #VALUE! | V18: =IFERROR( _xlfn.IMAGE(_xlfn.XLOOKUP(M18,按鍵位置表[方音符號], 按鍵位置表[Pict URL])), "") | W18: =IFERROR( _xlfn.IMAGE(_xlfn.XLOOKUP(N18,按鍵位置表[方音符號], 按鍵位置表[Pict URL])), "") | X18: =IFERROR( _xlfn.IMAGE(_xlfn.XLOOKUP(O18,按鍵位置表[方音符號], 按鍵位置表[Pict URL])), "") | Y18: =IFERROR( _xlfn.IMAGE(_xlfn.XLOOKUP(P18,按鍵位置表[方音符號], 按鍵位置表[Pict URL])), "")
B19: 雲 | C19: 君五喜 | D19: ㄏㄨㄣˊ | E19: =IF($D19="", "", IF(RIGHT($C19,1)="英",_xlfn.CONCAT("零", $D19),$D19)) -> ㄏㄨㄣˊ | F19: =IF(MID($C19,2,1)="一",_xlfn.CONCAT($D19,"1"),IF(MID($C19,2,1)="四",_xlfn.CONCAT($D19,"4"), IF($D19="","",$E19))) -> ㄏㄨㄣˊ | G19: =IF(LEN($F19)=0, "", LEN($F19)) -> 4 | H19: =IF($D19="", "", SEARCH(LEFT($F19), $C$1)) -> 13 | I19: =IF(AND($H19>0, I$4<$G19), IF(MID($F19,I$4+1,1)="1", """", IF(MID($F19,I$4+1,1)="4", "[", MID($F19,I$4+1,1))), IF(I$4<=$G19, IF(LEFT($F19,1)="零", "=", LEFT($F19,1)), "")) -> ㄨ | J19: =IF(AND($H19>0, J$4<$G19), IF(MID($F19,J$4+1,1)="1", """", IF(MID($F19,J$4+1,1)="4", "[", MID($F19,J$4+1,1))), IF(J$4<=$G19, IF(LEFT($F19,1)="零", "=", LEFT($F19,1)), "")) -> ㄣ | K19: =IF(AND($H19>0, K$4<$G19), IF(MID($F19,K$4+1,1)="1", """", IF(MID($F19,K$4+1,1)="4", "[", MID($F19,K$4+1,1))), IF(K$4<=$G19, IF(LEFT($F19,1)="零", "=", LEFT($F19,1)), "")) -> ˊ | L19: =IF(AND($H19>0, L$4<$G19), IF(MID($F19,L$4+1,1)="1", """", IF(MID($F19,L$4+1,1)="4", "[", MID($F19,L$4+1,1))), IF(L$4<=$G19, IF(LEFT($F19,1)="零", "=", LEFT($F19,1)), "")) -> ㄏ | M19: =IF(AND($H19>0, M$4<$G19), IF(MID($F19,M$4+1,1)="1", """", IF(MID($F19,M$4+1,1)="4", "[", MID($F19,M$4+1,1))), IF(M$4<=$G19, IF(LEFT($F19,1)="零", "=", LEFT($F19,1)), "")) | N19: =IF(AND($H19>0, N$4<$G19), IF(MID($F19,N$4+1,1)="1", """", IF(MID($F19,N$4+1,1)="4", "[", MID($F19,N$4+1,1))), IF(N$4<=$G19, IF(LEFT($F19,1)="零", "=", LEFT($F19,1)), "")) | O19: =IF(AND($H19>0, O$4<$G19), IF(MID($F19,O$4+1,1)="1", """", IF(MID($F19,O$4+1,1)="4", "[", MID($F19,O$4+1,1))), IF(O$4<=$G19, IF(LEFT($F19,1)="零", "=", LEFT($F19,1)), "")) | P19: =IF(AND($H19>0, P$4<$G19), IF(MID($F19,P$4+1,1)="1", """", IF(MID($F19,P$4+1,1)="4", "[", MID($F19,P$4+1,1))), IF(P$4<=$G19, IF(LEFT($F19,1)="零", "=", LEFT($F19,1)), "")) | R19: =IFERROR( _xlfn.IMAGE(_xlfn.XLOOKUP(I19,按鍵位置表[方音符號], 按鍵位置表[Pict URL])), "") -> #VALUE! | S19: =IFERROR( _xlfn.IMAGE(_xlfn.XLOOKUP(J19,按鍵位置表[方音符號], 按鍵位置表[Pict URL])), "") -> #VALUE! | T19: =IFERROR( _xlfn.IMAGE(_xlfn.XLOOKUP(K19,按鍵位置表[方音符號], 按鍵位置表[Pict URL])), "") -> #VALUE! | U19: =IFERROR( _xlfn.IMAGE(_xlfn.XLOOKUP(L19,按鍵位置表[方音符號], 按鍵位置表[Pict URL])), "") -> #VALUE! | V19: =IFERROR( _xlfn.IMAGE(_xlfn.XLOOKUP(M19,按鍵位置表[方音符號], 按鍵位置表[Pict URL])), "") | W19: =IFERROR( _xlfn.IMAGE(_xlfn.XLOOKUP(N19,按鍵位置表[方音符號], 按鍵位置表[Pict URL])), "") | X19: =IFERROR( _xlfn.IMAGE(_xlfn.XLOOKUP(O19,按鍵位置表[方音符號], 按鍵位置表[Pict URL])), "") | Y19: =IFERROR( _xlfn.IMAGE(_xlfn.XLOOKUP(P19,按鍵位置表[方音符號], 按鍵位置表[Pict URL])), "")
B20: 間 | C20: 干一求 | D20: ㄍㄢ | E20: =IF($D20="", "", IF(RIGHT($C20,1)="英",_xlfn.CONCAT("零", $D20),$D20)) -> ㄍㄢ | F20: =IF(MID($C20,2,1)="一",_xlfn.CONCAT($D20,"1"),IF(MID($C20,2,1)="四",_xlfn.CONCAT($D20,"4"), IF($D20="","",$E20))) -> ㄍㄢ1 | G20: =IF(LEN($F20)=0, "", LEN($F20)) -> 3 | H20: =IF($D20="", "", SEARCH(LEFT($F20), $C$1)) -> 10 | I20: =IF(AND($H20>0, I$4<$G20), IF(MID($F20,I$4+1,1)="1", """", IF(MID($F20,I$4+1,1)="4", "[", MID($F20,I$4+1,1))), IF(I$4<=$G20, IF(LEFT($F20,1)="零", "=", LEFT($F20,1)), "")) -> ㄢ | J20: =IF(AND($H20>0, J$4<$G20), IF(MID($F20,J$4+1,1)="1", """", IF(MID($F20,J$4+1,1)="4", "[", MID($F20,J$4+1,1))), IF(J$4<=$G20, IF(LEFT($F20,1)="零", "=", LEFT($F20,1)), "")) -> " | K20: =IF(AND($H20>0, K$4<$G20), IF(MID($F20,K$4+1,1)="1", """", IF(MID($F20,K$4+1,1)="4", "[", MID($F20,K$4+1,1))), IF(K$4<=$G20, IF(LEFT($F20,1)="零", "=", LEFT($F20,1)), "")) -> ㄍ | L20: =IF(AND($H20>0, L$4<$G20), IF(MID($F20,L$4+1,1)="1", """", IF(MID($F20,L$4+1,1)="4", "[", MID($F20,L$4+1,1))), IF(L$4<=$G20, IF(LEFT($F20,1)="零", "=", LEFT($F20,1)), "")) | M20: =IF(AND($H20>0, M$4<$G20), IF(MID($F20,M$4+1,1)="1", """", IF(MID($F20,M$4+1,1)="4", "[", MID($F20,M$4+1,1))), IF(M$4<=$G20, IF(LEFT($F20,1)="零", "=", LEFT($F20,1)), "")) | N20: =IF(AND($H20>0, N$4<$G20), IF(MID($F20,N$4+1,1)="1", """", IF(MID($F20,N$4+1,1)="4", "[", MID($F20,N$4+1,1))), IF(N$4<=$G20, IF(LEFT($F20,1)="零", "=", LEFT($F20,1)), "")) | O20: =IF(AND($H20>0, O$4<$G20), IF(MID($F20,O$4+1,1)="1", """", IF(MID($F20,O$4+1,1)="4", "[", MID($F20,O$4+1,1))), IF(O$4<=$G20, IF(LEFT($F20,1)="零", "=", LEFT($F20,1)), "")) | P20: =IF(AND($H20>0, P$4<$G20), IF(MID($F20,P$4+1,1)="1", """", IF(MID($F20,P$4+1,1)="4", "[", MID($F20,P$4+1,1))), IF(P$4<=$G20, IF(LEFT($F20,1)="零", "=", LEFT($F20,1)), "")) | R20: =IFERROR( _xlfn.IMAGE(_xlfn.XLOOKUP(I20,按鍵位置表[方音符號], 按鍵位置表[Pict URL])), "") -> #VALUE! | S20: =IFERROR( _xlfn.IMAGE(_xlfn.XLOOKUP(J20,按鍵位置表[方音符號], 按鍵位置表[Pict URL])), "") -> #VALUE! | T20: =IFERROR( _xlfn.IMAGE(_xlfn.XLOOKUP(K20,按鍵位置表[方音符號], 按鍵位置表[Pict URL])), "") -> #VALUE! | U20: =IFERROR( _xlfn.IMAGE(_xlfn.XLOOKUP(L20,按鍵位置表[方音符號], 按鍵位置表[Pict URL])), "") | V20: =IFERROR( _xlfn.IMAGE(_xlfn.XLOOKUP(M20,按鍵位置表[方音符號], 按鍵位置表[Pict URL])), "") | W20: =IFERROR( _xlfn.IMAGE(_xlfn.XLOOKUP(N20,按鍵位置表[方音符號], 按鍵位置表[Pict URL])), "") | X20: =IFERROR( _xlfn.IMAGE(_xlfn.XLOOKUP(O20,按鍵位置表[方音符號], 按鍵位置表[Pict URL])), "") | Y20: =IFERROR( _xlfn.IMAGE(_xlfn.XLOOKUP(P20,按鍵位置表[方音符號], 按鍵位置表[Pict URL])), "")
B21: ， | E21: =IF($D21="", "", IF(RIGHT($C21,1)="英",_xlfn.CONCAT("零", $D21),$D21)) | F21: =IF(MID($C21,2,1)="一",_xlfn.CONCAT($D21,"1"),IF(MID($C21,2,1)="四",_xlfn.CONCAT($D21,"4"), IF($D21="","",$E21))) | G21: =IF(LEN($F21)=0, "", LEN($F21)) | H21: =IF($D21="", "", SEARCH(LEFT($F21), $C$1)) | I21: =IF(AND($H21>0, I$4<$G21), IF(MID($F21,I$4+1,1)="1", """", IF(MID($F21,I$4+1,1)="4", "[", MID($F21,I$4+1,1))), IF(I$4<=$G21, IF(LEFT($F21,1)="零", "=", LEFT($F21,1)), "")) | J21: =IF(AND($H21>0, J$4<$G21), IF(MID($F21,J$4+1,1)="1", """", IF(MID($F21,J$4+1,1)="4", "[", MID($F21,J$4+1,1))), IF(J$4<=$G21, IF(LEFT($F21,1)="零", "=", LEFT($F21,1)), "")) | K21: =IF(AND($H21>0, K$4<$G21), IF(MID($F21,K$4+1,1)="1", """", IF(MID($F21,K$4+1,1)="4", "[", MID($F21,K$4+1,1))), IF(K$4<=$G21, IF(LEFT($F21,1)="零", "=", LEFT($F21,1)), "")) | L21: =IF(AND($H21>0, L$4<$G21), IF(MID($F21,L$4+1,1)="1", """", IF(MID($F21,L$4+1,1)="4", "[", MID($F21,L$4+1,1))), IF(L$4<=$G21, IF(LEFT($F21,1)="零", "=", LEFT($F21,1)), "")) | M21: =IF(AND($H21>0, M$4<$G21), IF(MID($F21,M$4+1,1)="1", """", IF(MID($F21,M$4+1,1)="4", "[", MID($F21,M$4+1,1))), IF(M$4<=$G21, IF(LEFT($F21,1)="零", "=", LEFT($F21,1)), "")) | N21: =IF(AND($H21>0, N$4<$G21), IF(MID($F21,N$4+1,1)="1", """", IF(MID($F21,N$4+1,1)="4", "[", MID($F21,N$4+1,1))), IF(N$4<=$G21, IF(LEFT($F21,1)="零", "=", LEFT($F21,1)), "")) | O21: =IF(AND($H21>0, O$4<$G21), IF(MID($F21,O$4+1,1)="1", """", IF(MID($F21,O$4+1,1)="4", "[", MID($F21,O$4+1,1))), IF(O$4<=$G21, IF(LEFT($F21,1)="零", "=", LEFT($F21,1)), "")) | P21: =IF(AND($H21>0, P$4<$G21), IF(MID($F21,P$4+1,1)="1", """", IF(MID($F21,P$4+1,1)="4", "[", MID($F21,P$4+1,1))), IF(P$4<=$G21, IF(LEFT($F21,1)="零", "=", LEFT($F21,1)), "")) | R21: =IFERROR( _xlfn.IMAGE(_xlfn.XLOOKUP(I21,按鍵位置表[方音符號], 按鍵位置表[Pict URL])), "") | S21: =IFERROR( _xlfn.IMAGE(_xlfn.XLOOKUP(J21,按鍵位置表[方音符號], 按鍵位置表[Pict URL])), "") | T21: =IFERROR( _xlfn.IMAGE(_xlfn.XLOOKUP(K21,按鍵位置表[方音符號], 按鍵位置表[Pict URL])), "") | U21: =IFERROR( _xlfn.IMAGE(_xlfn.XLOOKUP(L21,按鍵位置表[方音符號], 按鍵位置表[Pict URL])), "") | V21: =IFERROR( _xlfn.IMAGE(_xlfn.XLOOKUP(M21,按鍵位置表[方音符號], 按鍵位置表[Pict URL])), "") | W21: =IFERROR( _xlfn.IMAGE(_xlfn.XLOOKUP(N21,按鍵位置表[方音符號], 按鍵位置表[Pict URL])), "") | X21: =IFERROR( _xlfn.IMAGE(_xlfn.XLOOKUP(O21,按鍵位置表[方音符號], 按鍵位置表[Pict URL])), "") | Y21: =IFERROR( _xlfn.IMAGE(_xlfn.XLOOKUP(P21,按鍵位置表[方音符號], 按鍵位置表[Pict URL])), "")
B22: 一 | C22: 巾四英 | D22: ㄧㆵ | E22: =IF($D22="", "", IF(RIGHT($C22,1)="英",_xlfn.CONCAT("零", $D22),$D22)) -> 零ㄧㆵ | F22: =IF(MID($C22,2,1)="一",_xlfn.CONCAT($D22,"1"),IF(MID($C22,2,1)="四",_xlfn.CONCAT($D22,"4"), IF($D22="","",$E22))) -> ㄧㆵ4 | G22: =IF(LEN($F22)=0, "", LEN($F22)) -> 3 | H22: =IF($D22="", "", SEARCH(LEFT($F22), $C$1)) -> #VALUE! | I22: =IF(AND($H22>0, I$4<$G22), IF(MID($F22,I$4+1,1)="1", """", IF(MID($F22,I$4+1,1)="4", "[", MID($F22,I$4+1,1))), IF(I$4<=$G22, IF(LEFT($F22,1)="零", "=", LEFT($F22,1)), "")) -> #VALUE! | J22: =IF(AND($H22>0, J$4<$G22), IF(MID($F22,J$4+1,1)="1", """", IF(MID($F22,J$4+1,1)="4", "[", MID($F22,J$4+1,1))), IF(J$4<=$G22, IF(LEFT($F22,1)="零", "=", LEFT($F22,1)), "")) -> #VALUE! | K22: =IF(AND($H22>0, K$4<$G22), IF(MID($F22,K$4+1,1)="1", """", IF(MID($F22,K$4+1,1)="4", "[", MID($F22,K$4+1,1))), IF(K$4<=$G22, IF(LEFT($F22,1)="零", "=", LEFT($F22,1)), "")) -> #VALUE! | L22: =IF(AND($H22>0, L$4<$G22), IF(MID($F22,L$4+1,1)="1", """", IF(MID($F22,L$4+1,1)="4", "[", MID($F22,L$4+1,1))), IF(L$4<=$G22, IF(LEFT($F22,1)="零", "=", LEFT($F22,1)), "")) -> #VALUE! | M22: =IF(AND($H22>0, M$4<$G22), IF(MID($F22,M$4+1,1)="1", """", IF(MID($F22,M$4+1,1)="4", "[", MID($F22,M$4+1,1))), IF(M$4<=$G22, IF(LEFT($F22,1)="零", "=", LEFT($F22,1)), "")) -> #VALUE! | N22: =IF(AND($H22>0, N$4<$G22), IF(MID($F22,N$4+1,1)="1", """", IF(MID($F22,N$4+1,1)="4", "[", MID($F22,N$4+1,1))), IF(N$4<=$G22, IF(LEFT($F22,1)="零", "=", LEFT($F22,1)), "")) -> #VALUE! | O22: =IF(AND($H22>0, O$4<$G22), IF(MID($F22,O$4+1,1)="1", """", IF(MID($F22,O$4+1,1)="4", "[", MID($F22,O$4+1,1))), IF(O$4<=$G22, IF(LEFT($F22,1)="零", "=", LEFT($F22,1)), "")) -> #VALUE! | P22: =IF(AND($H22>0, P$4<$G22), IF(MID($F22,P$4+1,1)="1", """", IF(MID($F22,P$4+1,1)="4", "[", MID($F22,P$4+1,1))), IF(P$4<=$G22, IF(LEFT($F22,1)="零", "=", LEFT($F22,1)), "")) -> #VALUE! | R22: =IFERROR( _xlfn.IMAGE(_xlfn.XLOOKUP(I22,按鍵位置表[方音符號], 按鍵位置表[Pict URL])), "") | S22: =IFERROR( _xlfn.IMAGE(_xlfn.XLOOKUP(J22,按鍵位置表[方音符號], 按鍵位置表[Pict URL])), "") | T22: =IFERROR( _xlfn.IMAGE(_xlfn.XLOOKUP(K22,按鍵位置表[方音符號], 按鍵位置表[Pict URL])), "") | U22: =IFERROR( _xlfn.IMAGE(_xlfn.XLOOKUP(L22,按鍵位置表[方音符號], 按鍵位置表[Pict URL])), "") | V22: =IFERROR( _xlfn.IMAGE(_xlfn.XLOOKUP(M22,按鍵位置表[方音符號], 按鍵位置表[Pict URL])), "") | W22: =IFERROR( _xlfn.IMAGE(_xlfn.XLOOKUP(N22,按鍵位置表[方音符號], 按鍵位置表[Pict URL])), "") | X22: =IFERROR( _xlfn.IMAGE(_xlfn.XLOOKUP(O22,按鍵位置表[方音符號], 按鍵位置表[Pict URL])), "") | Y22: =IFERROR( _xlfn.IMAGE(_xlfn.XLOOKUP(P22,按鍵位置表[方音符號], 按鍵位置表[Pict URL])), "")
B23: 片 | C23: 堅三頗 | D23: ㄆㄧㄢ˪ | E23: =IF($D23="", "", IF(RIGHT($C23,1)="英",_xlfn.CONCAT("零", $D23),$D23)) -> ㄆㄧㄢ˪ | F23: =IF(MID($C23,2,1)="一",_xlfn.CONCAT($D23,"1"),IF(MID($C23,2,1)="四",_xlfn.CONCAT($D23,"4"), IF($D23="","",$E23))) -> ㄆㄧㄢ˪ | G23: =IF(LEN($F23)=0, "", LEN($F23)) -> 4 | H23: =IF($D23="", "", SEARCH(LEFT($F23), $C$1)) -> 3 | I23: =IF(AND($H23>0, I$4<$G23), IF(MID($F23,I$4+1,1)="1", """", IF(MID($F23,I$4+1,1)="4", "[", MID($F23,I$4+1,1))), IF(I$4<=$G23, IF(LEFT($F23,1)="零", "=", LEFT($F23,1)), "")) -> ㄧ | J23: =IF(AND($H23>0, J$4<$G23), IF(MID($F23,J$4+1,1)="1", """", IF(MID($F23,J$4+1,1)="4", "[", MID($F23,J$4+1,1))), IF(J$4<=$G23, IF(LEFT($F23,1)="零", "=", LEFT($F23,1)), "")) -> ㄢ | K23: =IF(AND($H23>0, K$4<$G23), IF(MID($F23,K$4+1,1)="1", """", IF(MID($F23,K$4+1,1)="4", "[", MID($F23,K$4+1,1))), IF(K$4<=$G23, IF(LEFT($F23,1)="零", "=", LEFT($F23,1)), "")) -> ˪ | L23: =IF(AND($H23>0, L$4<$G23), IF(MID($F23,L$4+1,1)="1", """", IF(MID($F23,L$4+1,1)="4", "[", MID($F23,L$4+1,1))), IF(L$4<=$G23, IF(LEFT($F23,1)="零", "=", LEFT($F23,1)), "")) -> ㄆ | M23: =IF(AND($H23>0, M$4<$G23), IF(MID($F23,M$4+1,1)="1", """", IF(MID($F23,M$4+1,1)="4", "[", MID($F23,M$4+1,1))), IF(M$4<=$G23, IF(LEFT($F23,1)="零", "=", LEFT($F23,1)), "")) | N23: =IF(AND($H23>0, N$4<$G23), IF(MID($F23,N$4+1,1)="1", """", IF(MID($F23,N$4+1,1)="4", "[", MID($F23,N$4+1,1))), IF(N$4<=$G23, IF(LEFT($F23,1)="零", "=", LEFT($F23,1)), "")) | O23: =IF(AND($H23>0, O$4<$G23), IF(MID($F23,O$4+1,1)="1", """", IF(MID($F23,O$4+1,1)="4", "[", MID($F23,O$4+1,1))), IF(O$4<=$G23, IF(LEFT($F23,1)="零", "=", LEFT($F23,1)), "")) | P23: =IF(AND($H23>0, P$4<$G23), IF(MID($F23,P$4+1,1)="1", """", IF(MID($F23,P$4+1,1)="4", "[", MID($F23,P$4+1,1))), IF(P$4<=$G23, IF(LEFT($F23,1)="零", "=", LEFT($F23,1)), "")) | R23: =IFERROR( _xlfn.IMAGE(_xlfn.XLOOKUP(I23,按鍵位置表[方音符號], 按鍵位置表[Pict URL])), "") -> #VALUE! | S23: =IFERROR( _xlfn.IMAGE(_xlfn.XLOOKUP(J23,按鍵位置表[方音符號], 按鍵位置表[Pict URL])), "") -> #VALUE! | T23: =IFERROR( _xlfn.IMAGE(_xlfn.XLOOKUP(K23,按鍵位置表[方音符號], 按鍵位置表[Pict URL])), "") -> #VALUE! | U23: =IFERROR( _xlfn.IMAGE(_xlfn.XLOOKUP(L23,按鍵位置表[方音符號], 按鍵位置表[Pict URL])), "") -> #VALUE! | V23: =IFERROR( _xlfn.IMAGE(_xlfn.XLOOKUP(M23,按鍵位置表[方音符號], 按鍵位置表[Pict URL])), "") | W23: =IFERROR( _xlfn.IMAGE(_xlfn.XLOOKUP(N23,按鍵位置表[方音符號], 按鍵位置表[Pict URL])), "") | X23: =IFERROR( _xlfn.IMAGE(_xlfn.XLOOKUP(O23,按鍵位置表[方音符號], 按鍵位置表[Pict URL])), "") | Y23: =IFERROR( _xlfn.IMAGE(_xlfn.XLOOKUP(P23,按鍵位置表[方音符號], 按鍵位置表[Pict URL])), "")
B24: 孤 | C24: 沽一求 | D24: ㄍㆦ | E24: =IF($D24="", "", IF(RIGHT($C24,1)="英",_xlfn.CONCAT("零", $D24),$D24)) -> ㄍㆦ | F24: =IF(MID($C24,2,1)="一",_xlfn.CONCAT($D24,"1"),IF(MID($C24,2,1)="四",_xlfn.CONCAT($D24,"4"), IF($D24="","",$E24))) -> ㄍㆦ1 | G24: =IF(LEN($F24)=0, "", LEN($F24)) -> 3 | H24: =IF($D24="", "", SEARCH(LEFT($F24), $C$1)) -> 10 | I24: =IF(AND($H24>0, I$4<$G24), IF(MID($F24,I$4+1,1)="1", """", IF(MID($F24,I$4+1,1)="4", "[", MID($F24,I$4+1,1))), IF(I$4<=$G24, IF(LEFT($F24,1)="零", "=", LEFT($F24,1)), "")) -> ㆦ | J24: =IF(AND($H24>0, J$4<$G24), IF(MID($F24,J$4+1,1)="1", """", IF(MID($F24,J$4+1,1)="4", "[", MID($F24,J$4+1,1))), IF(J$4<=$G24, IF(LEFT($F24,1)="零", "=", LEFT($F24,1)), "")) -> " | K24: =IF(AND($H24>0, K$4<$G24), IF(MID($F24,K$4+1,1)="1", """", IF(MID($F24,K$4+1,1)="4", "[", MID($F24,K$4+1,1))), IF(K$4<=$G24, IF(LEFT($F24,1)="零", "=", LEFT($F24,1)), "")) -> ㄍ | L24: =IF(AND($H24>0, L$4<$G24), IF(MID($F24,L$4+1,1)="1", """", IF(MID($F24,L$4+1,1)="4", "[", MID($F24,L$4+1,1))), IF(L$4<=$G24, IF(LEFT($F24,1)="零", "=", LEFT($F24,1)), "")) | M24: =IF(AND($H24>0, M$4<$G24), IF(MID($F24,M$4+1,1)="1", """", IF(MID($F24,M$4+1,1)="4", "[", MID($F24,M$4+1,1))), IF(M$4<=$G24, IF(LEFT($F24,1)="零", "=", LEFT($F24,1)), "")) | N24: =IF(AND($H24>0, N$4<$G24), IF(MID($F24,N$4+1,1)="1", """", IF(MID($F24,N$4+1,1)="4", "[", MID($F24,N$4+1,1))), IF(N$4<=$G24, IF(LEFT($F24,1)="零", "=", LEFT($F24,1)), "")) | O24: =IF(AND($H24>0, O$4<$G24), IF(MID($F24,O$4+1,1)="1", """", IF(MID($F24,O$4+1,1)="4", "[", MID($F24,O$4+1,1))), IF(O$4<=$G24, IF(LEFT($F24,1)="零", "=", LEFT($F24,1)), "")) | P24: =IF(AND($H24>0, P$4<$G24), IF(MID($F24,P$4+1,1)="1", """", IF(MID($F24,P$4+1,1)="4", "[", MID($F24,P$4+1,1))), IF(P$4<=$G24, IF(LEFT($F24,1)="零", "=", LEFT($F24,1)), "")) | R24: =IFERROR( _xlfn.IMAGE(_xlfn.XLOOKUP(I24,按鍵位置表[方音符號], 按鍵位置表[Pict URL])), "") -> #VALUE! | S24: =IFERROR( _xlfn.IMAGE(_xlfn.XLOOKUP(J24,按鍵位置表[方音符號], 按鍵位置表[Pict URL])), "") -> #VALUE! | T24: =IFERROR( _xlfn.IMAGE(_xlfn.XLOOKUP(K24,按鍵位置表[方音符號], 按鍵位置表[Pict URL])), "") -> #VALUE! | U24: =IFERROR( _xlfn.IMAGE(_xlfn.XLOOKUP(L24,按鍵位置表[方音符號], 按鍵位置表[Pict URL])), "") | V24: =IFERROR( _xlfn.IMAGE(_xlfn.XLOOKUP(M24,按鍵位置表[方音符號], 按鍵位置表[Pict URL])), "") | W24: =IFERROR( _xlfn.IMAGE(_xlfn.XLOOKUP(N24,按鍵位置表[方音符號], 按鍵位置表[Pict URL])), "") | X24: =IFERROR( _xlfn.IMAGE(_xlfn.XLOOKUP(O24,按鍵位置表[方音符號], 按鍵位置表[Pict URL])), "") | Y24: =IFERROR( _xlfn.IMAGE(_xlfn.XLOOKUP(P24,按鍵位置表[方音符號], 按鍵位置表[Pict URL])), "")
