Workbook
Name 十五音韻母: #REF!
Name 十五音韻母對照表: #REF!
Name 方音符號: #REF!
Name 方音符號: #REF!
Name 方音符號: #REF!
Name 台羅韻母八音反切: #REF!
Name 白話字韻母八音反切: #REF!
Name 字典編碼: #REF!
Name 字典編碼: #REF!
Name 字典編碼: #REF!
Name 注音符號: #REF!
Name 注音編碼: #REF!
Name 拼音字母: #REF!
Name 拼音字母: #REF!
Name 拼音字母: #REF!
Name 閩拼韻母八音反切: #REF!
Name 聲母碼: #REF!
Name 聲母碼表: #REF!
Name 鍵盤位置: #REF!
Name 鍵盤位置: #REF!
Name 鍵盤位置: #REF!
Name 鍵盤按鍵: #REF!
Name 韻母碼表: #REF!
Name 顯示注音輸入: #REF!

Sheet 【拼音類】鍵盤
B2: 1 ! | E2: 2 @ | H2: 3 # | K2: 4 $ | N2: 5 % | Q2: 6 ^ | T2: 7 & | W2: 8 * | Z2: 9 ( | AC2: 0 ) | AF2: - _ | AI2: = +
T3: -p/-t/-k/-h | AF3: 中/低音調
T4: 入聲尾韻 | V4: ptkh | AF4: 陽去/陰去 | AH4: an
C5: Q | F5: W | I5: E | L5: R | O5: T | R5: Y | U5: U | X5: I | AA5: O | AD5: P | AG5: [ { | AJ5: ] } | AM5: \ |
AG6: 低促調 | AJ6: 高促調 | AM6: 高降調
AG7: 陰入 | AJ7: 陽入 | AM7: 陰上（上声）
D8: A | G8: S | J8: D | M8: F | P8: G | S8: H | V8: J | Y8: K | AB8: L | AE8: ; : | AH8: ' "
AE9: 高音調
AE10: 陽平
E11: Z | H11: X | K11: C | N11: V | Q11: B | T11: N | W11: M | Z11: , < | AC11: . > | AF11: / ?
AF12: 低升調
AF13: 陽平

Sheet 【方音符號】鍵盤
BF1: 聲韻調 | BG1: 聲韻調 | BH1: 台語音標 | BO1: 聲韻調 | BP1: 聲韻調 | BQ1: 鼻化韻母 | BX1: 聲韻調 | BY1: 台語音標 | CG1: 聲韻調
B2: 1 ! | E2: 2 @ | H2: 3 # | K2: 4 $ | N2: 0.05 | Q2: 6 ^ | T2: 7 & | W2: 8 * | Z2: 9 ( | AC2: 0 ) | AF2: - _ | AI2: = + | BF2: 韻 | BG2: 韻尾 | BH2: * | BO2: 韻 | BP2: 韻尾 | BX2: 聲 | BY2: * | CG2: 鍵
B3: ㆠ | D3: b | H3: 低音調 | K3: 高降調 | N3: 中音調 | Q3: 低升調 | T3: 促聲調 | W3: ㆩ | Y3: ann | Z3: ㆮ | AA3: 0 | AB3: ainn | AV3: 對映總表
B4: ㄅ | D4: p | E4: ㄉ | G4: d | H4: ˪ | J4: （三）陰去 | K4: ˋ | M4: （二）上声 | N4: ˫ | P4: （七）陽去 | Q4: ˊ | S4: （五）陽平 | T4: 入聲 | V4: ptkh | W4: ㄚ | Y4: a | Z4: ㄞ | AB4: ai | AC4: ㄢ | AD4: 0 | AE4: an | AF4: ㄥㄚ | AH4: an | AI4: Ø | AV4: 台語音標 | AW4: 字典編碼 | AX4: 鍵盤按鍵 | AY4: 方音符號 | AZ4: 聲韻調 | BA4: 字母長度 | BF4: 台語音標 | BG4: 字典編碼 | BH4: 鍵盤按鍵 | BI4: 方音符號 | BJ4: 聲韻調 | BK4: 字母長度 | BO4: 台語音標 | BP4: 字典編碼 | BQ4: 鍵盤按鍵 | BR4: 方音符號 | BS4: 聲韻調 | BT4: 字母長度 | BX4: 台語音標 | BY4: 字典編碼 | BZ4: 鍵盤按鍵 | CA4: 方音符號 | CB4: 聲韻調 | CC4: 字母長度 | CG4: 台語音標 | CH4: 字典編碼 | CI4: 鍵盤按鍵 | CJ4: 方音符號 | CK4: 聲韻調 | CL4: 字母長度
C5: Q | F5: W | I5: E | L5: R | O5: T | R5: Y | U5: U | X5: I | AA5: O | AD5: P | AG5: [ { | AJ5: ] } | AM5: \ | | AU5: =ROW() - 4 -> 1 | AV5: {=TRANSPOSE(D17:AS20)} -> 0 | AW5: 0 | AX5: 0 | AY5: 0 | AZ5: 聲 | BA5: =LEN(AV5) -> 1 | BC5: =" """ & AX5 & """: { commit: """ & AY5 & """ }" & " # " & "/" & AV5 & "/ ==> " & AW5 -> "0": { commit: "0" } # /0/ ==> 0 | BE5: =ROW() - 4 -> 1 | BF5: {=_xlfn._xlws.SORT( _xlfn._xlws.FILTER($AV5:$BA64,($AZ5:$AZ64=BF2)*($AZ5:$AZ64<>BG2)*($AV5:$BA64=BH2), "無符合資料"), 6, -1)} -> #VALUE! | BM5: =IFERROR( IF(LEN(BG5)=0, "", IF(BG5=BF5, "", " - xform/" & BF5 & "/" & BG5 & "/ # " & "【" & BH5 & "】 ==> " & BJ5 & "： " & BI5 & " [" & BF5 & "]")), "") | BN5: =ROW() - 4 -> 1 | BO5: {=_xlfn._xlws.SORT( _xlfn._xlws.FILTER($AV5:$BA64,($AZ5:$AZ64=BO2)*($AZ5:$AZ64<>BP2), "無符合資料"), 6, -1)} -> 0 | BP5: 0 | BQ5: 0 | BR5: 0 | BS5: 韻 | BT5: 1 | BV5: =IFERROR( IF(LEN(BP5)=0, "", IF(EXACT(BP5,BO5), "", " - xform/" & BO5 & "/" & BP5 & "/ # " & "【" & BQ5 & "】 ==> " & BS5 & "： " & BR5 & " [" & BO5 & "]")), "") | BW5: =ROW() - 4 -> 1 | BX5: {=_xlfn._xlws.SORT( _xlfn._xlws.FILTER($AV$5:$BA$64,($AZ5:$AZ64=BX2)*($AV5:$AV64<>BY2), "無符合資料"), 6, -1)} -> 0 | BY5: 0 | BZ5: 0 | CA5: 0 | CB5: 聲 | CC5: 1 | CE5: =IFERROR( IF(LEN(BY5)=0, "", IF(EXACT(BY5,BX5), "", " - xform/^" & BX5 & "/" & BY5 & "/ # " & "【" & BZ5 & "】 ==> " & CB5 & "： " & CA5 & " [" & BX5 & "]")), "") | CF5: =ROW() - 4 -> 1 | CG5: {=_xlfn._xlws.FILTER($AV$5:$BA$64,($AZ5:$AZ64=CG2), "無符合資料")} -> 0 | CH5: 0 | CI5: 0 | CJ5: 0 | CK5: 鍵 | CL5: 0
I6: ㆣ | K6: gg | L6: ㆢ | N6: jj | R6: ㆡ | T6: zz | U6: ㆪ | W6: inn | X6: ㆧ | Z6: oonn | AA6: ㆱ | AC6: om | AG6: 低促調 | AJ6: 高促調 | AU6: =ROW() - 4 -> 2 | AV6: 0 | AW6: 0 | AX6: 0 | AY6: 0 | AZ6: 聲 | BA6: =LEN(AV6) -> 1 | BC6: =" """ & AX6 & """: { commit: """ & AY6 & """ }" & " # " & "/" & AV7 & "/ ==> " & AW6 -> "0": { commit: "0" } # /0/ ==> 0 | BE6: =ROW() - 4 -> 2 | BM6: =IFERROR( IF(LEN(BG6)=0, "", IF(BG6=BF6, "", " - xform/" & BF6 & "/" & BG6 & "/ # " & "【" & BH6 & "】 ==> " & BJ6 & "： " & BI6 & " [" & BF6 & "]")), "") | BN6: =ROW() - 4 -> 2 | BO6: 0 | BP6: 0 | BQ6: 0 | BR6: 0 | BS6: 韻 | BT6: 1 | BV6: =IFERROR( IF(LEN(BP6)=0, "", IF(EXACT(BP6,BO6), "", " - xform/" & BO6 & "/" & BP6 & "/ # " & "【" & BQ6 & "】 ==> " & BS6 & "： " & BR6 & " [" & BO6 & "]")), "") | BW6: =ROW() - 4 -> 2 | BX6: 0 | BY6: 0 | BZ6: 0 | CA6: 0 | CB6: 聲 | CC6: 1 | CE6: =IFERROR( IF(LEN(BY6)=0, "", IF(EXACT(BY6,BX6), "", " - xform/^" & BX6 & "/" & BY6 & "/ # " & "【" & BZ6 & "】 ==> " & CB6 & "： " & CA6 & " [" & BX6 & "]")), "") | CF6: =ROW() - 4 -> 2 | CG6: 0 | CH6: 0 | CI6: 0 | CJ6: 0 | CK6: 鍵 | CL6: 0
C7: ㄆ | E7: ph | F7: ㄊ | H7: t | I7: ㄍ | J7: 0 | K7: g | L7: ㄐ | N7: jj | O7: ㆵ | Q7: t0 | R7: ㄗ | T7: z | U7: ㄧ | W7: i | X7: ㆦ | Z7: oo | AA7: ㆲ | AC7: ong | AD7: ㄣ | AF7: -n | AI7: （四）陰入 | AJ7: · | AL7: （八）陽入 | AU7: =ROW() - 4 -> 3 | AV7: 0 | AW7: 0 | AX7: 0 | AY7: 0 | AZ7: 聲 | BA7: =LEN(AV7) -> 1 | BC7: =" """ & AX7 & """: { commit: """ & AY7 & """ }" & " # " & "/" & AV8 & "/ ==> " & AW7 -> "0": { commit: "0" } # /0/ ==> 0 | BE7: =ROW() - 4 -> 3 | BM7: =IFERROR( IF(LEN(BG7)=0, "", IF(BG7=BF7, "", " - xform/" & BF7 & "/" & BG7 & "/ # " & "【" & BH7 & "】 ==> " & BJ7 & "： " & BI7 & " [" & BF7 & "]")), "") | BN7: =ROW() - 4 -> 3 | BO7: 0 | BP7: 0 | BQ7: 0 | BR7: 0 | BS7: 韻 | BT7: 1 | BV7: =IFERROR( IF(LEN(BP7)=0, "", IF(EXACT(BP7,BO7), "", " - xform/" & BO7 & "/" & BP7 & "/ # " & "【" & BQ7 & "】 ==> " & BS7 & "： " & BR7 & " [" & BO7 & "]")), "") | BW7: =ROW() - 4 -> 3 | BX7: 0 | BY7: 0 | BZ7: 0 | CA7: 0 | CB7: 聲 | CC7: 1 | CE7: =IFERROR( IF(LEN(BY7)=0, "", IF(EXACT(BY7,BX7), "", " - xform/^" & BX7 & "/" & BY7 & "/ # " & "【" & BZ7 & "】 ==> " & CB7 & "： " & CA7 & " [" & BX7 & "]")), "") | CF7: =ROW() - 4 -> 3
D8: A | G8: S | J8: D | M8: F | P8: G | S8: H | V8: J | Y8: K | AB8: L | AE8: ; : | AH8: ' " | AU8: =ROW() - 4 -> 4 | AV8: 0 | AW8: 0 | AX8: 0 | AY8: 0 | AZ8: 聲 | BA8: =LEN(AV8) -> 1 | BC8: =" """ & AX8 & """: { commit: """ & AY8 & """ }" & " # " & "/" & AV9 & "/ ==> " & AW8 -> "0": { commit: "0" } # /0/ ==> 0 | BE8: =ROW() - 4 -> 4 | BM8: =IFERROR( IF(LEN(BG8)=0, "", IF(BG8=BF8, "", " - xform/" & BF8 & "/" & BG8 & "/ # " & "【" & BH8 & "】 ==> " & BJ8 & "： " & BI8 & " [" & BF8 & "]")), "") | BN8: =ROW() - 4 -> 4 | BO8: 0 | BP8: 0 | BQ8: 0 | BR8: 0 | BS8: 韻 | BT8: 1 | BV8: =IFERROR( IF(LEN(BP8)=0, "", IF(EXACT(BP8,BO8), "", " - xform/" & BO8 & "/" & BP8 & "/ # " & "【" & BQ8 & "】 ==> " & BS8 & "： " & BR8 & " [" & BO8 & "]")), "") | BW8: =ROW() - 4 -> 4 | BX8: 0 | BY8: 0 | BZ8: 0 | CA8: 0 | CB8: 聲 | CC8: 1 | CE8: =IFERROR( IF(LEN(BY8)=0, "", IF(EXACT(BY8,BX8), "", " - xform/^" & BX8 & "/" & BY8 & "/ # " & "【" & BZ8 & "】 ==> " & CB8 & "： " & CA8 & " [" & BX8 & "]")), "") | CF8: =ROW() - 4 -> 4
V9: ㆫ | W9: 0 | X9: unn | Y9: ㆨ | AA9: ir | AB9: ㆯ | AD9: aunn | AH9: 高音調 | AU9: =ROW() - 4 -> 5 | AV9: 0 | AW9: 0 | AX9: 0 | AY9: 0 | AZ9: 聲 | BA9: =LEN(AV9) -> 1 | BC9: =" """ & AX9 & """: { commit: """ & AY9 & """ }" & " # " & "/" & AV10 & "/ ==> " & AW9 -> "0": { commit: "0" } # /0/ ==> 0 | BE9: =ROW() - 4 -> 5 | BM9: =IFERROR( IF(LEN(BG9)=0, "", IF(BG9=BF9, "", " - xform/" & BF9 & "/" & BG9 & "/ # " & "【" & BH9 & "】 ==> " & BJ9 & "： " & BI9 & " [" & BF9 & "]")), "") | BN9: =ROW() - 4 -> 5 | BO9: 0 | BP9: 0 | BQ9: 0 | BR9: 0 | BS9: 韻 | BT9: 1 | BV9: =IFERROR( IF(LEN(BP9)=0, "", IF(EXACT(BP9,BO9), "", " - xform/" & BO9 & "/" & BP9 & "/ # " & "【" & BQ9 & "】 ==> " & BS9 & "： " & BR9 & " [" & BO9 & "]")), "") | BW9: =ROW() - 4 -> 5 | BX9: 0 | BY9: 0 | BZ9: 0 | CA9: 0 | CB9: 聲 | CC9: 1 | CE9: =IFERROR( IF(LEN(BY9)=0, "", IF(EXACT(BY9,BX9), "", " - xform/^" & BX9 & "/" & BY9 & "/ # " & "【" & BZ9 & "】 ==> " & CB9 & "： " & CA9 & " [" & BX9 & "]")), "") | CF9: =ROW() - 4 -> 5
D10: ㄇ | F10: m- | G10: ㄋ | I10: n- | J10: ㄎ | K10: 0 | L10: k | M10: ㄑ | O10: ch | P10: ㆻ | R10: k0 | S10: ㄘ | U10: c | V10: ㄨ | X10: u | Y10: ㄜ | AA10: or | AB10: ㄠ | AD10: au | AE10: ㄤ | AG10: ang | AJ10: （一）陰平 | AU10: =ROW() - 4 -> 6 | AV10: 0 | AW10: 0 | AX10: 0 | AY10: 0 | AZ10: 聲 | BA10: =LEN(AV10) -> 1 | BC10: =" """ & AX10 & """: { commit: """ & AY10 & """ }" & " # " & "/" & AV11 & "/ ==> " & AW10 -> "0": { commit: "0" } # /0/ ==> 0 | BE10: =ROW() - 4 -> 6 | BM10: =IFERROR( IF(LEN(BG10)=0, "", IF(BG10=BF10, "", " - xform/" & BF10 & "/" & BG10 & "/ # " & "【" & BH10 & "】 ==> " & BJ10 & "： " & BI10 & " [" & BF10 & "]")), "") | BN10: =ROW() - 4 -> 6 | BO10: 0 | BP10: 0 | BQ10: 0 | BR10: 0 | BS10: 韻 | BT10: 1 | BV10: =IFERROR( IF(LEN(BP10)=0, "", IF(EXACT(BP10,BO10), "", " - xform/" & BO10 & "/" & BP10 & "/ # " & "【" & BQ10 & "】 ==> " & BS10 & "： " & BR10 & " [" & BO10 & "]")), "") | BW10: =ROW() - 4 -> 6 | BX10: 0 | BY10: 0 | BZ10: 0 | CA10: 0 | CB10: 聲 | CC10: 1 | CE10: =IFERROR( IF(LEN(BY10)=0, "", IF(EXACT(BY10,BX10), "", " - xform/^" & BX10 & "/" & BY10 & "/ # " & "【" & BZ10 & "】 ==> " & CB10 & "： " & CA10 & " [" & BX10 & "]")), "") | CF10: =ROW() - 4 -> 6
E11: Z | H11: X | K11: C | N11: V | Q11: B | T11: N | W11: M | Z11: , < | AC11: . > | AF11: / ? | AU11: =ROW() - 4 -> 7 | AV11: 0 | AW11: 0 | AX11: 0 | AY11: 0 | AZ11: 聲 | BA11: =LEN(AV11) -> 1 | BC11: =" """ & AX11 & """: { commit: """ & AY11 & """ }" & " # " & "/" & AV12 & "/ ==> " & AW11 -> "0": { commit: "0" } # /0/ ==> 0 | BE11: =ROW() - 4 -> 7 | BM11: =IFERROR( IF(LEN(BG11)=0, "", IF(BG11=BF11, "", " - xform/" & BF11 & "/" & BG11 & "/ # " & "【" & BH11 & "】 ==> " & BJ11 & "： " & BI11 & " [" & BF11 & "]")), "") | BN11: =ROW() - 4 -> 7 | BO11: 0 | BP11: 0 | BQ11: 0 | BR11: 0 | BS11: 韻 | BT11: 1 | BV11: =IFERROR( IF(LEN(BP11)=0, "", IF(EXACT(BP11,BO11), "", " - xform/" & BO11 & "/" & BP11 & "/ # " & "【" & BQ11 & "】 ==> " & BS11 & "： " & BR11 & " [" & BO11 & "]")), "") | BW11: =ROW() - 4 -> 7 | BX11: 0 | BY11: 0 | BZ11: 0 | CA11: 0 | CB11: 聲 | CC11: 1 | CE11: =IFERROR( IF(LEN(BY11)=0, "", IF(EXACT(BY11,BX11), "", " - xform/^" & BX11 & "/" & BY11 & "/ # " & "【" & BZ11 & "】 ==> " & CB11 & "： " & CA11 & " [" & BX11 & "]")), "") | CF11: =ROW() - 4 -> 7
T12: ㄫ | V12: ng- | W12: ㆰ | Y12: am | Z12: ㆥ | AA12: 0 | AB12: enn | AU12: =ROW() - 4 -> 8 | AV12: 0 | AW12: 0 | AX12: 0 | AY12: 0 | AZ12: 聲 | BA12: =LEN(AV12) -> 1 | BC12: =" """ & AX12 & """: { commit: """ & AY12 & """ }" & " # " & "/" & AV13 & "/ ==> " & AW12 -> "0": { commit: "0" } # /0/ ==> 0 | BE12: =ROW() - 4 -> 8 | BM12: =IFERROR( IF(LEN(BG12)=0, "", IF(BG12=BF12, "", " - xform/" & BF12 & "/" & BG12 & "/ # " & "【" & BH12 & "】 ==> " & BJ12 & "： " & BI12 & " [" & BF12 & "]")), "") | BN12: =ROW() - 4 -> 8 | BO12: 0 | BP12: 0 | BQ12: 0 | BR12: 0 | BS12: 韻 | BT12: 1 | BV12: =IFERROR( IF(LEN(BP12)=0, "", IF(EXACT(BP12,BO12), "", " - xform/" & BO12 & "/" & BP12 & "/ # " & "【" & BQ12 & "】 ==> " & BS12 & "： " & BR12 & " [" & BO12 & "]")), "") | BW12: =ROW() - 4 -> 8 | BX12: 0 | BY12: 0 | BZ12: 0 | CA12: 0 | CB12: 聲 | CC12: 1 | CE12: =IFERROR( IF(LEN(BY12)=0, "", IF(EXACT(BY12,BX12), "", " - xform/^" & BX12 & "/" & BY12 & "/ # " & "【" & BZ12 & "】 ==> " & CB12 & "： " & CA12 & " [" & BX12 & "]")), "") | CF12: =ROW() - 4 -> 8
E13: ㆷ | G13: h0 | H13: ㄌ | J13: l | K13: ㄏ | M13: h | N13: ㄒ | P13: sh | Q13: ㆴ | S13: p0 | T13: ㄙ | V13: s | W13: ㆬ | Y13: -m | Z13: ㆤ | AA13: 0 | AB13: e | AF13: ㆭ | AH13: -ng | AU13: =ROW() - 4 -> 9 | AV13: 0 | AW13: 0 | AX13: 0 | AY13: 0 | AZ13: 聲 | BA13: =LEN(AV13) -> 1 | BC13: =" """ & AX13 & """: { commit: """ & AY13 & """ }" & " # " & "/" & AV14 & "/ ==> " & AW13 -> "0": { commit: "0" } # /0/ ==> 0 | BE13: =ROW() - 4 -> 9 | BM13: =IFERROR( IF(LEN(BG13)=0, "", IF(BG13=BF13, "", " - xform/" & BF13 & "/" & BG13 & "/ # " & "【" & BH13 & "】 ==> " & BJ13 & "： " & BI13 & " [" & BF13 & "]")), "") | BN13: =ROW() - 4 -> 9 | BO13: 0 | BP13: 0 | BQ13: 0 | BR13: 0 | BS13: 韻 | BT13: 0 | BV13: =IFERROR( IF(LEN(BP13)=0, "", IF(EXACT(BP13,BO13), "", " - xform/" & BO13 & "/" & BP13 & "/ # " & "【" & BQ13 & "】 ==> " & BS13 & "： " & BR13 & " [" & BO13 & "]")), "") | BW13: =ROW() - 4 -> 9 | BX13: 0 | BY13: 0 | BZ13: 0 | CA13: 0 | CB13: 聲 | CC13: 1 | CE13: =IFERROR( IF(LEN(BY13)=0, "", IF(EXACT(BY13,BX13), "", " - xform/^" & BX13 & "/" & BY13 & "/ # " & "【" & BZ13 & "】 ==> " & CB13 & "： " & CA13 & " [" & BX13 & "]")), "") | CF13: =ROW() - 4 -> 9
AU14: =ROW() - 4 -> 10 | AV14: 0 | AW14: 0 | AX14: 0 | AY14: 0 | AZ14: 聲 | BA14: =LEN(AV14) -> 1 | BC14: =" """ & AX14 & """: { commit: """ & AY14 & """ }" & " # " & "/" & AV15 & "/ ==> " & AW14 -> "0": { commit: "0" } # /0/ ==> 0 | BE14: =ROW() - 4 -> 10 | BM14: =IFERROR( IF(LEN(BG14)=0, "", IF(BG14=BF14, "", " - xform/" & BF14 & "/" & BG14 & "/ # " & "【" & BH14 & "】 ==> " & BJ14 & "： " & BI14 & " [" & BF14 & "]")), "") | BN14: =ROW() - 4 -> 10 | BO14: 0 | BP14: 0 | BQ14: 0 | BR14: 0 | BS14: 韻 | BT14: 0 | BV14: =IFERROR( IF(LEN(BP14)=0, "", IF(EXACT(BP14,BO14), "", " - xform/" & BO14 & "/" & BP14 & "/ # " & "【" & BQ14 & "】 ==> " & BS14 & "： " & BR14 & " [" & BO14 & "]")), "") | BW14: =ROW() - 4 -> 10 | BX14: 0 | BY14: 0 | BZ14: 0 | CA14: 0 | CB14: 聲 | CC14: 1 | CE14: =IFERROR( IF(LEN(BY14)=0, "", IF(EXACT(BY14,BX14), "", " - xform/^" & BX14 & "/" & BY14 & "/ # " & "【" & BZ14 & "】 ==> " & CB14 & "： " & CA14 & " [" & BX14 & "]")), "") | CF14: =ROW() - 4 -> 10
AU15: =ROW() - 4 -> 11 | AV15: 0 | AW15: 0 | AX15: 0 | AY15: 0 | AZ15: 聲 | BA15: =LEN(AV15) -> 1 | BC15: =" """ & AX15 & """: { commit: """ & AY15 & """ }" & " # " & "/" & AV16 & "/ ==> " & AW15 -> "0": { commit: "0" } # /0/ ==> 0 | BE15: =ROW() - 4 -> 11 | BM15: =IFERROR( IF(LEN(BG15)=0, "", IF(BG15=BF15, "", " - xform/" & BF15 & "/" & BG15 & "/ # " & "【" & BH15 & "】 ==> " & BJ15 & "： " & BI15 & " [" & BF15 & "]")), "") | BN15: =ROW() - 4 -> 11 | BO15: 0 | BP15: 0 | BQ15: 0 | BR15: 0 | BS15: 韻 | BT15: 0 | BV15: =IFERROR( IF(LEN(BP15)=0, "", IF(EXACT(BP15,BO15), "", " - xform/" & BO15 & "/" & BP15 & "/ # " & "【" & BQ15 & "】 ==> " & BS15 & "： " & BR15 & " [" & BO15 & "]")), "") | BW15: =ROW() - 4 -> 11 | BX15: 0 | BY15: 0 | BZ15: 0 | CA15: 0 | CB15: 聲 | CC15: 1 | CE15: =_xlfn.CONCAT(" - xform/^", BY15, "/", BY15, "/", " # ", CA15, " [", BX15, "]" ) -> - xform/^0/0/ # 0 [0] | CF15: =ROW() - 4 -> 11
AU16: =ROW() - 4 -> 12 | AV16: 0 | AW16: 0 | AX16: 0 | AY16: 0 | AZ16: 聲 | BA16: =LEN(AV16) -> 1 | BC16: =" """ & AX16 & """: { commit: """ & AY16 & """ }" & " # " & "/" & AV17 & "/ ==> " & AW16 -> "0": { commit: "0" } # /0/ ==> 0 | BE16: =ROW() - 4 -> 12 | BM16: =IFERROR( IF(LEN(BG16)=0, "", IF(BG16=BF16, "", " - xform/" & BF16 & "/" & BG16 & "/ # " & "【" & BH16 & "】 ==> " & BJ16 & "： " & BI16 & " [" & BF16 & "]")), "") | BN16: =ROW() - 4 -> 12 | BO16: 0 | BP16: 0 | BQ16: 0 | BR16: 0 | BS16: 韻 | BT16: 0 | BV16: =IFERROR( IF(LEN(BP16)=0, "", IF(EXACT(BP16,BO16), "", " - xform/" & BO16 & "/" & BP16 & "/ # " & "【" & BQ16 & "】 ==> " & BS16 & "： " & BR16 & " [" & BO16 & "]")), "") | BW16: =ROW() - 4 -> 12 | BX16: 0 | BY16: 0 | BZ16: 0 | CA16: 0 | CB16: 聲 | CC16: 1 | CE16: =_xlfn.CONCAT(" - xform/^", BY16, "/", BY16, "/", " # ", CA16, " [", BX16, "]" ) -> - xform/^0/0/ # 0 [0] | CF16: =ROW() - 4 -> 12
AU17: =ROW() - 4 -> 13 | AV17: 0 | AW17: 0 | AX17: 0 | AY17: 0 | AZ17: 聲 | BA17: =LEN(AV17) -> 1 | BC17: =" """ & AX17 & """: { commit: """ & AY17 & """ }" & " # " & "/" & AV18 & "/ ==> " & AW17 -> "0": { commit: "0" } # /0/ ==> 0 | BE17: =ROW() - 4 -> 13 | BM17: =IFERROR( IF(LEN(BG17)=0, "", IF(BG17=BF17, "", " - xform/" & BF17 & "/" & BG17 & "/ # " & "【" & BH17 & "】 ==> " & BJ17 & "： " & BI17 & " [" & BF17 & "]")), "") | BN17: =ROW() - 4 -> 13 | BO17: 0 | BP17: 0 | BQ17: 0 | BR17: 0 | BS17: 韻 | BT17: 0 | BV17: =IFERROR( IF(LEN(BP17)=0, "", IF(EXACT(BP17,BO17), "", " - xform/" & BO17 & "/" & BP17 & "/ # " & "【" & BQ17 & "】 ==> " & BS17 & "： " & BR17 & " [" & BO17 & "]")), "") | BW17: =ROW() - 4 -> 13 | BX17: 0 | BY17: 0 | BZ17: 0 | CA17: 0 | CB17: 聲 | CC17: 1 | CE17: =_xlfn.CONCAT(" - xform/^", BY17, "/", BY17, "/", " # ", CA17, " [", BX17, "]" ) -> - xform/^0/0/ # 0 [0] | CF17: =ROW() - 4 -> 13
AU18: =ROW() - 4 -> 14 | AV18: 0 | AW18: 0 | AX18: 0 | AY18: 0 | AZ18: 聲 | BA18: =LEN(AV18) -> 1 | BC18: =" """ & AX18 & """: { commit: """ & AY18 & """ }" & " # " & "/" & AV19 & "/ ==> " & AW18 -> "0": { commit: "0" } # /0/ ==> 0 | BE18: =ROW() - 4 -> 14 | BM18: =IFERROR( IF(LEN(BG18)=0, "", IF(BG18=BF18, "", " - xform/" & BF18 & "/" & BG18 & "/ # " & "【" & BH18 & "】 ==> " & BJ18 & "： " & BI18 & " [" & BF18 & "]")), "") | BN18: =ROW() - 4 -> 14 | BO18: 0 | BP18: 0 | BQ18: 0 | BR18: 0 | BS18: 韻 | BT18: 0 | BV18: =IFERROR( IF(LEN(BP18)=0, "", IF(EXACT(BP18,BO18), "", " - xform/" & BO18 & "/" & BP18 & "/ # " & "【" & BQ18 & "】 ==> " & BS18 & "： " & BR18 & " [" & BO18 & "]")), "") | BW18: =ROW() - 4 -> 14 | BX18: 0 | BY18: 0 | BZ18: 0 | CA18: 0 | CB18: 聲 | CC18: 1 | CE18: =_xlfn.CONCAT(" - xform/^", BY18, "/", BY18, "/", " # ", CA18, " [", BX18, "]" ) -> - xform/^0/0/ # 0 [0] | CF18: =ROW() - 4 -> 14
AU19: =ROW() - 4 -> 15 | AV19: 0 | AW19: 0 | AX19: 0 | AY19: 0 | AZ19: 聲 | BA19: =LEN(AV19) -> 1 | BC19: =" """ & AX19 & """: { commit: """ & AY19 & """ }" & " # " & "/" & AV20 & "/ ==> " & AW19 -> "0": { commit: "0" } # /0/ ==> 0 | BE19: =ROW() - 4 -> 15 | BM19: =IFERROR( IF(LEN(BG19)=0, "", IF(BG19=BF19, "", " - xform/" & BF19 & "/" & BG19 & "/ # " & "【" & BH19 & "】 ==> " & BJ19 & "： " & BI19 & " [" & BF19 & "]")), "") | BN19: =ROW() - 4 -> 15 | BO19: 0 | BP19: 0 | BQ19: 0 | BR19: 0 | BS19: 韻 | BT19: 0 | BV19: =IFERROR( IF(LEN(BP19)=0, "", IF(EXACT(BP19,BO19), "", " - xform/" & BO19 & "/" & BP19 & "/ # " & "【" & BQ19 & "】 ==> " & BS19 & "： " & BR19 & " [" & BO19 & "]")), "") | BW19: =ROW() - 4 -> 15 | BX19: 0 | BY19: 0 | BZ19: 0 | CA19: 0 | CB19: 聲 | CC19: 1 | CE19: =_xlfn.CONCAT(" - xform/^", BY19, "/", BY19, "/", " # ", CA19, " [", BX19, "]" ) -> - xform/^0/0/ # 0 [0] | CF19: =ROW() - 4 -> 15
AU20: =ROW() - 4 -> 16 | AV20: 0 | AW20: 0 | AX20: 0 | AY20: 0 | AZ20: 聲 | BA20: =LEN(AV20) -> 1 | BC20: =" """ & AX20 & """: { commit: """ & AY20 & """ }" & " # " & "/" & AV21 & "/ ==> " & AW20 -> "0": { commit: "0" } # /0/ ==> 0 | BE20: =ROW() - 4 -> 16 | BM20: =IFERROR( IF(LEN(BG20)=0, "", IF(BG20=BF20, "", " - xform/" & BF20 & "/" & BG20 & "/ # " & "【" & BH20 & "】 ==> " & BJ20 & "： " & BI20 & " [" & BF20 & "]")), "") | BN20: =ROW() - 4 -> 16 | BV20: =IFERROR( IF(LEN(BP20)=0, "", IF(EXACT(BP20,BO20), "", " - xform/" & BO20 & "/" & BP20 & "/ # " & "【" & BQ20 & "】 ==> " & BS20 & "： " & BR20 & " [" & BO20 & "]")), "") | BW20: =ROW() - 4 -> 16 | BX20: 0 | BY20: 0 | BZ20: 0 | CA20: 0 | CB20: 聲 | CC20: 1 | CE20: =_xlfn.CONCAT(" - xform/^", BY20, "/", BY20, "/", " # ", CA20, " [", BX20, "]" ) -> - xform/^0/0/ # 0 [0] | CF20: =ROW() - 4 -> 16
AU21: =ROW() - 4 -> 17 | AV21: 0 | AW21: 0 | AX21: 0 | AY21: 0 | AZ21: 聲 | BA21: =LEN(AV21) -> 1 | BC21: =" """ & AX21 & """: { commit: """ & AY21 & """ }" & " # " & "/" & AV22 & "/ ==> " & AW21 -> "0": { commit: "0" } # /0/ ==> 0 | BE21: =ROW() - 4 -> 17 | BM21: =IFERROR( IF(LEN(BG21)=0, "", IF(BG21=BF21, "", " - xform/" & BF21 & "/" & BG21 & "/ # " & "【" & BH21 & "】 ==> " & BJ21 & "： " & BI21 & " [" & BF21 & "]")), "") | BN21: =ROW() - 4 -> 17 | BV21: =IFERROR( IF(LEN(BP21)=0, "", IF(EXACT(BP21,BO21), "", " - xform/" & BO21 & "/" & BP21 & "/ # " & "【" & BQ21 & "】 ==> " & BS21 & "： " & BR21 & " [" & BO21 & "]")), "") | BW21: =ROW() - 4 -> 17 | BX21: 0 | BY21: 0 | BZ21: 0 | CA21: 0 | CB21: 聲 | CC21: 1 | CE21: =_xlfn.CONCAT(" - xform/^", BY21, "/", BY21, "/", " # ", CA21, " [", BX21, "]" ) -> - xform/^0/0/ # 0 [0] | CF21: =ROW() - 4 -> 17
AU22: =ROW() - 4 -> 18 | AV22: 0 | AW22: 0 | AX22: 0 | AY22: 0 | AZ22: 聲 | BA22: =LEN(AV22) -> 1 | BC22: =" """ & AX22 & """: { commit: """ & AY22 & """ }" & " # " & "/" & AV23 & "/ ==> " & AW22 -> "0": { commit: "0" } # /0/ ==> 0 | BE22: =ROW() - 4 -> 18 | BM22: =IFERROR( IF(LEN(BG22)=0, "", IF(BG22=BF22, "", " - xform/" & BF22 & "/" & BG22 & "/ # " & "【" & BH22 & "】 ==> " & BJ22 & "： " & BI22 & " [" & BF22 & "]")), "") | BN22: =ROW() - 4 -> 18 | BV22: =IFERROR( IF(LEN(BP22)=0, "", IF(EXACT(BP22,BO22), "", " - xform/" & BO22 & "/" & BP22 & "/ # " & "【" & BQ22 & "】 ==> " & BS22 & "： " & BR22 & " [" & BO22 & "]")), "") | BW22: =ROW() - 4 -> 18 | BX22: 0 | BY22: 0 | BZ22: 0 | CA22: 0 | CB22: 聲 | CC22: 1 | CE22: =_xlfn.CONCAT(" - xform/^", BY22, "/", BY22, "/", " # ", CA22, " [", BX22, "]" ) -> - xform/^0/0/ # 0 [0] | CF22: =ROW() - 4 -> 18
AU23: =ROW() - 4 -> 19 | AV23: 0 | AW23: 0 | AX23: 0 | AY23: 0 | AZ23: 聲 | BA23: =LEN(AV23) -> 1 | BC23: =" """ & AX23 & """: { commit: """ & AY23 & """ }" & " # " & "/" & AV24 & "/ ==> " & AW23 -> "0": { commit: "0" } # /0/ ==> 0 | BE23: =ROW() - 4 -> 19 | BM23: =IFERROR( IF(LEN(BG23)=0, "", IF(BG23=BF23, "", " - xform/" & BF23 & "/" & BG23 & "/ # " & "【" & BH23 & "】 ==> " & BJ23 & "： " & BI23 & " [" & BF23 & "]")), "") | BN23: =ROW() - 4 -> 19 | BV23: =IFERROR( IF(LEN(BP23)=0, "", IF(EXACT(BP23,BO23), "", " - xform/" & BO23 & "/" & BP23 & "/ # " & "【" & BQ23 & "】 ==> " & BS23 & "： " & BR23 & " [" & BO23 & "]")), "") | BW23: =ROW() - 4 -> 19 | BX23: 0 | BY23: 0 | BZ23: 0 | CA23: 0 | CB23: 聲 | CC23: 1 | CE23: =_xlfn.CONCAT(" - xform/^", BY23, "/", BY23, "/", " # ", CA23, " [", BX23, "]" ) -> - xform/^0/0/ # 0 [0] | CF23: =ROW() - 4 -> 19
AU24: =ROW() - 4 -> 20 | AV24: 0 | AW24: 0 | AX24: 0 | AY24: 0 | AZ24: 聲 | BA24: =LEN(AV24) -> 1 | BC24: =" """ & AX24 & """: { commit: """ & AY24 & """ }" & " # " & "/" & AV25 & "/ ==> " & AW24 -> "0": { commit: "0" } # /0/ ==> 0 | BE24: =ROW() - 4 -> 20 | BM24: =IFERROR( IF(LEN(BG24)=0, "", IF(BG24=BF24, "", " - xform/" & BF24 & "/" & BG24 & "/ # " & "【" & BH24 & "】 ==> " & BJ24 & "： " & BI24 & " [" & BF24 & "]")), "") | BN24: =ROW() - 4 -> 20 | BV24: =IFERROR( IF(LEN(BP24)=0, "", IF(EXACT(BP24,BO24), "", " - xform/" & BO24 & "/" & BP24 & "/ # " & "【" & BQ24 & "】 ==> " & BS24 & "： " & BR24 & " [" & BO24 & "]")), "") | BW24: =ROW() - 4 -> 20 | BX24: 0 | BY24: 0 | BZ24: 0 | CA24: 0 | CB24: 聲 | CC24: 1 | CE24: =_xlfn.CONCAT(" - xform/^", BY24, "/", BY24, "/", " # ", CA24, " [", BX24, "]" ) -> - xform/^0/0/ # 0 [0] | CF24: =ROW() - 4 -> 20
AU25: =ROW() - 4 -> 21 | AV25: 0 | AW25: 0 | AX25: 0 | AY25: 0 | AZ25: 聲 | BA25: =LEN(AV25) -> 1 | BC25: =" """ & AX25 & """: { commit: """ & AY25 & """ }" & " # " & "/" & AV26 & "/ ==> " & AW25 -> "0": { commit: "0" } # /0/ ==> 0 | BE25: =ROW() - 4 -> 21 | BM25: =IFERROR( IF(LEN(BG25)=0, "", IF(BG25=BF25, "", " - xform/" & BF25 & "/" & BG25 & "/ # " & "【" & BH25 & "】 ==> " & BJ25 & "： " & BI25 & " [" & BF25 & "]")), "") | BN25: =ROW() - 4 -> 21 | BV25: =IFERROR( IF(LEN(BP25)=0, "", IF(EXACT(BP25,BO25), "", " - xform/" & BO25 & "/" & BP25 & "/ # " & "【" & BQ25 & "】 ==> " & BS25 & "： " & BR25 & " [" & BO25 & "]")), "") | BW25: =ROW() - 4 -> 21 | BX25: 0 | BY25: 0 | BZ25: 0 | CA25: 0 | CB25: 聲 | CC25: 1 | CE25: =_xlfn.CONCAT(" - xform/^", BY25, "/", BY25, "/", " # ", CA25, " [", BX25, "]" ) -> - xform/^0/0/ # 0 [0] | CF25: =ROW() - 4 -> 21
AU26: =ROW() - 4 -> 22 | AV26: 0 | AW26: 0 | AX26: 0 | AY26: 0 | BA26: =LEN(AV26) -> 1 | BC26: =" """ & AX26 & """: { commit: """ & AY26 & """ }" & " # " & "/" & AV27 & "/ ==> " & AW26 -> "0": { commit: "0" } # /0/ ==> 0 | BE26: =ROW() - 4 -> 22 | BM26: =IFERROR( IF(LEN(BG26)=0, "", IF(BG26=BF26, "", " - xform/" & BF26 & "/" & BG26 & "/ # " & "【" & BH26 & "】 ==> " & BJ26 & "： " & BI26 & " [" & BF26 & "]")), "") | BN26: =ROW() - 4 -> 22 | BV26: =IFERROR( IF(LEN(BP26)=0, "", IF(EXACT(BP26,BO26), "", " - xform/" & BO26 & "/" & BP26 & "/ # " & "【" & BQ26 & "】 ==> " & BS26 & "： " & BR26 & " [" & BO26 & "]")), "") | BW26: =ROW() - 4 -> 22 | CE26: =IFERROR( IF(LEN(BY26)=0, "", IF(EXACT(BY26,BX26), "", " - xform/^" & BX26 & "/" & BY26 & "/ # " & "【" & BZ26 & "】 ==> " & CB26 & "： " & CA26 & " [" & BX26 & "]")), "") | CF26: =ROW() - 4 -> 22
AU27: =ROW() - 4 -> 23 | AV27: 0 | AW27: 0 | AX27: 0 | AY27: 0 | BA27: =LEN(AV27) -> 1 | BC27: =" """ & AX27 & """: { commit: """ & AY27 & """ }" & " # " & "/" & AV28 & "/ ==> " & AW27 -> "0": { commit: "0" } # /0/ ==> 0 | BE27: =ROW() - 4 -> 23 | BM27: =IFERROR( IF(LEN(BG27)=0, "", IF(BG27=BF27, "", " - xform/" & BF27 & "/" & BG27 & "/ # " & "【" & BH27 & "】 ==> " & BJ27 & "： " & BI27 & " [" & BF27 & "]")), "") | BN27: =ROW() - 4 -> 23 | BV27: =IFERROR( IF(LEN(BP27)=0, "", IF(EXACT(BP27,BO27), "", " - xform/" & BO27 & "/" & BP27 & "/ # " & "【" & BQ27 & "】 ==> " & BS27 & "： " & BR27 & " [" & BO27 & "]")), "") | BW27: =ROW() - 4 -> 23 | CE27: =IFERROR( IF(LEN(BY27)=0, "", IF(EXACT(BY27,BX27), "", " - xform/^" & BX27 & "/" & BY27 & "/ # " & "【" & BZ27 & "】 ==> " & CB27 & "： " & CA27 & " [" & BX27 & "]")), "") | CF27: =ROW() - 4 -> 23
AU28: =ROW() - 4 -> 24 | AV28: 0 | AW28: 0 | AX28: 0 | AY28: 0 | BA28: =LEN(AV28) -> 1 | BC28: =" """ & AX28 & """: { commit: """ & AY28 & """ }" & " # " & "/" & AV29 & "/ ==> " & AW28 -> "0": { commit: "0" } # /0/ ==> 0 | BE28: =ROW() - 4 -> 24 | BN28: =ROW() - 4 -> 24 | BW28: =ROW() - 4 -> 24 | CE28: =IFERROR( IF(LEN(BY28)=0, "", IF(EXACT(BY28,BX28), "", " - xform/^" & BX28 & "/" & BY28 & "/ # " & "【" & BZ28 & "】 ==> " & CB28 & "： " & CA28 & " [" & BX28 & "]")), "") | CF28: =ROW() - 4 -> 24
AU29: =ROW() - 4 -> 25 | AV29: 0 | AW29: 0 | AX29: 0 | AY29: 0 | BA29: =LEN(AV29) -> 1 | BC29: =" """ & AX29 & """: { commit: """ & AY29 & """ }" & " # " & "/" & AV30 & "/ ==> " & AW29 -> "0": { commit: "0" } # /0/ ==> 0 | BE29: =ROW() - 4 -> 25 | BN29: =ROW() - 4 -> 25 | BW29: =ROW() - 4 -> 25 | CE29: =IFERROR( IF(LEN(BY29)=0, "", IF(EXACT(BY29,BX29), "", " - xform/^" & BX29 & "/" & BY29 & "/ # " & "【" & BZ29 & "】 ==> " & CB29 & "： " & CA29 & " [" & BX29 & "]")), "") | CF29: =ROW() - 4 -> 25
AU30: =ROW() - 4 -> 26 | AV30: 0 | AW30: 0 | AX30: 0 | AY30: 0 | BA30: =LEN(AV30) -> 1 | BC30: =" """ & AX30 & """: { commit: """ & AY30 & """ }" & " # " & "/" & AV31 & "/ ==> " & AW30 -> "0": { commit: "0" } # /0/ ==> 0 | BE30: =ROW() - 4 -> 26 | BN30: =ROW() - 4 -> 26 | BW30: =ROW() - 4 -> 26 | CE30: =IFERROR( IF(LEN(BY30)=0, "", IF(EXACT(BY30,BX30), "", " - xform/^" & BX30 & "/" & BY30 & "/ # " & "【" & BZ30 & "】 ==> " & CB30 & "： " & CA30 & " [" & BX30 & "]")), "") | CF30: =ROW() - 4 -> 26
AU31: =ROW() - 4 -> 27 | AV31: 0 | AW31: 0 | AX31: 0 | AY31: 0 | BA31: =LEN(AV31) -> 1 | BC31: =" """ & AX31 & """: { commit: """ & AY31 & """ }" & " # " & "/" & AV32 & "/ ==> " & AW31 -> "0": { commit: "0" } # /0/ ==> 0 | BE31: =ROW() - 4 -> 27 | BN31: =ROW() - 4 -> 27 | BW31: =ROW() - 4 -> 27 | CE31: =IFERROR( IF(LEN(BY31)=0, "", IF(EXACT(BY31,BX31), "", " - xform/^" & BX31 & "/" & BY31 & "/ # " & "【" & BZ31 & "】 ==> " & CB31 & "： " & CA31 & " [" & BX31 & "]")), "") | CF31: =ROW() - 4 -> 27
AU32: =ROW() - 4 -> 28 | AV32: 0 | AW32: 0 | AX32: 0 | AY32: 0 | AZ32: 韻 | BA32: =LEN(AV32) -> 1 | BE32: =ROW() - 4 -> 28 | BN32: =ROW() - 4 -> 28 | BW32: =ROW() - 4 -> 28 | CF32: =ROW() - 4 -> 28
AU33: =ROW() - 4 -> 29 | AV33: 0 | AW33: 0 | AX33: 0 | AY33: 0 | AZ33: 韻尾 | BA33: =LEN(AV33) -> 1 | BC33: =" """ & AX33 & """: { commit: """ & AY33 & """ }" & " # " & "/" & AV33 & "/ ==> " & AW33 -> "0": { commit: "0" } # /0/ ==> 0 | BE33: =ROW() - 4 -> 29 | BN33: =ROW() - 4 -> 29 | BW33: =ROW() - 4 -> 29 | CE33: =IF(CB33=0, "", " - xform/^" & CB33 & "(?!\d)/" & BX33 & "/ # " & BY33 & " [ " & CB33 & "]") | CF33: =ROW() - 4 -> 29
AU34: =ROW() - 4 -> 30 | AV34: 0 | AW34: 0 | AX34: 0 | AY34: 0 | AZ34: 韻尾 | BA34: =LEN(AV34) -> 1 | BC34: =" """ & AX34 & """: { commit: """ & AY34 & """ }" & " # " & "/" & AV34 & "/ ==> " & AW34 -> "0": { commit: "0" } # /0/ ==> 0 | BE34: =ROW() - 4 -> 30 | BN34: =ROW() - 4 -> 30 | BW34: =ROW() - 4 -> 30 | CE34: =IF(CB34=0, "", " - xform/^" & CB34 & "(?!\d)/" & BX34 & "/ # " & BY34 & " [ " & CB34 & "]") | CF34: =ROW() - 4 -> 30
AU35: =ROW() - 4 -> 31 | AV35: 0 | AW35: 0 | AX35: 0 | AY35: 0 | AZ35: 韻尾 | BA35: =LEN(AV35) -> 1 | BC35: =" """ & AX35 & """: { commit: """ & AY35 & """ }" & " # " & "/" & AV35 & "/ ==> " & AW35 -> "0": { commit: "0" } # /0/ ==> 0 | BE35: =ROW() - 4 -> 31 | BN35: =ROW() - 4 -> 31 | BW35: =ROW() - 4 -> 31 | CE35: =IF(CB35=0, "", " - xform/^" & CB35 & "(?!\d)/" & BX35 & "/ # " & BY35 & " [ " & CB35 & "]") | CF35: =ROW() - 4 -> 31
AU36: =ROW() - 4 -> 32 | AV36: 0 | AW36: 0 | AX36: 0 | AY36: 0 | AZ36: 韻尾 | BA36: =LEN(AV36) -> 1 | BC36: =" """ & AX36 & """: { commit: """ & AY36 & """ }" & " # " & "/" & AV36 & "/ ==> " & AW36 -> "0": { commit: "0" } # /0/ ==> 0 | BE36: =ROW() - 4 -> 32 | BN36: =ROW() - 4 -> 32 | BW36: =ROW() - 4 -> 32 | CE36: =IF(CB36=0, "", " - xform/^" & CB36 & "(?!\d)/" & BX36 & "/ # " & BY36 & " [ " & CB36 & "]") | CF36: =ROW() - 4 -> 32
AU37: =ROW() - 4 -> 33 | AV37: 0 | AW37: 0 | AX37: 0 | AY37: 0 | AZ37: 韻尾 | BA37: =LEN(AV37) -> 1 | BC37: =" """ & AX37 & """: { commit: """ & AY37 & """ }" & " # " & "/" & AV37 & "/ ==> " & AW37 -> "0": { commit: "0" } # /0/ ==> 0 | BE37: =ROW() - 4 -> 33 | BN37: =ROW() - 4 -> 33 | BW37: =ROW() - 4 -> 33 | CE37: =IF(CB37=0, "", " - xform/^" & CB37 & "(?!\d)/" & BX37 & "/ # " & BY37 & " [ " & CB37 & "]") | CF37: =ROW() - 4 -> 33
AU38: =ROW() - 4 -> 34 | AV38: 0 | AW38: 0 | AX38: 0 | AY38: 0 | AZ38: 韻尾 | BA38: =LEN(AV38) -> 1 | BC38: =" """ & AX38 & """: { commit: """ & AY38 & """ }" & " # " & "/" & AV38 & "/ ==> " & AW38 -> "0": { commit: "0" } # /0/ ==> 0 | BE38: =ROW() - 4 -> 34 | BN38: =ROW() - 4 -> 34 | BW38: =ROW() - 4 -> 34 | CE38: =IF(CB38=0, "", " - xform/^" & CB38 & "(?!\d)/" & BX38 & "/ # " & BY38 & " [ " & CB38 & "]") | CF38: =ROW() - 4 -> 34
AU39: =ROW() - 4 -> 35 | AV39: 0 | AW39: 0 | AX39: 0 | AY39: 0 | AZ39: 韻尾 | BA39: =LEN(AV39) -> 1 | BC39: =" """ & AX39 & """: { commit: """ & AY39 & """ }" & " # " & "/" & AV39 & "/ ==> " & AW39 -> "0": { commit: "0" } # /0/ ==> 0 | BE39: =ROW() - 4 -> 35 | BN39: =ROW() - 4 -> 35 | BW39: =ROW() - 4 -> 35 | CE39: =IF(CB39=0, "", " - xform/^" & CB39 & "(?!\d)/" & BX39 & "/ # " & BY39 & " [ " & CB39 & "]") | CF39: =ROW() - 4 -> 35
AU40: =ROW() - 4 -> 36 | AV40: 0 | AW40: 0 | AX40: 0 | AY40: 0 | AZ40: 韻 | BA40: =LEN(AV40) -> 1 | BC40: =" """ & AX40 & """: { commit: """ & AY40 & """ }" & " # " & "/" & AV40 & "/ ==> " & AW40 -> "0": { commit: "0" } # /0/ ==> 0 | BE40: =ROW() - 4 -> 36 | BN40: =ROW() - 4 -> 36 | BW40: =ROW() - 4 -> 36 | CE40: =IF(CB40=0, "", " - xform/^" & CB40 & "(?!\d)/" & BX40 & "/ # " & BY40 & " [ " & CB40 & "]") | CF40: =ROW() - 4 -> 36
...

Sheet 【聲】聲母對照表
A1: 序號 | B1: 國際音標 | C1: 台羅拼音 | D1: 台語音標 | E1: 台語注音二式 | F1: 閩拼方案 | G1: 白話字 | H1: 方音符號 | I1: 台語注音 | J1: 十五音 | K1: 漢字例 | L1: 備註 | M1: s1 | N1: s2 | O1: s3
A2: 1 | J2: 英 | K2: 以 | L2: Ø | M2: 1 | N2: Ø | O2: Ø
A3: 2 | B3: m | C3: m | D3: m | E3: m | F3: bbn | G3: m | H3: ㄇ | I3: ㄇ | J3: 毛 | K3: 毛 | L3: b/m 本不分，此處分門/毛 | M3: 2 | N3: m | O3: bbn
A4: 3 | B4: b | C4: b | D4: b | E4: bb | F4: bb | G4: b | H4: ㆠ | I4: ㄪ | J4: 門 | K4: 美 | M4: 3 | N4: bb | O4: bb
A5: 4 | B5: p | C5: p | D5: p | E5: b | F5: b | G5: p | H5: ㄅ | I5: ㄅ | J5: 邊 | K5: 比 | M5: 4 | N5: b | O5: b
A6: 5 | B6: pʰ | C6: ph | D6: ph | E6: p | F6: p | G6: ph | H6: ㄆ | I6: ㄆ | J6: 頗 | K6: 鄙 | M6: 5 | N6: p | O6: p
A7: 6 | B7: n | C7: n | D7: n | E7: n | F7: ln | G7: n | H7: ㄋ | I7: ㄋ | J7: 耐 | K7: 耐 | L7: l/n 本不分，此處分柳/耐 | M7: 6 | N7: n | O7: ln
A8: 7 | B8: l | C8: l | D8: l | E8: l | F8: l | G8: l | H8: ㄌ | I8: ㄌ | J8: 柳 | K8: 理 | M8: 7 | N8: l | O8: l
A9: 8 | B9: t | C9: t | D9: t | E9: d | F9: d | G9: t | H9: ㄉ | I9: ㄉ | J9: 地 | K9: 底 | M9: 8 | N9: d | O9: d
A10: 9 | B10: tʰ | C10: th | D10: th | E10: t | F10: t | G10: th | H10: ㄊ | I10: ㄊ | J10: 他 | K10: 恥 | M10: 9 | N10: t | O10: t
A11: 10 | B11: ŋ | C11: ng | D11: ng | E11: ng | F11: ggn | G11: ng | H11: ㄫ | I11: ⁰ㄫ | J11: 雅 | K11: 雅 | L11: g/ng 本不分，此處分語/雅 | M11: 10 | N11: ng | O11: ggn
A12: 11 | B12: ɡ | C12: g | D12: g | E12: gg | F12: gg | G12: g | H12: ㆣ | I12: ㄫ | J12: 語 | K12: 禦 | M12: 11 | N12: gg | O12: gg
A13: 12 | B13: k | C13: k | D13: k | E13: g | F13: g | G13: k | H13: ㄍ | I13: ㄍ | J13: 求 | K13: 己 | M13: 12 | N13: g | O13: g
A14: 13 | B14: kʰ | C14: kh | D14: kh | E14: k | F14: k | G14: kh | H14: ㄎ | I14: ㄎ | J14: 去 | K14: 起 | M14: 13 | N14: k | O14: k
A15: 14 | B15: ʣ | C15: j | D15: j | E15: zz | F15: zz | G15: j | H15: ㆡ | I15: ㄖ | J15: 入 | K15: 熱 | M15: 14 | N15: zz | O15: zz
A16: 15 | B16: ʦ | C16: ts | D16: z | E16: z | F16: z | G16: ch | H16: ㄗ | I16: ㄗ | J16: 曾 | K16: 阻 | M16: 15 | N16: z | O16: z
A17: 16 | B17: ʦʰ | C17: tsh | D17: c | E17: c | F17: c | G17: chh | H17: ㄘ | I17: ㄘ | J17: 出 | K17: 取 | M17: 16 | N17: c | O17: c
A18: 17 | B18: s | C18: s | D18: s | E18: s | F18: s | G18: s | H18: ㄙ | I18: ㄙ | J18: 時 | K18: 詞 | M18: 17 | N18: s | O18: s
A19: 18 | B19: ʥ | C19: ji | D19: ji | E19: jj | F19: zzi | G19: ji | H19: ㆢ | I19: ㄖ | J19: 入 | K19: 熱 | L19: ㆢ = ㆡㄧ | M19: 18 | N19: jji | O19: zzi
A20: 19 | B20: ʨ | C20: tsi | D20: zi | E20: j | F20: zi | G20: chi | H20: ㄐ | I20: ㄐ | J20: 曾 | K20: 止 | L20: ㄐ = ㄗㄧ | M20: 19 | N20: ji | O20: zi
A21: 20 | B21: ʨʰ | C21: tshi | D21: ci | E21: ch | F21: ci | G21: chhi | H21: ㄑ | I21: ㄑ | J21: 出 | K21: 測 | L21: ㄑ = ㄘㄧ | M21: 20 | N21: chi | O21: ci
A22: 21 | B22: ɕ | C22: si | D22: si | E22: sh | F22: si | G22: si | H22: ㄒ | I22: ㄒ | J22: 時 | K22: 惜 | L22: ㄒ = ㄙㄧ | M22: 21 | N22: shi | O22: si
A23: 22 | B23: h | C23: h | D23: h | E23: h | F23: h | G23: h | H23: ㄏ | I23: ㄏ | J23: 喜 | K23: 喜 | M23: 22 | N23: h | O23: h

Sheet 工作表3
B2: 序號 | C2: =COLUMN() - 2 -> 1 | D2: =COLUMN() - 2 -> 2 | E2: =COLUMN() - 2 -> 3 | F2: =COLUMN() - 2 -> 4 | G2: =COLUMN() - 2 -> 5 | H2: =COLUMN() - 2 -> 6 | I2: =COLUMN() - 2 -> 7 | J2: =COLUMN() - 2 -> 8 | ... W2: =COLUMN() - 2 -> 21
B3: 國際音標 | C3: p | D3: pʰ | E3: b | F3: m | G3: t | H3: tʰ | I3: n | J3: l | K3: k | L3: kʰ | M3: h | N3: ŋ | O3: ɡ | P3: ʦ | Q3: ʦʰ | R3: s | S3: ʣ | T3: ʨ | U3: ʨʰ | V3: ɕ | W3: ʥ
B4: 方音符號 | C4: ㄅ | D4: ㄆ | E4: ㆠ | F4: ㄇ | G4: ㄉ | H4: ㄊ | I4: ㄋ | J4: ㄌ | K4: ㄍ | L4: ㄎ | M4: ㄏ | N4: ㄫ | O4: ㆣ | P4: ㄗ | Q4: ㄘ | R4: ㄙ | S4: ㆡ | T4: ㄐ | U4: ㄑ | V4: ㄒ | W4: ㆢ
B5: 台語注音 | C5: ㄅ | D5: ㄆ | E5: ㄪ | F5: ㄇ | G5: ㄉ | H5: ㄊ | I5: ㄋ | J5: ㄌ | K5: ㄍ | L5: ㄎ | M5: ㄏ | N5: ⁰ㄫ | O5: ㄫ | P5: ㄗ | Q5: ㄘ | R5: ㄙ | S5: ㄖ | T5: ㄐ | U5: ㄑ | V5: ㄒ | W5: ㄖ
B9: 序號 | C9: =COLUMN() - 2 -> 1 | D9: =COLUMN() - 2 -> 2 | E9: =COLUMN() - 2 -> 3 | F9: =COLUMN() - 2 -> 4 | G9: =COLUMN() - 2 -> 5 | H9: =COLUMN() - 2 -> 6 | I9: =COLUMN() - 2 -> 7 | J9: =COLUMN() - 2 -> 8 | ... W9: =COLUMN() - 2 -> 21
B10: 國際音標 | C10: p | D10: pʰ | E10: b | F10: m | G10: t | H10: tʰ | I10: n | J10: l | K10: k | L10: kʰ | M10: h | N10: ŋ | O10: ɡ | P10: ʦ | Q10: ʦʰ | R10: s | S10: ʣ | T10: ʨ | U10: ʨʰ | V10: ɕ | W10: ʥ
B11: 台羅拼音 | C11: p | D11: ph | E11: b | F11: m | G11: t | H11: th | I11: n | J11: l | K11: k | L11: kh | M11: h | N11: ng | O11: g | P11: ts | Q11: tsh | R11: s | S11: j | T11: tsi | U11: tshi | V11: si | W11: ji
B12: 台語音標 | C12: p | D12: ph | E12: b | F12: m | G12: t | H12: th | I12: n | J12: l | K12: k | L12: kh | M12: h | N12: ng | O12: g | P12: z | Q12: c | R12: s | S12: j | T12: zi | U12: ci | V12: si | W12: ji
B13: 台語注音二式 | C13: b | D13: p | E13: bb | F13: m | G13: d | H13: t | I13: n | J13: l | K13: g | L13: k | M13: h | N13: ng | O13: gg | P13: z | Q13: c | R13: s | S13: zz | T13: j | U13: ch | V13: sh | W13: jj
B14: 閩拼方案 | C14: b | D14: p | E14: bb | F14: bbn | G14: d | H14: t | I14: ln | J14: l | K14: g | L14: k | M14: h | N14: ggn | O14: gg | P14: z | Q14: c | R14: s | S14: zz | T14: zi | U14: ci | V14: si | W14: zzi
B15: 白話字 | C15: p | D15: ph | E15: b | F15: m | G15: t | H15: th | I15: n | J15: l | K15: k | L15: kh | M15: h | N15: ng | O15: g | P15: ch | Q15: chh | R15: s | S15: j | T15: chi | U15: chhi | V15: si | W15: ji
B16: 方音符號 | C16: ㄅ | D16: ㄆ | E16: ㆠ | F16: ㄇ | G16: ㄉ | H16: ㄊ | I16: ㄋ | J16: ㄌ | K16: ㄍ | L16: ㄎ | M16: ㄏ | N16: ㄫ | O16: ㆣ | P16: ㄗ | Q16: ㄘ | R16: ㄙ | S16: ㆡ | T16: ㄐ | U16: ㄑ | V16: ㄒ | W16: ㆢ
B17: 台語注音 | C17: ㄅ | D17: ㄆ | E17: ㄪ | F17: ㄇ | G17: ㄉ | H17: ㄊ | I17: ㄋ | J17: ㄌ | K17: ㄍ | L17: ㄎ | M17: ㄏ | N17: ⁰ㄫ | O17: ㄫ | P17: ㄗ | Q17: ㄘ | R17: ㄙ | S17: ㄖ | T17: ㄐ | U17: ㄑ | V17: ㄒ | W17: ㄖ

Sheet 【韻】韻母對照表
A1: 響度優先次第： a > oo > (e = o) > (i = u)〈低元音 > 高元音 > 無擦通音 > 擦音 > 塞音〉 | I1: ㄏ | J1: ⁰
A3: 序號 | B3: 國際音標 | C3: 台羅拼音 | D3: 台語音標 | E3: 台語注音二式 | F3: 閩拼方案 | G3: 白話字 | H3: 方音符號 | I3: 台語注音 | J3: 十五音 | K3: 漢字例 | L3: 十五音識別碼 | M3: 聲韻調類 | N3: 字長 | P3: =韻母對照表[[#Headers],[台羅拼音]] -> 台羅拼音 | Q3: 十五音 | R3: 方音符號 | S3: 聲韻調類 | T3: 字長 | V3: =P3 -> 台羅拼音 | W3: 十五音 | X3: 方音符號 | Y3: 聲韻調類 | Z3: 字長
A4: 1 | B4: a | C4: a | D4: a | E4: a | F4: a | G4: a | H4: ㄚ | I4: ㄚ | J4: 膠 | K4: 些 | L4: 膠舒 | N4: =LEN(韻母對照表[[#This Row],[台羅拼音]]) -> 1 | P4: {=_xlfn.LET(_xlpm.crit,韻母對照表[聲韻調類]="韻-鼻",_xlfn.SORTBY(_xlfn._xlws.FILTER(_xlfn.HSTACK(韻母對照表[台羅拼音],韻母對照表[十五音],韻母對照表[方音符號],韻母對照表[聲韻調類],韻母對照表[字長]),_xlpm.crit,"無符合資料"),_xlfn._xlws.FILTER(韻母對照表[字長],_xlpm.crit),-1))} -> uaihnn | Q4: 閂 | R4: ㄨㆮㆷ | S4: 韻-鼻 | T4: 6 | V4: {=_xlfn.LET(_xlpm.crit,(韻母對照表[聲韻調類]<>"韻-鼻")*(韻母對照表[台語注音二式]<>""),_xlfn.SORTBY(_xlfn._xlws.FILTER(_xlfn.HSTACK(韻母對照表[台語音標],韻母對照表[十五音],韻母對照表[方音符號],韻母對照表[聲韻調類],韻母對照表[字長]),_xlpm.crit,"無符合資料"),_xlfn._xlws.FILTER(韻母對照表[字長],_xlpm.crit),-1))} -> aunn | W4: 爻 | X4: ㆯ | Y4: 0 | Z4: 4 | AB4: =_xlfn.CONCAT(" - xform/", "》", $P4, "/", Q4, "》", "/") -> - xform/》uaihnn/閂》/ | AC4: =_xlfn.CONCAT(" - xform/", "》", $V4, "/", W4, "》", "/") -> - xform/》aunn/爻》/ | AE4: =_xlfn.CONCAT(" - xform/", "〉", $P4, "/", R4, "〉", "/") -> - xform/〉uaihnn/ㄨㆮㆷ〉/ | AF4: =_xlfn.CONCAT(" - xform/", "〉", $V4, "/", X4, "〉", "/") -> - xform/〉aunn/ㆯ〉/
A5: 2 | B5: aʔ | C5: ah | D5: ah | E5: ah | F5: ah | G5: ah | H5: ㄚㆷ | I5: ㄚㄏ | J5: 膠 | K5: 百 | L5: 膠促 | N5: =LEN(韻母對照表[[#This Row],[台羅拼音]]) -> 2 | P5: iahnn | Q5: 迦 | R5: ㄧㆩㆷ | S5: 韻-鼻 | T5: 5 | V5: iang | W5: 姜 | X5: ㄧㄤ | Y5: 0 | Z5: 4 | AB5: =_xlfn.CONCAT(" - xform/", "》", $P5, "/", Q5, "》", "/") -> - xform/》iahnn/迦》/ | AC5: =_xlfn.CONCAT(" - xform/", "》", $V5, "/", W5, "》", "/") -> - xform/》iang/姜》/ | AE5: =_xlfn.CONCAT(" - xform/", "〉", $P5, "/", R5, "〉", "/") -> - xform/〉iahnn/ㄧㆩㆷ〉/ | AF5: =_xlfn.CONCAT(" - xform/", "〉", $V5, "/", X5, "〉", "/") -> - xform/〉iang/ㄧㄤ〉/
A6: 3 | B6: aɪ | C6: ai | D6: ai | E6: ai | F6: ai | G6: ai | H6: ㄞ | I6: ㄞ | J6: 皆 | K6: 埃 | L6: 皆舒 | N6: =LEN(韻母對照表[[#This Row],[台羅拼音]]) -> 2 | P6: iaunn | Q6: 嘄 | R6: ㄧㆯ | S6: 韻-鼻 | T6: 5 | V6: iauh | W6: 嬌 | X6: ㄧㄠㆷ | Y6: 0 | Z6: 4 | AB6: =_xlfn.CONCAT(" - xform/", "》", $P6, "/", Q6, "》", "/") -> - xform/》iaunn/嘄》/ | AC6: =_xlfn.CONCAT(" - xform/", "》", $V6, "/", W6, "》", "/") -> - xform/》iauh/嬌》/ | AE6: =_xlfn.CONCAT(" - xform/", "〉", $P6, "/", R6, "〉", "/") -> - xform/〉iaunn/ㄧㆯ〉/ | AF6: =_xlfn.CONCAT(" - xform/", "〉", $V6, "/", X6, "〉", "/") -> - xform/〉iauh/ㄧㄠㆷ〉/
A7: 4 | B7: aɪʔ | C7: aih | D7: aih | E7: aih | F7: aih | G7: aih | H7: ㄞㆷ | I7: ㄞㄏ | J7: 皆 | K7: ◯ | L7: 皆促 | N7: =LEN(韻母對照表[[#This Row],[台羅拼音]]) -> 3 | P7: iuhnn | Q7: 牛 | R7: ㄧㆫㆷ | S7: 韻-鼻 | T7: 5 | V7: iooh | W7: 0 | X7: ㄧㆦㆷ | Y7: 0 | Z7: 4 | AB7: =_xlfn.CONCAT(" - xform/", "》", $P7, "/", Q7, "》", "/") -> - xform/》iuhnn/牛》/ | AC7: =_xlfn.CONCAT(" - xform/", "》", $V7, "/", W7, "》", "/") -> - xform/》iooh/0》/ | AE7: =_xlfn.CONCAT(" - xform/", "〉", $P7, "/", R7, "〉", "/") -> - xform/〉iuhnn/ㄧㆫㆷ〉/ | AF7: =_xlfn.CONCAT(" - xform/", "〉", $V7, "/", X7, "〉", "/") -> - xform/〉iooh/ㄧㆦㆷ〉/
A8: 5 | B8: ãɪ | C8: ainn | D8: ainn | E8: ainn | F8: nai | G8: aiⁿ | H8: ㆮ | I8: ⁰ㄞ | J8: 閒 | K8: 挨 | L8: 閒舒 | M8: 韻-鼻 | N8: =LEN(韻母對照表[[#This Row],[台羅拼音]]) -> 4 | P8: uainn | Q8: 閂 | R8: ㄨㆮ | S8: 韻-鼻 | T8: 5 | V8: iong | W8: 恭 | X8: ㄧㆲ | Y8: 0 | Z8: 4 | AB8: =_xlfn.CONCAT(" - xform/", "》", $P8, "/", Q8, "》", "/") -> - xform/》uainn/閂》/ | AC8: =_xlfn.CONCAT(" - xform/", "》", $V8, "/", W8, "》", "/") -> - xform/》iong/恭》/ | AE8: =_xlfn.CONCAT(" - xform/", "〉", $P8, "/", R8, "〉", "/") -> - xform/〉uainn/ㄨㆮ〉/ | AF8: =_xlfn.CONCAT(" - xform/", "〉", $V8, "/", X8, "〉", "/") -> - xform/〉iong/ㄧㆲ〉/
A9: 6 | B9: ak̚ | C9: ak | D9: ak | E9: ak | F9: ak | G9: ak | H9: ㄚㆻ | I9: ㄚㄍ | J9: 江 | K9: 角 | L9: 江促 | N9: =LEN(韻母對照表[[#This Row],[台羅拼音]]) -> 2 | P9: ainn | Q9: 閒 | R9: ㆮ | S9: 韻-鼻 | T9: 4 | V9: uaih | W9: 乖 | X9: ㄨㄞㆷ | Y9: 0 | Z9: 4 | AB9: =_xlfn.CONCAT(" - xform/", "》", $P9, "/", Q9, "》", "/") -> - xform/》ainn/閒》/ | AC9: =_xlfn.CONCAT(" - xform/", "》", $V9, "/", W9, "》", "/") -> - xform/》uaih/乖》/ | AE9: =_xlfn.CONCAT(" - xform/", "〉", $P9, "/", R9, "〉", "/") -> - xform/〉ainn/ㆮ〉/ | AF9: =_xlfn.CONCAT(" - xform/", "〉", $V9, "/", X9, "〉", "/") -> - xform/〉uaih/ㄨㄞㆷ〉/
A10: 7 | B10: am | C10: am | D10: am | E10: am | F10: am | G10: am | H10: ㆰ | I10: ㄚㄇ | J10: 甘 | K10: 堪 | L10: 甘舒 | N10: =LEN(韻母對照表[[#This Row],[台羅拼音]]) -> 2 | P10: ahnn | Q10: 監 | R10: ㆩㆷ | S10: 韻-鼻 | T10: 4 | V10: uang | W10: 光 | X10: ㄨㄤ | Y10: 0 | Z10: 4 | AB10: =_xlfn.CONCAT(" - xform/", "》", $P10, "/", Q10, "》", "/") -> - xform/》ahnn/監》/ | AC10: =_xlfn.CONCAT(" - xform/", "》", $V10, "/", W10, "》", "/") -> - xform/》uang/光》/ | AE10: =_xlfn.CONCAT(" - xform/", "〉", $P10, "/", R10, "〉", "/") -> - xform/〉ahnn/ㆩㆷ〉/ | AF10: =_xlfn.CONCAT(" - xform/", "〉", $V10, "/", X10, "〉", "/") -> - xform/〉uang/ㄨㄤ〉/
A11: 8 | B11: an | C11: an | D11: an | E11: an | F11: an | G11: an | H11: ㄢ | I11: ㄢ | J11: 干 | K11: 蘭 | L11: 干舒 | N11: =LEN(韻母對照表[[#This Row],[台羅拼音]]) -> 2 | P11: ehnn | Q11: 更 | R11: ㆥㆷ | S11: 韻-鼻 | T11: 4 | V11: uann | W11: 官 | X11: ㄨㆩ | Y11: 0 | Z11: 4 | AB11: =_xlfn.CONCAT(" - xform/", "》", $P11, "/", Q11, "》", "/") -> - xform/》ehnn/更》/ | AC11: =_xlfn.CONCAT(" - xform/", "》", $V11, "/", W11, "》", "/") -> - xform/》uann/官》/ | AE11: =_xlfn.CONCAT(" - xform/", "〉", $P11, "/", R11, "〉", "/") -> - xform/〉ehnn/ㆥㆷ〉/ | AF11: =_xlfn.CONCAT(" - xform/", "〉", $V11, "/", X11, "〉", "/") -> - xform/〉uann/ㄨㆩ〉/
A12: 9 | B12: aŋ | C12: ang | D12: ang | E12: ang | F12: ang | G12: ang | H12: ㄤ | I12: ㄤ | J12: 江 | K12: 邦 | L12: 江舒 | N12: =LEN(韻母對照表[[#This Row],[台羅拼音]]) -> 3 | P12: iann | Q12: 驚 | R12: ㄧㆩ | S12: 韻-鼻 | T12: 4 | V12: aih | W12: 皆 | X12: ㄞㆷ | Y12: 0 | Z12: 3 | AB12: =_xlfn.CONCAT(" - xform/", "》", $P12, "/", Q12, "》", "/") -> - xform/》iann/驚》/ | AC12: =_xlfn.CONCAT(" - xform/", "》", $V12, "/", W12, "》", "/") -> - xform/》aih/皆》/ | AE12: =_xlfn.CONCAT(" - xform/", "〉", $P12, "/", R12, "〉", "/") -> - xform/〉iann/ㄧㆩ〉/ | AF12: =_xlfn.CONCAT(" - xform/", "〉", $V12, "/", X12, "〉", "/") -> - xform/〉aih/ㄞㆷ〉/
A13: 10 | B13: ã | C13: ann | D13: ann | E13: ann | F13: na | G13: aⁿ | H13: ㆩ | I13: ⁰ㄚ | J13: 監 | K13: 聽 | L13: 監舒 | M13: 韻-鼻 | N13: =LEN(韻母對照表[[#This Row],[台羅拼音]]) -> 3 | P13: ionn | Q13: 薑 | R13: ㄧㆧ | S13: 韻-鼻 | T13: 4 | V13: ang | W13: 江 | X13: ㄤ | Y13: 0 | Z13: 3 | AB13: =_xlfn.CONCAT(" - xform/", "》", $P13, "/", Q13, "》", "/") -> - xform/》ionn/薑》/ | AC13: =_xlfn.CONCAT(" - xform/", "》", $V13, "/", W13, "》", "/") -> - xform/》ang/江》/ | AE13: =_xlfn.CONCAT(" - xform/", "〉", $P13, "/", R13, "〉", "/") -> - xform/〉ionn/ㄧㆧ〉/ | AF13: =_xlfn.CONCAT(" - xform/", "〉", $V13, "/", X13, "〉", "/") -> - xform/〉ang/ㄤ〉/
A14: 11 | B14: ãʔ | C14: ahnn | D14: annh | E14: annh | F14: nah | G14: ahⁿ | H14: ㆩㆷ | I14: ⁰ㄚㄏ | J14: 監 | K14: 含 | L14: 監促 | M14: 韻-鼻 | N14: =LEN(韻母對照表[[#This Row],[台羅拼音]]) -> 4 | P14: iunn | Q14: 牛 | R14: ㄧㆫ | S14: 韻-鼻 | T14: 4 | V14: auh | W14: 交 | X14: ㄠㆷ | Y14: 0 | Z14: 3 | AB14: =_xlfn.CONCAT(" - xform/", "》", $P14, "/", Q14, "》", "/") -> - xform/》iunn/牛》/ | AC14: =_xlfn.CONCAT(" - xform/", "》", $V14, "/", W14, "》", "/") -> - xform/》auh/交》/ | AE14: =_xlfn.CONCAT(" - xform/", "〉", $P14, "/", R14, "〉", "/") -> - xform/〉iunn/ㄧㆫ〉/ | AF14: =_xlfn.CONCAT(" - xform/", "〉", $V14, "/", X14, "〉", "/") -> - xform/〉auh/ㄠㆷ〉/
A15: 12 | B15: ap̚ | C15: ap | D15: ap | E15: ap | F15: ap | G15: ap | H15: ㄚㆴ | I15: ㄚㄅ | J15: 甘 | K15: 答 | L15: 甘促 | N15: =LEN(韻母對照表[[#This Row],[台羅拼音]]) -> 2 | P15: ohnn | Q15: 扛 | R15: ㆧㆷ | S15: 韻-鼻 | T15: 4 | V15: iah | W15: 迦 | X15: ㄧㄚㆷ | Y15: 0 | Z15: 3 | AB15: =_xlfn.CONCAT(" - xform/", "》", $P15, "/", Q15, "》", "/") -> - xform/》ohnn/扛》/ | AC15: =_xlfn.CONCAT(" - xform/", "》", $V15, "/", W15, "》", "/") -> - xform/》iah/迦》/ | AE15: =_xlfn.CONCAT(" - xform/", "〉", $P15, "/", R15, "〉", "/") -> - xform/〉ohnn/ㆧㆷ〉/ | AF15: =_xlfn.CONCAT(" - xform/", "〉", $V15, "/", X15, "〉", "/") -> - xform/〉iah/ㄧㄚㆷ〉/
A16: 13 | B16: at̚ | C16: at | D16: at | E16: at | F16: at | G16: at | H16: ㄚㆵ | I16: ㄚㄉ | J16: 干 | K16: 識 | L16: 干促 | N16: =LEN(韻母對照表[[#This Row],[台羅拼音]]) -> 2 | P16: uinn | Q16: 褌 | R16: ㄨㆪ | S16: 韻-鼻 | T16: 4 | V16: iak | W16: 姜 | X16: ㄧㄚㆻ | Y16: 0 | Z16: 3 | AB16: =_xlfn.CONCAT(" - xform/", "》", $P16, "/", Q16, "》", "/") -> - xform/》uinn/褌》/ | AC16: =_xlfn.CONCAT(" - xform/", "》", $V16, "/", W16, "》", "/") -> - xform/》iak/姜》/ | AE16: =_xlfn.CONCAT(" - xform/", "〉", $P16, "/", R16, "〉", "/") -> - xform/〉uinn/ㄨㆪ〉/ | AF16: =_xlfn.CONCAT(" - xform/", "〉", $V16, "/", X16, "〉", "/") -> - xform/〉iak/ㄧㄚㆻ〉/
A17: 14 | B17: aʊ | C17: au | D17: au | E17: au | F17: ao | G17: au | H17: ㄠ | I17: ㄠ | J17: 交 | K17: 鬧 | L17: 交舒 | N17: =LEN(韻母對照表[[#This Row],[台羅拼音]]) -> 2 | P17: ann | Q17: 監 | R17: ㆩ | S17: 韻-鼻 | T17: 3 | V17: iam | W17: 兼 | X17: ㄧㆰ | Y17: 0 | Z17: 3 | AB17: =_xlfn.CONCAT(" - xform/", "》", $P17, "/", Q17, "》", "/") -> - xform/》ann/監》/ | AC17: =_xlfn.CONCAT(" - xform/", "》", $V17, "/", W17, "》", "/") -> - xform/》iam/兼》/ | AE17: =_xlfn.CONCAT(" - xform/", "〉", $P17, "/", R17, "〉", "/") -> - xform/〉ann/ㆩ〉/ | AF17: =_xlfn.CONCAT(" - xform/", "〉", $V17, "/", X17, "〉", "/") -> - xform/〉iam/ㄧㆰ〉/
A18: 15 | B18: auʔ | C18: auh | D18: auh | E18: auh | F18: aoh | G18: auh | H18: ㄠㆷ | I18: ㄠㄏ | J18: 交 | K18: 暴 | L18: 交促 | N18: =LEN(韻母對照表[[#This Row],[台羅拼音]]) -> 3 | P18: enn | Q18: 更 | R18: ㆥ | S18: 韻-鼻 | T18: 3 | V18: ian | W18: 堅 | X18: ㄧㄢ | Y18: 0 | Z18: 3 | AB18: =_xlfn.CONCAT(" - xform/", "》", $P18, "/", Q18, "》", "/") -> - xform/》enn/更》/ | AC18: =_xlfn.CONCAT(" - xform/", "》", $V18, "/", W18, "》", "/") -> - xform/》ian/堅》/ | AE18: =_xlfn.CONCAT(" - xform/", "〉", $P18, "/", R18, "〉", "/") -> - xform/〉enn/ㆥ〉/ | AF18: =_xlfn.CONCAT(" - xform/", "〉", $V18, "/", X18, "〉", "/") -> - xform/〉ian/ㄧㄢ〉/
A19: 16 | B19: ãʊ | C19: aunn | D19: aunn | E19: aunn | F19: nau | G19: auⁿ | H19: ㆯ | I19: ⁰ㄠ | J19: 爻 | K19: 貎 | L19: 爻舒 | N19: =LEN(韻母對照表[[#This Row],[台羅拼音]]) -> 4 | P19: inn | Q19: 梔 | R19: ㆪ | S19: 韻-鼻 | T19: 3 | V19: iap | W19: 兼 | X19: ㄧㄚㆴ | Y19: 0 | Z19: 3 | AB19: =_xlfn.CONCAT(" - xform/", "》", $P19, "/", Q19, "》", "/") -> - xform/》inn/梔》/ | AC19: =_xlfn.CONCAT(" - xform/", "》", $V19, "/", W19, "》", "/") -> - xform/》iap/兼》/ | AE19: =_xlfn.CONCAT(" - xform/", "〉", $P19, "/", R19, "〉", "/") -> - xform/〉inn/ㆪ〉/ | AF19: =_xlfn.CONCAT(" - xform/", "〉", $V19, "/", X19, "〉", "/") -> - xform/〉iap/ㄧㄚㆴ〉/
A20: 17 | B20: e | C20: e | D20: e | E20: e | F20: e | G20: e | H20: ㆤ | I20: ㄝ | J20: 伽 | K20: 遞 | L20: 伽舒 | N20: =LEN(韻母對照表[[#This Row],[台羅拼音]]) -> 1 | P20: onn | Q20: 姑 | R20: ㆧ | S20: 韻-鼻 | T20: 3 | V20: iat | W20: 堅 | X20: ㄧㄚㆵ | Y20: 0 | Z20: 3 | AC20: =_xlfn.CONCAT(" - xform/", "》", $V20, "/", W20, "》", "/") -> - xform/》iat/堅》/ | AF20: =_xlfn.CONCAT(" - xform/", "〉", $V20, "/", X20, "〉", "/") -> - xform/〉iat/ㄧㄚㆵ〉/
A21: 18 | B21: ɛ | C21: ee | D21: ee | H21: ㄝ | I21: ㄝ | J21: 嘉 | K21: 家 | L21: 嘉舒 | N21: =LEN(韻母對照表[[#This Row],[台羅拼音]]) -> 2 | V21: iau | W21: 嬌 | X21: ㄧㄠ | Y21: 0 | Z21: 3 | AC21: =_xlfn.CONCAT(" - xform/", "》", $V21, "/", W21, "》", "/") -> - xform/》iau/嬌》/ | AF21: =_xlfn.CONCAT(" - xform/", "〉", $V21, "/", X21, "〉", "/") -> - xform/〉iau/ㄧㄠ〉/
A22: 19 | B22: ɛʔ | C22: eeh | D22: eeh | H22: ㄝㆷ | I22: ㄝㄏ | J22: 嘉 | K22: 八 | L22: 嘉促 | N22: =LEN(韻母對照表[[#This Row],[台羅拼音]]) -> 3 | V22: ing | W22: 經 | X22: ㄧㄥ | Y22: 0 | Z22: 3 | AC22: =_xlfn.CONCAT(" - xform/", "》", $V22, "/", W22, "》", "/") -> - xform/》ing/經》/ | AF22: =_xlfn.CONCAT(" - xform/", "〉", $V22, "/", X22, "〉", "/") -> - xform/〉ing/ㄧㄥ〉/
A23: 20 | B23: eʔ | C23: eh | D23: eh | E23: eh | F23: eh | G23: eh | H23: ㆤㆷ | I23: ㄝㄏ | J23: 伽 | K23: 伯 | L23: 伽促 | N23: =LEN(韻母對照表[[#This Row],[台羅拼音]]) -> 2 | V23: ioh | W23: 茄 | X23: ㄧㄜㆷ | Y23: 0 | Z23: 3 | AC23: =_xlfn.CONCAT(" - xform/", "》", $V23, "/", W23, "》", "/") -> - xform/》ioh/茄》/ | AF23: =_xlfn.CONCAT(" - xform/", "〉", $V23, "/", X23, "〉", "/") -> - xform/〉ioh/ㄧㄜㆷ〉/
A24: 21 | B24: ɪk | C24: ek | D24: ek | H24: ㄝㆻ | I24: ㄝㄍ | J24: 經 | K24: ◯ | L24: 經促 | N24: =LEN(韻母對照表[[#This Row],[台羅拼音]]) -> 2 | V24: ioo | W24: 0 | X24: ㄧㆦ | Y24: 0 | Z24: 3 | AC24: =_xlfn.CONCAT(" - xform/", "》", $V24, "/", W24, "》", "/") -> - xform/》ioo/0》/ | AF24: =_xlfn.CONCAT(" - xform/", "〉", $V24, "/", X24, "〉", "/") -> - xform/〉ioo/ㄧㆦ〉/
A25: 22 | B25: ɪŋ | C25: eng | D25: eng | H25: ㄝㆭ | I25: ㄝㄥ | J25: 經 | K25: ◯ | L25: 經舒 | N25: =LEN(韻母對照表[[#This Row],[台羅拼音]]) -> 3 | V25: iok | W25: 恭 | X25: ㄧㆦㆻ | Y25: 0 | Z25: 3 | AC25: =_xlfn.CONCAT(" - xform/", "》", $V25, "/", W25, "》", "/") -> - xform/》iok/恭》/ | AF25: =_xlfn.CONCAT(" - xform/", "〉", $V25, "/", X25, "〉", "/") -> - xform/〉iok/ㄧㆦㆻ〉/
A26: 23 | B26: ẽ | C26: enn | D26: enn | E26: enn | F26: ne | G26: eⁿ | H26: ㆥ | I26: ⁰ㄝ | J26: 更 | K26: 爭 | L26: 更舒 | M26: 韻-鼻 | N26: =LEN(韻母對照表[[#This Row],[台羅拼音]]) -> 3 | V26: ngh | W26: 鋼 | X26: ㆭㆷ | Y26: 0 | Z26: 3 | AC26: =_xlfn.CONCAT(" - xform/", "》", $V26, "/", W26, "》", "/") -> - xform/》ngh/鋼》/ | AF26: =_xlfn.CONCAT(" - xform/", "〉", $V26, "/", X26, "〉", "/") -> - xform/〉ngh/ㆭㆷ〉/
A27: 24 | B27: ẽʔ | C27: ehnn | D27: ennh | E27: ennh | F27: ennh | G27: ehⁿ | H27: ㆥㆷ | I27: ⁰ㄝㄏ | J27: 更 | K27: 挾 | L27: 更促 | M27: 韻-鼻 | N27: =LEN(韻母對照表[[#This Row],[台羅拼音]]) -> 4 | V27: ong | W27: 公 | X27: ㆲ | Y27: 0 | Z27: 3 | AC27: =_xlfn.CONCAT(" - xform/", "》", $V27, "/", W27, "》", "/") -> - xform/》ong/公》/ | AF27: =_xlfn.CONCAT(" - xform/", "〉", $V27, "/", X27, "〉", "/") -> - xform/〉ong/ㆲ〉/
A28: 25 | B28: i | C28: i | D28: i | E28: i | F28: i | G28: i | H28: ㄧ | I28: ㄧ | J28: 居 | K28: 爾 | L28: 居舒 | N28: =LEN(韻母對照表[[#This Row],[台羅拼音]]) -> 1 | V28: ooh | W28: 沽 | X28: ㆦㆷ | Y28: 0 | Z28: 3 | AC28: =_xlfn.CONCAT(" - xform/", "》", $V28, "/", W28, "》", "/") -> - xform/》ooh/沽》/ | AF28: =_xlfn.CONCAT(" - xform/", "〉", $V28, "/", X28, "〉", "/") -> - xform/〉ooh/ㆦㆷ〉/
A29: 26 | B29: ia | C29: ia | D29: ia | E29: ia | F29: ia | G29: ia | H29: ㄧㄚ | I29: ㄧㄚ | J29: 迦 | K29: 名 | L29: 迦舒 | N29: =LEN(韻母對照表[[#This Row],[台羅拼音]]) -> 2 | V29: uah | W29: 瓜 | X29: ㄨㄚㆷ | Y29: 0 | Z29: 3 | AC29: =_xlfn.CONCAT(" - xform/", "》", $V29, "/", W29, "》", "/") -> - xform/》uah/瓜》/ | AF29: =_xlfn.CONCAT(" - xform/", "〉", $V29, "/", X29, "〉", "/") -> - xform/〉uah/ㄨㄚㆷ〉/
A30: 27 | B30: iaʔ | C30: iah | D30: iah | E30: iah | F30: iah | G30: iah | H30: ㄧㄚㆷ | I30: ㄧㄚㄏ | J30: 迦 | K30: 壁 | L30: 迦促 | N30: =LEN(韻母對照表[[#This Row],[台羅拼音]]) -> 3 | V30: uai | W30: 乖 | X30: ㄨㄞ | Y30: 0 | Z30: 3 | AC30: =_xlfn.CONCAT(" - xform/", "》", $V30, "/", W30, "》", "/") -> - xform/》uai/乖》/ | AF30: =_xlfn.CONCAT(" - xform/", "〉", $V30, "/", X30, "〉", "/") -> - xform/〉uai/ㄨㄞ〉/
A31: 28 | B31: iak̚ | C31: iak | D31: iak | E31: iak | F31: iak | G31: iak | H31: ㄧㄚㆻ | I31: ㄧㄚㄍ | J31: 姜 | K31: 爆 | L31: 姜促 | N31: =LEN(韻母對照表[[#This Row],[台羅拼音]]) -> 3 | V31: uan | W31: 觀 | X31: ㄨㄢ | Y31: 0 | Z31: 3 | AC31: =_xlfn.CONCAT(" - xform/", "》", $V31, "/", W31, "》", "/") -> - xform/》uan/觀》/ | AF31: =_xlfn.CONCAT(" - xform/", "〉", $V31, "/", X31, "〉", "/") -> - xform/〉uan/ㄨㄢ〉/
A32: 29 | B32: iam | C32: iam | D32: iam | E32: iam | F32: iam | G32: iam | H32: ㄧㆰ | I32: ㄧㄚㄇ | J32: 兼 | K32: 尖 | L32: 兼舒 | N32: =LEN(韻母對照表[[#This Row],[台羅拼音]]) -> 3 | V32: uat | W32: 觀 | X32: ㄨㄚㆵ | Y32: 0 | Z32: 3 | AC32: =_xlfn.CONCAT(" - xform/", "》", $V32, "/", W32, "》", "/") -> - xform/》uat/觀》/ | AF32: =_xlfn.CONCAT(" - xform/", "〉", $V32, "/", X32, "〉", "/") -> - xform/〉uat/ㄨㄚㆵ〉/
A33: 30 | B33: ian | C33: ian | D33: ian | E33: ian | F33: ian | G33: ian | H33: ㄧㄢ | I33: ㄧㄢ | J33: 堅 | K33: 掀 | L33: 堅舒 | N33: =LEN(韻母對照表[[#This Row],[台羅拼音]]) -> 3 | V33: ueh | W33: 檜 | X33: ㄨㆤㆷ | Y33: 0 | Z33: 3 | AC33: =_xlfn.CONCAT(" - xform/", "》", $V33, "/", W33, "》", "/") -> - xform/》ueh/檜》/ | AF33: =_xlfn.CONCAT(" - xform/", "〉", $V33, "/", X33, "〉", "/") -> - xform/〉ueh/ㄨㆤㆷ〉/
A34: 31 | B34: iaŋ | C34: iang | D34: iang | E34: iang | F34: iang | G34: iang | H34: ㄧㄤ | I34: ㄧㄤ | J34: 姜 | K34: 將 | L34: 姜舒 | N34: =LEN(韻母對照表[[#This Row],[台羅拼音]]) -> 4 | V34: uih | W34: 褌 | X34: ㄨㄧㆷ | Y34: 0 | Z34: 3 | AC34: =_xlfn.CONCAT(" - xform/", "》", $V34, "/", W34, "》", "/") -> - xform/》uih/褌》/ | AF34: =_xlfn.CONCAT(" - xform/", "〉", $V34, "/", X34, "〉", "/") -> - xform/〉uih/ㄨㄧㆷ〉/
A35: 32 | B35: iã | C35: iann | D35: iann | E35: iann | F35: nia | G35: iaⁿ | H35: ㄧㆩ | I35: ⁰ㄧㄚ | J35: 驚 | K35: ◯ | L35: 驚舒 | M35: 韻-鼻 | N35: =LEN(韻母對照表[[#This Row],[台羅拼音]]) -> 4 | V35: unn | W35: 0 | X35: ㆫ | Y35: 0 | Z35: 3 | AC35: =_xlfn.CONCAT(" - xform/", "》", $V35, "/", W35, "》", "/") -> - xform/》unn/0》/ | AF35: =_xlfn.CONCAT(" - xform/", "〉", $V35, "/", X35, "〉", "/") -> - xform/〉unn/ㆫ〉/
A36: 33 | B36: iãʔ | C36: iahnn | D36: iannh | E36: iannh | F36: iannh | G36: iahⁿ | H36: ㄧㆩㆷ | I36: ⁰ㄧㄚㄏ | J36: 迦 | K36: 且 | L36: 迦促 | M36: 韻-鼻 | N36: =LEN(韻母對照表[[#This Row],[台羅拼音]]) -> 5 | V36: ah | W36: 膠 | X36: ㄚㆷ | Y36: 0 | Z36: 2 | AC36: =_xlfn.CONCAT(" - xform/", "》", $V36, "/", W36, "》", "/") -> - xform/》ah/膠》/ | AF36: =_xlfn.CONCAT(" - xform/", "〉", $V36, "/", X36, "〉", "/") -> - xform/〉ah/ㄚㆷ〉/
A37: 34 | B37: iap̚ | C37: iap | D37: iap | E37: iap | F37: iap | G37: iap | H37: ㄧㄚㆴ | I37: ㄧㄚㄅ | J37: 兼 | K37: 接 | L37: 兼促 | N37: =LEN(韻母對照表[[#This Row],[台羅拼音]]) -> 3 | V37: ai | W37: 皆 | X37: ㄞ | Y37: 0 | Z37: 2 | AC37: =_xlfn.CONCAT(" - xform/", "》", $V37, "/", W37, "》", "/") -> - xform/》ai/皆》/ | AF37: =_xlfn.CONCAT(" - xform/", "〉", $V37, "/", X37, "〉", "/") -> - xform/〉ai/ㄞ〉/
A38: 35 | B38: iat̚ | C38: iat | D38: iat | E38: iat | F38: iat | G38: iat | H38: ㄧㄚㆵ | I38: ㄧㄚㄉ | J38: 堅 | K38: 別 | L38: 堅促 | N38: =LEN(韻母對照表[[#This Row],[台羅拼音]]) -> 3 | V38: ak | W38: 江 | X38: ㄚㆻ | Y38: 0 | Z38: 2 | AC38: =_xlfn.CONCAT(" - xform/", "》", $V38, "/", W38, "》", "/") -> - xform/》ak/江》/ | AF38: =_xlfn.CONCAT(" - xform/", "〉", $V38, "/", X38, "〉", "/") -> - xform/〉ak/ㄚㆻ〉/
A39: 36 | B39: iaʊ | C39: iau | D39: iau | E39: iau | F39: iao | G39: iau | H39: ㄧㄠ | I39: ㄧㄠ | J39: 嬌 | K39: 遙 | L39: 嬌舒 | N39: =LEN(韻母對照表[[#This Row],[台羅拼音]]) -> 3 | V39: am | W39: 甘 | X39: ㆰ | Y39: 0 | Z39: 2 | AC39: =_xlfn.CONCAT(" - xform/", "》", $V39, "/", W39, "》", "/") -> - xform/》am/甘》/ | AF39: =_xlfn.CONCAT(" - xform/", "〉", $V39, "/", X39, "〉", "/") -> - xform/〉am/ㆰ〉/
A40: 37 | B40: iaʊʔ | C40: iauh | D40: iauh | E40: iauh | F40: iaoh | G40: iauh | H40: ㄧㄠㆷ | I40: ㄧㄠㄏ | J40: 嬌 | K40: 噭 | L40: 嬌促 | N40: =LEN(韻母對照表[[#This Row],[台羅拼音]]) -> 4 | V40: an | W40: 干 | X40: ㄢ | Y40: 0 | Z40: 2 | AC40: =_xlfn.CONCAT(" - xform/", "》", $V40, "/", W40, "》", "/") -> - xform/》an/干》/ | AF40: =_xlfn.CONCAT(" - xform/", "〉", $V40, "/", X40, "〉", "/") -> - xform/〉an/ㄢ〉/
A41: 38 | B41: =_xlfn.CONCAT("i", "a", _xlfn.UNICHAR(771), "ʊ") -> iãʊ | C41: iaunn | D41: iaunn | E41: iaunn | F41: niao | G41: iauⁿ | H41: ㄧㆯ | I41: ⁰ㄧㄠ | J41: 嘄 | K41: 鳥 | L41: 嘄舒 | M41: 韻-鼻 | N41: =LEN(韻母對照表[[#This Row],[台羅拼音]]) -> 5 | V41: ap | W41: 甘 | X41: ㄚㆴ | Y41: 0 | Z41: 2 | AC41: =_xlfn.CONCAT(" - xform/", "》", $V41, "/", W41, "》", "/") -> - xform/》ap/甘》/ | AF41: =_xlfn.CONCAT(" - xform/", "〉", $V41, "/", X41, "〉", "/") -> - xform/〉ap/ㄚㆴ〉/
...

Sheet 工作表4
B2: 序號 | C2: =COLUMN() - 2 -> 1 | D2: =COLUMN() - 2 -> 2 | E2: =COLUMN() - 2 -> 3 | F2: =COLUMN() - 2 -> 4 | G2: =COLUMN() - 2 -> 5 | H2: =COLUMN() - 2 -> 6 | I2: =COLUMN() - 2 -> 7 | J2: =COLUMN() - 2 -> 8 | ... V2: =COLUMN() - 2 -> 20
B3: 國際音標 | C3: a | D3: i | E3: u | F3: e | G3: ə | H3: ɔ | I3: aɪ | J3: aʊ | K3: an | L3: am | M3: aŋ | N3: m̩ | O3: ŋ̍ | P3: ua | Q3: ue | R3: uai | S3: uan | T3: iŋ | U3: ik̚ | V3: ã
B4: 方音符號 | C4: ㄚ | D4: ㄧ | E4: ㄨ | F4: ㆤ | G4: ㄜ | H4: ㆦ | I4: ㄞ | J4: ㄠ | K4: ㄢ | L4: ㆰ | M4: ㄤ | N4: ㆬ | O4: ㆭ | P4: ㄨㄚ | Q4: ㄨㆤ | R4: ㄨㄞ | S4: ㄨㄢ | T4: ㄧㄥ | U4: ㄧㆻ | V4: ㆩ
B5: 台語注音 | C5: ㄚ | D5: ㄧ | E5: ㄨ | F5: ㄝ | G5: ㄜ | H5: ㄛ | I5: ㄞ | J5: ㄠ | K5: ㄢ | L5: ㄚㄇ | M5: ㄤ | N5: ㄇ | O5: ㄥ | P5: ㄨㄚ | Q5: ㄨㄝ | R5: ㄨㄞ | S5: ㄨㄢ | T5: ㄧㄥ | U5: ㄧㄍ | V5: ⁰ㄚ
B9: 序號 | C9: =COLUMN() - 2 -> 1 | D9: =COLUMN() - 2 -> 2 | E9: =COLUMN() - 2 -> 3 | F9: =COLUMN() - 2 -> 4 | G9: =COLUMN() - 2 -> 5 | H9: =COLUMN() - 2 -> 6 | I9: =COLUMN() - 2 -> 7 | J9: =COLUMN() - 2 -> 8 | ... V9: =COLUMN() - 2 -> 20
B10: 國際音標 | C10: a | D10: i | E10: u | F10: e | G10: ə | H10: ɔ | I10: aɪ | J10: aʊ | K10: an | L10: am | M10: aŋ | N10: m̩ | O10: ŋ̍ | P10: ua | Q10: ue | R10: uai | S10: uan | T10: iŋ | U10: ik̚ | V10: ã
B11: 台羅拼音 | C11: a | D11: i | E11: u | F11: e | G11: o | H11: oo | I11: ai | J11: au | K11: an | L11: am | M11: ang | N11: m | O11: ng | P11: ua | Q11: ue | R11: uai | S11: uan | T11: ing | U11: ik | V11: ann
B12: 台語音標 | C12: a | D12: i | E12: u | F12: e | G12: o | H12: oo | I12: ai | J12: au | K12: an | L12: am | M12: ang | N12: m | O12: ng | P12: ua | Q12: ue | R12: uai | S12: uan | T12: ing | U12: ik | V12: ann
B13: 台語注音二式 | C13: a | D13: i | E13: u | F13: e | G13: or | H13: oo | I13: ai | J13: au | K13: an | L13: am | M13: ang | N13: m | O13: ng | P13: ua | Q13: ue | R13: uai | S13: uan | T13: ing | U13: iek | V13: ann
B14: 閩拼方案 | C14: a | D14: i | E14: u | F14: e | G14: o | H14: oo | I14: ai | J14: ao | K14: an | L14: am | M14: ang | N14: m | O14: ng | P14: ua | Q14: ue | R14: uai | S14: uan | T14: ing | U14: ik | V14: na
B15: 白話字 | C15: a | D15: i | E15: u | F15: e | G15: o | H15: o͘ | I15: ai | J15: au | K15: an | L15: am | M15: ang | N15: m | O15: ng | P15: oa | Q15: oe | R15: oai | S15: oan | T15: eng | U15: ek | V15: aⁿ
B16: 方音符號 | C16: ㄚ | D16: ㄧ | E16: ㄨ | F16: ㆤ | G16: ㄜ | H16: ㆦ | I16: ㄞ | J16: ㄠ | K16: ㄢ | L16: ㆰ | M16: ㄤ | N16: ㆬ | O16: ㆭ | P16: ㄨㄚ | Q16: ㄨㆤ | R16: ㄨㄞ | S16: ㄨㄢ | T16: ㄧㄥ | U16: ㄧㆻ | V16: ㆩ
B17: 台語注音 | C17: ㄚ | D17: ㄧ | E17: ㄨ | F17: ㄝ | G17: ㄜ | H17: ㄛ | I17: ㄞ | J17: ㄠ | K17: ㄢ | L17: ㄚㄇ | M17: ㄤ | N17: ㄇ | O17: ㄥ | P17: ㄨㄚ | Q17: ㄨㄝ | R17: ㄨㄞ | S17: ㄨㄢ | T17: ㄧㄥ | U17: ㄧㄍ | V17: ⁰ㄚ

Sheet 【韻】拉丁字母加調符
C1: 1 | D1: 2 | E1: 3 | F1: 4 | G1: 5 | H1: 6 | I1: 7 | J1: 8 | K1: 9 | L1: 9
D3: U+0301 | E3: U+0300 | G3: U+030C | H3: U+0301 | I3: U+0304 | J3: U+030D | K3: U+030B | L3: U+030A
B4: a | C4: =_xlfn.CONCAT($B4, IF(C$3="", "", _xlfn.UNICHAR( HEX2DEC( RIGHT(C$3,4))))) -> a | D4: =_xlfn.CONCAT($B4, IF(D$3="", "", _xlfn.UNICHAR( HEX2DEC( RIGHT(D$3,4))))) -> á | E4: =_xlfn.CONCAT($B4, IF(E$3="", "", _xlfn.UNICHAR( HEX2DEC( RIGHT(E$3,4))))) -> à | F4: =_xlfn.CONCAT($B4, IF(F$3="", "", _xlfn.UNICHAR( HEX2DEC( RIGHT(F$3,4))))) -> a | G4: =_xlfn.CONCAT($B4, IF(G$3="", "", _xlfn.UNICHAR( HEX2DEC( RIGHT(G$3,4))))) -> ǎ | H4: =_xlfn.CONCAT($B4, IF(H$3="", "", _xlfn.UNICHAR( HEX2DEC( RIGHT(H$3,4))))) -> á | I4: =_xlfn.CONCAT($B4, IF(I$3="", "", _xlfn.UNICHAR( HEX2DEC( RIGHT(I$3,4))))) -> ā | J4: =_xlfn.CONCAT($B4, IF(J$3="", "", _xlfn.UNICHAR( HEX2DEC( RIGHT(J$3,4))))) -> a̍ | ... L4: =_xlfn.CONCAT($B4, IF(L$3="", "", _xlfn.UNICHAR( HEX2DEC( RIGHT(L$3,4))))) -> å | N4: =_xlfn.CONCAT(" - xform/》", $B4, C$1, "/", C4, "/") -> - xform/》a1/a/ | O4: =_xlfn.CONCAT(" - xform/》", $B4, D$1, "/", D4, "/") -> - xform/》a2/á/ | P4: =_xlfn.CONCAT(" - xform/》", $B4, E$1, "/", E4, "/") -> - xform/》a3/à/ | Q4: =_xlfn.CONCAT(" - xform/》", $B4, F$1, "/", F4, "/") -> - xform/》a4/a/ | R4: =_xlfn.CONCAT(" - xform/》", $B4, G$1, "/", G4, "/") -> - xform/》a5/ǎ/ | S4: =_xlfn.CONCAT(" - xform/》", $B4, H$1, "/", H4, "/") -> - xform/》a6/á/ | T4: =_xlfn.CONCAT(" - xform/》", $B4, I$1, "/", I4, "/") -> - xform/》a7/ā/ | U4: =_xlfn.CONCAT(" - xform/》", $B4, J$1, "/", J4, "/") -> - xform/》a8/a̍/ | ... W4: =_xlfn.CONCAT(" - xform/》", $B4, L$1, "/", L4, "/") -> - xform/》a9/å/
