Workbook
Name 十五音韻母: #REF!
Name 十五音韻母: #REF!
Name 十五音韻母: '[1]十五音-韻母'!$C$5:$C$54
Name 十五音韻母: '[1]十五音-韻母'!$C$5:$C$54
Name 十五音韻母對照表: #REF!
Name 十五音韻母對照表: #REF!
Name 十五音韻母對照表: '[1]十五音-韻母'!$B$5:$R$54
Name 十五音韻母對照表: '[1]十五音-韻母'!$B$5:$R$54
Name 方音符號聲調: [2]設定!$J$3:$J$10
Name 台羅韻母八音反切: #REF!
Name 台羅韻母八音反切: #REF!
Name 台羅韻母八音反切: '[1]台羅-韻母八音反切'!$R$5:$Y$54
Name 台羅韻母八音反切: '[1]台羅-韻母八音反切'!$R$5:$Y$54
Name 白話字韻母八音反切: #REF!
Name 白話字韻母八音反切: #REF!
Name 白話字韻母八音反切: '[1]白話字-韻母八音反切'!$R$5:$Y$54
Name 白話字韻母八音反切: '[1]白話字-韻母八音反切'!$R$5:$Y$54
Name 閩拼八聲調: [2]設定!$I$3:$I$10
Name 閩拼韻母八音反切: #REF!
Name 閩拼韻母八音反切: #REF!
Name 閩拼韻母八音反切: '[1]閩拼-韻母八音反切'!$R$5:$Y$54
Name 閩拼韻母八音反切: '[1]閩拼-韻母八音反切'!$R$5:$Y$54
Name 聲母碼: [3]十五音聲母對照表!$F$4:$F$25
Name 聲母碼: [3]十五音聲母對照表!$F$4:$F$25
Name 聲母碼: #REF!
Name 聲母碼: [2]聲母對照表!$B$4:$B$21
Name 聲母碼表: #REF!
Name 聲母碼表: #REF!
Name 聲母碼表: [1]聲母碼!$D$6:$K$22
Name 聲母碼表: [1]聲母碼!$D$6:$K$22
Name 韻母對照表: #REF!
Name 韻母對照表: #REF!
Name 韻母對照表: [1]韻母對照表!$B$6:$K$105
Name 韻母對照表: [1]韻母對照表!$B$6:$K$105
Name 韻母碼: [2]韻母對照表!$B$4:$B$103
Name 韻母碼表: #REF!
Name 韻母碼表: #REF!
Name 韻母碼表: [1]韻母碼!$F$5:$M$78
Name 韻母碼表: [1]韻母碼!$F$5:$M$78
Name 顯示注音輸入: #REF!
Name 顯示注音輸入: #REF!
Name 顯示注音輸入: [4]env!$C$10
Name 顯示注音輸入: [4]env!$C$10

Sheet 宋人三十六字母表
B2: 發音部位 舊名 | D2: 發音部位 新名 | E2: 發音方法 | N2: 改用台羅拼音來對應與舉例：
E3: 全清 | G3: 次清 | I3: 全濁 | K3: 次濁（清濁）
B4: 唇音 | C4: 重唇 | D4: 雙唇 | E4: [p] | F4: 幫 | G4: [pʰ] | H4: 滂 | I4: [b] | J4: 並 | K4: [m] | L4: 明 | N4: 1. 輕唇音（脣齒音）
E5: ㄅ | F5: 邊 | G5: ㄆ | H5: 頗 | I5: ㆠ | J5: 門 | K5: ㄇ | L5: 毛 | N5: [f] 非 / [fʰ] 敷 / [v] 奉
C6: 輕唇 | D6: 唇齒 | E6: [f] | F6: 非 | G6: [fʰ] | H6: 敷 | I6: [v] | J6: 奉 | K6: [ɱ] | L6: 微 | N6: 台羅拼音： 台語歷史上沒有發展出唇齒擦音 [f]，所以這些字在台羅中大都回歸到重唇音（雙唇音），對應 p（不送氣清音）或 ph（送氣清音）。
N7: 舉例：
B8: 舌音 | C8: 舌頭 | D8: 舌尖中 | E8: [t] | F8: 端 | G8: [tʰ] | H8: 透 | I8: [d] | J8: 定 | K8: [n] | L8: 泥 | N8: 「非」：台羅 hui（特別的讀法）/ 類似字「副」讀 phù。
E9: ㄉ | F9: 地 | G9: ㄊ | H9: 他 | K9: ㄋ | L9: 耐 | N9: 「敷」：台羅 phu，例如「敷藥 (phu-io̍h)」。
C10: 舌上 | D10: 舌尖後 | E10: [ʈ] | F10: 知 | G10: [ʈʰ] | H10: 徹 | I10: [ɖ] | J10: 澄 | K10: [ɳ] | L10: 娘 | N10: 「奉」：台羅 pōng，例如「奉敬 (pōng-kìng)」。
N11: [ɱ] 微
B12: 齒音 | C12: 齒頭 | D12: 舌尖前 | E12: [ʦ] | F12: 精 | G12: [ʦʰ] | H12: 清 | I12: [ʣ] | J12: 從 | N12: 台羅拼音： 在台語中完美保留了鼻音特徵，對應 m 的發音。
E13: ㄗ | F13: 曾 | G13: ㄘ | H13: 出 | I13: ㆡ | J13: 熱 | N13: 舉例： 「微」台羅 bî（文讀）/「無」台羅 bô；但在白讀音中，微母字常對應 m，例如「目 (ba̍k/mats)」或「微 (mî)」。
E14: [s] | F14: 心 | I14: [z] | J14: 邪
E15: ㄙ | F15: 時 | N15: 2. 舌上音（捲舌音 ➡️ 台語轉為舌尖前/中音）
C16: 正齒 | D16: 舌面前 | E16: [ʨ] | F16: 照 | G16: [ʨʰ] | H16: 穿 | I16: [ʥ] | J16: 牀 | N16: 台語沒有華語的捲舌音（zh, ch, sh, r），中古漢語的捲舌音在台語裡一律讀作舌尖音。
E17: ㄐ | F17: 止 | G17: ㄑ | H17: 且 | I17: ㆢ | J17: 入 | N17: [ʈ] 知
E18: [ɕ] | F18: 審 | I18: [ʑ] | J18: 禪 | N18: 台羅拼音： 對應 ts（不送氣清音）。
E19: ㄒ | F19: 時 | N19: 舉例： 「知」台羅 tsi，例如「知影 (tsi-iann)」；「張」台羅 tiunn。
B20: 牙音 | D20: 舌根 | E20: [k] | F20: 見 | G20: [kʰ] | H20: 溪 | I20: [g] | J20: 群 | K20: [ŋ] | L20: 疑 | N20: [ʈʰ] 徹
E21: ㄍ | F21: 求 | G21: ㄎ | H21: 去 | I21: ㆣ | J21: 語 | K21: ㄫ | L21: 雅 | N21: 台羅拼音： 對應 tsh（送氣清音）。
B22: 喉音 | D22: 喉音 | E22: [ʔ] | F22: 影 | N22: 舉例： 「徹」台羅 thiat；「出」台羅 tshut，例如「出來 (tshut-lâi)」。
E23: Ø | F23: 英 | N23: [ɖ] 澄
D24: 舌根 | E24: [x] | F24: 曉 | I24: [ɣ] | J24: 匣 | N24: 台羅拼音： 中古全濁音在台語依平仄清化，演變為 ts 或 tsh。
E25: ㄏ | F25: 喜 | N25: 舉例： 「茶」台羅 tê（澄母平聲轉 th/tsh）；「治」台羅 tī（澄母仄聲轉 ts）。
D26: 半元音 | K26: [j] | L26: 喻 | N26: [ɳ] 娘
N27: 台羅拼音： 與泥母合併，對應 n 的發音。
B28: 半舌音 | D28: 舌尖中 | K28: [l] | L28: 來 | N28: 舉例： 「娘」台羅 niû，例如「阿娘 (a-niû)」；「鈕」台羅 liú/niú。
K29: ㄌ | L29: 柳
B30: 半齒音 | D30: 舌面前 | K30: [ɲʑ] | L30: 日 | N30: 3. 舌頭音（齒齦音）
N31: [d] 定
N32: 台羅拼音： 這是台語最具優勢的地方！中古全濁音 [d]，在台語平聲演變為送氣 th，仄聲演變為不送氣 t。
N33: 舉例：
N34: 平聲轉 th：「頭」台羅 thâu（頭殼）、「天」台羅 thian。
N35: 仄聲轉 t：「地」台羅 tē（土地）、「大」台羅 tuā/tāi（大人）。
N37: 4. 齒音（擦音）
N38: [z] 邪
N39: 台羅拼音： 現代台語主要演變為 s 或 ts/j。
N40: 舉例： 「俗」台羅 sio̍k（便宜）；「詞」台羅 sû；「徐」台羅 tshî/sî。
N41: [ʑ] 禪
N42: 台羅拼音： 主要演變為 s 或 ts/tsh。
...

Sheet 聲母
B2: 發音部位 | D2: 清塞音或塞擦音 | H2: 濁音 | J2: 鼻音 | L2: 擦音 | N2: 邊音
D3: 不送氣 | F3: 送氣
B4: 唇音 | C4: 唇音 | D4: /p/ | E4: b | F4: /pʰ/ | G4: p | H4: /b/ | I4: bb | J4: /m/ | K4: m
D5: ㄅ | E5: 邊 | F5: ㄆ | G5: 頗 | H5: ㆠ | I5: 門 | J5: ㄇ | K5: 毛
B6: 舌尖中音 | C6: 舌尖音 | D6: /t/ | E6: d | F6: /tʰ/ | G6: t | J6: /n/ | K6: n | N6: /l/ | O6: l
D7: ㄉ | E7: 地 | F7: ㄊ | G7: 他 | J7: ㄋ | K7: 耐 | N7: ㄌ | O7: 柳
B8: 舌尖前音 | C8: 舌齒音 | D8: /ʦ/ | E8: z | F8: /ʦʰ/ | G8: c | H8: /ʣ/ | I8: j | L8: /s/ | M8: s
D9: ㄗ | E9: 曾 | F9: ㄘ | G9: 出 | H9: ㆡ | I9: 熱 | L9: ㄙ | M9: 時
B10: 齦顎音 | C10: 齦顎音 | D10: /ʨ/ | E10: zz(i) | F10: /ʨʰ/ | G10: ch(i) | H10: /ʥ/ | I10: jj(i) | L10: /ɕ/ | M10: sh(i)
D11: ㄐ | E11: 止 | F11: ㄑ | G11: 且 | H11: ㆢ | I11: 入 | L11: ㄒ | M11: 時
B12: 舌根音 | C12: 舌根音 | D12: /k/ | E12: g | F12: /kʰ/ | G12: k | H12: /g/ | I12: gg | J12: /ŋ/ | K12: ng
D13: ㄍ | E13: 求 | F13: ㄎ | G13: 去 | H13: ㆣ | I13: 語 | J13: ㄫ | K13: 雅
B14: 喉音 | C14: 喉音 | L14: /h/ | M14: h
L15: ㄏ | M15: 喜
B16: 零聲母 | C16: 零聲母 | D16: ʔ | E16: Ø
E17: 英

Sheet 韻母
B2: 韻腹 | C2: 陰聲韻 | G2: 陽聲韻 | M2: 入聲韻
G3: m | I3: n | K3: ŋ | M3: p̚ | O3: t̚ | Q3: k̚ | S3: ʔ
B4: a | C4: a | D4: a | E4: ã | F4: ann | G4: am | H4: am | I4: an | J4: an | K4: aŋ | L4: ang | M4: ap˺ | N4: ap | O4: at˺ | P4: at | Q4: ak˺ | R4: ak | S4: aʔ | T4: ah | U4: ãʔ | V4: annh
C5: ㄚ | D5: 阿 | E5: ㆩ | F5: 餡 | G5: ㆰ | H5: 庵 | I5: ㄢ | J5: 安 | K5: ㄤ | L5: 尪 | M5: ㄚㆴ | N5: 壓 | O5: ㄚㆵ | P5: 遏 | Q5: ㄚㆻ | R5: 握 | S5: ㄚㆷ | T5: 鴨 | U5: ㆩㆷ | V5: 熁
B6: aɪ | C6: ai | D6: ai | E6: ãi | F6: ainn | S6: aiʔ | T6: aih | U6: ãiʔ | V6: ainnh
C7: ㄞ | D7: 哀 | E7: ㆮ | F7: 閑 | S7: ㄞㆷ | T7: 邁 | U7: ㆮㆷ | V7: 擺
B8: aʊ | C8: ãʊ | D8: au | S8: aʊʔ | T8: auh | U8: ãʊʔ | V8: aunnh
C9: ㄠ | D9: 甌 | S9: ㄠㆷ | T9: 暴 | U9: ㆯㆷ | V9: 好
B10: ɛ | C10: ɛ | D10: ee | K10: əŋ | L10: eng | Q10: ek | R10: ek | S10: ɛʔ | T10: eeh
C11: ㄝ | D11: 家 | K11: ㄥ | L11: 永 | Q11: ㆤㆻ | R11: 益 | S11: ㄝㆷ | T11: 格
B12: e | C12: e | D12: e | E12: ẽ | F12: enn | S12: eʔ | T12: eh | U12: ɛ̃ʔ | V12: ennh
C13: ㆤ | D13: 稽 | E13: ㆥ | F13: 嬰 | S13: ㆤㆷ | T13: 厄 | U13: ㆥㆷ | V13: 擲
B14: i | C14: i | D14: i | E14: ĩ | F14: inn | G14: im | H14: im | I14: in | J14: in | K14: iŋ | L14: ing | M14: ip˺ | N14: ip | O14: it˺ | P14: it | Q14: ik˺ | R14: ik | S14: iʔ | T14: ih | U14: ĩʔ | V14: innh
C15: ㄧ | D15: 伊 | E15: ㆪ | F15: 燕 | G15: ㄧㆬ | H15: 音 | I15: ㄧㄣ | J15: 因 | K15: ㄧㄥ | L15: 永 | M15: ㄧㆴ | N15: 揖 | O15: ㄧㆵ | P15: 乙 | Q15: ㄧㆻ | R15: 益 | S15: ㄧㆷ | T15: 舌 | U15: ㆪㆷ | V15: 物
B16: ɪa | C16: ia | D16: ia | E16: iã | F16: iann | G16: iam | H16: iam | I16: ian | J16: ian | K16: iaŋ | L16: iang | M16: iap˺ | N16: iap | O16: iat˺ | P16: iat | Q16: iak˺ | R16: iak | S16: iaʔ | T16: iah | U16: iãʔ | V16: iannh
C17: ㄧㄚ | D17: 耶 | E17: ㄧㆩ | F17: 纓 | G17: ㄧㆰ | H17: 閹 | I17: ㄧㄢ | J17: 煙 | K17: ㄧㄤ | L17: 雙 | M17: ㄧㄚㆴ | N17: 葉 | O17: ㄧㄚㆵ | P17: 閱 | Q17: ㄧㄚㆻ | R17: 約 | S17: ㄧㄚㆷ | T17: 役 | U17: ㄧㆩㆷ | V17: 挾
B18: ɪaʊ | C18: iaʊ | D18: iau | E18: iãu | F18: iaunn | S18: iãʊʔ | T18: iauh
C19: ㄧㄠ | D19: 妖 | E19: ㄧㆯ | F19: 貓 | S19: ㄧㄠㆷ | T19: 沓
B20: io | C20: io | D20: io | S20: ioʔ | T20: ioh
C21: ㄧㄜ | D21: 腰 | S21: ㄧㄜㆷ | T21: 着
B22: iɔ | C22: iɔ | D22: ioo | E22: iɔ̃ | F22: ioonn | K22: iɔŋ | L22: iong | Q22: iɔk˺ | R22: iook | S22: iooh
C23: ㄧㆦ | D23: 娘 | E23: ㄧㆧ | F23: 鴦 | K23: ㄧㆲ | L23: 雍 | Q23: ㄧㆦㆻ | R23: 育
B24: iu | C24: iu | D24: iu | E24: iũ | F24: iunn | S24: iuʔ | T24: iuh | U24: iũʔ | V24: iunnh
C25: ㄧㄨ | D25: 優 | E25: ㄧㆫ | F25: 鴦 | S25: ㄧㄨㆷ | T25: 抽 | U25: ㄧㆫㆷ | V25: 咻
B26: ə | C26: ə | D26: er | S26: əʔ | T26: erh
C27: ㄜ | D27: 鍋 | S27: ㄜㆷ | T27: 郭
B28: o | C28: o | D28: or | S28: əʔ | T28: orh
C29: ㄜ | D29: 蚵 | S29: ㄜㆷ | T29: 博
B30: ɔ | C30: ɔ | D30: oo | E30: ɔ̃ | F30: oonn | G30: ɔm | H30: oom | K30: ɔŋ | L30: ong | M30: ɔp˺ | N30: oop | Q30: ɔk˺ | R30: ook | S30: ɔʔ | T30: ooh | U30: ɔ̃ʔ | V30: oonnh
C31: ㆦ | D31: 烏 | E31: ㆧ | F31: 好 | G31: ㆱ | H31: 丼 | K31: ㆲ | L31: 汪 | M31: ㆦㆴ | N31: 鞹 | Q31: ㆦㆻ | R31: 惡 | S31: ㆦㆷ | T31: 瘼 | U31: ㆧㆷ | V31: 膜
B32: ɨ | C32: ɨ | D32: ir | G32: ɨm | H32: irm | I32: ɨ | J32: irn | K32: ɨŋ | L32: irng | M32: irp˺ | N32: irp | O32: irt˺ | P32: irt | Q32: irk˺ | R32: irk | S32: irh
C33: ㆨ | D33: 於 | G33: ㆨㆬ | H33: 蔘 | I33: ㆨ | J33: 恩 | K33: ㆨㆭ | L33: 登 | M33: ㆨㆴ | N33: 澀 | O33: ㆨㆵ | P33: 核 | Q33: ㆨㆻ | R33: 疄
B34: u | C34: u | D34: u | I34: un | J34: un | O34: ut˺ | P34: ut | S34: uʔ | T34: uh
C35: ㄨ | D35: 污 | I35: ㄨㄣ | J35: 溫 | O35: ㄨㆵ | P35: 熨 | S35: ㄨㆷ | T35: 突
B36: ua | C36: ua | D36: ua | E36: uã | F36: uann | I36: uan | J36: uan | K36: uang | L36: uang | O36: uat˺ | P36: uat | S36: uaʔ | T36: uah
C37: ㄨㄚ | D37: 娃 | E37: ㄨㆩ | F37: 鞍 | I37: ㄨㄢ | J37: 冤 | K37: ㄨㄤ | L37: 嚁 | O37: ㄨㄚㆵ | P37: 越 | S37: ㄨㄚㆷ | T37: 活
B38: uai | C38: uai | D38: uai | E38: uãi | F38: uainn
C39: ㄨㄞ | D39: 歪 | E39: ㄨㆮ | F39: 關
B40: uɛ | C40: uɛ | D40: uee | S40: ueeh
C41: ㄨㄝ | D41: 話
...

Sheet 朱兆祥方音符號聲母表
D2: 雙唇音 | L2: 舌尖前音 | T2: 舌尖中音 | AB2: 舌根音 | AJ2: 㗋塞音
D3: 上脣。下脣 | L3: 舌尖。上齒背 | T3: 舌尖。上齒齦 | AB3: 舌根軟顎 | AJ3: 氣管咽頭
D4: 清音 | H4: 濁音 | L4: 清音 | P4: 濁音 | T4: 清音 | X4: 濁音 | AB4: 清音 | AF4: 濁音 | AJ4: 清音 | AP4: 清塞音/塞擦音（不送氣） | AT4: 濁音 | AX4: 清塞音/塞擦音（送氣） | BB4: 鼻音 | BF4: 邊音 | BJ4: 擦音
B5: 鼻音 | H5: 門 | J5: m | X5: 柳 | Z5: n | AF5: 語 | AH5: ng | AP5: 邊 | AR5: p | AT5: 門 | AV5: b | AX5: 頗 | AZ5: ph | BB5: 毛 | BD5: m | BP5: 1 | BQ5: ㄅ
BP6: 2 | BQ6: ㆠ
H7: ㄇ | J7: m | X7: ㄋ | Z7: n | AF7: ㄫ | AH7: ng | AP7: ㄅ | AR7: b | AT7: ㆠ | AV7: bb | AX7: ㄆ | AZ7: p | BB7: ㄇ | BD7: m | BP7: 3 | BQ7: ㄆ
BP8: 4 | BQ8: ㄇ
B9: 塞音 | C9: 不送氣 | D9: 邊 | F9: p | H9: 門 | J9: b | T9: 地 | V9: t | AB9: 求 | AD9: k | AF9: 語 | AH9: g | AJ9: 英 | AL9: Ø | AP9: 地 | AR9: t | AX9: 他 | AZ9: th | BB9: 耐 | BD9: n | BF9: 柳 | BH9: l | BP9: 5 | BQ9: ㄉ
BP10: 6 | BQ10: ㄊ
D11: ㄅ | F11: b | H11: ㆠ | J11: bb | T11: ㄉ | V11: d | AB11: ㄍ | AD11: g | AF11: ㆣ | AH11: gg | AJ11: Ø | AL11: Ø | AP11: ㄉ | AR11: d | AX11: ㄊ | AZ11: t | BB11: ㄋ | BD11: n | BF11: ㄌ | BH11: l | BP11: 7 | BQ11: ㄋ
BP12: 8 | BQ12: ㄌ
C13: 送氣 | D13: 頗 | F13: ph | T13: 他 | V13: th | AB13: 去 | AD13: kh | AP13: 求 | AR13: k | AT13: 語 | AV13: g | AX13: 去 | AZ13: kh | BB13: 雅 | BD13: ng | BP13: 9 | BQ13: ㄍ
BP14: 10 | BQ14: ㆣ
D15: ㄆ | F15: p | T15: ㄊ | V15: t | AB15: ㄎ | AD15: k | AP15: ㄍ | AR15: g | AT15: ㆣ | AV15: gg | AX15: ㄎ | AZ15: k | BB15: ㄫ | BD15: ng | BP15: 11 | BQ15: ㄎ
BP16: 12 | BQ16: ㄫ
B17: 塞擦音 | C17: 不送氣 | L17: 曾 | N17: tsi | P17: 入 | R17: ji | T17: 曾 | V17: ts | X17: 入 | Z17: j | BJ17: 喜 | BL17: h | BP17: 13 | BQ17: ㄏ
BP18: 14 | BQ18: ㄐ
L19: ㄐ | N19: ji | P19: ㆢ | R19: jji | T19: ㄗ | V19: z | X19: ㆡ | Z19: zz | BJ19: ㄏ | BL19: h | BP19: 15 | BQ19: ㄑ
BP20: 16 | BQ20: ㄗ
C21: 送氣 | L21: 出 | N21: tshi | T21: 出 | V21: tsh | AP21: 曾 | AR21: tsi | AX21: 出 | AZ21: tshi | BP21: 17 | BQ21: ㄘ
BP22: 18 | BQ22: ㄙ
L23: ㄑ | N23: chi | T23: ㄘ | V23: c | AP23: ㄐ | AR23: ji | AX23: ㄑ | AZ23: chi
B25: 擦音 | L25: 時 | N25: si | T25: 時 | V25: s | AJ25: 喜 | AL25: h | AP25: 曾 | AR25: ts | AX25: 出 | AZ25: tsh | BJ25: 時 | BL25: s
L27: ㄒ | N27: shi | T27: ㄙ | V27: s | AJ27: ㄏ | AL27: h | AP27: ㄗ | AR27: z | AX27: ㄘ | AZ27: c | BJ27: ㄙ | BL27: s
B29: 邊音 | X29: 柳 | Z29: l
X31: ㄌ | Z31: l

Sheet 【聲】聲母排序表
A1: 注音序 | B1: 國際音標 | C1: 十五音 | D1: 方音符號 | E1: 台語注音 | F1: 注音二式 | G1: 閩拼方案 | H1: 台羅拼音 | I1: 台語音標 | J1: 白話字 | K1: 備註
A2: 1 | B2: Ø | C2: Ø | D2: Ø | E2: Ø | F2: Ø | G2: Ø | H2: Ø | I2: Ø | J2: Ø | K2: 零聲母
A3: 2 | B3: {=INDEX(聲母對照表[國際音標], MATCH(TRUE, EXACT(【聲】聲母排序表!$D3, 聲母對照表[方音符號]),0))} -> p | C3: {=INDEX(聲母對照表[十五音], MATCH(TRUE, EXACT(【聲】聲母排序表!$D3, 聲母對照表[方音符號]),0))} -> 邊 | D3: ㄅ | E3: {=INDEX(聲母對照表[台語注音], MATCH(TRUE, EXACT(【聲】聲母排序表!$D3, 聲母對照表[方音符號]),0))} -> ㄅ | F3: {=INDEX(聲母對照表[注音二式], MATCH(TRUE, EXACT(【聲】聲母排序表!$D3, 聲母對照表[方音符號]),0))} -> b | G3: {=INDEX(聲母對照表[閩拼方案], MATCH(TRUE, EXACT(【聲】聲母排序表!$D3, 聲母對照表[方音符號]),0))} -> b | H3: {=INDEX(聲母對照表[台羅拼音], MATCH(TRUE, EXACT(【聲】聲母排序表!$D3, 聲母對照表[方音符號]),0))} -> p | I3: {=INDEX(聲母對照表[台語音標], MATCH(TRUE, EXACT(【聲】聲母排序表!$D3, 聲母對照表[方音符號]),0))} -> p | J3: {=INDEX(聲母對照表[白話字], MATCH(TRUE, EXACT(【聲】聲母排序表!$D3, 聲母對照表[方音符號]),0))} -> p
A4: 3 | B4: {=INDEX(聲母對照表[國際音標], MATCH(TRUE, EXACT(【聲】聲母排序表!$D4, 聲母對照表[方音符號]),0))} -> b | C4: {=INDEX(聲母對照表[十五音], MATCH(TRUE, EXACT(【聲】聲母排序表!$D4, 聲母對照表[方音符號]),0))} -> 門 | D4: ㆠ | E4: {=INDEX(聲母對照表[台語注音], MATCH(TRUE, EXACT(【聲】聲母排序表!$D4, 聲母對照表[方音符號]),0))} -> ㄪ | F4: {=INDEX(聲母對照表[注音二式], MATCH(TRUE, EXACT(【聲】聲母排序表!$D4, 聲母對照表[方音符號]),0))} -> bb | G4: {=INDEX(聲母對照表[閩拼方案], MATCH(TRUE, EXACT(【聲】聲母排序表!$D4, 聲母對照表[方音符號]),0))} -> bb | H4: {=INDEX(聲母對照表[台羅拼音], MATCH(TRUE, EXACT(【聲】聲母排序表!$D4, 聲母對照表[方音符號]),0))} -> b | I4: {=INDEX(聲母對照表[台語音標], MATCH(TRUE, EXACT(【聲】聲母排序表!$D4, 聲母對照表[方音符號]),0))} -> b | J4: {=INDEX(聲母對照表[白話字], MATCH(TRUE, EXACT(【聲】聲母排序表!$D4, 聲母對照表[方音符號]),0))} -> b
A5: 4 | B5: {=INDEX(聲母對照表[國際音標], MATCH(TRUE, EXACT(【聲】聲母排序表!$D5, 聲母對照表[方音符號]),0))} -> pʰ | C5: {=INDEX(聲母對照表[十五音], MATCH(TRUE, EXACT(【聲】聲母排序表!$D5, 聲母對照表[方音符號]),0))} -> 頗 | D5: ㄆ | E5: {=INDEX(聲母對照表[台語注音], MATCH(TRUE, EXACT(【聲】聲母排序表!$D5, 聲母對照表[方音符號]),0))} -> ㄆ | F5: {=INDEX(聲母對照表[注音二式], MATCH(TRUE, EXACT(【聲】聲母排序表!$D5, 聲母對照表[方音符號]),0))} -> p | G5: {=INDEX(聲母對照表[閩拼方案], MATCH(TRUE, EXACT(【聲】聲母排序表!$D5, 聲母對照表[方音符號]),0))} -> p | H5: {=INDEX(聲母對照表[台羅拼音], MATCH(TRUE, EXACT(【聲】聲母排序表!$D5, 聲母對照表[方音符號]),0))} -> ph | I5: {=INDEX(聲母對照表[台語音標], MATCH(TRUE, EXACT(【聲】聲母排序表!$D5, 聲母對照表[方音符號]),0))} -> ph | J5: {=INDEX(聲母對照表[白話字], MATCH(TRUE, EXACT(【聲】聲母排序表!$D5, 聲母對照表[方音符號]),0))} -> ph
A6: 5 | B6: {=INDEX(聲母對照表[國際音標], MATCH(TRUE, EXACT(【聲】聲母排序表!$D6, 聲母對照表[方音符號]),0))} -> m | C6: {=INDEX(聲母對照表[十五音], MATCH(TRUE, EXACT(【聲】聲母排序表!$D6, 聲母對照表[方音符號]),0))} -> 毛 | D6: ㄇ | E6: {=INDEX(聲母對照表[台語注音], MATCH(TRUE, EXACT(【聲】聲母排序表!$D6, 聲母對照表[方音符號]),0))} -> ㄇ | F6: {=INDEX(聲母對照表[注音二式], MATCH(TRUE, EXACT(【聲】聲母排序表!$D6, 聲母對照表[方音符號]),0))} -> m | G6: {=INDEX(聲母對照表[閩拼方案], MATCH(TRUE, EXACT(【聲】聲母排序表!$D6, 聲母對照表[方音符號]),0))} -> bbn | H6: {=INDEX(聲母對照表[台羅拼音], MATCH(TRUE, EXACT(【聲】聲母排序表!$D6, 聲母對照表[方音符號]),0))} -> m | I6: {=INDEX(聲母對照表[台語音標], MATCH(TRUE, EXACT(【聲】聲母排序表!$D6, 聲母對照表[方音符號]),0))} -> m | J6: {=INDEX(聲母對照表[白話字], MATCH(TRUE, EXACT(【聲】聲母排序表!$D6, 聲母對照表[方音符號]),0))} -> m
A7: 6 | B7: {=INDEX(聲母對照表[國際音標], MATCH(TRUE, EXACT(【聲】聲母排序表!$D7, 聲母對照表[方音符號]),0))} -> t | C7: {=INDEX(聲母對照表[十五音], MATCH(TRUE, EXACT(【聲】聲母排序表!$D7, 聲母對照表[方音符號]),0))} -> 地 | D7: ㄉ | E7: {=INDEX(聲母對照表[台語注音], MATCH(TRUE, EXACT(【聲】聲母排序表!$D7, 聲母對照表[方音符號]),0))} -> ㄉ | F7: {=INDEX(聲母對照表[注音二式], MATCH(TRUE, EXACT(【聲】聲母排序表!$D7, 聲母對照表[方音符號]),0))} -> d | G7: {=INDEX(聲母對照表[閩拼方案], MATCH(TRUE, EXACT(【聲】聲母排序表!$D7, 聲母對照表[方音符號]),0))} -> d | H7: {=INDEX(聲母對照表[台羅拼音], MATCH(TRUE, EXACT(【聲】聲母排序表!$D7, 聲母對照表[方音符號]),0))} -> t | I7: {=INDEX(聲母對照表[台語音標], MATCH(TRUE, EXACT(【聲】聲母排序表!$D7, 聲母對照表[方音符號]),0))} -> t | J7: {=INDEX(聲母對照表[白話字], MATCH(TRUE, EXACT(【聲】聲母排序表!$D7, 聲母對照表[方音符號]),0))} -> t
A8: 7 | B8: {=INDEX(聲母對照表[國際音標], MATCH(TRUE, EXACT(【聲】聲母排序表!$D8, 聲母對照表[方音符號]),0))} -> tʰ | C8: {=INDEX(聲母對照表[十五音], MATCH(TRUE, EXACT(【聲】聲母排序表!$D8, 聲母對照表[方音符號]),0))} -> 他 | D8: ㄊ | E8: {=INDEX(聲母對照表[台語注音], MATCH(TRUE, EXACT(【聲】聲母排序表!$D8, 聲母對照表[方音符號]),0))} -> ㄊ | F8: {=INDEX(聲母對照表[注音二式], MATCH(TRUE, EXACT(【聲】聲母排序表!$D8, 聲母對照表[方音符號]),0))} -> t | G8: {=INDEX(聲母對照表[閩拼方案], MATCH(TRUE, EXACT(【聲】聲母排序表!$D8, 聲母對照表[方音符號]),0))} -> t | H8: {=INDEX(聲母對照表[台羅拼音], MATCH(TRUE, EXACT(【聲】聲母排序表!$D8, 聲母對照表[方音符號]),0))} -> th | I8: {=INDEX(聲母對照表[台語音標], MATCH(TRUE, EXACT(【聲】聲母排序表!$D8, 聲母對照表[方音符號]),0))} -> th | J8: {=INDEX(聲母對照表[白話字], MATCH(TRUE, EXACT(【聲】聲母排序表!$D8, 聲母對照表[方音符號]),0))} -> th
A9: 8 | B9: {=INDEX(聲母對照表[國際音標], MATCH(TRUE, EXACT(【聲】聲母排序表!$D9, 聲母對照表[方音符號]),0))} -> n | C9: {=INDEX(聲母對照表[十五音], MATCH(TRUE, EXACT(【聲】聲母排序表!$D9, 聲母對照表[方音符號]),0))} -> 耐 | D9: ㄋ | E9: {=INDEX(聲母對照表[台語注音], MATCH(TRUE, EXACT(【聲】聲母排序表!$D9, 聲母對照表[方音符號]),0))} -> ㄋ | F9: {=INDEX(聲母對照表[注音二式], MATCH(TRUE, EXACT(【聲】聲母排序表!$D9, 聲母對照表[方音符號]),0))} -> n | G9: {=INDEX(聲母對照表[閩拼方案], MATCH(TRUE, EXACT(【聲】聲母排序表!$D9, 聲母對照表[方音符號]),0))} -> ln | H9: {=INDEX(聲母對照表[台羅拼音], MATCH(TRUE, EXACT(【聲】聲母排序表!$D9, 聲母對照表[方音符號]),0))} -> n | I9: {=INDEX(聲母對照表[台語音標], MATCH(TRUE, EXACT(【聲】聲母排序表!$D9, 聲母對照表[方音符號]),0))} -> n | J9: {=INDEX(聲母對照表[白話字], MATCH(TRUE, EXACT(【聲】聲母排序表!$D9, 聲母對照表[方音符號]),0))} -> n
A10: 9 | B10: {=INDEX(聲母對照表[國際音標], MATCH(TRUE, EXACT(【聲】聲母排序表!$D10, 聲母對照表[方音符號]),0))} -> l | C10: {=INDEX(聲母對照表[十五音], MATCH(TRUE, EXACT(【聲】聲母排序表!$D10, 聲母對照表[方音符號]),0))} -> 柳 | D10: ㄌ | E10: {=INDEX(聲母對照表[台語注音], MATCH(TRUE, EXACT(【聲】聲母排序表!$D10, 聲母對照表[方音符號]),0))} -> ㄌ | F10: {=INDEX(聲母對照表[注音二式], MATCH(TRUE, EXACT(【聲】聲母排序表!$D10, 聲母對照表[方音符號]),0))} -> l | G10: {=INDEX(聲母對照表[閩拼方案], MATCH(TRUE, EXACT(【聲】聲母排序表!$D10, 聲母對照表[方音符號]),0))} -> l | H10: {=INDEX(聲母對照表[台羅拼音], MATCH(TRUE, EXACT(【聲】聲母排序表!$D10, 聲母對照表[方音符號]),0))} -> l | I10: {=INDEX(聲母對照表[台語音標], MATCH(TRUE, EXACT(【聲】聲母排序表!$D10, 聲母對照表[方音符號]),0))} -> l | J10: {=INDEX(聲母對照表[白話字], MATCH(TRUE, EXACT(【聲】聲母排序表!$D10, 聲母對照表[方音符號]),0))} -> l
A11: 10 | B11: {=INDEX(聲母對照表[國際音標], MATCH(TRUE, EXACT(【聲】聲母排序表!$D11, 聲母對照表[方音符號]),0))} -> k | C11: {=INDEX(聲母對照表[十五音], MATCH(TRUE, EXACT(【聲】聲母排序表!$D11, 聲母對照表[方音符號]),0))} -> 求 | D11: ㄍ | E11: {=INDEX(聲母對照表[台語注音], MATCH(TRUE, EXACT(【聲】聲母排序表!$D11, 聲母對照表[方音符號]),0))} -> ㄍ | F11: {=INDEX(聲母對照表[注音二式], MATCH(TRUE, EXACT(【聲】聲母排序表!$D11, 聲母對照表[方音符號]),0))} -> g | G11: {=INDEX(聲母對照表[閩拼方案], MATCH(TRUE, EXACT(【聲】聲母排序表!$D11, 聲母對照表[方音符號]),0))} -> g | H11: {=INDEX(聲母對照表[台羅拼音], MATCH(TRUE, EXACT(【聲】聲母排序表!$D11, 聲母對照表[方音符號]),0))} -> k | I11: {=INDEX(聲母對照表[台語音標], MATCH(TRUE, EXACT(【聲】聲母排序表!$D11, 聲母對照表[方音符號]),0))} -> k | J11: {=INDEX(聲母對照表[白話字], MATCH(TRUE, EXACT(【聲】聲母排序表!$D11, 聲母對照表[方音符號]),0))} -> k
A12: 11 | B12: {=INDEX(聲母對照表[國際音標], MATCH(TRUE, EXACT(【聲】聲母排序表!$D12, 聲母對照表[方音符號]),0))} -> ɡ | C12: {=INDEX(聲母對照表[十五音], MATCH(TRUE, EXACT(【聲】聲母排序表!$D12, 聲母對照表[方音符號]),0))} -> 語 | D12: ㆣ | E12: {=INDEX(聲母對照表[台語注音], MATCH(TRUE, EXACT(【聲】聲母排序表!$D12, 聲母對照表[方音符號]),0))} -> ㄫ | F12: {=INDEX(聲母對照表[注音二式], MATCH(TRUE, EXACT(【聲】聲母排序表!$D12, 聲母對照表[方音符號]),0))} -> gg | G12: {=INDEX(聲母對照表[閩拼方案], MATCH(TRUE, EXACT(【聲】聲母排序表!$D12, 聲母對照表[方音符號]),0))} -> gg | H12: {=INDEX(聲母對照表[台羅拼音], MATCH(TRUE, EXACT(【聲】聲母排序表!$D12, 聲母對照表[方音符號]),0))} -> g | I12: {=INDEX(聲母對照表[台語音標], MATCH(TRUE, EXACT(【聲】聲母排序表!$D12, 聲母對照表[方音符號]),0))} -> g | J12: {=INDEX(聲母對照表[白話字], MATCH(TRUE, EXACT(【聲】聲母排序表!$D12, 聲母對照表[方音符號]),0))} -> g
A13: 12 | B13: {=INDEX(聲母對照表[國際音標], MATCH(TRUE, EXACT(【聲】聲母排序表!$D13, 聲母對照表[方音符號]),0))} -> kʰ | C13: {=INDEX(聲母對照表[十五音], MATCH(TRUE, EXACT(【聲】聲母排序表!$D13, 聲母對照表[方音符號]),0))} -> 去 | D13: ㄎ | E13: {=INDEX(聲母對照表[台語注音], MATCH(TRUE, EXACT(【聲】聲母排序表!$D13, 聲母對照表[方音符號]),0))} -> ㄎ | F13: {=INDEX(聲母對照表[注音二式], MATCH(TRUE, EXACT(【聲】聲母排序表!$D13, 聲母對照表[方音符號]),0))} -> k | G13: {=INDEX(聲母對照表[閩拼方案], MATCH(TRUE, EXACT(【聲】聲母排序表!$D13, 聲母對照表[方音符號]),0))} -> k | H13: {=INDEX(聲母對照表[台羅拼音], MATCH(TRUE, EXACT(【聲】聲母排序表!$D13, 聲母對照表[方音符號]),0))} -> kh | I13: {=INDEX(聲母對照表[台語音標], MATCH(TRUE, EXACT(【聲】聲母排序表!$D13, 聲母對照表[方音符號]),0))} -> kh | J13: {=INDEX(聲母對照表[白話字], MATCH(TRUE, EXACT(【聲】聲母排序表!$D13, 聲母對照表[方音符號]),0))} -> kh
A14: 13 | B14: {=INDEX(聲母對照表[國際音標], MATCH(TRUE, EXACT(【聲】聲母排序表!$D14, 聲母對照表[方音符號]),0))} -> ŋ | C14: {=INDEX(聲母對照表[十五音], MATCH(TRUE, EXACT(【聲】聲母排序表!$D14, 聲母對照表[方音符號]),0))} -> 雅 | D14: ㄫ | E14: {=INDEX(聲母對照表[台語注音], MATCH(TRUE, EXACT(【聲】聲母排序表!$D14, 聲母對照表[方音符號]),0))} -> ⁰ㄫ | F14: {=INDEX(聲母對照表[注音二式], MATCH(TRUE, EXACT(【聲】聲母排序表!$D14, 聲母對照表[方音符號]),0))} -> ng | G14: {=INDEX(聲母對照表[閩拼方案], MATCH(TRUE, EXACT(【聲】聲母排序表!$D14, 聲母對照表[方音符號]),0))} -> ggn | H14: {=INDEX(聲母對照表[台羅拼音], MATCH(TRUE, EXACT(【聲】聲母排序表!$D14, 聲母對照表[方音符號]),0))} -> ng | I14: {=INDEX(聲母對照表[台語音標], MATCH(TRUE, EXACT(【聲】聲母排序表!$D14, 聲母對照表[方音符號]),0))} -> ng | J14: {=INDEX(聲母對照表[白話字], MATCH(TRUE, EXACT(【聲】聲母排序表!$D14, 聲母對照表[方音符號]),0))} -> ng
A15: 14 | B15: {=INDEX(聲母對照表[國際音標], MATCH(TRUE, EXACT(【聲】聲母排序表!$D15, 聲母對照表[方音符號]),0))} -> h | C15: {=INDEX(聲母對照表[十五音], MATCH(TRUE, EXACT(【聲】聲母排序表!$D15, 聲母對照表[方音符號]),0))} -> 喜 | D15: ㄏ | E15: {=INDEX(聲母對照表[台語注音], MATCH(TRUE, EXACT(【聲】聲母排序表!$D15, 聲母對照表[方音符號]),0))} -> ㄏ | F15: {=INDEX(聲母對照表[注音二式], MATCH(TRUE, EXACT(【聲】聲母排序表!$D15, 聲母對照表[方音符號]),0))} -> h | G15: {=INDEX(聲母對照表[閩拼方案], MATCH(TRUE, EXACT(【聲】聲母排序表!$D15, 聲母對照表[方音符號]),0))} -> h | H15: {=INDEX(聲母對照表[台羅拼音], MATCH(TRUE, EXACT(【聲】聲母排序表!$D15, 聲母對照表[方音符號]),0))} -> h | I15: {=INDEX(聲母對照表[台語音標], MATCH(TRUE, EXACT(【聲】聲母排序表!$D15, 聲母對照表[方音符號]),0))} -> h | J15: {=INDEX(聲母對照表[白話字], MATCH(TRUE, EXACT(【聲】聲母排序表!$D15, 聲母對照表[方音符號]),0))} -> h
A16: 15 | B16: {=INDEX(聲母對照表[國際音標], MATCH(TRUE, EXACT(【聲】聲母排序表!$D16, 聲母對照表[方音符號]),0))} -> ʨ | C16: {=INDEX(聲母對照表[十五音], MATCH(TRUE, EXACT(【聲】聲母排序表!$D16, 聲母對照表[方音符號]),0))} -> 曾 | D16: ㄐ | E16: {=INDEX(聲母對照表[台語注音], MATCH(TRUE, EXACT(【聲】聲母排序表!$D16, 聲母對照表[方音符號]),0))} -> ㄐ | F16: {=INDEX(聲母對照表[注音二式], MATCH(TRUE, EXACT(【聲】聲母排序表!$D16, 聲母對照表[方音符號]),0))} -> j | G16: {=INDEX(聲母對照表[閩拼方案], MATCH(TRUE, EXACT(【聲】聲母排序表!$D16, 聲母對照表[方音符號]),0))} -> zi | H16: {=INDEX(聲母對照表[台羅拼音], MATCH(TRUE, EXACT(【聲】聲母排序表!$D16, 聲母對照表[方音符號]),0))} -> tsi | I16: {=INDEX(聲母對照表[台語音標], MATCH(TRUE, EXACT(【聲】聲母排序表!$D16, 聲母對照表[方音符號]),0))} -> zi | J16: {=INDEX(聲母對照表[白話字], MATCH(TRUE, EXACT(【聲】聲母排序表!$D16, 聲母對照表[方音符號]),0))} -> chi | K16: ㄐ = ㄗㄧ
A17: 16 | B17: {=INDEX(聲母對照表[國際音標], MATCH(TRUE, EXACT(【聲】聲母排序表!$D17, 聲母對照表[方音符號]),0))} -> ʥ | C17: {=INDEX(聲母對照表[十五音], MATCH(TRUE, EXACT(【聲】聲母排序表!$D17, 聲母對照表[方音符號]),0))} -> 入 | D17: ㆢ | E17: {=INDEX(聲母對照表[台語注音], MATCH(TRUE, EXACT(【聲】聲母排序表!$D17, 聲母對照表[方音符號]),0))} -> ㄖ | F17: {=INDEX(聲母對照表[注音二式], MATCH(TRUE, EXACT(【聲】聲母排序表!$D17, 聲母對照表[方音符號]),0))} -> jj | G17: {=INDEX(聲母對照表[閩拼方案], MATCH(TRUE, EXACT(【聲】聲母排序表!$D17, 聲母對照表[方音符號]),0))} -> zzi | H17: {=INDEX(聲母對照表[台羅拼音], MATCH(TRUE, EXACT(【聲】聲母排序表!$D17, 聲母對照表[方音符號]),0))} -> ji | I17: {=INDEX(聲母對照表[台語音標], MATCH(TRUE, EXACT(【聲】聲母排序表!$D17, 聲母對照表[方音符號]),0))} -> ji | J17: {=INDEX(聲母對照表[白話字], MATCH(TRUE, EXACT(【聲】聲母排序表!$D17, 聲母對照表[方音符號]),0))} -> ji | K17: ㆢ = ㆡㄧ
A18: 17 | B18: {=INDEX(聲母對照表[國際音標], MATCH(TRUE, EXACT(【聲】聲母排序表!$D18, 聲母對照表[方音符號]),0))} -> ʨʰ | C18: {=INDEX(聲母對照表[十五音], MATCH(TRUE, EXACT(【聲】聲母排序表!$D18, 聲母對照表[方音符號]),0))} -> 出 | D18: ㄑ | E18: {=INDEX(聲母對照表[台語注音], MATCH(TRUE, EXACT(【聲】聲母排序表!$D18, 聲母對照表[方音符號]),0))} -> ㄑ | F18: {=INDEX(聲母對照表[注音二式], MATCH(TRUE, EXACT(【聲】聲母排序表!$D18, 聲母對照表[方音符號]),0))} -> ch | G18: {=INDEX(聲母對照表[閩拼方案], MATCH(TRUE, EXACT(【聲】聲母排序表!$D18, 聲母對照表[方音符號]),0))} -> ci | H18: {=INDEX(聲母對照表[台羅拼音], MATCH(TRUE, EXACT(【聲】聲母排序表!$D18, 聲母對照表[方音符號]),0))} -> tshi | I18: {=INDEX(聲母對照表[台語音標], MATCH(TRUE, EXACT(【聲】聲母排序表!$D18, 聲母對照表[方音符號]),0))} -> ci | J18: {=INDEX(聲母對照表[白話字], MATCH(TRUE, EXACT(【聲】聲母排序表!$D18, 聲母對照表[方音符號]),0))} -> chhi | K18: ㄑ = ㄘㄧ
A19: 18 | B19: {=INDEX(聲母對照表[國際音標], MATCH(TRUE, EXACT(【聲】聲母排序表!$D19, 聲母對照表[方音符號]),0))} -> ɕ | C19: {=INDEX(聲母對照表[十五音], MATCH(TRUE, EXACT(【聲】聲母排序表!$D19, 聲母對照表[方音符號]),0))} -> 時 | D19: ㄒ | E19: {=INDEX(聲母對照表[台語注音], MATCH(TRUE, EXACT(【聲】聲母排序表!$D19, 聲母對照表[方音符號]),0))} -> ㄒ | F19: {=INDEX(聲母對照表[注音二式], MATCH(TRUE, EXACT(【聲】聲母排序表!$D19, 聲母對照表[方音符號]),0))} -> sh | G19: {=INDEX(聲母對照表[閩拼方案], MATCH(TRUE, EXACT(【聲】聲母排序表!$D19, 聲母對照表[方音符號]),0))} -> si | H19: {=INDEX(聲母對照表[台羅拼音], MATCH(TRUE, EXACT(【聲】聲母排序表!$D19, 聲母對照表[方音符號]),0))} -> si | I19: {=INDEX(聲母對照表[台語音標], MATCH(TRUE, EXACT(【聲】聲母排序表!$D19, 聲母對照表[方音符號]),0))} -> si | J19: {=INDEX(聲母對照表[白話字], MATCH(TRUE, EXACT(【聲】聲母排序表!$D19, 聲母對照表[方音符號]),0))} -> si | K19: ㄒ = ㄙㄧ
A20: 19 | B20: {=INDEX(聲母對照表[國際音標], MATCH(TRUE, EXACT(【聲】聲母排序表!$D20, 聲母對照表[方音符號]),0))} -> ʦ | C20: {=INDEX(聲母對照表[十五音], MATCH(TRUE, EXACT(【聲】聲母排序表!$D20, 聲母對照表[方音符號]),0))} -> 曾 | D20: ㄗ | E20: {=INDEX(聲母對照表[台語注音], MATCH(TRUE, EXACT(【聲】聲母排序表!$D20, 聲母對照表[方音符號]),0))} -> ㄗ | F20: {=INDEX(聲母對照表[注音二式], MATCH(TRUE, EXACT(【聲】聲母排序表!$D20, 聲母對照表[方音符號]),0))} -> z | G20: {=INDEX(聲母對照表[閩拼方案], MATCH(TRUE, EXACT(【聲】聲母排序表!$D20, 聲母對照表[方音符號]),0))} -> z | H20: {=INDEX(聲母對照表[台羅拼音], MATCH(TRUE, EXACT(【聲】聲母排序表!$D20, 聲母對照表[方音符號]),0))} -> ts | I20: {=INDEX(聲母對照表[台語音標], MATCH(TRUE, EXACT(【聲】聲母排序表!$D20, 聲母對照表[方音符號]),0))} -> z | J20: {=INDEX(聲母對照表[白話字], MATCH(TRUE, EXACT(【聲】聲母排序表!$D20, 聲母對照表[方音符號]),0))} -> ch
A21: 20 | B21: {=INDEX(聲母對照表[國際音標], MATCH(TRUE, EXACT(【聲】聲母排序表!$D21, 聲母對照表[方音符號]),0))} -> ʣ | C21: {=INDEX(聲母對照表[十五音], MATCH(TRUE, EXACT(【聲】聲母排序表!$D21, 聲母對照表[方音符號]),0))} -> 入 | D21: ㆡ | E21: {=INDEX(聲母對照表[台語注音], MATCH(TRUE, EXACT(【聲】聲母排序表!$D21, 聲母對照表[方音符號]),0))} -> ㄖ | F21: {=INDEX(聲母對照表[注音二式], MATCH(TRUE, EXACT(【聲】聲母排序表!$D21, 聲母對照表[方音符號]),0))} -> zz | G21: {=INDEX(聲母對照表[閩拼方案], MATCH(TRUE, EXACT(【聲】聲母排序表!$D21, 聲母對照表[方音符號]),0))} -> zz | H21: {=INDEX(聲母對照表[台羅拼音], MATCH(TRUE, EXACT(【聲】聲母排序表!$D21, 聲母對照表[方音符號]),0))} -> j | I21: {=INDEX(聲母對照表[台語音標], MATCH(TRUE, EXACT(【聲】聲母排序表!$D21, 聲母對照表[方音符號]),0))} -> j | J21: {=INDEX(聲母對照表[白話字], MATCH(TRUE, EXACT(【聲】聲母排序表!$D21, 聲母對照表[方音符號]),0))} -> j
A22: 21 | B22: {=INDEX(聲母對照表[國際音標], MATCH(TRUE, EXACT(【聲】聲母排序表!$D22, 聲母對照表[方音符號]),0))} -> ʦʰ | C22: {=INDEX(聲母對照表[十五音], MATCH(TRUE, EXACT(【聲】聲母排序表!$D22, 聲母對照表[方音符號]),0))} -> 出 | D22: ㄘ | E22: {=INDEX(聲母對照表[台語注音], MATCH(TRUE, EXACT(【聲】聲母排序表!$D22, 聲母對照表[方音符號]),0))} -> ㄘ | F22: {=INDEX(聲母對照表[注音二式], MATCH(TRUE, EXACT(【聲】聲母排序表!$D22, 聲母對照表[方音符號]),0))} -> c | G22: {=INDEX(聲母對照表[閩拼方案], MATCH(TRUE, EXACT(【聲】聲母排序表!$D22, 聲母對照表[方音符號]),0))} -> c | H22: {=INDEX(聲母對照表[台羅拼音], MATCH(TRUE, EXACT(【聲】聲母排序表!$D22, 聲母對照表[方音符號]),0))} -> tsh | I22: {=INDEX(聲母對照表[台語音標], MATCH(TRUE, EXACT(【聲】聲母排序表!$D22, 聲母對照表[方音符號]),0))} -> c | J22: {=INDEX(聲母對照表[白話字], MATCH(TRUE, EXACT(【聲】聲母排序表!$D22, 聲母對照表[方音符號]),0))} -> chh
A23: 22 | B23: {=INDEX(聲母對照表[國際音標], MATCH(TRUE, EXACT(【聲】聲母排序表!$D23, 聲母對照表[方音符號]),0))} -> s | C23: {=INDEX(聲母對照表[十五音], MATCH(TRUE, EXACT(【聲】聲母排序表!$D23, 聲母對照表[方音符號]),0))} -> 時 | D23: ㄙ | E23: {=INDEX(聲母對照表[台語注音], MATCH(TRUE, EXACT(【聲】聲母排序表!$D23, 聲母對照表[方音符號]),0))} -> ㄙ | F23: {=INDEX(聲母對照表[注音二式], MATCH(TRUE, EXACT(【聲】聲母排序表!$D23, 聲母對照表[方音符號]),0))} -> s | G23: {=INDEX(聲母對照表[閩拼方案], MATCH(TRUE, EXACT(【聲】聲母排序表!$D23, 聲母對照表[方音符號]),0))} -> s | H23: {=INDEX(聲母對照表[台羅拼音], MATCH(TRUE, EXACT(【聲】聲母排序表!$D23, 聲母對照表[方音符號]),0))} -> s | I23: {=INDEX(聲母對照表[台語音標], MATCH(TRUE, EXACT(【聲】聲母排序表!$D23, 聲母對照表[方音符號]),0))} -> s | J23: {=INDEX(聲母對照表[白話字], MATCH(TRUE, EXACT(【聲】聲母排序表!$D23, 聲母對照表[方音符號]),0))} -> s

Sheet 【聲】聲母對照表
A1: 識別號 | B1: 國際音標 | C1: 漢字例 | D1: 十五音 | E1: 方音符號 | F1: 台語注音 | G1: 注音二式 | H1: 閩拼方案 | I1: 台羅拼音 | J1: 台語音標 | K1: 白話字 | L1: 備註 | M1: 注音符號序 | N1: 十五音序 | O1: 台羅字母序 | P1: 拼音字母序 | U1: Ø | V1: Ø
A2: 1 | C2: 以 | D2: 英 | L2: Ø | M2: 1 | N2: 11 | O2: 1 | P2: 1 | S2: 1 | T2: ㄅ | U2: l | V2: l
A3: 2 | B3: p | C3: 比 | D3: 邊 | E3: ㄅ | F3: ㄅ | G3: b | H3: b | I3: p | J3: p | K3: p | M3: 2 | N3: 2 | O3: 13 | P3: 2 | S3: 2 | T3: ㆠ | U3: b | V3: b
A4: 3 | B4: b | C4: 美 | D4: 門 | E4: ㆠ | F4: ㄪ | G4: bb | H4: bb | I4: b | J4: b | K4: b | M4: 3 | N4: 12 | O4: 2 | P4: =P3+1 -> 3 | S4: 3 | T4: ㄆ | U4: g | V4: g
A5: 4 | B5: pʰ | C5: 鄙 | D5: 頗 | E5: ㄆ | F5: ㄆ | G5: p | H5: p | I5: ph | J5: ph | K5: ph | M5: 4 | N5: 6 | O5: 14 | P5: =P4+1 -> 4 | S5: 4 | T5: ㄇ | U5: k | V5: k
A6: 5 | B6: m | C6: 毛 | D6: 毛 | E6: ㄇ | F6: ㄇ | G6: m | H6: bbn | I6: m | J6: m | K6: m | L6: b/m 本不分，此處分門/毛 | M6: 5 | N6: 16 | O6: 10 | P6: =P5+1 -> 5 | S6: 5 | T6: ㄉ | U6: d | V6: d
A7: 6 | B7: t | C7: 底 | D7: 地 | E7: ㄉ | F7: ㄉ | G7: d | H7: d | I7: t | J7: t | K7: t | M7: 6 | N7: 5 | O7: 17 | P7: =P6+1 -> 6 | S7: 6 | T7: ㄊ | U7: p | V7: p
A8: 7 | B8: tʰ | C8: 恥 | D8: 他 | E8: ㄊ | F8: ㄊ | G8: t | H8: t | I8: th | J8: th | K8: th | M8: 7 | N8: 7 | O8: 18 | P8: =P7+1 -> 7 | S8: 7 | T8: ㄋ | U8: t | V8: t
A9: 8 | B9: n | C9: 耐 | D9: 耐 | E9: ㄋ | F9: ㄋ | G9: n | H9: ln | I9: n | J9: n | K9: n | L9: l/n 本不分，此處分柳/耐 | M9: 8 | N9: 17 | O9: 11 | P9: =P8+1 -> 8 | S9: 8 | T9: ㄌ | U9: z | V9: z
A10: 9 | B10: l | C10: 理 | D10: 柳 | E10: ㄌ | F10: ㄌ | G10: l | H10: l | I10: l | J10: l | K10: l | M10: 9 | N10: 1 | O10: 9 | P10: =P9+1 -> 9 | S10: 9 | T10: ㄍ | U10: zz | V10: zz
A11: 10 | B11: k | C11: 己 | D11: 求 | E11: ㄍ | F11: ㄍ | G11: g | H11: g | I11: k | J11: k | K11: k | M11: 10 | N11: 3 | O11: 7 | P11: =P10+1 -> 10 | S11: 10 | T11: ㆣ | U11: s | V11: s
A12: 11 | B12: ɡ | C12: 禦 | D12: 語 | E12: ㆣ | F12: ㄫ | G12: gg | H12: gg | I12: g | J12: g | K12: g | M12: 11 | N12: 13 | O12: 3 | P12: =P11+1 -> 11 | S12: 11 | T12: ㄎ | U12: bb | V12: bb
A13: 12 | B13: kʰ | C13: 起 | D13: 去 | E13: ㄎ | F13: ㄎ | G13: k | H13: k | I13: kh | J13: kh | K13: kh | M13: 12 | N13: 4 | O13: 8 | P13: =P12+1 -> 12 | S13: 12 | T13: ㄫ | U13: gg | V13: gg
A14: 13 | B14: ŋ | C14: 雅 | D14: 雅 | E14: ㄫ | F14: ⁰ㄫ | G14: ng | H14: ggn | I14: ng | J14: ng | K14: ng | L14: g/ng 本不分，此處分語/雅 | M14: 13 | N14: 18 | O14: 12 | P14: =P13+1 -> 13 | S14: 13 | T14: ㄏ | U14: c | V14: c
A15: 14 | B15: h | C15: 喜 | D15: 喜 | E15: ㄏ | F15: ㄏ | G15: h | H15: h | I15: h | J15: h | K15: h | M15: 14 | N15: 15 | O15: 4 | P15: =P14+1 -> 14 | S15: 14 | T15: ㄐ | U15: h | V15: h
A16: 15 | B16: ʨ | C16: 止 | D16: 曾 | E16: ㄐ | F16: ㄐ | G16: j | H16: zi | I16: tsi | J16: zi | K16: chi | L16: ㄐ = ㄗㄧ | M16: 15 | N16: 20 | O16: 22 | P16: =P15+1 -> 15 | S16: 15 | T16: ㆢ | U16: m | V16: bbn
A17: 16 | B17: ʥ | C17: 熱 | D17: 入 | E17: ㆢ | F17: ㄖ | G17: jj | H17: zzi | I17: ji | J17: ji | K17: ji | L17: ㆢ = ㆡㄧ | M17: 16 | N17: 19 | O17: 6 | P17: =P16+1 -> 16 | S17: 16 | T17: ㄑ | U17: n | V17: ln
A18: 17 | B18: ʨʰ | C18: 測 | D18: 出 | E18: ㄑ | F18: ㄑ | G18: ch | H18: ci | I18: tshi | J18: ci | K18: chhi | L18: ㄑ = ㄘㄧ | M18: 17 | N18: 21 | O18: 21 | P18: =P17+1 -> 17 | S18: 17 | T18: ㄒ | U18: ng | V18: ggn
A19: 18 | B19: ɕ | C19: 惜 | D19: 時 | E19: ㄒ | F19: ㄒ | G19: sh | H19: si | I19: si | J19: si | K19: si | L19: ㄒ = ㄙㄧ | M19: 18 | N19: 22 | O19: 16 | P19: =P18+1 -> 18 | S19: 18 | T19: ㄗ | U19: jji | V19: zzi
A20: 19 | B20: ʦ | C20: 阻 | D20: 曾 | E20: ㄗ | F20: ㄗ | G20: z | H20: z | I20: ts | J20: z | K20: ch | M20: 19 | N20: 8 | O20: 19 | P20: =P19+1 -> 19 | S20: 19 | T20: ㆡ | U20: ji | V20: zi
A21: 20 | B21: ʣ | C21: 熱 | D21: 入 | E21: ㆡ | F21: ㄖ | G21: zz | H21: zz | I21: j | J21: j | K21: j | M21: 20 | N21: 9 | O21: 5 | P21: =P20+1 -> 20 | S21: 20 | T21: ㄘ | U21: chi | V21: ci
A22: 21 | B22: ʦʰ | C22: 取 | D22: 出 | E22: ㄘ | F22: ㄘ | G22: c | H22: c | I22: tsh | J22: c | K22: chh | M22: 21 | N22: 14 | O22: 20 | P22: =P21+1 -> 21 | S22: 21 | T22: ㄙ | U22: shi | V22: si
A23: 22 | B23: s | C23: 詞 | D23: 時 | E23: ㄙ | F23: ㄙ | G23: s | H23: s | I23: s | J23: s | K23: s | M23: 22 | N23: 10 | O23: 15 | P23: =P22+1 -> 22

Sheet 【韻】韻母對照表
A2: 序號 | B2: 國際音標 | C2: 漢字例 | D2: 十五音 | E2: 十五音識別碼 | F2: 方音符號 | G2: 台語注音 | H2: 台語注音二式 | I2: 閩拼方案 | J2: 台羅拼音 | K2: 台語音標 | L2: 白話字 | M2: 聲韻調類 | N2: 字長 | P2: 台羅拼音 | Q2: 台語音標 | S2: 台羅拼音 | T2: 標調字母 | U2: search() | V2: 台語音標 | AB2: U+0301 | AC2: U+0300 | AE2: U+030C | AF2: U+0301 | AG2: U+0304 | AH2: U+030D | AI2: U+030B | AJ2: U+030A
A3: =ROW() - 3 -> 0 | B3: a | C3: 些 | D3: =LEFT(韻母表[[#This Row],[十五音識別碼]],1) -> 膠 | E3: 膠（舒） | F3: ㄚ | G3: ㄚ | H3: a | I3: a | J3: a | K3: a | L3: a | N3: =LEN(K3) -> 1 | P3: =J3 -> a | Q3: =K3 -> a | S3: =_xlfn.CONCAT(P3, "(\d)") -> a(\d) | T3: a | U3: =IFERROR( IF(T3="", "", SEARCH(T3, $P3)), "") -> 1 | V3: =IFERROR( _xlfn.CONCAT(LEFT(P3,U3-1), "》", MID(P3,U3,1), "${1}", RIGHT(P3, LEN(P3)-U3)), "" ) -> 》a${1} | X3: =IF(AND(Q3<>"", P3<>""), " - xform/》" & S3 & "/" & V3 & "/", "") -> - xform/》a(\d)/》a${1}/ | Z3: a | AA3: =_xlfn.CONCAT($Z3, IF(AA$2="", "", _xlfn.UNICHAR( HEX2DEC( RIGHT(AA$2,4))))) -> a | AB3: =_xlfn.CONCAT($Z3, IF(AB$2="", "", _xlfn.UNICHAR( HEX2DEC( RIGHT(AB$2,4))))) -> á | AC3: =_xlfn.CONCAT($Z3, IF(AC$2="", "", _xlfn.UNICHAR( HEX2DEC( RIGHT(AC$2,4))))) -> à | AD3: =_xlfn.CONCAT($Z3, IF(AD$2="", "", _xlfn.UNICHAR( HEX2DEC( RIGHT(AD$2,4))))) -> a | AE3: =_xlfn.CONCAT($Z3, IF(AE$2="", "", _xlfn.UNICHAR( HEX2DEC( RIGHT(AE$2,4))))) -> ǎ | AF3: =_xlfn.CONCAT($Z3, IF(AF$2="", "", _xlfn.UNICHAR( HEX2DEC( RIGHT(AF$2,4))))) -> á | AG3: =_xlfn.CONCAT($Z3, IF(AG$2="", "", _xlfn.UNICHAR( HEX2DEC( RIGHT(AG$2,4))))) -> ā | AH3: =_xlfn.CONCAT($Z3, IF(AH$2="", "", _xlfn.UNICHAR( HEX2DEC( RIGHT(AH$2,4))))) -> a̍ | ... AJ3: =_xlfn.CONCAT($Z3, IF(AJ$2="", "", _xlfn.UNICHAR( HEX2DEC( RIGHT(AJ$2,4))))) -> å | AL3: =_xlfn.CONCAT(" - xform/》", $Z3, [5]【調】韻母標調!AJ$1, "/", AA3, "/") -> - xform/》a1/a/ | AM3: =_xlfn.CONCAT(" - xform/》", $Z3, [5]【調】韻母標調!AK$1, "/", AB3, "/") -> - xform/》a2/á/ | AN3: =_xlfn.CONCAT(" - xform/》", $Z3, [5]【調】韻母標調!AL$1, "/", AC3, "/") -> - xform/》a3/à/ | AO3: =_xlfn.CONCAT(" - xform/》", $Z3, [5]【調】韻母標調!AM$1, "/", AD3, "/") -> - xform/》a4/a/ | AP3: =_xlfn.CONCAT(" - xform/》", $Z3, [5]【調】韻母標調!AN$1, "/", AE3, "/") -> - xform/》a5/ǎ/ | AQ3: =_xlfn.CONCAT(" - xform/》", $Z3, [5]【調】韻母標調!AO$1, "/", AF3, "/") -> - xform/》a6/á/ | AR3: =_xlfn.CONCAT(" - xform/》", $Z3, [5]【調】韻母標調!AP$1, "/", AG3, "/") -> - xform/》a7/ā/ | AS3: =_xlfn.CONCAT(" - xform/》", $Z3, [5]【調】韻母標調!AQ$1, "/", AH3, "/") -> - xform/》a8/a̍/ | ... AU3: =_xlfn.CONCAT(" - xform/》", $Z3, [5]【調】韻母標調!AS$1, "/", AJ3, "/") -> - xform/》a9/å/
A4: =ROW() - 3 -> 1 | B4: aʔ | C4: 百 | D4: =LEFT(韻母表[[#This Row],[十五音識別碼]],1) -> 膠 | E4: 膠（促） | F4: ㄚㆷ | G4: ㄚㄏ | H4: ah | I4: ah | J4: ah | K4: ah | L4: ah | N4: =LEN(K4) -> 2 | P4: =J4 -> ah | Q4: =K4 -> ah | S4: =_xlfn.CONCAT(P4, "(\d)") -> ah(\d) | T4: a | U4: =IFERROR( IF(T4="", "", SEARCH(T4, $P4)), "") -> 1 | V4: =IFERROR( _xlfn.CONCAT(LEFT(P4,U4-1), "》", MID(P4,U4,1), "${1}", RIGHT(P4, LEN(P4)-U4)), "" ) -> 》a${1}h | X4: =IF(AND(Q4<>"", P4<>""), " - xform/》" & S4 & "/" & V4 & "/", "") -> - xform/》ah(\d)/》a${1}h/ | Z4: u | AA4: =_xlfn.CONCAT($Z4, IF(AA$2="", "", _xlfn.UNICHAR( HEX2DEC( RIGHT(AA$2,4))))) -> u | AB4: =_xlfn.CONCAT($Z4, IF(AB$2="", "", _xlfn.UNICHAR( HEX2DEC( RIGHT(AB$2,4))))) -> ú | AC4: =_xlfn.CONCAT($Z4, IF(AC$2="", "", _xlfn.UNICHAR( HEX2DEC( RIGHT(AC$2,4))))) -> ù | AD4: =_xlfn.CONCAT($Z4, IF(AD$2="", "", _xlfn.UNICHAR( HEX2DEC( RIGHT(AD$2,4))))) -> u | AE4: =_xlfn.CONCAT($Z4, IF(AE$2="", "", _xlfn.UNICHAR( HEX2DEC( RIGHT(AE$2,4))))) -> ǔ | AF4: =_xlfn.CONCAT($Z4, IF(AF$2="", "", _xlfn.UNICHAR( HEX2DEC( RIGHT(AF$2,4))))) -> ú | AG4: =_xlfn.CONCAT($Z4, IF(AG$2="", "", _xlfn.UNICHAR( HEX2DEC( RIGHT(AG$2,4))))) -> ū | AH4: =_xlfn.CONCAT($Z4, IF(AH$2="", "", _xlfn.UNICHAR( HEX2DEC( RIGHT(AH$2,4))))) -> u̍ | ... AJ4: =_xlfn.CONCAT($Z4, IF(AJ$2="", "", _xlfn.UNICHAR( HEX2DEC( RIGHT(AJ$2,4))))) -> ů | AL4: =_xlfn.CONCAT(" - xform/》", $Z4, [5]【調】韻母標調!AJ$1, "/", AA4, "/") -> - xform/》u1/u/ | AM4: =_xlfn.CONCAT(" - xform/》", $Z4, [5]【調】韻母標調!AK$1, "/", AB4, "/") -> - xform/》u2/ú/ | AN4: =_xlfn.CONCAT(" - xform/》", $Z4, [5]【調】韻母標調!AL$1, "/", AC4, "/") -> - xform/》u3/ù/ | AO4: =_xlfn.CONCAT(" - xform/》", $Z4, [5]【調】韻母標調!AM$1, "/", AD4, "/") -> - xform/》u4/u/ | AP4: =_xlfn.CONCAT(" - xform/》", $Z4, [5]【調】韻母標調!AN$1, "/", AE4, "/") -> - xform/》u5/ǔ/ | AQ4: =_xlfn.CONCAT(" - xform/》", $Z4, [5]【調】韻母標調!AO$1, "/", AF4, "/") -> - xform/》u6/ú/ | AR4: =_xlfn.CONCAT(" - xform/》", $Z4, [5]【調】韻母標調!AP$1, "/", AG4, "/") -> - xform/》u7/ū/ | AS4: =_xlfn.CONCAT(" - xform/》", $Z4, [5]【調】韻母標調!AQ$1, "/", AH4, "/") -> - xform/》u8/u̍/ | ... AU4: =_xlfn.CONCAT(" - xform/》", $Z4, [5]【調】韻母標調!AS$1, "/", AJ4, "/") -> - xform/》u9/ů/
A5: =ROW() - 3 -> 2 | B5: aɪ | C5: 埃 | D5: =LEFT(韻母表[[#This Row],[十五音識別碼]],1) -> 皆 | E5: 皆（舒） | F5: ㄞ | G5: ㄞ | H5: ai | I5: ai | J5: ai | K5: ai | L5: ai | N5: =LEN(K5) -> 2 | P5: =J5 -> ai | Q5: =K5 -> ai | S5: =_xlfn.CONCAT(P5, "(\d)") -> ai(\d) | T5: o | U5: =IFERROR( IF(T5="", "", SEARCH(T5, $P5)), "") | V5: =IFERROR( _xlfn.CONCAT(LEFT(P5,U5-1), "》", MID(P5,U5,1), "${1}", RIGHT(P5, LEN(P5)-U5)), "" ) | X5: =IF(AND(Q5<>"", P5<>""), " - xform/》" & S5 & "/" & V5 & "/", "") -> - xform/》ai(\d)//
A6: =ROW() - 3 -> 3 | B6: aɪʔ | C6: ◯ | D6: =LEFT(韻母表[[#This Row],[十五音識別碼]],1) -> 皆 | E6: 皆（促） | F6: ㄞㆷ | G6: ㄞㄏ | H6: aih | I6: aih | J6: aih | K6: aih | L6: aih | N6: =LEN(K6) -> 3 | P6: =J6 -> aih | Q6: =K6 -> aih | S6: =_xlfn.CONCAT(P6, "(\d)") -> aih(\d) | T6: a | U6: =IFERROR( IF(T6="", "", SEARCH(T6, $P6)), "") -> 1 | V6: =IFERROR( _xlfn.CONCAT(LEFT(P6,U6-1), "》", MID(P6,U6,1), "${1}", RIGHT(P6, LEN(P6)-U6)), "" ) -> 》a${1}ih | X6: =IF(AND(Q6<>"", P6<>""), " - xform/》" & S6 & "/" & V6 & "/", "") -> - xform/》aih(\d)/》a${1}ih/
A7: =ROW() - 3 -> 4 | B7: ãɪ | C7: 挨 | D7: =LEFT(韻母表[[#This Row],[十五音識別碼]],1) -> 閒 | E7: 閒（舒） | F7: ㆮ | G7: ⁰ㄞ | H7: ainn | I7: nai | J7: ainn | K7: ainn | L7: aiⁿ | M7: 韻-鼻 | N7: =LEN(K7) -> 4 | P7: =J7 -> ainn | Q7: =K7 -> ainn | S7: =_xlfn.CONCAT(P7, "(\d)") -> ainn(\d) | T7: a | U7: =IFERROR( IF(T7="", "", SEARCH(T7, $P7)), "") -> 1 | V7: =IFERROR( _xlfn.CONCAT(LEFT(P7,U7-1), "》", MID(P7,U7,1), "${1}", RIGHT(P7, LEN(P7)-U7)), "" ) -> 》a${1}inn | X7: =IF(AND(Q7<>"", P7<>""), " - xform/》" & S7 & "/" & V7 & "/", "") -> - xform/》ainn(\d)/》a${1}inn/
A8: =ROW() - 3 -> 5 | B8: =_xlfn.CONCAT("a","k",_xlfn.UNICHAR(794)) -> ak̚ | C8: 角 | D8: =LEFT(韻母表[[#This Row],[十五音識別碼]],1) -> 江 | E8: 江（促） | F8: ㄚㆻ | G8: ㄚㄍ | H8: ak | I8: ak | J8: ak | K8: ak | L8: ak | N8: =LEN(K8) -> 2 | P8: =J8 -> ak | Q8: =K8 -> ak | S8: =_xlfn.CONCAT(P8, "(\d)") -> ak(\d) | T8: e | U8: =IFERROR( IF(T8="", "", SEARCH(T8, $P8)), "") | V8: =IFERROR( _xlfn.CONCAT(LEFT(P8,U8-1), "》", MID(P8,U8,1), "${1}", RIGHT(P8, LEN(P8)-U8)), "" ) | X8: =IF(AND(Q8<>"", P8<>""), " - xform/》" & S8 & "/" & V8 & "/", "") -> - xform/》ak(\d)//
A9: =ROW() - 3 -> 6 | B9: am | C9: 堪 | D9: =LEFT(韻母表[[#This Row],[十五音識別碼]],1) -> 甘 | E9: 甘（舒） | F9: ㆰ | G9: ㄚㄇ | H9: am | I9: am | J9: am | K9: am | L9: am | N9: =LEN(K9) -> 2 | P9: =J9 -> am | Q9: =K9 -> am | S9: =_xlfn.CONCAT(P9, "(\d)") -> am(\d) | T9: a | U9: =IFERROR( IF(T9="", "", SEARCH(T9, $P9)), "") -> 1 | V9: =IFERROR( _xlfn.CONCAT(LEFT(P9,U9-1), "》", MID(P9,U9,1), "${1}", RIGHT(P9, LEN(P9)-U9)), "" ) -> 》a${1}m | X9: =IF(AND(Q9<>"", P9<>""), " - xform/》" & S9 & "/" & V9 & "/", "") -> - xform/》am(\d)/》a${1}m/ | Z9: o | AA9: =_xlfn.CONCAT($Z9, IF(AA$2="", "", _xlfn.UNICHAR( HEX2DEC( RIGHT(AA$2,4))))) -> o | AB9: =_xlfn.CONCAT($Z9, IF(AB$2="", "", _xlfn.UNICHAR( HEX2DEC( RIGHT(AB$2,4))))) -> ó | AC9: =_xlfn.CONCAT($Z9, IF(AC$2="", "", _xlfn.UNICHAR( HEX2DEC( RIGHT(AC$2,4))))) -> ò | AD9: =_xlfn.CONCAT($Z9, IF(AD$2="", "", _xlfn.UNICHAR( HEX2DEC( RIGHT(AD$2,4))))) -> o | AE9: =_xlfn.CONCAT($Z9, IF(AE$2="", "", _xlfn.UNICHAR( HEX2DEC( RIGHT(AE$2,4))))) -> ǒ | AF9: =_xlfn.CONCAT($Z9, IF(AF$2="", "", _xlfn.UNICHAR( HEX2DEC( RIGHT(AF$2,4))))) -> ó | AG9: =_xlfn.CONCAT($Z9, IF(AG$2="", "", _xlfn.UNICHAR( HEX2DEC( RIGHT(AG$2,4))))) -> ō | AH9: =_xlfn.CONCAT($Z9, IF(AH$2="", "", _xlfn.UNICHAR( HEX2DEC( RIGHT(AH$2,4))))) -> o̍ | ... AJ9: =_xlfn.CONCAT($Z9, IF(AJ$2="", "", _xlfn.UNICHAR( HEX2DEC( RIGHT(AJ$2,4))))) -> o̊ | AL9: =_xlfn.CONCAT(" - xform/》", $Z9, [5]【調】韻母標調!AJ$1, "/", AA9, "/") -> - xform/》o1/o/ | AM9: =_xlfn.CONCAT(" - xform/》", $Z9, [5]【調】韻母標調!AK$1, "/", AB9, "/") -> - xform/》o2/ó/ | AN9: =_xlfn.CONCAT(" - xform/》", $Z9, [5]【調】韻母標調!AL$1, "/", AC9, "/") -> - xform/》o3/ò/ | AO9: =_xlfn.CONCAT(" - xform/》", $Z9, [5]【調】韻母標調!AM$1, "/", AD9, "/") -> - xform/》o4/o/ | AP9: =_xlfn.CONCAT(" - xform/》", $Z9, [5]【調】韻母標調!AN$1, "/", AE9, "/") -> - xform/》o5/ǒ/ | AQ9: =_xlfn.CONCAT(" - xform/》", $Z9, [5]【調】韻母標調!AO$1, "/", AF9, "/") -> - xform/》o6/ó/ | AR9: =_xlfn.CONCAT(" - xform/》", $Z9, [5]【調】韻母標調!AP$1, "/", AG9, "/") -> - xform/》o7/ō/ | AS9: =_xlfn.CONCAT(" - xform/》", $Z9, [5]【調】韻母標調!AQ$1, "/", AH9, "/") -> - xform/》o8/o̍/ | ... AU9: =_xlfn.CONCAT(" - xform/》", $Z9, [5]【調】韻母標調!AS$1, "/", AJ9, "/") -> - xform/》o9/o̊/
A10: =ROW() - 3 -> 7 | B10: an | C10: 蘭 | D10: =LEFT(韻母表[[#This Row],[十五音識別碼]],1) -> 干 | E10: 干（舒） | F10: ㄢ | G10: ㄢ | H10: an | I10: an | J10: an | K10: an | L10: an | N10: =LEN(K10) -> 2 | P10: =J10 -> an | Q10: =K10 -> an | S10: =_xlfn.CONCAT(P10, "(\d)") -> an(\d) | T10: a | U10: =IFERROR( IF(T10="", "", SEARCH(T10, $P10)), "") -> 1 | V10: =IFERROR( _xlfn.CONCAT(LEFT(P10,U10-1), "》", MID(P10,U10,1), "${1}", RIGHT(P10, LEN(P10)-U10)), "" ) -> 》a${1}n | X10: =IF(AND(Q10<>"", P10<>""), " - xform/》" & S10 & "/" & V10 & "/", "") -> - xform/》an(\d)/》a${1}n/ | Z10: m | AA10: =_xlfn.CONCAT($Z10, IF(AA$2="", "", _xlfn.UNICHAR( HEX2DEC( RIGHT(AA$2,4))))) -> m | AB10: =_xlfn.CONCAT($Z10, IF(AB$2="", "", _xlfn.UNICHAR( HEX2DEC( RIGHT(AB$2,4))))) -> ḿ | AC10: =_xlfn.CONCAT($Z10, IF(AC$2="", "", _xlfn.UNICHAR( HEX2DEC( RIGHT(AC$2,4))))) -> m̀ | AD10: =_xlfn.CONCAT($Z10, IF(AD$2="", "", _xlfn.UNICHAR( HEX2DEC( RIGHT(AD$2,4))))) -> m | AE10: =_xlfn.CONCAT($Z10, IF(AE$2="", "", _xlfn.UNICHAR( HEX2DEC( RIGHT(AE$2,4))))) -> m̌ | AF10: =_xlfn.CONCAT($Z10, IF(AF$2="", "", _xlfn.UNICHAR( HEX2DEC( RIGHT(AF$2,4))))) -> ḿ | AG10: =_xlfn.CONCAT($Z10, IF(AG$2="", "", _xlfn.UNICHAR( HEX2DEC( RIGHT(AG$2,4))))) -> m̄ | AH10: =_xlfn.CONCAT($Z10, IF(AH$2="", "", _xlfn.UNICHAR( HEX2DEC( RIGHT(AH$2,4))))) -> m̍ | ... AJ10: =_xlfn.CONCAT($Z10, IF(AJ$2="", "", _xlfn.UNICHAR( HEX2DEC( RIGHT(AJ$2,4))))) -> m̊ | AL10: =_xlfn.CONCAT(" - xform/》", $Z10, [5]【調】韻母標調!AJ$1, "/", AA10, "/") -> - xform/》m1/m/ | AM10: =_xlfn.CONCAT(" - xform/》", $Z10, [5]【調】韻母標調!AK$1, "/", AB10, "/") -> - xform/》m2/ḿ/ | AN10: =_xlfn.CONCAT(" - xform/》", $Z10, [5]【調】韻母標調!AL$1, "/", AC10, "/") -> - xform/》m3/m̀/ | AO10: =_xlfn.CONCAT(" - xform/》", $Z10, [5]【調】韻母標調!AM$1, "/", AD10, "/") -> - xform/》m4/m/ | AP10: =_xlfn.CONCAT(" - xform/》", $Z10, [5]【調】韻母標調!AN$1, "/", AE10, "/") -> - xform/》m5/m̌/ | AQ10: =_xlfn.CONCAT(" - xform/》", $Z10, [5]【調】韻母標調!AO$1, "/", AF10, "/") -> - xform/》m6/ḿ/ | AR10: =_xlfn.CONCAT(" - xform/》", $Z10, [5]【調】韻母標調!AP$1, "/", AG10, "/") -> - xform/》m7/m̄/ | AS10: =_xlfn.CONCAT(" - xform/》", $Z10, [5]【調】韻母標調!AQ$1, "/", AH10, "/") -> - xform/》m8/m̍/ | ... AU10: =_xlfn.CONCAT(" - xform/》", $Z10, [5]【調】韻母標調!AS$1, "/", AJ10, "/") -> - xform/》m9/m̊/
A11: =ROW() - 3 -> 8 | B11: aŋ | C11: 邦 | D11: =LEFT(韻母表[[#This Row],[十五音識別碼]],1) -> 江 | E11: 江（舒） | F11: ㄤ | G11: ㄤ | H11: ang | I11: ang | J11: ang | K11: ang | L11: ang | N11: =LEN(K11) -> 3 | P11: =J11 -> ang | Q11: =K11 -> ang | S11: =_xlfn.CONCAT(P11, "(\d)") -> ang(\d) | T11: a | U11: =IFERROR( IF(T11="", "", SEARCH(T11, $P11)), "") -> 1 | V11: =IFERROR( _xlfn.CONCAT(LEFT(P11,U11-1), "》", MID(P11,U11,1), "${1}", RIGHT(P11, LEN(P11)-U11)), "" ) -> 》a${1}ng | X11: =IF(AND(Q11<>"", P11<>""), " - xform/》" & S11 & "/" & V11 & "/", "") -> - xform/》ang(\d)/》a${1}ng/ | Z11: n | AA11: =_xlfn.CONCAT($Z11, IF(AA$2="", "", _xlfn.UNICHAR( HEX2DEC( RIGHT(AA$2,4))))) -> n | AB11: =_xlfn.CONCAT($Z11, IF(AB$2="", "", _xlfn.UNICHAR( HEX2DEC( RIGHT(AB$2,4))))) -> ń | AC11: =_xlfn.CONCAT($Z11, IF(AC$2="", "", _xlfn.UNICHAR( HEX2DEC( RIGHT(AC$2,4))))) -> ǹ | AD11: =_xlfn.CONCAT($Z11, IF(AD$2="", "", _xlfn.UNICHAR( HEX2DEC( RIGHT(AD$2,4))))) -> n | AE11: =_xlfn.CONCAT($Z11, IF(AE$2="", "", _xlfn.UNICHAR( HEX2DEC( RIGHT(AE$2,4))))) -> ň | AF11: =_xlfn.CONCAT($Z11, IF(AF$2="", "", _xlfn.UNICHAR( HEX2DEC( RIGHT(AF$2,4))))) -> ń | AG11: =_xlfn.CONCAT($Z11, IF(AG$2="", "", _xlfn.UNICHAR( HEX2DEC( RIGHT(AG$2,4))))) -> n̄ | AH11: =_xlfn.CONCAT($Z11, IF(AH$2="", "", _xlfn.UNICHAR( HEX2DEC( RIGHT(AH$2,4))))) -> n̍ | ... AJ11: =_xlfn.CONCAT($Z11, IF(AJ$2="", "", _xlfn.UNICHAR( HEX2DEC( RIGHT(AJ$2,4))))) -> n̊ | AL11: =_xlfn.CONCAT(" - xform/》", $Z11, [5]【調】韻母標調!AJ$1, "/", AA11, "/") -> - xform/》n1/n/ | AM11: =_xlfn.CONCAT(" - xform/》", $Z11, [5]【調】韻母標調!AK$1, "/", AB11, "/") -> - xform/》n2/ń/ | AN11: =_xlfn.CONCAT(" - xform/》", $Z11, [5]【調】韻母標調!AL$1, "/", AC11, "/") -> - xform/》n3/ǹ/ | AO11: =_xlfn.CONCAT(" - xform/》", $Z11, [5]【調】韻母標調!AM$1, "/", AD11, "/") -> - xform/》n4/n/ | AP11: =_xlfn.CONCAT(" - xform/》", $Z11, [5]【調】韻母標調!AN$1, "/", AE11, "/") -> - xform/》n5/ň/ | AQ11: =_xlfn.CONCAT(" - xform/》", $Z11, [5]【調】韻母標調!AO$1, "/", AF11, "/") -> - xform/》n6/ń/ | AR11: =_xlfn.CONCAT(" - xform/》", $Z11, [5]【調】韻母標調!AP$1, "/", AG11, "/") -> - xform/》n7/n̄/ | AS11: =_xlfn.CONCAT(" - xform/》", $Z11, [5]【調】韻母標調!AQ$1, "/", AH11, "/") -> - xform/》n8/n̍/ | ... AU11: =_xlfn.CONCAT(" - xform/》", $Z11, [5]【調】韻母標調!AS$1, "/", AJ11, "/") -> - xform/》n9/n̊/
A12: =ROW() - 3 -> 9 | B12: ã | C12: 聽 | D12: =LEFT(韻母表[[#This Row],[十五音識別碼]],1) -> 監 | E12: 監（舒） | F12: ㆩ | G12: ⁰ㄚ | H12: ann | I12: na | J12: ann | K12: ann | L12: aⁿ | M12: 韻-鼻 | N12: =LEN(K12) -> 3 | P12: =J12 -> ann | Q12: =K12 -> ann | S12: =_xlfn.CONCAT(P12, "(\d)") -> ann(\d) | T12: a | U12: =IFERROR( IF(T12="", "", SEARCH(T12, $P12)), "") -> 1 | V12: =IFERROR( _xlfn.CONCAT(LEFT(P12,U12-1), "》", MID(P12,U12,1), "${1}", RIGHT(P12, LEN(P12)-U12)), "" ) -> 》a${1}nn | X12: =IF(AND(Q12<>"", P12<>""), " - xform/》" & S12 & "/" & V12 & "/", "") -> - xform/》ann(\d)/》a${1}nn/ | Z12: i | AA12: =_xlfn.CONCAT($Z12, IF(AA$2="", "", _xlfn.UNICHAR( HEX2DEC( RIGHT(AA$2,4))))) -> i | AB12: =_xlfn.CONCAT($Z12, IF(AB$2="", "", _xlfn.UNICHAR( HEX2DEC( RIGHT(AB$2,4))))) -> í | AC12: =_xlfn.CONCAT($Z12, IF(AC$2="", "", _xlfn.UNICHAR( HEX2DEC( RIGHT(AC$2,4))))) -> ì | AD12: =_xlfn.CONCAT($Z12, IF(AD$2="", "", _xlfn.UNICHAR( HEX2DEC( RIGHT(AD$2,4))))) -> i | AE12: =_xlfn.CONCAT($Z12, IF(AE$2="", "", _xlfn.UNICHAR( HEX2DEC( RIGHT(AE$2,4))))) -> ǐ | AF12: =_xlfn.CONCAT($Z12, IF(AF$2="", "", _xlfn.UNICHAR( HEX2DEC( RIGHT(AF$2,4))))) -> í | AG12: =_xlfn.CONCAT($Z12, IF(AG$2="", "", _xlfn.UNICHAR( HEX2DEC( RIGHT(AG$2,4))))) -> ī | AH12: =_xlfn.CONCAT($Z12, IF(AH$2="", "", _xlfn.UNICHAR( HEX2DEC( RIGHT(AH$2,4))))) -> i̍ | ... AJ12: =_xlfn.CONCAT($Z12, IF(AJ$2="", "", _xlfn.UNICHAR( HEX2DEC( RIGHT(AJ$2,4))))) -> i̊ | AL12: =_xlfn.CONCAT(" - xform/》", $Z12, [5]【調】韻母標調!AJ$1, "/", AA12, "/") -> - xform/》i1/i/ | AM12: =_xlfn.CONCAT(" - xform/》", $Z12, [5]【調】韻母標調!AK$1, "/", AB12, "/") -> - xform/》i2/í/ | AN12: =_xlfn.CONCAT(" - xform/》", $Z12, [5]【調】韻母標調!AL$1, "/", AC12, "/") -> - xform/》i3/ì/ | AO12: =_xlfn.CONCAT(" - xform/》", $Z12, [5]【調】韻母標調!AM$1, "/", AD12, "/") -> - xform/》i4/i/ | AP12: =_xlfn.CONCAT(" - xform/》", $Z12, [5]【調】韻母標調!AN$1, "/", AE12, "/") -> - xform/》i5/ǐ/ | AQ12: =_xlfn.CONCAT(" - xform/》", $Z12, [5]【調】韻母標調!AO$1, "/", AF12, "/") -> - xform/》i6/í/ | AR12: =_xlfn.CONCAT(" - xform/》", $Z12, [5]【調】韻母標調!AP$1, "/", AG12, "/") -> - xform/》i7/ī/ | AS12: =_xlfn.CONCAT(" - xform/》", $Z12, [5]【調】韻母標調!AQ$1, "/", AH12, "/") -> - xform/》i8/i̍/ | ... AU12: =_xlfn.CONCAT(" - xform/》", $Z12, [5]【調】韻母標調!AS$1, "/", AJ12, "/") -> - xform/》i9/i̊/
A13: =ROW() - 3 -> 10 | B13: ãʔ | C13: 含 | D13: =LEFT(韻母表[[#This Row],[十五音識別碼]],1) -> 監 | E13: 監（促） | F13: ㆩㆷ | G13: ⁰ㄚㄏ | H13: annh | I13: nah | J13: annh | K13: annh | L13: ahⁿ | M13: 韻-鼻 | N13: =LEN(K13) -> 4 | P13: =J13 -> annh | Q13: =K13 -> annh | S13: =_xlfn.CONCAT(P13, "(\d)") -> annh(\d) | T13: a | U13: =IFERROR( IF(T13="", "", SEARCH(T13, $P13)), "") -> 1 | V13: =IFERROR( _xlfn.CONCAT(LEFT(P13,U13-1), "》", MID(P13,U13,1), "${1}", RIGHT(P13, LEN(P13)-U13)), "" ) -> 》a${1}nnh | X13: =IF(AND(Q13<>"", P13<>""), " - xform/》" & S13 & "/" & V13 & "/", "") -> - xform/》annh(\d)/》a${1}nnh/ | Z13: e | AA13: =_xlfn.CONCAT($Z13, IF(AA$2="", "", _xlfn.UNICHAR( HEX2DEC( RIGHT(AA$2,4))))) -> e | AB13: =_xlfn.CONCAT($Z13, IF(AB$2="", "", _xlfn.UNICHAR( HEX2DEC( RIGHT(AB$2,4))))) -> é | AC13: =_xlfn.CONCAT($Z13, IF(AC$2="", "", _xlfn.UNICHAR( HEX2DEC( RIGHT(AC$2,4))))) -> è | AD13: =_xlfn.CONCAT($Z13, IF(AD$2="", "", _xlfn.UNICHAR( HEX2DEC( RIGHT(AD$2,4))))) -> e | AE13: =_xlfn.CONCAT($Z13, IF(AE$2="", "", _xlfn.UNICHAR( HEX2DEC( RIGHT(AE$2,4))))) -> ě | AF13: =_xlfn.CONCAT($Z13, IF(AF$2="", "", _xlfn.UNICHAR( HEX2DEC( RIGHT(AF$2,4))))) -> é | AG13: =_xlfn.CONCAT($Z13, IF(AG$2="", "", _xlfn.UNICHAR( HEX2DEC( RIGHT(AG$2,4))))) -> ē | AH13: =_xlfn.CONCAT($Z13, IF(AH$2="", "", _xlfn.UNICHAR( HEX2DEC( RIGHT(AH$2,4))))) -> e̍ | ... AJ13: =_xlfn.CONCAT($Z13, IF(AJ$2="", "", _xlfn.UNICHAR( HEX2DEC( RIGHT(AJ$2,4))))) -> e̊ | AL13: =_xlfn.CONCAT(" - xform/》", $Z13, [5]【調】韻母標調!AJ$1, "/", AA13, "/") -> - xform/》e1/e/ | AM13: =_xlfn.CONCAT(" - xform/》", $Z13, [5]【調】韻母標調!AK$1, "/", AB13, "/") -> - xform/》e2/é/ | AN13: =_xlfn.CONCAT(" - xform/》", $Z13, [5]【調】韻母標調!AL$1, "/", AC13, "/") -> - xform/》e3/è/ | AO13: =_xlfn.CONCAT(" - xform/》", $Z13, [5]【調】韻母標調!AM$1, "/", AD13, "/") -> - xform/》e4/e/ | AP13: =_xlfn.CONCAT(" - xform/》", $Z13, [5]【調】韻母標調!AN$1, "/", AE13, "/") -> - xform/》e5/ě/ | AQ13: =_xlfn.CONCAT(" - xform/》", $Z13, [5]【調】韻母標調!AO$1, "/", AF13, "/") -> - xform/》e6/é/ | AR13: =_xlfn.CONCAT(" - xform/》", $Z13, [5]【調】韻母標調!AP$1, "/", AG13, "/") -> - xform/》e7/ē/ | AS13: =_xlfn.CONCAT(" - xform/》", $Z13, [5]【調】韻母標調!AQ$1, "/", AH13, "/") -> - xform/》e8/e̍/ | ... AU13: =_xlfn.CONCAT(" - xform/》", $Z13, [5]【調】韻母標調!AS$1, "/", AJ13, "/") -> - xform/》e9/e̊/
A14: =ROW() - 3 -> 11 | B14: =_xlfn.CONCAT("a","p",_xlfn.UNICHAR(794)) -> ap̚ | C14: 答 | D14: =LEFT(韻母表[[#This Row],[十五音識別碼]],1) -> 甘 | E14: 甘（促） | F14: ㄚㆴ | G14: ㄚㄅ | H14: ap | I14: ap | J14: ap | K14: ap | L14: ap | N14: =LEN(K14) -> 2 | P14: =J14 -> ap | Q14: =K14 -> ap | S14: =_xlfn.CONCAT(P14, "(\d)") -> ap(\d) | T14: a | U14: =IFERROR( IF(T14="", "", SEARCH(T14, $P14)), "") -> 1 | V14: =IFERROR( _xlfn.CONCAT(LEFT(P14,U14-1), "》", MID(P14,U14,1), "${1}", RIGHT(P14, LEN(P14)-U14)), "" ) -> 》a${1}p | X14: =IF(AND(Q14<>"", P14<>""), " - xform/》" & S14 & "/" & V14 & "/", "") -> - xform/》ap(\d)/》a${1}p/
A15: =ROW() - 3 -> 12 | B15: =_xlfn.CONCAT("a","t",_xlfn.UNICHAR(794)) -> at̚ | C15: 識 | D15: =LEFT(韻母表[[#This Row],[十五音識別碼]],1) -> 干 | E15: 干（促） | F15: ㄚㆵ | G15: ㄚㄉ | H15: at | I15: at | J15: at | K15: at | L15: at | N15: =LEN(K15) -> 2 | P15: =J15 -> at | Q15: =K15 -> at | S15: =_xlfn.CONCAT(P15, "(\d)") -> at(\d) | T15: o | U15: =IFERROR( IF(T15="", "", SEARCH(T15, $P15)), "") | V15: =IFERROR( _xlfn.CONCAT(LEFT(P15,U15-1), "》", MID(P15,U15,1), "${1}", RIGHT(P15, LEN(P15)-U15)), "" ) | X15: =IF(AND(Q15<>"", P15<>""), " - xform/》" & S15 & "/" & V15 & "/", "") -> - xform/》at(\d)//
A16: =ROW() - 3 -> 13 | B16: aʊ | C16: 鬧 | D16: =LEFT(韻母表[[#This Row],[十五音識別碼]],1) -> 交 | E16: 交（舒） | F16: ㄠ | G16: ㄠ | H16: au | I16: ao | J16: au | K16: au | L16: au | N16: =LEN(K16) -> 2 | P16: =J16 -> au | Q16: =K16 -> au | S16: =_xlfn.CONCAT(P16, "(\d)") -> au(\d) | T16: a | U16: =IFERROR( IF(T16="", "", SEARCH(T16, $P16)), "") -> 1 | V16: =IFERROR( _xlfn.CONCAT(LEFT(P16,U16-1), "》", MID(P16,U16,1), "${1}", RIGHT(P16, LEN(P16)-U16)), "" ) -> 》a${1}u | X16: =IF(AND(Q16<>"", P16<>""), " - xform/》" & S16 & "/" & V16 & "/", "") -> - xform/》au(\d)/》a${1}u/
A17: =ROW() - 3 -> 14 | B17: auʔ | C17: 暴 | D17: =LEFT(韻母表[[#This Row],[十五音識別碼]],1) -> 交 | E17: 交（促） | F17: ㄠㆷ | G17: ㄠㄏ | H17: auh | I17: aoh | J17: auh | K17: auh | L17: auh | N17: =LEN(K17) -> 3 | P17: =J17 -> auh | Q17: =K17 -> auh | S17: =_xlfn.CONCAT(P17, "(\d)") -> auh(\d) | T17: a | U17: =IFERROR( IF(T17="", "", SEARCH(T17, $P17)), "") -> 1 | V17: =IFERROR( _xlfn.CONCAT(LEFT(P17,U17-1), "》", MID(P17,U17,1), "${1}", RIGHT(P17, LEN(P17)-U17)), "" ) -> 》a${1}uh | X17: =IF(AND(Q17<>"", P17<>""), " - xform/》" & S17 & "/" & V17 & "/", "") -> - xform/》auh(\d)/》a${1}uh/
A18: =ROW() - 3 -> 15 | B18: e | C18: 遞 | D18: =LEFT(韻母表[[#This Row],[十五音識別碼]],1) -> 稽 | E18: 稽（舒） | F18: ㆤ | G18: ㄝ | H18: e | I18: e | J18: e | K18: ei | L18: e | N18: =LEN(K18) -> 2 | P18: =J26 -> i | Q18: =K26 -> i | S18: =_xlfn.CONCAT(P18, "(\d)") -> i(\d) | T18: o | U18: =IFERROR( IF(T18="", "", SEARCH(T18, $P18)), "") | V18: =IFERROR( _xlfn.CONCAT(LEFT(P18,U18-1), "》", MID(P18,U18,1), "${1}", RIGHT(P18, LEN(P18)-U18)), "" ) | X18: =IF(AND(Q18<>"", P18<>""), " - xform/》" & S18 & "/" & V18 & "/", "") -> - xform/》i(\d)//
A19: =ROW() - 3 -> 16 | B19: ɛ | C19: 家 | D19: =LEFT(韻母表[[#This Row],[十五音識別碼]],1) -> 嘉 | E19: 嘉（舒） | F19: ㄝ | G19: ㄝ | J19: ee | K19: ee | N19: =LEN(K19) -> 2 | P19: =J18 -> e | Q19: =K18 -> ei | S19: =_xlfn.CONCAT(P19, "(\d)") -> e(\d) | T19: i | U19: =IFERROR( IF(T19="", "", SEARCH(T19, $P19)), "") | V19: =IFERROR( _xlfn.CONCAT(LEFT(P19,U19-1), "》", MID(P19,U19,1), "${1}", RIGHT(P19, LEN(P19)-U19)), "" ) | X19: =IF(AND(Q19<>"", P19<>""), " - xform/》" & S19 & "/" & V19 & "/", "") -> - xform/》e(\d)//
A20: =ROW() - 3 -> 17 | B20: =_xlfn.CONCAT(B19, "ʔ") -> ɛʔ | C20: 八 | D20: =LEFT(韻母表[[#This Row],[十五音識別碼]],1) -> 嘉 | E20: 嘉（促） | F20: ㄝㆷ | G20: ㄝㄏ | J20: eeh | K20: eeh | N20: =LEN(K20) -> 3 | P20: =J24 -> enn | Q20: =K24 -> enn | S20: =_xlfn.CONCAT(P20, "(\d)") -> enn(\d) | T20: i | U20: =IFERROR( IF(T20="", "", SEARCH(T20, $P20)), "") | V20: =IFERROR( _xlfn.CONCAT(LEFT(P20,U20-1), "》", MID(P20,U20,1), "${1}", RIGHT(P20, LEN(P20)-U20)), "" ) | X20: =IF(AND(Q20<>"", P20<>""), " - xform/》" & S20 & "/" & V20 & "/", "") -> - xform/》enn(\d)//
A21: =ROW() - 3 -> 18 | B21: eʔ | C21: 伯 | D21: =LEFT(韻母表[[#This Row],[十五音識別碼]],1) -> 伽 | E21: 伽（促） | F21: ㆤㆷ | G21: ㄝㄏ | H21: eh | I21: eh | J21: eh | K21: eh | L21: eh | N21: =LEN(K21) -> 2 | P21: =J40 -> ih | Q21: =K40 -> ih | S21: =_xlfn.CONCAT(P21, "(\d)") -> ih(\d) | T21: a | U21: =IFERROR( IF(T21="", "", SEARCH(T21, $P21)), "") | V21: =IFERROR( _xlfn.CONCAT(LEFT(P21,U21-1), "》", MID(P21,U21,1), "${1}", RIGHT(P21, LEN(P21)-U21)), "" ) | X21: =IF(AND(Q21<>"", P21<>""), " - xform/》" & S21 & "/" & V21 & "/", "") -> - xform/》ih(\d)//
A22: =ROW() - 3 -> 19 | B22: =_xlfn.CONCAT("ɪ",, "k") -> ɪk | C22: ◯ | D22: =LEFT(韻母表[[#This Row],[十五音識別碼]],1) -> 經 | E22: 經（促） | F22: ㄝㆻ | G22: ㄝㄍ | J22: ek | K22: ek | N22: =LEN(K22) -> 2 | P22: =J25 -> ennh | Q22: =K25 -> ennh | S22: =_xlfn.CONCAT(P22, "(\d)") -> ennh(\d) | T22: i | U22: =IFERROR( IF(T22="", "", SEARCH(T22, $P22)), "") | V22: =IFERROR( _xlfn.CONCAT(LEFT(P22,U22-1), "》", MID(P22,U22,1), "${1}", RIGHT(P22, LEN(P22)-U22)), "" ) | X22: =IF(AND(Q22<>"", P22<>""), " - xform/》" & S22 & "/" & V22 & "/", "") -> - xform/》ennh(\d)//
A23: =ROW() - 3 -> 20 | B23: =_xlfn.CONCAT("ɪ", "ŋ") -> ɪŋ | C23: ◯ | D23: =LEFT(韻母表[[#This Row],[十五音識別碼]],1) -> 經 | E23: 經（舒） | F23: ㄝㆭ | G23: ㄝㄥ | J23: eng | K23: eng | N23: =LEN(K23) -> 3 | P23: =J21 -> eh | Q23: =K21 -> eh | S23: =_xlfn.CONCAT(P23, "(\d)") -> eh(\d) | T23: a | U23: =IFERROR( IF(T23="", "", SEARCH(T23, $P23)), "") | V23: =IFERROR( _xlfn.CONCAT(LEFT(P23,U23-1), "》", MID(P23,U23,1), "${1}", RIGHT(P23, LEN(P23)-U23)), "" ) | X23: =IF(AND(Q23<>"", P23<>""), " - xform/》" & S23 & "/" & V23 & "/", "") -> - xform/》eh(\d)//
A24: =ROW() - 3 -> 21 | B24: ẽ | C24: 爭 | D24: =LEFT(韻母表[[#This Row],[十五音識別碼]],1) -> 更 | E24: 更（舒） | F24: ㆥ | G24: ⁰ㄝ | H24: enn | I24: ne | J24: enn | K24: enn | L24: eⁿ | M24: 韻-鼻 | N24: =LEN(K24) -> 3 | P24: =J45 -> inn | Q24: =K45 -> inn | S24: =_xlfn.CONCAT(P24, "(\d)") -> inn(\d) | T24: o | U24: =IFERROR( IF(T24="", "", SEARCH(T24, $P24)), "") | V24: =IFERROR( _xlfn.CONCAT(LEFT(P24,U24-1), "》", MID(P24,U24,1), "${1}", RIGHT(P24, LEN(P24)-U24)), "" ) | X24: =IF(AND(Q24<>"", P24<>""), " - xform/》" & S24 & "/" & V24 & "/", "") -> - xform/》inn(\d)//
A25: =ROW() - 3 -> 22 | B25: ẽʔ | C25: 挾 | D25: =LEFT(韻母表[[#This Row],[十五音識別碼]],1) -> 更 | E25: 更（促） | F25: ㆥㆷ | G25: ⁰ㄝㄏ | H25: ennh | I25: ennh | J25: ennh | K25: ennh | L25: ehⁿ | M25: 韻-鼻 | N25: =LEN(K25) -> 4 | P25: =J42 -> im | Q25: =K42 -> im | S25: =_xlfn.CONCAT(P25, "(\d)") -> im(\d) | T25: e | U25: =IFERROR( IF(T25="", "", SEARCH(T25, $P25)), "") | V25: =IFERROR( _xlfn.CONCAT(LEFT(P25,U25-1), "》", MID(P25,U25,1), "${1}", RIGHT(P25, LEN(P25)-U25)), "" ) | X25: =IF(AND(Q25<>"", P25<>""), " - xform/》" & S25 & "/" & V25 & "/", "") -> - xform/》im(\d)//
A26: =ROW() - 3 -> 23 | B26: i | C26: 爾 | D26: =LEFT(韻母表[[#This Row],[十五音識別碼]],1) -> 居 | E26: 居（舒） | F26: ㄧ | G26: ㄧ | H26: i | I26: i | J26: i | K26: i | L26: i | N26: =LEN(K26) -> 1 | P26: =J43 -> in | Q26: =K43 -> in | S26: =_xlfn.CONCAT(P26, "(\d)") -> in(\d) | T26: a | U26: =IFERROR( IF(T26="", "", SEARCH(T26, $P26)), "") | V26: =IFERROR( _xlfn.CONCAT(LEFT(P26,U26-1), "》", MID(P26,U26,1), "${1}", RIGHT(P26, LEN(P26)-U26)), "" ) | X26: =IF(AND(Q26<>"", P26<>""), " - xform/》" & S26 & "/" & V26 & "/", "") -> - xform/》in(\d)//
A27: =ROW() - 3 -> 24 | B27: ɪa | C27: 名 | D27: =LEFT(韻母表[[#This Row],[十五音識別碼]],1) -> 迦 | E27: 迦（舒） | F27: ㄧㄚ | G27: ㄧㄚ | H27: ia | I27: ia | J27: ia | K27: ia | L27: ia | N27: =LEN(K27) -> 2 | P27: =J30 -> iam | Q27: =K30 -> iam | S27: =_xlfn.CONCAT(P27, "(\d)") -> iam(\d) | T27: i | U27: =IFERROR( IF(T27="", "", SEARCH(T27, $P27)), "") -> 1 | V27: =IFERROR( _xlfn.CONCAT(LEFT(P27,U27-1), "》", MID(P27,U27,1), "${1}", RIGHT(P27, LEN(P27)-U27)), "" ) -> 》i${1}am | X27: =IF(AND(Q27<>"", P27<>""), " - xform/》" & S27 & "/" & V27 & "/", "") -> - xform/》iam(\d)/》i${1}am/
A28: =ROW() - 3 -> 25 | B28: =_xlfn.CONCAT(B27, "ʔ") -> ɪaʔ | C28: 壁 | D28: =LEFT(韻母表[[#This Row],[十五音識別碼]],1) -> 迦 | E28: 迦（促） | F28: ㄧㄚㆷ | G28: ㄧㄚㄏ | H28: iah | I28: iah | J28: iah | K28: iah | L28: iah | N28: =LEN(K28) -> 3 | P28: =J32 -> iang | Q28: =K32 -> iang | S28: =_xlfn.CONCAT(P28, "(\d)") -> iang(\d) | T28: i | U28: =IFERROR( IF(T28="", "", SEARCH(T28, $P28)), "") -> 1 | V28: =IFERROR( _xlfn.CONCAT(LEFT(P28,U28-1), "》", MID(P28,U28,1), "${1}", RIGHT(P28, LEN(P28)-U28)), "" ) -> 》i${1}ang | X28: =IF(AND(Q28<>"", P28<>""), " - xform/》" & S28 & "/" & V28 & "/", "") -> - xform/》iang(\d)/》i${1}ang/
A29: =ROW() - 3 -> 26 | B29: ɪak̚ | C29: 爆 | D29: =LEFT(韻母表[[#This Row],[十五音識別碼]],1) -> 姜 | E29: 姜（促） | F29: ㄧㄚㆻ | G29: ㄧㄚㄍ | H29: iak | I29: iak | J29: iak | K29: iak | L29: iak | N29: =LEN(K29) -> 3 | P29: =J46 -> io | Q29: =K46 -> io | S29: =_xlfn.CONCAT(P29, "(\d)") -> io(\d) | T29: a | U29: =IFERROR( IF(T29="", "", SEARCH(T29, $P29)), "") | V29: =IFERROR( _xlfn.CONCAT(LEFT(P29,U29-1), "》", MID(P29,U29,1), "${1}", RIGHT(P29, LEN(P29)-U29)), "" ) | X29: =IF(AND(Q29<>"", P29<>""), " - xform/》" & S29 & "/" & V29 & "/", "") -> - xform/》io(\d)//
A30: =ROW() - 3 -> 27 | B30: ɪam | C30: 尖 | D30: =LEFT(韻母表[[#This Row],[十五音識別碼]],1) -> 兼 | E30: 兼（舒） | F30: ㄧㆰ | G30: ㄧㄚㄇ | H30: iam | I30: iam | J30: iam | K30: iam | L30: iam | N30: =LEN(K30) -> 3 | P30: =J36 -> iat | Q30: =K36 -> iat | S30: =_xlfn.CONCAT(P30, "(\d)") -> iat(\d) | T30: e | U30: =IFERROR( IF(T30="", "", SEARCH(T30, $P30)), "") | V30: =IFERROR( _xlfn.CONCAT(LEFT(P30,U30-1), "》", MID(P30,U30,1), "${1}", RIGHT(P30, LEN(P30)-U30)), "" ) | X30: =IF(AND(Q30<>"", P30<>""), " - xform/》" & S30 & "/" & V30 & "/", "") -> - xform/》iat(\d)//
A31: =ROW() - 3 -> 28 | B31: ɪan | C31: 掀 | D31: =LEFT(韻母表[[#This Row],[十五音識別碼]],1) -> 堅 | E31: 堅（舒） | F31: ㄧㄢ | G31: ㄧㄢ | H31: ian | I31: ian | J31: ian | K31: ian | L31: ian | N31: =LEN(K31) -> 3 | P31: =J29 -> iak | Q31: =K29 -> iak | S31: =_xlfn.CONCAT(P31, "(\d)") -> iak(\d) | T31: n | U31: =IFERROR( IF(T31="", "", SEARCH(T31, $P31)), "") | V31: =IFERROR( _xlfn.CONCAT(LEFT(P31,U31-1), "》", MID(P31,U31,1), "${1}", RIGHT(P31, LEN(P31)-U31)), "" ) | X31: =IF(AND(Q31<>"", P31<>""), " - xform/》" & S31 & "/" & V31 & "/", "") -> - xform/》iak(\d)//
A32: =ROW() - 3 -> 29 | B32: ɪaŋ | C32: 將 | D32: =LEFT(韻母表[[#This Row],[十五音識別碼]],1) -> 姜 | E32: 姜（舒） | F32: ㄧㄤ | G32: ㄧㄤ | H32: iang | I32: iang | J32: iang | K32: iang | L32: iang | N32: =LEN(K32) -> 4 | P32: =J37 -> iau | Q32: =K37 -> iau | S32: =_xlfn.CONCAT(P32, "(\d)") -> iau(\d) | T32: o | U32: =IFERROR( IF(T32="", "", SEARCH(T32, $P32)), "") | V32: =IFERROR( _xlfn.CONCAT(LEFT(P32,U32-1), "》", MID(P32,U32,1), "${1}", RIGHT(P32, LEN(P32)-U32)), "" ) | X32: =IF(AND(Q32<>"", P32<>""), " - xform/》" & S32 & "/" & V32 & "/", "") -> - xform/》iau(\d)//
A33: =ROW() - 3 -> 30 | B33: =_xlfn.CONCAT("ɪ", "a", _xlfn.UNICHAR(771), "") -> ɪã | C33: ◯ | D33: =LEFT(韻母表[[#This Row],[十五音識別碼]],1) -> 驚 | E33: 驚（舒） | F33: ㄧㆩ | G33: ⁰ㄧㄚ | H33: iann | I33: nia | J33: iann | K33: iann | L33: iaⁿ | M33: 韻-鼻 | N33: =LEN(K33) -> 4 | P33: =J31 -> ian | Q33: =K31 -> ian | S33: =_xlfn.CONCAT(P33, "(\d)") -> ian(\d) | T33: i | U33: =IFERROR( IF(T33="", "", SEARCH(T33, $P33)), "") -> 1 | V33: =IFERROR( _xlfn.CONCAT(LEFT(P33,U33-1), "》", MID(P33,U33,1), "${1}", RIGHT(P33, LEN(P33)-U33)), "" ) -> 》i${1}an | X33: =IF(AND(Q33<>"", P33<>""), " - xform/》" & S33 & "/" & V33 & "/", "") -> - xform/》ian(\d)/》i${1}an/
A34: =ROW() - 3 -> 31 | B34: =_xlfn.CONCAT(B33, "ʔ") -> ɪãʔ | C34: 且 | D34: =LEFT(韻母表[[#This Row],[十五音識別碼]],1) -> 迦 | E34: 迦（促） | F34: ㄧㆩㆷ | G34: ⁰ㄧㄚㄏ | H34: iannh | I34: iannh | J34: iannh | K34: iannh | L34: iahⁿ | M34: 韻-鼻 | N34: =LEN(K34) -> 5 | P34: =J35 -> iap | Q34: =K35 -> iap | S34: =_xlfn.CONCAT(P34, "(\d)") -> iap(\d) | T34: i | U34: =IFERROR( IF(T34="", "", SEARCH(T34, $P34)), "") -> 1 | V34: =IFERROR( _xlfn.CONCAT(LEFT(P34,U34-1), "》", MID(P34,U34,1), "${1}", RIGHT(P34, LEN(P34)-U34)), "" ) -> 》i${1}ap | X34: =IF(AND(Q34<>"", P34<>""), " - xform/》" & S34 & "/" & V34 & "/", "") -> - xform/》iap(\d)/》i${1}ap/
