Workbook

Sheet 工作表1
B2: 序號 | C2: =COLUMN() -2 -> 1 | D2: =COLUMN() -2 -> 2 | E2: =COLUMN() -2 -> 3 | F2: =COLUMN() -2 -> 4 | G2: =COLUMN() -2 -> 5 | H2: =COLUMN() -2 -> 6 | I2: =COLUMN() -2 -> 7 | J2: =COLUMN() -2 -> 8 | ... R2: =COLUMN() -2 -> 16
B3: 漢字 | C3: 黄 | D3: 河 | E3: 遠 | F3: 上 | G3: 白 | H3: 雲 | I3: 間 | J3: ， | K3: 一 | L3: 片 | M3: 孤 | N3: 城 | O3: 萬 | P3: 仞 | Q3: 山 | R3: 。
B4: 台語音標 | C4: hong5 | D4: ho5 | E4: uan2 | F4: siong2 | G4: pik8 | H4: hun5 | I4: kan1 | J4: , | K4: it4 | L4: phian3 | M4: koo1 | N4: sing5 | O4: ban7 | P4: jim7 | Q4: san1 | R4: .
B5: 台羅拼音 | C5: hông | D5: hô | E5: uán | F5: sióng | G5: pi̍k | H5: hûn | I5: kan | J5: , | K5: it | L5: phiàn | M5: koo | N5: sîng | O5: bān | P5: jīm | Q5: san | R5: .
B6: 白話字 | C6: hông | D6: hô | E6: oán | F6: sióng | G6: pe̍k | H6: hûn | I6: kan | J6: , | K6: it | L6: phiàn | M6: ko͘ | N6: sêng | O6: bān | P6: jīm | Q6: san | R6: .
B7: 國際音標 | C7: hɔŋ² | D7: hə² | E7: uan³ | F7: sɪɔŋ³ | G7: pik̚⁸ | H7: hun² | I7: kan¹ | J7: , | K7: it̚⁷ | L7: pʰɪan⁵ | M7: kɔ¹ | N7: siŋ² | O7: ban³ | P7: ʣim⁶ | Q7: san¹ | R7: .
B8: 閩拼方案 | C8: hóng | D8: hó | E8: wǎn | F8: siǒng | G8: pík | H8: hún | I8: kān | J8: , | K8: yīt | L8: piàn | M8: gōo | N8: síng | O8: bbân | P8: zzîm | Q8: sān | R8: .
B9: 台語注音二式 | C9: hong5 | D9: hor5 | E9: uan2 | F9: shiong2 | G9: biek8 | H9: hun5 | I9: gan1 | J9: , | K9: it4 | L9: pian3 | M9: goo1 | N9: sing5 | O9: bban7 | P9: jjim7 | Q9: san1 | R9: .

Sheet 輸入工具
C2: 漢字 | D2: 閩拼方案 | E2: 國際音標 | F2: 聲母 | G2: 韻母 | H2: 音調 | J2: 聲母 | K2: 韻母 | L2: 音調
B3: 【閩拼方案】 | C3: 了 | D3: liao3 | E3: =IF(AND(F3<>"",G3<>"",H3<>""), _xlfn.CONCAT(J3:L3), "") -> lɪaʊ3 | F3: l | G3: iao | H3: 3 | J3: {=IF(F3<>"", INDEX(聲母對照表[國際音標], MATCH(TRUE, EXACT(輸入工具!F3, 聲母對照表[閩拼方案]), 0)), "")} -> l | K3: {=IF(G3<>"", INDEX(韻母對照表[國際音標], MATCH(TRUE, EXACT(輸入工具!G3, 韻母對照表[閩拼方案]), 0)), "")} -> ɪaʊ | L3: {=IF(H3<>"", INDEX(音調對照表[傳統調號], MATCH(TRUE, EXACT(輸入工具!H3, 音調對照表[傳統調號]), 0)), "")} -> 3
B4: 【閩拼方案】 | C4: 門 | D4: bbng2 | E4: =IF(AND(F4<>"",G4<>"",H4<>""), _xlfn.CONCAT(J4:L4), "") -> mŋ̍2 | F4: bbn | G4: ng | H4: 2 | J4: {=IF(F4<>"", INDEX(聲母對照表[國際音標], MATCH(TRUE, EXACT(輸入工具!F4, 聲母對照表[閩拼方案]), 0)), "")} -> m | K4: {=IF(G4<>"", INDEX(韻母對照表[國際音標], MATCH(TRUE, EXACT(輸入工具!G4, 韻母對照表[閩拼方案]), 0)), "")} -> ŋ̍ | L4: {=IF(H4<>"", INDEX(音調對照表[傳統調號], MATCH(TRUE, EXACT(輸入工具!H4, 音調對照表[傳統調號]), 0)), "")} -> 2
B5: 【閩拼方案】 | C5: 仞 | D5: zzim6 | E5: =IF(AND(F5<>"",G5<>"",H5<>""), _xlfn.CONCAT(J5:L5), "") -> ʣim6 | F5: zz | G5: im | H5: 6 | J5: {=IF(F5<>"", INDEX(聲母對照表[國際音標], MATCH(TRUE, EXACT(輸入工具!F5, 聲母對照表[閩拼方案]), 0)), "")} -> ʣ | K5: {=IF(G5<>"", INDEX(韻母對照表[國際音標], MATCH(TRUE, EXACT(輸入工具!G5, 韻母對照表[閩拼方案]), 0)), "")} -> im | L5: {=IF(H5<>"", INDEX(音調對照表[傳統調號], MATCH(TRUE, EXACT(輸入工具!H5, 音調對照表[傳統調號]), 0)), "")} -> 6
B6: 【閩拼方案】 | C6: 羌 | D6: gniu1 | E6: =IF(AND(F6<>"",G6<>"",H6<>""), _xlfn.CONCAT(J6:L6), "") -> kɪũ1 | F6: g | G6: niu | H6: 1 | J6: {=IF(F6<>"", INDEX(聲母對照表[國際音標], MATCH(TRUE, EXACT(輸入工具!F6, 聲母對照表[閩拼方案]), 0)), "")} -> k | K6: {=IF(G6<>"", INDEX(韻母對照表[國際音標], MATCH(TRUE, EXACT(輸入工具!G6, 韻母對照表[閩拼方案]), 0)), "")} -> ɪũ | L6: {=IF(H6<>"", INDEX(音調對照表[傳統調號], MATCH(TRUE, EXACT(輸入工具!H6, 音調對照表[傳統調號]), 0)), "")} -> 1
B7: 【閩拼方案】 | C7: 楊 | D7: ynu2 | E7: =IF(AND(F7<>"",G7<>"",H7<>""), _xlfn.CONCAT(J7:L7), "") -> ɪũ2 | F7: y | G7: niu | H7: 2 | J7: {=IFERROR( IF(F7<>"", INDEX(聲母對照表[國際音標], MATCH(TRUE, EXACT(輸入工具!F7, 聲母對照表[閩拼方案]), 0)), ""), "")} | K7: {=IF(G7<>"", INDEX(韻母對照表[國際音標], MATCH(TRUE, EXACT(輸入工具!G7, 韻母對照表[閩拼方案]), 0)), "")} -> ɪũ | L7: {=IF(H7<>"", INDEX(音調對照表[傳統調號], MATCH(TRUE, EXACT(輸入工具!H7, 音調對照表[傳統調號]), 0)), "")} -> 2
B8: 【閩拼方案】 | C8: 柳 | D8: liu3 | E8: =IF(AND(F8<>"",G8<>"",H8<>""), _xlfn.CONCAT(J8:L8), "") -> lɪu3 | F8: l | G8: iu | H8: 3 | J8: {=IF(F8<>"", INDEX(聲母對照表[國際音標], MATCH(TRUE, EXACT(輸入工具!F8, 聲母對照表[閩拼方案]), 0)), "")} -> l | K8: {=IF(G8<>"", INDEX(韻母對照表[國際音標], MATCH(TRUE, EXACT(輸入工具!G8, 韻母對照表[閩拼方案]), 0)), "")} -> ɪu | L8: {=IF(H8<>"", INDEX(音調對照表[傳統調號], MATCH(TRUE, EXACT(輸入工具!H8, 音調對照表[傳統調號]), 0)), "")} -> 3
B9: 【閩拼方案】 | E9: =IF(AND(F9<>"",G9<>"",H9<>""), _xlfn.CONCAT(J9:L9), "") | J9: {=IF(F9<>"", INDEX(聲母對照表[國際音標], MATCH(TRUE, EXACT(輸入工具!F9, 聲母對照表[閩拼方案]), 0)), "")} | K9: {=IF(G9<>"", INDEX(韻母對照表[國際音標], MATCH(TRUE, EXACT(輸入工具!G9, 韻母對照表[閩拼方案]), 0)), "")} | L9: {=IF(H9<>"", INDEX(#REF!, MATCH(TRUE, EXACT(輸入工具!H9,#REF!), 0)), "")}

Sheet 輸入工具 (閩拼方案)
B2: =_xlfn.CONCAT("【", D4, "】") -> 【閩拼方案】
B4: 序號 | C4: 漢字 | D4: 閩拼方案 | E4: 國際音標 | F4: 聲母 | G4: 韻母 | H4: 音調 | J4: 聲母 | K4: 韻母 | L4: 音調
B5: =ROW() - 4 -> 1 | C5: 黄 | D5: hong2 | E5: =IF(AND(F5<>"",G5<>"",H5<>""), _xlfn.CONCAT(J5:L5), "") -> hɔŋ² | F5: h | G5: =IFERROR( MID(D5, LEN(F5)+1, LEN(D5) - LEN(F5) - 1), "") -> ong | H5: =RIGHT(D5,1) -> 2 | J5: {=IFERROR( IF(F5<>"", INDEX(聲母對照表[國際音標], MATCH(TRUE, EXACT('輸入工具 (閩拼方案)'!F5, 聲母對照表[閩拼方案]), 0)), ""), "")} -> h | K5: {=IFERROR( IF(G5<>"", INDEX(韻母對照表[國際音標], MATCH(TRUE, EXACT('輸入工具 (閩拼方案)'!G5, 韻母對照表[閩拼方案]), 0)), ""), "")} -> ɔŋ | L5: {=IF(H5<>"", INDEX(上標對照表[上標值], MATCH(TRUE, EXACT('輸入工具 (閩拼方案)'!H5, 上標對照表[調號]), 0)), "")} -> ²
B6: =ROW() - 4 -> 2 | C6: 河 | D6: ho2 | E6: =IF(AND(F6<>"",G6<>"",H6<>""), _xlfn.CONCAT(J6:L6), "") -> hə² | F6: h | G6: =IFERROR( MID(D6, LEN(F6)+1, LEN(D6) - LEN(F6) - 1), "") -> o | H6: =RIGHT(D6,1) -> 2 | J6: {=IFERROR( IF(F6<>"", INDEX(聲母對照表[國際音標], MATCH(TRUE, EXACT('輸入工具 (閩拼方案)'!F6, 聲母對照表[閩拼方案]), 0)), ""), "")} -> h | K6: {=IFERROR( IF(G6<>"", INDEX(韻母對照表[國際音標], MATCH(TRUE, EXACT('輸入工具 (閩拼方案)'!G6, 韻母對照表[閩拼方案]), 0)), ""), "")} -> ə | L6: {=IF(H6<>"", INDEX(上標對照表[上標值], MATCH(TRUE, EXACT('輸入工具 (閩拼方案)'!H6, 上標對照表[調號]), 0)), "")} -> ²
B7: =ROW() - 4 -> 3 | C7: 遠 | D7: wan3 | E7: =IF(AND(F7<>"",G7<>"",H7<>""), _xlfn.CONCAT(J7:L7), "") -> uan³ | F7: w | G7: uan | H7: =RIGHT(D7,1) -> 3 | J7: {=IFERROR( IF(F7<>"", INDEX(聲母對照表[國際音標], MATCH(TRUE, EXACT('輸入工具 (閩拼方案)'!F7, 聲母對照表[閩拼方案]), 0)), ""), "")} | K7: {=IFERROR( IF(G7<>"", INDEX(韻母對照表[國際音標], MATCH(TRUE, EXACT('輸入工具 (閩拼方案)'!G7, 韻母對照表[閩拼方案]), 0)), ""), "")} -> uan | L7: {=IF(H7<>"", INDEX(上標對照表[上標值], MATCH(TRUE, EXACT('輸入工具 (閩拼方案)'!H7, 上標對照表[調號]), 0)), "")} -> ³
B8: =ROW() - 4 -> 4 | C8: 上 | D8: siong3 | E8: =IF(AND(F8<>"",G8<>"",H8<>""), _xlfn.CONCAT(J8:L8), "") -> sɪɔŋ³ | F8: s | G8: =IFERROR( MID(D8, LEN(F8)+1, LEN(D8) - LEN(F8) - 1), "") -> iong | H8: =RIGHT(D8,1) -> 3 | J8: {=IFERROR( IF(F8<>"", INDEX(聲母對照表[國際音標], MATCH(TRUE, EXACT('輸入工具 (閩拼方案)'!F8, 聲母對照表[閩拼方案]), 0)), ""), "")} -> s | K8: {=IFERROR( IF(G8<>"", INDEX(韻母對照表[國際音標], MATCH(TRUE, EXACT('輸入工具 (閩拼方案)'!G8, 韻母對照表[閩拼方案]), 0)), ""), "")} -> ɪɔŋ | L8: {=IF(H8<>"", INDEX(上標對照表[上標值], MATCH(TRUE, EXACT('輸入工具 (閩拼方案)'!H8, 上標對照表[調號]), 0)), "")} -> ³
B9: =ROW() - 4 -> 5 | C9: 白 | D9: bik8 | E9: =IF(AND(F9<>"",G9<>"",H9<>""), _xlfn.CONCAT(J9:L9), "") -> pik̚⁸ | F9: b | G9: =IFERROR( MID(D9, LEN(F9)+1, LEN(D9) - LEN(F9) - 1), "") -> ik | H9: =RIGHT(D9,1) -> 8 | J9: {=IFERROR( IF(F9<>"", INDEX(聲母對照表[國際音標], MATCH(TRUE, EXACT('輸入工具 (閩拼方案)'!F9, 聲母對照表[閩拼方案]), 0)), ""), "")} -> p | K9: {=IFERROR( IF(G9<>"", INDEX(韻母對照表[國際音標], MATCH(TRUE, EXACT('輸入工具 (閩拼方案)'!G9, 韻母對照表[閩拼方案]), 0)), ""), "")} -> ik̚ | L9: {=IF(H9<>"", INDEX(上標對照表[上標值], MATCH(TRUE, EXACT('輸入工具 (閩拼方案)'!H9, 上標對照表[調號]), 0)), "")} -> ⁸
B10: =ROW() - 4 -> 6 | C10: 雲 | D10: hun2 | E10: =IF(AND(F10<>"",G10<>"",H10<>""), _xlfn.CONCAT(J10:L10), "") -> hun² | F10: h | G10: =IFERROR( MID(D10, LEN(F10)+1, LEN(D10) - LEN(F10) - 1), "") -> un | H10: =RIGHT(D10,1) -> 2 | J10: {=IFERROR( IF(F10<>"", INDEX(聲母對照表[國際音標], MATCH(TRUE, EXACT('輸入工具 (閩拼方案)'!F10, 聲母對照表[閩拼方案]), 0)), ""), "")} -> h | K10: {=IFERROR( IF(G10<>"", INDEX(韻母對照表[國際音標], MATCH(TRUE, EXACT('輸入工具 (閩拼方案)'!G10, 韻母對照表[閩拼方案]), 0)), ""), "")} -> un | L10: {=IF(H10<>"", INDEX(上標對照表[上標值], MATCH(TRUE, EXACT('輸入工具 (閩拼方案)'!H10, 上標對照表[調號]), 0)), "")} -> ²
B11: =ROW() - 4 -> 7 | C11: 間 | D11: ging1 | E11: =IF(AND(F11<>"",G11<>"",H11<>""), _xlfn.CONCAT(J11:L11), "") -> kiŋ¹ | F11: g | G11: =IFERROR( MID(D11, LEN(F11)+1, LEN(D11) - LEN(F11) - 1), "") -> ing | H11: =RIGHT(D11,1) -> 1 | J11: {=IFERROR( IF(F11<>"", INDEX(聲母對照表[國際音標], MATCH(TRUE, EXACT('輸入工具 (閩拼方案)'!F11, 聲母對照表[閩拼方案]), 0)), ""), "")} -> k | K11: {=IFERROR( IF(G11<>"", INDEX(韻母對照表[國際音標], MATCH(TRUE, EXACT('輸入工具 (閩拼方案)'!G11, 韻母對照表[閩拼方案]), 0)), ""), "")} -> iŋ | L11: {=IF(H11<>"", INDEX(上標對照表[上標值], MATCH(TRUE, EXACT('輸入工具 (閩拼方案)'!H11, 上標對照表[調號]), 0)), "")} -> ¹
B12: =ROW() - 4 -> 8 | C12: ， | E12: =IF(AND(F12<>"",G12<>"",H12<>""), _xlfn.CONCAT(J12:L12), "") | G12: =IFERROR( MID(D12, LEN(F12)+1, LEN(D12) - LEN(F12) - 1), "") | H12: =RIGHT(D12,1) | J12: {=IFERROR( IF(F12<>"", INDEX(聲母對照表[國際音標], MATCH(TRUE, EXACT('輸入工具 (閩拼方案)'!F12, 聲母對照表[閩拼方案]), 0)), ""), "")} | K12: {=IFERROR( IF(G12<>"", INDEX(韻母對照表[國際音標], MATCH(TRUE, EXACT('輸入工具 (閩拼方案)'!G12, 韻母對照表[閩拼方案]), 0)), ""), "")} | L12: {=IF(H12<>"", INDEX(上標對照表[上標值], MATCH(TRUE, EXACT('輸入工具 (閩拼方案)'!H12, 上標對照表[調號]), 0)), "")}
B13: =ROW() - 4 -> 9 | C13: 一 | D13: yit7 | E13: =IF(AND(F13<>"",G13<>"",H13<>""), _xlfn.CONCAT(J13:L13), "") -> it̚⁷ | F13: y | G13: =IFERROR( MID(D13, LEN(F13)+1, LEN(D13) - LEN(F13) - 1), "") -> it | H13: =RIGHT(D13,1) -> 7 | J13: {=IFERROR( IF(F13<>"", INDEX(聲母對照表[國際音標], MATCH(TRUE, EXACT('輸入工具 (閩拼方案)'!F13, 聲母對照表[閩拼方案]), 0)), ""), "")} | K13: {=IFERROR( IF(G13<>"", INDEX(韻母對照表[國際音標], MATCH(TRUE, EXACT('輸入工具 (閩拼方案)'!G13, 韻母對照表[閩拼方案]), 0)), ""), "")} -> it̚ | L13: {=IF(H13<>"", INDEX(上標對照表[上標值], MATCH(TRUE, EXACT('輸入工具 (閩拼方案)'!H13, 上標對照表[調號]), 0)), "")} -> ⁷
B14: =ROW() - 4 -> 10 | C14: 片 | D14: pian5 | E14: =IF(AND(F14<>"",G14<>"",H14<>""), _xlfn.CONCAT(J14:L14), "") -> pʰɪan⁵ | F14: p | G14: =IFERROR( MID(D14, LEN(F14)+1, LEN(D14) - LEN(F14) - 1), "") -> ian | H14: =RIGHT(D14,1) -> 5 | J14: {=IFERROR( IF(F14<>"", INDEX(聲母對照表[國際音標], MATCH(TRUE, EXACT('輸入工具 (閩拼方案)'!F14, 聲母對照表[閩拼方案]), 0)), ""), "")} -> pʰ | K14: {=IFERROR( IF(G14<>"", INDEX(韻母對照表[國際音標], MATCH(TRUE, EXACT('輸入工具 (閩拼方案)'!G14, 韻母對照表[閩拼方案]), 0)), ""), "")} -> ɪan | L14: {=IF(H14<>"", INDEX(上標對照表[上標值], MATCH(TRUE, EXACT('輸入工具 (閩拼方案)'!H14, 上標對照表[調號]), 0)), "")} -> ⁵
B15: =ROW() - 4 -> 11 | C15: 孤 | D15: goo1 | E15: =IF(AND(F15<>"",G15<>"",H15<>""), _xlfn.CONCAT(J15:L15), "") -> kɔ¹ | F15: g | G15: =IFERROR( MID(D15, LEN(F15)+1, LEN(D15) - LEN(F15) - 1), "") -> oo | H15: =RIGHT(D15,1) -> 1 | J15: {=IFERROR( IF(F15<>"", INDEX(聲母對照表[國際音標], MATCH(TRUE, EXACT('輸入工具 (閩拼方案)'!F15, 聲母對照表[閩拼方案]), 0)), ""), "")} -> k | K15: {=IFERROR( IF(G15<>"", INDEX(韻母對照表[國際音標], MATCH(TRUE, EXACT('輸入工具 (閩拼方案)'!G15, 韻母對照表[閩拼方案]), 0)), ""), "")} -> ɔ | L15: {=IF(H15<>"", INDEX(上標對照表[上標值], MATCH(TRUE, EXACT('輸入工具 (閩拼方案)'!H15, 上標對照表[調號]), 0)), "")} -> ¹
B16: =ROW() - 4 -> 12 | C16: 城 | D16: sing2 | E16: =IF(AND(F16<>"",G16<>"",H16<>""), _xlfn.CONCAT(J16:L16), "") -> siŋ² | F16: s | G16: =IFERROR( MID(D16, LEN(F16)+1, LEN(D16) - LEN(F16) - 1), "") -> ing | H16: =RIGHT(D16,1) -> 2 | J16: {=IFERROR( IF(F16<>"", INDEX(聲母對照表[國際音標], MATCH(TRUE, EXACT('輸入工具 (閩拼方案)'!F16, 聲母對照表[閩拼方案]), 0)), ""), "")} -> s | K16: {=IFERROR( IF(G16<>"", INDEX(韻母對照表[國際音標], MATCH(TRUE, EXACT('輸入工具 (閩拼方案)'!G16, 韻母對照表[閩拼方案]), 0)), ""), "")} -> iŋ | L16: {=IF(H16<>"", INDEX(上標對照表[上標值], MATCH(TRUE, EXACT('輸入工具 (閩拼方案)'!H16, 上標對照表[調號]), 0)), "")} -> ²
B17: =ROW() - 4 -> 13 | C17: 萬 | D17: bban3 | E17: =IF(AND(F17<>"",G17<>"",H17<>""), _xlfn.CONCAT(J17:L17), "") -> ban³ | F17: bb | G17: =IFERROR( MID(D17, LEN(F17)+1, LEN(D17) - LEN(F17) - 1), "") -> an | H17: =RIGHT(D17,1) -> 3 | J17: {=IFERROR( IF(F17<>"", INDEX(聲母對照表[國際音標], MATCH(TRUE, EXACT('輸入工具 (閩拼方案)'!F17, 聲母對照表[閩拼方案]), 0)), ""), "")} -> b | K17: {=IFERROR( IF(G17<>"", INDEX(韻母對照表[國際音標], MATCH(TRUE, EXACT('輸入工具 (閩拼方案)'!G17, 韻母對照表[閩拼方案]), 0)), ""), "")} -> an | L17: {=IF(H17<>"", INDEX(上標對照表[上標值], MATCH(TRUE, EXACT('輸入工具 (閩拼方案)'!H17, 上標對照表[調號]), 0)), "")} -> ³
B18: =ROW() - 4 -> 14 | C18: 仞 | D18: zzim6 | E18: =IF(AND(F18<>"",G18<>"",H18<>""), _xlfn.CONCAT(J18:L18), "") -> ʣim⁶ | F18: zz | G18: =IFERROR( MID(D18, LEN(F18)+1, LEN(D18) - LEN(F18) - 1), "") -> im | H18: =RIGHT(D18,1) -> 6 | J18: {=IFERROR( IF(F18<>"", INDEX(聲母對照表[國際音標], MATCH(TRUE, EXACT('輸入工具 (閩拼方案)'!F18, 聲母對照表[閩拼方案]), 0)), ""), "")} -> ʣ | K18: {=IFERROR( IF(G18<>"", INDEX(韻母對照表[國際音標], MATCH(TRUE, EXACT('輸入工具 (閩拼方案)'!G18, 韻母對照表[閩拼方案]), 0)), ""), "")} -> im | L18: {=IF(H18<>"", INDEX(上標對照表[上標值], MATCH(TRUE, EXACT('輸入工具 (閩拼方案)'!H18, 上標對照表[調號]), 0)), "")} -> ⁶
B19: =ROW() - 4 -> 15 | C19: 山 | D19: san1 | E19: =IF(AND(F19<>"",G19<>"",H19<>""), _xlfn.CONCAT(J19:L19), "") -> san¹ | F19: s | G19: =IFERROR( MID(D19, LEN(F19)+1, LEN(D19) - LEN(F19) - 1), "") -> an | H19: =RIGHT(D19,1) -> 1 | J19: {=IFERROR( IF(F19<>"", INDEX(聲母對照表[國際音標], MATCH(TRUE, EXACT('輸入工具 (閩拼方案)'!F19, 聲母對照表[閩拼方案]), 0)), ""), "")} -> s | K19: {=IFERROR( IF(G19<>"", INDEX(韻母對照表[國際音標], MATCH(TRUE, EXACT('輸入工具 (閩拼方案)'!G19, 韻母對照表[閩拼方案]), 0)), ""), "")} -> an | L19: {=IF(H19<>"", INDEX(上標對照表[上標值], MATCH(TRUE, EXACT('輸入工具 (閩拼方案)'!H19, 上標對照表[調號]), 0)), "")} -> ¹
B20: =ROW() - 4 -> 16 | C20: 。 | G20: =IFERROR( MID(D20, LEN(F20)+1, LEN(D20) - LEN(F20) - 1), "") | H20: =RIGHT(D20,1) | J20: {=IFERROR( IF(F20<>"", INDEX(聲母對照表[國際音標], MATCH(TRUE, EXACT('輸入工具 (閩拼方案)'!F20, 聲母對照表[閩拼方案]), 0)), ""), "")} | K20: {=IFERROR( IF(G20<>"", INDEX(韻母對照表[國際音標], MATCH(TRUE, EXACT('輸入工具 (閩拼方案)'!G20, 韻母對照表[閩拼方案]), 0)), ""), "")} | L20: {=IF(H20<>"", INDEX(上標對照表[上標值], MATCH(TRUE, EXACT('輸入工具 (閩拼方案)'!H20, 上標對照表[調號]), 0)), "")}
B21: =ROW() - 4 -> 17 | C21: 羌 | D21: gniu1 | E21: =IF(AND(F21<>"",G21<>"",H21<>""), _xlfn.CONCAT(J21:L21), "") -> kɪũ¹ | F21: g | G21: =IFERROR( MID(D21, LEN(F21)+1, LEN(D21) - LEN(F21) - 1), "") -> niu | H21: =RIGHT(D21,1) -> 1 | J21: {=IFERROR( IF(F21<>"", INDEX(聲母對照表[國際音標], MATCH(TRUE, EXACT('輸入工具 (閩拼方案)'!F21, 聲母對照表[閩拼方案]), 0)), ""), "")} -> k | K21: {=IFERROR( IF(G21<>"", INDEX(韻母對照表[國際音標], MATCH(TRUE, EXACT('輸入工具 (閩拼方案)'!G21, 韻母對照表[閩拼方案]), 0)), ""), "")} -> ɪũ | L21: {=IF(H21<>"", INDEX(上標對照表[上標值], MATCH(TRUE, EXACT('輸入工具 (閩拼方案)'!H21, 上標對照表[調號]), 0)), "")} -> ¹
B22: =ROW() - 4 -> 18 | C22: 笛 | D22: dik8 | E22: =IF(AND(F22<>"",G22<>"",H22<>""), _xlfn.CONCAT(J22:L22), "") -> tik̚⁸ | F22: d | G22: =IFERROR( MID(D22, LEN(F22)+1, LEN(D22) - LEN(F22) - 1), "") -> ik | H22: =RIGHT(D22,1) -> 8 | J22: {=IFERROR( IF(F22<>"", INDEX(聲母對照表[國際音標], MATCH(TRUE, EXACT('輸入工具 (閩拼方案)'!F22, 聲母對照表[閩拼方案]), 0)), ""), "")} -> t | K22: {=IFERROR( IF(G22<>"", INDEX(韻母對照表[國際音標], MATCH(TRUE, EXACT('輸入工具 (閩拼方案)'!G22, 韻母對照表[閩拼方案]), 0)), ""), "")} -> ik̚ | L22: {=IF(H22<>"", INDEX(上標對照表[上標值], MATCH(TRUE, EXACT('輸入工具 (閩拼方案)'!H22, 上標對照表[調號]), 0)), "")} -> ⁸
B23: =ROW() - 4 -> 19 | C23: 何 | D23: ho2 | E23: =IF(AND(F23<>"",G23<>"",H23<>""), _xlfn.CONCAT(J23:L23), "") -> hə² | F23: h | G23: =IFERROR( MID(D23, LEN(F23)+1, LEN(D23) - LEN(F23) - 1), "") -> o | H23: =RIGHT(D23,1) -> 2 | J23: {=IFERROR( IF(F23<>"", INDEX(聲母對照表[國際音標], MATCH(TRUE, EXACT('輸入工具 (閩拼方案)'!F23, 聲母對照表[閩拼方案]), 0)), ""), "")} -> h | K23: {=IFERROR( IF(G23<>"", INDEX(韻母對照表[國際音標], MATCH(TRUE, EXACT('輸入工具 (閩拼方案)'!G23, 韻母對照表[閩拼方案]), 0)), ""), "")} -> ə | L23: {=IF(H23<>"", INDEX(上標對照表[上標值], MATCH(TRUE, EXACT('輸入工具 (閩拼方案)'!H23, 上標對照表[調號]), 0)), "")} -> ²
B24: =ROW() - 4 -> 20 | C24: 須 | D24: su1 | E24: =IF(AND(F24<>"",G24<>"",H24<>""), _xlfn.CONCAT(J24:L24), "") -> su¹ | F24: s | G24: =IFERROR( MID(D24, LEN(F24)+1, LEN(D24) - LEN(F24) - 1), "") -> u | H24: =RIGHT(D24,1) -> 1 | J24: {=IFERROR( IF(F24<>"", INDEX(聲母對照表[國際音標], MATCH(TRUE, EXACT('輸入工具 (閩拼方案)'!F24, 聲母對照表[閩拼方案]), 0)), ""), "")} -> s | K24: {=IFERROR( IF(G24<>"", INDEX(韻母對照表[國際音標], MATCH(TRUE, EXACT('輸入工具 (閩拼方案)'!G24, 韻母對照表[閩拼方案]), 0)), ""), "")} -> u | L24: {=IF(H24<>"", INDEX(上標對照表[上標值], MATCH(TRUE, EXACT('輸入工具 (閩拼方案)'!H24, 上標對照表[調號]), 0)), "")} -> ¹
B25: =ROW() - 4 -> 21 | C25: 怨 | D25: wan5 | E25: =IF(AND(F25<>"",G25<>"",H25<>""), _xlfn.CONCAT(J25:L25), "") -> uan⁵ | F25: w | G25: uan | H25: =RIGHT(D25,1) -> 5 | J25: {=IFERROR( IF(F25<>"", INDEX(聲母對照表[國際音標], MATCH(TRUE, EXACT('輸入工具 (閩拼方案)'!F25, 聲母對照表[閩拼方案]), 0)), ""), "")} | K25: {=IFERROR( IF(G25<>"", INDEX(韻母對照表[國際音標], MATCH(TRUE, EXACT('輸入工具 (閩拼方案)'!G25, 韻母對照表[閩拼方案]), 0)), ""), "")} -> uan | L25: {=IF(H25<>"", INDEX(上標對照表[上標值], MATCH(TRUE, EXACT('輸入工具 (閩拼方案)'!H25, 上標對照表[調號]), 0)), "")} -> ⁵
B26: =ROW() - 4 -> 22 | C26: 楊 | D26: ynu2 | E26: =IF(AND(F26<>"",G26<>"",H26<>""), _xlfn.CONCAT(J26:L26), "") -> ɪũ² | F26: y | G26: niu | H26: =RIGHT(D26,1) -> 2 | J26: {=IFERROR( IF(F26<>"", INDEX(聲母對照表[國際音標], MATCH(TRUE, EXACT('輸入工具 (閩拼方案)'!F26, 聲母對照表[閩拼方案]), 0)), ""), "")} | K26: {=IFERROR( IF(G26<>"", INDEX(韻母對照表[國際音標], MATCH(TRUE, EXACT('輸入工具 (閩拼方案)'!G26, 韻母對照表[閩拼方案]), 0)), ""), "")} -> ɪũ | L26: {=IF(H26<>"", INDEX(上標對照表[上標值], MATCH(TRUE, EXACT('輸入工具 (閩拼方案)'!H26, 上標對照表[調號]), 0)), "")} -> ²
B27: =ROW() - 4 -> 23 | C27: 柳 | D27: liu3 | E27: =IF(AND(F27<>"",G27<>"",H27<>""), _xlfn.CONCAT(J27:L27), "") -> lɪu³ | F27: l | G27: =IFERROR( MID(D27, LEN(F27)+1, LEN(D27) - LEN(F27) - 1), "") -> iu | H27: =RIGHT(D27,1) -> 3 | J27: {=IFERROR( IF(F27<>"", INDEX(聲母對照表[國際音標], MATCH(TRUE, EXACT('輸入工具 (閩拼方案)'!F27, 聲母對照表[閩拼方案]), 0)), ""), "")} -> l | K27: {=IFERROR( IF(G27<>"", INDEX(韻母對照表[國際音標], MATCH(TRUE, EXACT('輸入工具 (閩拼方案)'!G27, 韻母對照表[閩拼方案]), 0)), ""), "")} -> ɪu | L27: {=IF(H27<>"", INDEX(上標對照表[上標值], MATCH(TRUE, EXACT('輸入工具 (閩拼方案)'!H27, 上標對照表[調號]), 0)), "")} -> ³
B28: =ROW() - 4 -> 24 | C28: ， | E28: =IF(AND(F28<>"",G28<>"",H28<>""), _xlfn.CONCAT(J28:L28), "") | G28: =IFERROR( MID(D28, LEN(F28)+1, LEN(D28) - LEN(F28) - 1), "") | H28: =RIGHT(D28,1) | J28: {=IFERROR( IF(F28<>"", INDEX(聲母對照表[國際音標], MATCH(TRUE, EXACT('輸入工具 (閩拼方案)'!F28, 聲母對照表[閩拼方案]), 0)), ""), "")} | K28: {=IFERROR( IF(G28<>"", INDEX(韻母對照表[國際音標], MATCH(TRUE, EXACT('輸入工具 (閩拼方案)'!G28, 韻母對照表[閩拼方案]), 0)), ""), "")} | L28: {=IF(H28<>"", INDEX(上標對照表[上標值], MATCH(TRUE, EXACT('輸入工具 (閩拼方案)'!H28, 上標對照表[調號]), 0)), "")}
B29: =ROW() - 4 -> 25 | C29: 春 | D29: cun1 | E29: =IF(AND(F29<>"",G29<>"",H29<>""), _xlfn.CONCAT(J29:L29), "") -> ʦʰun¹ | F29: c | G29: =IFERROR( MID(D29, LEN(F29)+1, LEN(D29) - LEN(F29) - 1), "") -> un | H29: =RIGHT(D29,1) -> 1 | J29: {=IFERROR( IF(F29<>"", INDEX(聲母對照表[國際音標], MATCH(TRUE, EXACT('輸入工具 (閩拼方案)'!F29, 聲母對照表[閩拼方案]), 0)), ""), "")} -> ʦʰ | K29: {=IFERROR( IF(G29<>"", INDEX(韻母對照表[國際音標], MATCH(TRUE, EXACT('輸入工具 (閩拼方案)'!G29, 韻母對照表[閩拼方案]), 0)), ""), "")} -> un | L29: {=IF(H29<>"", INDEX(上標對照表[上標值], MATCH(TRUE, EXACT('輸入工具 (閩拼方案)'!H29, 上標對照表[調號]), 0)), "")} -> ¹
B30: =ROW() - 4 -> 26 | C30: 風 | D30: hong1 | E30: =IF(AND(F30<>"",G30<>"",H30<>""), _xlfn.CONCAT(J30:L30), "") -> hɔŋ¹ | F30: h | G30: =IFERROR( MID(D30, LEN(F30)+1, LEN(D30) - LEN(F30) - 1), "") -> ong | H30: =RIGHT(D30,1) -> 1 | J30: {=IFERROR( IF(F30<>"", INDEX(聲母對照表[國際音標], MATCH(TRUE, EXACT('輸入工具 (閩拼方案)'!F30, 聲母對照表[閩拼方案]), 0)), ""), "")} -> h | K30: {=IFERROR( IF(G30<>"", INDEX(韻母對照表[國際音標], MATCH(TRUE, EXACT('輸入工具 (閩拼方案)'!G30, 韻母對照表[閩拼方案]), 0)), ""), "")} -> ɔŋ | L30: {=IF(H30<>"", INDEX(上標對照表[上標值], MATCH(TRUE, EXACT('輸入工具 (閩拼方案)'!H30, 上標對照表[調號]), 0)), "")} -> ¹
B31: =ROW() - 4 -> 27 | C31: 不 | D31: but7 | E31: =IF(AND(F31<>"",G31<>"",H31<>""), _xlfn.CONCAT(J31:L31), "") -> put̚⁷ | F31: b | G31: =IFERROR( MID(D31, LEN(F31)+1, LEN(D31) - LEN(F31) - 1), "") -> ut | H31: =RIGHT(D31,1) -> 7 | J31: {=IFERROR( IF(F31<>"", INDEX(聲母對照表[國際音標], MATCH(TRUE, EXACT('輸入工具 (閩拼方案)'!F31, 聲母對照表[閩拼方案]), 0)), ""), "")} -> p | K31: {=IFERROR( IF(G31<>"", INDEX(韻母對照表[國際音標], MATCH(TRUE, EXACT('輸入工具 (閩拼方案)'!G31, 韻母對照表[閩拼方案]), 0)), ""), "")} -> ut̚ | L31: {=IF(H31<>"", INDEX(上標對照表[上標值], MATCH(TRUE, EXACT('輸入工具 (閩拼方案)'!H31, 上標對照表[調號]), 0)), "")} -> ⁷
B32: =ROW() - 4 -> 28 | C32: 度 | D32: doo6 | E32: =IF(AND(F32<>"",G32<>"",H32<>""), _xlfn.CONCAT(J32:L32), "") -> tɔ⁶ | F32: d | G32: =IFERROR( MID(D32, LEN(F32)+1, LEN(D32) - LEN(F32) - 1), "") -> oo | H32: =RIGHT(D32,1) -> 6 | J32: {=IFERROR( IF(F32<>"", INDEX(聲母對照表[國際音標], MATCH(TRUE, EXACT('輸入工具 (閩拼方案)'!F32, 聲母對照表[閩拼方案]), 0)), ""), "")} -> t | K32: {=IFERROR( IF(G32<>"", INDEX(韻母對照表[國際音標], MATCH(TRUE, EXACT('輸入工具 (閩拼方案)'!G32, 韻母對照表[閩拼方案]), 0)), ""), "")} -> ɔ | L32: {=IF(H32<>"", INDEX(上標對照表[上標值], MATCH(TRUE, EXACT('輸入工具 (閩拼方案)'!H32, 上標對照表[調號]), 0)), "")} -> ⁶
B33: =ROW() - 4 -> 29 | C33: 玉 | D33: ggiok8 | E33: =IF(AND(F33<>"",G33<>"",H33<>""), _xlfn.CONCAT(J33:L33), "") -> ɡɪɔk̚⁸ | F33: gg | G33: =IFERROR( MID(D33, LEN(F33)+1, LEN(D33) - LEN(F33) - 1), "") -> iok | H33: =RIGHT(D33,1) -> 8 | J33: {=IFERROR( IF(F33<>"", INDEX(聲母對照表[國際音標], MATCH(TRUE, EXACT('輸入工具 (閩拼方案)'!F33, 聲母對照表[閩拼方案]), 0)), ""), "")} -> ɡ | K33: {=IFERROR( IF(G33<>"", INDEX(韻母對照表[國際音標], MATCH(TRUE, EXACT('輸入工具 (閩拼方案)'!G33, 韻母對照表[閩拼方案]), 0)), ""), "")} -> ɪɔk̚ | L33: {=IF(H33<>"", INDEX(上標對照表[上標值], MATCH(TRUE, EXACT('輸入工具 (閩拼方案)'!H33, 上標對照表[調號]), 0)), "")} -> ⁸
B34: =ROW() - 4 -> 30 | C34: 門 | D34: bbng2 | E34: =IF(AND(F34<>"",G34<>"",H34<>""), _xlfn.CONCAT(J34:L34), "") -> bŋ̍² | F34: bb | G34: =IFERROR( MID(D34, LEN(F34)+1, LEN(D34) - LEN(F34) - 1), "") -> ng | H34: =RIGHT(D34,1) -> 2 | J34: {=IFERROR( IF(F34<>"", INDEX(聲母對照表[國際音標], MATCH(TRUE, EXACT('輸入工具 (閩拼方案)'!F34, 聲母對照表[閩拼方案]), 0)), ""), "")} -> b | K34: {=IFERROR( IF(G34<>"", INDEX(韻母對照表[國際音標], MATCH(TRUE, EXACT('輸入工具 (閩拼方案)'!G34, 韻母對照表[閩拼方案]), 0)), ""), "")} -> ŋ̍ | L34: {=IF(H34<>"", INDEX(上標對照表[上標值], MATCH(TRUE, EXACT('輸入工具 (閩拼方案)'!H34, 上標對照表[調號]), 0)), "")} -> ²
B35: =ROW() - 4 -> 31 | C35: 關 | D35: guan1 | E35: =IF(AND(F35<>"",G35<>"",H35<>""), _xlfn.CONCAT(J35:L35), "") -> kuan¹ | F35: g | G35: =IFERROR( MID(D35, LEN(F35)+1, LEN(D35) - LEN(F35) - 1), "") -> uan | H35: =RIGHT(D35,1) -> 1 | J35: {=IFERROR( IF(F35<>"", INDEX(聲母對照表[國際音標], MATCH(TRUE, EXACT('輸入工具 (閩拼方案)'!F35, 聲母對照表[閩拼方案]), 0)), ""), "")} -> k | K35: {=IFERROR( IF(G35<>"", INDEX(韻母對照表[國際音標], MATCH(TRUE, EXACT('輸入工具 (閩拼方案)'!G35, 韻母對照表[閩拼方案]), 0)), ""), "")} -> uan | L35: {=IF(H35<>"", INDEX(上標對照表[上標值], MATCH(TRUE, EXACT('輸入工具 (閩拼方案)'!H35, 上標對照表[調號]), 0)), "")} -> ¹
B36: =ROW() - 4 -> 32 | C36: 。 | G36: =IFERROR( MID(D36, LEN(F36)+1, LEN(D36) - LEN(F36) - 1), "") | H36: =RIGHT(D36,1) | J36: {=IFERROR( IF(F36<>"", INDEX(聲母對照表[國際音標], MATCH(TRUE, EXACT('輸入工具 (閩拼方案)'!F36, 聲母對照表[閩拼方案]), 0)), ""), "")} | K36: {=IFERROR( IF(G36<>"", INDEX(韻母對照表[國際音標], MATCH(TRUE, EXACT('輸入工具 (閩拼方案)'!G36, 韻母對照表[閩拼方案]), 0)), ""), "")} | L36: {=IF(H36<>"", INDEX(上標對照表[上標值], MATCH(TRUE, EXACT('輸入工具 (閩拼方案)'!H36, 上標對照表[調號]), 0)), "")}
J39: {=IF(F39<>"", INDEX(聲母對照表[國際音標], MATCH(TRUE, EXACT('輸入工具 (閩拼方案)'!F39, 聲母對照表[閩拼方案]), 0)), "")} | K39: {=IF(G39<>"", INDEX(韻母對照表[國際音標], MATCH(TRUE, EXACT('輸入工具 (閩拼方案)'!G39, 韻母對照表[閩拼方案]), 0)), "")} | L39: {=IF(H39<>"", INDEX(#REF!, MATCH(TRUE, EXACT('輸入工具 (閩拼方案)'!H39,#REF!), 0)), "")}

Sheet 輸入工具 (台語注音二式)
B2: =_xlfn.CONCAT("【", D4, "】") -> 【閩拼方案】
B4: 序號 | C4: 漢字 | D4: 閩拼方案 | E4: 國際音標 | F4: 聲母 | G4: 韻母 | H4: 音調 | J4: 聲母 | K4: 韻母 | L4: 音調
B5: =ROW() - 4 -> 1 | C5: 黄 | D5: hong5 | E5: =IF(AND(G5<>"",H5<>""), _xlfn.CONCAT(J5:L5), "") -> hɔŋ⁵ | F5: h | G5: =IFERROR( MID(D5, LEN(F5)+1, LEN(D5) - LEN(F5) - 1), "") -> ong | H5: =RIGHT(D5,1) -> 5 | J5: {=IFERROR( IF(F5<>"", INDEX(聲母對照表[國際音標], MATCH(TRUE, EXACT('輸入工具 (台語注音二式)'!F5, 聲母對照表[注音二式]), 0)), ""), "")} -> h | K5: {=IFERROR( IF(G5<>"", INDEX(韻母對照表[國際音標], MATCH(TRUE, EXACT('輸入工具 (台語注音二式)'!G5, 韻母對照表[台語注音二式]), 0)), ""), "")} -> ɔŋ | L5: {=IF(H5<>"", INDEX(上標對照表[上標值], MATCH(TRUE, EXACT(H5, 上標對照表[調號]), 0)), "")} -> ⁵
B6: =ROW() - 4 -> 2 | C6: 河 | D6: hor5 | E6: =IF(AND(G6<>"",H6<>""), _xlfn.CONCAT(J6:L6), "") -> hə⁵ | F6: h | G6: =IFERROR( MID(D6, LEN(F6)+1, LEN(D6) - LEN(F6) - 1), "") -> or | H6: =RIGHT(D6,1) -> 5 | J6: {=IFERROR( IF(F6<>"", INDEX(聲母對照表[國際音標], MATCH(TRUE, EXACT('輸入工具 (台語注音二式)'!F6, 聲母對照表[注音二式]), 0)), ""), "")} -> h | K6: {=IFERROR( IF(G6<>"", INDEX(韻母對照表[國際音標], MATCH(TRUE, EXACT('輸入工具 (台語注音二式)'!G6, 韻母對照表[台語注音二式]), 0)), ""), "")} -> ə | L6: {=IF(H6<>"", INDEX(上標對照表[上標值], MATCH(TRUE, EXACT(H6, 上標對照表[調號]), 0)), "")} -> ⁵
B7: =ROW() - 4 -> 3 | C7: 遠 | D7: uan2 | E7: =IF(AND(G7<>"",H7<>""), _xlfn.CONCAT(J7:L7), "") -> uan² | G7: uan | H7: =RIGHT(D7,1) -> 2 | J7: {=IFERROR( IF(F7<>"", INDEX(聲母對照表[國際音標], MATCH(TRUE, EXACT('輸入工具 (台語注音二式)'!F7, 聲母對照表[注音二式]), 0)), ""), "")} | K7: {=IFERROR( IF(G7<>"", INDEX(韻母對照表[國際音標], MATCH(TRUE, EXACT('輸入工具 (台語注音二式)'!G7, 韻母對照表[台語注音二式]), 0)), ""), "")} -> uan | L7: {=IF(H7<>"", INDEX(上標對照表[上標值], MATCH(TRUE, EXACT(H7, 上標對照表[調號]), 0)), "")} -> ²
B8: =ROW() - 4 -> 4 | C8: 上 | D8: shiong2 | E8: =IF(AND(G8<>"",H8<>""), _xlfn.CONCAT(J8:L8), "") -> ɕɪɔŋ² | F8: sh | G8: =IFERROR( MID(D8, LEN(F8)+1, LEN(D8) - LEN(F8) - 1), "") -> iong | H8: =RIGHT(D8,1) -> 2 | J8: {=IFERROR( IF(F8<>"", INDEX(聲母對照表[國際音標], MATCH(TRUE, EXACT('輸入工具 (台語注音二式)'!F8, 聲母對照表[注音二式]), 0)), ""), "")} -> ɕ | K8: {=IFERROR( IF(G8<>"", INDEX(韻母對照表[國際音標], MATCH(TRUE, EXACT('輸入工具 (台語注音二式)'!G8, 韻母對照表[台語注音二式]), 0)), ""), "")} -> ɪɔŋ | L8: {=IF(H8<>"", INDEX(上標對照表[上標值], MATCH(TRUE, EXACT(H8, 上標對照表[調號]), 0)), "")} -> ²
B9: =ROW() - 4 -> 5 | C9: 白 | D9: biek8 | E9: =IF(AND(G9<>"",H9<>""), _xlfn.CONCAT(J9:L9), "") -> pik̚⁸ | F9: b | G9: =IFERROR( MID(D9, LEN(F9)+1, LEN(D9) - LEN(F9) - 1), "") -> iek | H9: =RIGHT(D9,1) -> 8 | J9: {=IFERROR( IF(F9<>"", INDEX(聲母對照表[國際音標], MATCH(TRUE, EXACT('輸入工具 (台語注音二式)'!F9, 聲母對照表[注音二式]), 0)), ""), "")} -> p | K9: {=IFERROR( IF(G9<>"", INDEX(韻母對照表[國際音標], MATCH(TRUE, EXACT('輸入工具 (台語注音二式)'!G9, 韻母對照表[台語注音二式]), 0)), ""), "")} -> ik̚ | L9: {=IF(H9<>"", INDEX(上標對照表[上標值], MATCH(TRUE, EXACT(H9, 上標對照表[調號]), 0)), "")} -> ⁸
B10: =ROW() - 4 -> 6 | C10: 雲 | D10: hun5 | E10: =IF(AND(G10<>"",H10<>""), _xlfn.CONCAT(J10:L10), "") -> hun⁵ | F10: h | G10: =IFERROR( MID(D10, LEN(F10)+1, LEN(D10) - LEN(F10) - 1), "") -> un | H10: =RIGHT(D10,1) -> 5 | J10: {=IFERROR( IF(F10<>"", INDEX(聲母對照表[國際音標], MATCH(TRUE, EXACT('輸入工具 (台語注音二式)'!F10, 聲母對照表[注音二式]), 0)), ""), "")} -> h | K10: {=IFERROR( IF(G10<>"", INDEX(韻母對照表[國際音標], MATCH(TRUE, EXACT('輸入工具 (台語注音二式)'!G10, 韻母對照表[台語注音二式]), 0)), ""), "")} -> un | L10: {=IF(H10<>"", INDEX(上標對照表[上標值], MATCH(TRUE, EXACT(H10, 上標對照表[調號]), 0)), "")} -> ⁵
B11: =ROW() - 4 -> 7 | C11: 間 | D11: gan1 | E11: =IF(AND(G11<>"",H11<>""), _xlfn.CONCAT(J11:L11), "") -> kan¹ | F11: g | G11: =IFERROR( MID(D11, LEN(F11)+1, LEN(D11) - LEN(F11) - 1), "") -> an | H11: =RIGHT(D11,1) -> 1 | J11: {=IFERROR( IF(F11<>"", INDEX(聲母對照表[國際音標], MATCH(TRUE, EXACT('輸入工具 (台語注音二式)'!F11, 聲母對照表[注音二式]), 0)), ""), "")} -> k | K11: {=IFERROR( IF(G11<>"", INDEX(韻母對照表[國際音標], MATCH(TRUE, EXACT('輸入工具 (台語注音二式)'!G11, 韻母對照表[台語注音二式]), 0)), ""), "")} -> an | L11: {=IF(H11<>"", INDEX(上標對照表[上標值], MATCH(TRUE, EXACT(H11, 上標對照表[調號]), 0)), "")} -> ¹
B12: =ROW() - 4 -> 8 | C12: ， | E12: =IF(AND(G12<>"",H12<>""), _xlfn.CONCAT(J12:L12), "") | G12: =IFERROR( MID(D12, LEN(F12)+1, LEN(D12) - LEN(F12) - 1), "") | H12: =RIGHT(D12,1) | J12: {=IFERROR( IF(F12<>"", INDEX(聲母對照表[國際音標], MATCH(TRUE, EXACT('輸入工具 (台語注音二式)'!F12, 聲母對照表[注音二式]), 0)), ""), "")} | K12: {=IFERROR( IF(G12<>"", INDEX(韻母對照表[國際音標], MATCH(TRUE, EXACT('輸入工具 (台語注音二式)'!G12, 韻母對照表[台語注音二式]), 0)), ""), "")} | L12: {=IF(H12<>"", INDEX(上標對照表[上標值], MATCH(TRUE, EXACT(H12, 上標對照表[調號]), 0)), "")}
B13: =ROW() - 4 -> 9 | C13: 一 | D13: it4 | E13: =IF(AND(G13<>"",H13<>""), _xlfn.CONCAT(J13:L13), "") -> it̚⁴ | G13: =IFERROR( MID(D13, LEN(F13)+1, LEN(D13) - LEN(F13) - 1), "") -> it | H13: =RIGHT(D13,1) -> 4 | J13: {=IFERROR( IF(F13<>"", INDEX(聲母對照表[國際音標], MATCH(TRUE, EXACT('輸入工具 (台語注音二式)'!F13, 聲母對照表[注音二式]), 0)), ""), "")} | K13: {=IFERROR( IF(G13<>"", INDEX(韻母對照表[國際音標], MATCH(TRUE, EXACT('輸入工具 (台語注音二式)'!G13, 韻母對照表[台語注音二式]), 0)), ""), "")} -> it̚ | L13: {=IF(H13<>"", INDEX(上標對照表[上標值], MATCH(TRUE, EXACT(H13, 上標對照表[調號]), 0)), "")} -> ⁴
B14: =ROW() - 4 -> 10 | C14: 片 | D14: pian3 | E14: =IF(AND(G14<>"",H14<>""), _xlfn.CONCAT(J14:L14), "") -> pʰɪan³ | F14: p | G14: =IFERROR( MID(D14, LEN(F14)+1, LEN(D14) - LEN(F14) - 1), "") -> ian | H14: =RIGHT(D14,1) -> 3 | J14: {=IFERROR( IF(F14<>"", INDEX(聲母對照表[國際音標], MATCH(TRUE, EXACT('輸入工具 (台語注音二式)'!F14, 聲母對照表[注音二式]), 0)), ""), "")} -> pʰ | K14: {=IFERROR( IF(G14<>"", INDEX(韻母對照表[國際音標], MATCH(TRUE, EXACT('輸入工具 (台語注音二式)'!G14, 韻母對照表[台語注音二式]), 0)), ""), "")} -> ɪan | L14: {=IF(H14<>"", INDEX(上標對照表[上標值], MATCH(TRUE, EXACT(H14, 上標對照表[調號]), 0)), "")} -> ³
B15: =ROW() - 4 -> 11 | C15: 孤 | D15: goo1 | E15: =IF(AND(G15<>"",H15<>""), _xlfn.CONCAT(J15:L15), "") -> kɔ¹ | F15: g | G15: =IFERROR( MID(D15, LEN(F15)+1, LEN(D15) - LEN(F15) - 1), "") -> oo | H15: =RIGHT(D15,1) -> 1 | J15: {=IFERROR( IF(F15<>"", INDEX(聲母對照表[國際音標], MATCH(TRUE, EXACT('輸入工具 (台語注音二式)'!F15, 聲母對照表[注音二式]), 0)), ""), "")} -> k | K15: {=IFERROR( IF(G15<>"", INDEX(韻母對照表[國際音標], MATCH(TRUE, EXACT('輸入工具 (台語注音二式)'!G15, 韻母對照表[台語注音二式]), 0)), ""), "")} -> ɔ | L15: {=IF(H15<>"", INDEX(上標對照表[上標值], MATCH(TRUE, EXACT(H15, 上標對照表[調號]), 0)), "")} -> ¹
B16: =ROW() - 4 -> 12 | C16: 城 | D16: sing5 | E16: =IF(AND(G16<>"",H16<>""), _xlfn.CONCAT(J16:L16), "") -> siŋ⁵ | F16: s | G16: =IFERROR( MID(D16, LEN(F16)+1, LEN(D16) - LEN(F16) - 1), "") -> ing | H16: =RIGHT(D16,1) -> 5 | J16: {=IFERROR( IF(F16<>"", INDEX(聲母對照表[國際音標], MATCH(TRUE, EXACT('輸入工具 (台語注音二式)'!F16, 聲母對照表[注音二式]), 0)), ""), "")} -> s | K16: {=IFERROR( IF(G16<>"", INDEX(韻母對照表[國際音標], MATCH(TRUE, EXACT('輸入工具 (台語注音二式)'!G16, 韻母對照表[台語注音二式]), 0)), ""), "")} -> iŋ | L16: {=IF(H16<>"", INDEX(上標對照表[上標值], MATCH(TRUE, EXACT(H16, 上標對照表[調號]), 0)), "")} -> ⁵
B17: =ROW() - 4 -> 13 | C17: 萬 | D17: bban7 | E17: =IF(AND(G17<>"",H17<>""), _xlfn.CONCAT(J17:L17), "") -> ban⁷ | F17: bb | G17: =IFERROR( MID(D17, LEN(F17)+1, LEN(D17) - LEN(F17) - 1), "") -> an | H17: =RIGHT(D17,1) -> 7 | J17: {=IFERROR( IF(F17<>"", INDEX(聲母對照表[國際音標], MATCH(TRUE, EXACT('輸入工具 (台語注音二式)'!F17, 聲母對照表[注音二式]), 0)), ""), "")} -> b | K17: {=IFERROR( IF(G17<>"", INDEX(韻母對照表[國際音標], MATCH(TRUE, EXACT('輸入工具 (台語注音二式)'!G17, 韻母對照表[台語注音二式]), 0)), ""), "")} -> an | L17: {=IF(H17<>"", INDEX(上標對照表[上標值], MATCH(TRUE, EXACT(H17, 上標對照表[調號]), 0)), "")} -> ⁷
B18: =ROW() - 4 -> 14 | C18: 仞 | D18: jjim7 | E18: =IF(AND(G18<>"",H18<>""), _xlfn.CONCAT(J18:L18), "") -> ʥim⁷ | F18: jj | G18: =IFERROR( MID(D18, LEN(F18)+1, LEN(D18) - LEN(F18) - 1), "") -> im | H18: =RIGHT(D18,1) -> 7 | J18: {=IFERROR( IF(F18<>"", INDEX(聲母對照表[國際音標], MATCH(TRUE, EXACT('輸入工具 (台語注音二式)'!F18, 聲母對照表[注音二式]), 0)), ""), "")} -> ʥ | K18: {=IFERROR( IF(G18<>"", INDEX(韻母對照表[國際音標], MATCH(TRUE, EXACT('輸入工具 (台語注音二式)'!G18, 韻母對照表[台語注音二式]), 0)), ""), "")} -> im | L18: {=IF(H18<>"", INDEX(上標對照表[上標值], MATCH(TRUE, EXACT(H18, 上標對照表[調號]), 0)), "")} -> ⁷
B19: =ROW() - 4 -> 15 | C19: 山 | D19: san1 | E19: =IF(AND(G19<>"",H19<>""), _xlfn.CONCAT(J19:L19), "") -> san¹ | F19: s | G19: =IFERROR( MID(D19, LEN(F19)+1, LEN(D19) - LEN(F19) - 1), "") -> an | H19: =RIGHT(D19,1) -> 1 | J19: {=IFERROR( IF(F19<>"", INDEX(聲母對照表[國際音標], MATCH(TRUE, EXACT('輸入工具 (台語注音二式)'!F19, 聲母對照表[注音二式]), 0)), ""), "")} -> s | K19: {=IFERROR( IF(G19<>"", INDEX(韻母對照表[國際音標], MATCH(TRUE, EXACT('輸入工具 (台語注音二式)'!G19, 韻母對照表[台語注音二式]), 0)), ""), "")} -> an | L19: {=IF(H19<>"", INDEX(上標對照表[上標值], MATCH(TRUE, EXACT(H19, 上標對照表[調號]), 0)), "")} -> ¹
B20: =ROW() - 4 -> 16 | C20: 。 | E20: =IF(AND(G20<>"",H20<>""), _xlfn.CONCAT(J20:L20), "") | G20: =IFERROR( MID(D20, LEN(F20)+1, LEN(D20) - LEN(F20) - 1), "") | H20: =RIGHT(D20,1) | J20: {=IFERROR( IF(F20<>"", INDEX(聲母對照表[國際音標], MATCH(TRUE, EXACT('輸入工具 (台語注音二式)'!F20, 聲母對照表[注音二式]), 0)), ""), "")} | K20: {=IFERROR( IF(G20<>"", INDEX(韻母對照表[國際音標], MATCH(TRUE, EXACT('輸入工具 (台語注音二式)'!G20, 韻母對照表[台語注音二式]), 0)), ""), "")} | L20: {=IF(H20<>"", INDEX(上標對照表[上標值], MATCH(TRUE, EXACT(H20, 上標對照表[調號]), 0)), "")}
B21: =ROW() - 4 -> 17 | C21: 羌 | D21: giunn1 | E21: =IF(AND(G21<>"",H21<>""), _xlfn.CONCAT(J21:L21), "") -> kɪũ¹ | F21: g | G21: =IFERROR( MID(D21, LEN(F21)+1, LEN(D21) - LEN(F21) - 1), "") -> iunn | H21: =RIGHT(D21,1) -> 1 | J21: {=IFERROR( IF(F21<>"", INDEX(聲母對照表[國際音標], MATCH(TRUE, EXACT('輸入工具 (台語注音二式)'!F21, 聲母對照表[注音二式]), 0)), ""), "")} -> k | K21: {=IFERROR( IF(G21<>"", INDEX(韻母對照表[國際音標], MATCH(TRUE, EXACT('輸入工具 (台語注音二式)'!G21, 韻母對照表[台語注音二式]), 0)), ""), "")} -> ɪũ | L21: {=IF(H21<>"", INDEX(上標對照表[上標值], MATCH(TRUE, EXACT(H21, 上標對照表[調號]), 0)), "")} -> ¹
B22: =ROW() - 4 -> 18 | C22: 笛 | D22: diek8 | E22: =IF(AND(G22<>"",H22<>""), _xlfn.CONCAT(J22:L22), "") -> tik̚⁸ | F22: d | G22: =IFERROR( MID(D22, LEN(F22)+1, LEN(D22) - LEN(F22) - 1), "") -> iek | H22: =RIGHT(D22,1) -> 8 | J22: {=IFERROR( IF(F22<>"", INDEX(聲母對照表[國際音標], MATCH(TRUE, EXACT('輸入工具 (台語注音二式)'!F22, 聲母對照表[注音二式]), 0)), ""), "")} -> t | K22: {=IFERROR( IF(G22<>"", INDEX(韻母對照表[國際音標], MATCH(TRUE, EXACT('輸入工具 (台語注音二式)'!G22, 韻母對照表[台語注音二式]), 0)), ""), "")} -> ik̚ | L22: {=IF(H22<>"", INDEX(上標對照表[上標值], MATCH(TRUE, EXACT(H22, 上標對照表[調號]), 0)), "")} -> ⁸
B23: =ROW() - 4 -> 19 | C23: 何 | D23: hor5 | E23: =IF(AND(G23<>"",H23<>""), _xlfn.CONCAT(J23:L23), "") -> hə⁵ | F23: h | G23: =IFERROR( MID(D23, LEN(F23)+1, LEN(D23) - LEN(F23) - 1), "") -> or | H23: =RIGHT(D23,1) -> 5 | J23: {=IFERROR( IF(F23<>"", INDEX(聲母對照表[國際音標], MATCH(TRUE, EXACT('輸入工具 (台語注音二式)'!F23, 聲母對照表[注音二式]), 0)), ""), "")} -> h | K23: {=IFERROR( IF(G23<>"", INDEX(韻母對照表[國際音標], MATCH(TRUE, EXACT('輸入工具 (台語注音二式)'!G23, 韻母對照表[台語注音二式]), 0)), ""), "")} -> ə | L23: {=IF(H23<>"", INDEX(上標對照表[上標值], MATCH(TRUE, EXACT(H23, 上標對照表[調號]), 0)), "")} -> ⁵
B24: =ROW() - 4 -> 20 | C24: 須 | D24: su1 | E24: =IF(AND(G24<>"",H24<>""), _xlfn.CONCAT(J24:L24), "") -> su¹ | F24: s | G24: =IFERROR( MID(D24, LEN(F24)+1, LEN(D24) - LEN(F24) - 1), "") -> u | H24: =RIGHT(D24,1) -> 1 | J24: {=IFERROR( IF(F24<>"", INDEX(聲母對照表[國際音標], MATCH(TRUE, EXACT('輸入工具 (台語注音二式)'!F24, 聲母對照表[注音二式]), 0)), ""), "")} -> s | K24: {=IFERROR( IF(G24<>"", INDEX(韻母對照表[國際音標], MATCH(TRUE, EXACT('輸入工具 (台語注音二式)'!G24, 韻母對照表[台語注音二式]), 0)), ""), "")} -> u | L24: {=IF(H24<>"", INDEX(上標對照表[上標值], MATCH(TRUE, EXACT(H24, 上標對照表[調號]), 0)), "")} -> ¹
B25: =ROW() - 4 -> 21 | C25: 怨 | D25: uan3 | E25: =IF(AND(G25<>"",H25<>""), _xlfn.CONCAT(J25:L25), "") -> uan³ | G25: =IFERROR( MID(D25, LEN(F25)+1, LEN(D25) - LEN(F25) - 1), "") -> uan | H25: =RIGHT(D25,1) -> 3 | J25: {=IFERROR( IF(F25<>"", INDEX(聲母對照表[國際音標], MATCH(TRUE, EXACT('輸入工具 (台語注音二式)'!F25, 聲母對照表[注音二式]), 0)), ""), "")} | K25: {=IFERROR( IF(G25<>"", INDEX(韻母對照表[國際音標], MATCH(TRUE, EXACT('輸入工具 (台語注音二式)'!G25, 韻母對照表[台語注音二式]), 0)), ""), "")} -> uan | L25: {=IF(H25<>"", INDEX(上標對照表[上標值], MATCH(TRUE, EXACT(H25, 上標對照表[調號]), 0)), "")} -> ³
B26: =ROW() - 4 -> 22 | C26: 楊 | D26: iunn5 | E26: =IF(AND(G26<>"",H26<>""), _xlfn.CONCAT(J26:L26), "") -> ɪũ⁵ | G26: =IFERROR( MID(D26, LEN(F26)+1, LEN(D26) - LEN(F26) - 1), "") -> iunn | H26: =RIGHT(D26,1) -> 5 | J26: {=IFERROR( IF(F26<>"", INDEX(聲母對照表[國際音標], MATCH(TRUE, EXACT('輸入工具 (台語注音二式)'!F26, 聲母對照表[注音二式]), 0)), ""), "")} | K26: {=IFERROR( IF(G26<>"", INDEX(韻母對照表[國際音標], MATCH(TRUE, EXACT('輸入工具 (台語注音二式)'!G26, 韻母對照表[台語注音二式]), 0)), ""), "")} -> ɪũ | L26: {=IF(H26<>"", INDEX(上標對照表[上標值], MATCH(TRUE, EXACT(H26, 上標對照表[調號]), 0)), "")} -> ⁵
B27: =ROW() - 4 -> 23 | C27: 柳 | D27: liu2 | E27: =IF(AND(G27<>"",H27<>""), _xlfn.CONCAT(J27:L27), "") -> lɪu² | F27: l | G27: =IFERROR( MID(D27, LEN(F27)+1, LEN(D27) - LEN(F27) - 1), "") -> iu | H27: =RIGHT(D27,1) -> 2 | J27: {=IFERROR( IF(F27<>"", INDEX(聲母對照表[國際音標], MATCH(TRUE, EXACT('輸入工具 (台語注音二式)'!F27, 聲母對照表[注音二式]), 0)), ""), "")} -> l | K27: {=IFERROR( IF(G27<>"", INDEX(韻母對照表[國際音標], MATCH(TRUE, EXACT('輸入工具 (台語注音二式)'!G27, 韻母對照表[台語注音二式]), 0)), ""), "")} -> ɪu | L27: {=IF(H27<>"", INDEX(上標對照表[上標值], MATCH(TRUE, EXACT(H27, 上標對照表[調號]), 0)), "")} -> ²
B28: =ROW() - 4 -> 24 | C28: ， | E28: =IF(AND(G28<>"",H28<>""), _xlfn.CONCAT(J28:L28), "") | G28: =IFERROR( MID(D28, LEN(F28)+1, LEN(D28) - LEN(F28) - 1), "") | H28: =RIGHT(D28,1) | J28: {=IFERROR( IF(F28<>"", INDEX(聲母對照表[國際音標], MATCH(TRUE, EXACT('輸入工具 (台語注音二式)'!F28, 聲母對照表[注音二式]), 0)), ""), "")} | K28: {=IFERROR( IF(G28<>"", INDEX(韻母對照表[國際音標], MATCH(TRUE, EXACT('輸入工具 (台語注音二式)'!G28, 韻母對照表[台語注音二式]), 0)), ""), "")} | L28: {=IF(H28<>"", INDEX(上標對照表[上標值], MATCH(TRUE, EXACT(H28, 上標對照表[調號]), 0)), "")}
B29: =ROW() - 4 -> 25 | C29: 春 | D29: cun1 | E29: =IF(AND(G29<>"",H29<>""), _xlfn.CONCAT(J29:L29), "") -> ʦʰun¹ | F29: c | G29: =IFERROR( MID(D29, LEN(F29)+1, LEN(D29) - LEN(F29) - 1), "") -> un | H29: =RIGHT(D29,1) -> 1 | J29: {=IFERROR( IF(F29<>"", INDEX(聲母對照表[國際音標], MATCH(TRUE, EXACT('輸入工具 (台語注音二式)'!F29, 聲母對照表[注音二式]), 0)), ""), "")} -> ʦʰ | K29: {=IFERROR( IF(G29<>"", INDEX(韻母對照表[國際音標], MATCH(TRUE, EXACT('輸入工具 (台語注音二式)'!G29, 韻母對照表[台語注音二式]), 0)), ""), "")} -> un | L29: {=IF(H29<>"", INDEX(上標對照表[上標值], MATCH(TRUE, EXACT(H29, 上標對照表[調號]), 0)), "")} -> ¹
B30: =ROW() - 4 -> 26 | C30: 風 | D30: hong1 | E30: =IF(AND(G30<>"",H30<>""), _xlfn.CONCAT(J30:L30), "") -> hɔŋ¹ | F30: h | G30: =IFERROR( MID(D30, LEN(F30)+1, LEN(D30) - LEN(F30) - 1), "") -> ong | H30: =RIGHT(D30,1) -> 1 | J30: {=IFERROR( IF(F30<>"", INDEX(聲母對照表[國際音標], MATCH(TRUE, EXACT('輸入工具 (台語注音二式)'!F30, 聲母對照表[注音二式]), 0)), ""), "")} -> h | K30: {=IFERROR( IF(G30<>"", INDEX(韻母對照表[國際音標], MATCH(TRUE, EXACT('輸入工具 (台語注音二式)'!G30, 韻母對照表[台語注音二式]), 0)), ""), "")} -> ɔŋ | L30: {=IF(H30<>"", INDEX(上標對照表[上標值], MATCH(TRUE, EXACT(H30, 上標對照表[調號]), 0)), "")} -> ¹
B31: =ROW() - 4 -> 27 | C31: 不 | D31: but4 | E31: =IF(AND(G31<>"",H31<>""), _xlfn.CONCAT(J31:L31), "") -> put̚⁴ | F31: b | G31: =IFERROR( MID(D31, LEN(F31)+1, LEN(D31) - LEN(F31) - 1), "") -> ut | H31: =RIGHT(D31,1) -> 4 | J31: {=IFERROR( IF(F31<>"", INDEX(聲母對照表[國際音標], MATCH(TRUE, EXACT('輸入工具 (台語注音二式)'!F31, 聲母對照表[注音二式]), 0)), ""), "")} -> p | K31: {=IFERROR( IF(G31<>"", INDEX(韻母對照表[國際音標], MATCH(TRUE, EXACT('輸入工具 (台語注音二式)'!G31, 韻母對照表[台語注音二式]), 0)), ""), "")} -> ut̚ | L31: {=IF(H31<>"", INDEX(上標對照表[上標值], MATCH(TRUE, EXACT(H31, 上標對照表[調號]), 0)), "")} -> ⁴
B32: =ROW() - 4 -> 28 | C32: 度 | D32: doo7 | E32: =IF(AND(G32<>"",H32<>""), _xlfn.CONCAT(J32:L32), "") -> tɔ⁷ | F32: d | G32: =IFERROR( MID(D32, LEN(F32)+1, LEN(D32) - LEN(F32) - 1), "") -> oo | H32: =RIGHT(D32,1) -> 7 | J32: {=IFERROR( IF(F32<>"", INDEX(聲母對照表[國際音標], MATCH(TRUE, EXACT('輸入工具 (台語注音二式)'!F32, 聲母對照表[注音二式]), 0)), ""), "")} -> t | K32: {=IFERROR( IF(G32<>"", INDEX(韻母對照表[國際音標], MATCH(TRUE, EXACT('輸入工具 (台語注音二式)'!G32, 韻母對照表[台語注音二式]), 0)), ""), "")} -> ɔ | L32: {=IF(H32<>"", INDEX(上標對照表[上標值], MATCH(TRUE, EXACT(H32, 上標對照表[調號]), 0)), "")} -> ⁷
B33: =ROW() - 4 -> 29 | C33: 玉 | D33: ggiook8 | E33: =IF(AND(G33<>"",H33<>""), _xlfn.CONCAT(J33:L33), "") -> ɡɪɔk̚⁸ | F33: gg | G33: =IFERROR( MID(D33, LEN(F33)+1, LEN(D33) - LEN(F33) - 1), "") -> iook | H33: =RIGHT(D33,1) -> 8 | J33: {=IFERROR( IF(F33<>"", INDEX(聲母對照表[國際音標], MATCH(TRUE, EXACT('輸入工具 (台語注音二式)'!F33, 聲母對照表[注音二式]), 0)), ""), "")} -> ɡ | K33: {=IFERROR( IF(G33<>"", INDEX(韻母對照表[國際音標], MATCH(TRUE, EXACT('輸入工具 (台語注音二式)'!G33, 韻母對照表[台語注音二式]), 0)), ""), "")} -> ɪɔk̚ | L33: {=IF(H33<>"", INDEX(上標對照表[上標值], MATCH(TRUE, EXACT(H33, 上標對照表[調號]), 0)), "")} -> ⁸
B34: =ROW() - 4 -> 30 | C34: 門 | D34: mng5 | E34: =IF(AND(G34<>"",H34<>""), _xlfn.CONCAT(J34:L34), "") -> mŋ̍⁵ | F34: m | G34: =IFERROR( MID(D34, LEN(F34)+1, LEN(D34) - LEN(F34) - 1), "") -> ng | H34: =RIGHT(D34,1) -> 5 | J34: {=IFERROR( IF(F34<>"", INDEX(聲母對照表[國際音標], MATCH(TRUE, EXACT('輸入工具 (台語注音二式)'!F34, 聲母對照表[注音二式]), 0)), ""), "")} -> m | K34: {=IFERROR( IF(G34<>"", INDEX(韻母對照表[國際音標], MATCH(TRUE, EXACT('輸入工具 (台語注音二式)'!G34, 韻母對照表[台語注音二式]), 0)), ""), "")} -> ŋ̍ | L34: {=IF(H34<>"", INDEX(上標對照表[上標值], MATCH(TRUE, EXACT(H34, 上標對照表[調號]), 0)), "")} -> ⁵
B35: =ROW() - 4 -> 31 | C35: 關 | D35: guan1 | E35: =IF(AND(G35<>"",H35<>""), _xlfn.CONCAT(J35:L35), "") -> kuan¹ | F35: g | G35: =IFERROR( MID(D35, LEN(F35)+1, LEN(D35) - LEN(F35) - 1), "") -> uan | H35: =RIGHT(D35,1) -> 1 | J35: {=IFERROR( IF(F35<>"", INDEX(聲母對照表[國際音標], MATCH(TRUE, EXACT('輸入工具 (台語注音二式)'!F35, 聲母對照表[注音二式]), 0)), ""), "")} -> k | K35: {=IFERROR( IF(G35<>"", INDEX(韻母對照表[國際音標], MATCH(TRUE, EXACT('輸入工具 (台語注音二式)'!G35, 韻母對照表[台語注音二式]), 0)), ""), "")} -> uan | L35: {=IF(H35<>"", INDEX(上標對照表[上標值], MATCH(TRUE, EXACT(H35, 上標對照表[調號]), 0)), "")} -> ¹
B36: =ROW() - 4 -> 32 | C36: 。 | E36: =IF(AND(G36<>"",H36<>""), _xlfn.CONCAT(J36:L36), "") | G36: =IFERROR( MID(D36, LEN(F36)+1, LEN(D36) - LEN(F36) - 1), "") | H36: =RIGHT(D36,1) | J36: {=IFERROR( IF(F36<>"", INDEX(聲母對照表[國際音標], MATCH(TRUE, EXACT('輸入工具 (台語注音二式)'!F36, 聲母對照表[閩拼方案]), 0)), ""), "")} | K36: {=IFERROR( IF(G36<>"", INDEX(韻母對照表[國際音標], MATCH(TRUE, EXACT('輸入工具 (台語注音二式)'!G36, 韻母對照表[閩拼方案]), 0)), ""), "")} | L36: {=IF(H36<>"", INDEX(上標對照表[上標值], MATCH(TRUE, EXACT(H36, 上標對照表[調號]), 0)), "")}
J39: {=IF(F39<>"", INDEX(聲母對照表[國際音標], MATCH(TRUE, EXACT('輸入工具 (台語注音二式)'!F39, 聲母對照表[閩拼方案]), 0)), "")} | K39: {=IF(G39<>"", INDEX(韻母對照表[國際音標], MATCH(TRUE, EXACT('輸入工具 (台語注音二式)'!G39, 韻母對照表[閩拼方案]), 0)), "")} | L39: {=IF(H39<>"", INDEX(#REF!, MATCH(TRUE, EXACT('輸入工具 (台語注音二式)'!H39,#REF!), 0)), "")}

Sheet 輸入工具 (台語音標)
B2: =_xlfn.CONCAT("【", D4, "】") -> 【台語音標】
B4: 序號 | C4: 漢字 | D4: 台語音標 | E4: 國際音標 | F4: 聲母 | G4: 韻母 | H4: 音調 | J4: 聲母 | K4: 韻母 | L4: 音調
B5: =ROW() - 4 -> 1 | C5: 黄 | D5: hong5 | E5: =IF(AND(G5<>"",H5<>""), _xlfn.CONCAT(J5:L5), "") -> hɔŋ⁵ | F5: h | G5: =IFERROR( MID(D5, LEN(F5)+1, LEN(D5) - LEN(F5) - 1), "") -> ong | H5: =RIGHT(D5,1) -> 5 | J5: {=IFERROR( IF(F5<>"", INDEX(聲母對照表[國際音標], MATCH(TRUE, EXACT('輸入工具 (台語音標)'!F5, 聲母對照表[台語音標]), 0)), ""), "")} -> h | K5: {=IFERROR( IF(G5<>"", INDEX(韻母對照表[國際音標], MATCH(TRUE, EXACT('輸入工具 (台語音標)'!G5, 韻母對照表[台語音標]), 0)), ""), "")} -> ɔŋ | L5: {=IF(H5<>"", INDEX(上標對照表[上標值], MATCH(TRUE, EXACT(H5, 上標對照表[調號]), 0)), "")} -> ⁵
B6: =ROW() - 4 -> 2 | C6: 河 | D6: ho5 | E6: =IF(AND(G6<>"",H6<>""), _xlfn.CONCAT(J6:L6), "") -> hə⁵ | F6: h | G6: =IFERROR( MID(D6, LEN(F6)+1, LEN(D6) - LEN(F6) - 1), "") -> o | H6: =RIGHT(D6,1) -> 5 | J6: {=IFERROR( IF(F6<>"", INDEX(聲母對照表[國際音標], MATCH(TRUE, EXACT('輸入工具 (台語音標)'!F6, 聲母對照表[台語音標]), 0)), ""), "")} -> h | K6: {=IFERROR( IF(G6<>"", INDEX(韻母對照表[國際音標], MATCH(TRUE, EXACT('輸入工具 (台語音標)'!G6, 韻母對照表[台語音標]), 0)), ""), "")} -> ə | L6: {=IF(H6<>"", INDEX(上標對照表[上標值], MATCH(TRUE, EXACT(H6, 上標對照表[調號]), 0)), "")} -> ⁵
B7: =ROW() - 4 -> 3 | C7: 遠 | D7: uan2 | E7: =IF(AND(G7<>"",H7<>""), _xlfn.CONCAT(J7:L7), "") -> uan² | G7: uan | H7: =RIGHT(D7,1) -> 2 | J7: {=IFERROR( IF(F7<>"", INDEX(聲母對照表[國際音標], MATCH(TRUE, EXACT('輸入工具 (台語音標)'!F7, 聲母對照表[台語音標]), 0)), ""), "")} | K7: {=IFERROR( IF(G7<>"", INDEX(韻母對照表[國際音標], MATCH(TRUE, EXACT('輸入工具 (台語音標)'!G7, 韻母對照表[台語音標]), 0)), ""), "")} -> uan | L7: {=IF(H7<>"", INDEX(上標對照表[上標值], MATCH(TRUE, EXACT(H7, 上標對照表[調號]), 0)), "")} -> ²
B8: =ROW() - 4 -> 4 | C8: 上 | D8: siong2 | E8: =IF(AND(G8<>"",H8<>""), _xlfn.CONCAT(J8:L8), "") -> sɪɔŋ² | F8: s | G8: =IFERROR( MID(D8, LEN(F8)+1, LEN(D8) - LEN(F8) - 1), "") -> iong | H8: =RIGHT(D8,1) -> 2 | J8: {=IFERROR( IF(F8<>"", INDEX(聲母對照表[國際音標], MATCH(TRUE, EXACT('輸入工具 (台語音標)'!F8, 聲母對照表[台語音標]), 0)), ""), "")} -> s | K8: {=IFERROR( IF(G8<>"", INDEX(韻母對照表[國際音標], MATCH(TRUE, EXACT('輸入工具 (台語音標)'!G8, 韻母對照表[台語音標]), 0)), ""), "")} -> ɪɔŋ | L8: {=IF(H8<>"", INDEX(上標對照表[上標值], MATCH(TRUE, EXACT(H8, 上標對照表[調號]), 0)), "")} -> ²
B9: =ROW() - 4 -> 5 | C9: 白 | D9: pik8 | E9: =IF(AND(G9<>"",H9<>""), _xlfn.CONCAT(J9:L9), "") -> pik̚⁸ | F9: p | G9: =IFERROR( MID(D9, LEN(F9)+1, LEN(D9) - LEN(F9) - 1), "") -> ik | H9: =RIGHT(D9,1) -> 8 | J9: {=IFERROR( IF(F9<>"", INDEX(聲母對照表[國際音標], MATCH(TRUE, EXACT('輸入工具 (台語音標)'!F9, 聲母對照表[台語音標]), 0)), ""), "")} -> p | K9: {=IFERROR( IF(G9<>"", INDEX(韻母對照表[國際音標], MATCH(TRUE, EXACT('輸入工具 (台語音標)'!G9, 韻母對照表[台語音標]), 0)), ""), "")} -> ik̚ | L9: {=IF(H9<>"", INDEX(上標對照表[上標值], MATCH(TRUE, EXACT(H9, 上標對照表[調號]), 0)), "")} -> ⁸
B10: =ROW() - 4 -> 6 | C10: 雲 | D10: hun5 | E10: =IF(AND(G10<>"",H10<>""), _xlfn.CONCAT(J10:L10), "") -> hun⁵ | F10: h | G10: =IFERROR( MID(D10, LEN(F10)+1, LEN(D10) - LEN(F10) - 1), "") -> un | H10: =RIGHT(D10,1) -> 5 | J10: {=IFERROR( IF(F10<>"", INDEX(聲母對照表[國際音標], MATCH(TRUE, EXACT('輸入工具 (台語音標)'!F10, 聲母對照表[台語音標]), 0)), ""), "")} -> h | K10: {=IFERROR( IF(G10<>"", INDEX(韻母對照表[國際音標], MATCH(TRUE, EXACT('輸入工具 (台語音標)'!G10, 韻母對照表[台語音標]), 0)), ""), "")} -> un | L10: {=IF(H10<>"", INDEX(上標對照表[上標值], MATCH(TRUE, EXACT(H10, 上標對照表[調號]), 0)), "")} -> ⁵
B11: =ROW() - 4 -> 7 | C11: 間 | D11: kan1 | E11: =IF(AND(G11<>"",H11<>""), _xlfn.CONCAT(J11:L11), "") -> kan¹ | F11: k | G11: =IFERROR( MID(D11, LEN(F11)+1, LEN(D11) - LEN(F11) - 1), "") -> an | H11: =RIGHT(D11,1) -> 1 | J11: {=IFERROR( IF(F11<>"", INDEX(聲母對照表[國際音標], MATCH(TRUE, EXACT('輸入工具 (台語音標)'!F11, 聲母對照表[台語音標]), 0)), ""), "")} -> k | K11: {=IFERROR( IF(G11<>"", INDEX(韻母對照表[國際音標], MATCH(TRUE, EXACT('輸入工具 (台語音標)'!G11, 韻母對照表[台語音標]), 0)), ""), "")} -> an | L11: {=IF(H11<>"", INDEX(上標對照表[上標值], MATCH(TRUE, EXACT(H11, 上標對照表[調號]), 0)), "")} -> ¹
B12: =ROW() - 4 -> 8 | C12: ， | E12: =IF(AND(G12<>"",H12<>""), _xlfn.CONCAT(J12:L12), "") | G12: =IFERROR( MID(D12, LEN(F12)+1, LEN(D12) - LEN(F12) - 1), "") | H12: =RIGHT(D12,1) | J12: {=IFERROR( IF(F12<>"", INDEX(聲母對照表[國際音標], MATCH(TRUE, EXACT('輸入工具 (台語音標)'!F12, 聲母對照表[台語音標]), 0)), ""), "")} | K12: {=IFERROR( IF(G12<>"", INDEX(韻母對照表[國際音標], MATCH(TRUE, EXACT('輸入工具 (台語音標)'!G12, 韻母對照表[台語音標]), 0)), ""), "")} | L12: {=IF(H12<>"", INDEX(上標對照表[上標值], MATCH(TRUE, EXACT(H12, 上標對照表[調號]), 0)), "")}
B13: =ROW() - 4 -> 9 | C13: 一 | D13: it4 | E13: =IF(AND(G13<>"",H13<>""), _xlfn.CONCAT(J13:L13), "") -> it̚⁴ | G13: =IFERROR( MID(D13, LEN(F13)+1, LEN(D13) - LEN(F13) - 1), "") -> it | H13: =RIGHT(D13,1) -> 4 | J13: {=IFERROR( IF(F13<>"", INDEX(聲母對照表[國際音標], MATCH(TRUE, EXACT('輸入工具 (台語音標)'!F13, 聲母對照表[台語音標]), 0)), ""), "")} | K13: {=IFERROR( IF(G13<>"", INDEX(韻母對照表[國際音標], MATCH(TRUE, EXACT('輸入工具 (台語音標)'!G13, 韻母對照表[台語音標]), 0)), ""), "")} -> it̚ | L13: {=IF(H13<>"", INDEX(上標對照表[上標值], MATCH(TRUE, EXACT(H13, 上標對照表[調號]), 0)), "")} -> ⁴
B14: =ROW() - 4 -> 10 | C14: 片 | D14: phian3 | E14: =IF(AND(G14<>"",H14<>""), _xlfn.CONCAT(J14:L14), "") -> pʰɪan³ | F14: ph | G14: =IFERROR( MID(D14, LEN(F14)+1, LEN(D14) - LEN(F14) - 1), "") -> ian | H14: =RIGHT(D14,1) -> 3 | J14: {=IFERROR( IF(F14<>"", INDEX(聲母對照表[國際音標], MATCH(TRUE, EXACT('輸入工具 (台語音標)'!F14, 聲母對照表[台語音標]), 0)), ""), "")} -> pʰ | K14: {=IFERROR( IF(G14<>"", INDEX(韻母對照表[國際音標], MATCH(TRUE, EXACT('輸入工具 (台語音標)'!G14, 韻母對照表[台語音標]), 0)), ""), "")} -> ɪan | L14: {=IF(H14<>"", INDEX(上標對照表[上標值], MATCH(TRUE, EXACT(H14, 上標對照表[調號]), 0)), "")} -> ³
B15: =ROW() - 4 -> 11 | C15: 孤 | D15: koo1 | E15: =IF(AND(G15<>"",H15<>""), _xlfn.CONCAT(J15:L15), "") -> ɡɔ¹ | F15: g | G15: =IFERROR( MID(D15, LEN(F15)+1, LEN(D15) - LEN(F15) - 1), "") -> oo | H15: =RIGHT(D15,1) -> 1 | J15: {=IFERROR( IF(F15<>"", INDEX(聲母對照表[國際音標], MATCH(TRUE, EXACT('輸入工具 (台語音標)'!F15, 聲母對照表[台語音標]), 0)), ""), "")} -> ɡ | K15: {=IFERROR( IF(G15<>"", INDEX(韻母對照表[國際音標], MATCH(TRUE, EXACT('輸入工具 (台語音標)'!G15, 韻母對照表[台語音標]), 0)), ""), "")} -> ɔ | L15: {=IF(H15<>"", INDEX(上標對照表[上標值], MATCH(TRUE, EXACT(H15, 上標對照表[調號]), 0)), "")} -> ¹
B16: =ROW() - 4 -> 12 | C16: 城 | D16: sing5 | E16: =IF(AND(G16<>"",H16<>""), _xlfn.CONCAT(J16:L16), "") -> siŋ⁵ | F16: s | G16: =IFERROR( MID(D16, LEN(F16)+1, LEN(D16) - LEN(F16) - 1), "") -> ing | H16: =RIGHT(D16,1) -> 5 | J16: {=IFERROR( IF(F16<>"", INDEX(聲母對照表[國際音標], MATCH(TRUE, EXACT('輸入工具 (台語音標)'!F16, 聲母對照表[台語音標]), 0)), ""), "")} -> s | K16: {=IFERROR( IF(G16<>"", INDEX(韻母對照表[國際音標], MATCH(TRUE, EXACT('輸入工具 (台語音標)'!G16, 韻母對照表[台語音標]), 0)), ""), "")} -> iŋ | L16: {=IF(H16<>"", INDEX(上標對照表[上標值], MATCH(TRUE, EXACT(H16, 上標對照表[調號]), 0)), "")} -> ⁵
B17: =ROW() - 4 -> 13 | C17: 萬 | D17: ban7 | E17: =IF(AND(G17<>"",H17<>""), _xlfn.CONCAT(J17:L17), "") -> ban⁷ | F17: b | G17: =IFERROR( MID(D17, LEN(F17)+1, LEN(D17) - LEN(F17) - 1), "") -> an | H17: =RIGHT(D17,1) -> 7 | J17: {=IFERROR( IF(F17<>"", INDEX(聲母對照表[國際音標], MATCH(TRUE, EXACT('輸入工具 (台語音標)'!F17, 聲母對照表[台語音標]), 0)), ""), "")} -> b | K17: {=IFERROR( IF(G17<>"", INDEX(韻母對照表[國際音標], MATCH(TRUE, EXACT('輸入工具 (台語音標)'!G17, 韻母對照表[台語音標]), 0)), ""), "")} -> an | L17: {=IF(H17<>"", INDEX(上標對照表[上標值], MATCH(TRUE, EXACT(H17, 上標對照表[調號]), 0)), "")} -> ⁷
B18: =ROW() - 4 -> 14 | C18: 仞 | D18: jim7 | E18: =IF(AND(G18<>"",H18<>""), _xlfn.CONCAT(J18:L18), "") -> ʣim⁷ | F18: j | G18: =IFERROR( MID(D18, LEN(F18)+1, LEN(D18) - LEN(F18) - 1), "") -> im | H18: =RIGHT(D18,1) -> 7 | J18: {=IFERROR( IF(F18<>"", INDEX(聲母對照表[國際音標], MATCH(TRUE, EXACT('輸入工具 (台語音標)'!F18, 聲母對照表[台語音標]), 0)), ""), "")} -> ʣ | K18: {=IFERROR( IF(G18<>"", INDEX(韻母對照表[國際音標], MATCH(TRUE, EXACT('輸入工具 (台語音標)'!G18, 韻母對照表[台語音標]), 0)), ""), "")} -> im | L18: {=IF(H18<>"", INDEX(上標對照表[上標值], MATCH(TRUE, EXACT(H18, 上標對照表[調號]), 0)), "")} -> ⁷
B19: =ROW() - 4 -> 15 | C19: 山 | D19: san1 | E19: =IF(AND(G19<>"",H19<>""), _xlfn.CONCAT(J19:L19), "") -> san¹ | F19: s | G19: =IFERROR( MID(D19, LEN(F19)+1, LEN(D19) - LEN(F19) - 1), "") -> an | H19: =RIGHT(D19,1) -> 1 | J19: {=IFERROR( IF(F19<>"", INDEX(聲母對照表[國際音標], MATCH(TRUE, EXACT('輸入工具 (台語音標)'!F19, 聲母對照表[台語音標]), 0)), ""), "")} -> s | K19: {=IFERROR( IF(G19<>"", INDEX(韻母對照表[國際音標], MATCH(TRUE, EXACT('輸入工具 (台語音標)'!G19, 韻母對照表[台語音標]), 0)), ""), "")} -> an | L19: {=IF(H19<>"", INDEX(上標對照表[上標值], MATCH(TRUE, EXACT(H19, 上標對照表[調號]), 0)), "")} -> ¹
B20: =ROW() - 4 -> 16 | C20: 。 | E20: =IF(AND(G20<>"",H20<>""), _xlfn.CONCAT(J20:L20), "") | G20: =IFERROR( MID(D20, LEN(F20)+1, LEN(D20) - LEN(F20) - 1), "") | H20: =RIGHT(D20,1) | J20: {=IFERROR( IF(F20<>"", INDEX(聲母對照表[國際音標], MATCH(TRUE, EXACT('輸入工具 (台語音標)'!F20, 聲母對照表[台語音標]), 0)), ""), "")} | K20: {=IFERROR( IF(G20<>"", INDEX(韻母對照表[國際音標], MATCH(TRUE, EXACT('輸入工具 (台語音標)'!G20, 韻母對照表[台語音標]), 0)), ""), "")} | L20: {=IF(H20<>"", INDEX(上標對照表[上標值], MATCH(TRUE, EXACT(H20, 上標對照表[調號]), 0)), "")}
B21: =ROW() - 4 -> 17 | C21: 羌 | D21: kiunn1 | E21: =IF(AND(G21<>"",H21<>""), _xlfn.CONCAT(J21:L21), "") -> kɪũ¹ | F21: k | G21: =IFERROR( MID(D21, LEN(F21)+1, LEN(D21) - LEN(F21) - 1), "") -> iunn | H21: =RIGHT(D21,1) -> 1 | J21: {=IFERROR( IF(F21<>"", INDEX(聲母對照表[國際音標], MATCH(TRUE, EXACT('輸入工具 (台語音標)'!F21, 聲母對照表[台語音標]), 0)), ""), "")} -> k | K21: {=IFERROR( IF(G21<>"", INDEX(韻母對照表[國際音標], MATCH(TRUE, EXACT('輸入工具 (台語音標)'!G21, 韻母對照表[台語音標]), 0)), ""), "")} -> ɪũ | L21: {=IF(H21<>"", INDEX(上標對照表[上標值], MATCH(TRUE, EXACT(H21, 上標對照表[調號]), 0)), "")} -> ¹
B22: =ROW() - 4 -> 18 | C22: 笛 | D22: tik8 | E22: =IF(AND(G22<>"",H22<>""), _xlfn.CONCAT(J22:L22), "") -> tik̚⁸ | F22: t | G22: =IFERROR( MID(D22, LEN(F22)+1, LEN(D22) - LEN(F22) - 1), "") -> ik | H22: =RIGHT(D22,1) -> 8 | J22: {=IFERROR( IF(F22<>"", INDEX(聲母對照表[國際音標], MATCH(TRUE, EXACT('輸入工具 (台語音標)'!F22, 聲母對照表[台語音標]), 0)), ""), "")} -> t | K22: {=IFERROR( IF(G22<>"", INDEX(韻母對照表[國際音標], MATCH(TRUE, EXACT('輸入工具 (台語音標)'!G22, 韻母對照表[台語音標]), 0)), ""), "")} -> ik̚ | L22: {=IF(H22<>"", INDEX(上標對照表[上標值], MATCH(TRUE, EXACT(H22, 上標對照表[調號]), 0)), "")} -> ⁸
B23: =ROW() - 4 -> 19 | C23: 何 | D23: ho5 | E23: =IF(AND(G23<>"",H23<>""), _xlfn.CONCAT(J23:L23), "") -> hə⁵ | F23: h | G23: =IFERROR( MID(D23, LEN(F23)+1, LEN(D23) - LEN(F23) - 1), "") -> o | H23: =RIGHT(D23,1) -> 5 | J23: {=IFERROR( IF(F23<>"", INDEX(聲母對照表[國際音標], MATCH(TRUE, EXACT('輸入工具 (台語音標)'!F23, 聲母對照表[台語音標]), 0)), ""), "")} -> h | K23: {=IFERROR( IF(G23<>"", INDEX(韻母對照表[國際音標], MATCH(TRUE, EXACT('輸入工具 (台語音標)'!G23, 韻母對照表[台語音標]), 0)), ""), "")} -> ə | L23: {=IF(H23<>"", INDEX(上標對照表[上標值], MATCH(TRUE, EXACT(H23, 上標對照表[調號]), 0)), "")} -> ⁵
B24: =ROW() - 4 -> 20 | C24: 須 | D24: su1 | E24: =IF(AND(G24<>"",H24<>""), _xlfn.CONCAT(J24:L24), "") -> su¹ | F24: s | G24: =IFERROR( MID(D24, LEN(F24)+1, LEN(D24) - LEN(F24) - 1), "") -> u | H24: =RIGHT(D24,1) -> 1 | J24: {=IFERROR( IF(F24<>"", INDEX(聲母對照表[國際音標], MATCH(TRUE, EXACT('輸入工具 (台語音標)'!F24, 聲母對照表[台語音標]), 0)), ""), "")} -> s | K24: {=IFERROR( IF(G24<>"", INDEX(韻母對照表[國際音標], MATCH(TRUE, EXACT('輸入工具 (台語音標)'!G24, 韻母對照表[台語音標]), 0)), ""), "")} -> u | L24: {=IF(H24<>"", INDEX(上標對照表[上標值], MATCH(TRUE, EXACT(H24, 上標對照表[調號]), 0)), "")} -> ¹
B25: =ROW() - 4 -> 21 | C25: 怨 | D25: uan3 | E25: =IF(AND(G25<>"",H25<>""), _xlfn.CONCAT(J25:L25), "") -> uan³ | G25: =IFERROR( MID(D25, LEN(F25)+1, LEN(D25) - LEN(F25) - 1), "") -> uan | H25: =RIGHT(D25,1) -> 3 | J25: {=IFERROR( IF(F25<>"", INDEX(聲母對照表[國際音標], MATCH(TRUE, EXACT('輸入工具 (台語音標)'!F25, 聲母對照表[台語音標]), 0)), ""), "")} | K25: {=IFERROR( IF(G25<>"", INDEX(韻母對照表[國際音標], MATCH(TRUE, EXACT('輸入工具 (台語音標)'!G25, 韻母對照表[台語音標]), 0)), ""), "")} -> uan | L25: {=IF(H25<>"", INDEX(上標對照表[上標值], MATCH(TRUE, EXACT(H25, 上標對照表[調號]), 0)), "")} -> ³
B26: =ROW() - 4 -> 22 | C26: 楊 | D26: iunn5 | E26: =IF(AND(G26<>"",H26<>""), _xlfn.CONCAT(J26:L26), "") -> ɪũ⁵ | G26: =IFERROR( MID(D26, LEN(F26)+1, LEN(D26) - LEN(F26) - 1), "") -> iunn | H26: =RIGHT(D26,1) -> 5 | J26: {=IFERROR( IF(F26<>"", INDEX(聲母對照表[國際音標], MATCH(TRUE, EXACT('輸入工具 (台語音標)'!F26, 聲母對照表[台語音標]), 0)), ""), "")} | K26: {=IFERROR( IF(G26<>"", INDEX(韻母對照表[國際音標], MATCH(TRUE, EXACT('輸入工具 (台語音標)'!G26, 韻母對照表[台語音標]), 0)), ""), "")} -> ɪũ | L26: {=IF(H26<>"", INDEX(上標對照表[上標值], MATCH(TRUE, EXACT(H26, 上標對照表[調號]), 0)), "")} -> ⁵
B27: =ROW() - 4 -> 23 | C27: 柳 | D27: liu2 | E27: =IF(AND(G27<>"",H27<>""), _xlfn.CONCAT(J27:L27), "") -> lɪu² | F27: l | G27: =IFERROR( MID(D27, LEN(F27)+1, LEN(D27) - LEN(F27) - 1), "") -> iu | H27: =RIGHT(D27,1) -> 2 | J27: {=IFERROR( IF(F27<>"", INDEX(聲母對照表[國際音標], MATCH(TRUE, EXACT('輸入工具 (台語音標)'!F27, 聲母對照表[台語音標]), 0)), ""), "")} -> l | K27: {=IFERROR( IF(G27<>"", INDEX(韻母對照表[國際音標], MATCH(TRUE, EXACT('輸入工具 (台語音標)'!G27, 韻母對照表[台語音標]), 0)), ""), "")} -> ɪu | L27: {=IF(H27<>"", INDEX(上標對照表[上標值], MATCH(TRUE, EXACT(H27, 上標對照表[調號]), 0)), "")} -> ²
B28: =ROW() - 4 -> 24 | C28: ， | E28: =IF(AND(G28<>"",H28<>""), _xlfn.CONCAT(J28:L28), "") | G28: =IFERROR( MID(D28, LEN(F28)+1, LEN(D28) - LEN(F28) - 1), "") | H28: =RIGHT(D28,1) | J28: {=IFERROR( IF(F28<>"", INDEX(聲母對照表[國際音標], MATCH(TRUE, EXACT('輸入工具 (台語音標)'!F28, 聲母對照表[台語音標]), 0)), ""), "")} | K28: {=IFERROR( IF(G28<>"", INDEX(韻母對照表[國際音標], MATCH(TRUE, EXACT('輸入工具 (台語音標)'!G28, 韻母對照表[台語音標]), 0)), ""), "")} | L28: {=IF(H28<>"", INDEX(上標對照表[上標值], MATCH(TRUE, EXACT(H28, 上標對照表[調號]), 0)), "")}
B29: =ROW() - 4 -> 25 | C29: 春 | D29: cun1 | E29: =IF(AND(G29<>"",H29<>""), _xlfn.CONCAT(J29:L29), "") -> ʦʰun¹ | F29: c | G29: =IFERROR( MID(D29, LEN(F29)+1, LEN(D29) - LEN(F29) - 1), "") -> un | H29: =RIGHT(D29,1) -> 1 | J29: {=IFERROR( IF(F29<>"", INDEX(聲母對照表[國際音標], MATCH(TRUE, EXACT('輸入工具 (台語音標)'!F29, 聲母對照表[台語音標]), 0)), ""), "")} -> ʦʰ | K29: {=IFERROR( IF(G29<>"", INDEX(韻母對照表[國際音標], MATCH(TRUE, EXACT('輸入工具 (台語音標)'!G29, 韻母對照表[台語音標]), 0)), ""), "")} -> un | L29: {=IF(H29<>"", INDEX(上標對照表[上標值], MATCH(TRUE, EXACT(H29, 上標對照表[調號]), 0)), "")} -> ¹
B30: =ROW() - 4 -> 26 | C30: 風 | D30: hong1 | E30: =IF(AND(G30<>"",H30<>""), _xlfn.CONCAT(J30:L30), "") -> hɔŋ¹ | F30: h | G30: =IFERROR( MID(D30, LEN(F30)+1, LEN(D30) - LEN(F30) - 1), "") -> ong | H30: =RIGHT(D30,1) -> 1 | J30: {=IFERROR( IF(F30<>"", INDEX(聲母對照表[國際音標], MATCH(TRUE, EXACT('輸入工具 (台語音標)'!F30, 聲母對照表[台語音標]), 0)), ""), "")} -> h | K30: {=IFERROR( IF(G30<>"", INDEX(韻母對照表[國際音標], MATCH(TRUE, EXACT('輸入工具 (台語音標)'!G30, 韻母對照表[台語音標]), 0)), ""), "")} -> ɔŋ | L30: {=IF(H30<>"", INDEX(上標對照表[上標值], MATCH(TRUE, EXACT(H30, 上標對照表[調號]), 0)), "")} -> ¹
B31: =ROW() - 4 -> 27 | C31: 不 | D31: put4 | E31: =IF(AND(G31<>"",H31<>""), _xlfn.CONCAT(J31:L31), "") -> put̚⁴ | F31: p | G31: =IFERROR( MID(D31, LEN(F31)+1, LEN(D31) - LEN(F31) - 1), "") -> ut | H31: =RIGHT(D31,1) -> 4 | J31: {=IFERROR( IF(F31<>"", INDEX(聲母對照表[國際音標], MATCH(TRUE, EXACT('輸入工具 (台語音標)'!F31, 聲母對照表[台語音標]), 0)), ""), "")} -> p | K31: {=IFERROR( IF(G31<>"", INDEX(韻母對照表[國際音標], MATCH(TRUE, EXACT('輸入工具 (台語音標)'!G31, 韻母對照表[台語音標]), 0)), ""), "")} -> ut̚ | L31: {=IF(H31<>"", INDEX(上標對照表[上標值], MATCH(TRUE, EXACT(H31, 上標對照表[調號]), 0)), "")} -> ⁴
B32: =ROW() - 4 -> 28 | C32: 度 | D32: too7 | E32: =IF(AND(G32<>"",H32<>""), _xlfn.CONCAT(J32:L32), "") -> tɔ⁷ | F32: t | G32: =IFERROR( MID(D32, LEN(F32)+1, LEN(D32) - LEN(F32) - 1), "") -> oo | H32: =RIGHT(D32,1) -> 7 | J32: {=IFERROR( IF(F32<>"", INDEX(聲母對照表[國際音標], MATCH(TRUE, EXACT('輸入工具 (台語音標)'!F32, 聲母對照表[台語音標]), 0)), ""), "")} -> t | K32: {=IFERROR( IF(G32<>"", INDEX(韻母對照表[國際音標], MATCH(TRUE, EXACT('輸入工具 (台語音標)'!G32, 韻母對照表[台語音標]), 0)), ""), "")} -> ɔ | L32: {=IF(H32<>"", INDEX(上標對照表[上標值], MATCH(TRUE, EXACT(H32, 上標對照表[調號]), 0)), "")} -> ⁷
B33: =ROW() - 4 -> 29 | C33: 玉 | D33: giok8 | E33: =IF(AND(G33<>"",H33<>""), _xlfn.CONCAT(J33:L33), "") -> ɡɪɔk̚⁸ | F33: g | G33: =IFERROR( MID(D33, LEN(F33)+1, LEN(D33) - LEN(F33) - 1), "") -> iok | H33: =RIGHT(D33,1) -> 8 | J33: {=IFERROR( IF(F33<>"", INDEX(聲母對照表[國際音標], MATCH(TRUE, EXACT('輸入工具 (台語音標)'!F33, 聲母對照表[台語音標]), 0)), ""), "")} -> ɡ | K33: {=IFERROR( IF(G33<>"", INDEX(韻母對照表[國際音標], MATCH(TRUE, EXACT('輸入工具 (台語音標)'!G33, 韻母對照表[台語音標]), 0)), ""), "")} -> ɪɔk̚ | L33: {=IF(H33<>"", INDEX(上標對照表[上標值], MATCH(TRUE, EXACT(H33, 上標對照表[調號]), 0)), "")} -> ⁸
B34: =ROW() - 4 -> 30 | C34: 門 | D34: mng5 | E34: =IF(AND(G34<>"",H34<>""), _xlfn.CONCAT(J34:L34), "") -> mŋ̍⁵ | F34: m | G34: =IFERROR( MID(D34, LEN(F34)+1, LEN(D34) - LEN(F34) - 1), "") -> ng | H34: =RIGHT(D34,1) -> 5 | J34: {=IFERROR( IF(F34<>"", INDEX(聲母對照表[國際音標], MATCH(TRUE, EXACT('輸入工具 (台語音標)'!F34, 聲母對照表[台語音標]), 0)), ""), "")} -> m | K34: {=IFERROR( IF(G34<>"", INDEX(韻母對照表[國際音標], MATCH(TRUE, EXACT('輸入工具 (台語音標)'!G34, 韻母對照表[台語音標]), 0)), ""), "")} -> ŋ̍ | L34: {=IF(H34<>"", INDEX(上標對照表[上標值], MATCH(TRUE, EXACT(H34, 上標對照表[調號]), 0)), "")} -> ⁵
B35: =ROW() - 4 -> 31 | C35: 關 | D35: kuan1 | E35: =IF(AND(G35<>"",H35<>""), _xlfn.CONCAT(J35:L35), "") -> kuan¹ | F35: k | G35: =IFERROR( MID(D35, LEN(F35)+1, LEN(D35) - LEN(F35) - 1), "") -> uan | H35: =RIGHT(D35,1) -> 1 | J35: {=IFERROR( IF(F35<>"", INDEX(聲母對照表[國際音標], MATCH(TRUE, EXACT('輸入工具 (台語音標)'!F35, 聲母對照表[台語音標]), 0)), ""), "")} -> k | K35: {=IFERROR( IF(G35<>"", INDEX(韻母對照表[國際音標], MATCH(TRUE, EXACT('輸入工具 (台語音標)'!G35, 韻母對照表[台語音標]), 0)), ""), "")} -> uan | L35: {=IF(H35<>"", INDEX(上標對照表[上標值], MATCH(TRUE, EXACT(H35, 上標對照表[調號]), 0)), "")} -> ¹
B36: =ROW() - 4 -> 32 | C36: 。 | E36: =IF(AND(G36<>"",H36<>""), _xlfn.CONCAT(J36:L36), "") | G36: =IFERROR( MID(D36, LEN(F36)+1, LEN(D36) - LEN(F36) - 1), "") | H36: =RIGHT(D36,1) | J36: {=IFERROR( IF(F36<>"", INDEX(聲母對照表[國際音標], MATCH(TRUE, EXACT('輸入工具 (台語音標)'!F36, 聲母對照表[台語音標]), 0)), ""), "")} | K36: {=IFERROR( IF(G36<>"", INDEX(韻母對照表[國際音標], MATCH(TRUE, EXACT('輸入工具 (台語音標)'!G36, 韻母對照表[台語音標]), 0)), ""), "")} | L36: {=IF(H36<>"", INDEX(上標對照表[上標值], MATCH(TRUE, EXACT(H36, 上標對照表[調號]), 0)), "")}
J39: {=IF(F39<>"", INDEX(聲母對照表[國際音標], MATCH(TRUE, EXACT('輸入工具 (台語音標)'!F39, 聲母對照表[閩拼方案]), 0)), "")} | K39: {=IF(G39<>"", INDEX(韻母對照表[國際音標], MATCH(TRUE, EXACT('輸入工具 (台語音標)'!G39, 韻母對照表[閩拼方案]), 0)), "")} | L39: {=IF(H39<>"", INDEX(#REF!, MATCH(TRUE, EXACT('輸入工具 (台語音標)'!H39,#REF!), 0)), "")}

Sheet 輸入工具 (台羅拼音)
B2: =_xlfn.CONCAT("【", D4, "】") -> 【閩拼方案】
B4: 序號 | C4: 漢字 | D4: 閩拼方案 | E4: 國際音標 | F4: 聲母 | G4: 韻母 | H4: 音調 | J4: 聲母 | K4: 韻母 | L4: 音調
B5: =ROW() - 4 -> 1 | C5: 黄 | D5: hong5 | E5: =IF(AND(G5<>"",H5<>""), _xlfn.CONCAT(J5:L5), "") -> hɔŋ⁵ | F5: h | G5: =IFERROR( MID(D5, LEN(F5)+1, LEN(D5) - LEN(F5) - 1), "") -> ong | H5: =RIGHT(D5,1) -> 5 | J5: {=IFERROR( IF(F5<>"", INDEX(聲母對照表[國際音標], MATCH(TRUE, EXACT('輸入工具 (台羅拼音)'!F5, 聲母對照表[台羅拼音]), 0)), ""), "")} -> h | K5: {=IFERROR( IF(G5<>"", INDEX(韻母對照表[國際音標], MATCH(TRUE, EXACT('輸入工具 (台羅拼音)'!G5, 韻母對照表[台羅拼音]), 0)), ""), "")} -> ɔŋ | L5: {=IF(H5<>"", INDEX(上標對照表[上標值], MATCH(TRUE, EXACT(H5, 上標對照表[調號]), 0)), "")} -> ⁵
B6: =ROW() - 4 -> 2 | C6: 河 | D6: ho5 | E6: =IF(AND(G6<>"",H6<>""), _xlfn.CONCAT(J6:L6), "") -> hə⁵ | F6: h | G6: =IFERROR( MID(D6, LEN(F6)+1, LEN(D6) - LEN(F6) - 1), "") -> o | H6: =RIGHT(D6,1) -> 5 | J6: {=IFERROR( IF(F6<>"", INDEX(聲母對照表[國際音標], MATCH(TRUE, EXACT('輸入工具 (台羅拼音)'!F6, 聲母對照表[台羅拼音]), 0)), ""), "")} -> h | K6: {=IFERROR( IF(G6<>"", INDEX(韻母對照表[國際音標], MATCH(TRUE, EXACT('輸入工具 (台羅拼音)'!G6, 韻母對照表[台羅拼音]), 0)), ""), "")} -> ə | L6: {=IF(H6<>"", INDEX(上標對照表[上標值], MATCH(TRUE, EXACT(H6, 上標對照表[調號]), 0)), "")} -> ⁵
B7: =ROW() - 4 -> 3 | C7: 遠 | D7: uan2 | E7: =IF(AND(G7<>"",H7<>""), _xlfn.CONCAT(J7:L7), "") -> uan² | G7: uan | H7: =RIGHT(D7,1) -> 2 | J7: {=IFERROR( IF(F7<>"", INDEX(聲母對照表[國際音標], MATCH(TRUE, EXACT('輸入工具 (台羅拼音)'!F7, 聲母對照表[台羅拼音]), 0)), ""), "")} | K7: {=IFERROR( IF(G7<>"", INDEX(韻母對照表[國際音標], MATCH(TRUE, EXACT('輸入工具 (台羅拼音)'!G7, 韻母對照表[台羅拼音]), 0)), ""), "")} -> uan | L7: {=IF(H7<>"", INDEX(上標對照表[上標值], MATCH(TRUE, EXACT(H7, 上標對照表[調號]), 0)), "")} -> ²
