Workbook

Sheet 【聲】聲母表
A1: 十五音序 | B1: 十五音 | C1: 漢字例 | D1: 國際音標 | E1: 備註 | H1: 注音序 | I1: 台羅拼音 | J1: 台語注音 | K1: 方音符號 | L1: 台語音標 | M1: 白話字 | N1: 注音二式 | O1: 閩拼方案 | P1: 備註 | S1: 注音序 | T1: 台羅拼音 | U1: 台語注音 | V1: 方音符號
A2: 1 | B2: 柳 | C2: 理 | D2: l | H2: 1 | I2: p | J2: ㄅ | K2: ㄅ | L2: p | M2: p | N2: b | O2: b | S2: 4 | T2: b | U2: ㄪ | V2: ㆠ
A3: 2 | B3: 耐 | C3: 耐 | D3: n | E3: l/n 本不分，此處分柳/耐 | H3: 2 | I3: ph | J3: ㄆ | K3: ㄆ | L3: ph | M3: ph | N3: p | O3: p | S3: 11 | T3: ng | U3: ⁰ㄫ | V3: ㄫ
A4: 3 | B4: 邊 | C4: 比 | D4: p | H4: 3 | I4: m | J4: ㄇ | K4: ㄇ | L4: m | M4: m | N4: m | O4: bbn | S4: 12 | T4: g | U4: ㄫ | V4: ㆣ
A5: 4 | B5: 求 | C5: 己 | D5: k | H5: 4 | I5: b | J5: ㄪ | K5: ㆠ | L5: b | M5: b | N5: bb | O5: bb | S5: 16 | T5: j | U5: ㄖ | V5: ㆡ
A6: 5 | B6: 去 | C6: 起 | D6: kʰ | H6: 5 | I6: t | J6: ㄉ | K6: ㄉ | L6: t | M6: t | N6: d | O6: d | S6: 22 | T6: j+i | U6: ㄖ | V6: ㆢ
A7: 6 | B7: 地 | C7: 底 | D7: t | H7: 6 | I7: th | J7: ㄊ | K7: ㄊ | L7: th | M7: th | N7: t | O7: t
A8: 7 | B8: 頗 | C8: 鄙 | D8: pʰ | H8: 7 | I8: n | J8: ㄋ | K8: ㄋ | L8: n | M8: n | N8: n | O8: ln
A9: 8 | B9: 他 | C9: 恥 | D9: tʰ | H9: 8 | I9: l | J9: ㄌ | K9: ㄌ | L9: l | M9: l | N9: l | O9: l
A10: 9 | B10: 曾 | C10: 阻 | D10: ʦ | H10: 9 | I10: k | J10: ㄍ | K10: ㄍ | L10: k | M10: k | N10: g | O10: g
A11: 10 | B11: 入 | C11: 熱 | D11: ʣ | H11: 10 | I11: kh | J11: ㄎ | K11: ㄎ | L11: kh | M11: kh | N11: k | O11: k
A12: 11 | B12: 時 | C12: 詞 | D12: s | H12: 11 | I12: ng | J12: ⁰ㄫ | K12: ㄫ | L12: ng | M12: ng | N12: ng | O12: ggn
A13: 12 | B13: 英 | C13: 以 | E13: Ø | H13: 12 | I13: g | J13: ㄫ | K13: ㆣ | L13: g | M13: g | N13: gg | O13: gg
A14: 13 | B14: 門 | C14: 美 | D14: b | H14: 13 | I14: ts | J14: ㄗ | K14: ㄗ | L14: z | M14: ch | N14: z | O14: z
A15: 14 | B15: 毛 | C15: 毛 | D15: m | E15: b/m 本不分，此處分門/毛 | H15: 14 | I15: tsh | J15: ㄘ | K15: ㄘ | L15: c | M15: chh | N15: c | O15: c
A16: 15 | B16: 語 | C16: 禦 | D16: ɡ | H16: 15 | I16: s | J16: ㄙ | K16: ㄙ | L16: s | M16: s | N16: s | O16: s
A17: 16 | B17: 雅 | C17: 雅 | D17: ŋ | E17: g/ng 本不分，此處分語/雅 | H17: 16 | I17: j | J17: ㄖ | K17: ㆡ | L17: j | M17: j | N17: zz | O17: zz
A18: 17 | B18: 出 | C18: 取 | D18: ʦʰ | H18: 17 | I18: h | J18: ㄏ | K18: ㄏ | L18: h | M18: h | N18: h | O18: h
A19: 18 | B19: 喜 | C19: 喜 | D19: h | H19: 18 | I19: Ø | J19: Ø | K19: Ø | L19: Ø | M19: Ø | N19: Ø | O19: Ø | P19: 零聲母
A20: 19 | B20: 入 | C20: 熱 | D20: ʥ | E20: ㆢ = ㆡㄧ | H20: 19 | I20: ts+i | J20: ㄐ | K20: ㄐ | L20: zi | M20: chi | N20: j | O20: zi | P20: ㄐ = ㄗㄧ
A21: 20 | B21: 曾 | C21: 止 | D21: ʨ | E21: ㄐ = ㄗㄧ | H21: 20 | I21: tsh+i | J21: ㄑ | K21: ㄑ | L21: ci | M21: chhi | N21: ch | O21: ci | P21: ㄑ = ㄘㄧ
A22: 21 | B22: 出 | C22: 測 | D22: ʨʰ | E22: ㄑ = ㄘㄧ | H22: 21 | I22: s+i | J22: ㄒ | K22: ㄒ | L22: si | M22: si | N22: sh | O22: si | P22: ㄒ = ㄙㄧ
A23: 22 | B23: 時 | C23: 惜 | D23: ɕ | E23: ㄒ = ㄙㄧ | H23: 22 | I23: j+i | J23: ㄖ | K23: ㆢ | L23: ji | M23: ji | N23: jj | O23: zzi | P23: ㆢ = ㆡㄧ

Sheet 【韻】韻母表
A3: 序號 | B3: 台羅拼音 | C3: 台語注音 | D3: 方音符號 | E3: 十五音 | F3: 漢字例 | G3: 十五音識別碼 | J3: 序號 | K3: 台羅拼音 | L3: 台語注音 | M3: 方音符號
A4: =ROW() - 3 -> 1 | B4: a | C4: ㄚ | D4: ㄚ | E4: =LEFT(韻母對照表[[#This Row],[十五音識別碼]],1) -> 膠 | F4: 些 | G4: 膠舒 | J4: 2 | K4: ah | L4: ㄚㄏ | M4: ㄚㆷ
A5: =ROW() - 3 -> 2 | B5: ah | C5: ㄚㄏ | D5: ㄚㆷ | E5: =LEFT(韻母對照表[[#This Row],[十五音識別碼]],1) -> 膠 | F5: 百 | G5: 膠促 | J5: 3 | K5: ai | L5: ㄞ | M5: ㄞ
A6: =ROW() - 3 -> 3 | B6: ai | C6: ㄞ | D6: ㄞ | E6: =LEFT(韻母對照表[[#This Row],[十五音識別碼]],1) -> 皆 | F6: 埃 | G6: 皆舒 | J6: 4 | K6: aih | L6: ㄞㄏ | M6: ㄞㆷ
A7: =ROW() - 3 -> 4 | B7: aih | C7: ㄞㄏ | D7: ㄞㆷ | E7: =LEFT(韻母對照表[[#This Row],[十五音識別碼]],1) -> 皆 | F7: ◯ | G7: 皆促 | J7: 5 | K7: ainn | L7: ⁰ㄞ | M7: ㆮ
A8: =ROW() - 3 -> 5 | B8: ainn | C8: ⁰ㄞ | D8: ㆮ | E8: =LEFT(韻母對照表[[#This Row],[十五音識別碼]],1) -> 閒 | F8: 挨 | G8: 閒舒 | J8: 6 | K8: ak | L8: ㄚㄍ | M8: ㄚㆻ
A9: =ROW() - 3 -> 6 | B9: ak | C9: ㄚㄍ | D9: ㄚㆻ | E9: =LEFT(韻母對照表[[#This Row],[十五音識別碼]],1) -> 江 | F9: 角 | G9: 江促 | J9: 7 | K9: am | L9: ㄚㄇ | M9: ㆰ
A10: =ROW() - 3 -> 7 | B10: am | C10: ㄚㄇ | D10: ㆰ | E10: =LEFT(韻母對照表[[#This Row],[十五音識別碼]],1) -> 甘 | F10: 堪 | G10: 甘舒 | J10: 8 | K10: an | L10: ㄢ | M10: ㄢ
A11: =ROW() - 3 -> 8 | B11: an | C11: ㄢ | D11: ㄢ | E11: =LEFT(韻母對照表[[#This Row],[十五音識別碼]],1) -> 干 | F11: 蘭 | G11: 干舒 | J11: 9 | K11: ang | L11: ㄤ | M11: ㄤ
A12: =ROW() - 3 -> 9 | B12: ang | C12: ㄤ | D12: ㄤ | E12: =LEFT(韻母對照表[[#This Row],[十五音識別碼]],1) -> 江 | F12: 邦 | G12: 江舒 | J12: 10 | K12: ann | L12: ⁰ㄚ | M12: ㆩ
A13: =ROW() - 3 -> 10 | B13: ann | C13: ⁰ㄚ | D13: ㆩ | E13: =LEFT(韻母對照表[[#This Row],[十五音識別碼]],1) -> 監 | F13: 聽 | G13: 監舒 | J13: 11 | K13: annh | L13: ⁰ㄚㄏ | M13: ㆩㆷ
A14: =ROW() - 3 -> 11 | B14: annh | C14: ⁰ㄚㄏ | D14: ㆩㆷ | E14: =LEFT(韻母對照表[[#This Row],[十五音識別碼]],1) -> 監 | F14: 含 | G14: 監促 | J14: 12 | K14: ap | L14: ㄚㄅ | M14: ㄚㆴ
A15: =ROW() - 3 -> 12 | B15: ap | C15: ㄚㄅ | D15: ㄚㆴ | E15: =LEFT(韻母對照表[[#This Row],[十五音識別碼]],1) -> 甘 | F15: 答 | G15: 甘促 | J15: 13 | K15: at | L15: ㄚㄉ | M15: ㄚㆵ
... A88: =ROW() - 3 -> 85 | B88: un | C88: ㄨㄣ | D88: ㄨㄣ | E88: =LEFT(韻母對照表[[#This Row],[十五音識別碼]],1) -> 君 | F88: 汾 | G88: 君舒 | J88: 86 | K88: ut | L88: ㄨㄉ | M88: ㄨㆵ
A89: =ROW() - 3 -> 86 | B89: ut | C89: ㄨㄉ | D89: ㄨㆵ | E89: =LEFT(韻母對照表[[#This Row],[十五音識別碼]],1) -> 君 | F89: 不 | G89: 君促

Sheet 【聲】聲母排序表 (2)
A1: 十五音序 | B1: 十五音 | C1: 漢字例 | D1: 國際音標 | E1: 備註 | H1: 注音序 | I1: 方音符號 | J1: 台語注音 | K1: 台羅拼音 | L1: 台語音標 | M1: 白話字 | N1: 注音二式 | O1: 閩拼方案 | P1: 備註
A2: 1 | B2: 柳 | C2: 理 | D2: l | H2: 1 | I2: ㄅ | J2: ㄅ | K2: p | L2: p | M2: p | N2: b | O2: b
A3: 2 | B3: 耐 | C3: 耐 | D3: n | E3: l/n 本不分，此處分柳/耐 | H3: 2 | I3: ㄆ | J3: ㄆ | K3: ph | L3: ph | M3: ph | N3: p | O3: p
A4: 3 | B4: 邊 | C4: 比 | D4: p | H4: 3 | I4: ㄇ | J4: ㄇ | K4: m | L4: m | M4: m | N4: m | O4: bbn
A5: 4 | B5: 求 | C5: 己 | D5: k | H5: 4 | I5: ㆠ | J5: ㄪ | K5: b | L5: b | M5: b | N5: bb | O5: bb
A6: 5 | B6: 去 | C6: 起 | D6: kʰ | H6: 5 | I6: ㄉ | J6: ㄉ | K6: t | L6: t | M6: t | N6: d | O6: d
A7: 6 | B7: 地 | C7: 底 | D7: t | H7: 6 | I7: ㄊ | J7: ㄊ | K7: th | L7: th | M7: th | N7: t | O7: t
A8: 7 | B8: 頗 | C8: 鄙 | D8: pʰ | H8: 7 | I8: ㄋ | J8: ㄋ | K8: n | L8: n | M8: n | N8: n | O8: ln
A9: 8 | B9: 他 | C9: 恥 | D9: tʰ | H9: 8 | I9: ㄌ | J9: ㄌ | K9: l | L9: l | M9: l | N9: l | O9: l
A10: 9 | B10: 曾 | C10: 阻 | D10: ʦ | H10: 9 | I10: ㄍ | J10: ㄍ | K10: k | L10: k | M10: k | N10: g | O10: g
A11: 10 | B11: 入 | C11: 熱 | D11: ʣ | H11: 10 | I11: ㄎ | J11: ㄎ | K11: kh | L11: kh | M11: kh | N11: k | O11: k
A12: 11 | B12: 時 | C12: 詞 | D12: s | H12: 11 | I12: ㄫ | J12: ⁰ㄫ | K12: ng | L12: ng | M12: ng | N12: ng | O12: ggn
A13: 12 | B13: 英 | C13: 以 | E13: Ø | H13: 12 | I13: ㆣ | J13: ㄫ | K13: g | L13: g | M13: g | N13: gg | O13: gg
A14: 13 | B14: 門 | C14: 美 | D14: b | H14: 13 | I14: ㄗ | J14: ㄗ | K14: ts | L14: z | M14: ch | N14: z | O14: z
A15: 14 | B15: 毛 | C15: 毛 | D15: m | E15: b/m 本不分，此處分門/毛 | H15: 14 | I15: ㄘ | J15: ㄘ | K15: tsh | L15: c | M15: chh | N15: c | O15: c
A16: 15 | B16: 語 | C16: 禦 | D16: ɡ | H16: 15 | I16: ㄙ | J16: ㄙ | K16: s | L16: s | M16: s | N16: s | O16: s
A17: 16 | B17: 雅 | C17: 雅 | D17: ŋ | E17: g/ng 本不分，此處分語/雅 | H17: 16 | I17: ㆡ | J17: ㄖ | K17: j | L17: j | M17: j | N17: zz | O17: zz
A18: 17 | B18: 出 | C18: 取 | D18: ʦʰ | H18: 17 | I18: ㄏ | J18: ㄏ | K18: h | L18: h | M18: h | N18: h | O18: h
A19: 18 | B19: 喜 | C19: 喜 | D19: h | H19: 18 | I19: Ø | J19: Ø | K19: Ø | L19: Ø | M19: Ø | N19: Ø | O19: Ø | P19: 零聲母
A20: 19 | B20: 入 | C20: 熱 | D20: ʥ | E20: ㆢ = ㆡㄧ | H20: 19 | I20: ㄐ | J20: ㄐ | K20: tsi | L20: zi | M20: chi | N20: j | O20: zi | P20: ㄐ = ㄗㄧ
A21: 20 | B21: 曾 | C21: 止 | D21: ʨ | E21: ㄐ = ㄗㄧ | H21: 20 | I21: ㄑ | J21: ㄑ | K21: tshi | L21: ci | M21: chhi | N21: ch | O21: ci | P21: ㄑ = ㄘㄧ
A22: 21 | B22: 出 | C22: 測 | D22: ʨʰ | E22: ㄑ = ㄘㄧ | H22: 21 | I22: ㄒ | J22: ㄒ | K22: si | L22: si | M22: si | N22: sh | O22: si | P22: ㄒ = ㄙㄧ
A23: 22 | B23: 時 | C23: 惜 | D23: ɕ | E23: ㄒ = ㄙㄧ | H23: 22 | I23: ㆢ | J23: ㄖ | K23: ji | L23: ji | M23: ji | N23: jj | O23: zzi | P23: ㆢ = ㆡㄧ

Sheet 【聲】聲母對照表
A1: 識別號 | B1: 序號 | C1: 國際音標 | D1: 台羅拼音 | E1: 台語音標 | F1: 注音二式 | G1: 閩拼方案 | H1: 白話字 | I1: 方音符號 | J1: 台語注音 | K1: 十五音 | L1: 漢字例 | M1: 備註 | N1: s1 | O1: s2 | P1: s3
A2: 1 | B2: 7 | C2: l | D2: l | E2: l | F2: l | G2: l | H2: l | I2: ㄌ | J2: ㄌ | K2: 柳 | L2: 理 | N2: 7 | O2: l | P2: l
A3: 2 | B3: 4 | C3: p | D3: p | E3: p | F3: b | G3: b | H3: p | I3: ㄅ | J3: ㄅ | K3: 邊 | L3: 比 | N3: 4 | O3: b | P3: b
A4: 3 | B4: 12 | C4: k | D4: k | E4: k | F4: g | G4: g | H4: k | I4: ㄍ | J4: ㄍ | K4: 求 | L4: 己 | N4: 12 | O4: g | P4: g
A5: 4 | B5: 13 | C5: kʰ | D5: kh | E5: kh | F5: k | G5: k | H5: kh | I5: ㄎ | J5: ㄎ | K5: 去 | L5: 起 | N5: 13 | O5: k | P5: k
A6: 5 | B6: 8 | C6: t | D6: t | E6: t | F6: d | G6: d | H6: t | I6: ㄉ | J6: ㄉ | K6: 地 | L6: 底 | N6: 8 | O6: d | P6: d
A7: 6 | B7: 5 | C7: pʰ | D7: ph | E7: ph | F7: p | G7: p | H7: ph | I7: ㄆ | J7: ㄆ | K7: 頗 | L7: 鄙 | N7: 5 | O7: p | P7: p
A8: 7 | B8: 9 | C8: tʰ | D8: th | E8: th | F8: t | G8: t | H8: th | I8: ㄊ | J8: ㄊ | K8: 他 | L8: 恥 | N8: 9 | O8: t | P8: t
A9: 8 | B9: 15 | C9: ʦ | D9: ts | E9: z | F9: z | G9: z | H9: ch | I9: ㄗ | J9: ㄗ | K9: 曾 | L9: 阻 | N9: 15 | O9: z | P9: z
A10: 9 | B10: 14 | C10: ʣ | D10: j | E10: j | F10: zz | G10: zz | H10: j | I10: ㆡ | J10: ㄖ | K10: 入 | L10: 熱 | N10: 14 | O10: zz | P10: zz
A11: 10 | B11: 17 | C11: s | D11: s | E11: s | F11: s | G11: s | H11: s | I11: ㄙ | J11: ㄙ | K11: 時 | L11: 詞 | N11: 17 | O11: s | P11: s
A12: 11 | B12: 1 | K12: 英 | L12: 以 | M12: Ø | N12: 1 | O12: Ø | P12: Ø
A13: 12 | B13: 3 | C13: b | D13: b | E13: b | F13: bb | G13: bb | H13: b | I13: ㆠ | J13: ㄪ | K13: 門 | L13: 美 | N13: 3 | O13: bb | P13: bb
A14: 13 | B14: 11 | C14: ɡ | D14: g | E14: g | F14: gg | G14: gg | H14: g | I14: ㆣ | J14: ㄫ | K14: 語 | L14: 禦 | N14: 11 | O14: gg | P14: gg
A15: 14 | B15: 16 | C15: ʦʰ | D15: tsh | E15: c | F15: c | G15: c | H15: chh | I15: ㄘ | J15: ㄘ | K15: 出 | L15: 取 | N15: 16 | O15: c | P15: c
A16: 15 | B16: 22 | C16: h | D16: h | E16: h | F16: h | G16: h | H16: h | I16: ㄏ | J16: ㄏ | K16: 喜 | L16: 喜 | N16: 22 | O16: h | P16: h
A17: 16 | B17: 2 | C17: m | D17: m | E17: m | F17: m | G17: bbn | H17: m | I17: ㄇ | J17: ㄇ | K17: 毛 | L17: 毛 | M17: b/m 本不分，此處分門/毛 | N17: 2 | O17: m | P17: bbn
A18: 17 | B18: 6 | C18: n | D18: n | E18: n | F18: n | G18: ln | H18: n | I18: ㄋ | J18: ㄋ | K18: 耐 | L18: 耐 | M18: l/n 本不分，此處分柳/耐 | N18: 6 | O18: n | P18: ln
A19: 18 | B19: 10 | C19: ŋ | D19: ng | E19: ng | F19: ng | G19: ggn | H19: ng | I19: ㄫ | J19: ⁰ㄫ | K19: 雅 | L19: 雅 | M19: g/ng 本不分，此處分語/雅 | N19: 10 | O19: ng | P19: ggn
A20: 19 | B20: 18 | C20: ʥ | D20: ji | E20: ji | F20: jj | G20: zzi | H20: ji | I20: ㆢ | J20: ㄖ | K20: 入 | L20: 熱 | M20: ㆢ = ㆡㄧ | N20: 18 | O20: jji | P20: zzi
A21: 20 | B21: 19 | C21: ʨ | D21: tsi | E21: zi | F21: j | G21: zi | H21: chi | I21: ㄐ | J21: ㄐ | K21: 曾 | L21: 止 | M21: ㄐ = ㄗㄧ | N21: 19 | O21: ji | P21: zi
A22: 21 | B22: 20 | C22: ʨʰ | D22: tshi | E22: ci | F22: ch | G22: ci | H22: chhi | I22: ㄑ | J22: ㄑ | K22: 出 | L22: 測 | M22: ㄑ = ㄘㄧ | N22: 20 | O22: chi | P22: ci
A23: 22 | B23: 21 | C23: ɕ | D23: si | E23: si | F23: sh | G23: si | H23: si | I23: ㄒ | J23: ㄒ | K23: 時 | L23: 惜 | M23: ㄒ = ㄙㄧ | N23: 21 | O23: shi | P23: si

Sheet 【韻】韻母對照表
A3: 序號 | B3: 國際音標 | C3: 台羅拼音 | D3: 台語音標 | E3: 台語注音二式 | F3: 閩拼方案 | G3: 白話字 | H3: 方音符號 | I3: 台語注音 | J3: 十五音 | K3: 漢字例 | L3: 十五音識別碼 | M3: 聲韻調類 | N3: 字長 | P3: 台羅拼音 | Q3: 台語音標 | S3: 台羅拼音 | T3: 標調字母 | U3: search() | V3: 台語音標 | AB3: U+0301 | AC3: U+0300 | AE3: U+030C | AF3: U+0301 | AG3: U+0304 | AH3: U+030D | AI3: U+030B | AJ3: U+030A
A4: =ROW() - 3 -> 1 | B4: a | C4: a | D4: a | E4: a | F4: a | G4: a | H4: ㄚ | I4: ㄚ | J4: =LEFT(韻母對照表3[[#This Row],[十五音識別碼]],1) -> 膠 | K4: 些 | L4: 膠舒 | N4: =LEN(D4) -> 1 | P4: =C4 -> a | Q4: =D4 -> a | S4: =_xlfn.CONCAT(P4, "(\d)") -> a(\d) | T4: a | U4: =IFERROR( IF(T4="", "", SEARCH(T4, $P4)), "") -> 1 | V4: =IFERROR( _xlfn.CONCAT(LEFT(P4,U4-1), "》", MID(P4,U4,1), "${1}", RIGHT(P4, LEN(P4)-U4)), "" ) -> 》a${1} | X4: =IF(AND(Q4<>"", P4<>""), " - xform/》" & S4 & "/" & V4 & "/", "") -> - xform/》a(\d)/》a${1}/ | Z4: a | AA4: =_xlfn.CONCAT($Z4, IF(AA$3="", "", _xlfn.UNICHAR( HEX2DEC( RIGHT(AA$3,4))))) -> a | AB4: =_xlfn.CONCAT($Z4, IF(AB$3="", "", _xlfn.UNICHAR( HEX2DEC( RIGHT(AB$3,4))))) -> á | AC4: =_xlfn.CONCAT($Z4, IF(AC$3="", "", _xlfn.UNICHAR( HEX2DEC( RIGHT(AC$3,4))))) -> à | AD4: =_xlfn.CONCAT($Z4, IF(AD$3="", "", _xlfn.UNICHAR( HEX2DEC( RIGHT(AD$3,4))))) -> a | AE4: =_xlfn.CONCAT($Z4, IF(AE$3="", "", _xlfn.UNICHAR( HEX2DEC( RIGHT(AE$3,4))))) -> ǎ | AF4: =_xlfn.CONCAT($Z4, IF(AF$3="", "", _xlfn.UNICHAR( HEX2DEC( RIGHT(AF$3,4))))) -> á | AG4: =_xlfn.CONCAT($Z4, IF(AG$3="", "", _xlfn.UNICHAR( HEX2DEC( RIGHT(AG$3,4))))) -> ā | AH4: =_xlfn.CONCAT($Z4, IF(AH$3="", "", _xlfn.UNICHAR( HEX2DEC( RIGHT(AH$3,4))))) -> a̍ | ... AJ4: =_xlfn.CONCAT($Z4, IF(AJ$3="", "", _xlfn.UNICHAR( HEX2DEC( RIGHT(AJ$3,4))))) -> å | AL4: =_xlfn.CONCAT(" - xform/》", $Z4, [1]【調】韻母標調!AJ$1, "/", AA4, "/") -> - xform/》a1/a/ | AM4: =_xlfn.CONCAT(" - xform/》", $Z4, [1]【調】韻母標調!AK$1, "/", AB4, "/") -> - xform/》a2/á/ | AN4: =_xlfn.CONCAT(" - xform/》", $Z4, [1]【調】韻母標調!AL$1, "/", AC4, "/") -> - xform/》a3/à/ | AO4: =_xlfn.CONCAT(" - xform/》", $Z4, [1]【調】韻母標調!AM$1, "/", AD4, "/") -> - xform/》a4/a/ | AP4: =_xlfn.CONCAT(" - xform/》", $Z4, [1]【調】韻母標調!AN$1, "/", AE4, "/") -> - xform/》a5/ǎ/ | AQ4: =_xlfn.CONCAT(" - xform/》", $Z4, [1]【調】韻母標調!AO$1, "/", AF4, "/") -> - xform/》a6/á/ | AR4: =_xlfn.CONCAT(" - xform/》", $Z4, [1]【調】韻母標調!AP$1, "/", AG4, "/") -> - xform/》a7/ā/ | AS4: =_xlfn.CONCAT(" - xform/》", $Z4, [1]【調】韻母標調!AQ$1, "/", AH4, "/") -> - xform/》a8/a̍/ | ... AU4: =_xlfn.CONCAT(" - xform/》", $Z4, [1]【調】韻母標調!AS$1, "/", AJ4, "/") -> - xform/》a9/å/
A5: =ROW() - 3 -> 2 | B5: aʔ | C5: ah | D5: ah | E5: ah | F5: ah | G5: ah | H5: ㄚㆷ | I5: ㄚㄏ | J5: =LEFT(韻母對照表3[[#This Row],[十五音識別碼]],1) -> 膠 | K5: 百 | L5: 膠促 | N5: =LEN(D5) -> 2 | P5: =C5 -> ah | Q5: =D5 -> ah | S5: =_xlfn.CONCAT(P5, "(\d)") -> ah(\d) | T5: a | U5: =IFERROR( IF(T5="", "", SEARCH(T5, $P5)), "") -> 1 | V5: =IFERROR( _xlfn.CONCAT(LEFT(P5,U5-1), "》", MID(P5,U5,1), "${1}", RIGHT(P5, LEN(P5)-U5)), "" ) -> 》a${1}h | X5: =IF(AND(Q5<>"", P5<>""), " - xform/》" & S5 & "/" & V5 & "/", "") -> - xform/》ah(\d)/》a${1}h/ | Z5: u | AA5: =_xlfn.CONCAT($Z5, IF(AA$3="", "", _xlfn.UNICHAR( HEX2DEC( RIGHT(AA$3,4))))) -> u | AB5: =_xlfn.CONCAT($Z5, IF(AB$3="", "", _xlfn.UNICHAR( HEX2DEC( RIGHT(AB$3,4))))) -> ú | AC5: =_xlfn.CONCAT($Z5, IF(AC$3="", "", _xlfn.UNICHAR( HEX2DEC( RIGHT(AC$3,4))))) -> ù | AD5: =_xlfn.CONCAT($Z5, IF(AD$3="", "", _xlfn.UNICHAR( HEX2DEC( RIGHT(AD$3,4))))) -> u | AE5: =_xlfn.CONCAT($Z5, IF(AE$3="", "", _xlfn.UNICHAR( HEX2DEC( RIGHT(AE$3,4))))) -> ǔ | AF5: =_xlfn.CONCAT($Z5, IF(AF$3="", "", _xlfn.UNICHAR( HEX2DEC( RIGHT(AF$3,4))))) -> ú | AG5: =_xlfn.CONCAT($Z5, IF(AG$3="", "", _xlfn.UNICHAR( HEX2DEC( RIGHT(AG$3,4))))) -> ū | AH5: =_xlfn.CONCAT($Z5, IF(AH$3="", "", _xlfn.UNICHAR( HEX2DEC( RIGHT(AH$3,4))))) -> u̍ | ... AJ5: =_xlfn.CONCAT($Z5, IF(AJ$3="", "", _xlfn.UNICHAR( HEX2DEC( RIGHT(AJ$3,4))))) -> ů | AL5: =_xlfn.CONCAT(" - xform/》", $Z5, [1]【調】韻母標調!AJ$1, "/", AA5, "/") -> - xform/》u1/u/ | AM5: =_xlfn.CONCAT(" - xform/》", $Z5, [1]【調】韻母標調!AK$1, "/", AB5, "/") -> - xform/》u2/ú/ | AN5: =_xlfn.CONCAT(" - xform/》", $Z5, [1]【調】韻母標調!AL$1, "/", AC5, "/") -> - xform/》u3/ù/ | AO5: =_xlfn.CONCAT(" - xform/》", $Z5, [1]【調】韻母標調!AM$1, "/", AD5, "/") -> - xform/》u4/u/ | AP5: =_xlfn.CONCAT(" - xform/》", $Z5, [1]【調】韻母標調!AN$1, "/", AE5, "/") -> - xform/》u5/ǔ/ | AQ5: =_xlfn.CONCAT(" - xform/》", $Z5, [1]【調】韻母標調!AO$1, "/", AF5, "/") -> - xform/》u6/ú/ | AR5: =_xlfn.CONCAT(" - xform/》", $Z5, [1]【調】韻母標調!AP$1, "/", AG5, "/") -> - xform/》u7/ū/ | AS5: =_xlfn.CONCAT(" - xform/》", $Z5, [1]【調】韻母標調!AQ$1, "/", AH5, "/") -> - xform/》u8/u̍/ | ... AU5: =_xlfn.CONCAT(" - xform/》", $Z5, [1]【調】韻母標調!AS$1, "/", AJ5, "/") -> - xform/》u9/ů/
A6: =ROW() - 3 -> 3 | B6: aɪ | C6: ai | D6: ai | E6: ai | F6: ai | G6: ai | H6: ㄞ | I6: ㄞ | J6: =LEFT(韻母對照表3[[#This Row],[十五音識別碼]],1) -> 皆 | K6: 埃 | L6: 皆舒 | N6: =LEN(D6) -> 2 | P6: =C6 -> ai | Q6: =D6 -> ai | S6: =_xlfn.CONCAT(P6, "(\d)") -> ai(\d) | T6: o | U6: =IFERROR( IF(T6="", "", SEARCH(T6, $P6)), "") | V6: =IFERROR( _xlfn.CONCAT(LEFT(P6,U6-1), "》", MID(P6,U6,1), "${1}", RIGHT(P6, LEN(P6)-U6)), "" ) | X6: =IF(AND(Q6<>"", P6<>""), " - xform/》" & S6 & "/" & V6 & "/", "") -> - xform/》ai(\d)//
A7: =ROW() - 3 -> 4 | B7: aɪʔ | C7: aih | D7: aih | E7: aih | F7: aih | G7: aih | H7: ㄞㆷ | I7: ㄞㄏ | J7: =LEFT(韻母對照表3[[#This Row],[十五音識別碼]],1) -> 皆 | K7: ◯ | L7: 皆促 | N7: =LEN(D7) -> 3 | P7: =C7 -> aih | Q7: =D7 -> aih | S7: =_xlfn.CONCAT(P7, "(\d)") -> aih(\d) | T7: a | U7: =IFERROR( IF(T7="", "", SEARCH(T7, $P7)), "") -> 1 | V7: =IFERROR( _xlfn.CONCAT(LEFT(P7,U7-1), "》", MID(P7,U7,1), "${1}", RIGHT(P7, LEN(P7)-U7)), "" ) -> 》a${1}ih | X7: =IF(AND(Q7<>"", P7<>""), " - xform/》" & S7 & "/" & V7 & "/", "") -> - xform/》aih(\d)/》a${1}ih/
A8: =ROW() - 3 -> 5 | B8: ãɪ | C8: ainn | D8: ainn | E8: ainn | F8: nai | G8: aiⁿ | H8: ㆮ | I8: ⁰ㄞ | J8: =LEFT(韻母對照表3[[#This Row],[十五音識別碼]],1) -> 閒 | K8: 挨 | L8: 閒舒 | M8: 韻-鼻 | N8: =LEN(D8) -> 4 | P8: =C8 -> ainn | Q8: =D8 -> ainn | S8: =_xlfn.CONCAT(P8, "(\d)") -> ainn(\d) | T8: a | U8: =IFERROR( IF(T8="", "", SEARCH(T8, $P8)), "") -> 1 | V8: =IFERROR( _xlfn.CONCAT(LEFT(P8,U8-1), "》", MID(P8,U8,1), "${1}", RIGHT(P8, LEN(P8)-U8)), "" ) -> 》a${1}inn | X8: =IF(AND(Q8<>"", P8<>""), " - xform/》" & S8 & "/" & V8 & "/", "") -> - xform/》ainn(\d)/》a${1}inn/
A9: =ROW() - 3 -> 6 | B9: =_xlfn.CONCAT("a","k",_xlfn.UNICHAR(794)) -> ak̚ | C9: ak | D9: ak | E9: ak | F9: ak | G9: ak | H9: ㄚㆻ | I9: ㄚㄍ | J9: =LEFT(韻母對照表3[[#This Row],[十五音識別碼]],1) -> 江 | K9: 角 | L9: 江促 | N9: =LEN(D9) -> 2 | P9: =C9 -> ak | Q9: =D9 -> ak | S9: =_xlfn.CONCAT(P9, "(\d)") -> ak(\d) | T9: e | U9: =IFERROR( IF(T9="", "", SEARCH(T9, $P9)), "") | V9: =IFERROR( _xlfn.CONCAT(LEFT(P9,U9-1), "》", MID(P9,U9,1), "${1}", RIGHT(P9, LEN(P9)-U9)), "" ) | X9: =IF(AND(Q9<>"", P9<>""), " - xform/》" & S9 & "/" & V9 & "/", "") -> - xform/》ak(\d)//
A10: =ROW() - 3 -> 7 | B10: am | C10: am | D10: am | E10: am | F10: am | G10: am | H10: ㆰ | I10: ㄚㄇ | J10: =LEFT(韻母對照表3[[#This Row],[十五音識別碼]],1) -> 甘 | K10: 堪 | L10: 甘舒 | N10: =LEN(D10) -> 2 | P10: =C10 -> am | Q10: =D10 -> am | S10: =_xlfn.CONCAT(P10, "(\d)") -> am(\d) | T10: a | U10: =IFERROR( IF(T10="", "", SEARCH(T10, $P10)), "") -> 1 | V10: =IFERROR( _xlfn.CONCAT(LEFT(P10,U10-1), "》", MID(P10,U10,1), "${1}", RIGHT(P10, LEN(P10)-U10)), "" ) -> 》a${1}m | X10: =IF(AND(Q10<>"", P10<>""), " - xform/》" & S10 & "/" & V10 & "/", "") -> - xform/》am(\d)/》a${1}m/ | Z10: o | AA10: =_xlfn.CONCAT($Z10, IF(AA$3="", "", _xlfn.UNICHAR( HEX2DEC( RIGHT(AA$3,4))))) -> o | AB10: =_xlfn.CONCAT($Z10, IF(AB$3="", "", _xlfn.UNICHAR( HEX2DEC( RIGHT(AB$3,4))))) -> ó | AC10: =_xlfn.CONCAT($Z10, IF(AC$3="", "", _xlfn.UNICHAR( HEX2DEC( RIGHT(AC$3,4))))) -> ò | AD10: =_xlfn.CONCAT($Z10, IF(AD$3="", "", _xlfn.UNICHAR( HEX2DEC( RIGHT(AD$3,4))))) -> o | AE10: =_xlfn.CONCAT($Z10, IF(AE$3="", "", _xlfn.UNICHAR( HEX2DEC( RIGHT(AE$3,4))))) -> ǒ | AF10: =_xlfn.CONCAT($Z10, IF(AF$3="", "", _xlfn.UNICHAR( HEX2DEC( RIGHT(AF$3,4))))) -> ó | AG10: =_xlfn.CONCAT($Z10, IF(AG$3="", "", _xlfn.UNICHAR( HEX2DEC( RIGHT(AG$3,4))))) -> ō | AH10: =_xlfn.CONCAT($Z10, IF(AH$3="", "", _xlfn.UNICHAR( HEX2DEC( RIGHT(AH$3,4))))) -> o̍ | ... AJ10: =_xlfn.CONCAT($Z10, IF(AJ$3="", "", _xlfn.UNICHAR( HEX2DEC( RIGHT(AJ$3,4))))) -> o̊ | AL10: =_xlfn.CONCAT(" - xform/》", $Z10, [1]【調】韻母標調!AJ$1, "/", AA10, "/") -> - xform/》o1/o/ | AM10: =_xlfn.CONCAT(" - xform/》", $Z10, [1]【調】韻母標調!AK$1, "/", AB10, "/") -> - xform/》o2/ó/ | AN10: =_xlfn.CONCAT(" - xform/》", $Z10, [1]【調】韻母標調!AL$1, "/", AC10, "/") -> - xform/》o3/ò/ | AO10: =_xlfn.CONCAT(" - xform/》", $Z10, [1]【調】韻母標調!AM$1, "/", AD10, "/") -> - xform/》o4/o/ | AP10: =_xlfn.CONCAT(" - xform/》", $Z10, [1]【調】韻母標調!AN$1, "/", AE10, "/") -> - xform/》o5/ǒ/ | AQ10: =_xlfn.CONCAT(" - xform/》", $Z10, [1]【調】韻母標調!AO$1, "/", AF10, "/") -> - xform/》o6/ó/ | AR10: =_xlfn.CONCAT(" - xform/》", $Z10, [1]【調】韻母標調!AP$1, "/", AG10, "/") -> - xform/》o7/ō/ | AS10: =_xlfn.CONCAT(" - xform/》", $Z10, [1]【調】韻母標調!AQ$1, "/", AH10, "/") -> - xform/》o8/o̍/ | ... AU10: =_xlfn.CONCAT(" - xform/》", $Z10, [1]【調】韻母標調!AS$1, "/", AJ10, "/") -> - xform/》o9/o̊/
A11: =ROW() - 3 -> 8 | B11: an | C11: an | D11: an | E11: an | F11: an | G11: an | H11: ㄢ | I11: ㄢ | J11: =LEFT(韻母對照表3[[#This Row],[十五音識別碼]],1) -> 干 | K11: 蘭 | L11: 干舒 | N11: =LEN(D11) -> 2 | P11: =C11 -> an | Q11: =D11 -> an | S11: =_xlfn.CONCAT(P11, "(\d)") -> an(\d) | T11: a | U11: =IFERROR( IF(T11="", "", SEARCH(T11, $P11)), "") -> 1 | V11: =IFERROR( _xlfn.CONCAT(LEFT(P11,U11-1), "》", MID(P11,U11,1), "${1}", RIGHT(P11, LEN(P11)-U11)), "" ) -> 》a${1}n | X11: =IF(AND(Q11<>"", P11<>""), " - xform/》" & S11 & "/" & V11 & "/", "") -> - xform/》an(\d)/》a${1}n/ | Z11: m | AA11: =_xlfn.CONCAT($Z11, IF(AA$3="", "", _xlfn.UNICHAR( HEX2DEC( RIGHT(AA$3,4))))) -> m | AB11: =_xlfn.CONCAT($Z11, IF(AB$3="", "", _xlfn.UNICHAR( HEX2DEC( RIGHT(AB$3,4))))) -> ḿ | AC11: =_xlfn.CONCAT($Z11, IF(AC$3="", "", _xlfn.UNICHAR( HEX2DEC( RIGHT(AC$3,4))))) -> m̀ | AD11: =_xlfn.CONCAT($Z11, IF(AD$3="", "", _xlfn.UNICHAR( HEX2DEC( RIGHT(AD$3,4))))) -> m | AE11: =_xlfn.CONCAT($Z11, IF(AE$3="", "", _xlfn.UNICHAR( HEX2DEC( RIGHT(AE$3,4))))) -> m̌ | AF11: =_xlfn.CONCAT($Z11, IF(AF$3="", "", _xlfn.UNICHAR( HEX2DEC( RIGHT(AF$3,4))))) -> ḿ | AG11: =_xlfn.CONCAT($Z11, IF(AG$3="", "", _xlfn.UNICHAR( HEX2DEC( RIGHT(AG$3,4))))) -> m̄ | AH11: =_xlfn.CONCAT($Z11, IF(AH$3="", "", _xlfn.UNICHAR( HEX2DEC( RIGHT(AH$3,4))))) -> m̍ | ... AJ11: =_xlfn.CONCAT($Z11, IF(AJ$3="", "", _xlfn.UNICHAR( HEX2DEC( RIGHT(AJ$3,4))))) -> m̊ | AL11: =_xlfn.CONCAT(" - xform/》", $Z11, [1]【調】韻母標調!AJ$1, "/", AA11, "/") -> - xform/》m1/m/ | AM11: =_xlfn.CONCAT(" - xform/》", $Z11, [1]【調】韻母標調!AK$1, "/", AB11, "/") -> - xform/》m2/ḿ/ | AN11: =_xlfn.CONCAT(" - xform/》", $Z11, [1]【調】韻母標調!AL$1, "/", AC11, "/") -> - xform/》m3/m̀/ | AO11: =_xlfn.CONCAT(" - xform/》", $Z11, [1]【調】韻母標調!AM$1, "/", AD11, "/") -> - xform/》m4/m/ | AP11: =_xlfn.CONCAT(" - xform/》", $Z11, [1]【調】韻母標調!AN$1, "/", AE11, "/") -> - xform/》m5/m̌/ | AQ11: =_xlfn.CONCAT(" - xform/》", $Z11, [1]【調】韻母標調!AO$1, "/", AF11, "/") -> - xform/》m6/ḿ/ | AR11: =_xlfn.CONCAT(" - xform/》", $Z11, [1]【調】韻母標調!AP$1, "/", AG11, "/") -> - xform/》m7/m̄/ | AS11: =_xlfn.CONCAT(" - xform/》", $Z11, [1]【調】韻母標調!AQ$1, "/", AH11, "/") -> - xform/》m8/m̍/ | ... AU11: =_xlfn.CONCAT(" - xform/》", $Z11, [1]【調】韻母標調!AS$1, "/", AJ11, "/") -> - xform/》m9/m̊/
A12: =ROW() - 3 -> 9 | B12: aŋ | C12: ang | D12: ang | E12: ang | F12: ang | G12: ang | H12: ㄤ | I12: ㄤ | J12: =LEFT(韻母對照表3[[#This Row],[十五音識別碼]],1) -> 江 | K12: 邦 | L12: 江舒 | N12: =LEN(D12) -> 3 | P12: =C12 -> ang | Q12: =D12 -> ang | S12: =_xlfn.CONCAT(P12, "(\d)") -> ang(\d) | T12: a | U12: =IFERROR( IF(T12="", "", SEARCH(T12, $P12)), "") -> 1 | V12: =IFERROR( _xlfn.CONCAT(LEFT(P12,U12-1), "》", MID(P12,U12,1), "${1}", RIGHT(P12, LEN(P12)-U12)), "" ) -> 》a${1}ng | X12: =IF(AND(Q12<>"", P12<>""), " - xform/》" & S12 & "/" & V12 & "/", "") -> - xform/》ang(\d)/》a${1}ng/ | Z12: n | AA12: =_xlfn.CONCAT($Z12, IF(AA$3="", "", _xlfn.UNICHAR( HEX2DEC( RIGHT(AA$3,4))))) -> n | AB12: =_xlfn.CONCAT($Z12, IF(AB$3="", "", _xlfn.UNICHAR( HEX2DEC( RIGHT(AB$3,4))))) -> ń | AC12: =_xlfn.CONCAT($Z12, IF(AC$3="", "", _xlfn.UNICHAR( HEX2DEC( RIGHT(AC$3,4))))) -> ǹ | AD12: =_xlfn.CONCAT($Z12, IF(AD$3="", "", _xlfn.UNICHAR( HEX2DEC( RIGHT(AD$3,4))))) -> n | AE12: =_xlfn.CONCAT($Z12, IF(AE$3="", "", _xlfn.UNICHAR( HEX2DEC( RIGHT(AE$3,4))))) -> ň | AF12: =_xlfn.CONCAT($Z12, IF(AF$3="", "", _xlfn.UNICHAR( HEX2DEC( RIGHT(AF$3,4))))) -> ń | AG12: =_xlfn.CONCAT($Z12, IF(AG$3="", "", _xlfn.UNICHAR( HEX2DEC( RIGHT(AG$3,4))))) -> n̄ | AH12: =_xlfn.CONCAT($Z12, IF(AH$3="", "", _xlfn.UNICHAR( HEX2DEC( RIGHT(AH$3,4))))) -> n̍ | ... AJ12: =_xlfn.CONCAT($Z12, IF(AJ$3="", "", _xlfn.UNICHAR( HEX2DEC( RIGHT(AJ$3,4))))) -> n̊ | AL12: =_xlfn.CONCAT(" - xform/》", $Z12, [1]【調】韻母標調!AJ$1, "/", AA12, "/") -> - xform/》n1/n/ | AM12: =_xlfn.CONCAT(" - xform/》", $Z12, [1]【調】韻母標調!AK$1, "/", AB12, "/") -> - xform/》n2/ń/ | AN12: =_xlfn.CONCAT(" - xform/》", $Z12, [1]【調】韻母標調!AL$1, "/", AC12, "/") -> - xform/》n3/ǹ/ | AO12: =_xlfn.CONCAT(" - xform/》", $Z12, [1]【調】韻母標調!AM$1, "/", AD12, "/") -> - xform/》n4/n/ | AP12: =_xlfn.CONCAT(" - xform/》", $Z12, [1]【調】韻母標調!AN$1, "/", AE12, "/") -> - xform/》n5/ň/ | AQ12: =_xlfn.CONCAT(" - xform/》", $Z12, [1]【調】韻母標調!AO$1, "/", AF12, "/") -> - xform/》n6/ń/ | AR12: =_xlfn.CONCAT(" - xform/》", $Z12, [1]【調】韻母標調!AP$1, "/", AG12, "/") -> - xform/》n7/n̄/ | AS12: =_xlfn.CONCAT(" - xform/》", $Z12, [1]【調】韻母標調!AQ$1, "/", AH12, "/") -> - xform/》n8/n̍/ | ... AU12: =_xlfn.CONCAT(" - xform/》", $Z12, [1]【調】韻母標調!AS$1, "/", AJ12, "/") -> - xform/》n9/n̊/
A13: =ROW() - 3 -> 10 | B13: ã | C13: ann | D13: ann | E13: ann | F13: na | G13: aⁿ | H13: ㆩ | I13: ⁰ㄚ | J13: =LEFT(韻母對照表3[[#This Row],[十五音識別碼]],1) -> 監 | K13: 聽 | L13: 監舒 | M13: 韻-鼻 | N13: =LEN(D13) -> 3 | P13: =C13 -> ann | Q13: =D13 -> ann | S13: =_xlfn.CONCAT(P13, "(\d)") -> ann(\d) | T13: a | U13: =IFERROR( IF(T13="", "", SEARCH(T13, $P13)), "") -> 1 | V13: =IFERROR( _xlfn.CONCAT(LEFT(P13,U13-1), "》", MID(P13,U13,1), "${1}", RIGHT(P13, LEN(P13)-U13)), "" ) -> 》a${1}nn | X13: =IF(AND(Q13<>"", P13<>""), " - xform/》" & S13 & "/" & V13 & "/", "") -> - xform/》ann(\d)/》a${1}nn/ | Z13: i | AA13: =_xlfn.CONCAT($Z13, IF(AA$3="", "", _xlfn.UNICHAR( HEX2DEC( RIGHT(AA$3,4))))) -> i | AB13: =_xlfn.CONCAT($Z13, IF(AB$3="", "", _xlfn.UNICHAR( HEX2DEC( RIGHT(AB$3,4))))) -> í | AC13: =_xlfn.CONCAT($Z13, IF(AC$3="", "", _xlfn.UNICHAR( HEX2DEC( RIGHT(AC$3,4))))) -> ì | AD13: =_xlfn.CONCAT($Z13, IF(AD$3="", "", _xlfn.UNICHAR( HEX2DEC( RIGHT(AD$3,4))))) -> i | AE13: =_xlfn.CONCAT($Z13, IF(AE$3="", "", _xlfn.UNICHAR( HEX2DEC( RIGHT(AE$3,4))))) -> ǐ | AF13: =_xlfn.CONCAT($Z13, IF(AF$3="", "", _xlfn.UNICHAR( HEX2DEC( RIGHT(AF$3,4))))) -> í | AG13: =_xlfn.CONCAT($Z13, IF(AG$3="", "", _xlfn.UNICHAR( HEX2DEC( RIGHT(AG$3,4))))) -> ī | AH13: =_xlfn.CONCAT($Z13, IF(AH$3="", "", _xlfn.UNICHAR( HEX2DEC( RIGHT(AH$3,4))))) -> i̍ | ... AJ13: =_xlfn.CONCAT($Z13, IF(AJ$3="", "", _xlfn.UNICHAR( HEX2DEC( RIGHT(AJ$3,4))))) -> i̊ | AL13: =_xlfn.CONCAT(" - xform/》", $Z13, [1]【調】韻母標調!AJ$1, "/", AA13, "/") -> - xform/》i1/i/ | AM13: =_xlfn.CONCAT(" - xform/》", $Z13, [1]【調】韻母標調!AK$1, "/", AB13, "/") -> - xform/》i2/í/ | AN13: =_xlfn.CONCAT(" - xform/》", $Z13, [1]【調】韻母標調!AL$1, "/", AC13, "/") -> - xform/》i3/ì/ | AO13: =_xlfn.CONCAT(" - xform/》", $Z13, [1]【調】韻母標調!AM$1, "/", AD13, "/") -> - xform/》i4/i/ | AP13: =_xlfn.CONCAT(" - xform/》", $Z13, [1]【調】韻母標調!AN$1, "/", AE13, "/") -> - xform/》i5/ǐ/ | AQ13: =_xlfn.CONCAT(" - xform/》", $Z13, [1]【調】韻母標調!AO$1, "/", AF13, "/") -> - xform/》i6/í/ | AR13: =_xlfn.CONCAT(" - xform/》", $Z13, [1]【調】韻母標調!AP$1, "/", AG13, "/") -> - xform/》i7/ī/ | AS13: =_xlfn.CONCAT(" - xform/》", $Z13, [1]【調】韻母標調!AQ$1, "/", AH13, "/") -> - xform/》i8/i̍/ | ... AU13: =_xlfn.CONCAT(" - xform/》", $Z13, [1]【調】韻母標調!AS$1, "/", AJ13, "/") -> - xform/》i9/i̊/
A14: =ROW() - 3 -> 11 | B14: ãʔ | C14: annh | D14: annh | E14: annh | F14: nah | G14: ahⁿ | H14: ㆩㆷ | I14: ⁰ㄚㄏ | J14: =LEFT(韻母對照表3[[#This Row],[十五音識別碼]],1) -> 監 | K14: 含 | L14: 監促 | M14: 韻-鼻 | N14: =LEN(D14) -> 4 | P14: =C14 -> annh | Q14: =D14 -> annh | S14: =_xlfn.CONCAT(P14, "(\d)") -> annh(\d) | T14: a | U14: =IFERROR( IF(T14="", "", SEARCH(T14, $P14)), "") -> 1 | V14: =IFERROR( _xlfn.CONCAT(LEFT(P14,U14-1), "》", MID(P14,U14,1), "${1}", RIGHT(P14, LEN(P14)-U14)), "" ) -> 》a${1}nnh | X14: =IF(AND(Q14<>"", P14<>""), " - xform/》" & S14 & "/" & V14 & "/", "") -> - xform/》annh(\d)/》a${1}nnh/ | Z14: e | AA14: =_xlfn.CONCAT($Z14, IF(AA$3="", "", _xlfn.UNICHAR( HEX2DEC( RIGHT(AA$3,4))))) -> e | AB14: =_xlfn.CONCAT($Z14, IF(AB$3="", "", _xlfn.UNICHAR( HEX2DEC( RIGHT(AB$3,4))))) -> é | AC14: =_xlfn.CONCAT($Z14, IF(AC$3="", "", _xlfn.UNICHAR( HEX2DEC( RIGHT(AC$3,4))))) -> è | AD14: =_xlfn.CONCAT($Z14, IF(AD$3="", "", _xlfn.UNICHAR( HEX2DEC( RIGHT(AD$3,4))))) -> e | AE14: =_xlfn.CONCAT($Z14, IF(AE$3="", "", _xlfn.UNICHAR( HEX2DEC( RIGHT(AE$3,4))))) -> ě | AF14: =_xlfn.CONCAT($Z14, IF(AF$3="", "", _xlfn.UNICHAR( HEX2DEC( RIGHT(AF$3,4))))) -> é | AG14: =_xlfn.CONCAT($Z14, IF(AG$3="", "", _xlfn.UNICHAR( HEX2DEC( RIGHT(AG$3,4))))) -> ē | AH14: =_xlfn.CONCAT($Z14, IF(AH$3="", "", _xlfn.UNICHAR( HEX2DEC( RIGHT(AH$3,4))))) -> e̍ | ... AJ14: =_xlfn.CONCAT($Z14, IF(AJ$3="", "", _xlfn.UNICHAR( HEX2DEC( RIGHT(AJ$3,4))))) -> e̊ | AL14: =_xlfn.CONCAT(" - xform/》", $Z14, [1]【調】韻母標調!AJ$1, "/", AA14, "/") -> - xform/》e1/e/ | AM14: =_xlfn.CONCAT(" - xform/》", $Z14, [1]【調】韻母標調!AK$1, "/", AB14, "/") -> - xform/》e2/é/ | AN14: =_xlfn.CONCAT(" - xform/》", $Z14, [1]【調】韻母標調!AL$1, "/", AC14, "/") -> - xform/》e3/è/ | AO14: =_xlfn.CONCAT(" - xform/》", $Z14, [1]【調】韻母標調!AM$1, "/", AD14, "/") -> - xform/》e4/e/ | AP14: =_xlfn.CONCAT(" - xform/》", $Z14, [1]【調】韻母標調!AN$1, "/", AE14, "/") -> - xform/》e5/ě/ | AQ14: =_xlfn.CONCAT(" - xform/》", $Z14, [1]【調】韻母標調!AO$1, "/", AF14, "/") -> - xform/》e6/é/ | AR14: =_xlfn.CONCAT(" - xform/》", $Z14, [1]【調】韻母標調!AP$1, "/", AG14, "/") -> - xform/》e7/ē/ | AS14: =_xlfn.CONCAT(" - xform/》", $Z14, [1]【調】韻母標調!AQ$1, "/", AH14, "/") -> - xform/》e8/e̍/ | ... AU14: =_xlfn.CONCAT(" - xform/》", $Z14, [1]【調】韻母標調!AS$1, "/", AJ14, "/") -> - xform/》e9/e̊/
A15: =ROW() - 3 -> 12 | B15: =_xlfn.CONCAT("a","p",_xlfn.UNICHAR(794)) -> ap̚ | C15: ap | D15: ap | E15: ap | F15: ap | G15: ap | H15: ㄚㆴ | I15: ㄚㄅ | J15: =LEFT(韻母對照表3[[#This Row],[十五音識別碼]],1) -> 甘 | K15: 答 | L15: 甘促 | N15: =LEN(D15) -> 2 | P15: =C15 -> ap | Q15: =D15 -> ap | S15: =_xlfn.CONCAT(P15, "(\d)") -> ap(\d) | T15: a | U15: =IFERROR( IF(T15="", "", SEARCH(T15, $P15)), "") -> 1 | V15: =IFERROR( _xlfn.CONCAT(LEFT(P15,U15-1), "》", MID(P15,U15,1), "${1}", RIGHT(P15, LEN(P15)-U15)), "" ) -> 》a${1}p | X15: =IF(AND(Q15<>"", P15<>""), " - xform/》" & S15 & "/" & V15 & "/", "") -> - xform/》ap(\d)/》a${1}p/
A16: =ROW() - 3 -> 13 | B16: =_xlfn.CONCAT("a","t",_xlfn.UNICHAR(794)) -> at̚ | C16: at | D16: at | E16: at | F16: at | G16: at | H16: ㄚㆵ | I16: ㄚㄉ | J16: =LEFT(韻母對照表3[[#This Row],[十五音識別碼]],1) -> 干 | K16: 識 | L16: 干促 | N16: =LEN(D16) -> 2 | P16: =C16 -> at | Q16: =D16 -> at | S16: =_xlfn.CONCAT(P16, "(\d)") -> at(\d) | T16: o | U16: =IFERROR( IF(T16="", "", SEARCH(T16, $P16)), "") | V16: =IFERROR( _xlfn.CONCAT(LEFT(P16,U16-1), "》", MID(P16,U16,1), "${1}", RIGHT(P16, LEN(P16)-U16)), "" ) | X16: =IF(AND(Q16<>"", P16<>""), " - xform/》" & S16 & "/" & V16 & "/", "") -> - xform/》at(\d)//
A17: =ROW() - 3 -> 14 | B17: aʊ | C17: au | D17: au | E17: au | F17: ao | G17: au | H17: ㄠ | I17: ㄠ | J17: =LEFT(韻母對照表3[[#This Row],[十五音識別碼]],1) -> 交 | K17: 鬧 | L17: 交舒 | N17: =LEN(D17) -> 2 | P17: =C17 -> au | Q17: =D17 -> au | S17: =_xlfn.CONCAT(P17, "(\d)") -> au(\d) | T17: a | U17: =IFERROR( IF(T17="", "", SEARCH(T17, $P17)), "") -> 1 | V17: =IFERROR( _xlfn.CONCAT(LEFT(P17,U17-1), "》", MID(P17,U17,1), "${1}", RIGHT(P17, LEN(P17)-U17)), "" ) -> 》a${1}u | X17: =IF(AND(Q17<>"", P17<>""), " - xform/》" & S17 & "/" & V17 & "/", "") -> - xform/》au(\d)/》a${1}u/
A18: =ROW() - 3 -> 15 | B18: auʔ | C18: auh | D18: auh | E18: auh | F18: aoh | G18: auh | H18: ㄠㆷ | I18: ㄠㄏ | J18: =LEFT(韻母對照表3[[#This Row],[十五音識別碼]],1) -> 交 | K18: 暴 | L18: 交促 | N18: =LEN(D18) -> 3 | P18: =C18 -> auh | Q18: =D18 -> auh | S18: =_xlfn.CONCAT(P18, "(\d)") -> auh(\d) | T18: a | U18: =IFERROR( IF(T18="", "", SEARCH(T18, $P18)), "") -> 1 | V18: =IFERROR( _xlfn.CONCAT(LEFT(P18,U18-1), "》", MID(P18,U18,1), "${1}", RIGHT(P18, LEN(P18)-U18)), "" ) -> 》a${1}uh | X18: =IF(AND(Q18<>"", P18<>""), " - xform/》" & S18 & "/" & V18 & "/", "") -> - xform/》auh(\d)/》a${1}uh/
A19: =ROW() - 3 -> 16 | B19: e | C19: e | D19: ei | E19: e | F19: e | G19: e | H19: ㆤ | I19: ㄝ | J19: =LEFT(韻母對照表3[[#This Row],[十五音識別碼]],1) -> 稽 | K19: 遞 | L19: 稽舒 | N19: =LEN(D19) -> 2 | P19: =C27 -> i | Q19: =D27 -> i | S19: =_xlfn.CONCAT(P19, "(\d)") -> i(\d) | T19: o | U19: =IFERROR( IF(T19="", "", SEARCH(T19, $P19)), "") | V19: =IFERROR( _xlfn.CONCAT(LEFT(P19,U19-1), "》", MID(P19,U19,1), "${1}", RIGHT(P19, LEN(P19)-U19)), "" ) | X19: =IF(AND(Q19<>"", P19<>""), " - xform/》" & S19 & "/" & V19 & "/", "") -> - xform/》i(\d)//
A20: =ROW() - 3 -> 17 | B20: ɛ | C20: ee | D20: ee | H20: ㄝ | I20: ㄝ | J20: =LEFT(韻母對照表3[[#This Row],[十五音識別碼]],1) -> 嘉 | K20: 家 | L20: 嘉舒 | N20: =LEN(D20) -> 2 | P20: =C19 -> e | Q20: =D19 -> ei | S20: =_xlfn.CONCAT(P20, "(\d)") -> e(\d) | T20: i | U20: =IFERROR( IF(T20="", "", SEARCH(T20, $P20)), "") | V20: =IFERROR( _xlfn.CONCAT(LEFT(P20,U20-1), "》", MID(P20,U20,1), "${1}", RIGHT(P20, LEN(P20)-U20)), "" ) | X20: =IF(AND(Q20<>"", P20<>""), " - xform/》" & S20 & "/" & V20 & "/", "") -> - xform/》e(\d)//
A21: =ROW() - 3 -> 18 | B21: =_xlfn.CONCAT(B20, "ʔ") -> ɛʔ | C21: eeh | D21: eeh | H21: ㄝㆷ | I21: ㄝㄏ | J21: =LEFT(韻母對照表3[[#This Row],[十五音識別碼]],1) -> 嘉 | K21: 八 | L21: 嘉促 | N21: =LEN(D21) -> 3 | P21: =C25 -> enn | Q21: =D25 -> enn | S21: =_xlfn.CONCAT(P21, "(\d)") -> enn(\d) | T21: i | U21: =IFERROR( IF(T21="", "", SEARCH(T21, $P21)), "") | V21: =IFERROR( _xlfn.CONCAT(LEFT(P21,U21-1), "》", MID(P21,U21,1), "${1}", RIGHT(P21, LEN(P21)-U21)), "" ) | X21: =IF(AND(Q21<>"", P21<>""), " - xform/》" & S21 & "/" & V21 & "/", "") -> - xform/》enn(\d)//
A22: =ROW() - 3 -> 19 | B22: eʔ | C22: eh | D22: eh | E22: eh | F22: eh | G22: eh | H22: ㆤㆷ | I22: ㄝㄏ | J22: =LEFT(韻母對照表3[[#This Row],[十五音識別碼]],1) -> 伽 | K22: 伯 | L22: 伽促 | N22: =LEN(D22) -> 2 | P22: =C41 -> ih | Q22: =D41 -> ih | S22: =_xlfn.CONCAT(P22, "(\d)") -> ih(\d) | T22: a | U22: =IFERROR( IF(T22="", "", SEARCH(T22, $P22)), "") | V22: =IFERROR( _xlfn.CONCAT(LEFT(P22,U22-1), "》", MID(P22,U22,1), "${1}", RIGHT(P22, LEN(P22)-U22)), "" ) | X22: =IF(AND(Q22<>"", P22<>""), " - xform/》" & S22 & "/" & V22 & "/", "") -> - xform/》ih(\d)//
A23: =ROW() - 3 -> 20 | B23: =_xlfn.CONCAT("ɪ",, "k") -> ɪk | C23: ek | D23: ek | H23: ㄝㆻ | I23: ㄝㄍ | J23: =LEFT(韻母對照表3[[#This Row],[十五音識別碼]],1) -> 經 | K23: ◯ | L23: 經促 | N23: =LEN(D23) -> 2 | P23: =C26 -> ennh | Q23: =D26 -> ennh | S23: =_xlfn.CONCAT(P23, "(\d)") -> ennh(\d) | T23: i | U23: =IFERROR( IF(T23="", "", SEARCH(T23, $P23)), "") | V23: =IFERROR( _xlfn.CONCAT(LEFT(P23,U23-1), "》", MID(P23,U23,1), "${1}", RIGHT(P23, LEN(P23)-U23)), "" ) | X23: =IF(AND(Q23<>"", P23<>""), " - xform/》" & S23 & "/" & V23 & "/", "") -> - xform/》ennh(\d)//
A24: =ROW() - 3 -> 21 | B24: =_xlfn.CONCAT("ɪ", "ŋ") -> ɪŋ | C24: eng | D24: eng | H24: ㄝㆭ | I24: ㄝㄥ | J24: =LEFT(韻母對照表3[[#This Row],[十五音識別碼]],1) -> 經 | K24: ◯ | L24: 經舒 | N24: =LEN(D24) -> 3 | P24: =C22 -> eh | Q24: =D22 -> eh | S24: =_xlfn.CONCAT(P24, "(\d)") -> eh(\d) | T24: a | U24: =IFERROR( IF(T24="", "", SEARCH(T24, $P24)), "") | V24: =IFERROR( _xlfn.CONCAT(LEFT(P24,U24-1), "》", MID(P24,U24,1), "${1}", RIGHT(P24, LEN(P24)-U24)), "" ) | X24: =IF(AND(Q24<>"", P24<>""), " - xform/》" & S24 & "/" & V24 & "/", "") -> - xform/》eh(\d)//
A25: =ROW() - 3 -> 22 | B25: ẽ | C25: enn | D25: enn | E25: enn | F25: ne | G25: eⁿ | H25: ㆥ | I25: ⁰ㄝ | J25: =LEFT(韻母對照表3[[#This Row],[十五音識別碼]],1) -> 更 | K25: 爭 | L25: 更舒 | M25: 韻-鼻 | N25: =LEN(D25) -> 3 | P25: =C46 -> inn | Q25: =D46 -> inn | S25: =_xlfn.CONCAT(P25, "(\d)") -> inn(\d) | T25: o | U25: =IFERROR( IF(T25="", "", SEARCH(T25, $P25)), "") | V25: =IFERROR( _xlfn.CONCAT(LEFT(P25,U25-1), "》", MID(P25,U25,1), "${1}", RIGHT(P25, LEN(P25)-U25)), "" ) | X25: =IF(AND(Q25<>"", P25<>""), " - xform/》" & S25 & "/" & V25 & "/", "") -> - xform/》inn(\d)//
A26: =ROW() - 3 -> 23 | B26: ẽʔ | C26: ennh | D26: ennh | E26: ennh | F26: ennh | G26: ehⁿ | H26: ㆥㆷ | I26: ⁰ㄝㄏ | J26: =LEFT(韻母對照表3[[#This Row],[十五音識別碼]],1) -> 更 | K26: 挾 | L26: 更促 | M26: 韻-鼻 | N26: =LEN(D26) -> 4 | P26: =C43 -> im | Q26: =D43 -> im | S26: =_xlfn.CONCAT(P26, "(\d)") -> im(\d) | T26: e | U26: =IFERROR( IF(T26="", "", SEARCH(T26, $P26)), "") | V26: =IFERROR( _xlfn.CONCAT(LEFT(P26,U26-1), "》", MID(P26,U26,1), "${1}", RIGHT(P26, LEN(P26)-U26)), "" ) | X26: =IF(AND(Q26<>"", P26<>""), " - xform/》" & S26 & "/" & V26 & "/", "") -> - xform/》im(\d)//
A27: =ROW() - 3 -> 24 | B27: i | C27: i | D27: i | E27: i | F27: i | G27: i | H27: ㄧ | I27: ㄧ | J27: =LEFT(韻母對照表3[[#This Row],[十五音識別碼]],1) -> 居 | K27: 爾 | L27: 居舒 | N27: =LEN(D27) -> 1 | P27: =C44 -> in | Q27: =D44 -> in | S27: =_xlfn.CONCAT(P27, "(\d)") -> in(\d) | T27: a | U27: =IFERROR( IF(T27="", "", SEARCH(T27, $P27)), "") | V27: =IFERROR( _xlfn.CONCAT(LEFT(P27,U27-1), "》", MID(P27,U27,1), "${1}", RIGHT(P27, LEN(P27)-U27)), "" ) | X27: =IF(AND(Q27<>"", P27<>""), " - xform/》" & S27 & "/" & V27 & "/", "") -> - xform/》in(\d)//
A28: =ROW() - 3 -> 25 | B28: ɪa | C28: ia | D28: ia | E28: ia | F28: ia | G28: ia | H28: ㄧㄚ | I28: ㄧㄚ | J28: =LEFT(韻母對照表3[[#This Row],[十五音識別碼]],1) -> 迦 | K28: 名 | L28: 迦舒 | N28: =LEN(D28) -> 2 | P28: =C31 -> iam | Q28: =D31 -> iam | S28: =_xlfn.CONCAT(P28, "(\d)") -> iam(\d) | T28: i | U28: =IFERROR( IF(T28="", "", SEARCH(T28, $P28)), "") -> 1 | V28: =IFERROR( _xlfn.CONCAT(LEFT(P28,U28-1), "》", MID(P28,U28,1), "${1}", RIGHT(P28, LEN(P28)-U28)), "" ) -> 》i${1}am | X28: =IF(AND(Q28<>"", P28<>""), " - xform/》" & S28 & "/" & V28 & "/", "") -> - xform/》iam(\d)/》i${1}am/
A29: =ROW() - 3 -> 26 | B29: =_xlfn.CONCAT(B28, "ʔ") -> ɪaʔ | C29: iah | D29: iah | E29: iah | F29: iah | G29: iah | H29: ㄧㄚㆷ | I29: ㄧㄚㄏ | J29: =LEFT(韻母對照表3[[#This Row],[十五音識別碼]],1) -> 迦 | K29: 壁 | L29: 迦促 | N29: =LEN(D29) -> 3 | P29: =C33 -> iang | Q29: =D33 -> iang | S29: =_xlfn.CONCAT(P29, "(\d)") -> iang(\d) | T29: i | U29: =IFERROR( IF(T29="", "", SEARCH(T29, $P29)), "") -> 1 | V29: =IFERROR( _xlfn.CONCAT(LEFT(P29,U29-1), "》", MID(P29,U29,1), "${1}", RIGHT(P29, LEN(P29)-U29)), "" ) -> 》i${1}ang | X29: =IF(AND(Q29<>"", P29<>""), " - xform/》" & S29 & "/" & V29 & "/", "") -> - xform/》iang(\d)/》i${1}ang/
A30: =ROW() - 3 -> 27 | B30: ɪak̚ | C30: iak | D30: iak | E30: iak | F30: iak | G30: iak | H30: ㄧㄚㆻ | I30: ㄧㄚㄍ | J30: =LEFT(韻母對照表3[[#This Row],[十五音識別碼]],1) -> 姜 | K30: 爆 | L30: 姜促 | N30: =LEN(D30) -> 3 | P30: =C47 -> io | Q30: =D47 -> io | S30: =_xlfn.CONCAT(P30, "(\d)") -> io(\d) | T30: a | U30: =IFERROR( IF(T30="", "", SEARCH(T30, $P30)), "") | V30: =IFERROR( _xlfn.CONCAT(LEFT(P30,U30-1), "》", MID(P30,U30,1), "${1}", RIGHT(P30, LEN(P30)-U30)), "" ) | X30: =IF(AND(Q30<>"", P30<>""), " - xform/》" & S30 & "/" & V30 & "/", "") -> - xform/》io(\d)//
A31: =ROW() - 3 -> 28 | B31: ɪam | C31: iam | D31: iam | E31: iam | F31: iam | G31: iam | H31: ㄧㆰ | I31: ㄧㄚㄇ | J31: =LEFT(韻母對照表3[[#This Row],[十五音識別碼]],1) -> 兼 | K31: 尖 | L31: 兼舒 | N31: =LEN(D31) -> 3 | P31: =C37 -> iat | Q31: =D37 -> iat | S31: =_xlfn.CONCAT(P31, "(\d)") -> iat(\d) | T31: e | U31: =IFERROR( IF(T31="", "", SEARCH(T31, $P31)), "") | V31: =IFERROR( _xlfn.CONCAT(LEFT(P31,U31-1), "》", MID(P31,U31,1), "${1}", RIGHT(P31, LEN(P31)-U31)), "" ) | X31: =IF(AND(Q31<>"", P31<>""), " - xform/》" & S31 & "/" & V31 & "/", "") -> - xform/》iat(\d)//
A32: =ROW() - 3 -> 29 | B32: ɪan | C32: ian | D32: ian | E32: ian | F32: ian | G32: ian | H32: ㄧㄢ | I32: ㄧㄢ | J32: =LEFT(韻母對照表3[[#This Row],[十五音識別碼]],1) -> 堅 | K32: 掀 | L32: 堅舒 | N32: =LEN(D32) -> 3 | P32: =C30 -> iak | Q32: =D30 -> iak | S32: =_xlfn.CONCAT(P32, "(\d)") -> iak(\d) | T32: n | U32: =IFERROR( IF(T32="", "", SEARCH(T32, $P32)), "") | V32: =IFERROR( _xlfn.CONCAT(LEFT(P32,U32-1), "》", MID(P32,U32,1), "${1}", RIGHT(P32, LEN(P32)-U32)), "" ) | X32: =IF(AND(Q32<>"", P32<>""), " - xform/》" & S32 & "/" & V32 & "/", "") -> - xform/》iak(\d)//
A33: =ROW() - 3 -> 30 | B33: ɪaŋ | C33: iang | D33: iang | E33: iang | F33: iang | G33: iang | H33: ㄧㄤ | I33: ㄧㄤ | J33: =LEFT(韻母對照表3[[#This Row],[十五音識別碼]],1) -> 姜 | K33: 將 | L33: 姜舒 | N33: =LEN(D33) -> 4 | P33: =C38 -> iau | Q33: =D38 -> iau | S33: =_xlfn.CONCAT(P33, "(\d)") -> iau(\d) | T33: o | U33: =IFERROR( IF(T33="", "", SEARCH(T33, $P33)), "") | V33: =IFERROR( _xlfn.CONCAT(LEFT(P33,U33-1), "》", MID(P33,U33,1), "${1}", RIGHT(P33, LEN(P33)-U33)), "" ) | X33: =IF(AND(Q33<>"", P33<>""), " - xform/》" & S33 & "/" & V33 & "/", "") -> - xform/》iau(\d)//
A34: =ROW() - 3 -> 31 | B34: =_xlfn.CONCAT("ɪ", "a", _xlfn.UNICHAR(771), "") -> ɪã | C34: iann | D34: iann | E34: iann | F34: nia | G34: iaⁿ | H34: ㄧㆩ | I34: ⁰ㄧㄚ | J34: =LEFT(韻母對照表3[[#This Row],[十五音識別碼]],1) -> 驚 | K34: ◯ | L34: 驚舒 | M34: 韻-鼻 | N34: =LEN(D34) -> 4 | P34: =C32 -> ian | Q34: =D32 -> ian | S34: =_xlfn.CONCAT(P34, "(\d)") -> ian(\d) | T34: i | U34: =IFERROR( IF(T34="", "", SEARCH(T34, $P34)), "") -> 1 | V34: =IFERROR( _xlfn.CONCAT(LEFT(P34,U34-1), "》", MID(P34,U34,1), "${1}", RIGHT(P34, LEN(P34)-U34)), "" ) -> 》i${1}an | X34: =IF(AND(Q34<>"", P34<>""), " - xform/》" & S34 & "/" & V34 & "/", "") -> - xform/》ian(\d)/》i${1}an/
A35: =ROW() - 3 -> 32 | B35: =_xlfn.CONCAT(B34, "ʔ") -> ɪãʔ | C35: iannh | D35: iannh | E35: iannh | F35: iannh | G35: iahⁿ | H35: ㄧㆩㆷ | I35: ⁰ㄧㄚㄏ | J35: =LEFT(韻母對照表3[[#This Row],[十五音識別碼]],1) -> 迦 | K35: 且 | L35: 迦促 | M35: 韻-鼻 | N35: =LEN(D35) -> 5 | P35: =C36 -> iap | Q35: =D36 -> iap | S35: =_xlfn.CONCAT(P35, "(\d)") -> iap(\d) | T35: i | U35: =IFERROR( IF(T35="", "", SEARCH(T35, $P35)), "") -> 1 | V35: =IFERROR( _xlfn.CONCAT(LEFT(P35,U35-1), "》", MID(P35,U35,1), "${1}", RIGHT(P35, LEN(P35)-U35)), "" ) -> 》i${1}ap | X35: =IF(AND(Q35<>"", P35<>""), " - xform/》" & S35 & "/" & V35 & "/", "") -> - xform/》iap(\d)/》i${1}ap/
A36: =ROW() - 3 -> 33 | B36: ɪap̚ | C36: iap | D36: iap | E36: iap | F36: iap | G36: iap | H36: ㄧㄚㆴ | I36: ㄧㄚㄅ | J36: =LEFT(韻母對照表3[[#This Row],[十五音識別碼]],1) -> 兼 | K36: 接 | L36: 兼促 | N36: =LEN(D36) -> 3 | P36: =C40 -> iaunn | Q36: =D40 -> iaunn | S36: =_xlfn.CONCAT(P36, "(\d)") -> iaunn(\d) | T36: o | U36: =IFERROR( IF(T36="", "", SEARCH(T36, $P36)), "") | V36: =IFERROR( _xlfn.CONCAT(LEFT(P36,U36-1), "》", MID(P36,U36,1), "${1}", RIGHT(P36, LEN(P36)-U36)), "" ) | X36: =IF(AND(Q36<>"", P36<>""), " - xform/》" & S36 & "/" & V36 & "/", "") -> - xform/》iaunn(\d)//
A37: =ROW() - 3 -> 34 | B37: ɪat̚ | C37: iat | D37: iat | E37: iat | F37: iat | G37: iat | H37: ㄧㄚㆵ | I37: ㄧㄚㄉ | J37: =LEFT(韻母對照表3[[#This Row],[十五音識別碼]],1) -> 堅 | K37: 別 | L37: 堅促 | N37: =LEN(D37) -> 3 | P37: =C39 -> iauh | Q37: =D39 -> iauh | S37: =_xlfn.CONCAT(P37, "(\d)") -> iauh(\d) | T37: o | U37: =IFERROR( IF(T37="", "", SEARCH(T37, $P37)), "") | V37: =IFERROR( _xlfn.CONCAT(LEFT(P37,U37-1), "》", MID(P37,U37,1), "${1}", RIGHT(P37, LEN(P37)-U37)), "" ) | X37: =IF(AND(Q37<>"", P37<>""), " - xform/》" & S37 & "/" & V37 & "/", "") -> - xform/》iauh(\d)//
A38: =ROW() - 3 -> 35 | B38: ɪaʊ | C38: iau | D38: iau | E38: iau | F38: iao | G38: iau | H38: ㄧㄠ | I38: ㄧㄠ | J38: =LEFT(韻母對照表3[[#This Row],[十五音識別碼]],1) -> 嬌 | K38: 遙 | L38: 嬌舒 | N38: =LEN(D38) -> 3 | P38: =C53 -> ionn | Q38: =D53 -> ionn | S38: =_xlfn.CONCAT(P38, "(\d)") -> ionn(\d) | T38: a | U38: =IFERROR( IF(T38="", "", SEARCH(T38, $P38)), "") | V38: =IFERROR( _xlfn.CONCAT(LEFT(P38,U38-1), "》", MID(P38,U38,1), "${1}", RIGHT(P38, LEN(P38)-U38)), "" ) | X38: =IF(AND(Q38<>"", P38<>""), " - xform/》" & S38 & "/" & V38 & "/", "") -> - xform/》ionn(\d)//
A39: =ROW() - 3 -> 36 | B39: =_xlfn.CONCAT(B38, "ʔ") -> ɪaʊʔ | C39: iauh | D39: iauh | E39: iauh | F39: iaoh | G39: iauh | H39: ㄧㄠㆷ | I39: ㄧㄠㄏ | J39: =LEFT(韻母對照表3[[#This Row],[十五音識別碼]],1) -> 嬌 | K39: 噭 | L39: 嬌促 | N39: =LEN(D39) -> 4 | P39: =C50 -> iong | Q39: =D50 -> iong | S39: =_xlfn.CONCAT(P39, "(\d)") -> iong(\d) | T39: a | U39: =IFERROR( IF(T39="", "", SEARCH(T39, $P39)), "") | V39: =IFERROR( _xlfn.CONCAT(LEFT(P39,U39-1), "》", MID(P39,U39,1), "${1}", RIGHT(P39, LEN(P39)-U39)), "" ) | X39: =IF(AND(Q39<>"", P39<>""), " - xform/》" & S39 & "/" & V39 & "/", "") -> - xform/》iong(\d)//
A40: =ROW() - 3 -> 37 | B40: =_xlfn.CONCAT("ɪ", "a", _xlfn.UNICHAR(771), "ʊ") -> ɪãʊ | C40: iaunn | D40: iaunn | E40: iaunn | F40: niao | G40: iauⁿ | H40: ㄧㆯ | I40: ⁰ㄧㄠ | J40: =LEFT(韻母對照表3[[#This Row],[十五音識別碼]],1) -> 嘄 | K40: 鳥 | L40: 嘄舒 | M40: 韻-鼻 | N40: =LEN(D40) -> 5 | P40: =C48 -> ioh | Q40: =D48 -> ioh | S40: =_xlfn.CONCAT(P40, "(\d)") -> ioh(\d) | T40: a | U40: =IFERROR( IF(T40="", "", SEARCH(T40, $P40)), "") | V40: =IFERROR( _xlfn.CONCAT(LEFT(P40,U40-1), "》", MID(P40,U40,1), "${1}", RIGHT(P40, LEN(P40)-U40)), "" ) | X40: =IF(AND(Q40<>"", P40<>""), " - xform/》" & S40 & "/" & V40 & "/", "") -> - xform/》ioh(\d)//
A41: =ROW() - 3 -> 38 | B41: iʔ | C41: ih | D41: ih | E41: ih | F41: ih | G41: ih | H41: ㄧㆷ | I41: ㄧㄏ | J41: =LEFT(韻母對照表3[[#This Row],[十五音識別碼]],1) -> 居 | K41: 逼 | L41: 居促 | N41: =LEN(D41) -> 2 | P41: =C51 -> ip | Q41: =D51 -> ip | S41: =_xlfn.CONCAT(P41, "(\d)") -> ip(\d) | T41: a | U41: =IFERROR( IF(T41="", "", SEARCH(T41, $P41)), "") | V41: =IFERROR( _xlfn.CONCAT(LEFT(P41,U41-1), "》", MID(P41,U41,1), "${1}", RIGHT(P41, LEN(P41)-U41)), "" ) | X41: =IF(AND(Q41<>"", P41<>""), " - xform/》" & S41 & "/" & V41 & "/", "") -> - xform/》ip(\d)//
A42: =ROW() - 3 -> 39 | B42: ik̚ | C42: ik | D42: ik | E42: iek | F42: ik | G42: ek | H42: ㄧㆻ | I42: ㄧㄍ | J42: =LEFT(韻母對照表3[[#This Row],[十五音識別碼]],1) -> 經 | K42: 益 | L42: 經促 | N42: =LEN(D42) -> 2 | P42: =C35 -> iannh | Q42: =D35 -> iannh | S42: =_xlfn.CONCAT(P42, "(\d)") -> iannh(\d) | T42: a | U42: =IFERROR( IF(T42="", "", SEARCH(T42, $P42)), "") -> 2 | V42: =IFERROR( _xlfn.CONCAT(LEFT(P42,U42-1), "》", MID(P42,U42,1), "${1}", RIGHT(P42, LEN(P42)-U42)), "" ) -> i》a${1}nnh | X42: =IF(AND(Q42<>"", P42<>""), " - xform/》" & S42 & "/" & V42 & "/", "") -> - xform/》iannh(\d)/i》a${1}nnh/
...

Sheet 工作表1
