Workbook
Name 十五音韻母: '[1]十五音-韻母'!$C$5:$C$54
Name 十五音韻母對照表: '[1]十五音-韻母'!$B$5:$R$54
Name 方音符號聲調: [2]設定!$J$3:$J$10
Name 台羅韻母八音反切: '[1]台羅-韻母八音反切'!$R$5:$Y$54
Name 白話字韻母八音反切: '[1]白話字-韻母八音反切'!$R$5:$Y$54
Name 閩拼八聲調: [2]設定!$I$3:$I$10
Name 閩拼韻母八音反切: '[1]閩拼-韻母八音反切'!$R$5:$Y$54
Name 聲母碼: [2]聲母對照表!$B$4:$B$21
Name 聲母碼表: [1]聲母碼!$D$6:$K$22
Name 韻母對照表: [1]韻母對照表!$B$6:$K$105
Name 韻母碼: [2]韻母對照表!$B$4:$B$103
Name 韻母碼表: [1]韻母碼!$F$5:$M$78
Name 顯示注音輸入: [3]env!$C$10

Sheet 聲母十五音發聲表
B1: 台語注音二式 | AJ1: 閩拼方案
E3: 鼻音 | I3: 塞音 | Q3: 塞擦音 | Y3: 擦音 | AC3: 邊音 | AM3: 鼻音 | AQ3: 塞音 | AY3: 塞擦音 | BG3: 擦音 | BK3: 邊音
I4: 不送氣 | M4: 送氣 | Q4: 不送氣 | U4: 送氣 | AQ4: 不送氣 | AU4: 送氣 | AY4: 不送氣 | BC4: 送氣
B5: 雙唇音 | C5: 雙唇音 | D5: 清音 | I5: 邊 | K5: p | L5: 比 | M5: 頗 | O5: ph | P5: 鄙 | AJ5: 雙唇音 | AK5: 雙唇音 | AL5: 清音 | AQ5: 邊 | AS5: p | AT5: 比 | AU5: 頗 | AW5: ph | AX5: 鄙
I7: ㄅ | J7: 比 | K7: b | L7: ㄅ | M7: ㄆ | N7: 鄙 | O7: p | P7: ㄆ | AQ7: ㄅ | AR7: 比 | AS7: b | AT7: ㄅ | AU7: ㄆ | AV7: 鄙 | AW7: p | AX7: ㄆ
D9: 濁音 | E9: 門 | G9: m | I9: 門 | K9: b | L9: 美 | AL9: 濁音 | AM9: 門 | AO9: m | AQ9: 門 | AS9: b | AT9: 美
E11: ㄇ | G11: m | I11: ㆠ | J11: 美 | K11: b | L11: ㆠ | AM11: ㄇ | AO11: bbn | AQ11: ㆠ | AR11: 美 | AS11: bb | AT11: ㆠ
B13: 舌尖前音 | C13: 齦顎音 | D13: 清音 | Q13: 曾 | S13: tsi | T13: 尖 | U13: 出 | W13: tshi | X13: 手 | Y13: 時 | AA13: si | AJ13: 舌尖前音 | AK13: 齦顎音 | AL13: 清音 | AY13: 曾 | BA13: tsi | BB13: 尖 | BC13: 出 | BE13: tshi | BF13: 手 | BG13: 時 | BI13: si
Q15: ㄐ | R15: tsi | S15: ji | T15: ㄐ | U15: ㄑ | V15: tshi | W15: chi | X15: ㄑ | Y15: ㄒ | Z15: si | AA15: shi | AB15: ㄒ | AY15: ㄐ | AZ15: tsi | BA15: zi | BB15: ㄐ | BC15: ㄑ | BD15: tshi | BE15: ci | BF15: ㄑ | BG15: ㄒ | BH15: si | BI15: si | BJ15: ㄒ
D17: 濁音 | Q17: 入 | S17: ji | AL17: 濁音 | AY17: 入 | BA17: ji
Q19: ㆢ | R19: ji | S19: jji | T19: ㆢ | AY19: ㆢ | AZ19: ji | BA19: ji | BB19: ㆢ
B21: 舌尖中音 | C21: 齒齦音 | D21: 清音 | I21: 地 | K21: t | L21: 底 | M21: 他 | O21: th | P21: 恥 | Q21: 曾 | S21: ts | T21: 止 | U21: 出 | W21: tsh | X21: 取 | Y21: 時 | AA21: s | AB21: 始 | AJ21: 舌尖中音 | AK21: 齒齦音 | AL21: 清音 | AQ21: 地 | AS21: t | AT21: 底 | AU21: 他 | AW21: th | AX21: 恥 | AY21: 曾 | BA21: ts | BB21: 止 | BC21: 出 | BE21: tsh | BF21: 取 | BG21: 時 | BI21: s | BJ21: 始
I23: ㄉ | J23: t | K23: d | L23: ㄉ | M23: ㄊ | N23: th | O23: t | P23: ㄊ | Q23: ㄗ | R23: ts | S23: z | T23: ㄗ | U23: ㄘ | V23: tsh | W23: c | X23: ㄘ | Y23: ㄙ | Z23: s | AA23: s | AB23: ㄙ | AQ23: ㄉ | AR23: t | AS23: d | AT23: ㄉ | AU23: ㄊ | AV23: th | AW23: t | AX23: ㄊ | AY23: ㄗ | AZ23: ts | BA23: z | BB23: ㄗ | BC23: ㄘ | BD23: tsh | BE23: c | BF23: ㄘ | BG23: ㄙ | BH23: s | BI23: s | BJ23: ㄙ
D25: 濁音 | E25: 柳 | G25: n | Q25: 入 | S25: j | T25: 耳 | AC25: 柳 | AE25: l | AF25: 理 | AL25: 濁音 | AM25: 柳 | AO25: n | AY25: 入 | BA25: j | BB25: 耳 | BK25: 柳 | BM25: l | BN25: 理
E27: ㄋ | G27: n | Q27: ㆡ | R27: j | S27: zz | T27: ㆡ | AC27: ㄌ | AD27: l | AE27: l | AF27: ㄌ | AM27: ㄋ | AO27: ln | AY27: ㆡ | AZ27: j | BA27: zz | BB27: ㆡ | BK27: ㄌ | BL27: l | BM27: l | BN27: ㄌ
B29: 舌根音 | C29: 軟顎音 | D29: 清音 | I29: 求 | K29: k | L29: 己 | M29: 去 | O29: kh | P29: 起 | AJ29: 舌根音 | AK29: 軟顎音 | AL29: 清音 | AM29: 語 | AO29: ng | AP29: 雅 | AQ29: 求 | AS29: k | AT29: 己 | AU29: 去 | AW29: kh | AX29: 起
I31: ㄍ | J31: k | K31: g | L31: ㄍ | M31: ㄎ | N31: kh | O31: k | P31: ㄎ | AM31: ㄫ | AN31: ng | AO31: ggn | AP31: ㄫ | AQ31: ㄍ | AR31: k | AS31: g | AT31: ㄍ | AU31: ㄎ | AV31: kh | AW31: k | AX31: ㄎ
D33: 濁音 | E33: 語 | G33: ng | H33: 雅 | I33: 語 | K33: g | L33: 我 | AL33: 濁音 | AQ33: 語 | AS33: ㆣ | AT33: 我
E35: ㄫ | F35: ng | G35: ng | H35: ㄫ | I35: ㆣ | J35: g | K35: gg | L35: ㆣ | AQ35: ㆣ | AR35: g | AS35: gg | AT35: ㆣ
B37: 喉塞音 | C37: 聲門音 | D37: 清音 | I37: 英 | K37: Ø | L37: Ø | Y37: 喜 | AA37: h | AB37: 喜 | AJ37: 喉塞音 | AK37: 聲門音 | AL37: 清音 | AQ37: 英 | AS37: Ø | AT37: Ø | BG37: 喜 | BI37: h | BJ37: 喜
I39: Ø | J39: Ø | K39: Ø | L39: Ø | Y39: ㄏ | Z39: h | AA39: h | AB39: ㄏ | AQ39: Ø | AR39: Ø | AS39: Ø | AT39: Ø | BG39: ㄏ | BH39: h | BI39: h | BJ39: ㄏ

Sheet 聲母十五音發聲表（YX互換）
D2: 雙唇音 | L2: 舌尖前音 | T2: 舌尖中音 | AB2: 舌根音 | AJ2: 㗋塞音
D3: 上脣。下脣 | L3: 舌尖。上齒背 | T3: 舌尖。上齒齦 | AB3: 舌根軟顎 | AJ3: 氣管咽頭
D4: 清音 | H4: 濁音 | L4: 清音 | P4: 濁音 | T4: 清音 | X4: 濁音 | AB4: 清音 | AF4: 濁音 | AJ4: 清音
B5: 鼻音 | H5: 門 | J5: m | X5: 柳 | Z5: n | AF5: 語 | AH5: ng
BP6: 1 | BQ6: ㄅ
H7: ㄇ | J7: m | X7: ㄋ | Z7: n | AF7: ㄫ | AH7: ng | BP7: 2 | BQ7: {=INDIRECT(ADDRESS(ROW($AP$11),COLUMN($AP$11)+(BR7*4)))} -> ㆠ | BR7: 1
AP8: 清音+（塞音/塞擦音） | AT8: 濁音 | AX8: 清音+送氣 | BB8: 濁音+鼻音 | BF8: 濁音+邊音 | BJ8: 清音+擦音 | BP8: 3 | BQ8: {=INDIRECT(ADDRESS(ROW($AP$11),COLUMN($AP$11)+(BR8*4)))} -> ㄆ | BR8: 2
B9: 塞音 | C9: 不送氣 | D9: 邊 | F9: p | H9: 門 | J9: b | T9: 地 | V9: t | AB9: 求 | AD9: k | AF9: 語 | AH9: g | AJ9: 英 | AL9: Ø | AP9: 邊 | AR9: p | AT9: 門 | AV9: b | AX9: 頗 | AZ9: ph | BB9: 毛 | BD9: m | BP9: 4 | BQ9: {=INDIRECT(ADDRESS(ROW($AP$11),COLUMN($AP$11)+(BR9*4)))} -> ㄇ | BR9: 3
BP10: 5 | BQ10: =AP15 -> ㄉ
D11: ㄅ | F11: b | H11: ㆠ | J11: bb | T11: ㄉ | V11: d | AB11: ㄍ | AD11: g | AF11: ㆣ | AH11: gg | AJ11: Ø | AL11: Ø | AP11: ㄅ | AR11: b | AT11: ㆠ | AV11: bb | AX11: ㄆ | AZ11: p | BB11: ㄇ | BD11: m | BP11: 6 | BQ11: {=INDIRECT(ADDRESS(ROW($AP$15),COLUMN($AP$15)+(BR11*4)))} -> ㄊ | BR11: 2
BP12: 7 | BQ12: {=INDIRECT(ADDRESS(ROW($AP$15),COLUMN($AP$15)+(BR12*4)))} -> ㄋ | BR12: 3
C13: 送氣 | D13: 頗 | F13: ph | T13: 他 | V13: th | AB13: 去 | AD13: kh | AP13: 地 | AR13: t | AX13: 他 | AZ13: th | BB13: 耐 | BD13: n | BF13: 柳 | BH13: l | BP13: 8 | BQ13: {=INDIRECT(ADDRESS(ROW($AP$15),COLUMN($AP$15)+(BR13*4)))} -> ㄌ | BR13: 4
BP14: 9 | BQ14: =AP19 -> ㄍ
D15: ㄆ | F15: p | T15: ㄊ | V15: t | AB15: ㄎ | AD15: k | AP15: ㄉ | AR15: d | AX15: ㄊ | AZ15: t | BB15: ㄋ | BD15: n | BF15: ㄌ | BH15: l | BP15: 10 | BQ15: {=INDIRECT(ADDRESS(ROW($AP$19),COLUMN($AP$19)+(BR15*4)))} -> ㆣ | BR15: 1
BP16: 11 | BQ16: {=INDIRECT(ADDRESS(ROW($AP$19),COLUMN($AP$19)+(BR16*4)))} -> ㄎ | BR16: 2
B17: 塞擦音 | C17: 不送氣 | L17: 曾 | N17: tsi | P17: 入 | R17: ji | T17: 曾 | V17: ts | X17: 入 | Z17: j | AP17: 求 | AR17: k | AT17: 語 | AV17: g | AX17: 去 | AZ17: kh | BB17: 雅 | BD17: ng | BP17: 12 | BQ17: {=INDIRECT(ADDRESS(ROW($AP$19),COLUMN($AP$19)+(BR17*4)))} -> ㄫ | BR17: 3
BP18: 13 | BQ18: =BJ23 -> ㄏ
L19: ㄐ | N19: ji | P19: ㆢ | R19: jji | T19: ㄗ | V19: z | X19: ㆡ | Z19: zz | AP19: ㄍ | AR19: g | AT19: ㆣ | AV19: gg | AX19: ㄎ | AZ19: k | BB19: ㄫ | BD19: ng | BP19: 14 | BQ19: =AP27 -> ㄐ
BP20: 15 | BQ20: =AX27 -> ㄑ
C21: 送氣 | L21: 出 | N21: tshi | T21: 出 | V21: tsh | BJ21: 喜 | BL21: h | BP21: 16 | BQ21: =AP31 -> ㄗ
BP22: 17 | BQ22: =AX31 -> ㄘ
L23: ㄑ | N23: chi | T23: ㄘ | V23: c | BJ23: ㄏ | BL23: h | BP23: 18 | BQ23: =BJ31 -> ㄙ
B25: 擦音 | L25: 時 | N25: si | T25: 時 | V25: s | AJ25: 喜 | AL25: h | AP25: 曾 | AR25: tsi | AX25: 出 | AZ25: tshi
L27: ㄒ | N27: shi | T27: ㄙ | V27: s | AJ27: ㄏ | AL27: h | AP27: ㄐ | AR27: ji | AX27: ㄑ | AZ27: chi
B29: 邊音 | X29: 柳 | Z29: l | AP29: 曾 | AR29: ts | AX29: 出 | AZ29: tsh | BJ29: 時 | BL29: s
X31: ㄌ | Z31: l | AP31: ㄗ | AR31: z | AX31: ㄘ | AZ31: c | BJ31: ㄙ | BL31: s

Sheet 十五音聲母 (教材)
B2: 序號 | C2: 音序 | D2: 漢字例 | E2: 十五音 | F2: 新十五音 | G2: 國際音標 | H2: 台羅拼音 | I2: 台語音標 | J2: 白話字 | K2: 閩拼方案 | L2: 注音二式 | M2: 方音符號 | N2: 台語注音
B3: 8 | C3: 1 | D3: 理 | E3: 柳 | F3: 柳 | G3: l | H3: l | I3: l | J3: l | K3: l | L3: l | M3: ㄌ | N3: ㄌ
B4: 9 | C4: 1 | D4: 耐 | E4: 柳 | F4: 耐 | G4: n | H4: n | I4: n | J4: n | K4: ln | L4: n | M4: ㄋ | N4: ㄋ
B5: 2 | C5: 2 | D5: 比 | E5: 邊 | F5: 邊 | G5: p | H5: p | I5: p | J5: p | K5: b | L5: b | M5: ㄅ | N5: ㄅ
B6: 10 | C6: 3 | D6: 己 | E6: 求 | F6: 求 | G6: k | H6: k | I6: k | J6: k | K6: g | L6: g | M6: ㄍ | N6: ㄍ
B7: 11 | C7: 4 | D7: 起 | E7: 去 | F7: 去 | G7: kʰ | H7: kh | I7: kh | J7: kh | K7: k | L7: k | M7: ㄎ | N7: ㄎ
B8: 6 | C8: 5 | D8: 底 | E8: 地 | F8: 地 | G8: t | H8: t | I8: t | J8: t | K8: d | L8: d | M8: ㄉ | N8: ㄉ
B9: 3 | C9: 6 | D9: 鼻 | E9: 頗 | F9: 頗 | G9: pʰ | H9: ph | I9: ph | J9: ph | K9: p | L9: p | M9: ㄆ | N9: ㄆ
B10: 7 | C10: 7 | D10: 替 | E10: 他 | F10: 他 | G10: tʰ | H10: th | I10: th | J10: th | K10: t | L10: t | M10: ㄊ | N10: ㄊ
B11: 15 | C11: 8 | D11: 阻 | E11: 曾 | F11: 曾 | G11: ʦ | H11: ts | I11: z | J11: ch | K11: z | L11: z | M11: ㄗ | N11: ㄗ
B12: 16 | C12: 8 | D12: 止 | E12: 曾 | F12: 曾 | G12: ʨ | H12: tsi | I12: zi | J12: chi | K12: zi | L12: j | M12: ㄐ | N12: ㄐ
B13: 21 | C13: 9 | D13: 如 | E13: 入 | F13: 入 | G13: ʣ | H13: j | I13: j | J13: j | K13: zz | L13: zz | M13: ㆡ | N13: ㄖ
B14: 22 | C14: 9 | D14: 二 | E14: 入 | F14: 入 | G14: ʥ | H14: ji | I14: ji | J14: ji | K14: zzi | L14: jj | M14: ㆢ | N14: ㄖ
... B16: 20 | C16: 10 | D16: 施 | E16: 時 | F16: 時 | G16: ɕ | H16: si | I16: si | J16: si | K16: si | L16: sh | M16: ㄒ | N16: ㄒ
B17: 1 | C17: 11 | D17: 恩 | E17: 英 | F17: 英 | H17: Ø
B18: 4 | C18: 12 | D18: 文 | E18: 門 | F18: 門 | G18: b | H18: b | I18: b | J18: b | K18: bb | L18: bb | M18: ㆠ | N18: ㄪ
B19: 5 | C19: 12 | D19: 毛 | E19: 門 | F19: 毛 | G19: m | H19: m | I19: m | J19: m | K19: bbn | L19: m | M19: ㄇ | N19: ㄇ
B20: 12 | C20: 13 | D20: 禦 | E20: 語 | F20: 語 | G20: ɡ | H20: g | I20: g | J20: g | K20: gg | L20: gg | M20: ㆣ | N20: ㄫ
B21: 13 | C21: 13 | D21: 雅 | E21: 語 | F21: 雅 | G21: ŋ | H21: ng | I21: ng | J21: ng | K21: ggn | L21: ng | M21: ㄫ | N21: ⁰ㄫ
B22: 17 | C22: 14 | D22: 取 | E22: 出 | F22: 出 | G22: ʦʰ | H22: tsh | I22: c | J22: chh | K22: c | L22: c | M22: ㄘ | N22: ㄘ
B23: 18 | C23: 14 | D23: 測 | E23: 出 | F23: 出 | G23: ʨʰ | H23: tshi | I23: ci | J23: chhi | K23: ci | L23: ch | M23: ㄑ | N23: ㄑ
B24: 14 | C24: 15 | D24: 非 | E24: 喜 | F24: 喜 | G24: h | H24: h | I24: h | J24: h | K24: h | L24: h | M24: ㄏ | N24: ㄏ

Sheet 十五音韻母（教材）
B2: 序號 | C2: 韻序 | D2: 漢字例 | E2: 十五音 | F2: 國際音標 | G2: 國際音標2 | H2: 台羅拼音 | I2: 台語音標 | J2: 白話字 | K2: 閩拼方案 | L2: 注音二式 | M2: 方音符號 | N2: 台語注音
B3: 1 | C3: =IF(MOD(韻母表_47[[#This Row],[序號]],2)=0, 韻母表_47[[#This Row],[序號]]/2, ROUNDUP(韻母表_47[[#This Row],[序號]]/2,0)) -> 1 | D3: 分 | E3: 君（舒） | F3: un | H3: un | I3: un | J3: un | K3: un | L3: un | M3: ㄨㄣ | N3: ㄨㄣ
B4: 2 | C4: =IF(MOD(韻母表_47[[#This Row],[序號]],2)=0, 韻母表_47[[#This Row],[序號]]/2, ROUNDUP(韻母表_47[[#This Row],[序號]]/2,0)) -> 1 | D4: 佛 | E4: 君（促） | F4: ut̚ | H4: ut | I4: ut | J4: ut | K4: ut | L4: ut | M4: ㄨㆵ | N4: ㄨㄉ
B5: 3 | C5: =IF(MOD(韻母表_47[[#This Row],[序號]],2)=0, 韻母表_47[[#This Row],[序號]]/2, ROUNDUP(韻母表_47[[#This Row],[序號]]/2,0)) -> 2 | D5: 掀 | E5: 堅（舒） | F5: ɪan | H5: ian | I5: ian | J5: ian | K5: ian | L5: ian | M5: ㄧㄢ | N5: ㄧㄢ
B6: 4 | C6: =IF(MOD(韻母表_47[[#This Row],[序號]],2)=0, 韻母表_47[[#This Row],[序號]]/2, ROUNDUP(韻母表_47[[#This Row],[序號]]/2,0)) -> 2 | D6: 結 | E6: 堅（促） | F6: ɪat̚ | H6: iat | I6: iat | J6: iat | K6: iat | L6: iat | M6: ㄧㄚㆵ | N6: ㄧㄚㄉ
B7: 5 | C7: =IF(MOD(韻母表_47[[#This Row],[序號]],2)=0, 韻母表_47[[#This Row],[序號]]/2, ROUNDUP(韻母表_47[[#This Row],[序號]]/2,0)) -> 3 | D7: 深 | E7: 金（舒） | F7: im | H7: im | I7: im | J7: im | K7: im | L7: im | M7: ㄧㆬ | N7: ㄧㄇ
B8: 6 | C8: =IF(MOD(韻母表_47[[#This Row],[序號]],2)=0, 韻母表_47[[#This Row],[序號]]/2, ROUNDUP(韻母表_47[[#This Row],[序號]]/2,0)) -> 3 | D8: 急 | E8: 金（促） | F8: ip̚ | H8: ip | I8: ip | J8: ip | K8: ip | L8: ip | M8: 一ㆴ | N8: ㄧㄅ
B9: 7 | C9: =IF(MOD(韻母表_47[[#This Row],[序號]],2)=0, 韻母表_47[[#This Row],[序號]]/2, ROUNDUP(韻母表_47[[#This Row],[序號]]/2,0)) -> 4 | D9: 歸 | E9: 規（舒） | F9: ui | H9: ui | I9: ui | J9: ui | K9: ui | L9: ui | M9: ㄨㄧ | N9: ㄨㄧ
B10: 8 | C10: =IF(MOD(韻母表_47[[#This Row],[序號]],2)=0, 韻母表_47[[#This Row],[序號]]/2, ROUNDUP(韻母表_47[[#This Row],[序號]]/2,0)) -> 4 | E10: 規（促）
B11: 9 | C11: =IF(MOD(韻母表_47[[#This Row],[序號]],2)=0, 韻母表_47[[#This Row],[序號]]/2, ROUNDUP(韻母表_47[[#This Row],[序號]]/2,0)) -> 5 | D11: 加 | E11: 嘉（舒） | F11: e | G11: ɛ | H11: ee | I11: ee | J11: 0 | K11: 0 | L11: 0 | M11: ㄝ | N11: ㄝ
B12: 10 | C12: =IF(MOD(韻母表_47[[#This Row],[序號]],2)=0, 韻母表_47[[#This Row],[序號]]/2, ROUNDUP(韻母表_47[[#This Row],[序號]]/2,0)) -> 5 | D12: 格 | E12: 嘉（促） | F12: eʔ | G12: ɛʔ | H12: eeh | I12: eeh | J12: 0 | K12: 0 | L12: 0 | M12: ㄝㆷ | N12: ㄝㄏ
B13: 11 | C13: =IF(MOD(韻母表_47[[#This Row],[序號]],2)=0, 韻母表_47[[#This Row],[序號]]/2, ROUNDUP(韻母表_47[[#This Row],[序號]]/2,0)) -> 6 | D13: 蘭 | E13: 干（舒） | F13: an | H13: an | I13: an | J13: an | K13: an | L13: an | M13: ㄢ | N13: ㄢ
B14: 12 | C14: =IF(MOD(韻母表_47[[#This Row],[序號]],2)=0, 韻母表_47[[#This Row],[序號]]/2, ROUNDUP(韻母表_47[[#This Row],[序號]]/2,0)) -> 6 | D14: 擦 | E14: 干（促） | F14: at̚ | H14: at | I14: at | J14: at | K14: at | L14: at | M14: ㄚㆵ | N14: ㄚㄉ
B15: 13 | C15: =IF(MOD(韻母表_47[[#This Row],[序號]],2)=0, 韻母表_47[[#This Row],[序號]]/2, ROUNDUP(韻母表_47[[#This Row],[序號]]/2,0)) -> 7 | D15: 風 | E15: 公（舒） | F15: ɔŋ | H15: ong | I15: ong | J15: ong | K15: ong | L15: ong | M15: ㆲ | N15: ㄛㄥ
B16: 14 | C16: =IF(MOD(韻母表_47[[#This Row],[序號]],2)=0, 韻母表_47[[#This Row],[序號]]/2, ROUNDUP(韻母表_47[[#This Row],[序號]]/2,0)) -> 7 | D16: 服 | E16: 公（促） | F16: ɔk̚ | H16: ok | I16: ok | J16: ok | K16: ok | L16: ok | M16: ㆦㆻ | N16: ㄛㄍ
B17: 15 | C17: =IF(MOD(韻母表_47[[#This Row],[序號]],2)=0, 韻母表_47[[#This Row],[序號]]/2, ROUNDUP(韻母表_47[[#This Row],[序號]]/2,0)) -> 8 | D17: 怪 | E17: 乖（舒） | F17: uai | H17: uai | I17: uai | J17: oai | K17: uai | L17: uai | M17: ㄨㄞ | N17: ㄨㄞ
B18: 16 | C18: =IF(MOD(韻母表_47[[#This Row],[序號]],2)=0, 韻母表_47[[#This Row],[序號]]/2, ROUNDUP(韻母表_47[[#This Row],[序號]]/2,0)) -> 8 | D18: 孬 | E18: 乖（促） | F18: uaiʔ | H18: uaih | I18: uaih | J18: oaih | K18: uaih | L18: uaih | M18: ㄨㄞㆷ | N18: ㄨㄞㄏ
B19: 17 | C19: =IF(MOD(韻母表_47[[#This Row],[序號]],2)=0, 韻母表_47[[#This Row],[序號]]/2, ROUNDUP(韻母表_47[[#This Row],[序號]]/2,0)) -> 9 | D19: 情 | E19: 經（舒） | F19: ɪŋ | G19: ɛŋ | H19: ing | I19: ing | J19: eng | K19: ing | L19: ing | M19: ㄧㄥ | N19: ㄧㄥ
B20: 18 | C20: =IF(MOD(韻母表_47[[#This Row],[序號]],2)=0, 韻母表_47[[#This Row],[序號]]/2, ROUNDUP(韻母表_47[[#This Row],[序號]]/2,0)) -> 9 | D20: 測 | E20: 經（促） | F20: ɪk | G20: ɛk | H20: ik | I20: ik | J20: ek | K20: ik | L20: ik | M20: ㄧㆻ | N20: ㄧㄍ
B21: 19 | C21: =IF(MOD(韻母表_47[[#This Row],[序號]],2)=0, 韻母表_47[[#This Row],[序號]]/2, ROUNDUP(韻母表_47[[#This Row],[序號]]/2,0)) -> 10 | D21: 團 | E21: 觀（舒） | F21: uan | H21: uan | I21: uan | J21: oan | K21: uan | L21: uan | M21: ㄨㄢ | N21: ㄨㄢ
B22: 20 | C22: =IF(MOD(韻母表_47[[#This Row],[序號]],2)=0, 韻母表_47[[#This Row],[序號]]/2, ROUNDUP(韻母表_47[[#This Row],[序號]]/2,0)) -> 10 | D22: 決 | E22: 觀（促） | F22: uat̚ | H22: uat | I22: uat | J22: oat | K22: uat | L22: uat | M22: ㄨㄚㆵ | N22: ㄨㄚㄉ
B23: 21 | C23: =IF(MOD(韻母表_47[[#This Row],[序號]],2)=0, 韻母表_47[[#This Row],[序號]]/2, ROUNDUP(韻母表_47[[#This Row],[序號]]/2,0)) -> 11 | D23: 姑 | E23: 沽（舒） | F23: ɔ | G23: ou | H23: oo | I23: oo | J23: o͘ | K23: oo | L23: oo | M23: ㆦ | N23: ㄛ
B24: 22 | C24: =IF(MOD(韻母表_47[[#This Row],[序號]],2)=0, 韻母表_47[[#This Row],[序號]]/2, ROUNDUP(韻母表_47[[#This Row],[序號]]/2,0)) -> 11 | E24: 沽（促） | F24: =_xlfn.CONCAT(F23, "h") -> ɔh | H24: =_xlfn.CONCAT(H23, "h") -> ooh | I24: =_xlfn.CONCAT(I23, "h") -> ooh | J24: =_xlfn.CONCAT(J23, "h") -> o͘h | K24: =_xlfn.CONCAT(K23, "h") -> ooh | L24: =_xlfn.CONCAT(L23, "h") -> ooh | M24: =_xlfn.CONCAT(M23, "ㆷ") -> ㆦㆷ | N24: =_xlfn.CONCAT(N23, "ㄏ") -> ㄛㄏ
B25: 23 | C25: =IF(MOD(韻母表_47[[#This Row],[序號]],2)=0, 韻母表_47[[#This Row],[序號]]/2, ROUNDUP(韻母表_47[[#This Row],[序號]]/2,0)) -> 12 | D25: 鵰 | E25: 嬌（舒） | F25: ɪaʊ | H25: iau | I25: iau | J25: iau | K25: iao | L25: iau | M25: ㄧㄠ | N25: ㄧㄠ
B26: 24 | C26: =IF(MOD(韻母表_47[[#This Row],[序號]],2)=0, 韻母表_47[[#This Row],[序號]]/2, ROUNDUP(韻母表_47[[#This Row],[序號]]/2,0)) -> 12 | D26: 愀 | E26: 嬌（促） | F26: ɪaʊʔ | H26: iauh | I26: iauh | J26: iauh | K26: iaoh | L26: iauh | M26: ㄧㄠㆷ | N26: ㄧㄠㄏ
B27: 25 | C27: =IF(MOD(韻母表_47[[#This Row],[序號]],2)=0, 韻母表_47[[#This Row],[序號]]/2, ROUNDUP(韻母表_47[[#This Row],[序號]]/2,0)) -> 13 | D27: 街 | E27: 稽（舒） | F27: e | G27: ei | H27: e | I27: ei | J27: e | K27: e | L27: e | M27: ㆤ | N27: ㄝ
B28: 26 | C28: =IF(MOD(韻母表_47[[#This Row],[序號]],2)=0, 韻母表_47[[#This Row],[序號]]/2, ROUNDUP(韻母表_47[[#This Row],[序號]]/2,0)) -> 13
B29: 27 | C29: =IF(MOD(韻母表_47[[#This Row],[序號]],2)=0, 韻母表_47[[#This Row],[序號]]/2, ROUNDUP(韻母表_47[[#This Row],[序號]]/2,0)) -> 14 | D29: 中 | E29: 恭（舒） | F29: ɪɔŋ | H29: iong | I29: iong | J29: iong | K29: iong | L29: iong | M29: ㄧㆲ | N29: ㄧㄛㄥ
B30: 28 | C30: =IF(MOD(韻母表_47[[#This Row],[序號]],2)=0, 韻母表_47[[#This Row],[序號]]/2, ROUNDUP(韻母表_47[[#This Row],[序號]]/2,0)) -> 14 | D30: 菊 | E30: 恭（促） | F30: ɪɔk̚ | H30: iok | I30: iok | J30: iok | K30: iok | L30: iook | M30: ㄧㆦㆻ | N30: ㄧㄛㄍ
B31: 29 | C31: =IF(MOD(韻母表_47[[#This Row],[序號]],2)=0, 韻母表_47[[#This Row],[序號]]/2, ROUNDUP(韻母表_47[[#This Row],[序號]]/2,0)) -> 15 | D31: 刀 | E31: 高（舒） | F31: ə | H31: o | I31: o | J31: o | K31: o | L31: or | M31: ㄜ | N31: ㄜ
B32: 30 | C32: =IF(MOD(韻母表_47[[#This Row],[序號]],2)=0, 韻母表_47[[#This Row],[序號]]/2, ROUNDUP(韻母表_47[[#This Row],[序號]]/2,0)) -> 15 | D32: 卓 | E32: 高（促） | F32: əʔ | H32: oh | I32: oh | J32: oh | K32: oh | L32: orh | M32: ㄜㆷ | N32: ㄜㄏ
B33: 31 | C33: =IF(MOD(韻母表_47[[#This Row],[序號]],2)=0, 韻母表_47[[#This Row],[序號]]/2, ROUNDUP(韻母表_47[[#This Row],[序號]]/2,0)) -> 16 | D33: 皆 | E33: 皆（舒） | F33: aɪ | H33: ai | I33: ai | J33: ai | K33: ai | L33: ai | M33: ㄞ | N33: ㄞ
B34: 32 | C34: =IF(MOD(韻母表_47[[#This Row],[序號]],2)=0, 韻母表_47[[#This Row],[序號]]/2, ROUNDUP(韻母表_47[[#This Row],[序號]]/2,0)) -> 16
B35: 33 | C35: =IF(MOD(韻母表_47[[#This Row],[序號]],2)=0, 韻母表_47[[#This Row],[序號]]/2, ROUNDUP(韻母表_47[[#This Row],[序號]]/2,0)) -> 17 | D35: 今 | E35: 巾（舒） | F35: in | H35: in | I35: in | J35: in | K35: in | L35: in | M35: ㄧㄣ | N35: ㄧㄣ
B36: 34 | C36: =IF(MOD(韻母表_47[[#This Row],[序號]],2)=0, 韻母表_47[[#This Row],[序號]]/2, ROUNDUP(韻母表_47[[#This Row],[序號]]/2,0)) -> 17 | D36: 乞 | E36: 巾（促） | F36: it̚ | H36: it | I36: it | J36: it | K36: it | L36: it | M36: ㄧㆵ | N36: ㄧㄉ
B37: 35 | C37: =IF(MOD(韻母表_47[[#This Row],[序號]],2)=0, 韻母表_47[[#This Row],[序號]]/2, ROUNDUP(韻母表_47[[#This Row],[序號]]/2,0)) -> 18 | D37: 漳 | E37: 姜（舒） | F37: ɪaŋ | H37: iang | I37: iang | J37: iang | K37: iang | L37: iang | M37: ㄧㄤ | N37: ㄧㄤ
B38: 36 | C38: =IF(MOD(韻母表_47[[#This Row],[序號]],2)=0, 韻母表_47[[#This Row],[序號]]/2, ROUNDUP(韻母表_47[[#This Row],[序號]]/2,0)) -> 18 | D38: 鑠 | E38: 姜（促） | F38: ɪak̚ | H38: iak | I38: iak | J38: iak | K38: iak | L38: iak | M38: ㄧㄚㆻ | N38: ㄧㄚㄍ
B39: 37 | C39: =IF(MOD(韻母表_47[[#This Row],[序號]],2)=0, 韻母表_47[[#This Row],[序號]]/2, ROUNDUP(韻母表_47[[#This Row],[序號]]/2,0)) -> 19 | D39: 堪 | E39: 甘（舒） | F39: am | H39: am | I39: am | J39: am | K39: am | L39: am | M39: ㆰ | N39: ㄚㄇ
B40: 38 | C40: =IF(MOD(韻母表_47[[#This Row],[序號]],2)=0, 韻母表_47[[#This Row],[序號]]/2, ROUNDUP(韻母表_47[[#This Row],[序號]]/2,0)) -> 19 | D40: 合 | E40: 甘（促） | F40: ap̚ | H40: ap | I40: ap | J40: ap | K40: ap | L40: ap | M40: ㄚㆴ | N40: ㄚㄅ
B41: 39 | C41: =IF(MOD(韻母表_47[[#This Row],[序號]],2)=0, 韻母表_47[[#This Row],[序號]]/2, ROUNDUP(韻母表_47[[#This Row],[序號]]/2,0)) -> 20 | D41: 呱 | E41: 瓜（舒） | F41: ua | H41: ua | I41: ua | J41: oa | K41: ua | L41: ua | M41: ㄨㄚ | N41: ㄨㄚ
...

Sheet 字母八音反切
B2: 字母序 | C2: 上平 | D2: 上上 | E2: 上去 | F2: 上入 | G2: 下平 | H2: 下上 | I2: 下去 | J2: 下入 | K2: 舒聲韻 | L2: 促聲韻
C3: 一 | D3: 二 | E3: 三 | F3: 四 | G3: 五 | H3: 六 | I3: 七 | J3: 八 | N3: 1 | O3: 2 | P3: 3 | Q3: 4 | R3: 5 | S3: 6 | T3: 7 | U3: 8 | V3: 註 | W3: 韻讀擬測
B4: 1 | C4: 君 | D4: 滾 | E4: 棍 | F4: 骨 | G4: 群 | H4: 滾 | I4: 郡 | J4: 滑 | K4: =Z4 -> un | L4: =AA4 -> ut | N4: k_un | O4: k_ún | P4: k_ùn | Q4: k_ut | R4: k_ûn | S4: k_ún | T4: k_ūn | U4: k_u̍t | W4: un、ut | X4: un、ut | Y4: =FIND("、",W4) -> 3 | Z4: =LEFT(W4,Y4-1) -> un | AA4: =MID(W4,Y4+1, LEN(W4)) -> ut
B5: 2 | C5: 堅 | D5: 蹇 | E5: 見 | F5: 結 | G5: ○ | H5: 蹇 | I5: 健 | J5: 傑 | K5: =Z5 -> ian | L5: =AA5 -> iat | N5: k_ian | O5: k_ián | P5: k_iàn | Q5: k_iat | R5: k_iân | S5: k_ián | T5: k_iān | U5: k_ia̍t | W5: ian、iat | X5: an、at | Y5: =FIND("、",W5) -> 4 | Z5: =LEFT(W5,Y5-1) -> ian | AA5: =MID(W5,Y5+1, LEN(W5)) -> iat
B6: 3 | C6: 金 | D6: 錦 | E6: 禁 | F6: 急 | G6: ○ | H6: 錦 | I6: 㦗 | J6: 及 | K6: =Z6 -> im | L6: =AA6 -> ip | N6: k_im | O6: k_ím | P6: k_ìm | Q6: k_ip | R6: k_îm | S6: k_ím | T6: k_īm | U6: k_i̍p | W6: im、ip | X6: im、ip | Y6: =FIND("、",W6) -> 3 | Z6: =LEFT(W6,Y6-1) -> im | AA6: =MID(W6,Y6+1, LEN(W6)) -> ip
B7: 4 | C7: 規 | D7: 鬼 | E7: 季 | F7: ○ | G7: 葵 | H7: 鬼 | I7: 櫃 | J7: ○ | K7: =Z7 -> ui | L7: =AA7 -> uih | N7: k_ui | O7: k_uí | P7: k_uì | Q7: k_uih | R7: k_uî | S7: k_uí | T7: k_uī | U7: k_ui̍h | W7: ui、uih | X7: ui、uih | Y7: =FIND("、",W7) -> 3 | Z7: =LEFT(W7,Y7-1) -> ui | AA7: =MID(W7,Y7+1, LEN(W7)) -> uih
B8: 5 | C8: 嘉 | D8: 賈 | E8: 嫁 | F8: 骼 | G8: 枷 | H8: 假 | I8: 下 | J8: 逆 | K8: =Z8 -> ee | L8: =AA8 -> eeh | N8: k_ee | O8: k_ée | P8: k_èe | Q8: k_eeh | R8: k_êe | S8: k_ée | T8: k_ēe | U8: k_e̍h | V8: (c.f.稽&伽) | W8: ee、eeh | X8: e、eh | Y8: =FIND("、",W8) -> 3 | Z8: =LEFT(W8,Y8-1) -> ee | AA8: =MID(W8,Y8+1, LEN(W8)) -> eeh
B9: 6 | C9: 干 | D9: 柬 | E9: 澗 | F9: 葛 | G9: ○ | H9: 柬 | I9: ○ | J9: ○ | K9: =Z9 -> an | L9: =AA9 -> ant | N9: k_an | O9: k_án | P9: k_àn | Q9: k_at | R9: k_ân | S9: k_án | T9: k_ān | U9: k_a̍t | W9: an、ant | X9: an、ant | Y9: =FIND("、",W9) -> 3 | Z9: =LEFT(W9,Y9-1) -> an | AA9: =MID(W9,Y9+1, LEN(W9)) -> ant
B10: 7 | C10: 公 | D10: 廣 | E10: 貢 | F10: 國 | G10: 狂 | H10: 廣 | I10: 狂 | J10: 咯 | K10: =Z10 -> ong | L10: =AA10 -> ok | N10: k_ong | O10: k_óng | P10: k_òng | Q10: k_ok | R10: k_ông | S10: k_óng | T10: k_ōng | U10: k_o̍k | W10: ong、ok | X10: ong、ok | Y10: =FIND("、",W10) -> 4 | Z10: =LEFT(W10,Y10-1) -> ong | AA10: =MID(W10,Y10+1, LEN(W10)) -> ok
B11: 8 | C11: 乖 | D11: 拐 | E11: 怪 | F11: ○ | G11: ○ | H11: 拐 | I11: ○ | J11: ○ | K11: =Z11 -> uai | L11: =AA11 -> uaih | N11: k_uai | O11: k_uái | P11: k_uài | Q11: k_uaih | R11: k_uâi | S11: k_uái | T11: k_uāi | U11: k_ua̍ih | W11: uai、uaih | X11: uai、uaih | Y11: =FIND("、",W11) -> 4 | Z11: =LEFT(W11,Y11-1) -> uai | AA11: =MID(W11,Y11+1, LEN(W11)) -> uaih
B12: 9 | C12: 經 | D12: 景 | E12: 敬 | F12: 格 | G12: 煢 | H12: 景 | I12: 勁 | J12: 極 | K12: =Z12 -> eng | L12: =AA12 -> ek | N12: k_ing | O12: k_íng | P12: k_ìng | Q12: k_ik | R12: k_îng | S12: k_íng | T12: k_īng | U12: k_i̍k | V12: 勁，又作梗。 | W12: eng、ek | X12: ing、ik | Y12: =FIND("、",W12) -> 4 | Z12: =LEFT(W12,Y12-1) -> eng | AA12: =MID(W12,Y12+1, LEN(W12)) -> ek
B13: 10 | C13: 觀 | D13: 琯 | E13: 貫 | F13: 适 | G13: 權 | H13: 琯 | I13: 縣 | J13: 橜 | K13: =Z13 -> uan | L13: =AA13 -> uat | N13: k_uan | O13: k_uán | P13: k_uàn | Q13: k_uat | R13: k_uân | S13: k_uán | T13: k_uān | U13: k_ua̍t | V13: 适，又作決。縣，又作倦。 | W13: uan、uat | X13: uan、uat | Y13: =FIND("、",W13) -> 4 | Z13: =LEFT(W13,Y13-1) -> uan | AA13: =MID(W13,Y13+1, LEN(W13)) -> uat
B14: 11 | C14: 沽 | D14: 古 | E14: 固 | F14: ○ | G14: 糊 | H14: 古 | I14: 怙 | J14: ○ | K14: =Z14 -> oo | L14: =AA14 -> ooh | N14: k_ou | O14: k_óu | P14: k_òu | Q14: k_ouh | R14: k_ôu | S14: k_óu | T14: k_ōu | U14: k_o̍uh | W14: oo、ooh | X14: oo、ooh | Y14: =FIND("、",W14) -> 3 | Z14: =LEFT(W14,Y14-1) -> oo | AA14: =MID(W14,Y14+1, LEN(W14)) -> ooh
B15: 12 | C15: 嬌 | D15: 皎 | E15: 呌 | F15: 勪 | G15: 橋 | H15: 皎 | I15: 轎 | J15: 噭 | K15: =Z15 -> iau | L15: =AA15 -> iauh | N15: k_iau | O15: k_iáu | P15: k_iàu | Q15: k_iauh | R15: k_iâu | S15: k_iáu | T15: k_iāu | U15: k_ia̍uh | V15: 橋,又作喬。 | W15: iau、iauh | X15: iau、iauh | Y15: =FIND("、",W15) -> 4 | Z15: =LEFT(W15,Y15-1) -> iau | AA15: =MID(W15,Y15+1, LEN(W15)) -> iauh
B16: 13 | C16: 稽 | D16: 改 | E16: 計 | F16: 莢 | G16: 鮭 | H16: 改 | I16: 易 | J16: ○ | K16: =Z16 -> e | L16: =AA16 -> eh | N16: k_ei | O16: k_éi | P16: k_èi | Q16: k_eih | R16: k_êi | S16: k_éi | T16: k_ēi | U16: k_e̍ih | V16: (c.f.嘉&伽) | W16: e、eh | X16: e、eh | Y16: =FIND("、",W16) -> 2 | Z16: =LEFT(W16,Y16-1) -> e | AA16: =MID(W16,Y16+1, LEN(W16)) -> eh
B17: 14 | C17: 恭 | D17: 拱 | E17: 供 | F17: 菊 | G17: 窮 | H17: 拱 | I17: 共 | J17: 局 | K17: =Z17 -> iong | L17: =AA17 -> iok | N17: k_iong | O17: k_ióng | P17: k_iòng | Q17: k_iok | R17: k_iông | S17: k_ióng | T17: k_iōng | U17: k_io̍k | W17: iong、iok | X17: iong、iok | Y17: =FIND("、",W17) -> 5 | Z17: =LEFT(W17,Y17-1) -> iong | AA17: =MID(W17,Y17+1, LEN(W17)) -> iok
B18: 15 | C18: 高 | D18: 果 | E18: 過 | F18: 閣 | G18: 翗 | H18: 果 | I18: 膏 | J18: ○ | K18: =Z18 -> o | L18: =AA18 -> oh | N18: k_o | O18: k_ó | P18: k_ò | Q18: k_oh | R18: k_ô | S18: k_ó | T18: k_ò | U18: k_ōh | W18: o、oh | X18: o、oh | Y18: =FIND("、",W18) -> 2 | Z18: =LEFT(W18,Y18-1) -> o | AA18: =MID(W18,Y18+1, LEN(W18)) -> oh
B19: 16 | C19: 皆 | D19: 改 | E19: 介 | F19: ○ | G19: ○ | H19: 改 | I19: ○ | J19: ○ | K19: =Z19 -> ai | L19: =AA19 -> aih | N19: k_ai | O19: k_ái | P19: k_ài | Q19: k_aih | R19: k_âi | S19: k_ái | T19: k_āi | U19: k_a̍ih | W19: ai、aih | X19: ai、aih | Y19: =FIND("、",W19) -> 3 | Z19: =LEFT(W19,Y19-1) -> ai | AA19: =MID(W19,Y19+1, LEN(W19)) -> aih
B20: 17 | C20: 巾 | D20: 謹 | E20: 艮 | F20: 吉 | G20: ○ | H20: 謹 | I20: 近 | J20: 楗 | K20: =Z20 -> in | L20: =AA20 -> it | N20: k_in | O20: k_ín | P20: k_ìn | Q20: k_it | R20: k_în | S20: k_ín | T20: k_īn | U20: k_i̍t | W20: in、it | X20: in、it | Y20: =FIND("、",W20) -> 3 | Z20: =LEFT(W20,Y20-1) -> in | AA20: =MID(W20,Y20+1, LEN(W20)) -> it
B21: 18 | C21: 姜 | D21: 襁 | E21: ○ | F21: 腳 | G21: 强 | H21: 襁 | I21: 倞 | J21: 矍 | K21: =Z21 -> iang | L21: =AA21 -> iak | N21: k_iang | O21: k_iáng | P21: k_iàng | Q21: k_iak | R21: k_iâng | S21: k_iáng | T21: k_iāng | U21: k_ia̍k | V21: 矍(按原稿作｛賏攵｝] | W21: iang、iak | X21: iong、iok | Y21: =FIND("、",W21) -> 5 | Z21: =LEFT(W21,Y21-1) -> iang | AA21: =MID(W21,Y21+1, LEN(W21)) -> iak
B22: 19 | C22: 甘 | D22: 敢 | E22: 鑑 | F22: 鴿 | G22: 銜 | H22: 敢 | I22: 𩼳 | J22: ○ | K22: =Z22 -> am | L22: =AA22 -> ap | N22: k_am | O22: k_ám | P22: k_àm | Q22: k_ap | R22: k_âm | S22: k_ám | T22: k_ām | U22: k_a̍p | W22: am、ap | X22: am、ap | Y22: =FIND("、",W22) -> 3 | Z22: =LEFT(W22,Y22-1) -> am | AA22: =MID(W22,Y22+1, LEN(W22)) -> ap
B23: 20 | C23: 瓜 | D23: 𠙼 | E23: 卦 | F23: 嘓 | G23: ○ | H23: 𠙼 | I23: ○ | J23: ○ | K23: =Z23 -> ua | L23: =AA23 -> uah | N23: k_ua | O23: k_uá | P23: k_uà | Q23: k_uah | R23: k_uâ | S23: k_uá | T23: k_uā | U23: k_ua̍h | W23: ua、uah | X23: ua、uah | Y23: =FIND("、",W23) -> 3 | Z23: =LEFT(W23,Y23-1) -> ua | AA23: =MID(W23,Y23+1, LEN(W23)) -> uah
B24: 21 | C24: 江 | D24: 港 | E24: 降 | F24: 角 | G24: ○ | H24: 港 | I24: 共 | J24: 磔 | K24: =Z24 -> ang | L24: =AA24 -> ak | N24: k_ang | O24: k_áng | P24: k_àng | Q24: k_ak | R24: k_âng | S24: k_áng | T24: k_āng | U24: k_a̍k | W24: ang、ak | X24: ang、ak | Y24: =FIND("、",W24) -> 4 | Z24: =LEFT(W24,Y24-1) -> ang | AA24: =MID(W24,Y24+1, LEN(W24)) -> ak
B25: 22 | C25: 兼 | D25: 檢 | E25: 劍 | F25: 夾 | G25: 鹹 | H25: 檢 | I25: 鐱 | J25: ○ | K25: =Z25 -> iam | L25: =AA25 -> iap | N25: k_iam | O25: k_iám | P25: k_iàm | Q25: k_iap | R25: k_iâm | S25: k_iám | T25: k_iām | U25: k_ia̍p | V25: 鹹(按原稿空白) | W25: iam、iap | X25: iam、iap | Y25: =FIND("、",W25) -> 4 | Z25: =LEFT(W25,Y25-1) -> iam | AA25: =MID(W25,Y25+1, LEN(W25)) -> iap
B26: 23 | C26: 交 | D26: 狡 | E26: 教 | F26: 𩛩 | G26: 侯 | H26: 狡 | I26: 厚 | J26: ○ | K26: =Z26 -> au | L26: =AA26 -> auh | N26: k_au | O26: k_áu | P26: k_àu | Q26: k_auh | R26: k_âu | S26: k_áu | T26: k_āu | U26: k_a̍uh | W26: au、auh | X26: au、auh | Y26: =FIND("、",W26) -> 3 | Z26: =LEFT(W26,Y26-1) -> au | AA26: =MID(W26,Y26+1, LEN(W26)) -> auh
B27: 24 | C27: 迦 | D27: ○ | E27: 寄 | F27: ○ | G27: 伽 | H27: ○ | I27: 崎 | J27: 屐 | K27: =Z27 -> ia | L27: =AA27 -> iah | N27: k_ia | O27: k_iá | P27: k_ià | Q27: k_iah | R27: k_iâ | S27: k_iá | T27: k_iā | U27: k_ia̍h | W27: ia、iah | X27: ia、iah | Y27: =FIND("、",W27) -> 3 | Z27: =LEFT(W27,Y27-1) -> ia | AA27: =MID(W27,Y27+1, LEN(W27)) -> iah
B28: 25 | C28: 檜 | D28: 粿 | E28: 檜 | F28: 郭 | G28: 葵 | H28: 粿 | I28: 趶 | J28: 䭝 | K28: =Z28 -> ue | L28: =AA28 -> ueh | N28: k_uei | O28: k_uéi | P28: k_uèi | Q28: k_ueih | R28: k_uêi | S28: k_uéi | T28: k_uēi | U28: k_ue̍ih | W28: ue、ueh | X28: ue、ueh | Y28: =FIND("、",W28) -> 3 | Z28: =LEFT(W28,Y28-1) -> ue | AA28: =MID(W28,Y28+1, LEN(W28)) -> ueh
B29: 26 | C29: 監 | D29: 敢 | E29: 酵 | F29: ○ | G29: 㩜 | H29: 敢 | I29: ○ | J29: ○ | K29: =Z29 -> ann | L29: =AA29 -> annh | N29: k_ann | O29: k_ánn | P29: k_ànn | Q29: k_annh | R29: k_ânn | S29: k_ánn | T29: k_ānn | U29: k_a̍nnh | W29: ann、annh | X29: ann、annh | Y29: =FIND("、",W29) -> 4 | Z29: =LEFT(W29,Y29-1) -> ann | AA29: =MID(W29,Y29+1, LEN(W29)) -> annh
B30: 27 | C30: 艍 | D30: 韮 | E30: 句 | F30: 𣢯 | G30: 𨬡 | H30: 韮 | I30: 舅 | J30: ○ | K30: =Z30 -> u | L30: =AA30 -> uh | N30: k_u | O30: k_ú | P30: k_ù | Q30: k_uh | R30: k_û | S30: k_ú | T30: k_ū | U30: k_u̍h | W30: u、uh | X30: u、uh | Y30: =FIND("、",W30) -> 2 | Z30: =LEFT(W30,Y30-1) -> u | AA30: =MID(W30,Y30+1, LEN(W30)) -> uh
B31: 28 | C31: 膠 | D31: 絞 | E31: 教 | F31: 甲 | G31: ○ | H31: 絞 | I31: 齩 | J31: ○ | K31: =Z31 -> a | L31: =AA31 -> ah | N31: k_a | O31: k_á | P31: k_à | Q31: k_ah | R31: k_â | S31: k_á | T31: k_ā | U31: k_a̍h | W31: a、ah | X31: a、ah | Y31: =FIND("、",W31) -> 2 | Z31: =LEFT(W31,Y31-1) -> a | AA31: =MID(W31,Y31+1, LEN(W31)) -> ah
B32: 29 | C32: 居 | D32: 己 | E32: 旣 | F32: 築 | G32: 期 | H32: 已 | I32: 具 | J32: ○ | K32: =Z32 -> i | L32: =AA32 -> ih | N32: k_i | O32: k_í | P32: k_ì | Q32: k_ih | R32: k_î | S32: k_í | T32: k_ī | U32: k_i̍h | V32: 己(按古作已) | W32: i、ih | X32: i、ih | Y32: =FIND("、",W32) -> 2 | Z32: =LEFT(W32,Y32-1) -> i | AA32: =MID(W32,Y32+1, LEN(W32)) -> ih
B33: 30 | C33: 丩 | D33: 久 | E33: 救 | F33: ○ | G33: 求 | H33: 久 | I33: 舊 | J33: ○ | K33: =Z33 -> iu | L33: =AA33 -> iuh | N33: k_iu | O33: k_iú | P33: k_iù | Q33: k_iuh | R33: k_iû | S33: k_iú | T33: k_iū | U33: k_iu̍h | W33: iu、iuh | X33: iu、iuh | Y33: =FIND("、",W33) -> 3 | Z33: =LEFT(W33,Y33-1) -> iu | AA33: =MID(W33,Y33+1, LEN(W33)) -> iuh
B34: 31 | C34: 更 | D34: 耞 | E34: 徑 | F34: ○ | G34: ○ | H34: 耞 | I34: ○ | J34: ○ | K34: =Z34 -> enn | L34: =AA34 -> ennh | N34: k_eenn | O34: k_éenn | P34: k_èenn | Q34: k_eennh | R34: k_êenn | S34: k_éenn | T34: k_ēenn | U34: k_e̍ennh | W34: enn、ennh | X34: enn、ennh | Y34: =FIND("、",W34) -> 4 | Z34: =LEFT(W34,Y34-1) -> enn | AA34: =MID(W34,Y34+1, LEN(W34)) -> ennh
B35: 32 | C35: 褌 | D35: 捲 | E35: 卷 | F35: ○ | G35: ○ | H35: 捲 | I35: ○ | J35: ○ | K35: =Z35 -> uinn | L35: =AA35 -> uinnh | N35: k_uinn | O35: k_uínn | P35: k_uìnn | Q35: k_uinnh | R35: k_uînn | S35: k_uínn | T35: k_uīnn | U35: k_ui̍nnh | V35: (c.f.鋼) | W35: uinn、uinnh | X35: ng、ngh | Y35: =FIND("、",W35) -> 5 | Z35: =LEFT(W35,Y35-1) -> uinn | AA35: =MID(W35,Y35+1, LEN(W35)) -> uinnh
B36: 33 | C36: 茄 | D36: ○ | E36: 呌 | F36: 腳 | G36: 茄 | H36: ○ | I36: 轎 | J36: ○ | K36: =Z36 -> io | L36: =AA36 -> ioh | N36: k_io | O36: k_ió | P36: k_iò | Q36: k_ioh | R36: k_iô | S36: k_ió | T36: k_iō | U36: k_io̍h | W36: io、ioh | X36: io、ioh | Y36: =FIND("、",W36) -> 3 | Z36: =LEFT(W36,Y36-1) -> io | AA36: =MID(W36,Y36+1, LEN(W36)) -> ioh
B37: 34 | C37: 梔 | D37: ○ | E37: 見 | F37: ○ | G37: 墘 | H37: ○ | I37: ○ | J37: ○ | K37: =Z37 -> inn | L37: =AA37 -> innh | N37: k_inn | O37: k_ínn | P37: k_ìnn | Q37: k_innh | R37: k_înn | S37: k_ínn | T37: k_īnn | U37: k_i̍nnh | W37: inn、innh | X37: inn、innh | Y37: =FIND("、",W37) -> 4 | Z37: =LEFT(W37,Y37-1) -> inn | AA37: =MID(W37,Y37+1, LEN(W37)) -> innh
B38: 35 | C38: 薑 | D38: ○ | E38: ○ | F38: ○ | G38: 強 | H38: ○ | I38: 謽 | J38: ○ | K38: =Z38 -> ionn | L38: =AA38 -> ionnh | N38: k_ionn | O38: k_iónn | P38: k_iònn | Q38: k_ionnh | R38: k_iônn | S38: k_iónn | T38: k_iōnn | U38: k_io̍nnh | V38: (c.f.牛) | W38: ionn、ionnh | X38: iunn、iunnh | Y38: =FIND("、",W38) -> 5 | Z38: =LEFT(W38,Y38-1) -> ionn | AA38: =MID(W38,Y38+1, LEN(W38)) -> ionnh
B39: 36 | C39: 驚 | D39: 囝 | E39: 鏡 | F39: ○ | G39: 行 | H39: 囝 | I39: 件 | J39: ○ | K39: =Z39 -> iann | L39: =AA39 -> iannh | N39: k_iann | O39: k_iánn | P39: k_iànn | Q39: k_iannh | R39: k_iânn | S39: k_iánn | T39: k_iānn | U39: k_ia̍nnh | W39: iann、iannh | X39: iann、iannh | Y39: =FIND("、",W39) -> 5 | Z39: =LEFT(W39,Y39-1) -> iann | AA39: =MID(W39,Y39+1, LEN(W39)) -> iannh
B40: 37 | C40: 官 | D40: 寡 | E40: 觀 | F40: ○ | G40: 寒 | H40: 寡 | I40: 汗 | J40: ○ | K40: =Z40 -> uann | L40: =AA40 -> uannh | N40: k_uann | O40: k_uánn | P40: k_uànn | Q40: k_uannh | R40: k_uânn | S40: k_uánn | T40: k_uānn | U40: k_ua̍nnh | W40: uann、uannh | X40: uann、uannh | Y40: =FIND("、",W40) -> 5 | Z40: =LEFT(W40,Y40-1) -> uann | AA40: =MID(W40,Y40+1, LEN(W40)) -> uannh
B41: 38 | C41: 鋼 | D41: ○ | E41: 槓 | F41: ○ | G41: ○ | H41: ○ | I41: ○ | J41: ○ | K41: =Z41 -> ng | L41: =AA41 -> ngh | N41: k_ng | O41: k_ńg | P41: k_ǹg | Q41: k_ngh | R41: k_n̂g | S41: k_ńg | T41: k_n̄g | U41: k_n̍gh | V41: (c.f.褌) | W41: ng、ngh | X41: ng、ngh | Y41: =FIND("、",W41) -> 3 | Z41: =LEFT(W41,Y41-1) -> ng | AA41: =MID(W41,Y41+1, LEN(W41)) -> ngh
...

Sheet 字母八音反切【上下標音】
B2: 字母序 | C2: 上平 | D2: 上上 | E2: 上去 | F2: 上入 | G2: 下平 | H2: 下上 | I2: 下去 | J2: 下入
C3: 1 | D3: 2 | E3: 3 | F3: 4 | G3: 5 | H3: 6 | I3: 7 | J3: 8
B4: 1 | C4: =_xlfn.CONCAT( IF(OR(C$3=4, C$3=8), _xlfn.XLOOKUP(($B4*2), 韻母表[序號], 韻母表[方音符號]), _xlfn.XLOOKUP($B4, 韻母表[韻序], 韻母表[方音符號]) ), _xlfn.XLOOKUP(C$3, 聲調符號表[調號], 聲調符號表[調符])) -> ㄨㄣ | D4: =_xlfn.CONCAT( IF(OR(D$3=4, D$3=8), _xlfn.XLOOKUP(($B4*2), 韻母表[序號], 韻母表[方音符號]), _xlfn.XLOOKUP($B4, 韻母表[韻序], 韻母表[方音符號]) ), _xlfn.XLOOKUP(D$3, 聲調符號表[調號], 聲調符號表[調符])) -> ㄨㄣˋ | E4: =_xlfn.CONCAT( IF(OR(E$3=4, E$3=8), _xlfn.XLOOKUP(($B4*2), 韻母表[序號], 韻母表[方音符號]), _xlfn.XLOOKUP($B4, 韻母表[韻序], 韻母表[方音符號]) ), _xlfn.XLOOKUP(E$3, 聲調符號表[調號], 聲調符號表[調符])) -> ㄨㄣ˪ | F4: =_xlfn.CONCAT( IF(OR(F$3=4, F$3=8), _xlfn.XLOOKUP(($B4*2), 韻母表[序號], 韻母表[方音符號]), _xlfn.XLOOKUP($B4, 韻母表[韻序], 韻母表[方音符號]) ), _xlfn.XLOOKUP(F$3, 聲調符號表[調號], 聲調符號表[調符])) -> ㄨㆵ | G4: =_xlfn.CONCAT( IF(OR(G$3=4, G$3=8), _xlfn.XLOOKUP(($B4*2), 韻母表[序號], 韻母表[方音符號]), _xlfn.XLOOKUP($B4, 韻母表[韻序], 韻母表[方音符號]) ), _xlfn.XLOOKUP(G$3, 聲調符號表[調號], 聲調符號表[調符])) -> ㄨㄣˊ | H4: =_xlfn.CONCAT( IF(OR(H$3=4, H$3=8), _xlfn.XLOOKUP(($B4*2), 韻母表[序號], 韻母表[方音符號]), _xlfn.XLOOKUP($B4, 韻母表[韻序], 韻母表[方音符號]) ), _xlfn.XLOOKUP(H$3, 聲調符號表[調號], 聲調符號表[調符])) -> ㄨㄣˋ | I4: =_xlfn.CONCAT( IF(OR(I$3=4, I$3=8), _xlfn.XLOOKUP(($B4*2), 韻母表[序號], 韻母表[方音符號]), _xlfn.XLOOKUP($B4, 韻母表[韻序], 韻母表[方音符號]) ), _xlfn.XLOOKUP(I$3, 聲調符號表[調號], 聲調符號表[調符])) -> ㄨㄣ˫ | J4: =_xlfn.CONCAT( IF(OR(J$3=4, J$3=8), _xlfn.XLOOKUP(($B4*2), 韻母表[序號], 韻母表[方音符號]), _xlfn.XLOOKUP($B4, 韻母表[韻序], 韻母表[方音符號]) ), _xlfn.XLOOKUP(J$3, 聲調符號表[調號], 聲調符號表[調符])) -> ㄨㆵ˙
C5: {=INDEX(字母八音反切!$C$4:$J$53, $B4, C$3)} -> 君 | D5: {=INDEX(字母八音反切!$C$4:$J$53, $B4, D$3)} -> 滾 | E5: {=INDEX(字母八音反切!$C$4:$J$53, $B4, E$3)} -> 棍 | F5: {=INDEX(字母八音反切!$C$4:$J$53, $B4, F$3)} -> 骨 | G5: {=INDEX(字母八音反切!$C$4:$J$53, $B4, G$3)} -> 群 | H5: {=INDEX(字母八音反切!$C$4:$J$53, $B4, H$3)} -> 滾 | I5: {=INDEX(字母八音反切!$C$4:$J$53, $B4, I$3)} -> 郡 | J5: {=INDEX(字母八音反切!$C$4:$J$53, $B4, J$3)} -> 滑
C6: =_xlfn.CONCAT( IF(OR(C$3=4, C$3=8), _xlfn.XLOOKUP(($B4*2), 韻母表[序號], 韻母表[台羅拼音]), _xlfn.XLOOKUP($B4, 韻母表[韻序], 韻母表[台羅拼音]) ), C$3) -> un1 | D6: =_xlfn.CONCAT( IF(OR(D$3=4, D$3=8), _xlfn.XLOOKUP(($B4*2), 韻母表[序號], 韻母表[台羅拼音]), _xlfn.XLOOKUP($B4, 韻母表[韻序], 韻母表[台羅拼音]) ), D$3) -> un2 | E6: =_xlfn.CONCAT( IF(OR(E$3=4, E$3=8), _xlfn.XLOOKUP(($B4*2), 韻母表[序號], 韻母表[台羅拼音]), _xlfn.XLOOKUP($B4, 韻母表[韻序], 韻母表[台羅拼音]) ), E$3) -> un3 | F6: =_xlfn.CONCAT( IF(OR(F$3=4, F$3=8), _xlfn.XLOOKUP(($B4*2), 韻母表[序號], 韻母表[台羅拼音]), _xlfn.XLOOKUP($B4, 韻母表[韻序], 韻母表[台羅拼音]) ), F$3) -> ut4 | G6: =_xlfn.CONCAT( IF(OR(G$3=4, G$3=8), _xlfn.XLOOKUP(($B4*2), 韻母表[序號], 韻母表[台羅拼音]), _xlfn.XLOOKUP($B4, 韻母表[韻序], 韻母表[台羅拼音]) ), G$3) -> un5 | H6: =_xlfn.CONCAT( IF(OR(H$3=4, H$3=8), _xlfn.XLOOKUP(($B4*2), 韻母表[序號], 韻母表[台羅拼音]), _xlfn.XLOOKUP($B4, 韻母表[韻序], 韻母表[台羅拼音]) ), H$3) -> un6 | I6: =_xlfn.CONCAT( IF(OR(I$3=4, I$3=8), _xlfn.XLOOKUP(($B4*2), 韻母表[序號], 韻母表[台羅拼音]), _xlfn.XLOOKUP($B4, 韻母表[韻序], 韻母表[台羅拼音]) ), I$3) -> un7 | J6: =_xlfn.CONCAT( IF(OR(J$3=4, J$3=8), _xlfn.XLOOKUP(($B4*2), 韻母表[序號], 韻母表[台羅拼音]), _xlfn.XLOOKUP($B4, 韻母表[韻序], 韻母表[台羅拼音]) ), J$3) -> ut8
B7: 2 | C7: =_xlfn.CONCAT( IF(OR(C$3=4, C$3=8), _xlfn.XLOOKUP(($B7*2), 韻母表[序號], 韻母表[方音符號]), _xlfn.XLOOKUP($B7, 韻母表[韻序], 韻母表[方音符號]) ), _xlfn.XLOOKUP(C$3, 聲調符號表[調號], 聲調符號表[調符])) -> ㄧㄢ | D7: =_xlfn.CONCAT( IF(OR(D$3=4, D$3=8), _xlfn.XLOOKUP(($B7*2), 韻母表[序號], 韻母表[方音符號]), _xlfn.XLOOKUP($B7, 韻母表[韻序], 韻母表[方音符號]) ), _xlfn.XLOOKUP(D$3, 聲調符號表[調號], 聲調符號表[調符])) -> ㄧㄢˋ | E7: =_xlfn.CONCAT( IF(OR(E$3=4, E$3=8), _xlfn.XLOOKUP(($B7*2), 韻母表[序號], 韻母表[方音符號]), _xlfn.XLOOKUP($B7, 韻母表[韻序], 韻母表[方音符號]) ), _xlfn.XLOOKUP(E$3, 聲調符號表[調號], 聲調符號表[調符])) -> ㄧㄢ˪ | F7: =_xlfn.CONCAT( IF(OR(F$3=4, F$3=8), _xlfn.XLOOKUP(($B7*2), 韻母表[序號], 韻母表[方音符號]), _xlfn.XLOOKUP($B7, 韻母表[韻序], 韻母表[方音符號]) ), _xlfn.XLOOKUP(F$3, 聲調符號表[調號], 聲調符號表[調符])) -> ㄧㄚㆵ | G7: =_xlfn.CONCAT( IF(OR(G$3=4, G$3=8), _xlfn.XLOOKUP(($B7*2), 韻母表[序號], 韻母表[方音符號]), _xlfn.XLOOKUP($B7, 韻母表[韻序], 韻母表[方音符號]) ), _xlfn.XLOOKUP(G$3, 聲調符號表[調號], 聲調符號表[調符])) -> ㄧㄢˊ | H7: =_xlfn.CONCAT( IF(OR(H$3=4, H$3=8), _xlfn.XLOOKUP(($B7*2), 韻母表[序號], 韻母表[方音符號]), _xlfn.XLOOKUP($B7, 韻母表[韻序], 韻母表[方音符號]) ), _xlfn.XLOOKUP(H$3, 聲調符號表[調號], 聲調符號表[調符])) -> ㄧㄢˋ | I7: =_xlfn.CONCAT( IF(OR(I$3=4, I$3=8), _xlfn.XLOOKUP(($B7*2), 韻母表[序號], 韻母表[方音符號]), _xlfn.XLOOKUP($B7, 韻母表[韻序], 韻母表[方音符號]) ), _xlfn.XLOOKUP(I$3, 聲調符號表[調號], 聲調符號表[調符])) -> ㄧㄢ˫ | J7: =_xlfn.CONCAT( IF(OR(J$3=4, J$3=8), _xlfn.XLOOKUP(($B7*2), 韻母表[序號], 韻母表[方音符號]), _xlfn.XLOOKUP($B7, 韻母表[韻序], 韻母表[方音符號]) ), _xlfn.XLOOKUP(J$3, 聲調符號表[調號], 聲調符號表[調符])) -> ㄧㄚㆵ˙
B8: 2 | C8: {=INDEX(字母八音反切!$C$4:$J$53, $B7, C$3)} -> 堅 | D8: {=INDEX(字母八音反切!$C$4:$J$53, $B7, D$3)} -> 蹇 | E8: {=INDEX(字母八音反切!$C$4:$J$53, $B7, E$3)} -> 見 | F8: {=INDEX(字母八音反切!$C$4:$J$53, $B7, F$3)} -> 結 | G8: {=INDEX(字母八音反切!$C$4:$J$53, $B7, G$3)} -> ○ | H8: {=INDEX(字母八音反切!$C$4:$J$53, $B7, H$3)} -> 蹇 | I8: {=INDEX(字母八音反切!$C$4:$J$53, $B7, I$3)} -> 健 | J8: {=INDEX(字母八音反切!$C$4:$J$53, $B7, J$3)} -> 傑
C9: =_xlfn.CONCAT( IF(OR(C$3=4, C$3=8), _xlfn.XLOOKUP(($B7*2), 韻母表[序號], 韻母表[台羅拼音]), _xlfn.XLOOKUP($B7, 韻母表[韻序], 韻母表[台羅拼音]) ), C$3) -> ian1 | D9: =_xlfn.CONCAT( IF(OR(D$3=4, D$3=8), _xlfn.XLOOKUP(($B7*2), 韻母表[序號], 韻母表[台羅拼音]), _xlfn.XLOOKUP($B7, 韻母表[韻序], 韻母表[台羅拼音]) ), D$3) -> ian2 | E9: =_xlfn.CONCAT( IF(OR(E$3=4, E$3=8), _xlfn.XLOOKUP(($B7*2), 韻母表[序號], 韻母表[台羅拼音]), _xlfn.XLOOKUP($B7, 韻母表[韻序], 韻母表[台羅拼音]) ), E$3) -> ian3 | F9: =_xlfn.CONCAT( IF(OR(F$3=4, F$3=8), _xlfn.XLOOKUP(($B7*2), 韻母表[序號], 韻母表[台羅拼音]), _xlfn.XLOOKUP($B7, 韻母表[韻序], 韻母表[台羅拼音]) ), F$3) -> iat4 | G9: =_xlfn.CONCAT( IF(OR(G$3=4, G$3=8), _xlfn.XLOOKUP(($B7*2), 韻母表[序號], 韻母表[台羅拼音]), _xlfn.XLOOKUP($B7, 韻母表[韻序], 韻母表[台羅拼音]) ), G$3) -> ian5 | H9: =_xlfn.CONCAT( IF(OR(H$3=4, H$3=8), _xlfn.XLOOKUP(($B7*2), 韻母表[序號], 韻母表[台羅拼音]), _xlfn.XLOOKUP($B7, 韻母表[韻序], 韻母表[台羅拼音]) ), H$3) -> ian6 | I9: =_xlfn.CONCAT( IF(OR(I$3=4, I$3=8), _xlfn.XLOOKUP(($B7*2), 韻母表[序號], 韻母表[台羅拼音]), _xlfn.XLOOKUP($B7, 韻母表[韻序], 韻母表[台羅拼音]) ), I$3) -> ian7 | J9: =_xlfn.CONCAT( IF(OR(J$3=4, J$3=8), _xlfn.XLOOKUP(($B7*2), 韻母表[序號], 韻母表[台羅拼音]), _xlfn.XLOOKUP($B7, 韻母表[韻序], 韻母表[台羅拼音]) ), J$3) -> iat8
B10: 3 | C10: =_xlfn.CONCAT( IF(OR(C$3=4, C$3=8), _xlfn.XLOOKUP(($B10*2), 韻母表[序號], 韻母表[方音符號]), _xlfn.XLOOKUP($B10, 韻母表[韻序], 韻母表[方音符號]) ), _xlfn.XLOOKUP(C$3, 聲調符號表[調號], 聲調符號表[調符])) -> ㄧㆬ | D10: =_xlfn.CONCAT( IF(OR(D$3=4, D$3=8), _xlfn.XLOOKUP(($B10*2), 韻母表[序號], 韻母表[方音符號]), _xlfn.XLOOKUP($B10, 韻母表[韻序], 韻母表[方音符號]) ), _xlfn.XLOOKUP(D$3, 聲調符號表[調號], 聲調符號表[調符])) -> ㄧㆬˋ | E10: =_xlfn.CONCAT( IF(OR(E$3=4, E$3=8), _xlfn.XLOOKUP(($B10*2), 韻母表[序號], 韻母表[方音符號]), _xlfn.XLOOKUP($B10, 韻母表[韻序], 韻母表[方音符號]) ), _xlfn.XLOOKUP(E$3, 聲調符號表[調號], 聲調符號表[調符])) -> ㄧㆬ˪ | F10: =_xlfn.CONCAT( IF(OR(F$3=4, F$3=8), _xlfn.XLOOKUP(($B10*2), 韻母表[序號], 韻母表[方音符號]), _xlfn.XLOOKUP($B10, 韻母表[韻序], 韻母表[方音符號]) ), _xlfn.XLOOKUP(F$3, 聲調符號表[調號], 聲調符號表[調符])) -> 一ㆴ | G10: =_xlfn.CONCAT( IF(OR(G$3=4, G$3=8), _xlfn.XLOOKUP(($B10*2), 韻母表[序號], 韻母表[方音符號]), _xlfn.XLOOKUP($B10, 韻母表[韻序], 韻母表[方音符號]) ), _xlfn.XLOOKUP(G$3, 聲調符號表[調號], 聲調符號表[調符])) -> ㄧㆬˊ | H10: =_xlfn.CONCAT( IF(OR(H$3=4, H$3=8), _xlfn.XLOOKUP(($B10*2), 韻母表[序號], 韻母表[方音符號]), _xlfn.XLOOKUP($B10, 韻母表[韻序], 韻母表[方音符號]) ), _xlfn.XLOOKUP(H$3, 聲調符號表[調號], 聲調符號表[調符])) -> ㄧㆬˋ | I10: =_xlfn.CONCAT( IF(OR(I$3=4, I$3=8), _xlfn.XLOOKUP(($B10*2), 韻母表[序號], 韻母表[方音符號]), _xlfn.XLOOKUP($B10, 韻母表[韻序], 韻母表[方音符號]) ), _xlfn.XLOOKUP(I$3, 聲調符號表[調號], 聲調符號表[調符])) -> ㄧㆬ˫ | J10: =_xlfn.CONCAT( IF(OR(J$3=4, J$3=8), _xlfn.XLOOKUP(($B10*2), 韻母表[序號], 韻母表[方音符號]), _xlfn.XLOOKUP($B10, 韻母表[韻序], 韻母表[方音符號]) ), _xlfn.XLOOKUP(J$3, 聲調符號表[調號], 聲調符號表[調符])) -> 一ㆴ˙
B11: 3 | C11: {=INDEX(字母八音反切!$C$4:$J$53, $B10, C$3)} -> 金 | D11: {=INDEX(字母八音反切!$C$4:$J$53, $B10, D$3)} -> 錦 | E11: {=INDEX(字母八音反切!$C$4:$J$53, $B10, E$3)} -> 禁 | F11: {=INDEX(字母八音反切!$C$4:$J$53, $B10, F$3)} -> 急 | G11: {=INDEX(字母八音反切!$C$4:$J$53, $B10, G$3)} -> ○ | H11: {=INDEX(字母八音反切!$C$4:$J$53, $B10, H$3)} -> 錦 | I11: {=INDEX(字母八音反切!$C$4:$J$53, $B10, I$3)} -> 㦗 | J11: {=INDEX(字母八音反切!$C$4:$J$53, $B10, J$3)} -> 及
C12: =_xlfn.CONCAT( IF(OR(C$3=4, C$3=8), _xlfn.XLOOKUP(($B10*2), 韻母表[序號], 韻母表[台羅拼音]), _xlfn.XLOOKUP($B10, 韻母表[韻序], 韻母表[台羅拼音]) ), C$3) -> im1 | D12: =_xlfn.CONCAT( IF(OR(D$3=4, D$3=8), _xlfn.XLOOKUP(($B10*2), 韻母表[序號], 韻母表[台羅拼音]), _xlfn.XLOOKUP($B10, 韻母表[韻序], 韻母表[台羅拼音]) ), D$3) -> im2 | E12: =_xlfn.CONCAT( IF(OR(E$3=4, E$3=8), _xlfn.XLOOKUP(($B10*2), 韻母表[序號], 韻母表[台羅拼音]), _xlfn.XLOOKUP($B10, 韻母表[韻序], 韻母表[台羅拼音]) ), E$3) -> im3 | F12: =_xlfn.CONCAT( IF(OR(F$3=4, F$3=8), _xlfn.XLOOKUP(($B10*2), 韻母表[序號], 韻母表[台羅拼音]), _xlfn.XLOOKUP($B10, 韻母表[韻序], 韻母表[台羅拼音]) ), F$3) -> ip4 | G12: =_xlfn.CONCAT( IF(OR(G$3=4, G$3=8), _xlfn.XLOOKUP(($B10*2), 韻母表[序號], 韻母表[台羅拼音]), _xlfn.XLOOKUP($B10, 韻母表[韻序], 韻母表[台羅拼音]) ), G$3) -> im5 | H12: =_xlfn.CONCAT( IF(OR(H$3=4, H$3=8), _xlfn.XLOOKUP(($B10*2), 韻母表[序號], 韻母表[台羅拼音]), _xlfn.XLOOKUP($B10, 韻母表[韻序], 韻母表[台羅拼音]) ), H$3) -> im6 | I12: =_xlfn.CONCAT( IF(OR(I$3=4, I$3=8), _xlfn.XLOOKUP(($B10*2), 韻母表[序號], 韻母表[台羅拼音]), _xlfn.XLOOKUP($B10, 韻母表[韻序], 韻母表[台羅拼音]) ), I$3) -> im7 | J12: =_xlfn.CONCAT( IF(OR(J$3=4, J$3=8), _xlfn.XLOOKUP(($B10*2), 韻母表[序號], 韻母表[台羅拼音]), _xlfn.XLOOKUP($B10, 韻母表[韻序], 韻母表[台羅拼音]) ), J$3) -> ip8
B13: 4 | C13: =_xlfn.CONCAT( IF(OR(C$3=4, C$3=8), _xlfn.XLOOKUP(($B13*2), 韻母表[序號], 韻母表[方音符號]), _xlfn.XLOOKUP($B13, 韻母表[韻序], 韻母表[方音符號]) ), _xlfn.XLOOKUP(C$3, 聲調符號表[調號], 聲調符號表[調符])) -> ㄨㄧ | D13: =_xlfn.CONCAT( IF(OR(D$3=4, D$3=8), _xlfn.XLOOKUP(($B13*2), 韻母表[序號], 韻母表[方音符號]), _xlfn.XLOOKUP($B13, 韻母表[韻序], 韻母表[方音符號]) ), _xlfn.XLOOKUP(D$3, 聲調符號表[調號], 聲調符號表[調符])) -> ㄨㄧˋ | E13: =_xlfn.CONCAT( IF(OR(E$3=4, E$3=8), _xlfn.XLOOKUP(($B13*2), 韻母表[序號], 韻母表[方音符號]), _xlfn.XLOOKUP($B13, 韻母表[韻序], 韻母表[方音符號]) ), _xlfn.XLOOKUP(E$3, 聲調符號表[調號], 聲調符號表[調符])) -> ㄨㄧ˪ | F13: =_xlfn.CONCAT( IF(OR(F$3=4, F$3=8), _xlfn.XLOOKUP(($B13*2), 韻母表[序號], 韻母表[方音符號]), _xlfn.XLOOKUP($B13, 韻母表[韻序], 韻母表[方音符號]) ), _xlfn.XLOOKUP(F$3, 聲調符號表[調號], 聲調符號表[調符])) -> ㄨㄧㆷ | G13: =_xlfn.CONCAT( IF(OR(G$3=4, G$3=8), _xlfn.XLOOKUP(($B13*2), 韻母表[序號], 韻母表[方音符號]), _xlfn.XLOOKUP($B13, 韻母表[韻序], 韻母表[方音符號]) ), _xlfn.XLOOKUP(G$3, 聲調符號表[調號], 聲調符號表[調符])) -> ㄨㄧˊ | H13: =_xlfn.CONCAT( IF(OR(H$3=4, H$3=8), _xlfn.XLOOKUP(($B13*2), 韻母表[序號], 韻母表[方音符號]), _xlfn.XLOOKUP($B13, 韻母表[韻序], 韻母表[方音符號]) ), _xlfn.XLOOKUP(H$3, 聲調符號表[調號], 聲調符號表[調符])) -> ㄨㄧˋ | I13: =_xlfn.CONCAT( IF(OR(I$3=4, I$3=8), _xlfn.XLOOKUP(($B13*2), 韻母表[序號], 韻母表[方音符號]), _xlfn.XLOOKUP($B13, 韻母表[韻序], 韻母表[方音符號]) ), _xlfn.XLOOKUP(I$3, 聲調符號表[調號], 聲調符號表[調符])) -> ㄨㄧ˫ | J13: =_xlfn.CONCAT( IF(OR(J$3=4, J$3=8), _xlfn.XLOOKUP(($B13*2), 韻母表[序號], 韻母表[方音符號]), _xlfn.XLOOKUP($B13, 韻母表[韻序], 韻母表[方音符號]) ), _xlfn.XLOOKUP(J$3, 聲調符號表[調號], 聲調符號表[調符])) -> ㄨㄧㆷ˙
B14: 3.7 | C14: {=INDEX(字母八音反切!$C$4:$J$53, $B13, C$3)} -> 規 | D14: {=INDEX(字母八音反切!$C$4:$J$53, $B13, D$3)} -> 鬼 | E14: {=INDEX(字母八音反切!$C$4:$J$53, $B13, E$3)} -> 季 | F14: {=INDEX(字母八音反切!$C$4:$J$53, $B13, F$3)} -> ○ | G14: {=INDEX(字母八音反切!$C$4:$J$53, $B13, G$3)} -> 葵 | H14: {=INDEX(字母八音反切!$C$4:$J$53, $B13, H$3)} -> 鬼 | I14: {=INDEX(字母八音反切!$C$4:$J$53, $B13, I$3)} -> 櫃 | J14: {=INDEX(字母八音反切!$C$4:$J$53, $B13, J$3)} -> ○
B15: 4 | C15: =_xlfn.CONCAT( IF(OR(C$3=4, C$3=8), _xlfn.XLOOKUP(($B13*2), 韻母表[序號], 韻母表[台羅拼音]), _xlfn.XLOOKUP($B13, 韻母表[韻序], 韻母表[台羅拼音]) ), C$3) -> ui1 | D15: =_xlfn.CONCAT( IF(OR(D$3=4, D$3=8), _xlfn.XLOOKUP(($B13*2), 韻母表[序號], 韻母表[台羅拼音]), _xlfn.XLOOKUP($B13, 韻母表[韻序], 韻母表[台羅拼音]) ), D$3) -> ui2 | E15: =_xlfn.CONCAT( IF(OR(E$3=4, E$3=8), _xlfn.XLOOKUP(($B13*2), 韻母表[序號], 韻母表[台羅拼音]), _xlfn.XLOOKUP($B13, 韻母表[韻序], 韻母表[台羅拼音]) ), E$3) -> ui3 | F15: =_xlfn.CONCAT( IF(OR(F$3=4, F$3=8), _xlfn.XLOOKUP(($B13*2), 韻母表[序號], 韻母表[台羅拼音]), _xlfn.XLOOKUP($B13, 韻母表[韻序], 韻母表[台羅拼音]) ), F$3) -> ui4 | G15: =_xlfn.CONCAT( IF(OR(G$3=4, G$3=8), _xlfn.XLOOKUP(($B13*2), 韻母表[序號], 韻母表[台羅拼音]), _xlfn.XLOOKUP($B13, 韻母表[韻序], 韻母表[台羅拼音]) ), G$3) -> ui5 | H15: =_xlfn.CONCAT( IF(OR(H$3=4, H$3=8), _xlfn.XLOOKUP(($B13*2), 韻母表[序號], 韻母表[台羅拼音]), _xlfn.XLOOKUP($B13, 韻母表[韻序], 韻母表[台羅拼音]) ), H$3) -> ui6 | I15: =_xlfn.CONCAT( IF(OR(I$3=4, I$3=8), _xlfn.XLOOKUP(($B13*2), 韻母表[序號], 韻母表[台羅拼音]), _xlfn.XLOOKUP($B13, 韻母表[韻序], 韻母表[台羅拼音]) ), I$3) -> ui7 | J15: =_xlfn.CONCAT( IF(OR(J$3=4, J$3=8), _xlfn.XLOOKUP(($B13*2), 韻母表[序號], 韻母表[台羅拼音]), _xlfn.XLOOKUP($B13, 韻母表[韻序], 韻母表[台羅拼音]) ), J$3) -> ui8
B16: =B13+1 -> 5 | C16: =_xlfn.CONCAT( IF(OR(C$3=4, C$3=8), _xlfn.XLOOKUP(($B16*2), 韻母表[序號], 韻母表[方音符號]), _xlfn.XLOOKUP($B16, 韻母表[韻序], 韻母表[方音符號]) ), _xlfn.XLOOKUP(C$3, 聲調符號表[調號], 聲調符號表[調符])) -> ㄝ | D16: =_xlfn.CONCAT( IF(OR(D$3=4, D$3=8), _xlfn.XLOOKUP(($B16*2), 韻母表[序號], 韻母表[方音符號]), _xlfn.XLOOKUP($B16, 韻母表[韻序], 韻母表[方音符號]) ), _xlfn.XLOOKUP(D$3, 聲調符號表[調號], 聲調符號表[調符])) -> ㄝˋ | E16: =_xlfn.CONCAT( IF(OR(E$3=4, E$3=8), _xlfn.XLOOKUP(($B16*2), 韻母表[序號], 韻母表[方音符號]), _xlfn.XLOOKUP($B16, 韻母表[韻序], 韻母表[方音符號]) ), _xlfn.XLOOKUP(E$3, 聲調符號表[調號], 聲調符號表[調符])) -> ㄝ˪ | F16: =_xlfn.CONCAT( IF(OR(F$3=4, F$3=8), _xlfn.XLOOKUP(($B16*2), 韻母表[序號], 韻母表[方音符號]), _xlfn.XLOOKUP($B16, 韻母表[韻序], 韻母表[方音符號]) ), _xlfn.XLOOKUP(F$3, 聲調符號表[調號], 聲調符號表[調符])) -> ㄝㆷ | G16: =_xlfn.CONCAT( IF(OR(G$3=4, G$3=8), _xlfn.XLOOKUP(($B16*2), 韻母表[序號], 韻母表[方音符號]), _xlfn.XLOOKUP($B16, 韻母表[韻序], 韻母表[方音符號]) ), _xlfn.XLOOKUP(G$3, 聲調符號表[調號], 聲調符號表[調符])) -> ㄝˊ | H16: =_xlfn.CONCAT( IF(OR(H$3=4, H$3=8), _xlfn.XLOOKUP(($B16*2), 韻母表[序號], 韻母表[方音符號]), _xlfn.XLOOKUP($B16, 韻母表[韻序], 韻母表[方音符號]) ), _xlfn.XLOOKUP(H$3, 聲調符號表[調號], 聲調符號表[調符])) -> ㄝˋ | I16: =_xlfn.CONCAT( IF(OR(I$3=4, I$3=8), _xlfn.XLOOKUP(($B16*2), 韻母表[序號], 韻母表[方音符號]), _xlfn.XLOOKUP($B16, 韻母表[韻序], 韻母表[方音符號]) ), _xlfn.XLOOKUP(I$3, 聲調符號表[調號], 聲調符號表[調符])) -> ㄝ˫ | J16: =_xlfn.CONCAT( IF(OR(J$3=4, J$3=8), _xlfn.XLOOKUP(($B16*2), 韻母表[序號], 韻母表[方音符號]), _xlfn.XLOOKUP($B16, 韻母表[韻序], 韻母表[方音符號]) ), _xlfn.XLOOKUP(J$3, 聲調符號表[調號], 聲調符號表[調符])) -> ㄝㆷ˙
B17: 4.6 | C17: {=INDEX(字母八音反切!$C$4:$J$53, $B16, C$3)} -> 嘉 | D17: {=INDEX(字母八音反切!$C$4:$J$53, $B16, D$3)} -> 賈 | E17: {=INDEX(字母八音反切!$C$4:$J$53, $B16, E$3)} -> 嫁 | F17: {=INDEX(字母八音反切!$C$4:$J$53, $B16, F$3)} -> 骼 | G17: {=INDEX(字母八音反切!$C$4:$J$53, $B16, G$3)} -> 枷 | H17: {=INDEX(字母八音反切!$C$4:$J$53, $B16, H$3)} -> 假 | I17: {=INDEX(字母八音反切!$C$4:$J$53, $B16, I$3)} -> 下 | J17: {=INDEX(字母八音反切!$C$4:$J$53, $B16, J$3)} -> 逆
C18: =_xlfn.CONCAT( IF(OR(C$3=4, C$3=8), _xlfn.XLOOKUP(($B16*2), 韻母表[序號], 韻母表[台羅拼音]), _xlfn.XLOOKUP($B16, 韻母表[韻序], 韻母表[台羅拼音]) ), C$3) -> ee1 | D18: =_xlfn.CONCAT( IF(OR(D$3=4, D$3=8), _xlfn.XLOOKUP(($B16*2), 韻母表[序號], 韻母表[台羅拼音]), _xlfn.XLOOKUP($B16, 韻母表[韻序], 韻母表[台羅拼音]) ), D$3) -> ee2 | E18: =_xlfn.CONCAT( IF(OR(E$3=4, E$3=8), _xlfn.XLOOKUP(($B16*2), 韻母表[序號], 韻母表[台羅拼音]), _xlfn.XLOOKUP($B16, 韻母表[韻序], 韻母表[台羅拼音]) ), E$3) -> ee3 | F18: =_xlfn.CONCAT( IF(OR(F$3=4, F$3=8), _xlfn.XLOOKUP(($B16*2), 韻母表[序號], 韻母表[台羅拼音]), _xlfn.XLOOKUP($B16, 韻母表[韻序], 韻母表[台羅拼音]) ), F$3) -> eeh4 | G18: =_xlfn.CONCAT( IF(OR(G$3=4, G$3=8), _xlfn.XLOOKUP(($B16*2), 韻母表[序號], 韻母表[台羅拼音]), _xlfn.XLOOKUP($B16, 韻母表[韻序], 韻母表[台羅拼音]) ), G$3) -> ee5 | H18: =_xlfn.CONCAT( IF(OR(H$3=4, H$3=8), _xlfn.XLOOKUP(($B16*2), 韻母表[序號], 韻母表[台羅拼音]), _xlfn.XLOOKUP($B16, 韻母表[韻序], 韻母表[台羅拼音]) ), H$3) -> ee6 | I18: =_xlfn.CONCAT( IF(OR(I$3=4, I$3=8), _xlfn.XLOOKUP(($B16*2), 韻母表[序號], 韻母表[台羅拼音]), _xlfn.XLOOKUP($B16, 韻母表[韻序], 韻母表[台羅拼音]) ), I$3) -> ee7 | J18: =_xlfn.CONCAT( IF(OR(J$3=4, J$3=8), _xlfn.XLOOKUP(($B16*2), 韻母表[序號], 韻母表[台羅拼音]), _xlfn.XLOOKUP($B16, 韻母表[韻序], 韻母表[台羅拼音]) ), J$3) -> eeh8
B19: =B16+1 -> 6 | C19: =_xlfn.CONCAT( IF(OR(C$3=4, C$3=8), _xlfn.XLOOKUP(($B19*2), 韻母表[序號], 韻母表[方音符號]), _xlfn.XLOOKUP($B19, 韻母表[韻序], 韻母表[方音符號]) ), _xlfn.XLOOKUP(C$3, 聲調符號表[調號], 聲調符號表[調符])) -> ㄢ | D19: =_xlfn.CONCAT( IF(OR(D$3=4, D$3=8), _xlfn.XLOOKUP(($B19*2), 韻母表[序號], 韻母表[方音符號]), _xlfn.XLOOKUP($B19, 韻母表[韻序], 韻母表[方音符號]) ), _xlfn.XLOOKUP(D$3, 聲調符號表[調號], 聲調符號表[調符])) -> ㄢˋ | E19: =_xlfn.CONCAT( IF(OR(E$3=4, E$3=8), _xlfn.XLOOKUP(($B19*2), 韻母表[序號], 韻母表[方音符號]), _xlfn.XLOOKUP($B19, 韻母表[韻序], 韻母表[方音符號]) ), _xlfn.XLOOKUP(E$3, 聲調符號表[調號], 聲調符號表[調符])) -> ㄢ˪ | F19: =_xlfn.CONCAT( IF(OR(F$3=4, F$3=8), _xlfn.XLOOKUP(($B19*2), 韻母表[序號], 韻母表[方音符號]), _xlfn.XLOOKUP($B19, 韻母表[韻序], 韻母表[方音符號]) ), _xlfn.XLOOKUP(F$3, 聲調符號表[調號], 聲調符號表[調符])) -> ㄚㆵ | G19: =_xlfn.CONCAT( IF(OR(G$3=4, G$3=8), _xlfn.XLOOKUP(($B19*2), 韻母表[序號], 韻母表[方音符號]), _xlfn.XLOOKUP($B19, 韻母表[韻序], 韻母表[方音符號]) ), _xlfn.XLOOKUP(G$3, 聲調符號表[調號], 聲調符號表[調符])) -> ㄢˊ | H19: =_xlfn.CONCAT( IF(OR(H$3=4, H$3=8), _xlfn.XLOOKUP(($B19*2), 韻母表[序號], 韻母表[方音符號]), _xlfn.XLOOKUP($B19, 韻母表[韻序], 韻母表[方音符號]) ), _xlfn.XLOOKUP(H$3, 聲調符號表[調號], 聲調符號表[調符])) -> ㄢˋ | I19: =_xlfn.CONCAT( IF(OR(I$3=4, I$3=8), _xlfn.XLOOKUP(($B19*2), 韻母表[序號], 韻母表[方音符號]), _xlfn.XLOOKUP($B19, 韻母表[韻序], 韻母表[方音符號]) ), _xlfn.XLOOKUP(I$3, 聲調符號表[調號], 聲調符號表[調符])) -> ㄢ˫ | J19: =_xlfn.CONCAT( IF(OR(J$3=4, J$3=8), _xlfn.XLOOKUP(($B19*2), 韻母表[序號], 韻母表[方音符號]), _xlfn.XLOOKUP($B19, 韻母表[韻序], 韻母表[方音符號]) ), _xlfn.XLOOKUP(J$3, 聲調符號表[調號], 聲調符號表[調符])) -> ㄚㆵ˙
B20: 4.6 | C20: {=INDEX(字母八音反切!$C$4:$J$53, $B19, C$3)} -> 干 | D20: {=INDEX(字母八音反切!$C$4:$J$53, $B19, D$3)} -> 柬 | E20: {=INDEX(字母八音反切!$C$4:$J$53, $B19, E$3)} -> 澗 | F20: {=INDEX(字母八音反切!$C$4:$J$53, $B19, F$3)} -> 葛 | G20: {=INDEX(字母八音反切!$C$4:$J$53, $B19, G$3)} -> ○ | H20: {=INDEX(字母八音反切!$C$4:$J$53, $B19, H$3)} -> 柬 | I20: {=INDEX(字母八音反切!$C$4:$J$53, $B19, I$3)} -> ○ | J20: {=INDEX(字母八音反切!$C$4:$J$53, $B19, J$3)} -> ○
C21: =_xlfn.CONCAT( IF(OR(C$3=4, C$3=8), _xlfn.XLOOKUP(($B19*2), 韻母表[序號], 韻母表[台羅拼音]), _xlfn.XLOOKUP($B19, 韻母表[韻序], 韻母表[台羅拼音]) ), C$3) -> an1 | D21: =_xlfn.CONCAT( IF(OR(D$3=4, D$3=8), _xlfn.XLOOKUP(($B19*2), 韻母表[序號], 韻母表[台羅拼音]), _xlfn.XLOOKUP($B19, 韻母表[韻序], 韻母表[台羅拼音]) ), D$3) -> an2 | E21: =_xlfn.CONCAT( IF(OR(E$3=4, E$3=8), _xlfn.XLOOKUP(($B19*2), 韻母表[序號], 韻母表[台羅拼音]), _xlfn.XLOOKUP($B19, 韻母表[韻序], 韻母表[台羅拼音]) ), E$3) -> an3 | F21: =_xlfn.CONCAT( IF(OR(F$3=4, F$3=8), _xlfn.XLOOKUP(($B19*2), 韻母表[序號], 韻母表[台羅拼音]), _xlfn.XLOOKUP($B19, 韻母表[韻序], 韻母表[台羅拼音]) ), F$3) -> at4 | G21: =_xlfn.CONCAT( IF(OR(G$3=4, G$3=8), _xlfn.XLOOKUP(($B19*2), 韻母表[序號], 韻母表[台羅拼音]), _xlfn.XLOOKUP($B19, 韻母表[韻序], 韻母表[台羅拼音]) ), G$3) -> an5 | H21: =_xlfn.CONCAT( IF(OR(H$3=4, H$3=8), _xlfn.XLOOKUP(($B19*2), 韻母表[序號], 韻母表[台羅拼音]), _xlfn.XLOOKUP($B19, 韻母表[韻序], 韻母表[台羅拼音]) ), H$3) -> an6 | I21: =_xlfn.CONCAT( IF(OR(I$3=4, I$3=8), _xlfn.XLOOKUP(($B19*2), 韻母表[序號], 韻母表[台羅拼音]), _xlfn.XLOOKUP($B19, 韻母表[韻序], 韻母表[台羅拼音]) ), I$3) -> an7 | J21: =_xlfn.CONCAT( IF(OR(J$3=4, J$3=8), _xlfn.XLOOKUP(($B19*2), 韻母表[序號], 韻母表[台羅拼音]), _xlfn.XLOOKUP($B19, 韻母表[韻序], 韻母表[台羅拼音]) ), J$3) -> at8
B22: =B19+1 -> 7 | C22: =_xlfn.CONCAT( IF(OR(C$3=4, C$3=8), _xlfn.XLOOKUP(($B22*2), 韻母表[序號], 韻母表[方音符號]), _xlfn.XLOOKUP($B22, 韻母表[韻序], 韻母表[方音符號]) ), _xlfn.XLOOKUP(C$3, 聲調符號表[調號], 聲調符號表[調符])) -> ㆲ | D22: =_xlfn.CONCAT( IF(OR(D$3=4, D$3=8), _xlfn.XLOOKUP(($B22*2), 韻母表[序號], 韻母表[方音符號]), _xlfn.XLOOKUP($B22, 韻母表[韻序], 韻母表[方音符號]) ), _xlfn.XLOOKUP(D$3, 聲調符號表[調號], 聲調符號表[調符])) -> ㆲˋ | E22: =_xlfn.CONCAT( IF(OR(E$3=4, E$3=8), _xlfn.XLOOKUP(($B22*2), 韻母表[序號], 韻母表[方音符號]), _xlfn.XLOOKUP($B22, 韻母表[韻序], 韻母表[方音符號]) ), _xlfn.XLOOKUP(E$3, 聲調符號表[調號], 聲調符號表[調符])) -> ㆲ˪ | F22: =_xlfn.CONCAT( IF(OR(F$3=4, F$3=8), _xlfn.XLOOKUP(($B22*2), 韻母表[序號], 韻母表[方音符號]), _xlfn.XLOOKUP($B22, 韻母表[韻序], 韻母表[方音符號]) ), _xlfn.XLOOKUP(F$3, 聲調符號表[調號], 聲調符號表[調符])) -> ㆦㆻ | G22: =_xlfn.CONCAT( IF(OR(G$3=4, G$3=8), _xlfn.XLOOKUP(($B22*2), 韻母表[序號], 韻母表[方音符號]), _xlfn.XLOOKUP($B22, 韻母表[韻序], 韻母表[方音符號]) ), _xlfn.XLOOKUP(G$3, 聲調符號表[調號], 聲調符號表[調符])) -> ㆲˊ | H22: =_xlfn.CONCAT( IF(OR(H$3=4, H$3=8), _xlfn.XLOOKUP(($B22*2), 韻母表[序號], 韻母表[方音符號]), _xlfn.XLOOKUP($B22, 韻母表[韻序], 韻母表[方音符號]) ), _xlfn.XLOOKUP(H$3, 聲調符號表[調號], 聲調符號表[調符])) -> ㆲˋ | I22: =_xlfn.CONCAT( IF(OR(I$3=4, I$3=8), _xlfn.XLOOKUP(($B22*2), 韻母表[序號], 韻母表[方音符號]), _xlfn.XLOOKUP($B22, 韻母表[韻序], 韻母表[方音符號]) ), _xlfn.XLOOKUP(I$3, 聲調符號表[調號], 聲調符號表[調符])) -> ㆲ˫ | J22: =_xlfn.CONCAT( IF(OR(J$3=4, J$3=8), _xlfn.XLOOKUP(($B22*2), 韻母表[序號], 韻母表[方音符號]), _xlfn.XLOOKUP($B22, 韻母表[韻序], 韻母表[方音符號]) ), _xlfn.XLOOKUP(J$3, 聲調符號表[調號], 聲調符號表[調符])) -> ㆦㆻ˙
B23: 4.6 | C23: {=INDEX(字母八音反切!$C$4:$J$53, $B22, C$3)} -> 公 | D23: {=INDEX(字母八音反切!$C$4:$J$53, $B22, D$3)} -> 廣 | E23: {=INDEX(字母八音反切!$C$4:$J$53, $B22, E$3)} -> 貢 | F23: {=INDEX(字母八音反切!$C$4:$J$53, $B22, F$3)} -> 國 | G23: {=INDEX(字母八音反切!$C$4:$J$53, $B22, G$3)} -> 狂 | H23: {=INDEX(字母八音反切!$C$4:$J$53, $B22, H$3)} -> 廣 | I23: {=INDEX(字母八音反切!$C$4:$J$53, $B22, I$3)} -> 狂 | J23: {=INDEX(字母八音反切!$C$4:$J$53, $B22, J$3)} -> 咯
C24: =_xlfn.CONCAT( IF(OR(C$3=4, C$3=8), _xlfn.XLOOKUP(($B22*2), 韻母表[序號], 韻母表[台羅拼音]), _xlfn.XLOOKUP($B22, 韻母表[韻序], 韻母表[台羅拼音]) ), C$3) -> ong1 | D24: =_xlfn.CONCAT( IF(OR(D$3=4, D$3=8), _xlfn.XLOOKUP(($B22*2), 韻母表[序號], 韻母表[台羅拼音]), _xlfn.XLOOKUP($B22, 韻母表[韻序], 韻母表[台羅拼音]) ), D$3) -> ong2 | E24: =_xlfn.CONCAT( IF(OR(E$3=4, E$3=8), _xlfn.XLOOKUP(($B22*2), 韻母表[序號], 韻母表[台羅拼音]), _xlfn.XLOOKUP($B22, 韻母表[韻序], 韻母表[台羅拼音]) ), E$3) -> ong3 | F24: =_xlfn.CONCAT( IF(OR(F$3=4, F$3=8), _xlfn.XLOOKUP(($B22*2), 韻母表[序號], 韻母表[台羅拼音]), _xlfn.XLOOKUP($B22, 韻母表[韻序], 韻母表[台羅拼音]) ), F$3) -> ok4 | G24: =_xlfn.CONCAT( IF(OR(G$3=4, G$3=8), _xlfn.XLOOKUP(($B22*2), 韻母表[序號], 韻母表[台羅拼音]), _xlfn.XLOOKUP($B22, 韻母表[韻序], 韻母表[台羅拼音]) ), G$3) -> ong5 | H24: =_xlfn.CONCAT( IF(OR(H$3=4, H$3=8), _xlfn.XLOOKUP(($B22*2), 韻母表[序號], 韻母表[台羅拼音]), _xlfn.XLOOKUP($B22, 韻母表[韻序], 韻母表[台羅拼音]) ), H$3) -> ong6 | I24: =_xlfn.CONCAT( IF(OR(I$3=4, I$3=8), _xlfn.XLOOKUP(($B22*2), 韻母表[序號], 韻母表[台羅拼音]), _xlfn.XLOOKUP($B22, 韻母表[韻序], 韻母表[台羅拼音]) ), I$3) -> ong7 | J24: =_xlfn.CONCAT( IF(OR(J$3=4, J$3=8), _xlfn.XLOOKUP(($B22*2), 韻母表[序號], 韻母表[台羅拼音]), _xlfn.XLOOKUP($B22, 韻母表[韻序], 韻母表[台羅拼音]) ), J$3) -> ok8
B25: =B22+1 -> 8 | C25: =_xlfn.CONCAT( IF(OR(C$3=4, C$3=8), _xlfn.XLOOKUP(($B25*2), 韻母表[序號], 韻母表[方音符號]), _xlfn.XLOOKUP($B25, 韻母表[韻序], 韻母表[方音符號]) ), _xlfn.XLOOKUP(C$3, 聲調符號表[調號], 聲調符號表[調符])) -> ㄨㄞ | D25: =_xlfn.CONCAT( IF(OR(D$3=4, D$3=8), _xlfn.XLOOKUP(($B25*2), 韻母表[序號], 韻母表[方音符號]), _xlfn.XLOOKUP($B25, 韻母表[韻序], 韻母表[方音符號]) ), _xlfn.XLOOKUP(D$3, 聲調符號表[調號], 聲調符號表[調符])) -> ㄨㄞˋ | E25: =_xlfn.CONCAT( IF(OR(E$3=4, E$3=8), _xlfn.XLOOKUP(($B25*2), 韻母表[序號], 韻母表[方音符號]), _xlfn.XLOOKUP($B25, 韻母表[韻序], 韻母表[方音符號]) ), _xlfn.XLOOKUP(E$3, 聲調符號表[調號], 聲調符號表[調符])) -> ㄨㄞ˪ | F25: =_xlfn.CONCAT( IF(OR(F$3=4, F$3=8), _xlfn.XLOOKUP(($B25*2), 韻母表[序號], 韻母表[方音符號]), _xlfn.XLOOKUP($B25, 韻母表[韻序], 韻母表[方音符號]) ), _xlfn.XLOOKUP(F$3, 聲調符號表[調號], 聲調符號表[調符])) -> ㄨㄞㆷ | G25: =_xlfn.CONCAT( IF(OR(G$3=4, G$3=8), _xlfn.XLOOKUP(($B25*2), 韻母表[序號], 韻母表[方音符號]), _xlfn.XLOOKUP($B25, 韻母表[韻序], 韻母表[方音符號]) ), _xlfn.XLOOKUP(G$3, 聲調符號表[調號], 聲調符號表[調符])) -> ㄨㄞˊ | H25: =_xlfn.CONCAT( IF(OR(H$3=4, H$3=8), _xlfn.XLOOKUP(($B25*2), 韻母表[序號], 韻母表[方音符號]), _xlfn.XLOOKUP($B25, 韻母表[韻序], 韻母表[方音符號]) ), _xlfn.XLOOKUP(H$3, 聲調符號表[調號], 聲調符號表[調符])) -> ㄨㄞˋ | I25: =_xlfn.CONCAT( IF(OR(I$3=4, I$3=8), _xlfn.XLOOKUP(($B25*2), 韻母表[序號], 韻母表[方音符號]), _xlfn.XLOOKUP($B25, 韻母表[韻序], 韻母表[方音符號]) ), _xlfn.XLOOKUP(I$3, 聲調符號表[調號], 聲調符號表[調符])) -> ㄨㄞ˫ | J25: =_xlfn.CONCAT( IF(OR(J$3=4, J$3=8), _xlfn.XLOOKUP(($B25*2), 韻母表[序號], 韻母表[方音符號]), _xlfn.XLOOKUP($B25, 韻母表[韻序], 韻母表[方音符號]) ), _xlfn.XLOOKUP(J$3, 聲調符號表[調號], 聲調符號表[調符])) -> ㄨㄞㆷ˙
B26: 4.6 | C26: {=INDEX(字母八音反切!$C$4:$J$53, $B25, C$3)} -> 乖 | D26: {=INDEX(字母八音反切!$C$4:$J$53, $B25, D$3)} -> 拐 | E26: {=INDEX(字母八音反切!$C$4:$J$53, $B25, E$3)} -> 怪 | F26: {=INDEX(字母八音反切!$C$4:$J$53, $B25, F$3)} -> ○ | G26: {=INDEX(字母八音反切!$C$4:$J$53, $B25, G$3)} -> ○ | H26: {=INDEX(字母八音反切!$C$4:$J$53, $B25, H$3)} -> 拐 | I26: {=INDEX(字母八音反切!$C$4:$J$53, $B25, I$3)} -> ○ | J26: {=INDEX(字母八音反切!$C$4:$J$53, $B25, J$3)} -> ○
C27: =_xlfn.CONCAT( IF(OR(C$3=4, C$3=8), _xlfn.XLOOKUP(($B25*2), 韻母表[序號], 韻母表[台羅拼音]), _xlfn.XLOOKUP($B25, 韻母表[韻序], 韻母表[台羅拼音]) ), C$3) -> uai1 | D27: =_xlfn.CONCAT( IF(OR(D$3=4, D$3=8), _xlfn.XLOOKUP(($B25*2), 韻母表[序號], 韻母表[台羅拼音]), _xlfn.XLOOKUP($B25, 韻母表[韻序], 韻母表[台羅拼音]) ), D$3) -> uai2 | E27: =_xlfn.CONCAT( IF(OR(E$3=4, E$3=8), _xlfn.XLOOKUP(($B25*2), 韻母表[序號], 韻母表[台羅拼音]), _xlfn.XLOOKUP($B25, 韻母表[韻序], 韻母表[台羅拼音]) ), E$3) -> uai3 | F27: =_xlfn.CONCAT( IF(OR(F$3=4, F$3=8), _xlfn.XLOOKUP(($B25*2), 韻母表[序號], 韻母表[台羅拼音]), _xlfn.XLOOKUP($B25, 韻母表[韻序], 韻母表[台羅拼音]) ), F$3) -> uaih4 | G27: =_xlfn.CONCAT( IF(OR(G$3=4, G$3=8), _xlfn.XLOOKUP(($B25*2), 韻母表[序號], 韻母表[台羅拼音]), _xlfn.XLOOKUP($B25, 韻母表[韻序], 韻母表[台羅拼音]) ), G$3) -> uai5 | H27: =_xlfn.CONCAT( IF(OR(H$3=4, H$3=8), _xlfn.XLOOKUP(($B25*2), 韻母表[序號], 韻母表[台羅拼音]), _xlfn.XLOOKUP($B25, 韻母表[韻序], 韻母表[台羅拼音]) ), H$3) -> uai6 | I27: =_xlfn.CONCAT( IF(OR(I$3=4, I$3=8), _xlfn.XLOOKUP(($B25*2), 韻母表[序號], 韻母表[台羅拼音]), _xlfn.XLOOKUP($B25, 韻母表[韻序], 韻母表[台羅拼音]) ), I$3) -> uai7 | J27: =_xlfn.CONCAT( IF(OR(J$3=4, J$3=8), _xlfn.XLOOKUP(($B25*2), 韻母表[序號], 韻母表[台羅拼音]), _xlfn.XLOOKUP($B25, 韻母表[韻序], 韻母表[台羅拼音]) ), J$3) -> uaih8
B28: =B25+1 -> 9 | C28: =_xlfn.CONCAT( IF(OR(C$3=4, C$3=8), _xlfn.XLOOKUP(($B28*2), 韻母表[序號], 韻母表[方音符號]), _xlfn.XLOOKUP($B28, 韻母表[韻序], 韻母表[方音符號]) ), _xlfn.XLOOKUP(C$3, 聲調符號表[調號], 聲調符號表[調符])) -> ㄧㄥ | D28: =_xlfn.CONCAT( IF(OR(D$3=4, D$3=8), _xlfn.XLOOKUP(($B28*2), 韻母表[序號], 韻母表[方音符號]), _xlfn.XLOOKUP($B28, 韻母表[韻序], 韻母表[方音符號]) ), _xlfn.XLOOKUP(D$3, 聲調符號表[調號], 聲調符號表[調符])) -> ㄧㄥˋ | E28: =_xlfn.CONCAT( IF(OR(E$3=4, E$3=8), _xlfn.XLOOKUP(($B28*2), 韻母表[序號], 韻母表[方音符號]), _xlfn.XLOOKUP($B28, 韻母表[韻序], 韻母表[方音符號]) ), _xlfn.XLOOKUP(E$3, 聲調符號表[調號], 聲調符號表[調符])) -> ㄧㄥ˪ | F28: =_xlfn.CONCAT( IF(OR(F$3=4, F$3=8), _xlfn.XLOOKUP(($B28*2), 韻母表[序號], 韻母表[方音符號]), _xlfn.XLOOKUP($B28, 韻母表[韻序], 韻母表[方音符號]) ), _xlfn.XLOOKUP(F$3, 聲調符號表[調號], 聲調符號表[調符])) -> ㄧㆻ | G28: =_xlfn.CONCAT( IF(OR(G$3=4, G$3=8), _xlfn.XLOOKUP(($B28*2), 韻母表[序號], 韻母表[方音符號]), _xlfn.XLOOKUP($B28, 韻母表[韻序], 韻母表[方音符號]) ), _xlfn.XLOOKUP(G$3, 聲調符號表[調號], 聲調符號表[調符])) -> ㄧㄥˊ | H28: =_xlfn.CONCAT( IF(OR(H$3=4, H$3=8), _xlfn.XLOOKUP(($B28*2), 韻母表[序號], 韻母表[方音符號]), _xlfn.XLOOKUP($B28, 韻母表[韻序], 韻母表[方音符號]) ), _xlfn.XLOOKUP(H$3, 聲調符號表[調號], 聲調符號表[調符])) -> ㄧㄥˋ | I28: =_xlfn.CONCAT( IF(OR(I$3=4, I$3=8), _xlfn.XLOOKUP(($B28*2), 韻母表[序號], 韻母表[方音符號]), _xlfn.XLOOKUP($B28, 韻母表[韻序], 韻母表[方音符號]) ), _xlfn.XLOOKUP(I$3, 聲調符號表[調號], 聲調符號表[調符])) -> ㄧㄥ˫ | J28: =_xlfn.CONCAT( IF(OR(J$3=4, J$3=8), _xlfn.XLOOKUP(($B28*2), 韻母表[序號], 韻母表[方音符號]), _xlfn.XLOOKUP($B28, 韻母表[韻序], 韻母表[方音符號]) ), _xlfn.XLOOKUP(J$3, 聲調符號表[調號], 聲調符號表[調符])) -> ㄧㆻ˙
B29: 4.6 | C29: {=INDEX(字母八音反切!$C$4:$J$53, $B28, C$3)} -> 經 | D29: {=INDEX(字母八音反切!$C$4:$J$53, $B28, D$3)} -> 景 | E29: {=INDEX(字母八音反切!$C$4:$J$53, $B28, E$3)} -> 敬 | F29: {=INDEX(字母八音反切!$C$4:$J$53, $B28, F$3)} -> 格 | G29: {=INDEX(字母八音反切!$C$4:$J$53, $B28, G$3)} -> 煢 | H29: {=INDEX(字母八音反切!$C$4:$J$53, $B28, H$3)} -> 景 | I29: {=INDEX(字母八音反切!$C$4:$J$53, $B28, I$3)} -> 勁 | J29: {=INDEX(字母八音反切!$C$4:$J$53, $B28, J$3)} -> 極
C30: =_xlfn.CONCAT( IF(OR(C$3=4, C$3=8), _xlfn.XLOOKUP(($B28*2), 韻母表[序號], 韻母表[台羅拼音]), _xlfn.XLOOKUP($B28, 韻母表[韻序], 韻母表[台羅拼音]) ), C$3) -> ing1 | D30: =_xlfn.CONCAT( IF(OR(D$3=4, D$3=8), _xlfn.XLOOKUP(($B28*2), 韻母表[序號], 韻母表[台羅拼音]), _xlfn.XLOOKUP($B28, 韻母表[韻序], 韻母表[台羅拼音]) ), D$3) -> ing2 | E30: =_xlfn.CONCAT( IF(OR(E$3=4, E$3=8), _xlfn.XLOOKUP(($B28*2), 韻母表[序號], 韻母表[台羅拼音]), _xlfn.XLOOKUP($B28, 韻母表[韻序], 韻母表[台羅拼音]) ), E$3) -> ing3 | F30: =_xlfn.CONCAT( IF(OR(F$3=4, F$3=8), _xlfn.XLOOKUP(($B28*2), 韻母表[序號], 韻母表[台羅拼音]), _xlfn.XLOOKUP($B28, 韻母表[韻序], 韻母表[台羅拼音]) ), F$3) -> ik4 | G30: =_xlfn.CONCAT( IF(OR(G$3=4, G$3=8), _xlfn.XLOOKUP(($B28*2), 韻母表[序號], 韻母表[台羅拼音]), _xlfn.XLOOKUP($B28, 韻母表[韻序], 韻母表[台羅拼音]) ), G$3) -> ing5 | H30: =_xlfn.CONCAT( IF(OR(H$3=4, H$3=8), _xlfn.XLOOKUP(($B28*2), 韻母表[序號], 韻母表[台羅拼音]), _xlfn.XLOOKUP($B28, 韻母表[韻序], 韻母表[台羅拼音]) ), H$3) -> ing6 | I30: =_xlfn.CONCAT( IF(OR(I$3=4, I$3=8), _xlfn.XLOOKUP(($B28*2), 韻母表[序號], 韻母表[台羅拼音]), _xlfn.XLOOKUP($B28, 韻母表[韻序], 韻母表[台羅拼音]) ), I$3) -> ing7 | J30: =_xlfn.CONCAT( IF(OR(J$3=4, J$3=8), _xlfn.XLOOKUP(($B28*2), 韻母表[序號], 韻母表[台羅拼音]), _xlfn.XLOOKUP($B28, 韻母表[韻序], 韻母表[台羅拼音]) ), J$3) -> ik8
