Workbook
Name 十五音韻母: #REF!
Name 十五音韻母對照表: #REF!
Name 方音符號: #REF!
Name 方音符號: #REF!
Name 方音符號: #REF!
Name 台羅韻母八音反切: #REF!
Name 白話字韻母八音反切: #REF!
Name 字典編碼: #REF!
Name 字典編碼: #REF!
Name 字典編碼: #REF!
Name 注音符號: #REF!
Name 注音編碼: #REF!
Name 拼音字母: #REF!
Name 拼音字母: #REF!
Name 拼音字母: #REF!
Name 閩拼韻母八音反切: #REF!
Name 聲母碼: #REF!
Name 聲母碼表: #REF!
Name 鍵盤位置: #REF!
Name 鍵盤位置: #REF!
Name 鍵盤位置: #REF!
Name 鍵盤按鍵: #REF!
Name 韻母對照表: #REF!
Name 韻母碼表: #REF!
Name 顯示注音輸入: #REF!

Sheet 台語注音二式【xlit驗證】
A1: zu_im_bpm2
A3: alphabet: | BL3: 序號 | BM3: {=TRANSPOSE(#REF!)} -> #REF! | BR3: 序號 | BS3: 台羅拼音 | BT3: 字典編碼 | BU3: 按鍵 | BV3: 注音符號 | BX3: 序號 | BY3: 台羅拼音 | BZ3: 字典編碼 | CA3: 按鍵 | CB3: 注音符號 | CD3: 序號 | CE3: 台羅拼音 | CF3: 字典編碼 | CG3: 按鍵 | CH3: 注音符號
C4: BbpmdtnlĞgkŋhZzcsJjCSaiwueOəIUDfqrvxyMGNY@AWHRFQVØL173254806 | BR4: 12 | BS4: ng | BT4: ŋ | BU4: G | BV4: ㄫ | BX4: 12 | BY4: -t | BZ4: F | CA4: t | CB4: ㆵ
C5: !1qa2wsxEedNcYyhnRrfv8uKj,ik9l*UJ<I(Lm/pM0;Oobtgz=-"5346[].7 | BR5: 13 | BS5: j | BT5: j | BU5: Y | BV5: ㆡ | BX5: 13 | BY5: -k | BZ5: Q | CA5: g | CB5: ㆻ
BR6: 14 | BS6: z(ts) | BT6: z | BU6: y | BV6: ㄗ | BX6: 14 | BY6: -h | BZ6: V | CA6: z | CB6: ㆷ
C7: =COLUMN() -2 -> 1 | D7: =COLUMN() -2 -> 2 | E7: =COLUMN() -2 -> 3 | F7: =COLUMN() -2 -> 4 | G7: =COLUMN() -2 -> 5 | H7: =COLUMN() -2 -> 6 | I7: =COLUMN() -2 -> 7 | J7: =COLUMN() -2 -> 8 | ... BJ7: =COLUMN() -2 -> 60 | BR7: 15 | BS7: c(tsh) | BT7: c | BU7: h | BV7: ㄘ | BX7: 15 | BY7: ai | BZ7: I | CA7: 9 | CB7: ㄞ
A8: 字典編碼 | C8: =MID( $C$4,C$7,1) -> B | D8: =MID( $C$4,D$7,1) -> b | E8: =MID( $C$4,E$7,1) -> p | F8: =MID( $C$4,F$7,1) -> m | G8: =MID( $C$4,G$7,1) -> d | H8: =MID( $C$4,H$7,1) -> t | I8: =MID( $C$4,I$7,1) -> n | J8: =MID( $C$4,J$7,1) -> l | ... BJ8: =MID( $C$4,BJ$7,1) -> 6 | BR8: 16 | BS8: s | BT8: s | BU8: n | BV8: ㄙ | BX8: 16 | BY8: au | BZ8: U | CA8: l | CB8: ㄠ
A9: 鍵盤按鍵 | C9: =MID($C$5,C$7,1) -> ! | D9: =MID($C$5,D$7,1) -> 1 | E9: =MID($C$5,E$7,1) -> q | F9: =MID($C$5,F$7,1) -> a | G9: =MID($C$5,G$7,1) -> 2 | H9: =MID($C$5,H$7,1) -> w | I9: =MID($C$5,I$7,1) -> s | J9: =MID($C$5,J$7,1) -> x | ... BJ9: =MID($C$5,BJ$7,1) -> 7 | BR9: 17 | BS9: h | BT9: h | BU9: c | BV9: ㄏ | BX9: 17 | BY9: am | BZ9: Y | CA9: M | CB9: ㆰ
BR10: 18 | BS10: j(i) | BT10: J | BU10: R | BV10: ㆢ | BX10: 18 | BY10: an | BZ10: @ | CA10: 0 | CB10: ㄢ
A11: preedit_format: | BR11: 19 | BS11: z(i) | BT11: Z | BU11: r | BV11: ㄐ | BX11: 19 | BY11: ang | BZ11: A | CA11: ; | CB11: ㄤ
C12: !1qa2wsxEedNcYyhnRrfv8uKj,ik9l*UJ<I(Lm/pM0;Oobtgz=-"5346[].7 | BX12: 27 | BY12: aiⁿ | BZ12: x | CA12: ( | CB12: ㆮ
C13: ㆠㄅㄆㄇㄉㄊㄋㄌㆣㄍㄎㄫㄏㆡㄗㄘㄙㆢㄐㄑㄒㄚㄧㆨㄨㆤㆦㄜㄞㄠㆩㆪㆫㆥㆧㆮㆯㆬㆭㄣㆰㄢㄤㆱㆲㆴㆵㆻㆷØㄥ一七三二五四八輕ʔ | BX13: 28 | BY13: auⁿ | BZ13: y | CA13: L | CB13: ㆯ
C15: =COLUMN() -2 -> 1 | D15: =COLUMN() -2 -> 2 | E15: =COLUMN() -2 -> 3 | F15: =COLUMN() -2 -> 4 | G15: =COLUMN() -2 -> 5 | H15: =COLUMN() -2 -> 6 | I15: =COLUMN() -2 -> 7 | J15: =COLUMN() -2 -> 8 | ... BJ15: =COLUMN() -2 -> 60
A16: 字典編碼 | C16: =MID($C$12,C$15,1) -> ! | D16: =MID($C$12,D$15,1) -> 1 | E16: =MID($C$12,E$15,1) -> q | F16: =MID($C$12,F$15,1) -> a | G16: =MID($C$12,G$15,1) -> 2 | H16: =MID($C$12,H$15,1) -> w | I16: =MID($C$12,I$15,1) -> s | J16: =MID($C$12,J$15,1) -> x | ... BJ16: =MID($C$12,BJ$15,1) -> 7
A17: 注音符號 | C17: =MID($C$13,C$15,1) -> ㆠ | D17: =MID($C$13,D$15,1) -> ㄅ | E17: =MID($C$13,E$15,1) -> ㄆ | F17: =MID($C$13,F$15,1) -> ㄇ | G17: =MID($C$13,G$15,1) -> ㄉ | H17: =MID($C$13,H$15,1) -> ㄊ | I17: =MID($C$13,I$15,1) -> ㄋ | J17: =MID($C$13,J$15,1) -> ㄌ | ... BJ17: =MID($C$13,BJ$15,1) -> ʔ
C20: =COLUMN() -2 -> 1 | D20: =COLUMN() -2 -> 2 | E20: =COLUMN() -2 -> 3 | F20: =COLUMN() -2 -> 4 | G20: =COLUMN() -2 -> 5 | H20: =COLUMN() -2 -> 6 | I20: =COLUMN() -2 -> 7 | J20: =COLUMN() -2 -> 8 | ... BJ20: =COLUMN() -2 -> 60
A21: 台語注音二式 | C21: b | D21: p | E21: ph | F21: m | G21: n | H21: t | I21: th | J21: l | K21: g | L21: k | M21: kh | N21: ng | O21: j | P21: ts | Q21: tsh | R21: s | S21: j(i) | T21: ts(i) | U21: tsh(i) | V21: s(i) | W21: h | X21: a | Y21: i | Z21: ir | AA21: u | AB21: e | AC21: oo | AD21: o | AE21: ai | AF21: au | AG21: ann | AH21: inn | AI21: unn | AJ21: enn | AK21: onn | AL21: ainn | AM21: aunn | AN21: -m | AO21: -ng | AP21: -n | AQ21: am | AR21: an | AS21: ang | AT21: om | AU21: ong | AV21: -p | AW21: -t | AX21: -k | AY21: -h | AZ21: ñ | BA21: [48] | BB21: 1 | BC21: 7 | BD21: 3 | BE21: 2 | BF21: 5 | BG21: 8 | BH21: 4
A22: 字典編碼 | C22: =C8 -> B | D22: =D8 -> b | E22: =E8 -> p | F22: =F8 -> m | G22: =G8 -> d | H22: =H8 -> t | I22: =I8 -> n | J22: =J8 -> l | K22: Ğ | L22: =L8 -> g | M22: =M8 -> k | N22: =N8 -> ŋ | O22: =O8 -> h | P22: =P8 -> Z | Q22: =Q8 -> z | R22: =R8 -> c | S22: =S8 -> s | ... AF22: =AF8 -> U | AG22: D | AH22: =AH8 -> f | AI22: =AI8 -> q | AJ22: =AJ8 -> r | AK22: =AK8 -> v | AL22: =AL8 -> x | AM22: =AM8 -> y | AN22: =AN8 -> M | AO22: =AO8 -> G | ... AY22: =AY8 -> V | AZ22: =BG8 -> 4 | BA22: =BH8 -> 8 | BB22: =BF8 -> 5 | BC22: =AZ8 -> Ø | BD22: =BA8 -> L | BE22: =BB8 -> 1 | BF22: =BC8 -> 7 | BG22: =BD8 -> 3 | BH22: =BE8 -> 2 | BJ22: =BJ8 -> 6
A23: 鍵盤按鍵 | C23: =C9 -> ! | D23: =D9 -> 1 | E23: =E9 -> q | F23: =F9 -> a | G23: =G9 -> 2 | H23: =H9 -> w | I23: =I9 -> s | J23: =J9 -> x | ... AY23: =AY9 -> z | AZ23: - | BA23: =BH9 -> ] | BB23: " | BC23: =AZ9 -> = | BD23: =BA9 -> - | BE23: =BB9 -> " | BF23: =BC9 -> 5 | BG23: ] | BH23: [ | BJ23: =BJ9 -> 7
A24: 注音符號 | C24: =C17 -> ㆠ | D24: =D17 -> ㄅ | E24: =E17 -> ㄆ | F24: =F17 -> ㄇ | G24: =G17 -> ㄉ | H24: =H17 -> ㄊ | I24: =I17 -> ㄋ | J24: =J17 -> ㄌ | ... AY24: =AY17 -> ㆷ | AZ24: =BG17 -> 四 | BA24: =BH17 -> 八 | BB24: =BF17 -> 五 | BC24: =AZ17 -> Ø | BD24: =BA17 -> ㄥ | BE24: =BB17 -> 一 | BF24: =BC17 -> 七 | BG24: =BD17 -> 三 | BH24: =BE17 -> 二 | BJ24: =BJ17 -> ʔ
A26: alphabet: | C26: ="!1qas2wxEedGYyhncRrfv8uKj,ikmp/btgz9lM0;Oo*UJ<I(L:5346][7N" -> !1qas2wxEedGYyhncRrfv8uKj,ikmp/btgz9lM0;Oo*UJ<I(L:5346][7N | BL26: {=TRANSPOSE(C22:BJ24)} -> B | BM26: ! | BN26: ㆠ | BR26: 1 | BS26: b | BT26: b | BU26: ! | BV26: ㆠ | BX26: 1 | BY26: a | BZ26: a | CA26: 8 | CB26: ㄚ | CD26: 1 | CE26: 1 | CF26: 1 | CG26: : | CH26: 一
BL27: b | BM27: 1 | BN27: ㄅ | BR27: 2 | BS27: p | BT27: p | BU27: 1 | BV27: ㄅ | BX27: 2 | BY27: i | BZ27: i | CA27: u | CB27: ㄧ | CD27: 2 | CE27: 7 | CF27: 7 | CG27: 5 | CH27: 七
C28: =COLUMN() -2 -> 1 | D28: =COLUMN() -2 -> 2 | E28: =COLUMN() -2 -> 3 | F28: =COLUMN() -2 -> 4 | G28: =COLUMN() -2 -> 5 | H28: =COLUMN() -2 -> 6 | I28: =COLUMN() -2 -> 7 | J28: =COLUMN() -2 -> 8 | ... BJ28: =COLUMN() -2 -> 60 | BL28: p | BM28: q | BN28: ㄆ | BR28: 3 | BS28: ph | BT28: P | BU28: q | BV28: ㄆ | BX28: 3 | BY28: ir | BZ28: w | CA28: K | CB28: ㆨ | CD28: 3 | CE28: 3 | CF28: 3 | CG28: 3 | CH28: 三
C29: =MID($C$26, C28, 1) -> ! | D29: =MID($C$26, D28, 1) -> 1 | E29: =MID($C$26, E28, 1) -> q | F29: =MID($C$26, F28, 1) -> a | G29: =MID($C$26, G28, 1) -> s | H29: =MID($C$26, H28, 1) -> 2 | I29: =MID($C$26, I28, 1) -> w | J29: =MID($C$26, J28, 1) -> x | ... BJ29: =MID($C$26, BJ28, 1) | BL29: m | BM29: a | BN29: ㄇ | BR29: 4 | BS29: m | BT29: m | BU29: a | BV29: ㄇ | BX29: 4 | BY29: u | BZ29: u | CA29: j | CB29: ㄨ | CD29: 4 | CE29: 2 | CF29: 2 | CG29: 4 | CH29: 二
BL30: d | BM30: 2 | BN30: ㄉ | BR30: 5 | BS30: n | BT30: n | BU30: s | BV30: ㄋ | BX30: 5 | BY30: e | BZ30: e | CA30: , | CB30: ㆤ | CD30: 5 | CE30: 5 | CF30: 5 | CG30: 6 | CH30: 五
BL31: t | BM31: w | BN31: ㄊ
A32: algebra: | BL32: n | BM32: s | BN32: ㄋ | BR32: 6 | BS32: t | BT32: t | BU32: 2 | BV32: ㄉ | BX32: 6 | BY32: oo | BZ32: O | CA32: i | CB32: ㆦ | CD32: 6 | CE32: 8 | CF32: 8 | CG32: ] | CH32: 八
C33: ="- xlit|BbpmdtnlGgkŋZzcsJjCShaiwueOəIUdfqrvxyMGNY@AWHRFQV7325841L&*|!1qa2wsxEedGYyhnRrfvc8uKj,ik9l*UJ<I(Lm/pM0;Oobtgz53467][N.-|" -> - xlit|BbpmdtnlGgkŋZzcsJjCShaiwueOəIUdfqrvxyMGNY@AWHRFQV7325841L&*|!1qa2wsxEedGYyhnRrfvc8uKj,ik9l*UJ<I(Lm/pM0;Oobtgz53467][N.-| | BL33: l | BM33: x | BN33: ㄌ | BR33: 7 | BS33: th | BT33: T | BU33: w | BV33: ㄊ | BX33: 7 | BY33: o | BZ33: ə | CA33: k | CB33: ㄜ | CD33: 7 | CE33: 4 | CF33: 4 | CG33: [ | CH33: 四
A34: 第1個 |： | B34: =SEARCH("|", C33) -> 7 | BL34: Ğ | BM34: E | BN34: ㆣ | BR34: 8 | BS34: l | BT34: l | BU34: x | BV34: ㄌ | BX34: 8 | BY34: -m | BZ34: M | CA34: m | CB34: ㆬ | CD34: 8 | CE34: 0 | CF34: 0 | CG34: 7 | CH34: 入
A35: 第2個 |： | B35: =SEARCH("|", C33, B34+1) -> 67 | BL35: g | BM35: e | BN35: ㄍ | BR35: 9 | BS35: ㆣ | BT35: g | BU35: E | BV35: ㆣ | BX35: 9 | BY35: -n | BZ35: N | CA35: p | CB35: ㄣ | CD35: 9 | CE35: L | CF35: L | CG35: N | CH35: ㄥ
A36: 第3個 |： | B36: =SEARCH("|",C33, B35+1) -> 127 | BL36: k | BM36: d | BN36: ㄎ | BR36: 10 | BS36: k | BT36: k | BU36: e | BV36: ㄍ | BX36: 10 | BY36: -ng | BZ36: G | CA36: / | CB36: ㆭ
BL37: ŋ | BM37: N | BN37: ㄫ
A38: preedit_format: | BL38: h | BM38: c | BN38: ㄏ | BR38: 21 | BS38: s(i) | BT38: S | BU38: v | BV38: ㄒ | BX38: 21 | BY38: ong | BZ38: H | CA38: o | CB38: ㆲ
C39: ="- xlit|!1qa2wsxEedGYyhnRrfvc8uKj,ik9l*UJ<I(Lm/pM0;Oobtgz53467][N.-|ㆠㄅㄆㄇㄉㄊㄋㄌㆣㄍㄎㄫㆡㄗㄘㄙㆢㄐㄑㄒㄏㄚㄧㆨㄨㆤㆦㄜㄞㄠㆩㆪㆫㆥㆧㆮㆯㆬㆭㄣㆰㄢㄤㆱㆲㆴㆵㆻㆷ˫˪ˋˊ八四一ㄥ入ñ|" -> - xlit|!1qa2wsxEedGYyhnRrfvc8uKj,ik9l*UJ<I(Lm/pM0;Oobtgz53467][N.-|ㆠㄅㄆㄇㄉㄊㄋㄌㆣㄍㄎㄫㆡㄗㄘㄙㆢㄐㄑㄒㄏㄚㄧㆨㄨㆤㆦㄜㄞㄠㆩㆪㆫㆥㆧㆮㆯㆬㆭㄣㆰㄢㄤㆱㆲㆴㆵㆻㆷ˫˪ˋˊ八四一ㄥ入ñ| | BL39: Z | BM39: Y | BN39: ㆡ | BX39: 22 | BY39: aⁿ | BZ39: d | CA39: * | CB39: ㆩ
A40: 第1個 |： | B40: =SEARCH("|", C39) -> 7 | BL40: z | BM40: y | BN40: ㄗ | BX40: 23 | BY40: iⁿ | BZ40: f | CA40: U | CB40: ㆪ
A41: 第2個 |： | B41: =SEARCH("|", C39, B40+1) -> 67 | BL41: c | BM41: h | BN41: ㄘ | BX41: 24 | BY41: uⁿ | BZ41: q | CA41: J | CB41: ㆫ
A42: 第3個 |： | B42: =SEARCH("|",C39, B41+1) -> 127 | BL42: s | BM42: n | BN42: ㄙ | BX42: 25 | BY42: eⁿ | BZ42: r | CA42: < | CB42: ㆥ
BL43: J | BM43: R | BN43: ㆢ
BL44: j | BM44: r | BN44: ㄐ
BL45: C | BM45: f | BN45: ㄑ
...

Sheet 台語注音二式【xlit解析】
A1: zu_im_bpm2
BL2: 序號 | BM2: {=TRANSPOSE(#REF!)} -> #REF! | BR2: 序號 | BS2: 台羅拼音 | BT2: 字典編碼 | BU2: 按鍵 | BV2: 注音符號 | BX2: 序號 | BY2: 台羅拼音 | BZ2: 字典編碼 | CA2: 按鍵 | CB2: 注音符號 | CD2: 序號 | CE2: 台羅拼音 | CF2: 字典編碼 | CG2: 按鍵 | CH2: 注音符號
A3: alphabet: | C3: ="!1qas2wxEedGYyhncRrfv8uKj,ikmp/btgz9lM0;Oo*UJ<I(L:5346][7N" -> !1qas2wxEedGYyhncRrfv8uKj,ikmp/btgz9lM0;Oo*UJ<I(L:5346][7N | BL3: {=TRANSPOSE(C39:BJ41)} -> B | BM3: ! | BN3: ㆠ | BR3: 1 | BS3: b | BT3: b | BU3: ! | BV3: ㆠ | BX3: 1 | BY3: a | BZ3: a | CA3: 8 | CB3: ㄚ | CD3: 1 | CE3: 1 | CF3: 1 | CG3: : | CH3: 一
BL4: b | BM4: 1 | BN4: ㄅ | BR4: 2 | BS4: p | BT4: p | BU4: 1 | BV4: ㄅ | BX4: 2 | BY4: i | BZ4: i | CA4: u | CB4: ㄧ | CD4: 2 | CE4: 7 | CF4: 7 | CG4: 5 | CH4: 七
C5: =COLUMN() -2 -> 1 | D5: =COLUMN() -2 -> 2 | E5: =COLUMN() -2 -> 3 | F5: =COLUMN() -2 -> 4 | G5: =COLUMN() -2 -> 5 | H5: =COLUMN() -2 -> 6 | I5: =COLUMN() -2 -> 7 | J5: =COLUMN() -2 -> 8 | ... BJ5: =COLUMN() -2 -> 60 | BL5: p | BM5: q | BN5: ㄆ | BR5: 3 | BS5: ph | BT5: P | BU5: q | BV5: ㄆ | BX5: 3 | BY5: ir | BZ5: w | CA5: K | CB5: ㆨ | CD5: 3 | CE5: 3 | CF5: 3 | CG5: 3 | CH5: 三
C6: =MID($C$3, C5, 1) -> ! | D6: =MID($C$3, D5, 1) -> 1 | E6: =MID($C$3, E5, 1) -> q | F6: =MID($C$3, F5, 1) -> a | G6: =MID($C$3, G5, 1) -> s | H6: =MID($C$3, H5, 1) -> 2 | I6: =MID($C$3, I5, 1) -> w | J6: =MID($C$3, J5, 1) -> x | ... BJ6: =MID($C$3, BJ5, 1) | BL6: m | BM6: a | BN6: ㄇ | BR6: 4 | BS6: m | BT6: m | BU6: a | BV6: ㄇ | BX6: 4 | BY6: u | BZ6: u | CA6: j | CB6: ㄨ | CD6: 4 | CE6: 2 | CF6: 2 | CG6: 4 | CH6: 二
BL7: d | BM7: 2 | BN7: ㄉ | BR7: 5 | BS7: n | BT7: n | BU7: s | BV7: ㄋ | BX7: 5 | BY7: e | BZ7: e | CA7: , | CB7: ㆤ | CD7: 5 | CE7: 5 | CF7: 5 | CG7: 6 | CH7: 五
A8: algebra: | BL8: t | BM8: w | BN8: ㄊ | BR8: 6 | BS8: t | BT8: t | BU8: 2 | BV8: ㄉ | BX8: 6 | BY8: oo | BZ8: O | CA8: i | CB8: ㆦ | CD8: 6 | CE8: 8 | CF8: 8 | CG8: ] | CH8: 八
C9: ="- xlit|BbpmdtnlGgkŋZzcsJjCShaiwueOəIUdfqrvxyMGNY@AWHRFQV7325841L&*|!1qa2wsxEedGYyhnRrfvc8uKj,ik9l*UJ<I(Lm/pM0;Oobtgz53467][N.-|" -> - xlit|BbpmdtnlGgkŋZzcsJjCShaiwueOəIUdfqrvxyMGNY@AWHRFQV7325841L&*|!1qa2wsxEedGYyhnRrfvc8uKj,ik9l*UJ<I(Lm/pM0;Oobtgz53467][N.-| | BL9: n | BM9: s | BN9: ㄋ | BR9: 7 | BS9: th | BT9: T | BU9: w | BV9: ㄊ | BX9: 7 | BY9: o | BZ9: ə | CA9: k | CB9: ㄜ | CD9: 7 | CE9: 4 | CF9: 4 | CG9: [ | CH9: 四
A10: 第1個 |： | B10: =SEARCH("|", C9) -> 7 | BL10: l | BM10: x | BN10: ㄌ | BR10: 8 | BS10: l | BT10: l | BU10: x | BV10: ㄌ | BX10: 8 | BY10: -m | BZ10: M | CA10: m | CB10: ㆬ | CD10: 8 | CE10: 0 | CF10: 0 | CG10: 7 | CH10: 入
A11: 第2個 |： | B11: =SEARCH("|", C9, B10+1) -> 67 | BL11: Ğ | BM11: E | BN11: ㆣ | BR11: 9 | BS11: ㆣ | BT11: g | BU11: E | BV11: ㆣ | BX11: 9 | BY11: -n | BZ11: N | CA11: p | CB11: ㄣ | CD11: 9 | CE11: L | CF11: L | CG11: N | CH11: ㄥ
A12: 第3個 |： | B12: =SEARCH("|",C9, B11+1) -> 127 | BL12: g | BM12: e | BN12: ㄍ | BR12: 10 | BS12: k | BT12: k | BU12: e | BV12: ㄍ | BX12: 10 | BY12: -ng | BZ12: G | CA12: / | CB12: ㆭ
BL13: k | BM13: d | BN13: ㄎ | BR13: 11 | BS13: kh | BT13: K | BU13: d | BV13: ㄎ | BX13: 11 | BY13: -p | BZ13: R | CA13: b | CB13: ㆴ
C14: =MID(C9, B10+1, B11-B10-1) -> BbpmdtnlGgkŋZzcsJjCShaiwueOəIUdfqrvxyMGNY@AWHRFQV7325841L&* | BL14: ŋ | BM14: G | BN14: ㄫ | BR14: 12 | BS14: ng | BT14: ŋ | BU14: G | BV14: ㄫ | BX14: 12 | BY14: -t | BZ14: F | CA14: t | CB14: ㆵ
C15: =MID(C9, B11+1, B12-B11-1) -> !1qa2wsxEedGYyhnRrfvc8uKj,ik9l*UJ<I(Lm/pM0;Oobtgz53467][N.- | BL15: Z | BM15: Y | BN15: ㆡ | BR15: 13 | BS15: j | BT15: j | BU15: Y | BV15: ㆡ | BX15: 13 | BY15: -k | BZ15: Q | CA15: g | CB15: ㆻ
BL16: z | BM16: y | BN16: ㄗ | BR16: 14 | BS16: z(ts) | BT16: z | BU16: y | BV16: ㄗ | BX16: 14 | BY16: -h | BZ16: V | CA16: z | CB16: ㆷ
C17: =COLUMN() -2 -> 1 | D17: =COLUMN() -2 -> 2 | E17: =COLUMN() -2 -> 3 | F17: =COLUMN() -2 -> 4 | G17: =COLUMN() -2 -> 5 | H17: =COLUMN() -2 -> 6 | I17: =COLUMN() -2 -> 7 | J17: =COLUMN() -2 -> 8 | ... BJ17: =COLUMN() -2 -> 60 | BL17: c | BM17: h | BN17: ㄘ | BR17: 15 | BS17: c(tsh) | BT17: c | BU17: h | BV17: ㄘ | BX17: 15 | BY17: ai | BZ17: I | CA17: 9 | CB17: ㄞ
A18: 字典編碼 | C18: =MID( $C$14,C$17,1) -> B | D18: =MID( $C$14,D$17,1) -> b | E18: =MID( $C$14,E$17,1) -> p | F18: =MID( $C$14,F$17,1) -> m | G18: =MID( $C$14,G$17,1) -> d | H18: =MID( $C$14,H$17,1) -> t | I18: =MID( $C$14,I$17,1) -> n | J18: =MID( $C$14,J$17,1) -> l | ... BJ18: =MID( $C$14,BJ$17,1) | BL18: s | BM18: n | BN18: ㄙ | BR18: 16 | BS18: s | BT18: s | BU18: n | BV18: ㄙ | BX18: 16 | BY18: au | BZ18: U | CA18: l | CB18: ㄠ
A19: 鍵盤按鍵 | C19: =MID($C$15,C$17,1) -> ! | D19: =MID($C$15,D$17,1) -> 1 | E19: =MID($C$15,E$17,1) -> q | F19: =MID($C$15,F$17,1) -> a | G19: =MID($C$15,G$17,1) -> 2 | H19: =MID($C$15,H$17,1) -> w | I19: =MID($C$15,I$17,1) -> s | J19: =MID($C$15,J$17,1) -> x | ... BJ19: =MID($C$15,BJ$17,1) | BL19: J | BM19: R | BN19: ㆢ | BR19: 17 | BS19: h | BT19: h | BU19: c | BV19: ㄏ | BX19: 17 | BY19: am | BZ19: Y | CA19: M | CB19: ㆰ
BL20: j | BM20: r | BN20: ㄐ | BR20: 18 | BS20: j(i) | BT20: J | BU20: R | BV20: ㆢ | BX20: 18 | BY20: an | BZ20: @ | CA20: 0 | CB20: ㄢ
BL21: C | BM21: f | BN21: ㄑ | BR21: 19 | BS21: z(i) | BT21: Z | BU21: r | BV21: ㄐ | BX21: 19 | BY21: ang | BZ21: A | CA21: ; | CB21: ㄤ
BL22: S | BM22: v | BN22: ㄒ | BR22: 20 | BS22: c(i) | BT22: C | BU22: f | BV22: ㄑ | BX22: 20 | BY22: om | BZ22: W | CA22: O | CB22: ㆱ
A23: preedit_format: | BL23: h | BM23: c | BN23: ㄏ | BR23: 21 | BS23: s(i) | BT23: S | BU23: v | BV23: ㄒ | BX23: 21 | BY23: ong | BZ23: H | CA23: o | CB23: ㆲ
C24: ="- xlit|!1qa2wsxEedGYyhnRrfvc8uKj,ik9l*UJ<I(Lm/pM0;Oobtgz53467][N.-|ㆠㄅㄆㄇㄉㄊㄋㄌㆣㄍㄎㄫㆡㄗㄘㄙㆢㄐㄑㄒㄏㄚㄧㆨㄨㆤㆦㄜㄞㄠㆩㆪㆫㆥㆧㆮㆯㆬㆭㄣㆰㄢㄤㆱㆲㆴㆵㆻㆷ˫˪ˋˊ八四一ㄥ入ñ|" -> - xlit|!1qa2wsxEedGYyhnRrfvc8uKj,ik9l*UJ<I(Lm/pM0;Oobtgz53467][N.-|ㆠㄅㄆㄇㄉㄊㄋㄌㆣㄍㄎㄫㆡㄗㄘㄙㆢㄐㄑㄒㄏㄚㄧㆨㄨㆤㆦㄜㄞㄠㆩㆪㆫㆥㆧㆮㆯㆬㆭㄣㆰㄢㄤㆱㆲㆴㆵㆻㆷ˫˪ˋˊ八四一ㄥ入ñ| | BL24: a | BM24: 8 | BN24: ㄚ | BX24: 22 | BY24: aⁿ | BZ24: d | CA24: * | CB24: ㆩ
A25: 第1個 |： | B25: =SEARCH("|", C24) -> 7 | BL25: i | BM25: u | BN25: ㄧ | BX25: 23 | BY25: iⁿ | BZ25: f | CA25: U | CB25: ㆪ
A26: 第2個 |： | B26: =SEARCH("|", C24, B25+1) -> 67 | BL26: w | BM26: K | BN26: ㆨ | BX26: 24 | BY26: uⁿ | BZ26: q | CA26: J | CB26: ㆫ
A27: 第3個 |： | B27: =SEARCH("|",C24, B26+1) -> 127 | BL27: u | BM27: j | BN27: ㄨ | BX27: 25 | BY27: eⁿ | BZ27: r | CA27: < | CB27: ㆥ
BL28: e | BM28: , | BN28: ㆤ | BX28: 26 | BY28: oⁿ | BZ28: v | CA28: I | CB28: ㆧ
C29: =MID(C24, B25+1, B26-B25-1) -> !1qa2wsxEedGYyhnRrfvc8uKj,ik9l*UJ<I(Lm/pM0;Oobtgz53467][N.- | BL29: O | BM29: i | BN29: ㆦ | BX29: 27 | BY29: aiⁿ | BZ29: x | CA29: ( | CB29: ㆮ
C30: =MID(C24, B26+1, B27-B26-1) -> ㆠㄅㄆㄇㄉㄊㄋㄌㆣㄍㄎㄫㆡㄗㄘㄙㆢㄐㄑㄒㄏㄚㄧㆨㄨㆤㆦㄜㄞㄠㆩㆪㆫㆥㆧㆮㆯㆬㆭㄣㆰㄢㄤㆱㆲㆴㆵㆻㆷ˫˪ˋˊ八四一ㄥ入ñ | BL30: ə | BM30: k | BN30: ㄜ | BX30: 28 | BY30: auⁿ | BZ30: y | CA30: L | CB30: ㆯ
BL31: I | BM31: 9 | BN31: ㄞ
C32: =COLUMN() -2 -> 1 | D32: =COLUMN() -2 -> 2 | E32: =COLUMN() -2 -> 3 | F32: =COLUMN() -2 -> 4 | G32: =COLUMN() -2 -> 5 | H32: =COLUMN() -2 -> 6 | I32: =COLUMN() -2 -> 7 | J32: =COLUMN() -2 -> 8 | ... BJ32: =COLUMN() -2 -> 60 | BL32: U | BM32: l | BN32: ㄠ
A33: 字典編碼 | C33: =MID($C$29,C$32,1) -> ! | D33: =MID($C$29,D$32,1) -> 1 | E33: =MID($C$29,E$32,1) -> q | F33: =MID($C$29,F$32,1) -> a | G33: =MID($C$29,G$32,1) -> 2 | H33: =MID($C$29,H$32,1) -> w | I33: =MID($C$29,I$32,1) -> s | J33: =MID($C$29,J$32,1) -> x | ... BJ33: =MID($C$29,BJ$32,1) | BL33: D | BM33: * | BN33: ㆩ
A34: 注音符號 | C34: =MID($C$30,C$32,1) -> ㆠ | D34: =MID($C$30,D$32,1) -> ㄅ | E34: =MID($C$30,E$32,1) -> ㄆ | F34: =MID($C$30,F$32,1) -> ㄇ | G34: =MID($C$30,G$32,1) -> ㄉ | H34: =MID($C$30,H$32,1) -> ㄊ | I34: =MID($C$30,I$32,1) -> ㄋ | J34: =MID($C$30,J$32,1) -> ㄌ | ... BJ34: =MID($C$30,BJ$32,1) | BL34: f | BM34: U | BN34: ㆪ
BL35: q | BM35: J | BN35: ㆫ
BL36: r | BM36: < | BN36: ㆥ
C37: =COLUMN() -2 -> 1 | D37: =COLUMN() -2 -> 2 | E37: =COLUMN() -2 -> 3 | F37: =COLUMN() -2 -> 4 | G37: =COLUMN() -2 -> 5 | H37: =COLUMN() -2 -> 6 | I37: =COLUMN() -2 -> 7 | J37: =COLUMN() -2 -> 8 | ... BJ37: =COLUMN() -2 -> 60 | BL37: v | BM37: I | BN37: ㆧ
A38: 台語注音二式 | C38: b | D38: p | E38: ph | F38: m | G38: n | H38: t | I38: th | J38: l | K38: g | L38: k | M38: kh | N38: ng | O38: j | P38: ts | Q38: tsh | R38: s | S38: j(i) | T38: ts(i) | U38: tsh(i) | V38: s(i) | W38: h | X38: a | Y38: i | Z38: ir | AA38: u | AB38: e | AC38: oo | AD38: o | AE38: ai | AF38: au | AG38: ann | AH38: inn | AI38: unn | AJ38: enn | AK38: onn | AL38: ainn | AM38: aunn | AN38: -m | AO38: -ng | AP38: -n | AQ38: am | AR38: an | AS38: ang | AT38: om | AU38: ong | AV38: -p | AW38: -t | AX38: -k | AY38: -h | AZ38: ñ | BA38: [48] | BB38: 1 | BC38: 7 | BD38: 3 | BE38: 2 | BF38: 5 | BG38: 8 | BH38: 4 | BL38: x | BM38: ( | BN38: ㆮ
A39: 字典編碼 | C39: =C18 -> B | D39: =D18 -> b | E39: =E18 -> p | F39: =F18 -> m | G39: =G18 -> d | H39: =H18 -> t | I39: =I18 -> n | J39: =J18 -> l | K39: Ğ | L39: =L18 -> g | M39: =M18 -> k | N39: =N18 -> ŋ | O39: =O18 -> Z | P39: =P18 -> z | Q39: =Q18 -> c | R39: =R18 -> s | S39: =S18 -> J | ... AF39: =AF18 -> U | AG39: D | AH39: =AH18 -> f | AI39: =AI18 -> q | AJ39: =AJ18 -> r | AK39: =AK18 -> v | AL39: =AL18 -> x | AM39: =AM18 -> y | AN39: =AN18 -> M | AO39: =AO18 -> G | ... AY39: =AY18 -> V | AZ39: =BG18 -> L | BA39: =BH18 -> & | BB39: =BF18 -> 1 | BC39: =AZ18 -> 7 | BD39: =BA18 -> 3 | BE39: =BB18 -> 2 | BF39: =BC18 -> 5 | BG39: =BD18 -> 8 | BH39: =BE18 -> 4 | BJ39: =BJ18 | BL39: y | BM39: L | BN39: ㆯ
A40: 鍵盤按鍵 | C40: =C19 -> ! | D40: =D19 -> 1 | E40: =E19 -> q | F40: =F19 -> a | G40: =G19 -> 2 | H40: =H19 -> w | I40: =I19 -> s | J40: =J19 -> x | ... AY40: =AY19 -> z | AZ40: - | BA40: =BH19 -> . | BB40: " | BC40: =AZ19 -> 5 | BD40: =BA19 -> 3 | BE40: =BB19 -> 4 | BF40: =BC19 -> 6 | BG40: ] | BH40: [ | BJ40: =BJ19 | BL40: M | BM40: m | BN40: ㆬ
...

Sheet 台語注音二式【RIME設置】 
BY1: 聲韻調 | BZ1: 聲韻調 | CA1: 台語音標 | CH1: 聲韻調 | CI1: 聲韻調 | CJ1: 鼻化韻母 | CQ1: 聲韻調 | CR1: 台語音標 | CZ1: 聲韻調
B2: 1 ! | E2: 2 @ | H2: 3 # | K2: 4 $ | N2: 0.05 | Q2: 6 ^ | T2: 7 & | W2: 8 * | Z2: 9 ( | AC2: 0 ) | AF2: - _ | AI2: = + | BY2: 韻 | BZ2: 韻尾 | CA2: * | CH2: 韻 | CI2: 韻尾 | CQ2: 聲 | CR2: * | CZ2: 鍵
B3: ㆠ | D3: b | W3: ㆩ | X3: ann | Y3: ann | Z3: ㆮ | AA3: ainn | BO3: 對映總表
B4: ㄅ | D4: p | E4: ㄉ | G4: d | H4: ˪ | J4: 陰去 | K4: ˋ | M4: 上声 | N4: ˫ | P4: 陽去 | Q4: ˊ | S4: 陽平 | T4: · | V4: 輕声 | W4: ㄚ | Y4: a | Z4: ㄞ | AB4: ai | AC4: ㄢ | AD4: 0 | AE4: an | AF4: 入 | AH4: ptkh | BO4: 台語音標 | BP4: 字典編碼 | BQ4: 鍵盤按鍵 | BR4: 方音符號 | BS4: 聲韻調 | BT4: 字母長度 | BY4: 台語音標 | BZ4: 字典編碼 | CA4: 鍵盤按鍵 | CB4: 方音符號 | CC4: 聲韻調 | CD4: 字母長度 | CH4: 台語音標 | CI4: 字典編碼 | CJ4: 鍵盤按鍵 | CK4: 方音符號 | CL4: 聲韻調 | CM4: 字母長度 | CQ4: 台語音標 | CR4: 字典編碼 | CS4: 鍵盤按鍵 | CT4: 方音符號 | CU4: 聲韻調 | CV4: 字母長度 | CZ4: 台語音標 | DA4: 字典編碼 | DB4: 鍵盤按鍵 | DC4: 方音符號 | DD4: 聲韻調 | DE4: 字母長度
C5: Q | F5: W | I5: E | L5: R | O5: T | R5: Y | U5: U | X5: I | AA5: O | AD5: P | AG5: [ { | AJ5: ] } | AM5: \ | | BN5: =ROW() - 4 -> 1 | BO5: {=TRANSPOSE(D17:BJ20)} -> b | BP5: B | BQ5: ! | BR5: ㆠ | BS5: 聲 | BT5: =LEN(BO5) -> 1 | BV5: =" """ & BQ5 & """: { commit: """ & BR5 & """ }" & " # " & "/" & BO5 & "/ ==> " & BP5 -> "!": { commit: "ㆠ" } # /b/ ==> B | BX5: =ROW() - 4 -> 1 | BY5: {=_xlfn._xlws.SORT( _xlfn._xlws.FILTER($BO5:$BT64,($BS5:$BS64=BY2)*($BS5:$BS64<>BZ2)*($BO5:$BT64=CA2), "無符合資料"), 6, -1)} -> #VALUE! | CF5: =IFERROR( IF(LEN(BZ5)=0, "", IF(BZ5=BY5, "", " - xform/" & BY5 & "/" & BZ5 & "/ # " & "【" & CA5 & "】 ==> " & CC5 & "： " & CB5 & " [" & BY5 & "]")), "") | CG5: =ROW() - 4 -> 1 | CH5: {=_xlfn._xlws.SORT( _xlfn._xlws.FILTER($BO5:$BT64,($BS5:$BS64=CH2)*($BS5:$BS64<>CI2), "無符合資料"), 6, -1)} -> ainn | CI5: x | CJ5: ( | CK5: ㆮ | CL5: 韻 | CM5: 4 | CO5: =IFERROR( IF(LEN(CI5)=0, "", IF(EXACT(CI5,CH5), "", " - xform/" & CH5 & "/" & CI5 & "/ # " & "【" & CJ5 & "】 ==> " & CL5 & "： " & CK5 & " [" & CH5 & "]")), "") -> - xform/ainn/x/ # 【(】 ==> 韻： ㆮ [ainn] | CP5: =ROW() - 4 -> 1 | CQ5: {=_xlfn._xlws.SORT( _xlfn._xlws.FILTER($BO$5:$BT$64,($BS5:$BS64=CQ2)*($BO5:$BO64<>CR2), "無符合資料"), 6, -1)} -> tsh(i) | CR5: C | CS5: f | CT5: ㄑ | CU5: 聲 | CV5: 6 | CX5: =IFERROR( IF(LEN(CR5)=0, "", IF(EXACT(CR5,CQ5), "", " - xform/^" & CQ5 & "/" & CR5 & "/ # " & "【" & CS5 & "】 ==> " & CU5 & "： " & CT5 & " [" & CQ5 & "]")), "") -> - xform/^tsh(i)/C/ # 【f】 ==> 聲： ㄑ [tsh(i)] | CY5: =ROW() - 4 -> 1 | CZ5: {=_xlfn._xlws.FILTER($BO$5:$BT$64,($BS5:$BS64=CZ2), "無符合資料")} -> 5 | DA5: 5 | DB5: 6 | DC5: 五 | DD5: 鍵 | DE5: 1
I6: ㆣ | K6: g | L6: ㆢ | N6: ji | R6: ㆡ | T6: j | U6: ㆪ | V6: inn | W6: inn | X6: ㆧ | Y6: onn | Z6: oonn | AA6: ㆱ | AB6: om | BN6: =ROW() - 4 -> 2 | BO6: p | BP6: b | BQ6: 1 | BR6: ㄅ | BS6: 聲 | BT6: =LEN(BO6) -> 1 | BV6: =" """ & BQ6 & """: { commit: """ & BR6 & """ }" & " # " & "/" & BO7 & "/ ==> " & BP6 -> "1": { commit: "ㄅ" } # /ph/ ==> b | BX6: =ROW() - 4 -> 2 | CF6: =IFERROR( IF(LEN(BZ6)=0, "", IF(BZ6=BY6, "", " - xform/" & BY6 & "/" & BZ6 & "/ # " & "【" & CA6 & "】 ==> " & CC6 & "： " & CB6 & " [" & BY6 & "]")), "") | CG6: =ROW() - 4 -> 2 | CH6: aunn | CI6: y | CJ6: L | CK6: ㆯ | CL6: 韻 | CM6: 4 | CO6: =IFERROR( IF(LEN(CI6)=0, "", IF(EXACT(CI6,CH6), "", " - xform/" & CH6 & "/" & CI6 & "/ # " & "【" & CJ6 & "】 ==> " & CL6 & "： " & CK6 & " [" & CH6 & "]")), "") -> - xform/aunn/y/ # 【L】 ==> 韻： ㆯ [aunn] | CP6: =ROW() - 4 -> 2 | CQ6: ts(i) | CR6: j | CS6: r | CT6: ㄐ | CU6: 聲 | CV6: 5 | CX6: =IFERROR( IF(LEN(CR6)=0, "", IF(EXACT(CR6,CQ6), "", " - xform/^" & CQ6 & "/" & CR6 & "/ # " & "【" & CS6 & "】 ==> " & CU6 & "： " & CT6 & " [" & CQ6 & "]")), "") -> - xform/^ts(i)/j/ # 【r】 ==> 聲： ㄐ [ts(i)] | CY6: =ROW() - 4 -> 2 | CZ6: 8 | DA6: 8 | DB6: ] | DC6: 八 | DD6: 鍵 | DE6: 1
C7: ㄆ | E7: ph | F7: ㄊ | H7: t | I7: ㄍ | J7: 0 | K7: k | L7: ㄐ | N7: zi | O7: ㆵ | Q7: t0 | R7: ㄗ | T7: z | U7: ㄧ | W7: i | X7: ㆦ | Z7: oo | AA7: ㆲ | AC7: ong | AD7: ㄣ | AF7: -n | AI7: 陰入 | AJ7: · | AL7: 陽入 | BN7: =ROW() - 4 -> 3 | BO7: ph | BP7: p | BQ7: q | BR7: ㄆ | BS7: 聲 | BT7: =LEN(BO7) -> 2 | BV7: =" """ & BQ7 & """: { commit: """ & BR7 & """ }" & " # " & "/" & BO8 & "/ ==> " & BP7 -> "q": { commit: "ㄆ" } # /m/ ==> p | BX7: =ROW() - 4 -> 3 | CF7: =IFERROR( IF(LEN(BZ7)=0, "", IF(BZ7=BY7, "", " - xform/" & BY7 & "/" & BZ7 & "/ # " & "【" & CA7 & "】 ==> " & CC7 & "： " & CB7 & " [" & BY7 & "]")), "") | CG7: =ROW() - 4 -> 3 | CH7: -ng | CI7: G | CJ7: / | CK7: ㆭ | CL7: 韻 | CM7: 3 | CO7: =IFERROR( IF(LEN(CI7)=0, "", IF(EXACT(CI7,CH7), "", " - xform/" & CH7 & "/" & CI7 & "/ # " & "【" & CJ7 & "】 ==> " & CL7 & "： " & CK7 & " [" & CH7 & "]")), "") -> - xform/-ng/G/ # 【/】 ==> 韻： ㆭ [-ng] | CP7: =ROW() - 4 -> 3 | CQ7: j(i) | CR7: J | CS7: R | CT7: ㆢ | CU7: 聲 | CV7: 4 | CX7: =IFERROR( IF(LEN(CR7)=0, "", IF(EXACT(CR7,CQ7), "", " - xform/^" & CQ7 & "/" & CR7 & "/ # " & "【" & CS7 & "】 ==> " & CU7 & "： " & CT7 & " [" & CQ7 & "]")), "") -> - xform/^j(i)/J/ # 【R】 ==> 聲： ㆢ [j(i)] | CY7: =ROW() - 4 -> 3
D8: A | G8: S | J8: D | M8: F | P8: G | S8: H | V8: J | Y8: K | AB8: L | AE8: ; : | AH8: ' " | BN8: =ROW() - 4 -> 4 | BO8: m | BP8: m | BQ8: a | BR8: ㄇ | BS8: 聲 | BT8: =LEN(BO8) -> 1 | BV8: =" """ & BQ8 & """: { commit: """ & BR8 & """ }" & " # " & "/" & BO9 & "/ ==> " & BP8 -> "a": { commit: "ㄇ" } # /n/ ==> m | BX8: =ROW() - 4 -> 4 | CF8: =IFERROR( IF(LEN(BZ8)=0, "", IF(BZ8=BY8, "", " - xform/" & BY8 & "/" & BZ8 & "/ # " & "【" & CA8 & "】 ==> " & CC8 & "： " & CB8 & " [" & BY8 & "]")), "") | CG8: =ROW() - 4 -> 4 | CH8: ang | CI8: A | CJ8: ; | CK8: ㄤ | CL8: 韻 | CM8: 3 | CO8: =IFERROR( IF(LEN(CI8)=0, "", IF(EXACT(CI8,CH8), "", " - xform/" & CH8 & "/" & CI8 & "/ # " & "【" & CJ8 & "】 ==> " & CL8 & "： " & CK8 & " [" & CH8 & "]")), "") -> - xform/ang/A/ # 【;】 ==> 韻： ㄤ [ang] | CP8: =ROW() - 4 -> 4 | CQ8: s(i) | CR8: S | CS8: v | CT8: ㄒ | CU8: 聲 | CV8: 4 | CX8: =IFERROR( IF(LEN(CR8)=0, "", IF(EXACT(CR8,CQ8), "", " - xform/^" & CQ8 & "/" & CR8 & "/ # " & "【" & CS8 & "】 ==> " & CU8 & "： " & CT8 & " [" & CQ8 & "]")), "") -> - xform/^s(i)/S/ # 【v】 ==> 聲： ㄒ [s(i)] | CY8: =ROW() - 4 -> 4
V9: ㆫ | W9: unn | X9: unn | Y9: ㆨ | Z9: ir | AA9: ir | AB9: ㆯ | AC9: aunn | BN9: =ROW() - 4 -> 5 | BO9: n | BP9: d | BQ9: 2 | BR9: ㄉ | BS9: 聲 | BT9: =LEN(BO9) -> 1 | BV9: =" """ & BQ9 & """: { commit: """ & BR9 & """ }" & " # " & "/" & BO10 & "/ ==> " & BP9 -> "2": { commit: "ㄉ" } # /t/ ==> d | BX9: =ROW() - 4 -> 5 | CF9: =IFERROR( IF(LEN(BZ9)=0, "", IF(BZ9=BY9, "", " - xform/" & BY9 & "/" & BZ9 & "/ # " & "【" & CA9 & "】 ==> " & CC9 & "： " & CB9 & " [" & BY9 & "]")), "") | CG9: =ROW() - 4 -> 5 | CH9: ong | CI9: H | CJ9: o | CK9: ㆲ | CL9: 韻 | CM9: 3 | CO9: =IFERROR( IF(LEN(CI9)=0, "", IF(EXACT(CI9,CH9), "", " - xform/" & CH9 & "/" & CI9 & "/ # " & "【" & CJ9 & "】 ==> " & CL9 & "： " & CK9 & " [" & CH9 & "]")), "") -> - xform/ong/H/ # 【o】 ==> 韻： ㆲ [ong] | CP9: =ROW() - 4 -> 5 | CQ9: tsh | CR9: c | CS9: h | CT9: ㄘ | CU9: 聲 | CV9: 3 | CX9: =IFERROR( IF(LEN(CR9)=0, "", IF(EXACT(CR9,CQ9), "", " - xform/^" & CQ9 & "/" & CR9 & "/ # " & "【" & CS9 & "】 ==> " & CU9 & "： " & CT9 & " [" & CQ9 & "]")), "") -> - xform/^tsh/c/ # 【h】 ==> 聲： ㄘ [tsh] | CY9: =ROW() - 4 -> 5
D10: ㄇ | F10: m- | G10: ㄋ | I10: n- | J10: ㄎ | K10: 0 | L10: kh | M10: ㄑ | O10: ci | P10: ㆻ | R10: k0 | S10: ㄘ | U10: c | V10: ㄨ | X10: u | Y10: ㄜ | AA10: or | AB10: ㄠ | AD10: au | AE10: ㄤ | AG10: ang | AJ10: 陰平 | BN10: =ROW() - 4 -> 6 | BO10: t | BP10: t | BQ10: w | BR10: ㄊ | BS10: 聲 | BT10: =LEN(BO10) -> 1 | BV10: =" """ & BQ10 & """: { commit: """ & BR10 & """ }" & " # " & "/" & BO11 & "/ ==> " & BP10 -> "w": { commit: "ㄊ" } # /th/ ==> t | BX10: =ROW() - 4 -> 6 | CF10: =IFERROR( IF(LEN(BZ10)=0, "", IF(BZ10=BY10, "", " - xform/" & BY10 & "/" & BZ10 & "/ # " & "【" & CA10 & "】 ==> " & CC10 & "： " & CB10 & " [" & BY10 & "]")), "") | CG10: =ROW() - 4 -> 6 | CH10: -m | CI10: M | CJ10: m | CK10: ㆬ | CL10: 韻 | CM10: 2 | CO10: =IFERROR( IF(LEN(CI10)=0, "", IF(EXACT(CI10,CH10), "", " - xform/" & CH10 & "/" & CI10 & "/ # " & "【" & CJ10 & "】 ==> " & CL10 & "： " & CK10 & " [" & CH10 & "]")), "") -> - xform/-m/M/ # 【m】 ==> 韻： ㆬ [-m] | CP10: =ROW() - 4 -> 6 | CQ10: ph | CR10: p | CS10: q | CT10: ㄆ | CU10: 聲 | CV10: 2 | CX10: =IFERROR( IF(LEN(CR10)=0, "", IF(EXACT(CR10,CQ10), "", " - xform/^" & CQ10 & "/" & CR10 & "/ # " & "【" & CS10 & "】 ==> " & CU10 & "： " & CT10 & " [" & CQ10 & "]")), "") -> - xform/^ph/p/ # 【q】 ==> 聲： ㄆ [ph] | CY10: =ROW() - 4 -> 6
E11: Z | H11: X | K11: C | N11: V | Q11: B | T11: N | W11: M | Z11: , < | AC11: . > | AF11: / ? | BN11: =ROW() - 4 -> 7 | BO11: th | BP11: n | BQ11: s | BR11: ㄋ | BS11: 聲 | BT11: =LEN(BO11) -> 2 | BV11: =" """ & BQ11 & """: { commit: """ & BR11 & """ }" & " # " & "/" & BO12 & "/ ==> " & BP11 -> "s": { commit: "ㄋ" } # /l/ ==> n | BX11: =ROW() - 4 -> 7 | CF11: =IFERROR( IF(LEN(BZ11)=0, "", IF(BZ11=BY11, "", " - xform/" & BY11 & "/" & BZ11 & "/ # " & "【" & CA11 & "】 ==> " & CC11 & "： " & CB11 & " [" & BY11 & "]")), "") | CG11: =ROW() - 4 -> 7 | CH11: -n | CI11: N | CJ11: p | CK11: ㄣ | CL11: 韻 | CM11: 2 | CO11: =IFERROR( IF(LEN(CI11)=0, "", IF(EXACT(CI11,CH11), "", " - xform/" & CH11 & "/" & CI11 & "/ # " & "【" & CJ11 & "】 ==> " & CL11 & "： " & CK11 & " [" & CH11 & "]")), "") -> - xform/-n/N/ # 【p】 ==> 韻： ㄣ [-n] | CP11: =ROW() - 4 -> 7 | CQ11: th | CR11: n | CS11: s | CT11: ㄋ | CU11: 聲 | CV11: 2 | CX11: =IFERROR( IF(LEN(CR11)=0, "", IF(EXACT(CR11,CQ11), "", " - xform/^" & CQ11 & "/" & CR11 & "/ # " & "【" & CS11 & "】 ==> " & CU11 & "： " & CT11 & " [" & CQ11 & "]")), "") -> - xform/^th/n/ # 【s】 ==> 聲： ㄋ [th] | CY11: =ROW() - 4 -> 7
T12: ㄫ | V12: ng- | W12: ㆰ | X12: am | Y12: unn | Z12: ㆥ | AA12: enn | AB12: unn | BN12: =ROW() - 4 -> 8 | BO12: l | BP12: l | BQ12: x | BR12: ㄌ | BS12: 聲 | BT12: =LEN(BO12) -> 1 | BV12: =" """ & BQ12 & """: { commit: """ & BR12 & """ }" & " # " & "/" & BO13 & "/ ==> " & BP12 -> "x": { commit: "ㄌ" } # /g/ ==> l | BX12: =ROW() - 4 -> 8 | CF12: =IFERROR( IF(LEN(BZ12)=0, "", IF(BZ12=BY12, "", " - xform/" & BY12 & "/" & BZ12 & "/ # " & "【" & CA12 & "】 ==> " & CC12 & "： " & CB12 & " [" & BY12 & "]")), "") | CG12: =ROW() - 4 -> 8 | CH12: am | CI12: Y | CJ12: M | CK12: ㆰ | CL12: 韻 | CM12: 2 | CO12: =IFERROR( IF(LEN(CI12)=0, "", IF(EXACT(CI12,CH12), "", " - xform/" & CH12 & "/" & CI12 & "/ # " & "【" & CJ12 & "】 ==> " & CL12 & "： " & CK12 & " [" & CH12 & "]")), "") -> - xform/am/Y/ # 【M】 ==> 韻： ㆰ [am] | CP12: =ROW() - 4 -> 8 | CQ12: kh | CR12: k | CS12: d | CT12: ㄎ | CU12: 聲 | CV12: 2 | CX12: =IFERROR( IF(LEN(CR12)=0, "", IF(EXACT(CR12,CQ12), "", " - xform/^" & CQ12 & "/" & CR12 & "/ # " & "【" & CS12 & "】 ==> " & CU12 & "： " & CT12 & " [" & CQ12 & "]")), "") -> - xform/^kh/k/ # 【d】 ==> 聲： ㄎ [kh] | CY12: =ROW() - 4 -> 8
E13: ㆷ | G13: h0 | H13: ㄌ | J13: l | K13: ㄏ | M13: h | N13: ㄒ | P13: si | Q13: ㆴ | S13: p0 | T13: ㄙ | V13: s | W13: ㆬ | Y13: -m | Z13: ㆤ | AA13: 0 | AB13: e | AC13: ㄥㄚ | AE13: an | AF13: ㆭ | AH13: -ng | BN13: =ROW() - 4 -> 9 | BO13: g | BP13: Ğ | BQ13: E | BR13: ㆣ | BS13: 聲 | BT13: =LEN(BO13) -> 1 | BV13: =" """ & BQ13 & """: { commit: """ & BR13 & """ }" & " # " & "/" & BO14 & "/ ==> " & BP13 -> "E": { commit: "ㆣ" } # /k/ ==> Ğ | BX13: =ROW() - 4 -> 9 | CF13: =IFERROR( IF(LEN(BZ13)=0, "", IF(BZ13=BY13, "", " - xform/" & BY13 & "/" & BZ13 & "/ # " & "【" & CA13 & "】 ==> " & CC13 & "： " & CB13 & " [" & BY13 & "]")), "") | CG13: =ROW() - 4 -> 9 | CH13: an | CI13: @ | CJ13: 0 | CK13: ㄢ | CL13: 韻 | CM13: 2 | CO13: =IFERROR( IF(LEN(CI13)=0, "", IF(EXACT(CI13,CH13), "", " - xform/" & CH13 & "/" & CI13 & "/ # " & "【" & CJ13 & "】 ==> " & CL13 & "： " & CK13 & " [" & CH13 & "]")), "") -> - xform/an/@/ # 【0】 ==> 韻： ㄢ [an] | CP13: =ROW() - 4 -> 9 | CQ13: ng | CR13: ŋ | CS13: G | CT13: ㄫ | CU13: 聲 | CV13: 2 | CX13: =IFERROR( IF(LEN(CR13)=0, "", IF(EXACT(CR13,CQ13), "", " - xform/^" & CQ13 & "/" & CR13 & "/ # " & "【" & CS13 & "】 ==> " & CU13 & "： " & CT13 & " [" & CQ13 & "]")), "") -> - xform/^ng/ŋ/ # 【G】 ==> 聲： ㄫ [ng] | CY13: =ROW() - 4 -> 9
BN14: =ROW() - 4 -> 10 | BO14: k | BP14: g | BQ14: e | BR14: ㄍ | BS14: 聲 | BT14: =LEN(BO14) -> 1 | BV14: =" """ & BQ14 & """: { commit: """ & BR14 & """ }" & " # " & "/" & BO15 & "/ ==> " & BP14 -> "e": { commit: "ㄍ" } # /kh/ ==> g | BX14: =ROW() - 4 -> 10 | CF14: =IFERROR( IF(LEN(BZ14)=0, "", IF(BZ14=BY14, "", " - xform/" & BY14 & "/" & BZ14 & "/ # " & "【" & CA14 & "】 ==> " & CC14 & "： " & CB14 & " [" & BY14 & "]")), "") | CG14: =ROW() - 4 -> 10 | CH14: om | CI14: W | CJ14: O | CK14: ㆱ | CL14: 韻 | CM14: 2 | CO14: =IFERROR( IF(LEN(CI14)=0, "", IF(EXACT(CI14,CH14), "", " - xform/" & CH14 & "/" & CI14 & "/ # " & "【" & CJ14 & "】 ==> " & CL14 & "： " & CK14 & " [" & CH14 & "]")), "") -> - xform/om/W/ # 【O】 ==> 韻： ㆱ [om] | CP14: =ROW() - 4 -> 10 | CQ14: ts | CR14: z | CS14: y | CT14: ㄗ | CU14: 聲 | CV14: 2 | CX14: =IFERROR( IF(LEN(CR14)=0, "", IF(EXACT(CR14,CQ14), "", " - xform/^" & CQ14 & "/" & CR14 & "/ # " & "【" & CS14 & "】 ==> " & CU14 & "： " & CT14 & " [" & CQ14 & "]")), "") -> - xform/^ts/z/ # 【y】 ==> 聲： ㄗ [ts] | CY14: =ROW() - 4 -> 10
BN15: =ROW() - 4 -> 11 | BO15: kh | BP15: k | BQ15: d | BR15: ㄎ | BS15: 聲 | BT15: =LEN(BO15) -> 2 | BV15: =" """ & BQ15 & """: { commit: """ & BR15 & """ }" & " # " & "/" & BO16 & "/ ==> " & BP15 -> "d": { commit: "ㄎ" } # /ng/ ==> k | BX15: =ROW() - 4 -> 11 | CF15: =IFERROR( IF(LEN(BZ15)=0, "", IF(BZ15=BY15, "", " - xform/" & BY15 & "/" & BZ15 & "/ # " & "【" & CA15 & "】 ==> " & CC15 & "： " & CB15 & " [" & BY15 & "]")), "") | CG15: =ROW() - 4 -> 11 | CH15: -p | CI15: R | CJ15: b | CK15: ㆴ | CL15: 韻 | CM15: 2 | CO15: =IFERROR( IF(LEN(CI15)=0, "", IF(EXACT(CI15,CH15), "", " - xform/" & CH15 & "/" & CI15 & "/ # " & "【" & CJ15 & "】 ==> " & CL15 & "： " & CK15 & " [" & CH15 & "]")), "") -> - xform/-p/R/ # 【b】 ==> 韻： ㆴ [-p] | CP15: =ROW() - 4 -> 11 | CQ15: b | CR15: B | CS15: ! | CT15: ㆠ | CU15: 聲 | CV15: 1 | CX15: =_xlfn.CONCAT(" - xform/^", CR15, "/", CR15, "/", " # ", CT15, " [", CQ15, "]" ) -> - xform/^B/B/ # ㆠ [b] | CY15: =ROW() - 4 -> 11
B16: 序號 | D16: {=COLUMN() - COLUMN($C:$C)} -> 1 | E16: {=COLUMN() - COLUMN($C:$C)} -> 2 | F16: {=COLUMN() - COLUMN($C:$C)} -> 3 | G16: {=COLUMN() - COLUMN($C:$C)} -> 4 | H16: {=COLUMN() - COLUMN($C:$C)} -> 5 | I16: {=COLUMN() - COLUMN($C:$C)} -> 6 | J16: {=COLUMN() - COLUMN($C:$C)} -> 7 | K16: {=COLUMN() - COLUMN($C:$C)} -> 8 | ... BK16: {=COLUMN() - COLUMN($C:$C)} -> 60 | BN16: =ROW() - 4 -> 12 | BO16: ng | BP16: ŋ | BQ16: G | BR16: ㄫ | BS16: 聲 | BT16: =LEN(BO16) -> 2 | BV16: =" """ & BQ16 & """: { commit: """ & BR16 & """ }" & " # " & "/" & BO17 & "/ ==> " & BP16 -> "G": { commit: "ㄫ" } # /j/ ==> ŋ | BX16: =ROW() - 4 -> 12 | CF16: =IFERROR( IF(LEN(BZ16)=0, "", IF(BZ16=BY16, "", " - xform/" & BY16 & "/" & BZ16 & "/ # " & "【" & CA16 & "】 ==> " & CC16 & "： " & CB16 & " [" & BY16 & "]")), "") | CG16: =ROW() - 4 -> 12 | CH16: -t | CI16: F | CJ16: t | CK16: ㆵ | CL16: 韻 | CM16: 2 | CO16: =IFERROR( IF(LEN(CI16)=0, "", IF(EXACT(CI16,CH16), "", " - xform/" & CH16 & "/" & CI16 & "/ # " & "【" & CJ16 & "】 ==> " & CL16 & "： " & CK16 & " [" & CH16 & "]")), "") -> - xform/-t/F/ # 【t】 ==> 韻： ㆵ [-t] | CP16: =ROW() - 4 -> 12 | CQ16: p | CR16: b | CS16: 1 | CT16: ㄅ | CU16: 聲 | CV16: 1 | CX16: =_xlfn.CONCAT(" - xform/^", CR16, "/", CR16, "/", " # ", CT16, " [", CQ16, "]" ) -> - xform/^b/b/ # ㄅ [p] | CY16: =ROW() - 4 -> 12
B17: 台語音標 | D17: b | E17: p | F17: ph | G17: m | H17: n | I17: t | J17: th | K17: l | L17: g | M17: k | N17: kh | O17: ng | P17: j | Q17: ts | R17: tsh | S17: s | T17: j(i) | U17: ts(i) | V17: tsh(i) | W17: s(i) | X17: h | Y17: a | Z17: i | AA17: ir | AB17: u | AC17: e | AD17: oo | AE17: o | AF17: ai | AG17: au | AH17: ann | AI17: inn | AJ17: unn | AK17: enn | AL17: onn | AM17: ainn | AN17: aunn | AO17: -m | AP17: -ng | AQ17: -n | AR17: am | AS17: an | AT17: ang | AU17: om | AV17: ong | AW17: -p | AX17: -t | AY17: -k | AZ17: -h | BA17: [48] | BB17: ñ | BC17: Ø | BD17: 1 | BE17: 7 | BF17: 3 | BG17: 2 | BH17: 5 | BI17: 8 | BJ17: 4 | BN17: =ROW() - 4 -> 13 | BO17: j | BP17: Z | BQ17: Y | BR17: ㆡ | BS17: 聲 | BT17: =LEN(BO17) -> 1 | BV17: =" """ & BQ17 & """: { commit: """ & BR17 & """ }" & " # " & "/" & BO18 & "/ ==> " & BP17 -> "Y": { commit: "ㆡ" } # /ts/ ==> Z | BX17: =ROW() - 4 -> 13 | CF17: =IFERROR( IF(LEN(BZ17)=0, "", IF(BZ17=BY17, "", " - xform/" & BY17 & "/" & BZ17 & "/ # " & "【" & CA17 & "】 ==> " & CC17 & "： " & CB17 & " [" & BY17 & "]")), "") | CG17: =ROW() - 4 -> 13 | CH17: -k | CI17: Q | CJ17: g | CK17: ㆻ | CL17: 韻 | CM17: 2 | CO17: =IFERROR( IF(LEN(CI17)=0, "", IF(EXACT(CI17,CH17), "", " - xform/" & CH17 & "/" & CI17 & "/ # " & "【" & CJ17 & "】 ==> " & CL17 & "： " & CK17 & " [" & CH17 & "]")), "") -> - xform/-k/Q/ # 【g】 ==> 韻： ㆻ [-k] | CP17: =ROW() - 4 -> 13 | CQ17: m | CR17: m | CS17: a | CT17: ㄇ | CU17: 聲 | CV17: 1 | CX17: =_xlfn.CONCAT(" - xform/^", CR17, "/", CR17, "/", " # ", CT17, " [", CQ17, "]" ) -> - xform/^m/m/ # ㄇ [m] | CY17: =ROW() - 4 -> 13
B18: 字典編碼 | D18: B | E18: b | F18: p | G18: m | H18: d | I18: t | J18: n | K18: l | L18: Ğ | M18: g | N18: k | O18: ŋ | P18: Z | Q18: z | R18: c | S18: s | T18: J | U18: j | V18: C | W18: S | X18: h | Y18: a | Z18: i | AA18: w | AB18: u | AC18: e | AD18: O | AE18: ə | AF18: I | AG18: U | AH18: D | AI18: f | AJ18: q | AK18: r | AL18: v | AM18: x | AN18: y | AO18: M | AP18: G | AQ18: N | AR18: Y | AS18: @ | AT18: A | AU18: W | AV18: H | AW18: R | AX18: F | AY18: Q | AZ18: V | BA18: & | BB18: L | BC18: Ø | BD18: 1 | BE18: 7 | BF18: 3 | BG18: 2 | BH18: 5 | BI18: 8 | BJ18: 4 | BN18: =ROW() - 4 -> 14 | BO18: ts | BP18: z | BQ18: y | BR18: ㄗ | BS18: 聲 | BT18: =LEN(BO18) -> 2 | BV18: =" """ & BQ18 & """: { commit: """ & BR18 & """ }" & " # " & "/" & BO19 & "/ ==> " & BP18 -> "y": { commit: "ㄗ" } # /tsh/ ==> z | BX18: =ROW() - 4 -> 14 | CF18: =IFERROR( IF(LEN(BZ18)=0, "", IF(BZ18=BY18, "", " - xform/" & BY18 & "/" & BZ18 & "/ # " & "【" & CA18 & "】 ==> " & CC18 & "： " & CB18 & " [" & BY18 & "]")), "") | CG18: =ROW() - 4 -> 14 | CH18: -h | CI18: V | CJ18: z | CK18: ㆷ | CL18: 韻 | CM18: 2 | CO18: =IFERROR( IF(LEN(CI18)=0, "", IF(EXACT(CI18,CH18), "", " - xform/" & CH18 & "/" & CI18 & "/ # " & "【" & CJ18 & "】 ==> " & CL18 & "： " & CK18 & " [" & CH18 & "]")), "") -> - xform/-h/V/ # 【z】 ==> 韻： ㆷ [-h] | CP18: =ROW() - 4 -> 14 | CQ18: n | CR18: d | CS18: 2 | CT18: ㄉ | CU18: 聲 | CV18: 1 | CX18: =_xlfn.CONCAT(" - xform/^", CR18, "/", CR18, "/", " # ", CT18, " [", CQ18, "]" ) -> - xform/^d/d/ # ㄉ [n] | CY18: =ROW() - 4 -> 14
B19: 鍵盤按鍵 | D19: ! | E19: 1 | F19: q | G19: a | H19: 2 | I19: w | J19: s | K19: x | L19: E | M19: e | N19: d | O19: G | P19: Y | Q19: y | R19: h | S19: n | T19: R | U19: r | V19: f | W19: v | X19: c | Y19: 8 | Z19: u | AA19: K | AB19: j | AC19: , | AD19: i | AE19: k | AF19: 9 | AG19: l | AH19: * | AI19: U | AJ19: J | AK19: < | AL19: I | AM19: ( | AN19: L | AO19: m | AP19: / | AQ19: p | AR19: M | AS19: 0 | AT19: ; | AU19: O | AV19: o | AW19: b | AX19: t | AY19: g | AZ19: z | BA19: 7 | BB19: - | BC19: = | BD19: " | BE19: 5 | BF19: 3 | BG19: 4 | BH19: 6 | BI19: ] | BJ19: [ | BN19: =ROW() - 4 -> 15 | BO19: tsh | BP19: c | BQ19: h | BR19: ㄘ | BS19: 聲 | BT19: =LEN(BO19) -> 3 | BV19: =" """ & BQ19 & """: { commit: """ & BR19 & """ }" & " # " & "/" & BO20 & "/ ==> " & BP19 -> "h": { commit: "ㄘ" } # /s/ ==> c | BX19: =ROW() - 4 -> 15 | CF19: =IFERROR( IF(LEN(BZ19)=0, "", IF(BZ19=BY19, "", " - xform/" & BY19 & "/" & BZ19 & "/ # " & "【" & CA19 & "】 ==> " & CC19 & "： " & CB19 & " [" & BY19 & "]")), "") | CG19: =ROW() - 4 -> 15 | CH19: o | CI19: ə | CJ19: k | CK19: ㄜ | CL19: 韻 | CM19: 1 | CO19: =IFERROR( IF(LEN(CI19)=0, "", IF(EXACT(CI19,CH19), "", " - xform/" & CH19 & "/" & CI19 & "/ # " & "【" & CJ19 & "】 ==> " & CL19 & "： " & CK19 & " [" & CH19 & "]")), "") -> - xform/o/ə/ # 【k】 ==> 韻： ㄜ [o] | CP19: =ROW() - 4 -> 15 | CQ19: t | CR19: t | CS19: w | CT19: ㄊ | CU19: 聲 | CV19: 1 | CX19: =_xlfn.CONCAT(" - xform/^", CR19, "/", CR19, "/", " # ", CT19, " [", CQ19, "]" ) -> - xform/^t/t/ # ㄊ [t] | CY19: =ROW() - 4 -> 15
B20: 方音符號 | D20: ㆠ | E20: ㄅ | F20: ㄆ | G20: ㄇ | H20: ㄉ | I20: ㄊ | J20: ㄋ | K20: ㄌ | L20: ㆣ | M20: ㄍ | N20: ㄎ | O20: ㄫ | P20: ㆡ | Q20: ㄗ | R20: ㄘ | S20: ㄙ | T20: ㆢ | U20: ㄐ | V20: ㄑ | W20: ㄒ | X20: ㄏ | Y20: ㄚ | Z20: ㄧ | AA20: ㆨ | AB20: ㄨ | AC20: ㆤ | AD20: ㆦ | AE20: ㄜ | AF20: ㄞ | AG20: ㄠ | AH20: ㆩ | AI20: ㆪ | AJ20: ㆫ | AK20: ㆥ | AL20: ㆧ | AM20: ㆮ | AN20: ㆯ | AO20: ㆬ | AP20: ㆭ | AQ20: ㄣ | AR20: ㆰ | AS20: ㄢ | AT20: ㄤ | AU20: ㆱ | AV20: ㆲ | AW20: ㆴ | AX20: ㆵ | AY20: ㆻ | AZ20: ㆷ | BA20: 入 | BB20: ㄥ | BC20: Ø | BD20: 一 | BE20: 七 | BF20: 三 | BG20: 二 | BH20: 五 | BI20: 八 | BJ20: 四 | BN20: =ROW() - 4 -> 16 | BO20: s | BP20: s | BQ20: n | BR20: ㄙ | BS20: 聲 | BT20: =LEN(BO20) -> 1 | BV20: =" """ & BQ20 & """: { commit: """ & BR20 & """ }" & " # " & "/" & BO21 & "/ ==> " & BP20 -> "n": { commit: "ㄙ" } # /j(i)/ ==> s | BX20: =ROW() - 4 -> 16 | CF20: =IFERROR( IF(LEN(BZ20)=0, "", IF(BZ20=BY20, "", " - xform/" & BY20 & "/" & BZ20 & "/ # " & "【" & CA20 & "】 ==> " & CC20 & "： " & CB20 & " [" & BY20 & "]")), "") | CG20: =ROW() - 4 -> 16 | CO20: =IFERROR( IF(LEN(CI20)=0, "", IF(EXACT(CI20,CH20), "", " - xform/" & CH20 & "/" & CI20 & "/ # " & "【" & CJ20 & "】 ==> " & CL20 & "： " & CK20 & " [" & CH20 & "]")), "") | CP20: =ROW() - 4 -> 16 | CQ20: l | CR20: l | CS20: x | CT20: ㄌ | CU20: 聲 | CV20: 1 | CX20: =_xlfn.CONCAT(" - xform/^", CR20, "/", CR20, "/", " # ", CT20, " [", CQ20, "]" ) -> - xform/^l/l/ # ㄌ [l] | CY20: =ROW() - 4 -> 16
BN21: =ROW() - 4 -> 17 | BO21: j(i) | BP21: J | BQ21: R | BR21: ㆢ | BS21: 聲 | BT21: =LEN(BO21) -> 4 | BV21: =" """ & BQ21 & """: { commit: """ & BR21 & """ }" & " # " & "/" & BO22 & "/ ==> " & BP21 -> "R": { commit: "ㆢ" } # /ts(i)/ ==> J | BX21: =ROW() - 4 -> 17 | CF21: =IFERROR( IF(LEN(BZ21)=0, "", IF(BZ21=BY21, "", " - xform/" & BY21 & "/" & BZ21 & "/ # " & "【" & CA21 & "】 ==> " & CC21 & "： " & CB21 & " [" & BY21 & "]")), "") | CG21: =ROW() - 4 -> 17 | CO21: =IFERROR( IF(LEN(CI21)=0, "", IF(EXACT(CI21,CH21), "", " - xform/" & CH21 & "/" & CI21 & "/ # " & "【" & CJ21 & "】 ==> " & CL21 & "： " & CK21 & " [" & CH21 & "]")), "") | CP21: =ROW() - 4 -> 17 | CQ21: g | CR21: Ğ | CS21: E | CT21: ㆣ | CU21: 聲 | CV21: 1 | CX21: =_xlfn.CONCAT(" - xform/^", CR21, "/", CR21, "/", " # ", CT21, " [", CQ21, "]" ) -> - xform/^Ğ/Ğ/ # ㆣ [g] | CY21: =ROW() - 4 -> 17
B22: a | C22: b | D22: c | E22: d | F22: e | G22: f | H22: g | I22: h | J22: i | K22: j | L22: k | M22: l | N22: m | O22: n | P22: o | Q22: p | R22: q | S22: r | T22: s | U22: t | V22: u | W22: v | X22: w | Y22: x | Z22: y | AA22: z | AL22: a | AM22: b | AN22: c | AO22: d | AP22: e | AQ22: f | AR22: g | AS22: h | AT22: i | AU22: j | AV22: k | AW22: l | AX22: m | AY22: n | AZ22: o | BA22: p | BB22: q | BC22: r | BD22: s | BE22: t | BF22: u | BG22: v | BH22: w | BI22: x | BJ22: y | BK22: z | BN22: =ROW() - 4 -> 18 | BO22: ts(i) | BP22: j | BQ22: r | BR22: ㄐ | BS22: 聲 | BT22: =LEN(BO22) -> 5 | BV22: =" """ & BQ22 & """: { commit: """ & BR22 & """ }" & " # " & "/" & BO23 & "/ ==> " & BP22 -> "r": { commit: "ㄐ" } # /tsh(i)/ ==> j | BX22: =ROW() - 4 -> 18 | CF22: =IFERROR( IF(LEN(BZ22)=0, "", IF(BZ22=BY22, "", " - xform/" & BY22 & "/" & BZ22 & "/ # " & "【" & CA22 & "】 ==> " & CC22 & "： " & CB22 & " [" & BY22 & "]")), "") | CG22: =ROW() - 4 -> 18 | CO22: =IFERROR( IF(LEN(CI22)=0, "", IF(EXACT(CI22,CH22), "", " - xform/" & CH22 & "/" & CI22 & "/ # " & "【" & CJ22 & "】 ==> " & CL22 & "： " & CK22 & " [" & CH22 & "]")), "") | CP22: =ROW() - 4 -> 18 | CQ22: k | CR22: g | CS22: e | CT22: ㄍ | CU22: 聲 | CV22: 1 | CX22: =_xlfn.CONCAT(" - xform/^", CR22, "/", CR22, "/", " # ", CT22, " [", CQ22, "]" ) -> - xform/^g/g/ # ㄍ [k] | CY22: =ROW() - 4 -> 18
B23: =IF( ISNUMBER( FIND(B22, _xlfn.CONCAT($D$18:$BK$18)) ), FIND(B22, _xlfn.CONCAT($D$18:$BK$18)), "V") -> 22 | C23: =IF( ISNUMBER( FIND(C22, _xlfn.CONCAT($D$18:$BK$18)) ), FIND(C22, _xlfn.CONCAT($D$18:$BK$18)), "V") -> 2 | D23: =IF( ISNUMBER( FIND(D22, _xlfn.CONCAT($D$18:$BK$18)) ), FIND(D22, _xlfn.CONCAT($D$18:$BK$18)), "V") -> 15 | E23: =IF( ISNUMBER( FIND(E22, _xlfn.CONCAT($D$18:$BK$18)) ), FIND(E22, _xlfn.CONCAT($D$18:$BK$18)), "V") -> 5 | F23: =IF( ISNUMBER( FIND(F22, _xlfn.CONCAT($D$18:$BK$18)) ), FIND(F22, _xlfn.CONCAT($D$18:$BK$18)), "V") -> 26 | G23: =IF( ISNUMBER( FIND(G22, _xlfn.CONCAT($D$18:$BK$18)) ), FIND(G22, _xlfn.CONCAT($D$18:$BK$18)), "V") -> 32 | H23: =IF( ISNUMBER( FIND(H22, _xlfn.CONCAT($D$18:$BK$18)) ), FIND(H22, _xlfn.CONCAT($D$18:$BK$18)), "V") -> 10 | I23: =IF( ISNUMBER( FIND(I22, _xlfn.CONCAT($D$18:$BK$18)) ), FIND(I22, _xlfn.CONCAT($D$18:$BK$18)), "V") -> 21 | ... AA23: =IF( ISNUMBER( FIND(AA22, _xlfn.CONCAT($D$18:$BK$18)) ), FIND(AA22, _xlfn.CONCAT($D$18:$BK$18)), "V") -> 14 | AL23: =IF( ISNUMBER( FIND(AL22, _xlfn.CONCAT($D$18:$BK$18)) ), FIND(AL22, _xlfn.CONCAT($D$18:$BK$18)), "V") -> 22 | AM23: =IF( ISNUMBER( FIND(AM22, _xlfn.CONCAT($D$18:$BK$18)) ), FIND(AM22, _xlfn.CONCAT($D$18:$BK$18)), "V") -> 2 | AN23: =IF( ISNUMBER( FIND(AN22, _xlfn.CONCAT($D$18:$BK$18)) ), FIND(AN22, _xlfn.CONCAT($D$18:$BK$18)), "V") -> 15 | AO23: =IF( ISNUMBER( FIND(AO22, _xlfn.CONCAT($D$18:$BK$18)) ), FIND(AO22, _xlfn.CONCAT($D$18:$BK$18)), "V") -> 5 | AP23: =IF( ISNUMBER( FIND(AP22, _xlfn.CONCAT($D$18:$BK$18)) ), FIND(AP22, _xlfn.CONCAT($D$18:$BK$18)), "V") -> 26 | AQ23: =IF( ISNUMBER( FIND(AQ22, _xlfn.CONCAT($D$18:$BK$18)) ), FIND(AQ22, _xlfn.CONCAT($D$18:$BK$18)), "V") -> 32 | AR23: =IF( ISNUMBER( FIND(AR22, _xlfn.CONCAT($D$18:$BK$18)) ), FIND(AR22, _xlfn.CONCAT($D$18:$BK$18)), "V") -> 10 | AS23: =IF( ISNUMBER( FIND(AS22, _xlfn.CONCAT($D$18:$BK$18)) ), FIND(AS22, _xlfn.CONCAT($D$18:$BK$18)), "V") -> 21 | ... BK23: =IF( ISNUMBER( FIND(BK22, _xlfn.CONCAT($D$18:$BK$18)) ), FIND(BK22, _xlfn.CONCAT($D$18:$BK$18)), "V") -> 14 | BN23: =ROW() - 4 -> 19 | BO23: tsh(i) | BP23: C | BQ23: f | BR23: ㄑ | BS23: 聲 | BT23: =LEN(BO23) -> 6 | BV23: =" """ & BQ23 & """: { commit: """ & BR23 & """ }" & " # " & "/" & BO24 & "/ ==> " & BP23 -> "f": { commit: "ㄑ" } # /s(i)/ ==> C | BX23: =ROW() - 4 -> 19 | CF23: =IFERROR( IF(LEN(BZ23)=0, "", IF(BZ23=BY23, "", " - xform/" & BY23 & "/" & BZ23 & "/ # " & "【" & CA23 & "】 ==> " & CC23 & "： " & CB23 & " [" & BY23 & "]")), "") | CG23: =ROW() - 4 -> 19 | CO23: =IFERROR( IF(LEN(CI23)=0, "", IF(EXACT(CI23,CH23), "", " - xform/" & CH23 & "/" & CI23 & "/ # " & "【" & CJ23 & "】 ==> " & CL23 & "： " & CK23 & " [" & CH23 & "]")), "") | CP23: =ROW() - 4 -> 19 | CQ23: j | CR23: Z | CS23: Y | CT23: ㆡ | CU23: 聲 | CV23: 1 | CX23: =_xlfn.CONCAT(" - xform/^", CR23, "/", CR23, "/", " # ", CT23, " [", CQ23, "]" ) -> - xform/^Z/Z/ # ㆡ [j] | CY23: =ROW() - 4 -> 19
B24: =IF( ISNUMBER( FIND(B22, _xlfn.CONCAT($D$18:$BK$18)) ), "X", B22) -> X | C24: =IF( ISNUMBER( FIND(C22, _xlfn.CONCAT($D$18:$BK$18)) ), "X", C22) -> X | D24: =IF( ISNUMBER( FIND(D22, _xlfn.CONCAT($D$18:$BK$18)) ), "X", D22) -> X | E24: =IF( ISNUMBER( FIND(E22, _xlfn.CONCAT($D$18:$BK$18)) ), "X", E22) -> X | F24: =IF( ISNUMBER( FIND(F22, _xlfn.CONCAT($D$18:$BK$18)) ), "X", F22) -> X | G24: =IF( ISNUMBER( FIND(G22, _xlfn.CONCAT($D$18:$BK$18)) ), "X", G22) -> X | H24: =IF( ISNUMBER( FIND(H22, _xlfn.CONCAT($D$18:$BK$18)) ), "X", H22) -> X | I24: =IF( ISNUMBER( FIND(I22, _xlfn.CONCAT($D$18:$BK$18)) ), "X", I22) -> X | ... AA24: =IF( ISNUMBER( FIND(AA22, _xlfn.CONCAT($D$18:$BK$18)) ), "X", AA22) -> X | AL24: =IF( ISNUMBER( FIND(AL22, _xlfn.CONCAT($D$18:$BK$18)) ), "X", AL22) -> X | AM24: =IF( ISNUMBER( FIND(AM22, _xlfn.CONCAT($D$18:$BK$18)) ), "X", AM22) -> X | AN24: =IF( ISNUMBER( FIND(AN22, _xlfn.CONCAT($D$18:$BK$18)) ), "X", AN22) -> X | AO24: =IF( ISNUMBER( FIND(AO22, _xlfn.CONCAT($D$18:$BK$18)) ), "X", AO22) -> X | AP24: =IF( ISNUMBER( FIND(AP22, _xlfn.CONCAT($D$18:$BK$18)) ), "X", AP22) -> X | AQ24: =IF( ISNUMBER( FIND(AQ22, _xlfn.CONCAT($D$18:$BK$18)) ), "X", AQ22) -> X | AR24: =IF( ISNUMBER( FIND(AR22, _xlfn.CONCAT($D$18:$BK$18)) ), "X", AR22) -> X | AS24: =IF( ISNUMBER( FIND(AS22, _xlfn.CONCAT($D$18:$BK$18)) ), "X", AS22) -> X | ... BK24: =IF( ISNUMBER( FIND(BK22, _xlfn.CONCAT($D$18:$BK$18)) ), "X", BK22) -> X | BN24: =ROW() - 4 -> 20 | BO24: s(i) | BP24: S | BQ24: v | BR24: ㄒ | BS24: 聲 | BT24: =LEN(BO24) -> 4 | BV24: =" """ & BQ24 & """: { commit: """ & BR24 & """ }" & " # " & "/" & BO25 & "/ ==> " & BP24 -> "v": { commit: "ㄒ" } # /h/ ==> S | BX24: =ROW() - 4 -> 20 | CF24: =IFERROR( IF(LEN(BZ24)=0, "", IF(BZ24=BY24, "", " - xform/" & BY24 & "/" & BZ24 & "/ # " & "【" & CA24 & "】 ==> " & CC24 & "： " & CB24 & " [" & BY24 & "]")), "") | CG24: =ROW() - 4 -> 20 | CO24: =IFERROR( IF(LEN(CI24)=0, "", IF(EXACT(CI24,CH24), "", " - xform/" & CH24 & "/" & CI24 & "/ # " & "【" & CJ24 & "】 ==> " & CL24 & "： " & CK24 & " [" & CH24 & "]")), "") | CP24: =ROW() - 4 -> 20 | CQ24: s | CR24: s | CS24: n | CT24: ㄙ | CU24: 聲 | CV24: 1 | CX24: =_xlfn.CONCAT(" - xform/^", CR24, "/", CR24, "/", " # ", CT24, " [", CQ24, "]" ) -> - xform/^s/s/ # ㄙ [s] | CY24: =ROW() - 4 -> 20
BN25: =ROW() - 4 -> 21 | BO25: h | BP25: h | BQ25: c | BR25: ㄏ | BS25: 聲 | BT25: =LEN(BO25) -> 1 | BV25: =" """ & BQ25 & """: { commit: """ & BR25 & """ }" & " # " & "/" & BO26 & "/ ==> " & BP25 -> "c": { commit: "ㄏ" } # /a/ ==> h | BX25: =ROW() - 4 -> 21 | CF25: =IFERROR( IF(LEN(BZ25)=0, "", IF(BZ25=BY25, "", " - xform/" & BY25 & "/" & BZ25 & "/ # " & "【" & CA25 & "】 ==> " & CC25 & "： " & CB25 & " [" & BY25 & "]")), "") | CG25: =ROW() - 4 -> 21 | CO25: =IFERROR( IF(LEN(CI25)=0, "", IF(EXACT(CI25,CH25), "", " - xform/" & CH25 & "/" & CI25 & "/ # " & "【" & CJ25 & "】 ==> " & CL25 & "： " & CK25 & " [" & CH25 & "]")), "") | CP25: =ROW() - 4 -> 21 | CQ25: h | CR25: h | CS25: c | CT25: ㄏ | CU25: 聲 | CV25: 1 | CX25: =_xlfn.CONCAT(" - xform/^", CR25, "/", CR25, "/", " # ", CT25, " [", CQ25, "]" ) -> - xform/^h/h/ # ㄏ [h] | CY25: =ROW() - 4 -> 21
BN26: =ROW() - 4 -> 22 | BO26: a | BP26: a | BQ26: 8 | BR26: ㄚ | BT26: =LEN(BO26) -> 1 | BV26: =" """ & BQ26 & """: { commit: """ & BR26 & """ }" & " # " & "/" & BO27 & "/ ==> " & BP26 -> "8": { commit: "ㄚ" } # /i/ ==> a | BX26: =ROW() - 4 -> 22 | CF26: =IFERROR( IF(LEN(BZ26)=0, "", IF(BZ26=BY26, "", " - xform/" & BY26 & "/" & BZ26 & "/ # " & "【" & CA26 & "】 ==> " & CC26 & "： " & CB26 & " [" & BY26 & "]")), "") | CG26: =ROW() - 4 -> 22 | CO26: =IFERROR( IF(LEN(CI26)=0, "", IF(EXACT(CI26,CH26), "", " - xform/" & CH26 & "/" & CI26 & "/ # " & "【" & CJ26 & "】 ==> " & CL26 & "： " & CK26 & " [" & CH26 & "]")), "") | CP26: =ROW() - 4 -> 22 | CX26: =IFERROR( IF(LEN(CR26)=0, "", IF(EXACT(CR26,CQ26), "", " - xform/^" & CQ26 & "/" & CR26 & "/ # " & "【" & CS26 & "】 ==> " & CU26 & "： " & CT26 & " [" & CQ26 & "]")), "") | CY26: =ROW() - 4 -> 22
BN27: =ROW() - 4 -> 23 | BO27: i | BP27: i | BQ27: u | BR27: ㄧ | BT27: =LEN(BO27) -> 1 | BV27: =" """ & BQ27 & """: { commit: """ & BR27 & """ }" & " # " & "/" & BO28 & "/ ==> " & BP27 -> "u": { commit: "ㄧ" } # /ir/ ==> i | BX27: =ROW() - 4 -> 23 | CF27: =IFERROR( IF(LEN(BZ27)=0, "", IF(BZ27=BY27, "", " - xform/" & BY27 & "/" & BZ27 & "/ # " & "【" & CA27 & "】 ==> " & CC27 & "： " & CB27 & " [" & BY27 & "]")), "") | CG27: =ROW() - 4 -> 23 | CO27: =IFERROR( IF(LEN(CI27)=0, "", IF(EXACT(CI27,CH27), "", " - xform/" & CH27 & "/" & CI27 & "/ # " & "【" & CJ27 & "】 ==> " & CL27 & "： " & CK27 & " [" & CH27 & "]")), "") | CP27: =ROW() - 4 -> 23 | CX27: =IFERROR( IF(LEN(CR27)=0, "", IF(EXACT(CR27,CQ27), "", " - xform/^" & CQ27 & "/" & CR27 & "/ # " & "【" & CS27 & "】 ==> " & CU27 & "： " & CT27 & " [" & CQ27 & "]")), "") | CY27: =ROW() - 4 -> 23
BN28: =ROW() - 4 -> 24 | BO28: ir | BP28: w | BQ28: K | BR28: ㆨ | BT28: =LEN(BO28) -> 2 | BV28: =" """ & BQ28 & """: { commit: """ & BR28 & """ }" & " # " & "/" & BO29 & "/ ==> " & BP28 -> "K": { commit: "ㆨ" } # /u/ ==> w | BX28: =ROW() - 4 -> 24 | CG28: =ROW() - 4 -> 24 | CP28: =ROW() - 4 -> 24 | CX28: =IFERROR( IF(LEN(CR28)=0, "", IF(EXACT(CR28,CQ28), "", " - xform/^" & CQ28 & "/" & CR28 & "/ # " & "【" & CS28 & "】 ==> " & CU28 & "： " & CT28 & " [" & CQ28 & "]")), "") | CY28: =ROW() - 4 -> 24
BN29: =ROW() - 4 -> 25 | BO29: u | BP29: u | BQ29: j | BR29: ㄨ | BT29: =LEN(BO29) -> 1 | BV29: =" """ & BQ29 & """: { commit: """ & BR29 & """ }" & " # " & "/" & BO30 & "/ ==> " & BP29 -> "j": { commit: "ㄨ" } # /e/ ==> u | BX29: =ROW() - 4 -> 25 | CG29: =ROW() - 4 -> 25 | CP29: =ROW() - 4 -> 25 | CX29: =IFERROR( IF(LEN(CR29)=0, "", IF(EXACT(CR29,CQ29), "", " - xform/^" & CQ29 & "/" & CR29 & "/ # " & "【" & CS29 & "】 ==> " & CU29 & "： " & CT29 & " [" & CQ29 & "]")), "") | CY29: =ROW() - 4 -> 25
BN30: =ROW() - 4 -> 26 | BO30: e | BP30: e | BQ30: , | BR30: ㆤ | BT30: =LEN(BO30) -> 1 | BV30: =" """ & BQ30 & """: { commit: """ & BR30 & """ }" & " # " & "/" & BO31 & "/ ==> " & BP30 -> ",": { commit: "ㆤ" } # /oo/ ==> e | BX30: =ROW() - 4 -> 26 | CG30: =ROW() - 4 -> 26 | CP30: =ROW() - 4 -> 26 | CX30: =IFERROR( IF(LEN(CR30)=0, "", IF(EXACT(CR30,CQ30), "", " - xform/^" & CQ30 & "/" & CR30 & "/ # " & "【" & CS30 & "】 ==> " & CU30 & "： " & CT30 & " [" & CQ30 & "]")), "") | CY30: =ROW() - 4 -> 26
BN31: =ROW() - 4 -> 27 | BO31: oo | BP31: O | BQ31: i | BR31: ㆦ | BT31: =LEN(BO31) -> 2 | BV31: =" """ & BQ31 & """: { commit: """ & BR31 & """ }" & " # " & "/" & BO32 & "/ ==> " & BP31 -> "i": { commit: "ㆦ" } # /o/ ==> O | BX31: =ROW() - 4 -> 27 | CG31: =ROW() - 4 -> 27 | CP31: =ROW() - 4 -> 27 | CX31: =IFERROR( IF(LEN(CR31)=0, "", IF(EXACT(CR31,CQ31), "", " - xform/^" & CQ31 & "/" & CR31 & "/ # " & "【" & CS31 & "】 ==> " & CU31 & "： " & CT31 & " [" & CQ31 & "]")), "") | CY31: =ROW() - 4 -> 27
BN32: =ROW() - 4 -> 28 | BO32: o | BP32: ə | BQ32: k | BR32: ㄜ | BS32: 韻 | BT32: =LEN(BO32) -> 1 | BX32: =ROW() - 4 -> 28 | CG32: =ROW() - 4 -> 28 | CP32: =ROW() - 4 -> 28 | CY32: =ROW() - 4 -> 28
B33: 使用按鍵設定 | BN33: =ROW() - 4 -> 29 | BO33: ai | BP33: I | BQ33: 9 | BR33: ㄞ | BS33: 韻尾 | BT33: =LEN(BO33) -> 2 | BV33: =" """ & BQ33 & """: { commit: """ & BR33 & """ }" & " # " & "/" & BO33 & "/ ==> " & BP33 -> "9": { commit: "ㄞ" } # /ai/ ==> I | BX33: =ROW() - 4 -> 29 | CG33: =ROW() - 4 -> 29 | CP33: =ROW() - 4 -> 29 | CX33: =IF(CU33=0, "", " - xform/^" & CU33 & "(?!\d)/" & CQ33 & "/ # " & CR33 & " [ " & CU33 & "]") | CY33: =ROW() - 4 -> 29
B34: =_xlfn.CONCAT(" alphabet: """,D19:BC19, BD19:BJ19,"""") -> alphabet: "!1qa2wsxEedGYyhnRrfvc8uKj,ik9l*UJ<I(Lm/pM0;Oobtgz7-="5346][" | BN34: =ROW() - 4 -> 30 | BO34: au | BP34: U | BQ34: l | BR34: ㄠ | BS34: 韻尾 | BT34: =LEN(BO34) -> 2 | BV34: =" """ & BQ34 & """: { commit: """ & BR34 & """ }" & " # " & "/" & BO34 & "/ ==> " & BP34 -> "l": { commit: "ㄠ" } # /au/ ==> U | BX34: =ROW() - 4 -> 30 | CG34: =ROW() - 4 -> 30 | CP34: =ROW() - 4 -> 30 | CX34: =IF(CU34=0, "", " - xform/^" & CU34 & "(?!\d)/" & CQ34 & "/ # " & CR34 & " [ " & CU34 & "]") | CY34: =ROW() - 4 -> 30
B35: =_xlfn.CONCAT(" initials: """,D19:BC19, """") -> initials: "!1qa2wsxEedGYyhnRrfvc8uKj,ik9l*UJ<I(Lm/pM0;Oobtgz7-=" | BN35: =ROW() - 4 -> 31 | BO35: ann | BP35: D | BQ35: * | BR35: ㆩ | BS35: 韻尾 | BT35: =LEN(BO35) -> 3 | BV35: =" """ & BQ35 & """: { commit: """ & BR35 & """ }" & " # " & "/" & BO35 & "/ ==> " & BP35 -> "*": { commit: "ㆩ" } # /ann/ ==> D | BX35: =ROW() - 4 -> 31 | CG35: =ROW() - 4 -> 31 | CP35: =ROW() - 4 -> 31 | CX35: =IF(CU35=0, "", " - xform/^" & CU35 & "(?!\d)/" & CQ35 & "/ # " & CR35 & " [ " & CU35 & "]") | CY35: =ROW() - 4 -> 31
B36: =_xlfn.CONCAT(" finals: """,BD19:BJ19,"""") -> finals: ""5346][" | BN36: =ROW() - 4 -> 32 | BO36: inn | BP36: f | BQ36: U | BR36: ㆪ | BS36: 韻尾 | BT36: =LEN(BO36) -> 3 | BV36: =" """ & BQ36 & """: { commit: """ & BR36 & """ }" & " # " & "/" & BO36 & "/ ==> " & BP36 -> "U": { commit: "ㆪ" } # /inn/ ==> f | BX36: =ROW() - 4 -> 32 | CG36: =ROW() - 4 -> 32 | CP36: =ROW() - 4 -> 32 | CX36: =IF(CU36=0, "", " - xform/^" & CU36 & "(?!\d)/" & CQ36 & "/ # " & CR36 & " [ " & CU36 & "]") | CY36: =ROW() - 4 -> 32
BN37: =ROW() - 4 -> 33 | BO37: unn | BP37: q | BQ37: J | BR37: ㆫ | BS37: 韻尾 | BT37: =LEN(BO37) -> 3 | BV37: =" """ & BQ37 & """: { commit: """ & BR37 & """ }" & " # " & "/" & BO37 & "/ ==> " & BP37 -> "J": { commit: "ㆫ" } # /unn/ ==> q | BX37: =ROW() - 4 -> 33 | CG37: =ROW() - 4 -> 33 | CP37: =ROW() - 4 -> 33 | CX37: =IF(CU37=0, "", " - xform/^" & CU37 & "(?!\d)/" & CQ37 & "/ # " & CR37 & " [ " & CU37 & "]") | CY37: =ROW() - 4 -> 33
AF38: =_xlfn.CONCAT(D18:X18) -> BbpmdtnlĞgkŋZzcsJjCSh | BN38: =ROW() - 4 -> 34 | BO38: enn | BP38: r | BQ38: < | BR38: ㆥ | BS38: 韻尾 | BT38: =LEN(BO38) -> 3 | BV38: =" """ & BQ38 & """: { commit: """ & BR38 & """ }" & " # " & "/" & BO38 & "/ ==> " & BP38 -> "<": { commit: "ㆥ" } # /enn/ ==> r | BX38: =ROW() - 4 -> 34 | CG38: =ROW() - 4 -> 34 | CP38: =ROW() - 4 -> 34 | CX38: =IF(CU38=0, "", " - xform/^" & CU38 & "(?!\d)/" & CQ38 & "/ # " & CR38 & " [ " & CU38 & "]") | CY38: =ROW() - 4 -> 34
B39: 拚音碼與鍵盤對映 (speller) | BN39: =ROW() - 4 -> 35 | BO39: onn | BP39: v | BQ39: I | BR39: ㆧ | BS39: 韻尾 | BT39: =LEN(BO39) -> 3 | BV39: =" """ & BQ39 & """: { commit: """ & BR39 & """ }" & " # " & "/" & BO39 & "/ ==> " & BP39 -> "I": { commit: "ㆧ" } # /onn/ ==> v | BX39: =ROW() - 4 -> 35 | CG39: =ROW() - 4 -> 35 | CP39: =ROW() - 4 -> 35 | CX39: =IF(CU39=0, "", " - xform/^" & CU39 & "(?!\d)/" & CQ39 & "/ # " & CR39 & " [ " & CU39 & "]") | CY39: =ROW() - 4 -> 35
B40: # 設定「字典編碼」與「鍵盤位置」的對映關係：字典檔案中，漢字的 '拼音字母' ，轉成 '字典編碼' ，並與‘鍵盤位置’建立對映關聯 | BN40: =ROW() - 4 -> 36 | BO40: ainn | BP40: x | BQ40: ( | BR40: ㆮ | BS40: 韻 | BT40: =LEN(BO40) -> 4 | BV40: =" """ & BQ40 & """: { commit: """ & BR40 & """ }" & " # " & "/" & BO40 & "/ ==> " & BP40 -> "(": { commit: "ㆮ" } # /ainn/ ==> x | BX40: =ROW() - 4 -> 36 | CG40: =ROW() - 4 -> 36 | CP40: =ROW() - 4 -> 36 | CX40: =IF(CU40=0, "", " - xform/^" & CU40 & "(?!\d)/" & CQ40 & "/ # " & CR40 & " [ " & CU40 & "]") | CY40: =ROW() - 4 -> 36
...

Sheet  台語音標【xlit解析】
A1: huan_ciat_tps | BL1: 序號 | BM1: {=TRANSPOSE(A3:A6)} -> 台羅拼音 | BN1: 字典編碼 | BO1: 鍵盤按鍵 | BP1: 注音符號 | BR1: 序號 | BS1: 台羅拼音 | BT1: 字典編碼 | BU1: 按鍵 | BV1: 注音符號 | BX1: 序號 | BY1: 台羅拼音 | BZ1: 字典編碼 | CA1: 按鍵 | CB1: 注音符號 | CD1: 序號 | CE1: 台羅拼音 | CF1: 字典編碼 | CG1: 按鍵 | CH1: 注音符號
C2: =COLUMN() -2 -> 1 | D2: =COLUMN() -2 -> 2 | E2: =COLUMN() -2 -> 3 | F2: =COLUMN() -2 -> 4 | G2: =COLUMN() -2 -> 5 | H2: =COLUMN() -2 -> 6 | I2: =COLUMN() -2 -> 7 | J2: =COLUMN() -2 -> 8 | ... BJ2: =COLUMN() -2 -> 60 | BL2: {=TRANSPOSE(C2:BJ6)} -> 1 | BM2: b | BN2: b | BO2: ! | BP2: ㆠ | BR2: 1 | BS2: b | BT2: b | BU2: ! | BV2: ㆠ | BX2: 1 | BY2: a | BZ2: a | CA2: 8 | CB2: ㄚ | CD2: 1 | CE2: 1 | CF2: 1 | CG2: : | CH2: 一
A3: 台羅拼音 | C3: b | D3: p | E3: ph | F3: m | G3: n | H3: t | I3: th | J3: l | K3: g | L3: k | M3: kh | N3: ng | O3: j | P3: z(ts) | Q3: c(tsh) | R3: s | S3: h | T3: j(i) | U3: z(i) | V3: c(i) | W3: s(i) | X3: a | Y3: i | Z3: ir | AA3: u | AB3: e | AC3: oo | AD3: o | AE3: -m | AF3: -n | AG3: -ng | AH3: -p | AI3: -t | AJ3: -k | AK3: -h | AL3: ai | AM3: au | AN3: am | AO3: an | AP3: ang | AQ3: om | AR3: ong | AS3: =_xlfn.CONCAT("a", _xlfn.UNICHAR(HEX2DEC(RIGHT("U+207F",4)))) -> aⁿ | AT3: =_xlfn.CONCAT("i", _xlfn.UNICHAR(HEX2DEC(RIGHT("U+207F",4)))) -> iⁿ | AU3: =_xlfn.CONCAT("u", _xlfn.UNICHAR(HEX2DEC(RIGHT("U+207F",4)))) -> uⁿ | AV3: =_xlfn.CONCAT("e", _xlfn.UNICHAR(HEX2DEC(RIGHT("U+207F",4)))) -> eⁿ | AW3: =_xlfn.CONCAT("o", _xlfn.UNICHAR(HEX2DEC(RIGHT("U+207F",4)))) -> oⁿ | AX3: =_xlfn.CONCAT("ai", _xlfn.UNICHAR(HEX2DEC(RIGHT("U+207F",4)))) -> aiⁿ | AY3: =_xlfn.CONCAT("au", _xlfn.UNICHAR(HEX2DEC(RIGHT("U+207F",4)))) -> auⁿ | AZ3: =_xlfn.UNICHAR(HEX2DEC(RIGHT("U+207F",4))) -> ⁿ | BA3: Ø | BB3: 1 | BC3: 7 | BD3: 3 | BE3: 2 | BF3: 5 | BG3: 8 | BH3: 4 | BI3: 0 | BL3: 2 | BM3: p | BN3: p | BO3: 1 | BP3: ㄅ | BR3: 2 | BS3: p | BT3: p | BU3: 1 | BV3: ㄅ | BX3: 2 | BY3: i | BZ3: i | CA3: u | CB3: ㄧ | CD3: 2 | CE3: 7 | CF3: 7 | CG3: 5 | CH3: 七
A4: 字典編碼 | C4: b | D4: p | E4: P | F4: m | G4: n | H4: t | I4: T | J4: l | K4: g | L4: k | M4: K | N4: ŋ | O4: j | P4: z | Q4: c | R4: s | S4: h | T4: J | U4: Z | V4: C | W4: S | X4: a | Y4: i | Z4: w | AA4: u | AB4: e | AC4: O | AD4: ə | AE4: M | AF4: N | AG4: G | AH4: R | AI4: F | AJ4: Q | AK4: V | AL4: I | AM4: U | AN4: Y | AO4: @ | AP4: A | AQ4: W | AR4: H | AS4: d | AT4: f | AU4: q | AV4: r | AW4: v | AX4: x | AY4: y | AZ4: L | BA4: Ø | BB4: 1 | BC4: 7 | BD4: 3 | BE4: 2 | BF4: 5 | BG4: 8 | BH4: 4 | BI4: & | BL4: 3 | BM4: ph | BN4: P | BO4: q | BP4: ㄆ | BR4: 3 | BS4: ph | BT4: P | BU4: q | BV4: ㄆ | BX4: 3 | BY4: ir | BZ4: w | CA4: K | CB4: ㆨ | CD4: 3 | CE4: 3 | CF4: 3 | CG4: 3 | CH4: 三
A5: 鍵盤按鍵 | C5: ! | D5: 1 | E5: q | F5: a | G5: s | H5: 2 | I5: w | J5: x | K5: E | L5: e | M5: d | N5: N | O5: Y | P5: y | Q5: h | R5: n | S5: c | T5: R | U5: r | V5: f | W5: v | X5: 8 | Y5: u | Z5: K | AA5: j | AB5: , | AC5: i | AD5: k | AE5: m | AF5: p | AG5: / | AH5: b | AI5: t | AJ5: g | AK5: z | AL5: 9 | AM5: l | AN5: M | AO5: 0 | AP5: ; | AQ5: O | AR5: o | AS5: * | AT5: U | AU5: J | AV5: < | AW5: I | AX5: ( | AY5: L | AZ5: - | BA5: = | BB5: " | BC5: 5 | BD5: 3 | BE5: 4 | BF5: 6 | BG5: ] | BH5: [ | BI5: 7 | BL5: 4 | BM5: m | BN5: m | BO5: a | BP5: ㄇ | BR5: 4 | BS5: m | BT5: m | BU5: a | BV5: ㄇ | BX5: 4 | BY5: u | BZ5: u | CA5: j | CB5: ㄨ | CD5: 4 | CE5: 2 | CF5: 2 | CG5: 4 | CH5: 二
