Workbook

Sheet 【聲】聲母對照表
A1: 識別號 | B1: 十五音 | C1: 漢字例 | D1: 國際音標 | E1: 方音符號 | F1: 台語音標 | G1: 台羅拼音 | H1: 注音二式 | I1: 白話字 | J1: 閩拼方案 | K1: 備註
A2: 1 | B2: 柳 | C2: 理 | D2: l | E2: ㄌ | F2: l | G2: l | H2: l | I2: l | J2: l
A3: 2 | B3: 邊 | C3: 比 | D3: p | E3: ㄅ | F3: p | G3: p | H3: b | I3: p | J3: b
A4: 3 | B4: 求 | C4: 己 | D4: k | E4: ㄍ | F4: k | G4: k | H4: g | I4: k | J4: g
A5: 4 | B5: 去 | C5: 起 | D5: kʰ | E5: ㄎ | F5: kh | G5: kh | H5: k | I5: kh | J5: k
A6: 5 | B6: 地 | C6: 底 | D6: t | E6: ㄉ | F6: t | G6: t | H6: d | I6: t | J6: d
A7: 6 | B7: 頗 | C7: 鄙 | D7: pʰ | E7: ㄆ | F7: ph | G7: ph | H7: p | I7: ph | J7: p
A8: 7 | B8: 他 | C8: 恥 | D8: tʰ | E8: ㄊ | F8: th | G8: th | H8: t | I8: th | J8: t
A9: 8 | B9: 曾 | C9: 阻 | D9: ʦ | E9: ㄗ | F9: z | G9: ts | H9: z | I9: ch | J9: z
A10: 9 | B10: 入 | C10: 熱 | D10: ʣ | E10: ㆡ | F10: j | G10: j | H10: zz | I10: j | J10: zz
A11: 10 | B11: 時 | C11: 詞 | D11: s | E11: ㄙ | F11: s | G11: s | H11: s | I11: s | J11: s
A12: 11 | B12: 英 | C12: 以 | D12: ʔ | E12: Ø | F12: Ø | G12: Ø | H12: Ø | I12: Ø | J12: Ø
A13: 12 | B13: 門 | C13: 美 | D13: b | E13: ㆠ | F13: b | G13: b | H13: bb | I13: b | J13: bb
... A16: 15 | B16: 喜 | C16: 喜 | D16: h | E16: ㄏ | F16: h | G16: h | H16: h | I16: h | J16: h
A17: 16 | B17: 毛 | C17: 毛 | D17: m | E17: ㄇ | F17: m | G17: m | H17: m | I17: m | J17: bbn | K17: b/m 本不分，此處分門/毛
A18: 17 | B18: 耐 | C18: 耐 | D18: n | E18: ㄋ | F18: n | G18: n | H18: n | I18: n | J18: ln | K18: l/n 本不分，此處分柳/耐
A19: 18 | B19: 雅 | C19: 雅 | D19: ŋ | E19: ㄫ | F19: ng | G19: ng | H19: ng | I19: ng | J19: ggn | K19: g/ng 本不分，此處分語/雅
A20: 19 | B20: 入 | C20: 熱 | D20: ʥ | E20: ㆢ | F20: ji | G20: ji | H20: jji | I20: ji | J20: zzi | K20: ㆢ = ㆡㄧ
A21: 20 | B21: 曾 | C21: 止 | D21: ʨ | E21: ㄐ | F21: zi | G21: tsi | H21: ji | I21: chi | J21: zi | K21: ㄐ = ㄗㄧ
A22: 21 | B22: 出 | C22: 測 | D22: ʨʰ | E22: ㄑ | F22: ci | G22: tshi | H22: chi | I22: chhi | J22: ci | K22: ㄑ = ㄘㄧ
A23: 22 | B23: 時 | C23: 惜 | D23: ɕ | E23: ㄒ | F23: si | G23: si | H23: shi | I23: si | J23: si | K23: ㄒ = ㄙㄧ

Sheet 【韻】韻母對照表
A1: 識別號 | B1: 十五音 | C1: 漢字例 | D1: 方音符號 | E1: 國際音標 | F1: 台羅拼音 | G1: 台語音標 | H1: 閩拼方案 | I1: 白話字 | J1: 注音二式 | K1: 十五音序 | L1: 舒促聲 | M1: 十五音識別碼
A2: 1 | B2: 君 | C2: 汾 | D2: ㄨㄣ | E2: un | F2: un | G2: un | H2: un | I2: un | J2: un | K2: 1 | L2: 舒聲 | M2: 君舒
A3: 2 | B3: 君 | C3: 不 | D3: ㄨㆵ | E3: ut | F3: ut | G3: ut | H3: ut | I3: ut | J3: ut | K3: 1 | L3: 促聲 | M3: 君促
A4: 3 | B4: 堅 | C4: 掀 | D4: ㄧㄢ | E4: ɪan | F4: ian | G4: ian | H4: ian | I4: ian | J4: ian | K4: 2 | L4: 舒聲 | M4: 堅舒
A5: 4 | B5: 堅 | C5: 別 | D5: ㄧㄚㆵ | E5: ɪat̚ | F5: iat | G5: iat | H5: iat | I5: iat | J5: iat | K5: 2 | L5: 促聲 | M5: 堅促
A6: 5 | B6: 金 | C6: 深 | D6: ㄧㆬ | E6: im | F6: im | G6: im | H6: im | I6: im | J6: im | K6: 3 | L6: 舒聲 | M6: 金舒
A7: 6 | B7: 金 | C7: 蟄 | D7: 一ㆴ | E7: ip̚ | F7: ip | G7: ip | H7: ip | I7: ip | J7: ip | K7: 3 | L7: 促聲 | M7: 金促
A8: 7 | B8: 規 | C8: 歸 | D8: ㄨㄧ | E8: ui | F8: ui | G8: ui | H8: ui | I8: ui | J8: ui | K8: 4 | L8: 舒聲 | M8: 規舒
A9: 9 | B9: 嘉 | C9: 家 | D9: ㄝ | E9: ɛ | F9: ee | G9: ee | H9: e | J9: e | K9: 5 | L9: 舒聲 | M9: 嘉舒
A10: 10 | B10: 嘉 | C10: 八 | D10: ㄝㆷ | E10: ɛʔ | F10: eeh | G10: eeh | H10: eh | J10: eh | K10: 5 | L10: 促聲 | M10: 嘉促
A11: 11 | B11: 干 | C11: 蘭 | D11: ㄢ | E11: an | F11: an | G11: an | H11: an | I11: an | J11: an | K11: 6 | L11: 舒聲 | M11: 干舒
A12: 12 | B12: 干 | C12: 識 | D12: ㄚㆵ | E12: at̚ | F12: at | G12: at | H12: at | I12: at | J12: at | K12: 6 | L12: 促聲 | M12: 干促
A13: 13 | B13: 公 | C13: 風 | D13: ㆲ | E13: ɔŋ | F13: ong | G13: ong | H13: ong | I13: ong | J13: ong | K13: 7 | L13: 舒聲 | M13: 公舒
A14: 14 | B14: 公 | C14: 福 | D14: ㆦㆻ | E14: ɔk̚ | F14: ok | G14: ok | H14: ok | I14: ok | J14: ok | K14: 7 | L14: 促聲 | M14: 公促
A15: 15 | B15: 乖 | C15: 怪 | D15: ㄨㄞ | E15: uai | F15: uai | G15: uai | H15: uai | I15: oai | J15: uai | K15: 8 | L15: 舒聲 | M15: 乖舒
A16: 16 | B16: 乖 | C16: ◯ | D16: ㄨㄞㆷ | E16: uaiʔ | F16: uaih | G16: uaih | H16: uaih | I16: oaih | J16: uaih | K16: 8 | L16: 促聲 | M16: 乖促
A17: 17 | B17: 經 | C17: 情 | D17: ㄧㄥ | E17: ɪŋ | F17: ing | G17: ing | H17: ing | I17: eng | J17: ing | K17: 9 | L17: 舒聲 | M17: 經舒
A18: 18 | B18: 經 | C18: 益 | D18: ㄧㆻ | E18: ɪk̚ | F18: ik | G18: ik | H18: ik | I18: ek | J18: ik | K18: 9 | L18: 促聲 | M18: 經促
A19: 19 | B19: 觀 | C19: 猿 | D19: ㄨㄢ | E19: uan | F19: uan | G19: uan | H19: uan | I19: oan | J19: uan | K19: 10 | L19: 舒聲 | M19: 觀舒
A20: 20 | B20: 觀 | C20: 說 | D20: ㄨㄚㆵ | E20: uat̚ | F20: uat | G20: uat | H20: uat | I20: oat | J20: uat | K20: 10 | L20: 促聲 | M20: 觀促
A21: 21 | B21: 沽 | C21: 捕 | D21: ㆦ | E21: ɔ | F21: oo | G21: oo | H21: oo | I21: =_xlfn.CONCAT("o", _xlfn.UNICHAR(HEX2DEC(358))) -> o͘ | J21: oo | K21: 11 | L21: 舒聲 | M21: 沽舒
A22: 23 | B22: 嬌 | C22: 遙 | D22: ㄧㄠ | E22: ɪaʊ | F22: iau | G22: iau | H22: iao | I22: iau | J22: iau | K22: 12 | L22: 舒聲 | M22: 嬌舒
A23: 24 | B23: 嬌 | C23: 噭 | D23: ㄧㄠㆷ | E23: ɪaʊʔ | F23: iauh | G23: iauh | H23: iaoh | I23: iauh | J23: iauh | K23: 12 | L23: 促聲 | M23: 嬌促
A24: 25 | B24: 稽 | C24: 遞 | D24: ㆤ | E24: e | F24: e | G24: ei | H24: e | J24: e | K24: 13 | L24: 舒聲 | M24: 稽舒
A25: 27 | B25: 恭 | C25: 中 | D25: ㄧㆲ | E25: ɪɔŋ | F25: iong | G25: iong | H25: iong | I25: iong | J25: iong | K25: 14 | L25: 舒聲 | M25: 恭舒
A26: 28 | B26: 恭 | C26: 俗 | D26: ㄧㆦㆻ | E26: ɪɔk̚ | F26: iok | G26: iok | H26: iok | I26: iok | J26: iook | K26: 14 | L26: 促聲 | M26: 恭促
A27: 29 | B27: 高 | C27: 果 | D27: ㄜ | E27: o | F27: o | G27: o | H27: o | I27: o | J27: or | K27: 15 | L27: 舒聲 | M27: 高舒
A28: 30 | B28: 高 | C28: 卜 | D28: ㄜㆷ | E28: oʔ | F28: oh | G28: oh | H28: oh | I28: oh | J28: orh | K28: 15 | L28: 促聲 | M28: 高促
A29: 31 | B29: 皆 | C29: 埃 | D29: ㄞ | E29: aɪ | F29: ai | G29: ai | H29: ai | I29: ai | J29: ai | K29: 16 | L29: 舒聲 | M29: 皆舒
A30: 33 | B30: 巾 | C30: 恩 | D30: ㄧㄣ | E30: in | F30: in | G30: in | H30: in | I30: in | J30: in | K30: 17 | L30: 舒聲 | M30: 巾舒
A31: 34 | B31: 巾 | C31: 一 | D31: ㄧㆵ | E31: it̚ | F31: it | G31: it | H31: it | I31: it | J31: it | K31: 17 | L31: 促聲 | M31: 巾促
A32: 35 | B32: 姜 | C32: 將 | D32: ㄧㄤ | E32: ɪaŋ | F32: iang | G32: iang | H32: iang | I32: iang | J32: iang | K32: 18 | L32: 舒聲 | M32: 姜舒
A33: 36 | B33: 姜 | C33: 爆 | D33: ㄧㄚㆻ | E33: ɪak̚ | F33: iak | G33: iak | H33: iak | I33: iak | J33: iak | K33: 18 | L33: 促聲 | M33: 姜促
A34: 37 | B34: 甘 | C34: 堪 | D34: ㆰ | E34: am | F34: am | G34: am | H34: am | I34: am | J34: am | K34: 19 | L34: 舒聲 | M34: 甘舒
A35: 38 | B35: 甘 | C35: 答 | D35: ㄚㆴ | E35: ap̚ | F35: ap | G35: ap | H35: ap | I35: ap | J35: ap | K35: 19 | L35: 促聲 | M35: 甘促
A36: 39 | B36: 瓜 | C36: 花 | D36: ㄨㄚ | E36: ua | F36: ua | G36: ua | H36: ua | I36: oa | J36: ua | K36: 20 | L36: 舒聲 | M36: 瓜舒
... A57: 61 | B57: 更 | C57: 爭 | D57: ㆥ | E57: ẽ | F57: enn | G57: enn | H57: ne | I57: eⁿ | J57: enn | K57: 31 | L57: 舒聲 | M57: 更舒
A58: 62 | B58: 更 | C58: 挾 | D58: ㆥㆷ | G58: ehnn | I58: ehⁿ | J58: ennh | K58: 31 | L58: 促聲 | M58: 更促
A59: 63 | B59: 褌 | C59: 荒 | D59: ㄨㆪ | E59: ũĩ | F59: uinn | G59: uinn | H59: nui | I59: uiⁿ | J59: uinn | K59: 32 | L59: 舒聲 | M59: 褌舒
A60: 65 | B60: 茄 | C60: 少 | D60: ㄧㄜ | E60: ɪo | F60: io | G60: io | H60: io | I60: io | J60: ior | K60: 33 | L60: 舒聲 | M60: 茄舒
...

Sheet 韻母轉換規則
B1: ="(""" & _xlfn.TEXTJOIN(""",""",TRUE,F3:F86) & """)" -> ("niɑoh","nuɑih","iɑnɡ","iaoh","ionɡ","nɑeh","nɑoh","niɑh","niɑo","nooh","ɑeh","anɡ","ɑoh","iɑh","iɑk","iɑm","iɑn","iɑo","iɑp","iɑt","inɡ","ioh","iok","iuh","nɑe","nɑh","nɑi","nɑo","ngh","nia","nih","niu","noo","nua","nui","onɡ","ooh","uɑh","uai","uɑi","uɑn","uɑt","ueh","ɑe","ɑh","ai","ɑk","ɑm","ɑn","ao","ɑp","ɑt","eh","eu","iɑ","ie","ih","ik","im","in","io","ip","it","iu","mh","na","ng","ni","oh","ok","oo","op","uɑ","ue","uh","ui","un","ut","ɑ","e","i","m","o","u")
A2: 序號 | B2: 國際音標 | C2: 台羅拼音 | D2: 台語音標 | E2: 台語注音二式 | F2: 閩拼方案 | G2: 白話字 | H2: 十五音 | I2: 方音符號 | K2: 台語注音二式 | L2: 台語音標
A3: =ROW() -2 -> 1 | B3: {=IFERROR( INDEX(韻母對照表[國際音標], MATCH(TRUE, EXACT(韻母轉換規則!$C3, 韻母對照表[台羅拼音]), 0)), "")} -> ĩãũʔ | C3: iaunnh | D3: iaunnh | E3: {=IFERROR( INDEX(韻母對照表[注音二式], MATCH(TRUE, EXACT(韻母轉換規則!$C3, 韻母對照表[台羅拼音]), 0)), "")} -> iaunnh | F3: niɑoh | G3: {=IFERROR( INDEX(韻母對照表[白話字], MATCH(TRUE, EXACT(韻母轉換規則!$C3, 韻母對照表[台羅拼音]), 0)), "")} -> iauhⁿ | H3: {=IFERROR( INDEX(韻母對照表[十五音識別碼], MATCH(TRUE, EXACT(韻母轉換規則!$C3, 韻母對照表[台羅拼音]), 0)), "")} -> 嘄促 | I3: {=IFERROR( INDEX(韻母對照表[方音符號], MATCH(TRUE, EXACT(韻母轉換規則!$C3, 韻母對照表[台羅拼音]), 0)), "")} -> ㄧㆯㆷ | K3: =E3 -> iaunnh | L3: =D3 -> iaunnh | N3: =IF(AND(K3<>"", L3<>""), "xform/" & $E3 & "/" & $D3 & "/", "") -> xform/iaunnh/iaunnh/
A4: =ROW() -2 -> 2 | B4: {=IFERROR( INDEX(韻母對照表[國際音標], MATCH(TRUE, EXACT(韻母轉換規則!$C4, 韻母對照表[台羅拼音]), 0)), "")} -> ũãĩʔ | C4: uainnh | D4: uainnh | E4: {=IFERROR( INDEX(韻母對照表[注音二式], MATCH(TRUE, EXACT(韻母轉換規則!$C4, 韻母對照表[台羅拼音]), 0)), "")} -> uainnh | F4: nuɑih | G4: {=IFERROR( INDEX(韻母對照表[白話字], MATCH(TRUE, EXACT(韻母轉換規則!$C4, 韻母對照表[台羅拼音]), 0)), "")} -> oaihⁿ | H4: {=IFERROR( INDEX(韻母對照表[十五音識別碼], MATCH(TRUE, EXACT(韻母轉換規則!$C4, 韻母對照表[台羅拼音]), 0)), "")} -> 閂促 | I4: {=IFERROR( INDEX(韻母對照表[方音符號], MATCH(TRUE, EXACT(韻母轉換規則!$C4, 韻母對照表[台羅拼音]), 0)), "")} -> ㄨㆮㆷ | K4: =E4 -> uainnh | L4: =D4 -> uainnh | N4: =IF(AND(K4<>"", L4<>""), "xform/" & $E4 & "/" & $D4 & "/", "") -> xform/uainnh/uainnh/
A5: =ROW() -2 -> 3 | B5: iɑŋ | C5: iang | D5: iang | E5: {=IFERROR( INDEX(韻母對照表[注音二式], MATCH(TRUE, EXACT(韻母轉換規則!$C5, 韻母對照表[台羅拼音]), 0)), "")} -> iang | F5: iɑnɡ | G5: {=IFERROR( INDEX(韻母對照表[白話字], MATCH(TRUE, EXACT(韻母轉換規則!$C5, 韻母對照表[台羅拼音]), 0)), "")} -> iang | H5: {=IFERROR( INDEX(韻母對照表[十五音識別碼], MATCH(TRUE, EXACT(韻母轉換規則!$C5, 韻母對照表[台羅拼音]), 0)), "")} -> 姜舒 | I5: {=IFERROR( INDEX(韻母對照表[方音符號], MATCH(TRUE, EXACT(韻母轉換規則!$C5, 韻母對照表[台羅拼音]), 0)), "")} -> ㄧㄤ | K5: =E5 -> iang | L5: =D5 -> iang | N5: =IF(AND(K5<>"", L5<>""), "xform/" & $E5 & "/" & $D5 & "/", "") -> xform/iang/iang/
A6: =ROW() -2 -> 4 | B6: iauʔ | C6: iauh | D6: iauh | E6: {=IFERROR( INDEX(韻母對照表[注音二式], MATCH(TRUE, EXACT(韻母轉換規則!$C6, 韻母對照表[台羅拼音]), 0)), "")} -> iauh | F6: iaoh | G6: {=IFERROR( INDEX(韻母對照表[白話字], MATCH(TRUE, EXACT(韻母轉換規則!$C6, 韻母對照表[台羅拼音]), 0)), "")} -> iauh | H6: {=IFERROR( INDEX(韻母對照表[十五音識別碼], MATCH(TRUE, EXACT(韻母轉換規則!$C6, 韻母對照表[台羅拼音]), 0)), "")} -> 嬌促 | I6: {=IFERROR( INDEX(韻母對照表[方音符號], MATCH(TRUE, EXACT(韻母轉換規則!$C6, 韻母對照表[台羅拼音]), 0)), "")} -> ㄧㄠㆷ | K6: =E6 -> iauh | L6: =D6 -> iauh | N6: =IF(AND(K6<>"", L6<>""), "xform/" & $E6 & "/" & $D6 & "/", "") -> xform/iauh/iauh/
A7: =ROW() -2 -> 5 | B7: iɔŋ | C7: iong | D7: iong | E7: {=IFERROR( INDEX(韻母對照表[注音二式], MATCH(TRUE, EXACT(韻母轉換規則!$C7, 韻母對照表[台羅拼音]), 0)), "")} -> iong | F7: ionɡ | G7: {=IFERROR( INDEX(韻母對照表[白話字], MATCH(TRUE, EXACT(韻母轉換規則!$C7, 韻母對照表[台羅拼音]), 0)), "")} -> iong | H7: {=IFERROR( INDEX(韻母對照表[十五音識別碼], MATCH(TRUE, EXACT(韻母轉換規則!$C7, 韻母對照表[台羅拼音]), 0)), "")} -> 恭舒 | I7: {=IFERROR( INDEX(韻母對照表[方音符號], MATCH(TRUE, EXACT(韻母轉換規則!$C7, 韻母對照表[台羅拼音]), 0)), "")} -> ㄧㆲ | K7: =E7 -> iong | L7: =D7 -> iong | N7: =IF(AND(K7<>"", L7<>""), "xform/" & $E7 & "/" & $D7 & "/", "") -> xform/iong/iong/
A8: =ROW() -2 -> 6 | B8: ɛ̃ʔ | C8: ennh | D8: ennh | E8: {=IFERROR( INDEX(韻母對照表[注音二式], MATCH(TRUE, EXACT(韻母轉換規則!$C8, 韻母對照表[台羅拼音]), 0)), "")} | F8: nɑeh | G8: {=IFERROR( INDEX(韻母對照表[白話字], MATCH(TRUE, EXACT(韻母轉換規則!$C8, 韻母對照表[台羅拼音]), 0)), "")} | H8: {=IFERROR( INDEX(韻母對照表[十五音識別碼], MATCH(TRUE, EXACT(韻母轉換規則!$C8, 韻母對照表[台羅拼音]), 0)), "")} | I8: {=IFERROR( INDEX(韻母對照表[方音符號], MATCH(TRUE, EXACT(韻母轉換規則!$C8, 韻母對照表[台羅拼音]), 0)), "")} | K8: =E8 | L8: =D8 -> ennh | N8: =IF(AND(K8<>"", L8<>""), "xform/" & $E8 & "/" & $D8 & "/", "")
A9: =ROW() -2 -> 7 | B9: ãuʔ | C9: aunnh | D9: aunnh | E9: {=IFERROR( INDEX(韻母對照表[注音二式], MATCH(TRUE, EXACT(韻母轉換規則!$C9, 韻母對照表[台羅拼音]), 0)), "")} | F9: nɑoh | G9: {=IFERROR( INDEX(韻母對照表[白話字], MATCH(TRUE, EXACT(韻母轉換規則!$C9, 韻母對照表[台羅拼音]), 0)), "")} | H9: {=IFERROR( INDEX(韻母對照表[十五音識別碼], MATCH(TRUE, EXACT(韻母轉換規則!$C9, 韻母對照表[台羅拼音]), 0)), "")} | I9: {=IFERROR( INDEX(韻母對照表[方音符號], MATCH(TRUE, EXACT(韻母轉換規則!$C9, 韻母對照表[台羅拼音]), 0)), "")} | K9: =E9 | L9: =D9 -> aunnh | N9: =IF(AND(K9<>"", L9<>""), "xform/" & $E9 & "/" & $D9 & "/", "")
A10: =ROW() -2 -> 8 | B10: iãʔ | C10: iannh | D10: iannh | E10: {=IFERROR( INDEX(韻母對照表[注音二式], MATCH(TRUE, EXACT(韻母轉換規則!$C10, 韻母對照表[台羅拼音]), 0)), "")} | F10: niɑh | G10: {=IFERROR( INDEX(韻母對照表[白話字], MATCH(TRUE, EXACT(韻母轉換規則!$C10, 韻母對照表[台羅拼音]), 0)), "")} | H10: {=IFERROR( INDEX(韻母對照表[十五音識別碼], MATCH(TRUE, EXACT(韻母轉換規則!$C10, 韻母對照表[台羅拼音]), 0)), "")} | I10: {=IFERROR( INDEX(韻母對照表[方音符號], MATCH(TRUE, EXACT(韻母轉換規則!$C10, 韻母對照表[台羅拼音]), 0)), "")} | K10: =E10 | L10: =D10 -> iannh | N10: =IF(AND(K10<>"", L10<>""), "xform/" & $E10 & "/" & $D10 & "/", "")
A11: =ROW() -2 -> 9 | B11: iau | C11: iaunn | D11: iaunn | E11: {=IFERROR( INDEX(韻母對照表[注音二式], MATCH(TRUE, EXACT(韻母轉換規則!$C11, 韻母對照表[台羅拼音]), 0)), "")} -> iaunn | F11: niɑo | G11: {=IFERROR( INDEX(韻母對照表[白話字], MATCH(TRUE, EXACT(韻母轉換規則!$C11, 韻母對照表[台羅拼音]), 0)), "")} -> iauⁿ | H11: {=IFERROR( INDEX(韻母對照表[十五音識別碼], MATCH(TRUE, EXACT(韻母轉換規則!$C11, 韻母對照表[台羅拼音]), 0)), "")} -> 嘄舒 | I11: {=IFERROR( INDEX(韻母對照表[方音符號], MATCH(TRUE, EXACT(韻母轉換規則!$C11, 韻母對照表[台羅拼音]), 0)), "")} -> ㄧㆯ | K11: =E11 -> iaunn | L11: =D11 -> iaunn | N11: =IF(AND(K11<>"", L11<>""), "xform/" & $E11 & "/" & $D11 & "/", "") -> xform/iaunn/iaunn/
A12: =ROW() -2 -> 10 | B12: {=IFERROR( INDEX(韻母對照表[國際音標], MATCH(TRUE, EXACT(韻母轉換規則!$C12, 韻母對照表[台羅拼音]), 0)), "")} -> ɔ̃ʔ | C12: onnh | D12: onnh | E12: {=IFERROR( INDEX(韻母對照表[注音二式], MATCH(TRUE, EXACT(韻母轉換規則!$C12, 韻母對照表[台羅拼音]), 0)), "")} -> uenn | F12: nooh | G12: {=IFERROR( INDEX(韻母對照表[白話字], MATCH(TRUE, EXACT(韻母轉換規則!$C12, 韻母對照表[台羅拼音]), 0)), "")} -> ohⁿ | H12: {=IFERROR( INDEX(韻母對照表[十五音識別碼], MATCH(TRUE, EXACT(韻母轉換規則!$C12, 韻母對照表[台羅拼音]), 0)), "")} -> 扛促 | I12: {=IFERROR( INDEX(韻母對照表[方音符號], MATCH(TRUE, EXACT(韻母轉換規則!$C12, 韻母對照表[台羅拼音]), 0)), "")} -> ㆧㆷ | K12: =E12 -> uenn | L12: =D12 -> onnh | N12: =IF(AND(K12<>"", L12<>""), "xform/" & $E12 & "/" & $D12 & "/", "") -> xform/uenn/onnh/
A13: =ROW() -2 -> 11 | B13: εʔ | C13: eeh | D13: eeh | E13: {=IFERROR( INDEX(韻母對照表[注音二式], MATCH(TRUE, EXACT(韻母轉換規則!$C13, 韻母對照表[台羅拼音]), 0)), "")} -> eh | F13: ɑeh | H13: {=IFERROR( INDEX(韻母對照表[十五音識別碼], MATCH(TRUE, EXACT(韻母轉換規則!$C13, 韻母對照表[台羅拼音]), 0)), "")} -> 嘉促 | I13: {=IFERROR( INDEX(韻母對照表[方音符號], MATCH(TRUE, EXACT(韻母轉換規則!$C13, 韻母對照表[台羅拼音]), 0)), "")} -> ㄝㆷ | K13: =E13 -> eh | L13: =D13 -> eeh | N13: =IF(AND(K13<>"", L13<>""), "xform/" & $E13 & "/" & $D13 & "/", "") -> xform/eh/eeh/
A14: =ROW() -2 -> 12 | B14: ɑŋ | C14: ang | D14: ang | E14: {=IFERROR( INDEX(韻母對照表[注音二式], MATCH(TRUE, EXACT(韻母轉換規則!$C14, 韻母對照表[台羅拼音]), 0)), "")} -> ang | F14: anɡ | G14: {=IFERROR( INDEX(韻母對照表[白話字], MATCH(TRUE, EXACT(韻母轉換規則!$C14, 韻母對照表[台羅拼音]), 0)), "")} -> ang | H14: {=IFERROR( INDEX(韻母對照表[十五音識別碼], MATCH(TRUE, EXACT(韻母轉換規則!$C14, 韻母對照表[台羅拼音]), 0)), "")} -> 江舒 | I14: {=IFERROR( INDEX(韻母對照表[方音符號], MATCH(TRUE, EXACT(韻母轉換規則!$C14, 韻母對照表[台羅拼音]), 0)), "")} -> ㄤ | K14: =E14 -> ang | L14: =D14 -> ang | N14: =IF(AND(K14<>"", L14<>""), "xform/" & $E14 & "/" & $D14 & "/", "") -> xform/ang/ang/
A15: =ROW() -2 -> 13 | B15: auʔ | C15: auh | D15: auh | E15: {=IFERROR( INDEX(韻母對照表[注音二式], MATCH(TRUE, EXACT(韻母轉換規則!$C15, 韻母對照表[台羅拼音]), 0)), "")} -> auh | F15: ɑoh | G15: {=IFERROR( INDEX(韻母對照表[白話字], MATCH(TRUE, EXACT(韻母轉換規則!$C15, 韻母對照表[台羅拼音]), 0)), "")} -> auh | H15: {=IFERROR( INDEX(韻母對照表[十五音識別碼], MATCH(TRUE, EXACT(韻母轉換規則!$C15, 韻母對照表[台羅拼音]), 0)), "")} -> 交促 | I15: {=IFERROR( INDEX(韻母對照表[方音符號], MATCH(TRUE, EXACT(韻母轉換規則!$C15, 韻母對照表[台羅拼音]), 0)), "")} -> ㄠㆷ | K15: =E15 -> auh | L15: =D15 -> auh | N15: =IF(AND(K15<>"", L15<>""), "xform/" & $E15 & "/" & $D15 & "/", "") -> xform/auh/auh/
A16: =ROW() -2 -> 14 | B16: iaʔ | C16: iah | D16: iah | E16: {=IFERROR( INDEX(韻母對照表[注音二式], MATCH(TRUE, EXACT(韻母轉換規則!$C16, 韻母對照表[台羅拼音]), 0)), "")} -> iah | F16: iɑh | G16: {=IFERROR( INDEX(韻母對照表[白話字], MATCH(TRUE, EXACT(韻母轉換規則!$C16, 韻母對照表[台羅拼音]), 0)), "")} -> iah | H16: {=IFERROR( INDEX(韻母對照表[十五音識別碼], MATCH(TRUE, EXACT(韻母轉換規則!$C16, 韻母對照表[台羅拼音]), 0)), "")} -> 迦促 | I16: {=IFERROR( INDEX(韻母對照表[方音符號], MATCH(TRUE, EXACT(韻母轉換規則!$C16, 韻母對照表[台羅拼音]), 0)), "")} -> ㄧㄚㆷ | K16: =E16 -> iah | L16: =D16 -> iah | N16: =IF(AND(K16<>"", L16<>""), "xform/" & $E16 & "/" & $D16 & "/", "") -> xform/iah/iah/
A17: =ROW() -2 -> 15 | B17: iɑk̚ | C17: iak | D17: iak | E17: {=IFERROR( INDEX(韻母對照表[注音二式], MATCH(TRUE, EXACT(韻母轉換規則!$C17, 韻母對照表[台羅拼音]), 0)), "")} -> iak | F17: iɑk | G17: {=IFERROR( INDEX(韻母對照表[白話字], MATCH(TRUE, EXACT(韻母轉換規則!$C17, 韻母對照表[台羅拼音]), 0)), "")} -> iak | H17: {=IFERROR( INDEX(韻母對照表[十五音識別碼], MATCH(TRUE, EXACT(韻母轉換規則!$C17, 韻母對照表[台羅拼音]), 0)), "")} -> 姜促 | I17: {=IFERROR( INDEX(韻母對照表[方音符號], MATCH(TRUE, EXACT(韻母轉換規則!$C17, 韻母對照表[台羅拼音]), 0)), "")} -> ㄧㄚㆻ | K17: =E17 -> iak | L17: =D17 -> iak | N17: =IF(AND(K17<>"", L17<>""), "xform/" & $E17 & "/" & $D17 & "/", "") -> xform/iak/iak/
A18: =ROW() -2 -> 16 | B18: iam | C18: iam | D18: iam | E18: {=IFERROR( INDEX(韻母對照表[注音二式], MATCH(TRUE, EXACT(韻母轉換規則!$C18, 韻母對照表[台羅拼音]), 0)), "")} -> iam | F18: iɑm | G18: {=IFERROR( INDEX(韻母對照表[白話字], MATCH(TRUE, EXACT(韻母轉換規則!$C18, 韻母對照表[台羅拼音]), 0)), "")} -> iam | H18: {=IFERROR( INDEX(韻母對照表[十五音識別碼], MATCH(TRUE, EXACT(韻母轉換規則!$C18, 韻母對照表[台羅拼音]), 0)), "")} -> 兼舒 | I18: {=IFERROR( INDEX(韻母對照表[方音符號], MATCH(TRUE, EXACT(韻母轉換規則!$C18, 韻母對照表[台羅拼音]), 0)), "")} -> ㄧㆰ | K18: =E18 -> iam | L18: =D18 -> iam | N18: =IF(AND(K18<>"", L18<>""), "xform/" & $E18 & "/" & $D18 & "/", "") -> xform/iam/iam/
A19: =ROW() -2 -> 17 | B19: ian | C19: ian | D19: ian | E19: {=IFERROR( INDEX(韻母對照表[注音二式], MATCH(TRUE, EXACT(韻母轉換規則!$C19, 韻母對照表[台羅拼音]), 0)), "")} -> ian | F19: iɑn | G19: {=IFERROR( INDEX(韻母對照表[白話字], MATCH(TRUE, EXACT(韻母轉換規則!$C19, 韻母對照表[台羅拼音]), 0)), "")} -> ian | H19: {=IFERROR( INDEX(韻母對照表[十五音識別碼], MATCH(TRUE, EXACT(韻母轉換規則!$C19, 韻母對照表[台羅拼音]), 0)), "")} -> 堅舒 | I19: {=IFERROR( INDEX(韻母對照表[方音符號], MATCH(TRUE, EXACT(韻母轉換規則!$C19, 韻母對照表[台羅拼音]), 0)), "")} -> ㄧㄢ | K19: =E19 -> ian | L19: =D19 -> ian | N19: =IF(AND(K19<>"", L19<>""), "xform/" & $E19 & "/" & $D19 & "/", "") -> xform/ian/ian/
A20: =ROW() -2 -> 18 | B20: iau | C20: iau | D20: iau | E20: {=IFERROR( INDEX(韻母對照表[注音二式], MATCH(TRUE, EXACT(韻母轉換規則!$C20, 韻母對照表[台羅拼音]), 0)), "")} -> iau | F20: iɑo | G20: {=IFERROR( INDEX(韻母對照表[白話字], MATCH(TRUE, EXACT(韻母轉換規則!$C20, 韻母對照表[台羅拼音]), 0)), "")} -> iau | H20: {=IFERROR( INDEX(韻母對照表[十五音識別碼], MATCH(TRUE, EXACT(韻母轉換規則!$C20, 韻母對照表[台羅拼音]), 0)), "")} -> 嬌舒 | I20: {=IFERROR( INDEX(韻母對照表[方音符號], MATCH(TRUE, EXACT(韻母轉換規則!$C20, 韻母對照表[台羅拼音]), 0)), "")} -> ㄧㄠ | K20: =E20 -> iau | L20: =D20 -> iau | N20: =IF(AND(K20<>"", L20<>""), "xform/" & $E20 & "/" & $D20 & "/", "") -> xform/iau/iau/
A21: =ROW() -2 -> 19 | B21: iap̚ | C21: iap | D21: iap | E21: {=IFERROR( INDEX(韻母對照表[注音二式], MATCH(TRUE, EXACT(韻母轉換規則!$C21, 韻母對照表[台羅拼音]), 0)), "")} -> iap | F21: iɑp | G21: {=IFERROR( INDEX(韻母對照表[白話字], MATCH(TRUE, EXACT(韻母轉換規則!$C21, 韻母對照表[台羅拼音]), 0)), "")} -> iap | H21: {=IFERROR( INDEX(韻母對照表[十五音識別碼], MATCH(TRUE, EXACT(韻母轉換規則!$C21, 韻母對照表[台羅拼音]), 0)), "")} -> 兼促 | I21: {=IFERROR( INDEX(韻母對照表[方音符號], MATCH(TRUE, EXACT(韻母轉換規則!$C21, 韻母對照表[台羅拼音]), 0)), "")} -> ㄧㄚㆴ | K21: =E21 -> iap | L21: =D21 -> iap | N21: =IF(AND(K21<>"", L21<>""), "xform/" & $E21 & "/" & $D21 & "/", "") -> xform/iap/iap/
A22: =ROW() -2 -> 20 | B22: iat̚ | C22: iat | D22: iat | E22: {=IFERROR( INDEX(韻母對照表[注音二式], MATCH(TRUE, EXACT(韻母轉換規則!$C22, 韻母對照表[台羅拼音]), 0)), "")} -> iat | F22: iɑt | G22: {=IFERROR( INDEX(韻母對照表[白話字], MATCH(TRUE, EXACT(韻母轉換規則!$C22, 韻母對照表[台羅拼音]), 0)), "")} -> iat | H22: {=IFERROR( INDEX(韻母對照表[十五音識別碼], MATCH(TRUE, EXACT(韻母轉換規則!$C22, 韻母對照表[台羅拼音]), 0)), "")} -> 堅促 | I22: {=IFERROR( INDEX(韻母對照表[方音符號], MATCH(TRUE, EXACT(韻母轉換規則!$C22, 韻母對照表[台羅拼音]), 0)), "")} -> ㄧㄚㆵ | K22: =E22 -> iat | L22: =D22 -> iat | N22: =IF(AND(K22<>"", L22<>""), "xform/" & $E22 & "/" & $D22 & "/", "") -> xform/iat/iat/
A23: =ROW() -2 -> 21 | B23: iŋ | C23: ing | D23: ing | E23: {=IFERROR( INDEX(韻母對照表[注音二式], MATCH(TRUE, EXACT(韻母轉換規則!$C23, 韻母對照表[台羅拼音]), 0)), "")} -> ing | F23: inɡ | G23: {=IFERROR( INDEX(韻母對照表[白話字], MATCH(TRUE, EXACT(韻母轉換規則!$C23, 韻母對照表[台羅拼音]), 0)), "")} -> eng | H23: {=IFERROR( INDEX(韻母對照表[十五音識別碼], MATCH(TRUE, EXACT(韻母轉換規則!$C23, 韻母對照表[台羅拼音]), 0)), "")} -> 經舒 | I23: {=IFERROR( INDEX(韻母對照表[方音符號], MATCH(TRUE, EXACT(韻母轉換規則!$C23, 韻母對照表[台羅拼音]), 0)), "")} -> ㄧㄥ | K23: =E23 -> ing | L23: =D23 -> ing | N23: =IF(AND(K23<>"", L23<>""), "xform/" & $E23 & "/" & $D23 & "/", "") -> xform/ing/ing/
A24: =ROW() -2 -> 22 | B24: ioʔ | C24: ioh | D24: ioh | E24: {=IFERROR( INDEX(韻母對照表[注音二式], MATCH(TRUE, EXACT(韻母轉換規則!$C24, 韻母對照表[台羅拼音]), 0)), "")} -> iorh | F24: ioh | G24: {=IFERROR( INDEX(韻母對照表[白話字], MATCH(TRUE, EXACT(韻母轉換規則!$C24, 韻母對照表[台羅拼音]), 0)), "")} -> ioh | H24: {=IFERROR( INDEX(韻母對照表[十五音識別碼], MATCH(TRUE, EXACT(韻母轉換規則!$C24, 韻母對照表[台羅拼音]), 0)), "")} -> 茄促 | I24: {=IFERROR( INDEX(韻母對照表[方音符號], MATCH(TRUE, EXACT(韻母轉換規則!$C24, 韻母對照表[台羅拼音]), 0)), "")} -> ㄧㄜㆷ | K24: =E24 -> iorh | L24: =D24 -> ioh | N24: =IF(AND(K24<>"", L24<>""), "xform/" & $E24 & "/" & $D24 & "/", "") -> xform/iorh/ioh/
A25: =ROW() -2 -> 23 | B25: iɔk̚ | C25: iok | D25: iok | E25: {=IFERROR( INDEX(韻母對照表[注音二式], MATCH(TRUE, EXACT(韻母轉換規則!$C25, 韻母對照表[台羅拼音]), 0)), "")} -> iook | F25: iok | G25: {=IFERROR( INDEX(韻母對照表[白話字], MATCH(TRUE, EXACT(韻母轉換規則!$C25, 韻母對照表[台羅拼音]), 0)), "")} -> iok | H25: {=IFERROR( INDEX(韻母對照表[十五音識別碼], MATCH(TRUE, EXACT(韻母轉換規則!$C25, 韻母對照表[台羅拼音]), 0)), "")} -> 恭促 | I25: {=IFERROR( INDEX(韻母對照表[方音符號], MATCH(TRUE, EXACT(韻母轉換規則!$C25, 韻母對照表[台羅拼音]), 0)), "")} -> ㄧㆦㆻ | K25: =E25 -> iook | L25: =D25 -> iok | N25: =IF(AND(K25<>"", L25<>""), "xform/" & $E25 & "/" & $D25 & "/", "") -> xform/iook/iok/
... A32: =ROW() -2 -> 30 | B32: iã | C32: iann | D32: iann | E32: {=IFERROR( INDEX(韻母對照表[注音二式], MATCH(TRUE, EXACT(韻母轉換規則!$C32, 韻母對照表[台羅拼音]), 0)), "")} -> iann | F32: nia | G32: {=IFERROR( INDEX(韻母對照表[白話字], MATCH(TRUE, EXACT(韻母轉換規則!$C32, 韻母對照表[台羅拼音]), 0)), "")} -> iaⁿ | H32: {=IFERROR( INDEX(韻母對照表[十五音識別碼], MATCH(TRUE, EXACT(韻母轉換規則!$C32, 韻母對照表[台羅拼音]), 0)), "")} -> 驚舒 | I32: {=IFERROR( INDEX(韻母對照表[方音符號], MATCH(TRUE, EXACT(韻母轉換規則!$C32, 韻母對照表[台羅拼音]), 0)), "")} -> ㄧㆩ | K32: =E32 -> iann | L32: =D32 -> iann | N32: =IF(AND(K32<>"", L32<>""), "xform/" & $E32 & "/" & $D32 & "/", "") -> xform/iann/iann/
A33: =ROW() -2 -> 31 | B33: {=IFERROR( INDEX(韻母對照表[國際音標], MATCH(TRUE, EXACT(韻母轉換規則!$C33, 韻母對照表[台羅拼音]), 0)), "")} -> ĩʔ | C33: innh | D33: innh | E33: {=IFERROR( INDEX(韻母對照表[注音二式], MATCH(TRUE, EXACT(韻母轉換規則!$C33, 韻母對照表[台羅拼音]), 0)), "")} -> innh | F33: nih | G33: {=IFERROR( INDEX(韻母對照表[白話字], MATCH(TRUE, EXACT(韻母轉換規則!$C33, 韻母對照表[台羅拼音]), 0)), "")} -> ihⁿ | H33: {=IFERROR( INDEX(韻母對照表[十五音識別碼], MATCH(TRUE, EXACT(韻母轉換規則!$C33, 韻母對照表[台羅拼音]), 0)), "")} -> 梔促 | I33: {=IFERROR( INDEX(韻母對照表[方音符號], MATCH(TRUE, EXACT(韻母轉換規則!$C33, 韻母對照表[台羅拼音]), 0)), "")} -> ㆪㆷ | K33: =E33 -> innh | L33: =D33 -> innh | N33: =IF(AND(K33<>"", L33<>""), "xform/" & $E33 & "/" & $D33 & "/", "") -> xform/innh/innh/
A34: =ROW() -2 -> 32 | B34: {=IFERROR( INDEX(韻母對照表[國際音標], MATCH(TRUE, EXACT(韻母轉換規則!$C34, 韻母對照表[台羅拼音]), 0)), "")} -> ĩũ | C34: iunn | D34: iunn | E34: {=IFERROR( INDEX(韻母對照表[注音二式], MATCH(TRUE, EXACT(韻母轉換規則!$C34, 韻母對照表[台羅拼音]), 0)), "")} -> iunn | F34: niu | G34: {=IFERROR( INDEX(韻母對照表[白話字], MATCH(TRUE, EXACT(韻母轉換規則!$C34, 韻母對照表[台羅拼音]), 0)), "")} -> iuⁿ | H34: {=IFERROR( INDEX(韻母對照表[十五音識別碼], MATCH(TRUE, EXACT(韻母轉換規則!$C34, 韻母對照表[台羅拼音]), 0)), "")} -> 牛舒 | I34: {=IFERROR( INDEX(韻母對照表[方音符號], MATCH(TRUE, EXACT(韻母轉換規則!$C34, 韻母對照表[台羅拼音]), 0)), "")} -> ㄧㆫ | K34: =E34 -> iunn | L34: =D34 -> iunn | N34: =IF(AND(K34<>"", L34<>""), "xform/" & $E34 & "/" & $D34 & "/", "") -> xform/iunn/iunn/
A35: =ROW() -2 -> 33 | B35: ɔ̃ | C35: onn | D35: onn | E35: {=IFERROR( INDEX(韻母對照表[注音二式], MATCH(TRUE, EXACT(韻母轉換規則!$C35, 韻母對照表[台羅拼音]), 0)), "")} -> oonn | F35: noo | G35: {=IFERROR( INDEX(韻母對照表[白話字], MATCH(TRUE, EXACT(韻母轉換規則!$C35, 韻母對照表[台羅拼音]), 0)), "")} -> oⁿ | H35: {=IFERROR( INDEX(韻母對照表[十五音識別碼], MATCH(TRUE, EXACT(韻母轉換規則!$C35, 韻母對照表[台羅拼音]), 0)), "")} -> 姑舒 | I35: {=IFERROR( INDEX(韻母對照表[方音符號], MATCH(TRUE, EXACT(韻母轉換規則!$C35, 韻母對照表[台羅拼音]), 0)), "")} -> ㆧ | K35: =E35 -> oonn | L35: =D35 -> onn | N35: =IF(AND(K35<>"", L35<>""), "xform/" & $E35 & "/" & $D35 & "/", "") -> xform/oonn/onn/
A36: =ROW() -2 -> 34 | B36: {=IFERROR( INDEX(韻母對照表[國際音標], MATCH(TRUE, EXACT(韻母轉換規則!$C36, 韻母對照表[台羅拼音]), 0)), "")} -> ũã | C36: uann | D36: uann | E36: {=IFERROR( INDEX(韻母對照表[注音二式], MATCH(TRUE, EXACT(韻母轉換規則!$C36, 韻母對照表[台羅拼音]), 0)), "")} -> uann | F36: nua | G36: {=IFERROR( INDEX(韻母對照表[白話字], MATCH(TRUE, EXACT(韻母轉換規則!$C36, 韻母對照表[台羅拼音]), 0)), "")} -> oaⁿ | H36: {=IFERROR( INDEX(韻母對照表[十五音識別碼], MATCH(TRUE, EXACT(韻母轉換規則!$C36, 韻母對照表[台羅拼音]), 0)), "")} -> 官舒 | I36: {=IFERROR( INDEX(韻母對照表[方音符號], MATCH(TRUE, EXACT(韻母轉換規則!$C36, 韻母對照表[台羅拼音]), 0)), "")} -> ㄨㆩ | K36: =E36 -> uann | L36: =D36 -> uann | N36: =IF(AND(K36<>"", L36<>""), "xform/" & $E36 & "/" & $D36 & "/", "") -> xform/uann/uann/
A37: =ROW() -2 -> 35 | B37: {=IFERROR( INDEX(韻母對照表[國際音標], MATCH(TRUE, EXACT(韻母轉換規則!$C37, 韻母對照表[台羅拼音]), 0)), "")} -> ũĩ | C37: uinn | D37: uinn | E37: {=IFERROR( INDEX(韻母對照表[注音二式], MATCH(TRUE, EXACT(韻母轉換規則!$C37, 韻母對照表[台羅拼音]), 0)), "")} -> uinn | F37: nui | G37: {=IFERROR( INDEX(韻母對照表[白話字], MATCH(TRUE, EXACT(韻母轉換規則!$C37, 韻母對照表[台羅拼音]), 0)), "")} -> uiⁿ | H37: {=IFERROR( INDEX(韻母對照表[十五音識別碼], MATCH(TRUE, EXACT(韻母轉換規則!$C37, 韻母對照表[台羅拼音]), 0)), "")} -> 褌舒 | I37: {=IFERROR( INDEX(韻母對照表[方音符號], MATCH(TRUE, EXACT(韻母轉換規則!$C37, 韻母對照表[台羅拼音]), 0)), "")} -> ㄨㆪ | K37: =E37 -> uinn | L37: =D37 -> uinn | N37: =IF(AND(K37<>"", L37<>""), "xform/" & $E37 & "/" & $D37 & "/", "") -> xform/uinn/uinn/
A38: =ROW() -2 -> 36 | B38: ɔŋ | C38: ong | D38: ong | E38: {=IFERROR( INDEX(韻母對照表[注音二式], MATCH(TRUE, EXACT(韻母轉換規則!$C38, 韻母對照表[台羅拼音]), 0)), "")} -> ong | F38: onɡ | G38: {=IFERROR( INDEX(韻母對照表[白話字], MATCH(TRUE, EXACT(韻母轉換規則!$C38, 韻母對照表[台羅拼音]), 0)), "")} -> ong | H38: {=IFERROR( INDEX(韻母對照表[十五音識別碼], MATCH(TRUE, EXACT(韻母轉換規則!$C38, 韻母對照表[台羅拼音]), 0)), "")} -> 公舒 | I38: {=IFERROR( INDEX(韻母對照表[方音符號], MATCH(TRUE, EXACT(韻母轉換規則!$C38, 韻母對照表[台羅拼音]), 0)), "")} -> ㆲ | K38: =E38 -> ong | L38: =D38 -> ong | N38: =IF(AND(K38<>"", L38<>""), "xform/" & $E38 & "/" & $D38 & "/", "") -> xform/ong/ong/
A39: =ROW() -2 -> 37 | B39: ɔʔ | C39: ooh | D39: ooh | E39: {=IFERROR( INDEX(韻母對照表[注音二式], MATCH(TRUE, EXACT(韻母轉換規則!$C39, 韻母對照表[台羅拼音]), 0)), "")} | F39: ooh | G39: {=IFERROR( INDEX(韻母對照表[白話字], MATCH(TRUE, EXACT(韻母轉換規則!$C39, 韻母對照表[台羅拼音]), 0)), "")} | H39: {=IFERROR( INDEX(韻母對照表[十五音識別碼], MATCH(TRUE, EXACT(韻母轉換規則!$C39, 韻母對照表[台羅拼音]), 0)), "")} | I39: {=IFERROR( INDEX(韻母對照表[方音符號], MATCH(TRUE, EXACT(韻母轉換規則!$C39, 韻母對照表[台羅拼音]), 0)), "")} | K39: =E39 | L39: =D39 -> ooh | N39: =IF(AND(K39<>"", L39<>""), "xform/" & $E39 & "/" & $D39 & "/", "")
A40: =ROW() -2 -> 38 | B40: uaʔ | C40: uah | D40: uah | E40: {=IFERROR( INDEX(韻母對照表[注音二式], MATCH(TRUE, EXACT(韻母轉換規則!$C40, 韻母對照表[台羅拼音]), 0)), "")} -> uah | F40: uɑh | G40: {=IFERROR( INDEX(韻母對照表[白話字], MATCH(TRUE, EXACT(韻母轉換規則!$C40, 韻母對照表[台羅拼音]), 0)), "")} -> oah | H40: {=IFERROR( INDEX(韻母對照表[十五音識別碼], MATCH(TRUE, EXACT(韻母轉換規則!$C40, 韻母對照表[台羅拼音]), 0)), "")} -> 瓜促 | I40: {=IFERROR( INDEX(韻母對照表[方音符號], MATCH(TRUE, EXACT(韻母轉換規則!$C40, 韻母對照表[台羅拼音]), 0)), "")} -> ㄨㄚㆷ | K40: =E40 -> uah | L40: =D40 -> uah | N40: =IF(AND(K40<>"", L40<>""), "xform/" & $E40 & "/" & $D40 & "/", "") -> xform/uah/uah/
A41: =ROW() -2 -> 39 | B41: uai | C41: uai | D41: uai | E41: {=IFERROR( INDEX(韻母對照表[注音二式], MATCH(TRUE, EXACT(韻母轉換規則!$C41, 韻母對照表[台羅拼音]), 0)), "")} -> uai | F41: uai | G41: {=IFERROR( INDEX(韻母對照表[白話字], MATCH(TRUE, EXACT(韻母轉換規則!$C41, 韻母對照表[台羅拼音]), 0)), "")} -> oai | H41: {=IFERROR( INDEX(韻母對照表[十五音識別碼], MATCH(TRUE, EXACT(韻母轉換規則!$C41, 韻母對照表[台羅拼音]), 0)), "")} -> 乖舒 | I41: {=IFERROR( INDEX(韻母對照表[方音符號], MATCH(TRUE, EXACT(韻母轉換規則!$C41, 韻母對照表[台羅拼音]), 0)), "")} -> ㄨㄞ | K41: =E41 -> uai | L41: =D41 -> uai | N41: =IF(AND(K41<>"", L41<>""), "xform/" & $E41 & "/" & $D41 & "/", "") -> xform/uai/uai/
A42: =ROW() -2 -> 40 | B42: {=IFERROR( INDEX(韻母對照表[國際音標], MATCH(TRUE, EXACT(韻母轉換規則!$C42, 韻母對照表[台羅拼音]), 0)), "")} -> ũãĩ | C42: uainn | D42: uainn | E42: {=IFERROR( INDEX(韻母對照表[注音二式], MATCH(TRUE, EXACT(韻母轉換規則!$C42, 韻母對照表[台羅拼音]), 0)), "")} -> uainn | F42: uɑi | G42: {=IFERROR( INDEX(韻母對照表[白話字], MATCH(TRUE, EXACT(韻母轉換規則!$C42, 韻母對照表[台羅拼音]), 0)), "")} -> oaiⁿ | H42: {=IFERROR( INDEX(韻母對照表[十五音識別碼], MATCH(TRUE, EXACT(韻母轉換規則!$C42, 韻母對照表[台羅拼音]), 0)), "")} -> 閂舒 | I42: {=IFERROR( INDEX(韻母對照表[方音符號], MATCH(TRUE, EXACT(韻母轉換規則!$C42, 韻母對照表[台羅拼音]), 0)), "")} -> ㄨㆮ | K42: =E42 -> uainn | L42: =D42 -> uainn | N42: =IF(AND(K42<>"", L42<>""), "xform/" & $E42 & "/" & $D42 & "/", "") -> xform/uainn/uainn/
A43: =ROW() -2 -> 41 | B43: uan | C43: uan | D43: uan | E43: {=IFERROR( INDEX(韻母對照表[注音二式], MATCH(TRUE, EXACT(韻母轉換規則!$C43, 韻母對照表[台羅拼音]), 0)), "")} -> uan | F43: uɑn | G43: {=IFERROR( INDEX(韻母對照表[白話字], MATCH(TRUE, EXACT(韻母轉換規則!$C43, 韻母對照表[台羅拼音]), 0)), "")} -> oan | H43: {=IFERROR( INDEX(韻母對照表[十五音識別碼], MATCH(TRUE, EXACT(韻母轉換規則!$C43, 韻母對照表[台羅拼音]), 0)), "")} -> 觀舒 | I43: {=IFERROR( INDEX(韻母對照表[方音符號], MATCH(TRUE, EXACT(韻母轉換規則!$C43, 韻母對照表[台羅拼音]), 0)), "")} -> ㄨㄢ | K43: =E43 -> uan | L43: =D43 -> uan | N43: =IF(AND(K43<>"", L43<>""), "xform/" & $E43 & "/" & $D43 & "/", "") -> xform/uan/uan/
A44: =ROW() -2 -> 42 | B44: uat̚ | C44: uat | D44: uat | E44: {=IFERROR( INDEX(韻母對照表[注音二式], MATCH(TRUE, EXACT(韻母轉換規則!$C44, 韻母對照表[台羅拼音]), 0)), "")} -> uat | F44: uɑt | G44: {=IFERROR( INDEX(韻母對照表[白話字], MATCH(TRUE, EXACT(韻母轉換規則!$C44, 韻母對照表[台羅拼音]), 0)), "")} -> oat | H44: {=IFERROR( INDEX(韻母對照表[十五音識別碼], MATCH(TRUE, EXACT(韻母轉換規則!$C44, 韻母對照表[台羅拼音]), 0)), "")} -> 觀促 | I44: {=IFERROR( INDEX(韻母對照表[方音符號], MATCH(TRUE, EXACT(韻母轉換規則!$C44, 韻母對照表[台羅拼音]), 0)), "")} -> ㄨㄚㆵ | K44: =E44 -> uat | L44: =D44 -> uat | N44: =IF(AND(K44<>"", L44<>""), "xform/" & $E44 & "/" & $D44 & "/", "") -> xform/uat/uat/
A45: =ROW() -2 -> 43 | B45: ueʔ | C45: ueh | D45: ueh | E45: {=IFERROR( INDEX(韻母對照表[注音二式], MATCH(TRUE, EXACT(韻母轉換規則!$C45, 韻母對照表[台羅拼音]), 0)), "")} -> ueh | F45: ueh | G45: {=IFERROR( INDEX(韻母對照表[白話字], MATCH(TRUE, EXACT(韻母轉換規則!$C45, 韻母對照表[台羅拼音]), 0)), "")} -> oeh | H45: {=IFERROR( INDEX(韻母對照表[十五音識別碼], MATCH(TRUE, EXACT(韻母轉換規則!$C45, 韻母對照表[台羅拼音]), 0)), "")} -> 檜促 | I45: {=IFERROR( INDEX(韻母對照表[方音符號], MATCH(TRUE, EXACT(韻母轉換規則!$C45, 韻母對照表[台羅拼音]), 0)), "")} -> ㄨㆤㆷ | K45: =E45 -> ueh | L45: =D45 -> ueh | N45: =IF(AND(K45<>"", L45<>""), "xform/" & $E45 & "/" & $D45 & "/", "") -> xform/ueh/ueh/
A46: =ROW() -2 -> 44 | B46: ɛ | C46: ee | D46: ee | E46: {=IFERROR( INDEX(韻母對照表[注音二式], MATCH(TRUE, EXACT(韻母轉換規則!$C46, 韻母對照表[台羅拼音]), 0)), "")} -> e | F46: ɑe | H46: {=IFERROR( INDEX(韻母對照表[十五音識別碼], MATCH(TRUE, EXACT(韻母轉換規則!$C46, 韻母對照表[台羅拼音]), 0)), "")} -> 嘉舒 | I46: {=IFERROR( INDEX(韻母對照表[方音符號], MATCH(TRUE, EXACT(韻母轉換規則!$C46, 韻母對照表[台羅拼音]), 0)), "")} -> ㄝ | K46: =E46 -> e | L46: =D46 -> ee | N46: =IF(AND(K46<>"", L46<>""), "xform/" & $E46 & "/" & $D46 & "/", "") -> xform/e/ee/
...

Sheet 台語注音二式轉換
A1: 序號 | B1: 字長 | C1: 台語注音二式 | D1: 台語音標 | E1: 對映
A2: 1 | B2: =LEN(C2) -> 6 | C2: iaunnh | D2: iaunnh | E2: ="xform/" & $C2 & "/" & $D2 & "/" -> xform/iaunnh/iaunnh/
A3: 2 | B3: =LEN(C3) -> 6 | C3: uainnh | D3: uainnh | E3: ="xform/" & $C3 & "/" & $D3 & "/" -> xform/uainnh/uainnh/
A4: 7 | B4: =LEN(C4) -> 5 | C4: aunnh | D4: aunnh | E4: ="xform/" & $C4 & "/" & $D4 & "/" -> xform/aunnh/aunnh/
A5: 8 | B5: =LEN(C5) -> 5 | C5: iannh | D5: iannh | E5: ="xform/" & $C5 & "/" & $D5 & "/" -> xform/iannh/iannh/
A6: 40 | B6: =LEN(C6) -> 5 | C6: uainn | D6: uainn | E6: ="xform/" & $C6 & "/" & $D6 & "/" -> xform/uainn/uainn/
A7: 86 | B7: =LEN(C7) -> 5 | C7: ioonn | D7: ionn | E7: ="xform/" & $C7 & "/" & $D7 & "/" -> xform/ioonn/ionn/
A8: 3 | B8: =LEN(C8) -> 4 | C8: iang | D8: iang | E8: ="xform/" & $C8 & "/" & $D8 & "/" -> xform/iang/iang/
A9: 4 | B9: =LEN(C9) -> 4 | C9: iauh | D9: iauh | E9: ="xform/" & $C9 & "/" & $D9 & "/" -> xform/iauh/iauh/
A10: 5 | B10: =LEN(C10) -> 4 | C10: iong | D10: iong | E10: ="xform/" & $C10 & "/" & $D10 & "/" -> xform/iong/iong/
A11: 6 | B11: =LEN(C11) -> 4 | C11: ennh | D11: ennh | E11: ="xform/" & $C11 & "/" & $D11 & "/" -> xform/ennh/ennh/
A12: 10 | B12: =LEN(C12) -> 4 | C12: onnh | D12: onnh | E12: ="xform/" & $C12 & "/" & $D12 & "/" -> xform/onnh/onnh/
A13: 22 | B13: =LEN(C13) -> 4 | C13: iorh | D13: ioh | E13: ="xform/" & $C13 & "/" & $D13 & "/" -> xform/iorh/ioh/
... A88: 44 | B88: =LEN(C88) -> 1 | C88: e | D88: ee | E88: ="xform/" & $C88 & "/" & $D88 & "/" -> xform/e/ee/
A89: 54 | B89: =LEN(C89) -> 1 | C89: 0 | D89: ir | E89: ="xform/" & $C89 & "/" & $D89 & "/" -> xform/0/ir/
A90: 56 | B90: =LEN(C90) -> 1 | C90: 0 | D90: er | E90: ="xform/" & $C90 & "/" & $D90 & "/" -> xform/0/er/
A91: 79 | B91: =LEN(C91) -> 1 | C91: a | D91: a | E91: ="xform/" & $C91 & "/" & $D91 & "/" -> xform/a/a/
A92: 80 | B92: =LEN(C92) -> 1 | C92: e | D92: e | E92: ="xform/" & $C92 & "/" & $D92 & "/" -> xform/e/e/
A93: 81 | B93: =LEN(C93) -> 1 | C93: i | D93: i | E93: ="xform/" & $C93 & "/" & $D93 & "/" -> xform/i/i/
A94: 82 | B94: =LEN(C94) -> 1 | C94: m | D94: m | E94: ="xform/" & $C94 & "/" & $D94 & "/" -> xform/m/m/
A95: 84 | B95: =LEN(C95) -> 1 | C95: u | D95: u | E95: ="xform/" & $C95 & "/" & $D95 & "/" -> xform/u/u/
A96: 88 | B96: =LEN(C96) -> 1 | C96: e | D96: ei | E96: ="xform/" & $C96 & "/" & $D96 & "/" -> xform/e/ei/
A97: 94 | B97: =LEN(C97) -> 1 | C97: 0 | D97: ioo | E97: ="xform/" & $C97 & "/" & $D97 & "/" -> xform/0/ioo/

Sheet 【調】聲調對照表
A1: 識別號 | B1: W調名 | C1: 四聲八調 | D1: 漢字 | E1: 調值 | F1: 方音調值 | G1: 台羅調號 | H1: 閩拼調號 | I1: 台語音標 | J1: 羅馬拼音調符 | K1: 拼音調符編碼 | L1: 注音調符 | M1: 注音調符編碼 | N1: 鍵盤按鍵
A2: 1 | B2: 高音調 | C2: 陰平 | D2: 東 | E2: 44 | F2: 55 | G2: 1 | H2: 1 | I2: tong1 | J2: a | L2: ㄚ | N2: ;
A3: 2 | B3: 中音調 | C3: 陽去 | D3: 動 | E3: 22 | F3: 33 | G3: 7 | H3: 6 | I3: tong7 | J3: ā | K3: U+0304 | L3: ㄚ˫ | M3: ˫ | N3: -
A4: 3 | B4: 低音調 | C4: 陰去 | D4: 棟 | E4: 21 | F4: 31 | G4: 3 | H4: 5 | I4: tong3 | J4: à | L4: ㄚ˪ | M4: ˪ | N4: _
A5: 4 | B5: 高降調 | C5: 上声/陰上 | D5: 董 | E5: 53 | F5: 51 | G5: 2 | H5: 3 | I5: tong2 | J5: á | K5: U+0301 | L5: ㄚˋ | M5: ˋ | N5: \
A6: 5 | B6: 低升調 | C6: 陽平 | D6: 同 | E6: 13 | F6: 24 | G6: 5 | H6: 2 | I6: tong5 | J6: â | L6: ㄚˊ | M6: ˊ | N6: /
A7: 6 | B7: 低促調 | C7: 陰入 | D7: 督 | E7: 32 | F7: 30 | G7: 4 | H7: 7 | I7: tok4 | J7: ah | L7: ㄚ◌ | N7: [
A8: 7 | B8: 高促調 | C8: 陽入 | D8: 獨 | E8: 121 | F8: 50 | G8: 8 | H8: 8 | I8: tok8 | J8: a̍h | L8: ㄚ◌˙ | M8: ˙ | N8: ]
J10: Noto Sans TC Medium | P10: Charis
G11: 調名 | H11: 調號 | I11: 台羅調符編碼 | J11: 台羅拼音 | K11: 方音調符編碼 | L11: 方音符號 | M11: 閩拼調符編碼 | N11: 閩拼方案 | P11: 台羅拼音
G12: 上平 | H12: 1 | J12: =IFERROR( _xlfn.CONCAT("a"), "") -> a | L12: =IFERROR( _xlfn.CONCAT("ㄚ"), "") -> ㄚ | M12: U+0304 | N12: =IFERROR( _xlfn.CONCAT("a", _xlfn.UNICHAR(HEX2DEC(RIGHT(M12,4)))), "") -> ā | P12: =IFERROR( _xlfn.CONCAT("a"), "") -> a | R12: =IFERROR( _xlfn.CONCAT("l", "u", _xlfn.UNICHAR(HEX2DEC(RIGHT($M12,4))), "n"), "") -> lūn | S12: =IFERROR( _xlfn.CONCAT("n", "g", "o", _xlfn.UNICHAR(HEX2DEC(RIGHT($M12,4))), "o"), "") -> ngōo
G13: 上聲 | H13: 2 | I13: U+0301 | J13: =IFERROR( _xlfn.CONCAT("a", _xlfn.UNICHAR(HEX2DEC(RIGHT($I13,4)))), "") -> á | K13: U+0300 | L13: =IFERROR( _xlfn.CONCAT("ㄚ", _xlfn.UNICHAR(HEX2DEC(RIGHT(K13,4)))), "") -> ㄚ̀ | M13: U+030C | N13: =IFERROR( _xlfn.CONCAT("a", _xlfn.UNICHAR(HEX2DEC(RIGHT(M13,4)))), "") -> ǎ | P13: =IFERROR( _xlfn.CONCAT("a", _xlfn.UNICHAR(HEX2DEC(RIGHT($I13,4)))), "") -> á | R13: =IFERROR( _xlfn.CONCAT("l", "u", _xlfn.UNICHAR(HEX2DEC(RIGHT($M13,4))), "n"), "") -> lǔn | S13: =IFERROR( _xlfn.CONCAT("n", "g", "o", _xlfn.UNICHAR(HEX2DEC(RIGHT($M13,4))), "o"), "") -> ngǒo
G14: 上去 | H14: 3 | I14: U+0300 | J14: =IFERROR( _xlfn.CONCAT("a", _xlfn.UNICHAR(HEX2DEC(RIGHT($I14,4)))), "") -> à | K14: U+02EA | L14: =IFERROR( _xlfn.CONCAT("ㄚ", _xlfn.UNICHAR(HEX2DEC(RIGHT(K14,4)))), "") -> ㄚ˪ | M14: U+0300 | N14: =IFERROR( _xlfn.CONCAT("a", _xlfn.UNICHAR(HEX2DEC(RIGHT(M14,4)))), "") -> à | P14: =IFERROR( _xlfn.CONCAT("a", _xlfn.UNICHAR(HEX2DEC(RIGHT($I14,4)))), "") -> à | R14: =IFERROR( _xlfn.CONCAT("l", "u", _xlfn.UNICHAR(HEX2DEC(RIGHT($M14,4))), "n"), "") -> lùn | S14: =IFERROR( _xlfn.CONCAT("n", "g", "o", _xlfn.UNICHAR(HEX2DEC(RIGHT($M14,4))), "o"), "") -> ngòo
G15: 上入 | H15: 4 | J15: =IFERROR( _xlfn.CONCAT("a", _xlfn.UNICHAR(HEX2DEC(RIGHT($I15,4)))), "") | L15: =IFERROR( _xlfn.CONCAT("ㄚ", "ㆷ"), "") -> ㄚㆷ | M15: U+0304 | N15: =IFERROR( _xlfn.CONCAT("a", _xlfn.UNICHAR(HEX2DEC(RIGHT(M15,4))), "h"), "") -> āh | P15: =IFERROR( _xlfn.CONCAT("a", _xlfn.UNICHAR(HEX2DEC(RIGHT($I15,4)))), "") | R15: =IFERROR( _xlfn.CONCAT("l", "u", _xlfn.UNICHAR(HEX2DEC(RIGHT($M15,4))), "n"), "") -> lūn | S15: =IFERROR( _xlfn.CONCAT("n", "g", "o", _xlfn.UNICHAR(HEX2DEC(RIGHT($M15,4))), "o"), "") -> ngōo
G16: 下平 | H16: 5 | I16: U+030C | J16: =IFERROR( _xlfn.CONCAT("a", _xlfn.UNICHAR(HEX2DEC(RIGHT($I16,4)))), "") -> ǎ | K16: U+0301 | L16: =IFERROR( _xlfn.CONCAT("ㄚ", _xlfn.UNICHAR(HEX2DEC(RIGHT(K16,4)))), "") -> ㄚ́ | M16: U+0301 | N16: =IFERROR( _xlfn.CONCAT("a", _xlfn.UNICHAR(HEX2DEC(RIGHT(M16,4)))), "") -> á | P16: =IFERROR( _xlfn.CONCAT("a", _xlfn.UNICHAR(HEX2DEC(RIGHT($I16,4)))), "") -> ǎ | R16: =IFERROR( _xlfn.CONCAT("l", "u", _xlfn.UNICHAR(HEX2DEC(RIGHT($M16,4))), "n"), "") -> lún | S16: =IFERROR( _xlfn.CONCAT("n", "g", "o", _xlfn.UNICHAR(HEX2DEC(RIGHT($M16,4))), "o"), "") -> ngóo
G17: 上聲 | H17: 6 | I17: U+0301 | J17: =IFERROR( _xlfn.CONCAT("a", _xlfn.UNICHAR(HEX2DEC(RIGHT($I17,4)))), "") -> á | K17: U+0300 | L17: =IFERROR( _xlfn.CONCAT("ㄚ", _xlfn.UNICHAR(HEX2DEC(RIGHT(K17,4)))), "") -> ㄚ̀ | M17: U+030C | N17: =IFERROR( _xlfn.CONCAT("a", _xlfn.UNICHAR(HEX2DEC(RIGHT(M17,4)))), "") -> ǎ | P17: =IFERROR( _xlfn.CONCAT("a", _xlfn.UNICHAR(HEX2DEC(RIGHT($I17,4)))), "") -> á | R17: =IFERROR( _xlfn.CONCAT("l", "u", _xlfn.UNICHAR(HEX2DEC(RIGHT($M17,4))), "n"), "") -> lǔn | S17: =IFERROR( _xlfn.CONCAT("n", "g", "o", _xlfn.UNICHAR(HEX2DEC(RIGHT($M17,4))), "o"), "") -> ngǒo
G18: 下入 | H18: 7 | I18: U+0304 | J18: =IFERROR( _xlfn.CONCAT("a", _xlfn.UNICHAR(HEX2DEC(RIGHT($I18,4)))), "") -> ā | K18: U+02EB | L18: =IFERROR( _xlfn.CONCAT("ㄚ", _xlfn.UNICHAR(HEX2DEC(RIGHT(K18,4)))), "") -> ㄚ˫ | M18: U+0302 | N18: =IFERROR( _xlfn.CONCAT("a", _xlfn.UNICHAR(HEX2DEC(RIGHT(M18,4)))), "") -> â | P18: =IFERROR( _xlfn.CONCAT("a", _xlfn.UNICHAR(HEX2DEC(RIGHT($I18,4)))), "") -> ā | R18: =IFERROR( _xlfn.CONCAT("l", "u", _xlfn.UNICHAR(HEX2DEC(RIGHT($M18,4))), "n"), "") -> lûn | S18: =IFERROR( _xlfn.CONCAT("n", "g", "o", _xlfn.UNICHAR(HEX2DEC(RIGHT($M18,4))), "o"), "") -> ngôo
G19: 下去 | H19: 8 | I19: U+030D | J19: =IFERROR( _xlfn.CONCAT("a", _xlfn.UNICHAR(HEX2DEC(RIGHT($I19,4)))), "") -> a̍ | K19: U+02D9 | L19: =IFERROR( _xlfn.CONCAT("ㄚ", "ㆷ", _xlfn.UNICHAR(HEX2DEC(RIGHT(K19,4)))), "") -> ㄚㆷ˙ | M19: U+0301 | N19: =IFERROR( _xlfn.CONCAT("a", _xlfn.UNICHAR(HEX2DEC(RIGHT(M19,4))), "h"), "") -> áh | P19: =IFERROR( _xlfn.CONCAT("a", _xlfn.UNICHAR(HEX2DEC(RIGHT($I19,4)))), "") -> a̍ | R19: =IFERROR( _xlfn.CONCAT("l", "u", _xlfn.UNICHAR(HEX2DEC(RIGHT($M19,4))), "n"), "") -> lún | S19: =IFERROR( _xlfn.CONCAT("n", "g", "o", _xlfn.UNICHAR(HEX2DEC(RIGHT($M19,4))), "o"), "") -> ngóo
G20: 輕聲 | H20: 9 | I20: U+030B | J20: =IFERROR( _xlfn.CONCAT("a", _xlfn.UNICHAR(HEX2DEC(RIGHT($I20,4)))), "") -> a̋ | P20: =IFERROR( _xlfn.CONCAT("a", _xlfn.UNICHAR(HEX2DEC(RIGHT($I20,4)))), "") -> a̋ | R20: =IFERROR( _xlfn.CONCAT("l", "u", _xlfn.UNICHAR(HEX2DEC(RIGHT(M20,4))), "n"), "")
G21: 輕聲 | H21: 0 | I21: U+030A | J21: =IFERROR( _xlfn.CONCAT("a", _xlfn.UNICHAR(HEX2DEC(RIGHT($I21,4)))), "") -> å | K21: U+030A | L21: =IFERROR( _xlfn.CONCAT("ㄚ", _xlfn.UNICHAR(HEX2DEC(RIGHT(K21,4)))), "") -> ㄚ̊ | P21: =IFERROR( _xlfn.CONCAT("a", _xlfn.UNICHAR(HEX2DEC(RIGHT($I21,4)))), "") -> å | R21: =IFERROR( _xlfn.CONCAT("l", "u", _xlfn.UNICHAR(HEX2DEC(RIGHT(M21,4))), "n"), "")

Sheet 十五音韻母
B2: 韻母 | D2: 馬重奇擬音 | G2: 國際音標 | I2: 閩南拼音 | K2: 台羅拼音 | S2: / | T2: 舒聲韻母 | U2: 促聲韻母 | W2: ( | X2: 舒聲韻母 | Y2: 促聲韻母
A3: =ROW() - 2 -> 1 | B3: 君 | C3: un/t | D3: un | E3: ut | F3: un | G3: un | H3: ut | I3: un | J3: ut | K3: un | L3: ut | N3: =Q3 & T3 & X3 | O3: =U3 & Y3 | S3: =IFERROR( SEARCH($S$2, $I3), "") | T3: =IFERROR(LEFT($F3, S3-1), "") | U3: =IFERROR( _xlfn.CONCAT(LEFT(T3,LEN(T3)-1), RIGHT(C3,1)), "") | W3: =IFERROR( SEARCH($W$2, $F3), "") | X3: =IF(AND(LEN(W3)>0,W3>0), LEFT(F3, LEN(F3)-3), "") | Y3: =IF(AND(LEN(W3)>0,LEN(X3)>0),_xlfn.CONCAT(X3,MID(C3,W3+1,1)), "")
A4: =ROW() - 2 -> 2 | B4: 堅 | C4: ian/t | D4: ian | E4: iat | F4: ɪan/t̚ | G4: ɪan | H4: ɪat̚ | I4: ian | J4: iat | K4: ian | L4: iat | N4: =Q4 & T4 & X4 -> ian | O4: =U4 & Y4 -> iat̚ | Q4: =IF( AND(S4="", W4=""), F4, "") | S4: =IFERROR( SEARCH($S$2, $F4), "") -> 4 | T4: =IFERROR(LEFT($I4, S4-1), "") -> ian | U4: =IFERROR( _xlfn.CONCAT(LEFT(T4,LEN(T4)-1), RIGHT(C4,1), _xlfn.UNICHAR(794)), "") -> iat̚ | W4: =IFERROR( SEARCH($W$2, $F4), "") | X4: =IF(AND(LEN(W4)>0,W4>0), LEFT(F4, LEN(F4)-3), "") | Y4: =IF(AND(LEN(W4)>0,LEN(X4)>0),_xlfn.CONCAT(X4,MID(C4,W4+1,1)), "")
A5: =ROW() - 2 -> 3 | B5: 金 | C5: im/p | D5: im | E5: ip | F5: im/p̚ | G5: im | H5: ip̚ | I5: im | J5: ip | K5: im | L5: ip | N5: =Q5 & T5 & X5 -> im | O5: =U5 & Y5 -> ip̚ | Q5: =IF( AND(S5="", W5=""), F5, "") | S5: =IFERROR( SEARCH($S$2, $F5), "") -> 3 | T5: =IFERROR(LEFT($I5, S5-1), "") -> im | U5: =IFERROR( _xlfn.CONCAT(LEFT(T5,LEN(T5)-1), RIGHT(C5,1), _xlfn.UNICHAR(794)), "") -> ip̚ | W5: =IFERROR( SEARCH($W$2, $F5), "") | X5: =IF(AND(LEN(W5)>0,W5>0), LEFT(F5, LEN(F5)-3), "") | Y5: =IF(AND(LEN(W5)>0,LEN(X5)>0),_xlfn.CONCAT(X5,MID(C5,W5+1,1)), "")
A6: =ROW() - 2 -> 4 | B6: 規 | C6: ui | D6: ui | F6: ui | G6: ui | I6: ui | K6: ui | N6: =Q6 & T6 & X6 -> ui | O6: =U6 & Y6 | Q6: =IF( AND(S6="", W6=""), F6, "") -> ui | S6: =IFERROR( SEARCH($S$2, $F6), "") | T6: =IFERROR(LEFT($I6, S6-1), "") | U6: =IFERROR( _xlfn.CONCAT(LEFT(T6,LEN(T6)-1), RIGHT(C6,1), _xlfn.UNICHAR(794)), "") | W6: =IFERROR( SEARCH($W$2, $F6), "") | X6: =IF(AND(LEN(W6)>0,W6>0), LEFT(F6, LEN(F6)-3), "") | Y6: =IF(AND(LEN(W6)>0,LEN(X6)>0),_xlfn.CONCAT(X6,MID(C6,W6+1,1)), "")
A7: =ROW() - 2 -> 5 | B7: 嘉 | C7: ɛ(ʔ) | D7: ɛ | E7: ɛʔ | F7: ɛ(ʔ) | G7: ɛ | H7: ɛʔ | I7: e | J7: eh | K7: ee | L7: eeh | N7: =Q7 & T7 & X7 -> ɛ | O7: =U7 & Y7 -> ɛʔ | Q7: =IF( AND(S7="", W7=""), F7, "") | S7: =IFERROR( SEARCH($S$2, $F7), "") | T7: =IFERROR(LEFT($I7, S7-1), "") | U7: =IFERROR( _xlfn.CONCAT(LEFT(T7,LEN(T7)-1), RIGHT(C7,1), _xlfn.UNICHAR(794)), "") | W7: =IFERROR( SEARCH($W$2, $F7), "") -> 2 | X7: =IF(AND(LEN(W7)>0,W7>0), LEFT(F7, LEN(F7)-3), "") -> ɛ | Y7: =IF(AND(LEN(W7)>0,LEN(X7)>0),_xlfn.CONCAT(X7,MID(C7,W7+1,1)), "") -> ɛʔ
A8: =ROW() - 2 -> 6 | B8: 干 | C8: an/t | D8: an | E8: at | F8: an/t̚ | G8: an | H8: at̚ | I8: an | J8: at | K8: an | L8: at | N8: =Q8 & T8 & X8 -> an | O8: =U8 & Y8 -> at̚ | Q8: =IF( AND(S8="", W8=""), F8, "") | S8: =IFERROR( SEARCH($S$2, $F8), "") -> 3 | T8: =IFERROR(LEFT($I8, S8-1), "") -> an | U8: =IFERROR( _xlfn.CONCAT(LEFT(T8,LEN(T8)-1), RIGHT(C8,1), _xlfn.UNICHAR(794)), "") -> at̚ | W8: =IFERROR( SEARCH($W$2, $F8), "") | X8: =IF(AND(LEN(W8)>0,W8>0), LEFT(F8, LEN(F8)-3), "") | Y8: =IF(AND(LEN(W8)>0,LEN(X8)>0),_xlfn.CONCAT(X8,MID(C8,W8+1,1)), "")
A9: =ROW() - 2 -> 7 | B9: 公 | C9: ɔŋ/k | D9: ɔŋ | E9: ɔk | F9: ɔŋ/k̚ | G9: ɔŋ | H9: ɔk̚ | I9: ong | J9: ok | K9: ong | L9: ok | N9: =Q9 & T9 & X9 -> on | O9: =U9 & Y9 -> ok̚ | Q9: =IF( AND(S9="", W9=""), F9, "") | S9: =IFERROR( SEARCH($S$2, $F9), "") -> 3 | T9: =IFERROR(LEFT($I9, S9-1), "") -> on | U9: =IFERROR( _xlfn.CONCAT(LEFT(T9,LEN(T9)-1), RIGHT(C9,1), _xlfn.UNICHAR(794)), "") -> ok̚ | W9: =IFERROR( SEARCH($W$2, $F9), "") | X9: =IF(AND(LEN(W9)>0,W9>0), LEFT(F9, LEN(F9)-3), "") | Y9: =IF(AND(LEN(W9)>0,LEN(X9)>0),_xlfn.CONCAT(X9,MID(C9,W9+1,1)), "")
A10: =ROW() - 2 -> 8 | B10: 乖 | C10: uai(ʔ) | D10: uai | E10: uaiʔ | F10: uai(ʔ) | G10: uai | H10: uaiʔ | I10: uai | J10: uaih | K10: uai | L10: uaih | N10: =Q10 & T10 & X10 -> uai | O10: =U10 & Y10 -> uaiʔ | Q10: =IF( AND(S10="", W10=""), F10, "") | S10: =IFERROR( SEARCH($S$2, $F10), "") | T10: =IFERROR(LEFT($I10, S10-1), "") | U10: =IFERROR( _xlfn.CONCAT(LEFT(T10,LEN(T10)-1), RIGHT(C10,1), _xlfn.UNICHAR(794)), "") | W10: =IFERROR( SEARCH($W$2, $F10), "") -> 4 | X10: =IF(AND(LEN(W10)>0,W10>0), LEFT(F10, LEN(F10)-3), "") -> uai | Y10: =IF(AND(LEN(W10)>0,LEN(X10)>0),_xlfn.CONCAT(X10,MID(C10,W10+1,1)), "") -> uaiʔ
A11: =ROW() - 2 -> 9 | B11: 經 | C11: ɛŋ/k | D11: ɛŋ | E11: ɛk | F11: ɪŋ/k̚ | G11: ɪŋ | H11: ɪk̚ | I11: ing | J11: ik | K11: ing | L11: ik | N11: =Q11 & T11 & X11 -> in | O11: =U11 & Y11 -> ik̚ | Q11: =IF( AND(S11="", W11=""), F11, "") | S11: =IFERROR( SEARCH($S$2, $F11), "") -> 3 | T11: =IFERROR(LEFT($I11, S11-1), "") -> in | U11: =IFERROR( _xlfn.CONCAT(LEFT(T11,LEN(T11)-1), RIGHT(C11,1), _xlfn.UNICHAR(794)), "") -> ik̚ | W11: =IFERROR( SEARCH($W$2, $F11), "") | X11: =IF(AND(LEN(W11)>0,W11>0), LEFT(F11, LEN(F11)-3), "") | Y11: =IF(AND(LEN(W11)>0,LEN(X11)>0),_xlfn.CONCAT(X11,MID(C11,W11+1,1)), "")
A12: =ROW() - 2 -> 10 | B12: 觀 | C12: uan/t | D12: uan | E12: uat | F12: uan/t̚ | G12: uan | H12: uat̚ | I12: uan | J12: uat | K12: uan | L12: uat | N12: =Q12 & T12 & X12 -> uan | O12: =U12 & Y12 -> uat̚ | Q12: =IF( AND(S12="", W12=""), F12, "") | S12: =IFERROR( SEARCH($S$2, $F12), "") -> 4 | T12: =IFERROR(LEFT($I12, S12-1), "") -> uan | U12: =IFERROR( _xlfn.CONCAT(LEFT(T12,LEN(T12)-1), RIGHT(C12,1), _xlfn.UNICHAR(794)), "") -> uat̚ | W12: =IFERROR( SEARCH($W$2, $F12), "") | X12: =IF(AND(LEN(W12)>0,W12>0), LEFT(F12, LEN(F12)-3), "") | Y12: =IF(AND(LEN(W12)>0,LEN(X12)>0),_xlfn.CONCAT(X12,MID(C12,W12+1,1)), "")
A13: =ROW() - 2 -> 11 | B13: 沽 | C13: ɔu | D13: ɔu | F13: ɔ | G13: ɔ | I13: oo | K13: oo | N13: =Q13 & T13 & X13 -> ɔ | O13: =U13 & Y13 | Q13: =IF( AND(S13="", W13=""), F13, "") -> ɔ | S13: =IFERROR( SEARCH($S$2, $F13), "") | T13: =IFERROR(LEFT($I13, S13-1), "") | U13: =IFERROR( _xlfn.CONCAT(LEFT(T13,LEN(T13)-1), RIGHT(C13,1), _xlfn.UNICHAR(794)), "") | W13: =IFERROR( SEARCH($W$2, $F13), "") | X13: =IF(AND(LEN(W13)>0,W13>0), LEFT(F13, LEN(F13)-3), "") | Y13: =IF(AND(LEN(W13)>0,LEN(X13)>0),_xlfn.CONCAT(X13,MID(C13,W13+1,1)), "")
A14: =ROW() - 2 -> 12 | B14: 嬌 | C14: iau(ʔ) | D14: iau | E14: iauʔ | F14: ɪaʊ(ʔ) | G14: ɪaʊ | H14: ɪaʊʔ | I14: iao | J14: iaoh | K14: iau | L14: iauh | N14: =Q14 & T14 & X14 -> ɪaʊ | O14: =U14 & Y14 -> ɪaʊʔ | Q14: =IF( AND(S14="", W14=""), F14, "") | S14: =IFERROR( SEARCH($S$2, $F14), "") | T14: =IFERROR(LEFT($I14, S14-1), "") | U14: =IFERROR( _xlfn.CONCAT(LEFT(T14,LEN(T14)-1), RIGHT(C14,1), _xlfn.UNICHAR(794)), "") | W14: =IFERROR( SEARCH($W$2, $F14), "") -> 4 | X14: =IF(AND(LEN(W14)>0,W14>0), LEFT(F14, LEN(F14)-3), "") -> ɪaʊ | Y14: =IF(AND(LEN(W14)>0,LEN(X14)>0),_xlfn.CONCAT(X14,MID(C14,W14+1,1)), "") -> ɪaʊʔ
A15: =ROW() - 2 -> 13 | B15: 稽 | C15: ei | D15: ei | F15: e | G15: e | I15: e | K15: e | N15: =Q15 & T15 & X15 -> e | O15: =U15 & Y15 | Q15: =IF( AND(S15="", W15=""), F15, "") -> e | S15: =IFERROR( SEARCH($S$2, $F15), "") | T15: =IFERROR(LEFT($I15, S15-1), "") | U15: =IFERROR( _xlfn.CONCAT(LEFT(T15,LEN(T15)-1), RIGHT(C15,1), _xlfn.UNICHAR(794)), "") | W15: =IFERROR( SEARCH($W$2, $F15), "") | X15: =IF(AND(LEN(W15)>0,W15>0), LEFT(F15, LEN(F15)-3), "") | Y15: =IF(AND(LEN(W15)>0,LEN(X15)>0),_xlfn.CONCAT(X15,MID(C15,W15+1,1)), "")
A16: =ROW() - 2 -> 14 | B16: 恭 | C16: iɔŋ/k | D16: iɔŋ | E16: iɔk | F16: ɪɔŋ/k̚ | G16: ɪɔŋ | H16: ɪɔk̚ | I16: iong | J16: iok | K16: iong | L16: iok | N16: =Q16 & T16 & X16 -> ion | O16: =U16 & Y16 -> iok̚ | Q16: =IF( AND(S16="", W16=""), F16, "") | S16: =IFERROR( SEARCH($S$2, $F16), "") -> 4 | T16: =IFERROR(LEFT($I16, S16-1), "") -> ion | U16: =IFERROR( _xlfn.CONCAT(LEFT(T16,LEN(T16)-1), RIGHT(C16,1), _xlfn.UNICHAR(794)), "") -> iok̚ | W16: =IFERROR( SEARCH($W$2, $F16), "") | X16: =IF(AND(LEN(W16)>0,W16>0), LEFT(F16, LEN(F16)-3), "") | Y16: =IF(AND(LEN(W16)>0,LEN(X16)>0),_xlfn.CONCAT(X16,MID(C16,W16+1,1)), "")
A17: =ROW() - 2 -> 15 | B17: 高 | C17: o(ʔ) | D17: o | E17: oʔ | F17: o(ʔ) | G17: o | H17: oʔ | I17: o | J17: oh | K17: o | L17: oh | N17: =Q17 & T17 & X17 -> o | O17: =U17 & Y17 -> oʔ | Q17: =IF( AND(S17="", W17=""), F17, "") | S17: =IFERROR( SEARCH($S$2, $F17), "") | T17: =IFERROR(LEFT($I17, S17-1), "") | U17: =IFERROR( _xlfn.CONCAT(LEFT(T17,LEN(T17)-1), RIGHT(C17,1), _xlfn.UNICHAR(794)), "") | W17: =IFERROR( SEARCH($W$2, $F17), "") -> 2 | X17: =IF(AND(LEN(W17)>0,W17>0), LEFT(F17, LEN(F17)-3), "") -> o | Y17: =IF(AND(LEN(W17)>0,LEN(X17)>0),_xlfn.CONCAT(X17,MID(C17,W17+1,1)), "") -> oʔ
A18: =ROW() - 2 -> 16 | B18: 皆 | C18: ai | D18: ai | F18: aɪ | G18: aɪ | I18: ai | K18: ai | N18: =Q18 & T18 & X18 -> aɪ | O18: =U18 & Y18 | Q18: =IF( AND(S18="", W18=""), F18, "") -> aɪ | S18: =IFERROR( SEARCH($S$2, $F18), "") | T18: =IFERROR(LEFT($I18, S18-1), "") | U18: =IFERROR( _xlfn.CONCAT(LEFT(T18,LEN(T18)-1), RIGHT(C18,1), _xlfn.UNICHAR(794)), "") | W18: =IFERROR( SEARCH($W$2, $F18), "") | X18: =IF(AND(LEN(W18)>0,W18>0), LEFT(F18, LEN(F18)-3), "") | Y18: =IF(AND(LEN(W18)>0,LEN(X18)>0),_xlfn.CONCAT(X18,MID(C18,W18+1,1)), "")
A19: =ROW() - 2 -> 17 | B19: 巾 | C19: in/t | D19: in | E19: it | F19: in/t̚ | G19: in | H19: it̚ | I19: in | J19: it | K19: in | L19: it | N19: =Q19 & T19 & X19 -> in | O19: =U19 & Y19 -> it̚ | Q19: =IF( AND(S19="", W19=""), F19, "") | S19: =IFERROR( SEARCH($S$2, $F19), "") -> 3 | T19: =IFERROR(LEFT($I19, S19-1), "") -> in | U19: =IFERROR( _xlfn.CONCAT(LEFT(T19,LEN(T19)-1), RIGHT(C19,1), _xlfn.UNICHAR(794)), "") -> it̚ | W19: =IFERROR( SEARCH($W$2, $F19), "") | X19: =IF(AND(LEN(W19)>0,W19>0), LEFT(F19, LEN(F19)-3), "") | Y19: =IF(AND(LEN(W19)>0,LEN(X19)>0),_xlfn.CONCAT(X19,MID(C19,W19+1,1)), "")
A20: =ROW() - 2 -> 18 | B20: 姜 | C20: iaŋ/k | D20: iaŋ | E20: iak | F20: ɪaŋ/k̚ | G20: ɪaŋ | H20: ɪak̚ | I20: iang | J20: iak | K20: iang | L20: iak | N20: =Q20 & T20 & X20 -> ian | O20: =U20 & Y20 -> iak̚ | Q20: =IF( AND(S20="", W20=""), F20, "") | S20: =IFERROR( SEARCH($S$2, $F20), "") -> 4 | T20: =IFERROR(LEFT($I20, S20-1), "") -> ian | U20: =IFERROR( _xlfn.CONCAT(LEFT(T20,LEN(T20)-1), RIGHT(C20,1), _xlfn.UNICHAR(794)), "") -> iak̚ | W20: =IFERROR( SEARCH($W$2, $F20), "") | X20: =IF(AND(LEN(W20)>0,W20>0), LEFT(F20, LEN(F20)-3), "") | Y20: =IF(AND(LEN(W20)>0,LEN(X20)>0),_xlfn.CONCAT(X20,MID(C20,W20+1,1)), "")
A21: =ROW() - 2 -> 19 | B21: 甘 | C21: am/p | D21: am | E21: ap | F21: am/p̚ | G21: am | H21: ap̚ | I21: am | J21: ap | K21: am | L21: ap | N21: =Q21 & T21 & X21 -> am | O21: =U21 & Y21 -> ap̚ | Q21: =IF( AND(S21="", W21=""), F21, "") | S21: =IFERROR( SEARCH($S$2, $F21), "") -> 3 | T21: =IFERROR(LEFT($I21, S21-1), "") -> am | U21: =IFERROR( _xlfn.CONCAT(LEFT(T21,LEN(T21)-1), RIGHT(C21,1), _xlfn.UNICHAR(794)), "") -> ap̚ | W21: =IFERROR( SEARCH($W$2, $F21), "") | X21: =IF(AND(LEN(W21)>0,W21>0), LEFT(F21, LEN(F21)-3), "") | Y21: =IF(AND(LEN(W21)>0,LEN(X21)>0),_xlfn.CONCAT(X21,MID(C21,W21+1,1)), "")
A22: =ROW() - 2 -> 20 | B22: 瓜 | C22: ua(ʔ) | D22: ua | E22: uaʔ | F22: ua(ʔ) | G22: ua | H22: uaʔ | I22: ua | J22: uah | K22: ua | L22: uah | N22: =Q22 & T22 & X22 -> ua | O22: =U22 & Y22 -> uaʔ | Q22: =IF( AND(S22="", W22=""), F22, "") | S22: =IFERROR( SEARCH($S$2, $F22), "") | T22: =IFERROR(LEFT($I22, S22-1), "") | U22: =IFERROR( _xlfn.CONCAT(LEFT(T22,LEN(T22)-1), RIGHT(C22,1), _xlfn.UNICHAR(794)), "") | W22: =IFERROR( SEARCH($W$2, $F22), "") -> 3 | X22: =IF(AND(LEN(W22)>0,W22>0), LEFT(F22, LEN(F22)-3), "") -> ua | Y22: =IF(AND(LEN(W22)>0,LEN(X22)>0),_xlfn.CONCAT(X22,MID(C22,W22+1,1)), "") -> uaʔ
A23: =ROW() - 2 -> 21 | B23: 江 | C23: aŋ/k | D23: aŋ | E23: ak | F23: aŋ/k̚ | G23: aŋ | H23: ak̚ | I23: ang | J23: ak | K23: ang | L23: ak | N23: =Q23 & T23 & X23 -> an | O23: =U23 & Y23 -> ak̚ | Q23: =IF( AND(S23="", W23=""), F23, "") | S23: =IFERROR( SEARCH($S$2, $F23), "") -> 3 | T23: =IFERROR(LEFT($I23, S23-1), "") -> an | U23: =IFERROR( _xlfn.CONCAT(LEFT(T23,LEN(T23)-1), RIGHT(C23,1), _xlfn.UNICHAR(794)), "") -> ak̚ | W23: =IFERROR( SEARCH($W$2, $F23), "") | X23: =IF(AND(LEN(W23)>0,W23>0), LEFT(F23, LEN(F23)-3), "") | Y23: =IF(AND(LEN(W23)>0,LEN(X23)>0),_xlfn.CONCAT(X23,MID(C23,W23+1,1)), "")
A24: =ROW() - 2 -> 22 | B24: 兼 | C24: iam/p | D24: iam | E24: iap | F24: iam/p̚ | G24: iam | H24: iap̚ | I24: iam | J24: iap | K24: iam | L24: iap | N24: =Q24 & T24 & X24 -> iam | O24: =U24 & Y24 -> iap̚ | Q24: =IF( AND(S24="", W24=""), F24, "") | S24: =IFERROR( SEARCH($S$2, $F24), "") -> 4 | T24: =IFERROR(LEFT($I24, S24-1), "") -> iam | U24: =IFERROR( _xlfn.CONCAT(LEFT(T24,LEN(T24)-1), RIGHT(C24,1), _xlfn.UNICHAR(794)), "") -> iap̚ | W24: =IFERROR( SEARCH($W$2, $F24), "") | X24: =IF(AND(LEN(W24)>0,W24>0), LEFT(F24, LEN(F24)-3), "") | Y24: =IF(AND(LEN(W24)>0,LEN(X24)>0),_xlfn.CONCAT(X24,MID(C24,W24+1,1)), "")
A25: =ROW() - 2 -> 23 | B25: 交 | C25: au(ʔ) | D25: au | E25: auʔ | F25: aʊ(ʔ) | G25: aʊ | H25: aʊʔ | I25: ao | J25: aoh | K25: au | L25: auh | N25: =Q25 & T25 & X25 -> aʊ | O25: =U25 & Y25 -> aʊʔ | Q25: =IF( AND(S25="", W25=""), F25, "") | S25: =IFERROR( SEARCH($S$2, $F25), "") | T25: =IFERROR(LEFT($I25, S25-1), "") | U25: =IFERROR( _xlfn.CONCAT(LEFT(T25,LEN(T25)-1), RIGHT(C25,1), _xlfn.UNICHAR(794)), "") | W25: =IFERROR( SEARCH($W$2, $F25), "") -> 3 | X25: =IF(AND(LEN(W25)>0,W25>0), LEFT(F25, LEN(F25)-3), "") -> aʊ | Y25: =IF(AND(LEN(W25)>0,LEN(X25)>0),_xlfn.CONCAT(X25,MID(C25,W25+1,1)), "") -> aʊʔ
A26: =ROW() - 2 -> 24 | B26: 迦 | C26: ia(ʔ) | D26: ia | E26: iaʔ | F26: ɪa(ʔ) | G26: ɪa | H26: ɪaʔ | I26: ia | J26: iah | K26: ia | L26: iah | N26: =Q26 & T26 & X26 -> ɪa | O26: =U26 & Y26 -> ɪaʔ | Q26: =IF( AND(S26="", W26=""), F26, "") | S26: =IFERROR( SEARCH($S$2, $F26), "") | T26: =IFERROR(LEFT($I26, S26-1), "") | U26: =IFERROR( _xlfn.CONCAT(LEFT(T26,LEN(T26)-1), RIGHT(C26,1), _xlfn.UNICHAR(794)), "") | W26: =IFERROR( SEARCH($W$2, $F26), "") -> 3 | X26: =IF(AND(LEN(W26)>0,W26>0), LEFT(F26, LEN(F26)-3), "") -> ɪa | Y26: =IF(AND(LEN(W26)>0,LEN(X26)>0),_xlfn.CONCAT(X26,MID(C26,W26+1,1)), "") -> ɪaʔ
A27: =ROW() - 2 -> 25 | B27: 檜 | C27: uei(ʔ) | D27: uei | E27: ueiʔ | F27: ue(ʔ) | G27: ue | H27: ueʔ | I27: ue | J27: ueh | K27: ue | L27: ueh | N27: =Q27 & T27 & X27 -> ue | O27: =U27 & Y27 -> ue( | Q27: =IF( AND(S27="", W27=""), F27, "") | S27: =IFERROR( SEARCH($S$2, $F27), "") | T27: =IFERROR(LEFT($I27, S27-1), "") | U27: =IFERROR( _xlfn.CONCAT(LEFT(T27,LEN(T27)-1), RIGHT(C27,1), _xlfn.UNICHAR(794)), "") | W27: =IFERROR( SEARCH($W$2, $F27), "") -> 3 | X27: =IF(AND(LEN(W27)>0,W27>0), LEFT(F27, LEN(F27)-3), "") -> ue | Y27: =IF(AND(LEN(W27)>0,LEN(X27)>0),_xlfn.CONCAT(X27,MID(C27,W27+1,1)), "") -> ue(
A28: =ROW() - 2 -> 26 | B28: 監 | C28: ã(ʔ) | D28: ã | E28: ãʔ | F28: ã(ʔ) | G28: ã | H28: ãʔ | I28: na | J28: nah | K28: ann | L28: annh | N28: =Q28 & T28 & X28 -> ã | O28: =U28 & Y28 -> ãʔ | Q28: =IF( AND(S28="", W28=""), F28, "") | S28: =IFERROR( SEARCH($S$2, $F28), "") | T28: =IFERROR(LEFT($I28, S28-1), "") | U28: =IFERROR( _xlfn.CONCAT(LEFT(T28,LEN(T28)-1), RIGHT(C28,1), _xlfn.UNICHAR(794)), "") | W28: =IFERROR( SEARCH($W$2, $F28), "") -> 2 | X28: =IF(AND(LEN(W28)>0,W28>0), LEFT(F28, LEN(F28)-3), "") -> ã | Y28: =IF(AND(LEN(W28)>0,LEN(X28)>0),_xlfn.CONCAT(X28,MID(C28,W28+1,1)), "") -> ãʔ
A29: =ROW() - 2 -> 27 | B29: 艍 | C29: u(ʔ) | D29: u | E29: uʔ | F29: u(ʔ) | G29: u | H29: uʔ | I29: u | J29: uh | K29: u | L29: uh | N29: =Q29 & T29 & X29 -> u | O29: =U29 & Y29 -> uʔ | Q29: =IF( AND(S29="", W29=""), F29, "") | S29: =IFERROR( SEARCH($S$2, $F29), "") | T29: =IFERROR(LEFT($I29, S29-1), "") | U29: =IFERROR( _xlfn.CONCAT(LEFT(T29,LEN(T29)-1), RIGHT(C29,1), _xlfn.UNICHAR(794)), "") | W29: =IFERROR( SEARCH($W$2, $F29), "") -> 2 | X29: =IF(AND(LEN(W29)>0,W29>0), LEFT(F29, LEN(F29)-3), "") -> u | Y29: =IF(AND(LEN(W29)>0,LEN(X29)>0),_xlfn.CONCAT(X29,MID(C29,W29+1,1)), "") -> uʔ
A30: =ROW() - 2 -> 28 | B30: 膠 | C30: a(ʔ) | D30: a | E30: aʔ | F30: a(ʔ) | G30: a | H30: aʔ | I30: a | J30: ah | K30: a | L30: ah | N30: =Q30 & T30 & X30 -> a | O30: =U30 & Y30 -> aʔ | Q30: =IF( AND(S30="", W30=""), F30, "") | S30: =IFERROR( SEARCH($S$2, $F30), "") | T30: =IFERROR(LEFT($I30, S30-1), "") | U30: =IFERROR( _xlfn.CONCAT(LEFT(T30,LEN(T30)-1), RIGHT(C30,1), _xlfn.UNICHAR(794)), "") | W30: =IFERROR( SEARCH($W$2, $F30), "") -> 2 | X30: =IF(AND(LEN(W30)>0,W30>0), LEFT(F30, LEN(F30)-3), "") -> a | Y30: =IF(AND(LEN(W30)>0,LEN(X30)>0),_xlfn.CONCAT(X30,MID(C30,W30+1,1)), "") -> aʔ
A31: =ROW() - 2 -> 29 | B31: 居 | C31: i(ʔ) | D31: i | E31: iʔ | F31: i(ʔ) | G31: i | H31: iʔ | I31: i | J31: ih | K31: i | L31: ih | N31: =Q31 & T31 & X31 -> i | O31: =U31 & Y31 -> iʔ | Q31: =IF( AND(S31="", W31=""), F31, "") | S31: =IFERROR( SEARCH($S$2, $F31), "") | T31: =IFERROR(LEFT($I31, S31-1), "") | U31: =IFERROR( _xlfn.CONCAT(LEFT(T31,LEN(T31)-1), RIGHT(C31,1), _xlfn.UNICHAR(794)), "") | W31: =IFERROR( SEARCH($W$2, $F31), "") -> 2 | X31: =IF(AND(LEN(W31)>0,W31>0), LEFT(F31, LEN(F31)-3), "") -> i | Y31: =IF(AND(LEN(W31)>0,LEN(X31)>0),_xlfn.CONCAT(X31,MID(C31,W31+1,1)), "") -> iʔ
A32: =ROW() - 2 -> 30 | B32: 丩 | C32: iu | D32: iu | F32: iu | G32: iu | I32: iu | K32: iu | N32: =Q32 & T32 & X32 -> iu | O32: =U32 & Y32 | Q32: =IF( AND(S32="", W32=""), F32, "") -> iu | S32: =IFERROR( SEARCH($S$2, $F32), "") | T32: =IFERROR(LEFT($I32, S32-1), "") | U32: =IFERROR( _xlfn.CONCAT(LEFT(T32,LEN(T32)-1), RIGHT(C32,1), _xlfn.UNICHAR(794)), "") | W32: =IFERROR( SEARCH($W$2, $F32), "") | X32: =IF(AND(LEN(W32)>0,W32>0), LEFT(F32, LEN(F32)-3), "") | Y32: =IF(AND(LEN(W32)>0,LEN(X32)>0),_xlfn.CONCAT(X32,MID(C32,W32+1,1)), "")
A33: =ROW() - 2 -> 31 | B33: 更 | C33: ɛ̃ | D33: ɛ̃ | F33: ẽ | G33: ẽ | I33: ne | K33: enn | N33: =Q33 & T33 & X33 -> ẽ | O33: =U33 & Y33 | Q33: =IF( AND(S33="", W33=""), F33, "") -> ẽ | S33: =IFERROR( SEARCH($S$2, $F33), "") | T33: =IFERROR(LEFT($I33, S33-1), "") | U33: =IFERROR( _xlfn.CONCAT(LEFT(T33,LEN(T33)-1), RIGHT(C33,1), _xlfn.UNICHAR(794)), "") | W33: =IFERROR( SEARCH($W$2, $F33), "") | X33: =IF(AND(LEN(W33)>0,W33>0), LEFT(F33, LEN(F33)-3), "") | Y33: =IF(AND(LEN(W33)>0,LEN(X33)>0),_xlfn.CONCAT(X33,MID(C33,W33+1,1)), "")
A34: =ROW() - 2 -> 32 | B34: 褌 | C34: ũĩ | D34: ũĩ | F34: ũĩ | G34: ũĩ | I34: nui | K34: uinn | N34: =Q34 & T34 & X34 -> ũĩ | O34: =U34 & Y34 | Q34: =IF( AND(S34="", W34=""), F34, "") -> ũĩ | S34: =IFERROR( SEARCH($S$2, $F34), "") | T34: =IFERROR(LEFT($I34, S34-1), "") | U34: =IFERROR( _xlfn.CONCAT(LEFT(T34,LEN(T34)-1), RIGHT(C34,1), _xlfn.UNICHAR(794)), "") | W34: =IFERROR( SEARCH($W$2, $F34), "") | X34: =IF(AND(LEN(W34)>0,W34>0), LEFT(F34, LEN(F34)-3), "") | Y34: =IF(AND(LEN(W34)>0,LEN(X34)>0),_xlfn.CONCAT(X34,MID(C34,W34+1,1)), "")
A35: =ROW() - 2 -> 33 | B35: 茄 | C35: io(ʔ) | D35: io | E35: ioʔ | F35: ɪo(ʔ) | G35: ɪo | H35: ɪoʔ | I35: io | J35: ioh | K35: io | L35: ioh | N35: =Q35 & T35 & X35 -> ɪo | O35: =U35 & Y35 -> ɪoʔ | Q35: =IF( AND(S35="", W35=""), F35, "") | S35: =IFERROR( SEARCH($S$2, $F35), "") | T35: =IFERROR(LEFT($I35, S35-1), "") | U35: =IFERROR( _xlfn.CONCAT(LEFT(T35,LEN(T35)-1), RIGHT(C35,1), _xlfn.UNICHAR(794)), "") | W35: =IFERROR( SEARCH($W$2, $F35), "") -> 3 | X35: =IF(AND(LEN(W35)>0,W35>0), LEFT(F35, LEN(F35)-3), "") -> ɪo | Y35: =IF(AND(LEN(W35)>0,LEN(X35)>0),_xlfn.CONCAT(X35,MID(C35,W35+1,1)), "") -> ɪoʔ
A36: =ROW() - 2 -> 34 | B36: 梔 | C36: ĩ(ʔ) | D36: ĩ | E36: ĩʔ | F36: ĩ(ʔ) | G36: ĩ | H36: ĩʔ | I36: ni | J36: nih | K36: inn | L36: innh | N36: =Q36 & T36 & X36 -> ĩ | O36: =U36 & Y36 -> ĩʔ | Q36: =IF( AND(S36="", W36=""), F36, "") | S36: =IFERROR( SEARCH($S$2, $F36), "") | T36: =IFERROR(LEFT($I36, S36-1), "") | U36: =IFERROR( _xlfn.CONCAT(LEFT(T36,LEN(T36)-1), RIGHT(C36,1), _xlfn.UNICHAR(794)), "") | W36: =IFERROR( SEARCH($W$2, $F36), "") -> 2 | X36: =IF(AND(LEN(W36)>0,W36>0), LEFT(F36, LEN(F36)-3), "") -> ĩ | Y36: =IF(AND(LEN(W36)>0,LEN(X36)>0),_xlfn.CONCAT(X36,MID(C36,W36+1,1)), "") -> ĩʔ
A37: =ROW() - 2 -> 35 | B37: 薑 | C37: ĩõ | D37: ĩõ | F37: ĩɔ̃ | G37: ĩɔ̃ | I37: nioo | K37: ionn | N37: =Q37 & T37 & X37 -> ĩɔ̃ | O37: =U37 & Y37 | Q37: =IF( AND(S37="", W37=""), F37, "") -> ĩɔ̃ | S37: =IFERROR( SEARCH($S$2, $F37), "") | T37: =IFERROR(LEFT($I37, S37-1), "") | U37: =IFERROR( _xlfn.CONCAT(LEFT(T37,LEN(T37)-1), RIGHT(C37,1), _xlfn.UNICHAR(794)), "") | W37: =IFERROR( SEARCH($W$2, $F37), "") | X37: =IF(AND(LEN(W37)>0,W37>0), LEFT(F37, LEN(F37)-3), "") | Y37: =IF(AND(LEN(W37)>0,LEN(X37)>0),_xlfn.CONCAT(X37,MID(C37,W37+1,1)), "")
