Workbook
Name 方音符號: #REF!
Name 方音符號: #REF!
Name 方音符號: #REF!
Name 方音符號: #REF!
Name 方音符號: #REF!
Name 方音符號: #REF!
Name 方音符號: #REF!
Name 方音符號: [1]RIME編碼!$AA$3:$AA$45
Name 字典編碼: #REF!
Name 字典編碼: #REF!
Name 字典編碼: #REF!
Name 字典編碼: #REF!
Name 字典編碼: #REF!
Name 字典編碼: #REF!
Name 字典編碼: #REF!
Name 字典編碼: [1]RIME編碼!$AB$3:$AB$45
Name 注音符號: #REF!
Name 注音編碼: #REF!
Name 拼音字母: #REF!
Name 拼音字母: #REF!
Name 拼音字母: #REF!
Name 拼音字母: #REF!
Name 拼音字母: #REF!
Name 拼音字母: #REF!
Name 拼音字母: #REF!
Name 拼音字母: [1]RIME編碼!$AC$3:$AC$45
Name 鍵盤位置: #REF!
Name 鍵盤位置: #REF!
Name 鍵盤位置: #REF!
Name 鍵盤位置: #REF!
Name 鍵盤位置: #REF!
Name 鍵盤位置: #REF!
Name 鍵盤位置: #REF!
Name 鍵盤位置: [1]RIME編碼!$W$3:$W$40
Name 鍵盤按鍵: #REF!

Sheet 注音編碼對照表
B1: 聲母與韻母表
B2: 序號 | C2: 國際音標 | D2: 台語音標 | E2: 注音符號 | F2: 漢字例 | G2: 聲韻調 | H2: 十五音 | I2: 台羅拼音 | J2: 白話字 | K2: 閩拼方案 | L2: 注音二式 | M2: 附註
B3: =ROW() - 2 -> 1 | C3: b | D3: b | E3: ㆠ | F3: 眉 | G3: 聲 | H3: 門 | I3: b | J3: b | K3: bb | L3: bb
B4: =ROW() - 2 -> 2 | C4: p | D4: p | E4: ㄅ | F4: 幫 | G4: 聲 | H4: 邊 | I4: p | J4: p | K4: b | L4: b
B5: =ROW() - 2 -> 3 | C5: pʰ | D5: ph | E5: ㄆ | F5: 普 | G5: 聲 | H5: 頗 | I5: ph | J5: ph | K5: p | L5: p
B6: =ROW() - 2 -> 4 | C6: m | D6: m | E6: ㄇ | F6: 名 | G6: 聲 | H6: 門 | I6: m | J6: m | K6: bbn | L6: m | M6: 門/毛
B7: =ROW() - 2 -> 5 | C7: n | D7: n | E7: ㄋ | F7: 泥 | G7: 聲 | H7: 柳 | I7: n | J7: n | K7: ln | L7: n | M7: 柳/耐
B8: =ROW() - 2 -> 6 | C8: t | D8: t | E8: ㄉ | F8: 端 | G8: 聲 | H8: 地 | I8: t | J8: t | K8: d | L8: d
B9: =ROW() - 2 -> 7 | C9: tʰ | D9: th | E9: ㄊ | F9: 透 | G9: 聲 | H9: 他 | I9: th | J9: th | K9: t | L9: t
B10: =ROW() - 2 -> 8 | C10: l | D10: l | E10: ㄌ | F10: 來 | G10: 聲 | H10: 柳 | I10: l | J10: l | K10: l | L10: l
B11: =ROW() - 2 -> 9 | C11: g | D11: g | E11: ㆣ | F11: 疑 | G11: 聲 | H11: 語 | I11: g | J11: g | K11: gg | L11: gg
B12: =ROW() - 2 -> 10 | C12: k | D12: k | E12: ㄍ | F12: 見 | G12: 聲 | H12: 求 | I12: k | J12: k | K12: g | L12: g
B13: =ROW() - 2 -> 11 | C13: kʰ | D13: kh | E13: ㄎ | F13: 溪 | G13: 聲 | H13: 氣 | I13: kh | J13: kh | K13: k | L13: k
B14: =ROW() - 2 -> 12 | C14: ŋ | D14: ng | E14: ㄫ | F14: 吳 | G14: 聲 | H14: 語 | I14: ng | J14: ng | K14: ggn | L14: ng | M14: 語/雅
B15: =ROW() - 2 -> 13 | C15: d͡z | D15: j | E15: ㆡ | F15: 熱 | G15: 聲 | H15: 入 | I15: j | J15: j | K15: zz | L15: zz
B16: =ROW() - 2 -> 14 | C16: t͡s | D16: z | E16: ㄗ | F16: 裝 | G16: 聲 | H16: 曾 | I16: ts | J16: ch | K16: z | L16: z
B17: =ROW() - 2 -> 15 | C17: t͡sʰ | D17: c | E17: ㄘ | F17: 初 | G17: 聲 | H17: 出 | I17: tsh | J17: chh | K17: c | L17: c
B18: =ROW() - 2 -> 16 | C18: s | D18: s | E18: ㄙ | F18: 疏 | G18: 聲 | H18: 時 | I18: s | J18: s | K18: s | L18: s
B19: =ROW() - 2 -> 17 | C19: h | D19: h | E19: ㄏ | F19: 雨 | G19: 聲 | H19: 喜 | I19: h | J19: h | K19: h | L19: h | M19: h入聲韻尾編碼：【H】
B20: =ROW() - 2 -> 18 | C20: d͡ʑ | D20: ji | E20: ㆢ | F20: 日 | G20: 聲 | H20: 入 | I20: ji | J20: ji | L20: jj
B21: =ROW() - 2 -> 19 | C21: t͡ɕ | D21: zi | E21: ㄐ | F21: 精 | G21: 聲 | H21: 曾 | I21: zi | J21: zi | L21: j
B22: =ROW() - 2 -> 20 | C22: t͡ɕʰ | D22: ci | E22: ㄑ | F22: 清 | G22: 聲 | H22: 出 | I22: ci | J22: ci | L22: ch
B23: =ROW() - 2 -> 21 | C23: ɕ | D23: si | E23: ㄒ | F23: 心 | G23: 聲 | H23: 時 | I23: si | J23: si | L23: sh
B24: =ROW() - 2 -> 22 | C24: a | D24: a | E24: ㄚ | F24: 阿 | G24: 韻 | H24: 膠 | I24: a | J24: a | K24: a | L24: a
B25: =ROW() - 2 -> 23 | C25: i | D25: i | E25: ㄧ | F25: 伊 | G25: 韻 | H25: 居 | I25: i | J25: i | K25: i | L25: i
B26: =ROW() - 2 -> 24 | C26: ɯ | D26: ir | E26: ㆨ | F26: 猪 | G26: 韻 | I26: ir | J26: ir | K26: eu | L26: ir
B27: =ROW() - 2 -> 25 | C27: u | D27: u | E27: ㄨ | F27: 污 | G27: 韻 | H27: 艍 | I27: u | J27: u | K27: u | L27: u
B28: =ROW() - 2 -> 26 | C28: e | D28: e | E28: ㆤ | F28: 稽 | G28: 韻 | H28: 伽 | I28: e | J28: e | K28: e | L28: e
B29: =ROW() - 2 -> 27 | C29: ɔ | D29: oo | E29: ㆦ | F29: 烏 | G29: 韻 | H29: 沽 | I29: oo | J29: oo | K29: oo | L29: oo
B30: =ROW() - 2 -> 28 | C30: o | D30: o | E30: ㄜ | F30: 蚵 | G30: 韻 | H30: 高 | I30: o | J30: o | K30: o | L30: or
B31: =ROW() - 2 -> 29 | C31: m̩ | D31: -m | E31: ㆬ | F31: 姆 | G31: 韻 | H31: 姆 | I31: m | J31: m | K31: m | L31: m
B32: =ROW() - 2 -> 30 | C32: n | D32: -n | E32: ㄣ | F32: 恩 | G32: 韻 | I32: n | J32: n | K32: n | L32: n | M32: n鼻音韻尾編碼：【N】
B33: =ROW() - 2 -> 31 | C33: ŋ̍ | D33: -ng | E33: ㆭ | F33: 秧 | G33: 韻 | H33: 鋼 | I33: ng | J33: ng | K33: ng | L33: ng | M33: ng鼻音韻尾編碼：【G】
B34: =ROW() - 2 -> 32 | C34: ai | D34: ai | E34: ㄞ | F34: 哀 | G34: 韻 | H34: 皆 | I34: ai | J34: ai | K34: ai | L34: ai
B35: =ROW() - 2 -> 33 | C35: aʊ | D35: au | E35: ㄠ | F35: 甌 | G35: 韻 | H35: 交 | I35: au | J35: au | K35: ao | L35: au
B36: =ROW() - 2 -> 34 | C36: am | D36: am | E36: ㆰ | F36: 庵 | G36: 韻 | H36: 甘 | I36: am | J36: am | K36: am | L36: am | M36: 【ㆱ】共用【m】按鍵；【編碼】=【v】
B37: =ROW() - 2 -> 35 | C37: an | D37: an | E37: ㄢ | F37: 安 | G37: 韻 | H37: 干 | I37: an | J37: an | K37: an | L37: an
B38: =ROW() - 2 -> 36 | C38: aŋ | D38: ang | E38: ㄤ | F38: 尪 | G38: 韻 | H38: 江 | I38: ang | J38: ang | K38: ang | L38: ang
B39: =ROW() - 2 -> 37 | C39: ɔm | D39: om | E39: ㆱ | F39: 丼 | G39: 韻 | H39: 箴 | I39: om | J39: om | K39: - | L39: om | M39: 【ㆱ】共用【m】按鍵；【編碼】=【v】
B40: =ROW() - 2 -> 38 | C40: ɔŋ | D40: ong | E40: ㆲ | F40: 汪 | G40: 韻 | H40: 公 | I40: ong | J40: ong | K40: ong | L40: ong | M40: 原用【H】；ang【f】；ong【F】
...

Sheet 按鍵設計
U1: 公式準則
U2: =LEN(#REF!)>0 -> #REF!
B4: 序號 | C4: 鍵盤按鍵 | D4: 台語音標 | E4: 字典編碼 | F4: 極簡編碼 | G4: 注音符號 | H4: 漢字例 | I4: 聲韻調 | J4: 十五音 | K4: 注音二式 | L4: 台羅拼音 | M4: 白話字 | N4: 閩拼方案 | O4: 附註 | T4: 序號 | U4: 鍵盤按鍵 | V4: 注音符號 | W4: 注音編碼 | X4: 注音二式 | Y4: 閩拼方案 | Z4: 台語拼音 | AA4: 聲韻調 | AB4: 附註 | AD4: 序號 | AE4: 按鍵字元 | AF4: 按鍵編碼 | AG4: 注音符號 | AH4: 音標字母 | AJ4: 按鍵編碼 | AK4: 鍵盤按鍵 | AL4: 國際音標 | AM4: 注音符號 | AN4: 注音二式 | AO4: 台語音標
B5: =ROW() - 4 -> 1 | C5: ! | D5: b | E5: b | F5: b | G5: =_xlfn.XLOOKUP(按鍵設計表[[#This Row],[台語音標]], 注音編碼對照表[台語音標], 注音編碼對照表[注音符號], "") -> ㆠ | H5: =_xlfn.XLOOKUP(按鍵設計表[[#This Row],[台語音標]], 注音編碼對照表[台語音標], 注音編碼對照表[漢字例], "") -> 眉 | I5: =_xlfn.XLOOKUP(按鍵設計表[[#This Row],[台語音標]], 注音編碼對照表[台語音標], 注音編碼對照表[聲韻調], "") -> 聲 | J5: =_xlfn.XLOOKUP(按鍵設計表[[#This Row],[台語音標]], 注音編碼對照表[台語音標], 注音編碼對照表[十五音], "") -> 門 | K5: =_xlfn.XLOOKUP(按鍵設計表[[#This Row],[台語音標]], 注音編碼對照表[台語音標], 注音編碼對照表[注音二式], "") -> bb | L5: =_xlfn.XLOOKUP(按鍵設計表[[#This Row],[台語音標]], 注音編碼對照表[台語音標], 注音編碼對照表[台羅拼音], "") -> b | M5: =_xlfn.XLOOKUP(按鍵設計表[[#This Row],[台語音標]], 注音編碼對照表[台語音標], 注音編碼對照表[白話字], "") -> b | N5: =_xlfn.XLOOKUP(按鍵設計表[[#This Row],[台語音標]], 注音編碼對照表[台語音標], 注音編碼對照表[閩拼方案], "") -> bb | Q5: =LEN(按鍵設計表[[#This Row],[注音符號]]) -> 1 | S5: =ROW() - 4 -> 1 | T5: =ROW() - 4 -> 1 | U5: 1 | V5: ㄅ | W5: p | X5: b | Y5: b | Z5: p | AA5: 聲 | AB5: p入聲韻尾編碼：【P】 | AD5: 1 | AE5: 1 | AF5: b | AG5: ㄅ | AH5: b | AJ5: 1 | AK5: =CHAR(32) | AM5: ˉ | AN5: 1 | AO5: 1
B6: =ROW() - 4 -> 2 | C6: 1 | D6: p | E6: p | F6: p | G6: =_xlfn.XLOOKUP(按鍵設計表[[#This Row],[台語音標]], 注音編碼對照表[台語音標], 注音編碼對照表[注音符號], "") -> ㄅ | H6: =_xlfn.XLOOKUP(按鍵設計表[[#This Row],[台語音標]], 注音編碼對照表[台語音標], 注音編碼對照表[漢字例], "") -> 幫 | I6: =_xlfn.XLOOKUP(按鍵設計表[[#This Row],[台語音標]], 注音編碼對照表[台語音標], 注音編碼對照表[聲韻調], "") -> 聲 | J6: =_xlfn.XLOOKUP(按鍵設計表[[#This Row],[台語音標]], 注音編碼對照表[台語音標], 注音編碼對照表[十五音], "") -> 邊 | K6: =_xlfn.XLOOKUP(按鍵設計表[[#This Row],[台語音標]], 注音編碼對照表[台語音標], 注音編碼對照表[注音二式], "") -> b | L6: =_xlfn.XLOOKUP(按鍵設計表[[#This Row],[台語音標]], 注音編碼對照表[台語音標], 注音編碼對照表[台羅拼音], "") -> p | M6: =_xlfn.XLOOKUP(按鍵設計表[[#This Row],[台語音標]], 注音編碼對照表[台語音標], 注音編碼對照表[白話字], "") -> p | N6: =_xlfn.XLOOKUP(按鍵設計表[[#This Row],[台語音標]], 注音編碼對照表[台語音標], 注音編碼對照表[閩拼方案], "") -> b | O6: p入聲韻尾編碼：【P】 | P6: =ISBLANK(按鍵設計表[[#This Row],[注音符號]]) -> FALSE | Q6: =LEN(按鍵設計表[[#This Row],[注音符號]]) -> 1 | S6: =ROW() - 4 -> 2 | T6: =ROW() - 4 -> 2 | U6: ! | V6: ㆠ | W6: b | X6: bb | Y6: bb | Z6: b | AA6: 聲 | AD6: 2 | AE6: ! | AF6: B | AG6: ㆠ | AH6: bb | AJ6: 2 | AK6: 4 | AM6: ˋ | AN6: 2 | AO6: 2
B7: =ROW() - 4 -> 3 | C7: q | D7: ph | E7: P | F7: P | G7: =_xlfn.XLOOKUP(按鍵設計表[[#This Row],[台語音標]], 注音編碼對照表[台語音標], 注音編碼對照表[注音符號], "") -> ㄆ | H7: =_xlfn.XLOOKUP(按鍵設計表[[#This Row],[台語音標]], 注音編碼對照表[台語音標], 注音編碼對照表[漢字例], "") -> 普 | I7: =_xlfn.XLOOKUP(按鍵設計表[[#This Row],[台語音標]], 注音編碼對照表[台語音標], 注音編碼對照表[聲韻調], "") -> 聲 | J7: =_xlfn.XLOOKUP(按鍵設計表[[#This Row],[台語音標]], 注音編碼對照表[台語音標], 注音編碼對照表[十五音], "") -> 頗 | K7: =_xlfn.XLOOKUP(按鍵設計表[[#This Row],[台語音標]], 注音編碼對照表[台語音標], 注音編碼對照表[注音二式], "") -> p | L7: =_xlfn.XLOOKUP(按鍵設計表[[#This Row],[台語音標]], 注音編碼對照表[台語音標], 注音編碼對照表[台羅拼音], "") -> ph | M7: =_xlfn.XLOOKUP(按鍵設計表[[#This Row],[台語音標]], 注音編碼對照表[台語音標], 注音編碼對照表[白話字], "") -> ph | N7: =_xlfn.XLOOKUP(按鍵設計表[[#This Row],[台語音標]], 注音編碼對照表[台語音標], 注音編碼對照表[閩拼方案], "") -> p | Q7: =LEN(按鍵設計表[[#This Row],[注音符號]]) -> 1 | S7: =ROW() - 4 -> 3 | T7: =ROW() - 4 -> 3 | U7: q | V7: ㄆ | W7: P | X7: p | Y7: p | Z7: ph | AA7: 聲 | AD7: 3 | AE7: q | AF7: p | AG7: ㄆ | AH7: p | AJ7: 3 | AK7: 3 | AM7: ˪ | AN7: 3 | AO7: 3
B8: =ROW() - 4 -> 4 | C8: a | D8: m | E8: m | F8: b | G8: =_xlfn.XLOOKUP(按鍵設計表[[#This Row],[台語音標]], 注音編碼對照表[台語音標], 注音編碼對照表[注音符號], "") -> ㄇ | H8: =_xlfn.XLOOKUP(按鍵設計表[[#This Row],[台語音標]], 注音編碼對照表[台語音標], 注音編碼對照表[漢字例], "") -> 名 | I8: =_xlfn.XLOOKUP(按鍵設計表[[#This Row],[台語音標]], 注音編碼對照表[台語音標], 注音編碼對照表[聲韻調], "") -> 聲 | J8: =_xlfn.XLOOKUP(按鍵設計表[[#This Row],[台語音標]], 注音編碼對照表[台語音標], 注音編碼對照表[十五音], "") -> 門 | K8: =_xlfn.XLOOKUP(按鍵設計表[[#This Row],[台語音標]], 注音編碼對照表[台語音標], 注音編碼對照表[注音二式], "") -> m | L8: =_xlfn.XLOOKUP(按鍵設計表[[#This Row],[台語音標]], 注音編碼對照表[台語音標], 注音編碼對照表[台羅拼音], "") -> m | M8: =_xlfn.XLOOKUP(按鍵設計表[[#This Row],[台語音標]], 注音編碼對照表[台語音標], 注音編碼對照表[白話字], "") -> m | N8: =_xlfn.XLOOKUP(按鍵設計表[[#This Row],[台語音標]], 注音編碼對照表[台語音標], 注音編碼對照表[閩拼方案], "") -> bbn | O8: m鼻音韻尾編碼：【M】 | Q8: =LEN(按鍵設計表[[#This Row],[注音符號]]) -> 1 | S8: =ROW() - 4 -> 4 | T8: =ROW() - 4 -> 4 | U8: a | V8: ㄇ | W8: m | X8: m | Y8: bbn | Z8: m | AA8: 聲 | AB8: m鼻音韻尾編碼：【M】 | AD8: 4 | AE8: a | AF8: m | AG8: ㄇ | AH8: m | AJ8: 5 | AK8: 6 | AM8: ˊ | AN8: 5 | AO8: 5
B9: =ROW() - 4 -> 5 | C9: s | D9: n | E9: n | F9: n | G9: =_xlfn.XLOOKUP(按鍵設計表[[#This Row],[台語音標]], 注音編碼對照表[台語音標], 注音編碼對照表[注音符號], "") -> ㄋ | H9: =_xlfn.XLOOKUP(按鍵設計表[[#This Row],[台語音標]], 注音編碼對照表[台語音標], 注音編碼對照表[漢字例], "") -> 泥 | I9: =_xlfn.XLOOKUP(按鍵設計表[[#This Row],[台語音標]], 注音編碼對照表[台語音標], 注音編碼對照表[聲韻調], "") -> 聲 | J9: =_xlfn.XLOOKUP(按鍵設計表[[#This Row],[台語音標]], 注音編碼對照表[台語音標], 注音編碼對照表[十五音], "") -> 柳 | K9: =_xlfn.XLOOKUP(按鍵設計表[[#This Row],[台語音標]], 注音編碼對照表[台語音標], 注音編碼對照表[注音二式], "") -> n | L9: =_xlfn.XLOOKUP(按鍵設計表[[#This Row],[台語音標]], 注音編碼對照表[台語音標], 注音編碼對照表[台羅拼音], "") -> n | M9: =_xlfn.XLOOKUP(按鍵設計表[[#This Row],[台語音標]], 注音編碼對照表[台語音標], 注音編碼對照表[白話字], "") -> n | N9: =_xlfn.XLOOKUP(按鍵設計表[[#This Row],[台語音標]], 注音編碼對照表[台語音標], 注音編碼對照表[閩拼方案], "") -> ln | O9: n鼻音韻尾編碼：【N】 | Q9: =LEN(按鍵設計表[[#This Row],[注音符號]]) -> 1 | S9: =ROW() - 4 -> 5 | T9: =ROW() - 4 -> 5 | U9: z | V9: ㆷ | W9: v | X9: h | Y9: h | Z9: h | AA9: 韻尾 | AB9: h入聲韻尾 | AD9: 5 | AE9: 2 | AF9: d | AG9: ㄉ | AH9: d | AJ9: 7 | AK9: 5 | AM9: ˫ | AN9: 7 | AO9: 7
B10: =ROW() - 4 -> 6 | C10: 2 | D10: t | E10: t | F10: t | G10: =_xlfn.XLOOKUP(按鍵設計表[[#This Row],[台語音標]], 注音編碼對照表[台語音標], 注音編碼對照表[注音符號], "") -> ㄉ | H10: =_xlfn.XLOOKUP(按鍵設計表[[#This Row],[台語音標]], 注音編碼對照表[台語音標], 注音編碼對照表[漢字例], "") -> 端 | I10: =_xlfn.XLOOKUP(按鍵設計表[[#This Row],[台語音標]], 注音編碼對照表[台語音標], 注音編碼對照表[聲韻調], "") -> 聲 | J10: =_xlfn.XLOOKUP(按鍵設計表[[#This Row],[台語音標]], 注音編碼對照表[台語音標], 注音編碼對照表[十五音], "") -> 地 | K10: =_xlfn.XLOOKUP(按鍵設計表[[#This Row],[台語音標]], 注音編碼對照表[台語音標], 注音編碼對照表[注音二式], "") -> d | L10: =_xlfn.XLOOKUP(按鍵設計表[[#This Row],[台語音標]], 注音編碼對照表[台語音標], 注音編碼對照表[台羅拼音], "") -> t | M10: =_xlfn.XLOOKUP(按鍵設計表[[#This Row],[台語音標]], 注音編碼對照表[台語音標], 注音編碼對照表[白話字], "") -> t | N10: =_xlfn.XLOOKUP(按鍵設計表[[#This Row],[台語音標]], 注音編碼對照表[台語音標], 注音編碼對照表[閩拼方案], "") -> d | O10: t入聲韻尾編碼：【T】 | Q10: =LEN(按鍵設計表[[#This Row],[注音符號]]) -> 1 | S10: =ROW() - 4 -> 6 | T10: =ROW() - 4 -> 6 | U10: 2 | V10: ㄉ | W10: t | X10: d | Y10: d | Z10: t | AA10: 聲 | AB10: t入聲韻尾編碼：【T】 | AD10: 6 | AE10: w | AF10: t | AG10: ㄊ | AH10: t | AJ10: 0 | AK10: 7 | AM10: ˙ | AN10: 48 | AO10: [48]
B11: =ROW() - 4 -> 7 | C11: w | D11: th | E11: T | F11: T | G11: =_xlfn.XLOOKUP(按鍵設計表[[#This Row],[台語音標]], 注音編碼對照表[台語音標], 注音編碼對照表[注音符號], "") -> ㄊ | H11: =_xlfn.XLOOKUP(按鍵設計表[[#This Row],[台語音標]], 注音編碼對照表[台語音標], 注音編碼對照表[漢字例], "") -> 透 | I11: =_xlfn.XLOOKUP(按鍵設計表[[#This Row],[台語音標]], 注音編碼對照表[台語音標], 注音編碼對照表[聲韻調], "") -> 聲 | J11: =_xlfn.XLOOKUP(按鍵設計表[[#This Row],[台語音標]], 注音編碼對照表[台語音標], 注音編碼對照表[十五音], "") -> 他 | K11: =_xlfn.XLOOKUP(按鍵設計表[[#This Row],[台語音標]], 注音編碼對照表[台語音標], 注音編碼對照表[注音二式], "") -> t | L11: =_xlfn.XLOOKUP(按鍵設計表[[#This Row],[台語音標]], 注音編碼對照表[台語音標], 注音編碼對照表[台羅拼音], "") -> th | M11: =_xlfn.XLOOKUP(按鍵設計表[[#This Row],[台語音標]], 注音編碼對照表[台語音標], 注音編碼對照表[白話字], "") -> th | N11: =_xlfn.XLOOKUP(按鍵設計表[[#This Row],[台語音標]], 注音編碼對照表[台語音標], 注音編碼對照表[閩拼方案], "") -> t | Q11: =LEN(按鍵設計表[[#This Row],[注音符號]]) -> 1 | S11: =ROW() - 4 -> 7 | T11: =ROW() - 4 -> 7 | U11: w | V11: ㄊ | W11: T | X11: t | Y11: t | Z11: th | AA11: 聲 | AD11: 7 | AE11: s | AF11: n | AG11: ㄋ | AH11: n | AJ11: R | AK11: b | AL11: p̚ | AM11: ㆴ | AN11: b0 | AO11: -p0
B12: =ROW() - 4 -> 8 | C12: x | D12: l | E12: l | F12: n | G12: =_xlfn.XLOOKUP(按鍵設計表[[#This Row],[台語音標]], 注音編碼對照表[台語音標], 注音編碼對照表[注音符號], "") -> ㄌ | H12: =_xlfn.XLOOKUP(按鍵設計表[[#This Row],[台語音標]], 注音編碼對照表[台語音標], 注音編碼對照表[漢字例], "") -> 來 | I12: =_xlfn.XLOOKUP(按鍵設計表[[#This Row],[台語音標]], 注音編碼對照表[台語音標], 注音編碼對照表[聲韻調], "") -> 聲 | J12: =_xlfn.XLOOKUP(按鍵設計表[[#This Row],[台語音標]], 注音編碼對照表[台語音標], 注音編碼對照表[十五音], "") -> 柳 | K12: =_xlfn.XLOOKUP(按鍵設計表[[#This Row],[台語音標]], 注音編碼對照表[台語音標], 注音編碼對照表[注音二式], "") -> l | L12: =_xlfn.XLOOKUP(按鍵設計表[[#This Row],[台語音標]], 注音編碼對照表[台語音標], 注音編碼對照表[台羅拼音], "") -> l | M12: =_xlfn.XLOOKUP(按鍵設計表[[#This Row],[台語音標]], 注音編碼對照表[台語音標], 注音編碼對照表[白話字], "") -> l | N12: =_xlfn.XLOOKUP(按鍵設計表[[#This Row],[台語音標]], 注音編碼對照表[台語音標], 注音編碼對照表[閩拼方案], "") -> l | Q12: =LEN(按鍵設計表[[#This Row],[注音符號]]) -> 1 | S12: =ROW() - 4 -> 8 | T12: =ROW() - 4 -> 8 | U12: s | V12: ㄋ | W12: n | X12: n | Y12: ln | Z12: n | AA12: 聲 | AB12: n鼻音韻尾編碼：【N】 | AD12: 8 | AE12: x | AF12: l | AG12: ㄌ | AH12: l | AJ12: F | AK12: t | AL12: t̚ | AM12: ㆵ | AN12: d0 | AO12: -t0
B13: =ROW() - 4 -> 9 | C13: E | D13: g | E13: q | F13: g | G13: =_xlfn.XLOOKUP(按鍵設計表[[#This Row],[台語音標]], 注音編碼對照表[台語音標], 注音編碼對照表[注音符號], "") -> ㆣ | H13: =_xlfn.XLOOKUP(按鍵設計表[[#This Row],[台語音標]], 注音編碼對照表[台語音標], 注音編碼對照表[漢字例], "") -> 疑 | I13: =_xlfn.XLOOKUP(按鍵設計表[[#This Row],[台語音標]], 注音編碼對照表[台語音標], 注音編碼對照表[聲韻調], "") -> 聲 | J13: =_xlfn.XLOOKUP(按鍵設計表[[#This Row],[台語音標]], 注音編碼對照表[台語音標], 注音編碼對照表[十五音], "") -> 語 | K13: =_xlfn.XLOOKUP(按鍵設計表[[#This Row],[台語音標]], 注音編碼對照表[台語音標], 注音編碼對照表[注音二式], "") -> gg | L13: =_xlfn.XLOOKUP(按鍵設計表[[#This Row],[台語音標]], 注音編碼對照表[台語音標], 注音編碼對照表[台羅拼音], "") -> g | M13: =_xlfn.XLOOKUP(按鍵設計表[[#This Row],[台語音標]], 注音編碼對照表[台語音標], 注音編碼對照表[白話字], "") -> g | N13: =_xlfn.XLOOKUP(按鍵設計表[[#This Row],[台語音標]], 注音編碼對照表[台語音標], 注音編碼對照表[閩拼方案], "") -> gg | Q13: =LEN(按鍵設計表[[#This Row],[注音符號]]) -> 1 | S13: =ROW() - 4 -> 9 | T13: =ROW() - 4 -> 9 | U13: x | V13: ㄌ | W13: l | X13: l | Y13: l | Z13: l | AA13: 聲 | AD13: 9 | AE13: e | AF13: g | AG13: ㄍ | AH13: g | AJ13: V | AK13: g | AL13: k̚ | AM13: ㆻ | AN13: g0 | AO13: -k0
B14: =ROW() - 4 -> 10 | C14: e | D14: k | E14: k | F14: k | G14: =_xlfn.XLOOKUP(按鍵設計表[[#This Row],[台語音標]], 注音編碼對照表[台語音標], 注音編碼對照表[注音符號], "") -> ㄍ | H14: =_xlfn.XLOOKUP(按鍵設計表[[#This Row],[台語音標]], 注音編碼對照表[台語音標], 注音編碼對照表[漢字例], "") -> 見 | I14: =_xlfn.XLOOKUP(按鍵設計表[[#This Row],[台語音標]], 注音編碼對照表[台語音標], 注音編碼對照表[聲韻調], "") -> 聲 | J14: =_xlfn.XLOOKUP(按鍵設計表[[#This Row],[台語音標]], 注音編碼對照表[台語音標], 注音編碼對照表[十五音], "") -> 求 | K14: =_xlfn.XLOOKUP(按鍵設計表[[#This Row],[台語音標]], 注音編碼對照表[台語音標], 注音編碼對照表[注音二式], "") -> g | L14: =_xlfn.XLOOKUP(按鍵設計表[[#This Row],[台語音標]], 注音編碼對照表[台語音標], 注音編碼對照表[台羅拼音], "") -> k | M14: =_xlfn.XLOOKUP(按鍵設計表[[#This Row],[台語音標]], 注音編碼對照表[台語音標], 注音編碼對照表[白話字], "") -> k | N14: =_xlfn.XLOOKUP(按鍵設計表[[#This Row],[台語音標]], 注音編碼對照表[台語音標], 注音編碼對照表[閩拼方案], "") -> g | O14: k入聲編碼：【K】 | Q14: =LEN(按鍵設計表[[#This Row],[注音符號]]) -> 1 | S14: =ROW() - 4 -> 10 | T14: =ROW() - 4 -> 10 | U14: 3 | V14: ˪ | W14: 3 | X14: 3 | Y14: 5 | Z14: 3 | AA14: 調 | AD14: 10 | AE14: E | AF14: G | AG14: ㆣ | AH14: gg | AJ14: C | AK14: C | AL14: ʔ | AM14: ㆷ | AN14: h0 | AO14: -h0
B15: =ROW() - 4 -> 11 | C15: d | D15: kh | E15: K | F15: K | G15: =_xlfn.XLOOKUP(按鍵設計表[[#This Row],[台語音標]], 注音編碼對照表[台語音標], 注音編碼對照表[注音符號], "") -> ㄎ | H15: =_xlfn.XLOOKUP(按鍵設計表[[#This Row],[台語音標]], 注音編碼對照表[台語音標], 注音編碼對照表[漢字例], "") -> 溪 | I15: =_xlfn.XLOOKUP(按鍵設計表[[#This Row],[台語音標]], 注音編碼對照表[台語音標], 注音編碼對照表[聲韻調], "") -> 聲 | J15: =_xlfn.XLOOKUP(按鍵設計表[[#This Row],[台語音標]], 注音編碼對照表[台語音標], 注音編碼對照表[十五音], "") -> 氣 | K15: =_xlfn.XLOOKUP(按鍵設計表[[#This Row],[台語音標]], 注音編碼對照表[台語音標], 注音編碼對照表[注音二式], "") -> k | L15: =_xlfn.XLOOKUP(按鍵設計表[[#This Row],[台語音標]], 注音編碼對照表[台語音標], 注音編碼對照表[台羅拼音], "") -> kh | M15: =_xlfn.XLOOKUP(按鍵設計表[[#This Row],[台語音標]], 注音編碼對照表[台語音標], 注音編碼對照表[白話字], "") -> kh | N15: =_xlfn.XLOOKUP(按鍵設計表[[#This Row],[台語音標]], 注音編碼對照表[台語音標], 注音編碼對照表[閩拼方案], "") -> k | Q15: =LEN(按鍵設計表[[#This Row],[注音符號]]) -> 1 | S15: =ROW() - 4 -> 11 | T15: =ROW() - 4 -> 11 | U15: e | V15: ㄍ | W15: k | X15: g | Y15: g | Z15: k | AA15: 聲 | AB15: k入聲編碼：【K】 | AD15: 11 | AE15: d | AF15: k | AG15: ㄎ | AH15: k
B16: =ROW() - 4 -> 12 | C16: ? | D16: ng | E16: g | F16: g | G16: =_xlfn.XLOOKUP(按鍵設計表[[#This Row],[台語音標]], 注音編碼對照表[台語音標], 注音編碼對照表[注音符號], "") -> ㄫ | H16: =_xlfn.XLOOKUP(按鍵設計表[[#This Row],[台語音標]], 注音編碼對照表[台語音標], 注音編碼對照表[漢字例], "") -> 吳 | I16: =_xlfn.XLOOKUP(按鍵設計表[[#This Row],[台語音標]], 注音編碼對照表[台語音標], 注音編碼對照表[聲韻調], "") -> 聲 | J16: =_xlfn.XLOOKUP(按鍵設計表[[#This Row],[台語音標]], 注音編碼對照表[台語音標], 注音編碼對照表[十五音], "") -> 語 | K16: =_xlfn.XLOOKUP(按鍵設計表[[#This Row],[台語音標]], 注音編碼對照表[台語音標], 注音編碼對照表[注音二式], "") -> ng | L16: =_xlfn.XLOOKUP(按鍵設計表[[#This Row],[台語音標]], 注音編碼對照表[台語音標], 注音編碼對照表[台羅拼音], "") -> ng | M16: =_xlfn.XLOOKUP(按鍵設計表[[#This Row],[台語音標]], 注音編碼對照表[台語音標], 注音編碼對照表[白話字], "") -> ng | N16: =_xlfn.XLOOKUP(按鍵設計表[[#This Row],[台語音標]], 注音編碼對照表[台語音標], 注音編碼對照表[閩拼方案], "") -> ggn | O16: ng鼻音韻尾編碼：【W】 | Q16: =LEN(按鍵設計表[[#This Row],[注音符號]]) -> 1 | S16: =ROW() - 4 -> 12 | T16: =ROW() - 4 -> 12 | U16: E | V16: ㆣ | W16: g | X16: gg | Y16: gg | Z16: g | AA16: 聲 | AD16: 12 | AE16: z | AF16: w | AG16: ㄫ | AH16: ng-
B17: =ROW() - 4 -> 13 | C17: Y | D17: j | E17: j | F17: j | G17: =_xlfn.XLOOKUP(按鍵設計表[[#This Row],[台語音標]], 注音編碼對照表[台語音標], 注音編碼對照表[注音符號], "") -> ㆡ | H17: =_xlfn.XLOOKUP(按鍵設計表[[#This Row],[台語音標]], 注音編碼對照表[台語音標], 注音編碼對照表[漢字例], "") -> 熱 | I17: =_xlfn.XLOOKUP(按鍵設計表[[#This Row],[台語音標]], 注音編碼對照表[台語音標], 注音編碼對照表[聲韻調], "") -> 聲 | J17: =_xlfn.XLOOKUP(按鍵設計表[[#This Row],[台語音標]], 注音編碼對照表[台語音標], 注音編碼對照表[十五音], "") -> 入 | K17: =_xlfn.XLOOKUP(按鍵設計表[[#This Row],[台語音標]], 注音編碼對照表[台語音標], 注音編碼對照表[注音二式], "") -> zz | L17: =_xlfn.XLOOKUP(按鍵設計表[[#This Row],[台語音標]], 注音編碼對照表[台語音標], 注音編碼對照表[台羅拼音], "") -> j | M17: =_xlfn.XLOOKUP(按鍵設計表[[#This Row],[台語音標]], 注音編碼對照表[台語音標], 注音編碼對照表[白話字], "") -> j | N17: =_xlfn.XLOOKUP(按鍵設計表[[#This Row],[台語音標]], 注音編碼對照表[台語音標], 注音編碼對照表[閩拼方案], "") -> zz | Q17: =LEN(按鍵設計表[[#This Row],[注音符號]]) -> 1 | S17: =ROW() - 4 -> 13 | T17: =ROW() - 4 -> 13 | U17: d | V17: ㄎ | W17: K | X17: k | Y17: k | Z17: kh | AA17: 聲 | AD17: 13 | AE17: c | AF17: h | AG17: ㄏ | AH17: h
B18: =ROW() - 4 -> 14 | C18: y | D18: z | E18: z | F18: z | G18: =_xlfn.XLOOKUP(按鍵設計表[[#This Row],[台語音標]], 注音編碼對照表[台語音標], 注音編碼對照表[注音符號], "") -> ㄗ | H18: =_xlfn.XLOOKUP(按鍵設計表[[#This Row],[台語音標]], 注音編碼對照表[台語音標], 注音編碼對照表[漢字例], "") -> 裝 | I18: =_xlfn.XLOOKUP(按鍵設計表[[#This Row],[台語音標]], 注音編碼對照表[台語音標], 注音編碼對照表[聲韻調], "") -> 聲 | J18: =_xlfn.XLOOKUP(按鍵設計表[[#This Row],[台語音標]], 注音編碼對照表[台語音標], 注音編碼對照表[十五音], "") -> 曾 | K18: =_xlfn.XLOOKUP(按鍵設計表[[#This Row],[台語音標]], 注音編碼對照表[台語音標], 注音編碼對照表[注音二式], "") -> z | L18: =_xlfn.XLOOKUP(按鍵設計表[[#This Row],[台語音標]], 注音編碼對照表[台語音標], 注音編碼對照表[台羅拼音], "") -> ts | M18: =_xlfn.XLOOKUP(按鍵設計表[[#This Row],[台語音標]], 注音編碼對照表[台語音標], 注音編碼對照表[白話字], "") -> ch | N18: =_xlfn.XLOOKUP(按鍵設計表[[#This Row],[台語音標]], 注音編碼對照表[台語音標], 注音編碼對照表[閩拼方案], "") -> z | Q18: =LEN(按鍵設計表[[#This Row],[注音符號]]) -> 1 | S18: =ROW() - 4 -> 14 | T18: =ROW() - 4 -> 14 | U18: c | V18: ㄏ | W18: h | X18: h | Y18: h | Z18: h | AA18: 聲 | AB18: h入聲韻尾編碼：【H】 | AD18: 14 | AE18: r | AF18: zi | AG18: ㄐ | AH18: ji
B19: =ROW() - 4 -> 15 | C19: h | D19: c | E19: c | F19: c | G19: =_xlfn.XLOOKUP(按鍵設計表[[#This Row],[台語音標]], 注音編碼對照表[台語音標], 注音編碼對照表[注音符號], "") -> ㄘ | H19: =_xlfn.XLOOKUP(按鍵設計表[[#This Row],[台語音標]], 注音編碼對照表[台語音標], 注音編碼對照表[漢字例], "") -> 初 | I19: =_xlfn.XLOOKUP(按鍵設計表[[#This Row],[台語音標]], 注音編碼對照表[台語音標], 注音編碼對照表[聲韻調], "") -> 聲 | J19: =_xlfn.XLOOKUP(按鍵設計表[[#This Row],[台語音標]], 注音編碼對照表[台語音標], 注音編碼對照表[十五音], "") -> 出 | K19: =_xlfn.XLOOKUP(按鍵設計表[[#This Row],[台語音標]], 注音編碼對照表[台語音標], 注音編碼對照表[注音二式], "") -> c | L19: =_xlfn.XLOOKUP(按鍵設計表[[#This Row],[台語音標]], 注音編碼對照表[台語音標], 注音編碼對照表[台羅拼音], "") -> tsh | M19: =_xlfn.XLOOKUP(按鍵設計表[[#This Row],[台語音標]], 注音編碼對照表[台語音標], 注音編碼對照表[白話字], "") -> chh | N19: =_xlfn.XLOOKUP(按鍵設計表[[#This Row],[台語音標]], 注音編碼對照表[台語音標], 注音編碼對照表[閩拼方案], "") -> c | Q19: =LEN(按鍵設計表[[#This Row],[注音符號]]) -> 1 | S19: =ROW() - 4 -> 15 | T19: =ROW() - 4 -> 15 | U19: 4 | V19: ˋ | W19: 2 | X19: 2 | Y19: 3 | Z19: 2 | AA19: 調 | AD19: 15 | AE19: R | AF19: Zi | AG19: ㆢ | AH19: jji
B20: =ROW() - 4 -> 16 | C20: n | D20: s | E20: s | F20: s | G20: =_xlfn.XLOOKUP(按鍵設計表[[#This Row],[台語音標]], 注音編碼對照表[台語音標], 注音編碼對照表[注音符號], "") -> ㄙ | H20: =_xlfn.XLOOKUP(按鍵設計表[[#This Row],[台語音標]], 注音編碼對照表[台語音標], 注音編碼對照表[漢字例], "") -> 疏 | I20: =_xlfn.XLOOKUP(按鍵設計表[[#This Row],[台語音標]], 注音編碼對照表[台語音標], 注音編碼對照表[聲韻調], "") -> 聲 | J20: =_xlfn.XLOOKUP(按鍵設計表[[#This Row],[台語音標]], 注音編碼對照表[台語音標], 注音編碼對照表[十五音], "") -> 時 | K20: =_xlfn.XLOOKUP(按鍵設計表[[#This Row],[台語音標]], 注音編碼對照表[台語音標], 注音編碼對照表[注音二式], "") -> s | L20: =_xlfn.XLOOKUP(按鍵設計表[[#This Row],[台語音標]], 注音編碼對照表[台語音標], 注音編碼對照表[台羅拼音], "") -> s | M20: =_xlfn.XLOOKUP(按鍵設計表[[#This Row],[台語音標]], 注音編碼對照表[台語音標], 注音編碼對照表[白話字], "") -> s | N20: =_xlfn.XLOOKUP(按鍵設計表[[#This Row],[台語音標]], 注音編碼對照表[台語音標], 注音編碼對照表[閩拼方案], "") -> s | Q20: =LEN(按鍵設計表[[#This Row],[注音符號]]) -> 1 | S20: =ROW() - 4 -> 16 | T20: =ROW() - 4 -> 16 | U20: r | V20: ㄐ | W20: Z | X20: j | Z20: zi | AA20: 聲 | AD20: 16 | AE20: f | AF20: ci | AG20: ㄑ | AH20: chi
B21: =ROW() - 4 -> 17 | C21: c | D21: h | E21: h | F21: h | G21: =_xlfn.XLOOKUP(按鍵設計表[[#This Row],[台語音標]], 注音編碼對照表[台語音標], 注音編碼對照表[注音符號], "") -> ㄏ | H21: =_xlfn.XLOOKUP(按鍵設計表[[#This Row],[台語音標]], 注音編碼對照表[台語音標], 注音編碼對照表[漢字例], "") -> 雨 | I21: =_xlfn.XLOOKUP(按鍵設計表[[#This Row],[台語音標]], 注音編碼對照表[台語音標], 注音編碼對照表[聲韻調], "") -> 聲 | J21: =_xlfn.XLOOKUP(按鍵設計表[[#This Row],[台語音標]], 注音編碼對照表[台語音標], 注音編碼對照表[十五音], "") -> 喜 | K21: =_xlfn.XLOOKUP(按鍵設計表[[#This Row],[台語音標]], 注音編碼對照表[台語音標], 注音編碼對照表[注音二式], "") -> h | L21: =_xlfn.XLOOKUP(按鍵設計表[[#This Row],[台語音標]], 注音編碼對照表[台語音標], 注音編碼對照表[台羅拼音], "") -> h | M21: =_xlfn.XLOOKUP(按鍵設計表[[#This Row],[台語音標]], 注音編碼對照表[台語音標], 注音編碼對照表[白話字], "") -> h | N21: =_xlfn.XLOOKUP(按鍵設計表[[#This Row],[台語音標]], 注音編碼對照表[台語音標], 注音編碼對照表[閩拼方案], "") -> h | O21: h入聲韻尾編碼：【H】 | Q21: =LEN(按鍵設計表[[#This Row],[注音符號]]) -> 1 | S21: =ROW() - 4 -> 17 | T21: =ROW() - 4 -> 17 | U21: R | V21: ㆢ | W21: J | X21: jj | Z21: ji | AA21: 聲 | AD21: 17 | AE21: v | AF21: si | AG21: ㄒ | AH21: shi
B22: =ROW() - 4 -> 18 | C22: R | D22: ji | E22: J | F22: ji- | G22: =_xlfn.XLOOKUP(按鍵設計表[[#This Row],[台語音標]], 注音編碼對照表[台語音標], 注音編碼對照表[注音符號], "") -> ㆢ | H22: =_xlfn.XLOOKUP(按鍵設計表[[#This Row],[台語音標]], 注音編碼對照表[台語音標], 注音編碼對照表[漢字例], "") -> 日 | I22: =_xlfn.XLOOKUP(按鍵設計表[[#This Row],[台語音標]], 注音編碼對照表[台語音標], 注音編碼對照表[聲韻調], "") -> 聲 | J22: =_xlfn.XLOOKUP(按鍵設計表[[#This Row],[台語音標]], 注音編碼對照表[台語音標], 注音編碼對照表[十五音], "") -> 入 | K22: =_xlfn.XLOOKUP(按鍵設計表[[#This Row],[台語音標]], 注音編碼對照表[台語音標], 注音編碼對照表[注音二式], "") -> jj | L22: =_xlfn.XLOOKUP(按鍵設計表[[#This Row],[台語音標]], 注音編碼對照表[台語音標], 注音編碼對照表[台羅拼音], "") -> ji | M22: =_xlfn.XLOOKUP(按鍵設計表[[#This Row],[台語音標]], 注音編碼對照表[台語音標], 注音編碼對照表[白話字], "") -> ji | N22: =_xlfn.XLOOKUP(按鍵設計表[[#This Row],[台語音標]], 注音編碼對照表[台語音標], 注音編碼對照表[閩拼方案], "") -> 0 | Q22: =LEN(按鍵設計表[[#This Row],[注音符號]]) -> 1 | S22: =ROW() - 4 -> 18 | T22: =ROW() - 4 -> 18 | U22: f | V22: ㄑ | W22: C | X22: ch | Z22: ci | AA22: 聲 | AD22: 18 | AE22: y | AF22: z | AG22: ㄗ | AH22: z
B23: =ROW() - 4 -> 19 | C23: r | D23: zi | E23: Z | F23: zi- | G23: =_xlfn.XLOOKUP(按鍵設計表[[#This Row],[台語音標]], 注音編碼對照表[台語音標], 注音編碼對照表[注音符號], "") -> ㄐ | H23: =_xlfn.XLOOKUP(按鍵設計表[[#This Row],[台語音標]], 注音編碼對照表[台語音標], 注音編碼對照表[漢字例], "") -> 精 | I23: =_xlfn.XLOOKUP(按鍵設計表[[#This Row],[台語音標]], 注音編碼對照表[台語音標], 注音編碼對照表[聲韻調], "") -> 聲 | J23: =_xlfn.XLOOKUP(按鍵設計表[[#This Row],[台語音標]], 注音編碼對照表[台語音標], 注音編碼對照表[十五音], "") -> 曾 | K23: =_xlfn.XLOOKUP(按鍵設計表[[#This Row],[台語音標]], 注音編碼對照表[台語音標], 注音編碼對照表[注音二式], "") -> j | L23: =_xlfn.XLOOKUP(按鍵設計表[[#This Row],[台語音標]], 注音編碼對照表[台語音標], 注音編碼對照表[台羅拼音], "") -> zi | M23: =_xlfn.XLOOKUP(按鍵設計表[[#This Row],[台語音標]], 注音編碼對照表[台語音標], 注音編碼對照表[白話字], "") -> zi | N23: =_xlfn.XLOOKUP(按鍵設計表[[#This Row],[台語音標]], 注音編碼對照表[台語音標], 注音編碼對照表[閩拼方案], "") -> 0 | Q23: =LEN(按鍵設計表[[#This Row],[注音符號]]) -> 1 | S23: =ROW() - 4 -> 19 | T23: =ROW() - 4 -> 19 | U23: v | V23: ㄒ | W23: S | X23: sh | Z23: si | AA23: 聲 | AD23: 19 | AE23: Y | AF23: Z | AG23: ㆡ | AH23: zz
B24: =ROW() - 4 -> 20 | C24: f | D24: ci | E24: C | F24: ci- | G24: =_xlfn.XLOOKUP(按鍵設計表[[#This Row],[台語音標]], 注音編碼對照表[台語音標], 注音編碼對照表[注音符號], "") -> ㄑ | H24: =_xlfn.XLOOKUP(按鍵設計表[[#This Row],[台語音標]], 注音編碼對照表[台語音標], 注音編碼對照表[漢字例], "") -> 清 | I24: =_xlfn.XLOOKUP(按鍵設計表[[#This Row],[台語音標]], 注音編碼對照表[台語音標], 注音編碼對照表[聲韻調], "") -> 聲 | J24: =_xlfn.XLOOKUP(按鍵設計表[[#This Row],[台語音標]], 注音編碼對照表[台語音標], 注音編碼對照表[十五音], "") -> 出 | K24: =_xlfn.XLOOKUP(按鍵設計表[[#This Row],[台語音標]], 注音編碼對照表[台語音標], 注音編碼對照表[注音二式], "") -> ch | L24: =_xlfn.XLOOKUP(按鍵設計表[[#This Row],[台語音標]], 注音編碼對照表[台語音標], 注音編碼對照表[台羅拼音], "") -> ci | M24: =_xlfn.XLOOKUP(按鍵設計表[[#This Row],[台語音標]], 注音編碼對照表[台語音標], 注音編碼對照表[白話字], "") -> ci | N24: =_xlfn.XLOOKUP(按鍵設計表[[#This Row],[台語音標]], 注音編碼對照表[台語音標], 注音編碼對照表[閩拼方案], "") -> 0 | Q24: =LEN(按鍵設計表[[#This Row],[注音符號]]) -> 1 | S24: =ROW() - 4 -> 20 | T24: =ROW() - 4 -> 20 | U24: 5 | V24: ˫ | W24: 7 | X24: 7 | Y24: 6 | Z24: 7 | AA24: 調 | AD24: 20 | AE24: h | AF24: c | AG24: ㄘ | AH24: c
B25: =ROW() - 4 -> 21 | C25: v | D25: si | E25: S | F25: si- | G25: =_xlfn.XLOOKUP(按鍵設計表[[#This Row],[台語音標]], 注音編碼對照表[台語音標], 注音編碼對照表[注音符號], "") -> ㄒ | H25: =_xlfn.XLOOKUP(按鍵設計表[[#This Row],[台語音標]], 注音編碼對照表[台語音標], 注音編碼對照表[漢字例], "") -> 心 | I25: =_xlfn.XLOOKUP(按鍵設計表[[#This Row],[台語音標]], 注音編碼對照表[台語音標], 注音編碼對照表[聲韻調], "") -> 聲 | J25: =_xlfn.XLOOKUP(按鍵設計表[[#This Row],[台語音標]], 注音編碼對照表[台語音標], 注音編碼對照表[十五音], "") -> 時 | K25: =_xlfn.XLOOKUP(按鍵設計表[[#This Row],[台語音標]], 注音編碼對照表[台語音標], 注音編碼對照表[注音二式], "") -> sh | L25: =_xlfn.XLOOKUP(按鍵設計表[[#This Row],[台語音標]], 注音編碼對照表[台語音標], 注音編碼對照表[台羅拼音], "") -> si | M25: =_xlfn.XLOOKUP(按鍵設計表[[#This Row],[台語音標]], 注音編碼對照表[台語音標], 注音編碼對照表[白話字], "") -> si | N25: =_xlfn.XLOOKUP(按鍵設計表[[#This Row],[台語音標]], 注音編碼對照表[台語音標], 注音編碼對照表[閩拼方案], "") -> 0 | Q25: =LEN(按鍵設計表[[#This Row],[注音符號]]) -> 1 | S25: =ROW() - 4 -> 21 | T25: =ROW() - 4 -> 21 | U25: t | V25: ㆵ | W25: f | X25: t | Y25: t | Z25: t | AA25: 韻尾 | AB25: t入聲韻尾 | AD25: 21 | AE25: n | AF25: s | AG25: ㄙ | AH25: s
B26: =ROW() - 4 -> 22 | C26: 8 | D26: a | E26: a | F26: a | G26: =_xlfn.XLOOKUP(按鍵設計表[[#This Row],[台語音標]], 注音編碼對照表[台語音標], 注音編碼對照表[注音符號], "") -> ㄚ | H26: =_xlfn.XLOOKUP(按鍵設計表[[#This Row],[台語音標]], 注音編碼對照表[台語音標], 注音編碼對照表[漢字例], "") -> 阿 | I26: =_xlfn.XLOOKUP(按鍵設計表[[#This Row],[台語音標]], 注音編碼對照表[台語音標], 注音編碼對照表[聲韻調], "") -> 韻 | J26: =_xlfn.XLOOKUP(按鍵設計表[[#This Row],[台語音標]], 注音編碼對照表[台語音標], 注音編碼對照表[十五音], "") -> 膠 | K26: =_xlfn.XLOOKUP(按鍵設計表[[#This Row],[台語音標]], 注音編碼對照表[台語音標], 注音編碼對照表[注音二式], "") -> a | L26: =_xlfn.XLOOKUP(按鍵設計表[[#This Row],[台語音標]], 注音編碼對照表[台語音標], 注音編碼對照表[台羅拼音], "") -> a | M26: =_xlfn.XLOOKUP(按鍵設計表[[#This Row],[台語音標]], 注音編碼對照表[台語音標], 注音編碼對照表[白話字], "") -> a | N26: =_xlfn.XLOOKUP(按鍵設計表[[#This Row],[台語音標]], 注音編碼對照表[台語音標], 注音編碼對照表[閩拼方案], "") -> a | Q26: =LEN(按鍵設計表[[#This Row],[注音符號]]) -> 1 | S26: =ROW() - 4 -> 22 | T26: =ROW() - 4 -> 22 | U26: g | V26: ㆻ | W26: q | X26: k | Y26: k | Z26: k | AA26: 韻尾 | AB26: k入聲韻尾 | AD26: 22 | AE26: u | AF26: i | AG26: ㄧ | AH26: i
B27: =ROW() - 4 -> 23 | C27: u | D27: i | E27: i | F27: i | G27: =_xlfn.XLOOKUP(按鍵設計表[[#This Row],[台語音標]], 注音編碼對照表[台語音標], 注音編碼對照表[注音符號], "") -> ㄧ | H27: =_xlfn.XLOOKUP(按鍵設計表[[#This Row],[台語音標]], 注音編碼對照表[台語音標], 注音編碼對照表[漢字例], "") -> 伊 | I27: =_xlfn.XLOOKUP(按鍵設計表[[#This Row],[台語音標]], 注音編碼對照表[台語音標], 注音編碼對照表[聲韻調], "") -> 韻 | J27: =_xlfn.XLOOKUP(按鍵設計表[[#This Row],[台語音標]], 注音編碼對照表[台語音標], 注音編碼對照表[十五音], "") -> 居 | K27: =_xlfn.XLOOKUP(按鍵設計表[[#This Row],[台語音標]], 注音編碼對照表[台語音標], 注音編碼對照表[注音二式], "") -> i | L27: =_xlfn.XLOOKUP(按鍵設計表[[#This Row],[台語音標]], 注音編碼對照表[台語音標], 注音編碼對照表[台羅拼音], "") -> i | M27: =_xlfn.XLOOKUP(按鍵設計表[[#This Row],[台語音標]], 注音編碼對照表[台語音標], 注音編碼對照表[白話字], "") -> i | N27: =_xlfn.XLOOKUP(按鍵設計表[[#This Row],[台語音標]], 注音編碼對照表[台語音標], 注音編碼對照表[閩拼方案], "") -> i | Q27: =LEN(按鍵設計表[[#This Row],[注音符號]]) -> 1 | S27: =ROW() - 4 -> 23 | T27: =ROW() - 4 -> 23 | U27: b | V27: ㆴ | W27: r | X27: p | Y27: p | Z27: p | AA27: 韻尾 | AB27: p入聲韻尾 | AD27: 23 | AE27: U | AF27: I | AG27: ㆪ | AH27: inn
B28: =ROW() - 4 -> 24 | C28: K | D28: ir | E28: w | F28: w | G28: =_xlfn.XLOOKUP(按鍵設計表[[#This Row],[台語音標]], 注音編碼對照表[台語音標], 注音編碼對照表[注音符號], "") -> ㆨ | H28: =_xlfn.XLOOKUP(按鍵設計表[[#This Row],[台語音標]], 注音編碼對照表[台語音標], 注音編碼對照表[漢字例], "") -> 猪 | I28: =_xlfn.XLOOKUP(按鍵設計表[[#This Row],[台語音標]], 注音編碼對照表[台語音標], 注音編碼對照表[聲韻調], "") -> 韻 | J28: =_xlfn.XLOOKUP(按鍵設計表[[#This Row],[台語音標]], 注音編碼對照表[台語音標], 注音編碼對照表[十五音], "") -> 0 | K28: =_xlfn.XLOOKUP(按鍵設計表[[#This Row],[台語音標]], 注音編碼對照表[台語音標], 注音編碼對照表[注音二式], "") -> ir | L28: =_xlfn.XLOOKUP(按鍵設計表[[#This Row],[台語音標]], 注音編碼對照表[台語音標], 注音編碼對照表[台羅拼音], "") -> ir | M28: =_xlfn.XLOOKUP(按鍵設計表[[#This Row],[台語音標]], 注音編碼對照表[台語音標], 注音編碼對照表[白話字], "") -> ir | N28: =_xlfn.XLOOKUP(按鍵設計表[[#This Row],[台語音標]], 注音編碼對照表[台語音標], 注音編碼對照表[閩拼方案], "") -> eu | Q28: =LEN(按鍵設計表[[#This Row],[注音符號]]) -> 1 | S28: =ROW() - 4 -> 24 | T28: =ROW() - 4 -> 24 | U28: 6 | V28: ˊ | W28: 5 | X28: 5 | Y28: 2 | Z28: 5 | AA28: 調 | AD28: 24 | AE28: j | AF28: u | AG28: ㄨ | AH28: u
B29: =ROW() - 4 -> 25 | C29: j | D29: u | E29: u | F29: u | G29: =_xlfn.XLOOKUP(按鍵設計表[[#This Row],[台語音標]], 注音編碼對照表[台語音標], 注音編碼對照表[注音符號], "") -> ㄨ | H29: =_xlfn.XLOOKUP(按鍵設計表[[#This Row],[台語音標]], 注音編碼對照表[台語音標], 注音編碼對照表[漢字例], "") -> 污 | I29: =_xlfn.XLOOKUP(按鍵設計表[[#This Row],[台語音標]], 注音編碼對照表[台語音標], 注音編碼對照表[聲韻調], "") -> 韻 | J29: =_xlfn.XLOOKUP(按鍵設計表[[#This Row],[台語音標]], 注音編碼對照表[台語音標], 注音編碼對照表[十五音], "") -> 艍 | K29: =_xlfn.XLOOKUP(按鍵設計表[[#This Row],[台語音標]], 注音編碼對照表[台語音標], 注音編碼對照表[注音二式], "") -> u | L29: =_xlfn.XLOOKUP(按鍵設計表[[#This Row],[台語音標]], 注音編碼對照表[台語音標], 注音編碼對照表[台羅拼音], "") -> u | M29: =_xlfn.XLOOKUP(按鍵設計表[[#This Row],[台語音標]], 注音編碼對照表[台語音標], 注音編碼對照表[白話字], "") -> u | N29: =_xlfn.XLOOKUP(按鍵設計表[[#This Row],[台語音標]], 注音編碼對照表[台語音標], 注音編碼對照表[閩拼方案], "") -> u | Q29: =LEN(按鍵設計表[[#This Row],[注音符號]]) -> 1 | S29: =ROW() - 4 -> 25 | T29: =ROW() - 4 -> 25 | U29: y | V29: ㄗ | W29: z | X29: z | Y29: z | Z29: z | AA29: 聲 | AD29: 25 | AE29: J | AF29: U | AG29: ㆫ | AH29: unn
B30: =ROW() - 4 -> 26 | C30: , | D30: e | E30: e | F30: e | G30: =_xlfn.XLOOKUP(按鍵設計表[[#This Row],[台語音標]], 注音編碼對照表[台語音標], 注音編碼對照表[注音符號], "") -> ㆤ | H30: =_xlfn.XLOOKUP(按鍵設計表[[#This Row],[台語音標]], 注音編碼對照表[台語音標], 注音編碼對照表[漢字例], "") -> 稽 | I30: =_xlfn.XLOOKUP(按鍵設計表[[#This Row],[台語音標]], 注音編碼對照表[台語音標], 注音編碼對照表[聲韻調], "") -> 韻 | J30: =_xlfn.XLOOKUP(按鍵設計表[[#This Row],[台語音標]], 注音編碼對照表[台語音標], 注音編碼對照表[十五音], "") -> 伽 | K30: =_xlfn.XLOOKUP(按鍵設計表[[#This Row],[台語音標]], 注音編碼對照表[台語音標], 注音編碼對照表[注音二式], "") -> e | L30: =_xlfn.XLOOKUP(按鍵設計表[[#This Row],[台語音標]], 注音編碼對照表[台語音標], 注音編碼對照表[台羅拼音], "") -> e | M30: =_xlfn.XLOOKUP(按鍵設計表[[#This Row],[台語音標]], 注音編碼對照表[台語音標], 注音編碼對照表[白話字], "") -> e | N30: =_xlfn.XLOOKUP(按鍵設計表[[#This Row],[台語音標]], 注音編碼對照表[台語音標], 注音編碼對照表[閩拼方案], "") -> e | Q30: =LEN(按鍵設計表[[#This Row],[注音符號]]) -> 1 | S30: =ROW() - 4 -> 26 | T30: =ROW() - 4 -> 26 | U30: Y | V30: ㆡ | W30: j | X30: zz | Y30: zz | Z30: j | AA30: 聲 | AD30: 26 | AE30: 8 | AF30: a | AG30: ㄚ | AH30: a
B31: =ROW() - 4 -> 27 | C31: i | D31: oo | E31: o | F31: o | G31: =_xlfn.XLOOKUP(按鍵設計表[[#This Row],[台語音標]], 注音編碼對照表[台語音標], 注音編碼對照表[注音符號], "") -> ㆦ | H31: =_xlfn.XLOOKUP(按鍵設計表[[#This Row],[台語音標]], 注音編碼對照表[台語音標], 注音編碼對照表[漢字例], "") -> 烏 | I31: =_xlfn.XLOOKUP(按鍵設計表[[#This Row],[台語音標]], 注音編碼對照表[台語音標], 注音編碼對照表[聲韻調], "") -> 韻 | J31: =_xlfn.XLOOKUP(按鍵設計表[[#This Row],[台語音標]], 注音編碼對照表[台語音標], 注音編碼對照表[十五音], "") -> 沽 | K31: =_xlfn.XLOOKUP(按鍵設計表[[#This Row],[台語音標]], 注音編碼對照表[台語音標], 注音編碼對照表[注音二式], "") -> oo | L31: =_xlfn.XLOOKUP(按鍵設計表[[#This Row],[台語音標]], 注音編碼對照表[台語音標], 注音編碼對照表[台羅拼音], "") -> oo | M31: =_xlfn.XLOOKUP(按鍵設計表[[#This Row],[台語音標]], 注音編碼對照表[台語音標], 注音編碼對照表[白話字], "") -> oo | N31: =_xlfn.XLOOKUP(按鍵設計表[[#This Row],[台語音標]], 注音編碼對照表[台語音標], 注音編碼對照表[閩拼方案], "") -> oo | Q31: =LEN(按鍵設計表[[#This Row],[注音符號]]) -> 1 | S31: =ROW() - 4 -> 27 | T31: =ROW() - 4 -> 27 | U31: h | V31: ㄘ | W31: c | X31: c | Y31: c | Z31: c | AA31: 聲 | AD31: 27 | AE31: * | AF31: A | AG31: ㆩ | AH31: ann
B32: =ROW() - 4 -> 28 | C32: k | D32: o | E32: ø | F32: ø | G32: =_xlfn.XLOOKUP(按鍵設計表[[#This Row],[台語音標]], 注音編碼對照表[台語音標], 注音編碼對照表[注音符號], "") -> ㄜ | H32: =_xlfn.XLOOKUP(按鍵設計表[[#This Row],[台語音標]], 注音編碼對照表[台語音標], 注音編碼對照表[漢字例], "") -> 蚵 | I32: =_xlfn.XLOOKUP(按鍵設計表[[#This Row],[台語音標]], 注音編碼對照表[台語音標], 注音編碼對照表[聲韻調], "") -> 韻 | J32: =_xlfn.XLOOKUP(按鍵設計表[[#This Row],[台語音標]], 注音編碼對照表[台語音標], 注音編碼對照表[十五音], "") -> 高 | K32: =_xlfn.XLOOKUP(按鍵設計表[[#This Row],[台語音標]], 注音編碼對照表[台語音標], 注音編碼對照表[注音二式], "") -> or | L32: =_xlfn.XLOOKUP(按鍵設計表[[#This Row],[台語音標]], 注音編碼對照表[台語音標], 注音編碼對照表[台羅拼音], "") -> o | M32: =_xlfn.XLOOKUP(按鍵設計表[[#This Row],[台語音標]], 注音編碼對照表[台語音標], 注音編碼對照表[白話字], "") -> o | N32: =_xlfn.XLOOKUP(按鍵設計表[[#This Row],[台語音標]], 注音編碼對照表[台語音標], 注音編碼對照表[閩拼方案], "") -> o | Q32: =LEN(按鍵設計表[[#This Row],[注音符號]]) -> 1 | S32: =ROW() - 4 -> 28 | T32: =ROW() - 4 -> 28 | U32: n | V32: ㄙ | W32: s | X32: s | Y32: s | Z32: s | AA32: 聲 | AD32: 28 | AE32: i | AF32: O | AG32: ㆦ | AH32: oo
B33: =ROW() - 4 -> 29 | C33: m | D33: -m | E33: M | F33: M | G33: =_xlfn.XLOOKUP(按鍵設計表[[#This Row],[台語音標]], 注音編碼對照表[台語音標], 注音編碼對照表[注音符號], "") -> ㆬ | H33: =_xlfn.XLOOKUP(按鍵設計表[[#This Row],[台語音標]], 注音編碼對照表[台語音標], 注音編碼對照表[漢字例], "") -> 姆 | I33: =_xlfn.XLOOKUP(按鍵設計表[[#This Row],[台語音標]], 注音編碼對照表[台語音標], 注音編碼對照表[聲韻調], "") -> 韻 | J33: =_xlfn.XLOOKUP(按鍵設計表[[#This Row],[台語音標]], 注音編碼對照表[台語音標], 注音編碼對照表[十五音], "") -> 姆 | K33: =_xlfn.XLOOKUP(按鍵設計表[[#This Row],[台語音標]], 注音編碼對照表[台語音標], 注音編碼對照表[注音二式], "") -> m | L33: =_xlfn.XLOOKUP(按鍵設計表[[#This Row],[台語音標]], 注音編碼對照表[台語音標], 注音編碼對照表[台羅拼音], "") -> m | M33: =_xlfn.XLOOKUP(按鍵設計表[[#This Row],[台語音標]], 注音編碼對照表[台語音標], 注音編碼對照表[白話字], "") -> m | N33: =_xlfn.XLOOKUP(按鍵設計表[[#This Row],[台語音標]], 注音編碼對照表[台語音標], 注音編碼對照表[閩拼方案], "") -> m | Q33: =LEN(按鍵設計表[[#This Row],[注音符號]]) -> 1 | S33: =ROW() - 4 -> 29 | T33: =ROW() - 4 -> 29 | U33: N | V33: ㄫ | W33: w | X33: ng | Y33: ggn | Z33: ng | AA33: 聲 | AB33: ng鼻音韻尾編碼：【W】 | AD33: 29 | AE33: I | AF33: Q | AG33: ㆧ | AH33: oonn
B34: =ROW() - 4 -> 30 | C34: p | D34: -n | E34: N | F34: N | G34: =_xlfn.XLOOKUP(按鍵設計表[[#This Row],[台語音標]], 注音編碼對照表[台語音標], 注音編碼對照表[注音符號], "") -> ㄣ | H34: =_xlfn.XLOOKUP(按鍵設計表[[#This Row],[台語音標]], 注音編碼對照表[台語音標], 注音編碼對照表[漢字例], "") -> 恩 | I34: =_xlfn.XLOOKUP(按鍵設計表[[#This Row],[台語音標]], 注音編碼對照表[台語音標], 注音編碼對照表[聲韻調], "") -> 韻 | J34: =_xlfn.XLOOKUP(按鍵設計表[[#This Row],[台語音標]], 注音編碼對照表[台語音標], 注音編碼對照表[十五音], "") -> 0 | K34: =_xlfn.XLOOKUP(按鍵設計表[[#This Row],[台語音標]], 注音編碼對照表[台語音標], 注音編碼對照表[注音二式], "") -> n | L34: =_xlfn.XLOOKUP(按鍵設計表[[#This Row],[台語音標]], 注音編碼對照表[台語音標], 注音編碼對照表[台羅拼音], "") -> n | M34: =_xlfn.XLOOKUP(按鍵設計表[[#This Row],[台語音標]], 注音編碼對照表[台語音標], 注音編碼對照表[白話字], "") -> n | N34: =_xlfn.XLOOKUP(按鍵設計表[[#This Row],[台語音標]], 注音編碼對照表[台語音標], 注音編碼對照表[閩拼方案], "") -> n | O34: n鼻音韻尾編碼：【N】 | Q34: =LEN(按鍵設計表[[#This Row],[注音符號]]) -> 1 | S34: =ROW() - 4 -> 30 | T34: =ROW() - 4 -> 30 | U34: 7 | V34: ˙ | W34: 8 | X34: 8 | Y34: 8 | Z34: 8 | AA34: 調 | AB34: 入聲韻母輸入鍵 | AD34: 30 | AE34: k | AF34: o | AG34: ㄜ | AH34: or
B35: =ROW() - 4 -> 31 | C35: / | D35: -ng | E35: G | F35: G | G35: =_xlfn.XLOOKUP(按鍵設計表[[#This Row],[台語音標]], 注音編碼對照表[台語音標], 注音編碼對照表[注音符號], "") -> ㆭ | H35: =_xlfn.XLOOKUP(按鍵設計表[[#This Row],[台語音標]], 注音編碼對照表[台語音標], 注音編碼對照表[漢字例], "") -> 秧 | I35: =_xlfn.XLOOKUP(按鍵設計表[[#This Row],[台語音標]], 注音編碼對照表[台語音標], 注音編碼對照表[聲韻調], "") -> 韻 | J35: =_xlfn.XLOOKUP(按鍵設計表[[#This Row],[台語音標]], 注音編碼對照表[台語音標], 注音編碼對照表[十五音], "") -> 鋼 | K35: =_xlfn.XLOOKUP(按鍵設計表[[#This Row],[台語音標]], 注音編碼對照表[台語音標], 注音編碼對照表[注音二式], "") -> ng | L35: =_xlfn.XLOOKUP(按鍵設計表[[#This Row],[台語音標]], 注音編碼對照表[台語音標], 注音編碼對照表[台羅拼音], "") -> ng | M35: =_xlfn.XLOOKUP(按鍵設計表[[#This Row],[台語音標]], 注音編碼對照表[台語音標], 注音編碼對照表[白話字], "") -> ng | N35: =_xlfn.XLOOKUP(按鍵設計表[[#This Row],[台語音標]], 注音編碼對照表[台語音標], 注音編碼對照表[閩拼方案], "") -> ng | O35: ng鼻音韻尾編碼：【G】 | Q35: =LEN(按鍵設計表[[#This Row],[注音符號]]) -> 1 | S35: =ROW() - 4 -> 31 | T35: =ROW() - 4 -> 31 | U35: u | V35: ㄧ | W35: i | X35: i | Y35: i | Z35: i | AA35: 韻 | AD35: 31 | AE35: , | AF35: e | AG35: ㆤ | AH35: e
B36: =ROW() - 4 -> 32 | C36: b | D36: -p | E36: R | F36: ph | G36: =_xlfn.XLOOKUP(按鍵設計表[[#This Row],[台語音標]], 注音編碼對照表[台語音標], 注音編碼對照表[注音符號], "",0, 1 ) -> ㆴ | H36: =_xlfn.XLOOKUP(按鍵設計表[[#This Row],[台語音標]], 注音編碼對照表[台語音標], 注音編碼對照表[漢字例], "") -> 哈沓 | I36: =_xlfn.XLOOKUP(按鍵設計表[[#This Row],[台語音標]], 注音編碼對照表[台語音標], 注音編碼對照表[聲韻調], "") -> 韻尾 | J36: =_xlfn.XLOOKUP(按鍵設計表[[#This Row],[台語音標]], 注音編碼對照表[台語音標], 注音編碼對照表[十五音], "") -> 0 | K36: =_xlfn.XLOOKUP(按鍵設計表[[#This Row],[台語音標]], 注音編碼對照表[台語音標], 注音編碼對照表[注音二式], "") -> p | L36: =_xlfn.XLOOKUP(按鍵設計表[[#This Row],[台語音標]], 注音編碼對照表[台語音標], 注音編碼對照表[台羅拼音], "") -> p | M36: =_xlfn.XLOOKUP(按鍵設計表[[#This Row],[台語音標]], 注音編碼對照表[台語音標], 注音編碼對照表[白話字], "") -> p | N36: =_xlfn.XLOOKUP(按鍵設計表[[#This Row],[台語音標]], 注音編碼對照表[台語音標], 注音編碼對照表[閩拼方案], "") -> p | O36: p入聲韻尾 | P36: ㆴ | Q36: =LEN(按鍵設計表[[#This Row],[注音符號]]) -> 1 | S36: =ROW() - 4 -> 32 | T36: =ROW() - 4 -> 32 | U36: U | V36: ㆪ | W36: I | X36: inn | Y36: ni | Z36: inn | AA36: 韻 | AD36: 32 | AE36: < | AF36: E | AG36: ㆥ | AH36: enn
B37: =ROW() - 4 -> 33 | C37: t | D37: -t | E37: F | F37: th | G37: =_xlfn.XLOOKUP(按鍵設計表[[#This Row],[台語音標]], 注音編碼對照表[台語音標], 注音編碼對照表[注音符號], "") -> ㆵ | H37: =_xlfn.XLOOKUP(按鍵設計表[[#This Row],[台語音標]], 注音編碼對照表[台語音標], 注音編碼對照表[漢字例], "") -> 叭別 | I37: =_xlfn.XLOOKUP(按鍵設計表[[#This Row],[台語音標]], 注音編碼對照表[台語音標], 注音編碼對照表[聲韻調], "") -> 韻尾 | J37: =_xlfn.XLOOKUP(按鍵設計表[[#This Row],[台語音標]], 注音編碼對照表[台語音標], 注音編碼對照表[十五音], "") -> 0 | K37: =_xlfn.XLOOKUP(按鍵設計表[[#This Row],[台語音標]], 注音編碼對照表[台語音標], 注音編碼對照表[注音二式], "") -> t | L37: =_xlfn.XLOOKUP(按鍵設計表[[#This Row],[台語音標]], 注音編碼對照表[台語音標], 注音編碼對照表[台羅拼音], "") -> t | M37: =_xlfn.XLOOKUP(按鍵設計表[[#This Row],[台語音標]], 注音編碼對照表[台語音標], 注音編碼對照表[白話字], "") -> t | N37: =_xlfn.XLOOKUP(按鍵設計表[[#This Row],[台語音標]], 注音編碼對照表[台語音標], 注音編碼對照表[閩拼方案], "") -> t | O37: t入聲韻尾 | P37: ㆵ | Q37: =LEN(按鍵設計表[[#This Row],[注音符號]]) -> 1 | S37: =ROW() - 4 -> 33 | T37: =ROW() - 4 -> 33 | U37: j | V37: ㄨ | W37: u | X37: u | Y37: u | Z37: u | AA37: 韻 | AD37: 33 | AE37: 9 | AF37: x | AG37: ㄞ | AH37: ai
B38: =ROW() - 4 -> 34 | C38: g | D38: -k | E38: Q | F38: kh | G38: =_xlfn.XLOOKUP(按鍵設計表[[#This Row],[台語音標]], 注音編碼對照表[台語音標], 注音編碼對照表[注音符號], "") -> ㆻ | H38: =_xlfn.XLOOKUP(按鍵設計表[[#This Row],[台語音標]], 注音編碼對照表[台語音標], 注音編碼對照表[漢字例], "") -> 德俗 | I38: =_xlfn.XLOOKUP(按鍵設計表[[#This Row],[台語音標]], 注音編碼對照表[台語音標], 注音編碼對照表[聲韻調], "") -> 韻尾 | J38: =_xlfn.XLOOKUP(按鍵設計表[[#This Row],[台語音標]], 注音編碼對照表[台語音標], 注音編碼對照表[十五音], "") -> 0 | K38: =_xlfn.XLOOKUP(按鍵設計表[[#This Row],[台語音標]], 注音編碼對照表[台語音標], 注音編碼對照表[注音二式], "") -> k | L38: =_xlfn.XLOOKUP(按鍵設計表[[#This Row],[台語音標]], 注音編碼對照表[台語音標], 注音編碼對照表[台羅拼音], "") -> k | M38: =_xlfn.XLOOKUP(按鍵設計表[[#This Row],[台語音標]], 注音編碼對照表[台語音標], 注音編碼對照表[白話字], "") -> k | N38: =_xlfn.XLOOKUP(按鍵設計表[[#This Row],[台語音標]], 注音編碼對照表[台語音標], 注音編碼對照表[閩拼方案], "") -> k | O38: k入聲韻尾 | P38: ㆻ | Q38: =LEN(按鍵設計表[[#This Row],[注音符號]]) -> 1 | S38: =ROW() - 4 -> 34 | T38: =ROW() - 4 -> 34 | U38: J | V38: ㆫ | W38: U | X38: unn | Y38: nu | Z38: unn | AA38: 韻 | AD38: 34 | AE38: ( | AF38: X | AG38: ㆮ | AH38: ainn
B39: =ROW() - 4 -> 35 | C39: z | D39: -k | E39: V | F39: h | G39: =_xlfn.XLOOKUP(按鍵設計表[[#This Row],[台語音標]], 注音編碼對照表[台語音標], 注音編碼對照表[注音符號], "") -> ㆻ | H39: =_xlfn.XLOOKUP(按鍵設計表[[#This Row],[台語音標]], 注音編碼對照表[台語音標], 注音編碼對照表[漢字例], "") -> 德俗 | I39: =_xlfn.XLOOKUP(按鍵設計表[[#This Row],[台語音標]], 注音編碼對照表[台語音標], 注音編碼對照表[聲韻調], "") -> 韻尾 | J39: =_xlfn.XLOOKUP(按鍵設計表[[#This Row],[台語音標]], 注音編碼對照表[台語音標], 注音編碼對照表[十五音], "") -> 0 | K39: =_xlfn.XLOOKUP(按鍵設計表[[#This Row],[台語音標]], 注音編碼對照表[台語音標], 注音編碼對照表[注音二式], "") -> k | L39: =_xlfn.XLOOKUP(按鍵設計表[[#This Row],[台語音標]], 注音編碼對照表[台語音標], 注音編碼對照表[台羅拼音], "") -> k | M39: =_xlfn.XLOOKUP(按鍵設計表[[#This Row],[台語音標]], 注音編碼對照表[台語音標], 注音編碼對照表[白話字], "") -> k | N39: =_xlfn.XLOOKUP(按鍵設計表[[#This Row],[台語音標]], 注音編碼對照表[台語音標], 注音編碼對照表[閩拼方案], "") -> k | O39: h入聲韻尾 | P39: ㆷ | Q39: =LEN(按鍵設計表[[#This Row],[注音符號]]) -> 1 | S39: =ROW() - 4 -> 35 | T39: =ROW() - 4 -> 35 | U39: m | V39: ㆬ | W39: M | X39: m | Y39: m | Z39: m | AA39: 韻 | AD39: 35 | AE39: l | AF39: y | AG39: ㄠ | AH39: au
B40: =ROW() - 4 -> 36 | C40: 9 | D40: ai | E40: I | F40: I | G40: =_xlfn.XLOOKUP(按鍵設計表[[#This Row],[台語音標]], 注音編碼對照表[台語音標], 注音編碼對照表[注音符號], "") -> ㄞ | H40: =_xlfn.XLOOKUP(按鍵設計表[[#This Row],[台語音標]], 注音編碼對照表[台語音標], 注音編碼對照表[漢字例], "") -> 哀 | I40: =_xlfn.XLOOKUP(按鍵設計表[[#This Row],[台語音標]], 注音編碼對照表[台語音標], 注音編碼對照表[聲韻調], "") -> 韻 | J40: =_xlfn.XLOOKUP(按鍵設計表[[#This Row],[台語音標]], 注音編碼對照表[台語音標], 注音編碼對照表[十五音], "") -> 皆 | K40: =_xlfn.XLOOKUP(按鍵設計表[[#This Row],[台語音標]], 注音編碼對照表[台語音標], 注音編碼對照表[注音二式], "") -> ai | L40: =_xlfn.XLOOKUP(按鍵設計表[[#This Row],[台語音標]], 注音編碼對照表[台語音標], 注音編碼對照表[台羅拼音], "") -> ai | M40: =_xlfn.XLOOKUP(按鍵設計表[[#This Row],[台語音標]], 注音編碼對照表[台語音標], 注音編碼對照表[白話字], "") -> ai | N40: =_xlfn.XLOOKUP(按鍵設計表[[#This Row],[台語音標]], 注音編碼對照表[台語音標], 注音編碼對照表[閩拼方案], "") -> ai | P40: =_xlfn.UNICODE(P36) -> 12724 | Q40: =LEN(按鍵設計表[[#This Row],[注音符號]]) -> 1 | S40: =ROW() - 4 -> 36 | T40: =ROW() - 4 -> 36 | U40: M | V40: ㆰ | W40: V | X40: am | Y40: am | Z40: am | AA40: 韻 | AB40: 【ㆱ】共用【m】按鍵；【編碼】=【v】 | AD40: 36 | AE40: L | AF40: Y | AG40: ㆯ | AH40: aunn
B41: =ROW() - 4 -> 37 | C41: l | D41: au | E41: U | F41: U | G41: =_xlfn.XLOOKUP(按鍵設計表[[#This Row],[台語音標]], 注音編碼對照表[台語音標], 注音編碼對照表[注音符號], "") -> ㄠ | H41: =_xlfn.XLOOKUP(按鍵設計表[[#This Row],[台語音標]], 注音編碼對照表[台語音標], 注音編碼對照表[漢字例], "") -> 甌 | I41: =_xlfn.XLOOKUP(按鍵設計表[[#This Row],[台語音標]], 注音編碼對照表[台語音標], 注音編碼對照表[聲韻調], "") -> 韻 | J41: =_xlfn.XLOOKUP(按鍵設計表[[#This Row],[台語音標]], 注音編碼對照表[台語音標], 注音編碼對照表[十五音], "") -> 交 | K41: =_xlfn.XLOOKUP(按鍵設計表[[#This Row],[台語音標]], 注音編碼對照表[台語音標], 注音編碼對照表[注音二式], "") -> au | L41: =_xlfn.XLOOKUP(按鍵設計表[[#This Row],[台語音標]], 注音編碼對照表[台語音標], 注音編碼對照表[台羅拼音], "") -> au | M41: =_xlfn.XLOOKUP(按鍵設計表[[#This Row],[台語音標]], 注音編碼對照表[台語音標], 注音編碼對照表[白話字], "") -> au | N41: =_xlfn.XLOOKUP(按鍵設計表[[#This Row],[台語音標]], 注音編碼對照表[台語音標], 注音編碼對照表[閩拼方案], "") -> ao | P41: =_xlfn.UNICODE(G36) -> 12724 | Q41: =LEN(按鍵設計表[[#This Row],[注音符號]]) -> 1 | S41: =ROW() - 4 -> 37 | T41: =ROW() - 4 -> 37 | U41: 8 | V41: ㄚ | W41: a | X41: a | Y41: a | Z41: a | AA41: 韻 | AD41: 37 | AE41: 0 | AF41: @ | AG41: ㄢ | AH41: an
...

Sheet 輸入方案設計規格
BZ1: 聲韻調 | CJ1: 聲韻調 | CK1: 聲韻調 | CT1: 聲韻調
B2: 1 ! | E2: 2 @ | H2: 3 # | K2: 4 $ | N2: 0.05 | Q2: 6 ^ | T2: 7 & | W2: 8 * | Z2: 9 ( | AC2: 0 ) | AF2: - _ | AI2: = + | BZ2: 聲 | CJ2: 韻 | CK2: <>韻尾 | CT2: 調
B3: ㆠ | D3: b | W3: ㆩ | Y3: ann | Z3: ㆮ | AA3: 0 | AB3: ainn | BO3: 對映總表
B4: ㄅ | D4: p | E4: ㄉ | G4: t | H4: =_xlfn.UNICHAR(HEX2DEC(RIGHT("U+02EA",4))) -> ˪ | J4: 陰去 | K4: ˋ | M4: 上声 | N4: ˫ | P4: 陽去 | Q4: ˊ | S4: 陽平 | T4: · | V4: 入声 | W4: ㄚ | Y4: a | Z4: ㄞ | AB4: ai | AC4: ㄢ | AD4: 0 | AE4: an | AF4: ñ | AH4: *nn | AI4: ㄥㄚ | AK4: na | BP4: 注音符號 | BQ4: 聲韻調 | BR4: 鍵盤按鍵 | BS4: 字典編碼 | BT4: 台語音標 | BU4: 字母長度 | BZ4: 注音符號 | CA4: 聲韻調 | CB4: 鍵盤按鍵 | CC4: 注音編碼 | CD4: =輸入方案設計規格!$BT$4 -> 台語音標 | CE4: 字母長度 | CJ4: 注音符號 | CK4: 聲韻調 | CL4: 鍵盤按鍵 | CM4: 注音編碼 | CN4: =輸入方案設計規格!$BT$4 -> 台語音標 | CO4: 字母長度 | CT4: 注音符號 | CU4: 聲韻調 | CV4: 鍵盤按鍵 | CW4: 注音編碼 | CX4: =輸入方案設計規格!$BT$4 -> 台語音標 | CY4: 字母長度
C5: Q | F5: W | I5: E | L5: R | O5: T | R5: Y | U5: U | X5: I | AA5: O | AD5: P | AG5: [ { | AJ5: ] } | AM5: \ | | BM5: {=INDEX($D$18:$BH$18, 1, $BO5)} -> ㆠ | BN5: {=INDIRECT(ADDRESS(17, COLUMN($D$18) + $BO5 - 1))} -> ! | BO5: =ROW() - 4 -> 1 | BP5: {=TRANSPOSE($D$18:$BH$18)} -> ㆠ | BQ5: =_xlfn.XLOOKUP(BP5, 按鍵設計表[注音符號], 按鍵設計表[聲韻調], "") -> 聲 | BR5: {=TRANSPOSE($D$17:$BH$17)} -> ! | BS5: {=TRANSPOSE($D$19:$BH$19)} -> b | BT5: {=TRANSPOSE($D$20:$BH$20)} -> b | BU5: =LEN(BT5) -> 1 | BW5: =" """ & BR6 & """: { commit: """ & BP6 & """ }" & " # " & "/" & BT6 & "/ ==> " & BS6 -> "1": { commit: "ㄅ" } # /p/ ==> p | BY5: =ROW() - 4 -> 1 | BZ5: {=_xlfn._xlws.FILTER(BP5:BU61,(BQ5:BQ61=BZ2))} -> ㆠ | CA5: 聲 | CB5: ! | CC5: b | CD5: b | CE5: 1 | CG5: =IF( OR(CD5=0, CC5=CD5), "", " - xform/^" & CD5 & "/" & CC5 & "/ # " & BZ5 & " [ " & CD5 & "]") | CH5: {=_xlfn._xlws.FILTER(CG5:CG61, CG5:CG61<>"")} -> - xform/^ph/P/ # ㄆ [ ph] | CI5: =ROW() - 4 -> 1 | CJ5: {=_xlfn._xlws.FILTER(BP5:BU61,(BQ5:BQ61=CJ2)*(BQ5:BQ61<>CK2))} -> ㄚ | CK5: 韻 | CL5: 8 | CM5: a | CN5: a | CO5: 1 | CQ5: =IFERROR( IF(OR(CN5=0, CM5=CN5), "", IF(CL5=CM5, "", " - xform/" & CN5 & "/" & CM5 & "/ # " & CJ5 & " [" & CP5 & CN5 & "]")), "") | CR5: {=_xlfn._xlws.FILTER(CQ5:CQ61, CQ5:CQ61<>"")} -> - xform/ir/w/ # ㆨ [ir] | CT5: {=_xlfn._xlws.FILTER(BP5:BU61,(BQ5:BQ61=CT2))} -> ˙ | CU5: 調 | CV5: 7 | CW5: 0 | CX5: 0 | CY5: 1 | DA5: =IF(CX5=0, "", " - xform/" & CX5 & "/" & CT5 & "/ # 按鍵：" & CV5 & " [ 第 " & CX5 & " 調 ]")
I6: ㆣ | K6: g | L6: ㆢ | N6: J | R6: ㆡ | T6: j | U6: ㆪ | W6: inn | X6: ㆧ | Y6: oonn | AA6: ㆱ | AC6: om | BM6: {=INDEX($D$18:$BH$18, 1, $BO6)} -> ㄅ | BN6: {=INDIRECT(ADDRESS(17, COLUMN($D$18) + $BO6 - 1))} -> 1 | BO6: =ROW() - 4 -> 2 | BP6: ㄅ | BQ6: =_xlfn.XLOOKUP(BP6, 按鍵設計表[注音符號], 按鍵設計表[聲韻調], "") -> 聲 | BR6: 1 | BS6: p | BT6: p | BU6: =LEN(BT6) -> 1 | BW6: =" """ & BR5 & """: { commit: """ & BP5 & """ }" & " # " & "/" & BT5 & "/ ==> " & BS5 -> "!": { commit: "ㆠ" } # /b/ ==> b | BY6: =ROW() - 4 -> 2 | BZ6: ㄅ | CA6: 聲 | CB6: 1 | CC6: p | CD6: p | CE6: 1 | CG6: =IF( OR(CD6=0, CC6=CD6), "", " - xform/^" & CD6 & "/" & CC6 & "/ # " & BZ6 & " [ " & CD6 & "]") | CH6: - xform/^th/T/ # ㄊ [ th] | CI6: =ROW() - 4 -> 2 | CJ6: ㄧ | CK6: 韻 | CL6: u | CM6: i | CN6: i | CO6: 1 | CQ6: =IFERROR( IF(OR(CN6=0, CM6=CN6), "", IF(CL6=CM6, "", " - xform/" & CN6 & "/" & CM6 & "/ # " & CJ6 & " [" & CP6 & CN6 & "]")), "") | CR6: - xform/oo/o/ # ㆦ [oo] | CT6: ˫ | CU6: 調 | CV6: 5 | CW6: 7 | CX6: 7 | CY6: 1 | DA6: =IF(CX6=0, "", " - xform/" & CX6 & "/" & CT6 & "/ # 按鍵：" & CV6 & " [ 第 " & CX6 & " 調 ]") -> - xform/7/˫/ # 按鍵：5 [ 第 7 調 ]
C7: ㄆ | E7: ph | F7: ㄊ | H7: th | I7: ㄍ | J7: 0 | K7: k | L7: ㄐ | N7: Z | O7: ㆵ | Q7: t0 | R7: ㄗ | T7: z | U7: ㄧ | W7: i | X7: ㆦ | Z7: oo | AA7: ㆲ | AC7: ong | AD7: ㄣ | AF7: -n | AI7: 陰入 | AJ7: · | AL7: 陽入 | BM7: {=INDEX($D$18:$BH$18, 1, $BO7)} -> ㄆ | BN7: {=INDIRECT(ADDRESS(17, COLUMN($D$18) + $BO7 - 1))} -> q | BO7: =ROW() - 4 -> 3 | BP7: ㄆ | BQ7: =_xlfn.XLOOKUP(BP7, 按鍵設計表[注音符號], 按鍵設計表[聲韻調], "") -> 聲 | BR7: q | BS7: P | BT7: ph | BU7: =LEN(BT7) -> 2 | BW7: =" """ & BR7 & """: { commit: """ & BP7 & """ }" & " # " & "/" & BT7 & "/ ==> " & BS7 -> "q": { commit: "ㄆ" } # /ph/ ==> P | BY7: =ROW() - 4 -> 3 | BZ7: ㄆ | CA7: 聲 | CB7: q | CC7: P | CD7: ph | CE7: 2 | CG7: =IF( OR(CD7=0, CC7=CD7), "", " - xform/^" & CD7 & "/" & CC7 & "/ # " & BZ7 & " [ " & CD7 & "]") -> - xform/^ph/P/ # ㄆ [ ph] | CH7: - xform/^g/q/ # ㆣ [ g] | CI7: =ROW() - 4 -> 3 | CJ7: ㆨ | CK7: 韻 | CL7: K | CM7: w | CN7: ir | CO7: 2 | CQ7: =IFERROR( IF(OR(CN7=0, CM7=CN7), "", IF(CL7=CM7, "", " - xform/" & CN7 & "/" & CM7 & "/ # " & CJ7 & " [" & CP7 & CN7 & "]")), "") -> - xform/ir/w/ # ㆨ [ir] | CR7: - xform/o/ø/ # ㄜ [o] | CT7: ˪ | CU7: 調 | CV7: 3 | CW7: 3 | CX7: 3 | CY7: 1 | DA7: =IF(CX7=0, "", " - xform/" & CX7 & "/" & CT7 & "/ # 按鍵：" & CV7 & " [ 第 " & CX7 & " 調 ]") -> - xform/3/˪/ # 按鍵：3 [ 第 3 調 ]
D8: A | G8: S | J8: D | M8: F | P8: G | S8: H | V8: J | Y8: K | AB8: L | AE8: ; : | AH8: ' " | BM8: {=INDEX($D$18:$BH$18, 1, $BO8)} -> ㄇ | BN8: {=INDIRECT(ADDRESS(17, COLUMN($D$18) + $BO8 - 1))} -> a | BO8: =ROW() - 4 -> 4 | BP8: ㄇ | BQ8: =_xlfn.XLOOKUP(BP8, 按鍵設計表[注音符號], 按鍵設計表[聲韻調], "") -> 聲 | BR8: a | BS8: m | BT8: m | BU8: =LEN(BT8) -> 1 | BW8: =" """ & BR8 & """: { commit: """ & BP8 & """ }" & " # " & "/" & BT8 & "/ ==> " & BS8 -> "a": { commit: "ㄇ" } # /m/ ==> m | BY8: =ROW() - 4 -> 4 | BZ8: ㄇ | CA8: 聲 | CB8: a | CC8: m | CD8: m | CE8: 1 | CG8: =IF( OR(CD8=0, CC8=CD8), "", " - xform/^" & CD8 & "/" & CC8 & "/ # " & BZ8 & " [ " & CD8 & "]") | CH8: - xform/^kh/K/ # ㄎ [ kh] | CI8: =ROW() - 4 -> 4 | CJ8: ㄨ | CK8: 韻 | CL8: j | CM8: u | CN8: u | CO8: 1 | CQ8: =IFERROR( IF(OR(CN8=0, CM8=CN8), "", IF(CL8=CM8, "", " - xform/" & CN8 & "/" & CM8 & "/ # " & CJ8 & " [" & CP8 & CN8 & "]")), "") | CR8: - xform/-n/N/ # ㄣ [-n] | CT8: ˋ | CU8: 調 | CV8: 4 | CW8: 2 | CX8: 2 | CY8: 1 | DA8: =IF(CX8=0, "", " - xform/" & CX8 & "/" & CT8 & "/ # 按鍵：" & CV8 & " [ 第 " & CX8 & " 調 ]") -> - xform/2/ˋ/ # 按鍵：4 [ 第 2 調 ]
V9: ㆫ | W9: 0 | X9: unn | Y9: ㆨ | AA9: ir | AB9: ㆯ | AC9: aunn | BM9: {=INDEX($D$18:$BH$18, 1, $BO9)} -> ㄋ | BN9: {=INDIRECT(ADDRESS(17, COLUMN($D$18) + $BO9 - 1))} -> s | BO9: =ROW() - 4 -> 5 | BP9: ㄋ | BQ9: =_xlfn.XLOOKUP(BP9, 按鍵設計表[注音符號], 按鍵設計表[聲韻調], "") -> 聲 | BR9: s | BS9: n | BT9: n | BU9: =LEN(BT9) -> 1 | BW9: =" """ & BR9 & """: { commit: """ & BP9 & """ }" & " # " & "/" & BT9 & "/ ==> " & BS9 -> "s": { commit: "ㄋ" } # /n/ ==> n | BY9: =ROW() - 4 -> 5 | BZ9: ㄋ | CA9: 聲 | CB9: s | CC9: n | CD9: n | CE9: 1 | CG9: =IF( OR(CD9=0, CC9=CD9), "", " - xform/^" & CD9 & "/" & CC9 & "/ # " & BZ9 & " [ " & CD9 & "]") | CH9: - xform/^ng/g/ # ㄫ [ ng] | CI9: =ROW() - 4 -> 5 | CJ9: ㆤ | CK9: 韻 | CL9: , | CM9: e | CN9: e | CO9: 1 | CQ9: =IFERROR( IF(OR(CN9=0, CM9=CN9), "", IF(CL9=CM9, "", " - xform/" & CN9 & "/" & CM9 & "/ # " & CJ9 & " [" & CP9 & CN9 & "]")), "") | CR9: - xform/-ng/G/ # ㆭ [-ng] | CT9: ˊ | CU9: 調 | CV9: 6 | CW9: 5 | CX9: 5 | CY9: 1 | DA9: =IF(CX9=0, "", " - xform/" & CX9 & "/" & CT9 & "/ # 按鍵：" & CV9 & " [ 第 " & CX9 & " 調 ]") -> - xform/5/ˊ/ # 按鍵：6 [ 第 5 調 ]
D10: ㄇ | F10: m | G10: ㄋ | I10: n | J10: ㄎ | K10: 0 | L10: kh | M10: ㄑ | O10: C | P10: ㆻ | R10: k0 | S10: ㄘ | U10: c | V10: ㄨ | X10: u | Y10: ㄜ | AA10: or | AB10: ㄠ | AD10: au | AE10: ㄤ | AG10: ang | AH10: =_xlfn.UNICHAR(HEX2DEC(RIGHT("U+00AF",4))) -> ¯ | AJ10: 陰平 | AR10: ¯ | BM10: {=INDEX($D$18:$BH$18, 1, $BO10)} -> ㄉ | BN10: {=INDIRECT(ADDRESS(17, COLUMN($D$18) + $BO10 - 1))} -> 2 | BO10: =ROW() - 4 -> 6 | BP10: ㄉ | BQ10: =_xlfn.XLOOKUP(BP10, 按鍵設計表[注音符號], 按鍵設計表[聲韻調], "") -> 聲 | BR10: 2 | BS10: t | BT10: t | BU10: =LEN(BT10) -> 1 | BW10: =" """ & BR10 & """: { commit: """ & BP10 & """ }" & " # " & "/" & BT10 & "/ ==> " & BS10 -> "2": { commit: "ㄉ" } # /t/ ==> t | BY10: =ROW() - 4 -> 6 | BZ10: ㄉ | CA10: 聲 | CB10: 2 | CC10: t | CD10: t | CE10: 1 | CG10: =IF( OR(CD10=0, CC10=CD10), "", " - xform/^" & CD10 & "/" & CC10 & "/ # " & BZ10 & " [ " & CD10 & "]") | CH10: - xform/^ji/J/ # ㆢ [ ji] | CI10: =ROW() - 4 -> 6 | CJ10: ㆦ | CK10: 韻 | CL10: i | CM10: o | CN10: oo | CO10: 2 | CQ10: =IFERROR( IF(OR(CN10=0, CM10=CN10), "", IF(CL10=CM10, "", " - xform/" & CN10 & "/" & CM10 & "/ # " & CJ10 & " [" & CP10 & CN10 & "]")), "") -> - xform/oo/o/ # ㆦ [oo] | CR10: - xform/ai/I/ # ㄞ [ai] | DA10: =IF(CX10=0, "", " - xform/" & CX10 & "/" & CT10 & "/ # 按鍵：" & CV10 & " [ 第 " & CX10 & " 調 ]")
E11: Z | H11: X | K11: C | N11: V | Q11: B | T11: N | W11: M | Z11: , < | AC11: . > | AF11: / ? | BM11: {=INDEX($D$18:$BH$18, 1, $BO11)} -> ㄊ | BN11: {=INDIRECT(ADDRESS(17, COLUMN($D$18) + $BO11 - 1))} -> w | BO11: =ROW() - 4 -> 7 | BP11: ㄊ | BQ11: =_xlfn.XLOOKUP(BP11, 按鍵設計表[注音符號], 按鍵設計表[聲韻調], "") -> 聲 | BR11: w | BS11: T | BT11: th | BU11: =LEN(BT11) -> 2 | BW11: =" """ & BR11 & """: { commit: """ & BP11 & """ }" & " # " & "/" & BT11 & "/ ==> " & BS11 -> "w": { commit: "ㄊ" } # /th/ ==> T | BY11: =ROW() - 4 -> 7 | BZ11: ㄊ | CA11: 聲 | CB11: w | CC11: T | CD11: th | CE11: 2 | CG11: =IF( OR(CD11=0, CC11=CD11), "", " - xform/^" & CD11 & "/" & CC11 & "/ # " & BZ11 & " [ " & CD11 & "]") -> - xform/^th/T/ # ㄊ [ th] | CH11: - xform/^zi/Z/ # ㄐ [ zi] | CI11: =ROW() - 4 -> 7 | CJ11: ㄜ | CK11: 韻 | CL11: k | CM11: ø | CN11: o | CO11: 1 | CQ11: =IFERROR( IF(OR(CN11=0, CM11=CN11), "", IF(CL11=CM11, "", " - xform/" & CN11 & "/" & CM11 & "/ # " & CJ11 & " [" & CP11 & CN11 & "]")), "") -> - xform/o/ø/ # ㄜ [o] | CR11: - xform/au/U/ # ㄠ [au] | DA11: =IF(CX11=0, "", " - xform/" & CX11 & "/" & CT11 & "/ # 按鍵：" & CV11 & " [ 第 " & CX11 & " 調 ]")
T12: ㄫ | V12: ng | W12: ㆰ | Y12: am | Z12: ㆥ | AA12: 0 | AB12: enn | BM12: {=INDEX($D$18:$BH$18, 1, $BO12)} -> ㄌ | BN12: {=INDIRECT(ADDRESS(17, COLUMN($D$18) + $BO12 - 1))} -> x | BO12: =ROW() - 4 -> 8 | BP12: ㄌ | BQ12: =_xlfn.XLOOKUP(BP12, 按鍵設計表[注音符號], 按鍵設計表[聲韻調], "") -> 聲 | BR12: x | BS12: l | BT12: l | BU12: =LEN(BT12) -> 1 | BW12: =" """ & BR12 & """: { commit: """ & BP12 & """ }" & " # " & "/" & BT12 & "/ ==> " & BS12 -> "x": { commit: "ㄌ" } # /l/ ==> l | BY12: =ROW() - 4 -> 8 | BZ12: ㄌ | CA12: 聲 | CB12: x | CC12: l | CD12: l | CE12: 1 | CG12: =IF( OR(CD12=0, CC12=CD12), "", " - xform/^" & CD12 & "/" & CC12 & "/ # " & BZ12 & " [ " & CD12 & "]") | CH12: - xform/^ci/C/ # ㄑ [ ci] | CI12: =ROW() - 4 -> 8 | CJ12: ㆬ | CK12: 韻 | CL12: m | CM12: M | CN12: -m | CO12: 2 | CQ12: =IFERROR( IF(OR(CN12=0, CM12=CN12), "", IF(CL12=CM12, "", " - xform/" & CN12 & "/" & CM12 & "/ # " & CJ12 & " [" & CP12 & CN12 & "]")), "") | CR12: - xform/am/Y/ # ㆰ [am] | DA12: =IF(CX12=0, "", " - xform/" & CX12 & "/" & CT12 & "/ # 按鍵：" & CV12 & " [ 第 " & CX12 & " 調 ]")
E13: ㆷ | G13: h0 | H13: ㄌ | J13: l | K13: ㄏ | M13: h | N13: ㄒ | P13: S | Q13: ㆴ | S13: p0 | T13: ㄙ | V13: s | W13: ㆬ | Y13: -m | Z13: ㆤ | AA13: 0 | AB13: e | AC13: 入 | AE13: ptkh | AF13: ㆭ | AH13: -ng | BM13: {=INDEX($D$18:$BH$18, 1, $BO13)} -> ㆣ | BN13: {=INDIRECT(ADDRESS(17, COLUMN($D$18) + $BO13 - 1))} -> E | BO13: =ROW() - 4 -> 9 | BP13: ㆣ | BQ13: =_xlfn.XLOOKUP(BP13, 按鍵設計表[注音符號], 按鍵設計表[聲韻調], "") -> 聲 | BR13: E | BS13: q | BT13: g | BU13: =LEN(BT13) -> 1 | BW13: =" """ & BR14 & """: { commit: """ & BP14 & """ }" & " # " & "/" & BT14 & "/ ==> " & BS14 -> "e": { commit: "ㄍ" } # /k/ ==> k | BY13: =ROW() - 4 -> 9 | BZ13: ㆣ | CA13: 聲 | CB13: E | CC13: q | CD13: g | CE13: 1 | CG13: =IF( OR(CD13=0, CC13=CD13), "", " - xform/^" & CD13 & "/" & CC13 & "/ # " & BZ13 & " [ " & CD13 & "]") -> - xform/^g/q/ # ㆣ [ g] | CH13: - xform/^si/S/ # ㄒ [ si] | CI13: =ROW() - 4 -> 9 | CJ13: ㄣ | CK13: 韻 | CL13: p | CM13: N | CN13: -n | CO13: 2 | CQ13: =IFERROR( IF(OR(CN13=0, CM13=CN13), "", IF(CL13=CM13, "", " - xform/" & CN13 & "/" & CM13 & "/ # " & CJ13 & " [" & CP13 & CN13 & "]")), "") -> - xform/-n/N/ # ㄣ [-n] | CR13: - xform/an/@/ # ㄢ [an] | DA13: =IF(CX13=0, "", " - xform/" & CX13 & "/" & CT13 & "/ # 按鍵：" & CV13 & " [ 第 " & CX13 & " 調 ]")
BM14: {=INDEX($D$18:$BH$18, 1, $BO14)} -> ㄍ | BN14: {=INDIRECT(ADDRESS(17, COLUMN($D$18) + $BO14 - 1))} -> e | BO14: =ROW() - 4 -> 10 | BP14: ㄍ | BQ14: =_xlfn.XLOOKUP(BP14, 按鍵設計表[注音符號], 按鍵設計表[聲韻調], "") -> 聲 | BR14: e | BS14: k | BT14: k | BU14: =LEN(BT14) -> 1 | BW14: =" """ & BR13 & """: { commit: """ & BP13 & """ }" & " # " & "/" & BT13 & "/ ==> " & BS13 -> "E": { commit: "ㆣ" } # /g/ ==> q | BY14: =ROW() - 4 -> 10 | BZ14: ㄍ | CA14: 聲 | CB14: e | CC14: k | CD14: k | CE14: 1 | CG14: =IF( OR(CD14=0, CC14=CD14), "", " - xform/^" & CD14 & "/" & CC14 & "/ # " & BZ14 & " [ " & CD14 & "]") | CI14: =ROW() - 4 -> 10 | CJ14: ㆭ | CK14: 韻 | CL14: / | CM14: G | CN14: -ng | CO14: 3 | CQ14: =IFERROR( IF(OR(CN14=0, CM14=CN14), "", IF(CL14=CM14, "", " - xform/" & CN14 & "/" & CM14 & "/ # " & CJ14 & " [" & CP14 & CN14 & "]")), "") -> - xform/-ng/G/ # ㆭ [-ng] | CR14: - xform/ang/A/ # ㄤ [ang] | DA14: =IF(CX14=0, "", " - xform/" & CX14 & "/" & CT14 & "/ # 按鍵：" & CV14 & " [ 第 " & CX14 & " 調 ]")
BM15: {=INDEX($D$18:$BH$18, 1, $BO15)} -> ㄎ | BN15: {=INDIRECT(ADDRESS(17, COLUMN($D$18) + $BO15 - 1))} -> d | BO15: =ROW() - 4 -> 11 | BP15: ㄎ | BQ15: =_xlfn.XLOOKUP(BP15, 按鍵設計表[注音符號], 按鍵設計表[聲韻調], "") -> 聲 | BR15: d | BS15: K | BT15: kh | BU15: =LEN(BT15) -> 2 | BW15: =" """ & BR15 & """: { commit: """ & BP15 & """ }" & " # " & "/" & BT15 & "/ ==> " & BS15 -> "d": { commit: "ㄎ" } # /kh/ ==> K | BY15: =ROW() - 4 -> 11 | BZ15: ㄎ | CA15: 聲 | CB15: d | CC15: K | CD15: kh | CE15: 2 | CG15: =IF( OR(CD15=0, CC15=CD15), "", " - xform/^" & CD15 & "/" & CC15 & "/ # " & BZ15 & " [ " & CD15 & "]") -> - xform/^kh/K/ # ㄎ [ kh] | CI15: =ROW() - 4 -> 11 | CJ15: ㄞ | CK15: 韻 | CL15: 9 | CM15: I | CN15: ai | CO15: 2 | CQ15: =IFERROR( IF(OR(CN15=0, CM15=CN15), "", IF(CL15=CM15, "", " - xform/" & CN15 & "/" & CM15 & "/ # " & CJ15 & " [" & CP15 & CN15 & "]")), "") -> - xform/ai/I/ # ㄞ [ai] | CR15: - xform/om/W/ # ㆱ [om] | DA15: =IF(CX15=0, "", " - xform/" & CX15 & "/" & CT15 & "/ # 按鍵：" & CV15 & " [ 第 " & CX15 & " 調 ]")
B16: 序號 | D16: {=COLUMN() - COLUMN($C:$C)} -> 1 | E16: {=COLUMN() - COLUMN($C:$C)} -> 2 | F16: {=COLUMN() - COLUMN($C:$C)} -> 3 | G16: {=COLUMN() - COLUMN($C:$C)} -> 4 | H16: {=COLUMN() - COLUMN($C:$C)} -> 5 | I16: {=COLUMN() - COLUMN($C:$C)} -> 6 | J16: {=COLUMN() - COLUMN($C:$C)} -> 7 | K16: {=COLUMN() - COLUMN($C:$C)} -> 8 | ... BJ16: {=COLUMN() - COLUMN($C:$C)} -> 59 | BM16: {=INDEX($D$18:$BH$18, 1, $BO16)} -> ㄫ | BN16: {=INDIRECT(ADDRESS(17, COLUMN($D$18) + $BO16 - 1))} -> ? | BO16: =ROW() - 4 -> 12 | BP16: ㄫ | BQ16: =_xlfn.XLOOKUP(BP16, 按鍵設計表[注音符號], 按鍵設計表[聲韻調], "") -> 聲 | BR16: ? | BS16: g | BT16: ng | BU16: =LEN(BT16) -> 2 | BW16: =" """ & BR16 & """: { commit: """ & BP16 & """ }" & " # " & "/" & BT16 & "/ ==> " & BS16 -> "?": { commit: "ㄫ" } # /ng/ ==> g | BY16: =ROW() - 4 -> 12 | BZ16: ㄫ | CA16: 聲 | CB16: ? | CC16: g | CD16: ng | CE16: 2 | CG16: =IF( OR(CD16=0, CC16=CD16), "", " - xform/^" & CD16 & "/" & CC16 & "/ # " & BZ16 & " [ " & CD16 & "]") -> - xform/^ng/g/ # ㄫ [ ng] | CI16: =ROW() - 4 -> 12 | CJ16: ㄠ | CK16: 韻 | CL16: l | CM16: U | CN16: au | CO16: 2 | CQ16: =IFERROR( IF(OR(CN16=0, CM16=CN16), "", IF(CL16=CM16, "", " - xform/" & CN16 & "/" & CM16 & "/ # " & CJ16 & " [" & CP16 & CN16 & "]")), "") -> - xform/au/U/ # ㄠ [au] | CR16: - xform/ong/H/ # ㆲ [ong] | DA16: =IF(CX16=0, "", " - xform/" & CX16 & "/" & CT16 & "/ # 按鍵：" & CV16 & " [ 第 " & CX16 & " 調 ]")
B17: 鍵盤按鍵 | D17: {=TRANSPOSE(按鍵設計表[鍵盤按鍵])} -> ! | E17: 1 | F17: q | G17: a | H17: s | I17: 2 | J17: w | K17: x | L17: E | M17: e | N17: d | O17: ? | P17: Y | Q17: y | R17: h | S17: n | T17: c | U17: R | V17: r | W17: f | X17: v | Y17: 8 | Z17: u | AA17: K | AB17: j | AC17: , | AD17: i | AE17: k | AF17: m | AG17: p | AH17: / | AI17: b | AJ17: t | AK17: g | AL17: z | AM17: 9 | AN17: l | AO17: M | AP17: 0 | AQ17: ; | AR17: O | AS17: o | AT17: * | AU17: U | AV17: J | AW17: < | AX17: I | AY17: ( | AZ17: L | BA17: 7 | BB17: 5 | BC17: 3 | BD17: 4 | BE17: 6 | BF17: N | BG17: . | BH17: - | BM17: {=INDEX($D$18:$BH$18, 1, $BO17)} -> ㆡ | BN17: {=INDIRECT(ADDRESS(17, COLUMN($D$18) + $BO17 - 1))} -> Y | BO17: =ROW() - 4 -> 13 | BP17: ㆡ | BQ17: =_xlfn.XLOOKUP(BP17, 按鍵設計表[注音符號], 按鍵設計表[聲韻調], "") -> 聲 | BR17: Y | BS17: j | BT17: j | BU17: =LEN(BT17) -> 1 | BW17: =" """ & BR17 & """: { commit: """ & BP17 & """ }" & " # " & "/" & BT17 & "/ ==> " & BS17 -> "Y": { commit: "ㆡ" } # /j/ ==> j | BY17: =ROW() - 4 -> 13 | BZ17: ㆡ | CA17: 聲 | CB17: Y | CC17: j | CD17: j | CE17: 1 | CG17: =IF( OR(CD17=0, CC17=CD17), "", " - xform/^" & CD17 & "/" & CC17 & "/ # " & BZ17 & " [ " & CD17 & "]") | CI17: =ROW() - 4 -> 13 | CJ17: ㆰ | CK17: 韻 | CL17: M | CM17: Y | CN17: am | CO17: 2 | CQ17: =IFERROR( IF(OR(CN17=0, CM17=CN17), "", IF(CL17=CM17, "", " - xform/" & CN17 & "/" & CM17 & "/ # " & CJ17 & " [" & CP17 & CN17 & "]")), "") -> - xform/am/Y/ # ㆰ [am] | CR17: - xform/ann/La/ # ㆩ [ann] | DA17: =IF(CX17=0, "", " - xform/" & CX17 & "/" & CT17 & "/ # 按鍵：" & CV17 & " [ 第 " & CX17 & " 調 ]")
